File: GFBaking/data/misc/13Gluten_Compression_Misc/13gluten_2.is_comp.raw
"Test Type","Compression"
"Method Name","C:\Users\Public\Documents\Instron\Bluehill\Templates\Instron Examples\Bluehill\CompressionTest Bread.im_comp"
"Sample name","P:\+Courses\MatSci\Spring2016\GF Baking - Emily, Elizabeth, Frances\13gluten_2.is_comp"
"User",""
"Sample note 1",""
"Sample note 2",""
"Sample note 3",""
"Geometry","Circular"
"Specimen",1
"Specimen label","13gluten4"
"Width",50.000000,"mm"
"Thickness",50.000000,"mm"
"Anvil height",22.660000,"mm"
"Diameter",22.890000,"mm"
"Inner diameter",8.000000,"mm"
"Outer diameter",10.000000,"mm"
"Wall thickness",1.000000,"mm"
"Area",4.115110,"cm^2"
"Linear density",100.000000,"tex"
"Sled weight",10.000000,"N"
"Loading span",10.000000,"mm"
"Support span",100.000000,"mm"
"Span ratio","2"
"Fixture type","4-point"
"Included"
"Final width",50.000000,"mm"
"Final thickness",50.000000,"mm"
"Final anvil height",50.000000,"mm"
"Final diameter",1.000000,"mm"
"Final Inner diameter",0.000000,"mm"
"Final outer diameter",1.000000,"mm"
"Final wall thickness",0.500000,"mm"
"Final area",0.007854,"cm^2"
"Final linear density",1.000000,"tex"
"Operator ID","George"
"Company","ABC"
"Laboratory Name","Zyx"
"Comment",""
"Custom text input  5",""
"Custom text input  6",""
"Custom text input  7",""
"Custom text input  8",""
"Custom text input  9",""
"Custom text input 10",""
"Custom text input 11",""
"Custom text input 12",""
"Custom text input 13",""
"Custom text input 14",""
"Custom text input 15",""
"Custom text input 16",""
"Custom text input 17",""
"Custom text input 18",""
"Custom text input 19",""
"Custom text input 20",""
"Custom text input 21",""
"Custom text input 22",""
"Custom text input 23",""
"Custom text input 24",""
"Custom text input 25",""
"Custom text input 26",""
"Custom text input 27",""
"Custom text input 28",""
"Custom text input 29",""
"Custom text input 30",""
"Custom text input 31",""
"Custom text input 32",""
"Custom text input 33",""
"Custom text input 34",""
"Custom text input 35",""
"Custom text input 36",""
"Custom text input 37",""
"Custom text input 38",""
"Custom text input 39",""
"Custom text input 40",""
"Custom text input 41",""
"Custom text input 42",""
"Custom text input 43",""
"Custom text input 44",""
"Custom text input 45",""
"Custom text input 46",""
"Custom text input 47",""
"Custom text input 48",""
"Custom text input 49",""
"Custom text input 50",""
"Temperature (deg C)",18.000000,""
"Humidity (%)",50.000000,""
"Custom number input  3",0.000000,""
"Custom number input  4",0.000000,""
"Custom number input  5",0.000000,""
"Custom number input  6",0.000000,""
"Custom number input  7",0.000000,""
"Custom number input  8",0.000000,""
"Custom number input  9",0.000000,""
"Custom number input 10",0.000000,""
"Time sec","Extension mm","Load kgf","Compressive stress MPa","Cycle Count ","Total Cycle Count ","Repetitions Count ","Marked Data ","PIP Count ","Compressive extension mm","Compressive strain %","Compressive load kgf","Displacement (Strain 1) mm","True strain %","Corrected Position mm","True stress Pa"
0,-0.000133333,-0.02556578,0.0006092539,0,0,0,0,0,0,0,0.02556578,0,0,-0.000133333,609.2539
0.2,-0.02413327,-0.02862625,0.0006821874,0,0,0,0,0,0.02399994,0.1059132,0.02862625,0,0.1059694,-0.02413327,681.4649
0.4,-0.06359984,-0.03395715,0.0008092271,0,0,0,0,0,0.06346651,0.2800817,0.03395715,0,0.2804747,-0.06359984,806.9606
0.6,-0.09933309,-0.03819726,0.0009102725,0,0,0,0,0,0.09919976,0.4377747,0.03819726,0,0.4387358,-0.09933309,906.2875
0.8,-0.133333,-0.0417818,0.0009956951,0,0,0,0,0,0.1331997,0.5878186,0.0417818,0,0.589553,-0.133333,989.8422
1,-0.1665329,-0.04505024,0.001073585,0,0,0,0,0,0.1663996,0.7343318,0.04505024,0,0.7370413,-0.1665329,1065.701
1.2,-0.1999995,-0.04849672,0.001155717,0,0,0,0,0,0.1998662,0.882022,0.04849672,0,0.8859348,-0.1999995,1145.524
1.4,-0.2334661,-0.0518637,0.001235955,0,0,0,0,0,0.2333328,1.029712,0.0518637,0,1.03505,-0.2334661,1223.228
1.6,-0.266666,-0.05508071,0.001312619,0,0,0,0,0,0.2665327,1.176226,0.05508071,0,1.183198,-0.266666,1297.18
1.8,-0.2999993,-0.0581847,0.00138659,0,0,0,0,0,0.2998659,1.323327,0.05818469,0,1.332161,-0.2999993,1368.241
2,-0.3334659,-0.06142258,0.001463751,0,0,0,0,0,0.3333325,1.471017,0.06142258,0,1.481944,-0.3334659,1442.219
2.2,-0.3669325,-0.06470456,0.001541964,0,0,0,0,0,0.3667991,1.618708,0.06470456,0,1.631952,-0.3669325,1517.004
2.4,-0.4002657,-0.06800303,0.001620569,0,0,0,0,0,0.4001323,1.765809,0.06800304,0,1.781585,-0.4002657,1591.953
2.6,-0.4335989,-0.07138861,0.00170125,0,0,0,0,0,0.4334656,1.912911,0.07138862,0,1.931444,-0.4335989,1668.707
2.8,-0.4666655,-0.07461832,0.001778217,0,0,0,0,0,0.4665322,2.058836,0.07461832,0,2.080325,-0.4666655,1741.606
3,-0.5001321,-0.07795549,0.001857744,0,0,0,0,0,0.4999987,2.206526,0.07795548,0,2.231234,-0.5001321,1816.753
3.2,-0.5335987,-0.08109611,0.001932588,0,0,0,0,0,0.5334653,2.354216,0.08109611,0,2.38237,-0.5335987,1887.091
3.4,-0.5667986,-0.08441577,0.002011698,0,0,0,0,0,0.5666652,2.500729,0.08441577,0,2.532529,-0.5667986,1961.391
3.6,-0.6001319,-0.08763357,0.002088381,0,0,0,0,0,0.5999986,2.647831,0.08763357,0,2.683518,-0.6001319,2033.084
3.8,-0.6335985,-0.09132422,0.002176332,0,0,0,0,0,0.6334652,2.795521,0.09132422,0,2.83534,-0.6335985,2115.492
4,-0.6671984,-0.09464305,0.002255423,0,0,0,0,0,0.6670651,2.9438,0.09464305,0,2.987999,-0.6671984,2189.028
4.2,-0.7001316,-0.09756646,0.00232509,0,0,0,0,0,0.6999983,3.089136,0.09756646,0,3.137856,-0.7001316,2253.265
4.4,-0.7333315,-0.1007724,0.00240149,0,0,0,0,0,0.7331982,3.23565,0.1007724,0,3.289154,-0.7333315,2323.786
4.6,-0.7669315,-0.1040321,0.002479171,0,0,0,0,0,0.7667981,3.383928,0.1040321,0,3.442508,-0.7669315,2395.278
4.8,-0.8001314,-0.1071833,0.002554267,0,0,0,0,0,0.799998,3.530441,0.1071833,0,3.594268,-0.8001314,2464.09
5,-0.8333313,-0.1103671,0.002630139,0,0,0,0,0,0.833198,3.676955,0.1103671,0,3.746259,-0.8333313,2533.431
5.2,-0.8666646,-0.113539,0.00270573,0,0,0,0,0,0.8665312,3.824057,0.113539,0,3.899093,-0.8666646,2602.261
5.4,-0.9002645,-0.116731,0.002781796,0,0,0,0,0,0.9001311,3.972335,0.116731,0,4.053386,-0.9002645,2671.294
5.6,-0.933731,-0.1198836,0.002856925,0,0,0,0,0,0.9335977,4.120025,0.1198836,0,4.207304,-0.933731,2739.219
5.8,-0.966931,-0.1231141,0.002933912,0,0,0,0,0,0.9667976,4.266539,0.1231141,0,4.36023,-0.966931,2808.736
6,-0.9999976,-0.1261691,0.003006716,0,0,0,0,0,0.9998643,4.412464,0.1261691,0,4.512775,-0.9999976,2874.045
6.2,-1.033464,-0.1293272,0.003081974,0,0,0,0,0,1.033331,4.560154,0.1293272,0,4.667402,-1.033464,2941.431
6.4,-1.066797,-0.1324275,0.003155858,0,0,0,0,0,1.066664,4.707255,0.1324275,0,4.821651,-1.066797,3007.304
6.6,-1.100131,-0.1353668,0.003225904,0,0,0,0,0,1.099997,4.854357,0.1353668,0,4.976138,-1.100131,3069.307
6.8,-1.133331,-0.1383977,0.003298132,0,0,0,0,0,1.133197,5.000871,0.1383977,0,5.130246,-1.133331,3133.196
7,-1.166931,-0.1414914,0.003371859,0,0,0,0,0,1.166797,5.149149,0.1414914,0,5.286452,-1.166931,3198.237
7.2,-1.200397,-0.144428,0.003441839,0,0,0,0,0,1.200264,5.296839,0.144428,0,5.44228,-1.200397,3259.53
7.4,-1.233464,-0.1473044,0.003510387,0,0,0,0,0,1.23333,5.442764,0.1473044,0,5.596486,-1.233464,3319.325
7.6,-1.266664,-0.1501442,0.003578061,0,0,0,0,0,1.26653,5.589277,0.1501442,0,5.751553,-1.266664,3378.073
7.8,-1.30013,-0.1529298,0.003644445,0,0,0,0,0,1.299997,5.736968,0.1529298,0,5.908109,-1.30013,3435.364
8,-1.333463,-0.1555585,0.003707088,0,0,0,0,0,1.33333,5.884069,0.1555585,0,6.064286,-1.333463,3488.96
8.200001,-1.366663,-0.1581722,0.003769375,0,0,0,0,0,1.36653,6.030583,0.1581722,0,6.220081,-1.366663,3542.059
8.400001,-1.399997,-0.1605811,0.003826782,0,0,0,0,0,1.399863,6.177684,0.1605811,0,6.376745,-1.399997,3590.376
8.6,-1.433463,-0.1636383,0.003899637,0,0,0,0,0,1.43333,6.325375,0.1636383,0,6.534284,-1.433463,3652.97
8.8,-1.467063,-0.1661688,0.00395994,0,0,0,0,0,1.46693,6.473653,0.1661688,0,6.6927,-1.467063,3703.587
9,-1.500396,-0.1691027,0.004029859,0,0,0,0,0,1.500263,6.620754,0.1691027,0,6.850107,-1.500396,3763.052
9.200001,-1.53333,-0.171637,0.004090254,0,0,0,0,0,1.533196,6.766091,0.171637,0,7.00587,-1.53333,3813.503
9.400001,-1.566796,-0.1741355,0.004149795,0,0,0,0,0,1.566663,6.913782,0.1741355,0,7.164404,-1.566796,3862.887
9.6,-1.600263,-0.176812,0.004213577,0,0,0,0,0,1.600129,7.061471,0.176812,0,7.323189,-1.600263,3916.037
9.8,-1.633463,-0.1793374,0.004273759,0,0,0,0,0,1.633329,7.207985,0.1793374,0,7.48096,-1.633463,3965.707
10,-1.666663,-0.1818534,0.004333718,0,0,0,0,0,1.666529,7.354498,0.1818534,0,7.638979,-1.666663,4014.995
10.2,-1.700263,-0.1845074,0.004396966,0,0,0,0,0,1.700129,7.502777,0.1845074,0,7.799156,-1.700263,4067.071
10.4,-1.733729,-0.1870233,0.00445692,0,0,0,0,0,1.733596,7.650467,0.1870233,0,7.958954,-1.733729,4115.945
10.6,-1.766796,-0.1894854,0.004515594,0,0,0,0,0,1.766662,7.796391,0.1894854,0,8.117092,-1.766796,4163.541
10.8,-1.799996,-0.1920507,0.004576728,0,0,0,0,0,1.799862,7.942905,0.1920507,0,8.27612,-1.799996,4213.203
11,-1.833596,-0.1945524,0.004636346,0,0,0,0,0,1.833462,8.091184,0.1945524,0,8.437323,-1.833596,4261.211
11.2,-1.866795,-0.1969194,0.004692753,0,0,0,0,0,1.866662,8.237697,0.1969194,0,8.596861,-1.866795,4306.178
11.4,-1.899995,-0.1993568,0.004750839,0,0,0,0,0,1.899862,8.384211,0.1993568,0,8.756655,-1.899995,4352.519
11.6,-1.933462,-0.2017522,0.004807924,0,0,0,0,0,1.933329,8.5319,0.2017522,0,8.917991,-1.933462,4397.717
11.8,-1.966795,-0.2040557,0.004862817,0,0,0,0,0,1.966662,8.679002,0.2040557,0,9.078943,-1.966795,4440.774
12,-2.000262,-0.206447,0.004919804,0,0,0,0,0,2.000129,8.826693,0.206447,0,9.240802,-2.000262,4485.548
12.2,-2.033462,-0.2086314,0.00497186,0,0,0,0,0,2.033328,8.973206,0.2086314,0,9.401628,-2.033462,4525.725
12.4,-2.066662,-0.2107442,0.005022209,0,0,0,0,0,2.066528,9.119719,0.2107442,0,9.562713,-2.066662,4564.197
12.6,-2.100128,-0.2127852,0.005070847,0,0,0,0,0,2.099995,9.267409,0.2127852,0,9.725357,-2.100128,4600.911
12.8,-2.133595,-0.2148803,0.005120775,0,0,0,0,0,2.133461,9.415099,0.2148803,0,9.888264,-2.133595,4638.649
13,-2.166795,-0.2168693,0.005168176,0,0,0,0,0,2.166662,9.561613,0.2168693,0,10.05014,-2.166795,4674.015
13.2,-2.200128,-0.218966,0.005218143,0,0,0,0,0,2.199995,9.708714,0.218966,0,10.21292,-2.200128,4711.528
13.4,-2.233595,-0.2210316,0.005267367,0,0,0,0,0,2.233461,9.856404,0.2210316,0,10.37663,-2.233595,4748.194
13.6,-2.267061,-0.223094,0.005316515,0,0,0,0,0,2.266928,10.0041,0.223094,0,10.5406,-2.267061,4784.646
13.8,-2.299994,-0.2250254,0.005362542,0,0,0,0,0,2.299861,10.14943,0.2250254,0,10.70222,-2.299994,4818.275
14,-2.333194,-0.2270198,0.005410071,0,0,0,0,0,2.333061,10.29594,0.2270198,0,10.86542,-2.333194,4853.053
14.2,-2.366928,-0.2291779,0.0054615,0,0,0,0,0,2.366794,10.44481,0.2291779,0,11.03151,-2.366928,4891.057
14.4,-2.399994,-0.2310195,0.005505386,0,0,0,0,0,2.399861,10.59074,0.2310195,0,11.19459,-2.399994,4922.325
14.6,-2.433327,-0.2328388,0.005548743,0,0,0,0,0,2.433194,10.73784,0.2328388,0,11.35925,-2.433327,4952.928
14.8,-2.466794,-0.2345489,0.005589496,0,0,0,0,0,2.466661,10.88553,0.2345489,0,11.52484,-2.466794,4981.05
15,-2.50026,-0.2365095,0.005636218,0,0,0,0,0,2.500127,11.03322,0.2365095,0,11.69071,-2.50026,5014.362
15.2,-2.533594,-0.2382858,0.005678549,0,0,0,0,0,2.533461,11.18032,0.2382858,0,11.85619,-2.533594,5043.669
15.4,-2.566927,-0.2398275,0.00571529,0,0,0,0,0,2.566794,11.32742,0.2398275,0,12.02195,-2.566927,5067.894
15.6,-2.599994,-0.2415837,0.005757142,0,0,0,0,0,2.59986,11.47335,0.2415837,0,12.18665,-2.599994,5096.605
15.8,-2.633327,-0.2431043,0.005793378,0,0,0,0,0,2.633193,11.62045,0.2431043,0,12.35296,-2.633327,5120.162
16,-2.66706,-0.2447247,0.005831994,0,0,0,0,0,2.666927,11.76931,0.2447247,0,12.52154,-2.66706,5145.608
16.2,-2.70026,-0.2464286,0.005872598,0,0,0,0,0,2.700127,11.91583,0.2464286,0,12.68773,-2.70026,5172.829
16.4,-2.73346,-0.2474315,0.005896498,0,0,0,0,0,2.733326,12.06234,0.2474315,0,12.8542,-2.73346,5185.243
16.6,-2.766927,-0.2489719,0.005933207,0,0,0,0,0,2.766793,12.21003,0.2489719,0,13.02229,-2.766927,5208.761
16.8,-2.800393,-0.2505417,0.005970617,0,0,0,0,0,2.80026,12.35772,0.2505417,0,13.19067,-2.800393,5232.785
17,-2.833326,-0.2516945,0.005998089,0,0,0,0,0,2.833193,12.50306,0.2516945,0,13.35663,-2.833326,5248.144
17.2,-2.86666,-0.2531213,0.006032092,0,0,0,0,0,2.866526,12.65016,0.2531213,0,13.5249,-2.86666,5269.023
17.4,-2.900126,-0.2546571,0.006068692,0,0,0,0,0,2.899993,12.79785,0.2546571,0,13.69412,-2.900126,5292.03
17.6,-2.933326,-0.2559571,0.00609967,0,0,0,0,0,2.933193,12.94436,0.2559571,0,13.86228,-2.933326,5310.107
17.8,-2.966526,-0.25717,0.006128575,0,0,0,0,0,2.966393,13.09088,0.25717,0,14.03072,-2.966526,5326.291
18,-3.000126,-0.258566,0.006161842,0,0,0,0,0,2.999993,13.23916,0.258566,0,14.20148,-3.000126,5346.066
18.2,-3.033593,-0.2597806,0.006190788,0,0,0,0,0,3.033459,13.38685,0.2597806,0,14.37185,-3.033593,5362.037
18.4,-3.066926,-0.2612455,0.006225698,0,0,0,0,0,3.066792,13.53395,0.2612455,0,14.54183,-3.066926,5383.115
18.6,-3.100259,-0.262445,0.006254283,0,0,0,0,0,3.100126,13.68105,0.262445,0,14.7121,-3.100259,5398.631
18.8,-3.133326,-0.2635136,0.006279747,0,0,0,0,0,3.133192,13.82697,0.2635136,0,14.8813,-3.133326,5411.449
19,-3.166792,-0.2647933,0.006310244,0,0,0,0,0,3.166659,13.97466,0.2647932,0,15.05283,-3.166792,5428.408
19.2,-3.200259,-0.2660185,0.006339443,0,0,0,0,0,3.200126,14.12235,0.2660185,0,15.22466,-3.200259,5444.165
19.4,-3.233459,-0.2672006,0.006367613,0,0,0,0,0,3.233326,14.26887,0.2672006,0,15.39542,-3.233459,5459.026
19.6,-3.266792,-0.2683435,0.006394849,0,0,0,0,0,3.266659,14.41597,0.2683435,0,15.56715,-3.266792,5472.969
19.8,-3.300259,-0.2693461,0.006418742,0,0,0,0,0,3.300125,14.56366,0.2693461,0,15.73986,-3.300259,5483.938
20,-3.333858,-0.2704534,0.00644513,0,0,0,0,0,3.333725,14.71194,0.2704534,0,15.91357,-3.333858,5496.926
20.2,-3.366658,-0.2711978,0.00646287,0,0,0,0,0,3.366525,14.85669,0.2711978,0,16.08343,-3.366658,5502.702
20.4,-3.399858,-0.2722353,0.006487594,0,0,0,0,0,3.399725,15.0032,0.2722353,0,16.25566,-3.399858,5514.247
20.6,-3.433458,-0.2733959,0.006515252,0,0,0,0,0,3.433325,15.15148,0.2733959,0,16.43026,-3.433458,5528.095
20.8,-3.466791,-0.274026,0.006530269,0,0,0,0,0,3.466658,15.29858,0.274026,0,16.60378,-3.466791,5531.23
21,-3.499991,-0.2750664,0.006555061,0,0,0,0,0,3.499858,15.44509,0.2750664,0,16.77691,-3.499991,5542.626
21.2,-3.533458,-0.2762186,0.006582519,0,0,0,0,0,3.533325,15.59278,0.2762186,0,16.95173,-3.533458,5556.121
21.4,-3.566925,-0.2772909,0.006608073,0,0,0,0,0,3.566791,15.74047,0.2772909,0,17.12685,-3.566925,5567.931
21.6,-3.600258,-0.2778479,0.006621348,0,0,0,0,0,3.600125,15.88758,0.2778479,0,17.30159,-3.600258,5569.376
21.8,-3.633591,-0.278899,0.006646395,0,0,0,0,0,3.633458,16.03468,0.278899,0,17.47663,-3.633591,5580.667
22,-3.666658,-0.2797103,0.00666573,0,0,0,0,0,3.666524,16.1806,0.2797103,0,17.65057,-3.666658,5587.175
22.2,-3.699991,-0.2809881,0.006696181,0,0,0,0,0,3.699857,16.3277,0.2809881,0,17.82622,-3.699991,5602.849
22.4,-3.733591,-0.281487,0.006708069,0,0,0,0,0,3.733458,16.47598,0.281487,0,18.0036,-3.733591,5602.849
22.6,-3.766924,-0.2825341,0.006733024,0,0,0,0,0,3.766791,16.62308,0.2825341,0,18.17987,-3.766924,5613.787
22.8,-3.800124,-0.2833741,0.006753041,0,0,0,0,0,3.79999,16.7696,0.2833741,0,18.35575,-3.800124,5620.583
23,-3.833724,-0.2841439,0.006771385,0,0,0,0,0,3.833591,16.91788,0.2841439,0,18.53406,-3.833724,5625.811
23.2,-3.867057,-0.2849831,0.006791384,0,0,0,0,0,3.866924,17.06498,0.2849831,0,18.71128,-3.867057,5632.436
23.4,-3.89999,-0.2856281,0.006806756,0,0,0,0,0,3.899857,17.21031,0.2856281,0,18.88667,-3.89999,5635.292
23.6,-3.93319,-0.2860077,0.006815802,0,0,0,0,0,3.933057,17.35683,0.2860077,0,19.0638,-3.93319,5632.795
23.8,-3.966924,-0.286849,0.006835851,0,0,0,0,0,3.966791,17.5057,0.286849,0,19.24409,-3.966924,5639.188
24,-4.000124,-0.2875546,0.006852665,0,0,0,0,0,3.99999,17.65221,0.2875546,0,19.42185,-4.000124,5643.019
24.2,-4.033323,-0.2877216,0.006856645,0,0,0,0,0,4.03319,17.79872,0.2877216,0,19.59993,-4.033323,5636.249
24.4,-4.06679,-0.2884908,0.006874977,0,0,0,0,0,4.066657,17.94641,0.2884908,0,19.77976,-4.06679,5641.165
24.6,-4.100257,-0.288988,0.006886824,0,0,0,0,0,4.100123,18.0941,0.288988,0,19.95992,-4.100257,5640.716
24.8,-4.133723,-0.2892646,0.006893416,0,0,0,0,0,4.13359,18.24179,0.2892646,0,20.1404,-4.133723,5635.934
25,-4.166923,-0.2897401,0.006904747,0,0,0,0,0,4.16679,18.38831,0.2897401,0,20.31976,-4.166923,5635.081
25.2,-4.199856,-0.2903698,0.006919754,0,0,0,0,0,4.199723,18.53364,0.2903698,0,20.498,-4.199856,5637.272
25.4,-4.233456,-0.2903994,0.006920459,0,0,0,0,0,4.233323,18.68192,0.2903994,0,20.68018,-4.233456,5627.585
25.6,-4.266923,-0.2905519,0.006924093,0,0,0,0,0,4.266789,18.82961,0.2905519,0,20.86196,-4.266923,5620.313
25.8,-4.300123,-0.2910955,0.006937049,0,0,0,0,0,4.299989,18.97612,0.2910955,0,21.04263,-4.300123,5620.666
26,-4.333456,-0.291075,0.006936559,0,0,0,0,0,4.333323,19.12322,0.291075,0,21.22435,-4.333456,5610.065
26.2,-4.367056,-0.2913739,0.006943681,0,0,0,0,0,4.366923,19.27151,0.2913738,0,21.40786,-4.367056,5605.53
26.4,-4.400389,-0.2915952,0.006948957,0,0,0,0,0,4.400256,19.41861,0.2915953,0,21.59024,-4.400389,5599.567
26.6,-4.433323,-0.2913678,0.006943537,0,0,0,0,0,4.433189,19.56394,0.2913678,0,21.77076,-4.433323,5585.108
26.8,-4.466522,-0.2917579,0.006952833,0,0,0,0,0,4.466389,19.71045,0.2917579,0,21.95308,-4.466522,5582.398
27,-4.500256,-0.2917371,0.006952337,0,0,0,0,0,4.500123,19.85932,0.2917371,0,22.13866,-4.500256,5571.65
27.2,-4.533323,-0.2918813,0.006955775,0,0,0,0,0,4.533189,20.00525,0.2918813,0,22.32091,-4.533323,5564.255
27.4,-4.566655,-0.2921057,0.006961123,0,0,0,0,0,4.566522,20.15235,0.2921057,0,22.50497,-4.566655,5558.293
27.6,-4.599989,-0.2917662,0.006953032,0,0,0,0,0,4.599856,20.29945,0.2917662,0,22.68937,-4.599989,5541.604
27.8,-4.633589,-0.2919328,0.006957001,0,0,0,0,0,4.633456,20.44773,0.2919328,0,22.87559,-4.633589,5534.452
28,-4.667055,-0.2920043,0.006958707,0,0,0,0,0,4.666922,20.59542,0.2920043,0,23.06141,-4.667055,5525.532
28.2,-4.700122,-0.2917293,0.006952153,0,0,0,0,0,4.699989,20.74134,0.2917293,0,23.24536,-4.700122,5510.183
28.4,-4.733455,-0.291757,0.006952811,0,0,0,0,0,4.733322,20.88845,0.291757,0,23.43113,-4.733455,5500.477
28.6,-4.766655,-0.2915271,0.006947333,0,0,0,0,0,4.766522,21.03496,0.2915271,0,23.6165,-4.766655,5485.965
28.8,-4.800255,-0.2912441,0.00694059,0,0,0,0,0,4.800121,21.18324,0.2912441,0,23.80445,-4.800255,5470.348
29,-4.833455,-0.2908579,0.006931385,0,0,0,0,0,4.833322,21.32975,0.2908579,0,23.99051,-4.833455,5452.938
29.2,-4.866655,-0.2901074,0.006913501,0,0,0,0,0,4.866522,21.47626,0.2901074,0,24.17693,-4.866655,5428.739
29.4,-4.900255,-0.2891306,0.006890223,0,0,0,0,0,4.900121,21.62454,0.2891306,0,24.36593,-4.900255,5400.244
29.6,-4.933721,-0.289672,0.006903125,0,0,0,0,0,4.933588,21.77223,0.289672,0,24.55455,-4.933721,5400.161
29.8,-4.966788,-0.2899012,0.006908587,0,0,0,0,0,4.966654,21.91816,0.2899012,0,24.74126,-4.966788,5394.352
30,-4.999988,-0.2897412,0.006904773,0,0,0,0,0,4.999854,22.06467,0.2897412,0,24.92908,-4.999988,5381.258
30.2,-5.033454,-0.2898093,0.006906397,0,0,0,0,0,5.033321,22.21236,0.2898093,0,25.11876,-5.033454,5372.323
30.4,-5.066788,-0.289648,0.006902553,0,0,0,0,0,5.066655,22.35946,0.289648,0,25.30805,-5.066788,5359.179
30.6,-5.099988,-0.2893691,0.006895907,0,0,0,0,0,5.099854,22.50598,0.2893691,0,25.49694,-5.099988,5343.916
30.8,-5.133454,-0.2894532,0.006897911,0,0,0,0,0,5.133321,22.65367,0.2894532,0,25.6877,-5.133454,5335.281
31,-5.166921,-0.289353,0.006895522,0,0,0,0,0,5.166788,22.80136,0.289353,0,25.87883,-5.166921,5323.249
31.2,-5.200254,-0.2889605,0.006886168,0,0,0,0,0,5.20012,22.94846,0.2889605,0,26.06956,-5.200254,5305.899
31.4,-5.233454,-0.288776,0.006881773,0,0,0,0,0,5.233321,23.09497,0.288776,0,26.25989,-5.233454,5292.43
31.6,-5.266521,-0.2884749,0.006874598,0,0,0,0,0,5.266387,23.2409,0.2884749,0,26.44982,-5.266521,5276.879
31.8,-5.30012,-0.2884694,0.006874465,0,0,0,0,0,5.299987,23.38918,0.2884694,0,26.64318,-5.30012,5266.584
32,-5.333587,-0.2881627,0.006867156,0,0,0,0,0,5.333454,23.53687,0.2881627,0,26.83615,-5.333587,5250.843
32.2,-5.366787,-0.2881204,0.00686615,0,0,0,0,0,5.366653,23.68338,0.2881204,0,27.02794,-5.366787,5240.013
32.4,-5.40012,-0.2881835,0.006867654,0,0,0,0,0,5.399987,23.83048,0.2881835,0,27.22088,-5.40012,5231.059
32.6,-5.433587,-0.2882303,0.006868767,0,0,0,0,0,5.433453,23.97817,0.2882303,0,27.41496,-5.433587,5221.762
32.8,-5.467054,-0.2883725,0.006872157,0,0,0,0,0,5.46692,24.12586,0.2883725,0,27.60943,-5.467054,5214.19
33,-5.50012,-0.2879651,0.006862448,0,0,0,0,0,5.499987,24.27179,0.2879651,0,27.80194,-5.50012,5196.809
33.2,-5.53332,-0.2875872,0.006853442,0,0,0,0,0,5.533187,24.4183,0.2875872,0,27.9956,-5.53332,5179.948
33.4,-5.56692,-0.2874685,0.006850615,0,0,0,0,0,5.566786,24.56658,0.2874685,0,28.19197,-5.56692,5167.653
33.6,-5.599986,-0.2868828,0.006836656,0,0,0,0,0,5.599853,24.7125,0.2868828,0,28.38561,-5.599986,5147.147
33.8,-5.63332,-0.2866017,0.006829956,0,0,0,0,0,5.633186,24.8596,0.2866017,0,28.58119,-5.63332,5132.056
34,-5.666786,-0.2866945,0.006832169,0,0,0,0,0,5.666653,25.0073,0.2866945,0,28.77794,-5.666786,5123.628
34.2,-5.700253,-0.2861936,0.006820233,0,0,0,0,0,5.70012,25.15499,0.2861936,0,28.97507,-5.700253,5104.604
34.4,-5.73372,-0.2867653,0.006833856,0,0,0,0,0,5.733586,25.30268,0.2867653,0,29.17259,-5.73372,5104.707
34.6,-5.766919,-0.2870036,0.006839535,0,0,0,0,0,5.766786,25.44919,0.2870036,0,29.36893,-5.766919,5098.929
34.8,-5.799852,-0.2869621,0.006838545,0,0,0,0,0,5.799719,25.59452,0.2869621,0,29.56406,-5.799852,5088.252
35,-5.833453,-0.2870791,0.006841335,0,0,0,0,0,5.833319,25.7428,0.2870792,0,29.76355,-5.833453,5080.184
35.2,-5.866919,-0.2875028,0.00685143,0,0,0,0,0,5.866786,25.89049,0.2875028,0,29.96264,-5.866919,5077.561
35.4,-5.900119,-0.2877769,0.006857964,0,0,0,0,0,5.899986,26.03701,0.2877769,0,30.16053,-5.900119,5072.355
35.6,-5.933319,-0.2879548,0.006862202,0,0,0,0,0,5.933186,26.18352,0.2879548,0,30.35882,-5.933319,5065.436
35.8,-5.966919,-0.288521,0.006875696,0,0,0,0,0,5.966785,26.3318,0.288521,0,30.55989,-5.966919,5065.201
36,-6.000519,-0.2884207,0.006873306,0,0,0,0,0,6.000386,26.48008,0.2884207,0,30.76138,-6.000519,5053.249
36.2,-6.033319,-0.2893968,0.006896566,0,0,0,0,0,6.033185,26.62482,0.2893968,0,30.95845,-6.033319,5060.367
36.4,-6.066652,-0.2887351,0.006880797,0,0,0,0,0,6.066519,26.77193,0.2887351,0,31.15913,-6.066652,5038.675
36.6,-6.100119,-0.2886633,0.006879087,0,0,0,0,0,6.099985,26.91962,0.2886633,0,31.36102,-6.100119,5027.263
36.8,-6.133452,-0.2892692,0.006893525,0,0,0,0,0,6.133318,27.06672,0.2892692,0,31.56251,-6.133452,5027.674
37,-6.166652,-0.2891059,0.006889634,0,0,0,0,0,6.166518,27.21323,0.2891059,0,31.7636,-6.166652,5014.742
37.2,-6.199985,-0.2889128,0.006885032,0,0,0,0,0,6.199851,27.36033,0.2889128,0,31.9659,-6.199985,5001.265
37.4,-6.233585,-0.2893427,0.006895279,0,0,0,0,0,6.233451,27.50861,0.2893427,0,32.17024,-6.233585,4998.483
37.6,-6.266918,-0.2899995,0.006910929,0,0,0,0,0,6.266785,27.65571,0.2899995,0,32.37337,-6.266918,4999.663
37.8,-6.300251,-0.2906142,0.006925578,0,0,0,0,0,6.300118,27.80282,0.2906142,0,32.57692,-6.300251,5000.072
38,-6.333318,-0.2912198,0.00694001,0,0,0,0,0,6.333185,27.94874,0.2912198,0,32.77924,-6.333318,5000.364
38.2,-6.366785,-0.2917468,0.006952568,0,0,0,0,0,6.366652,28.09643,0.2917468,0,32.98443,-6.366785,4999.145
38.4,-6.400251,-0.2921992,0.006963351,0,0,0,0,0,6.400118,28.24412,0.2921993,0,33.19004,-6.400251,4996.614
38.6,-6.433451,-0.2925194,0.006970981,0,0,0,0,0,6.433318,28.39063,0.2925194,0,33.39443,-6.433451,4991.875
38.8,-6.466784,-0.2929626,0.006981542,0,0,0,0,0,6.466651,28.53773,0.2929626,0,33.60006,-6.466784,4989.168
39,-6.500251,-0.2933085,0.006989786,0,0,0,0,0,6.500117,28.68542,0.2933085,0,33.80695,-6.500251,4984.737
39.2,-6.533717,-0.2935471,0.006995472,0,0,0,0,0,6.533584,28.83311,0.2935471,0,34.01426,-6.533717,4978.459
39.4,-6.566651,-0.293713,0.006999425,0,0,0,0,0,6.566517,28.97845,0.293713,0,34.21869,-6.566651,4971.099
39.6,-6.59985,-0.2940205,0.007006754,0,0,0,0,0,6.599717,29.12497,0.2940205,0,34.42519,-6.59985,4966.039
39.8,-6.63345,-0.2944809,0.007017726,0,0,0,0,0,6.633317,29.27324,0.2944809,0,34.63462,-6.63345,4963.41
40,-6.666784,-0.2945814,0.007020119,0,0,0,0,0,6.66665,29.42035,0.2945814,0,34.84282,-6.666784,4954.776
40.2,-6.69985,-0.2949986,0.007030062,0,0,0,0,0,6.699717,29.56627,0.2949986,0,35.04979,-6.69985,4951.535
40.4,-6.73345,-0.2952952,0.007037129,0,0,0,0,0,6.733316,29.71455,0.2952951,0,35.26053,-6.73345,4946.078
40.6,-6.766917,-0.2956805,0.007046312,0,0,0,0,0,6.766784,29.86224,0.2956805,0,35.47089,-6.766917,4942.125
40.8,-6.800383,-0.296167,0.007057906,0,0,0,0,0,6.80025,30.00993,0.296167,0,35.68168,-6.800383,4939.833
41,-6.833583,-0.2963922,0.007063273,0,0,0,0,0,6.83345,30.15644,0.2963922,0,35.89123,-6.833583,4933.241
41.2,-6.86665,-0.2962182,0.007059126,0,0,0,0,0,6.866516,30.30237,0.2962182,0,36.10038,-6.86665,4920.044
41.4,-6.900116,-0.2963421,0.007062078,0,0,0,0,0,6.899983,30.45006,0.2963421,0,36.31251,-6.900116,4911.672
41.6,-6.933583,-0.2959802,0.007053454,0,0,0,0,0,6.93345,30.59775,0.2959802,0,36.52509,-6.933583,4895.256
41.8,-6.966783,-0.2961079,0.007056498,0,0,0,0,0,6.96665,30.74426,0.2961079,0,36.73642,-6.966783,4887.03
42,-7.000116,-0.2960295,0.00705463,0,0,0,0,0,6.999983,30.89136,0.2960295,0,36.94905,-7.000116,4875.359
42.2,-7.033583,-0.2961294,0.00705701,0,0,0,0,0,7.03345,31.03905,0.2961294,0,37.16298,-7.033583,4866.581
42.4,-7.067049,-0.2962345,0.007059514,0,0,0,0,0,7.066916,31.18674,0.2962345,0,37.37738,-7.067049,4857.882
42.6,-7.100116,-0.2957629,0.007048275,0,0,0,0,0,7.099983,31.33267,0.2957629,0,37.58966,-7.100116,4839.862
42.8,-7.133316,-0.295601,0.007044417,0,0,0,0,0,7.133183,31.47918,0.295601,0,37.80326,-7.133316,4826.892
43,-7.166916,-0.2957904,0.007048931,0,0,0,0,0,7.166782,31.62746,0.2957904,0,38.01989,-7.166916,4819.533
43.2,-7.200116,-0.2958445,0.00705022,0,0,0,0,0,7.199982,31.77397,0.2958445,0,38.23441,-7.200116,4810.085
43.4,-7.233449,-0.2956998,0.007046773,0,0,0,0,0,7.233315,31.92107,0.2956998,0,38.45025,-7.233449,4797.367
43.6,-7.266649,-0.2955955,0.007044286,0,0,0,0,0,7.266515,32.06759,0.2955955,0,38.66569,-7.266649,4785.353
43.8,-7.300249,-0.295711,0.007047039,0,0,0,0,0,7.300115,32.21587,0.295711,0,38.8842,-7.300249,4776.774
44,-7.333715,-0.2957316,0.00704753,0,0,0,0,0,7.333582,32.36356,0.2957316,0,39.10232,-7.333715,4766.699
44.2,-7.366782,-0.2957616,0.007048246,0,0,0,0,0,7.366649,32.50948,0.2957616,0,39.31831,-7.366782,4756.898
44.4,-7.399849,-0.2957439,0.007047822,0,0,0,0,0,7.399715,32.65541,0.2957439,0,39.53476,-7.399849,4746.327
44.6,-7.433448,-0.2955784,0.00704388,0,0,0,0,0,7.433315,32.80368,0.2955784,0,39.75518,-7.433448,4733.228
44.8,-7.466915,-0.2956141,0.007044729,0,0,0,0,0,7.466782,32.95137,0.2956141,0,39.97521,-7.466915,4723.394
45,-7.500115,-0.2958486,0.00705032,0,0,0,0,0,7.499982,33.09789,0.2958486,0,40.19397,-7.500115,4716.813
45.2,-7.533448,-0.2957695,0.007048435,0,0,0,0,0,7.533315,33.24499,0.2957695,0,40.41409,-7.533448,4705.183
45.4,-7.567048,-0.295924,0.007052115,0,0,0,0,0,7.566915,33.39327,0.295924,0,40.63646,-7.567048,4697.183
45.6,-7.600515,-0.2962388,0.007059618,0,0,0,0,0,7.600381,33.54096,0.2962388,0,40.85843,-7.600515,4691.755
45.8,-7.633314,-0.2966448,0.007069293,0,0,0,0,0,7.633181,33.68571,0.2966448,0,41.07647,-7.633314,4687.952
46,-7.666781,-0.2972643,0.007084056,0,0,0,0,0,7.666648,33.8334,0.2972643,0,41.29943,-7.666781,4687.279
46.2,-7.700115,-0.2978483,0.007097973,0,0,0,0,0,7.699981,33.9805,0.2978483,0,41.522,-7.700115,4686.047
46.4,-7.733448,-0.2985284,0.00711418,0,0,0,0,0,7.733315,34.1276,0.2985284,0,41.74507,-7.733448,4686.281
46.6,-7.766648,-0.2987539,0.007119555,0,0,0,0,0,7.766515,34.27412,0.2987539,0,41.96774,-7.766648,4679.391
46.8,-7.800114,-0.2991603,0.007129239,0,0,0,0,0,7.799981,34.42181,0.2991603,0,42.19269,-7.800114,4675.226
47,-7.833715,-0.2997499,0.007143289,0,0,0,0,0,7.83358,34.57008,0.2997499,0,42.41906,-7.833715,4673.848
47.2,-7.866914,-0.3004246,0.007159369,0,0,0,0,0,7.866781,34.7166,0.3004246,0,42.64324,-7.866914,4673.879
47.4,-7.900247,-0.301216,0.007178228,0,0,0,0,0,7.900114,34.8637,0.301216,0,42.86882,-7.900247,4675.633
47.6,-7.933181,-0.302032,0.007197673,0,0,0,0,0,7.933048,35.00904,0.302032,0,43.09219,-7.933181,4677.837
47.8,-7.966781,-0.3031058,0.007223265,0,0,0,0,0,7.966648,35.15731,0.3031058,0,43.32061,-7.966781,4683.759
48,-8.00038,-0.3039845,0.007244204,0,0,0,0,0,8.000247,35.30559,0.3039845,0,43.54954,-8.00038,4686.595
48.2,-8.033447,-0.3047159,0.007261634,0,0,0,0,0,8.033314,35.45152,0.3047159,0,43.77536,-8.033447,4687.275
48.4,-8.066647,-0.3053374,0.007276445,0,0,0,0,0,8.066514,35.59803,0.3053374,0,44.0026,-8.066647,4686.174
48.6,-8.100247,-0.3059646,0.007291391,0,0,0,0,0,8.100113,35.74631,0.3059646,0,44.2331,-8.100247,4684.988
48.8,-8.133714,-0.3068297,0.007312007,0,0,0,0,0,8.133581,35.894,0.3068297,0,44.46323,-8.133714,4687.435
49,-8.166781,-0.3073802,0.007325127,0,0,0,0,0,8.166648,36.03993,0.3073803,0,44.69112,-8.166781,4685.157
49.2,-8.19998,-0.3081403,0.007343241,0,0,0,0,0,8.199847,36.18644,0.3081403,0,44.92045,-8.19998,4685.983
49.4,-8.23358,-0.3089351,0.00736218,0,0,0,0,0,8.233447,36.33472,0.3089351,0,45.15308,-8.23358,4687.153
49.6,-8.266646,-0.3094751,0.00737505,0,0,0,0,0,8.266513,36.48064,0.3094751,0,45.38255,-8.266646,4684.584
49.8,-8.300113,-0.3101776,0.007391791,0,0,0,0,0,8.29998,36.62833,0.3101776,0,45.61533,-8.300113,4684.301
50,-8.333446,-0.310953,0.00741027,0,0,0,0,0,8.333313,36.77543,0.3109531,0,45.84773,-8.333446,4685.111
50.2,-8.366914,-0.3121082,0.007437798,0,0,0,0,0,8.36678,36.92313,0.3121082,0,46.0816,-8.366914,4691.53
50.4,-8.40038,-0.313306,0.007466344,0,0,0,0,0,8.400247,37.07081,0.313306,0,46.31601,-8.40038,4698.509
50.6,-8.433713,-0.3141803,0.007487178,0,0,0,0,0,8.433579,37.21791,0.3141803,0,46.55004,-8.433713,4700.606
50.8,-8.466646,-0.3150179,0.007507139,0,0,0,0,0,8.466513,37.36325,0.3150179,0,46.78181,-8.466646,4702.228
51,-8.499979,-0.3155422,0.007519633,0,0,0,0,0,8.499846,37.51035,0.3155422,0,47.01693,-8.499979,4698.992
51.2,-8.533446,-0.3161655,0.007534486,0,0,0,0,0,8.533313,37.65804,0.3161654,0,47.25355,-8.533446,4697.146
51.4,-8.566779,-0.317251,0.007560356,0,0,0,0,0,8.566646,37.80515,0.317251,0,47.48979,-8.566779,4702.152
51.6,-8.599846,-0.3182251,0.00758357,0,0,0,0,0,8.599712,37.95107,0.3182251,0,47.72469,-8.599846,4705.524
51.8,-8.633579,-0.3195394,0.007614889,0,0,0,0,0,8.633446,38.09994,0.3195394,0,47.9649,-8.633579,4713.621
52,-8.667179,-0.3208294,0.007645632,0,0,0,0,0,8.667047,38.24822,0.3208294,0,48.20474,-8.667179,4721.314
52.2,-8.699979,-0.3219298,0.007671856,0,0,0,0,0,8.699845,38.39296,0.3219298,0,48.43941,-8.699979,4726.403
52.4,-8.733313,-0.3231607,0.007701188,0,0,0,0,0,8.733178,38.54007,0.3231607,0,48.67847,-8.733313,4733.145
52.6,-8.766912,-0.3244599,0.007732149,0,0,0,0,0,8.766779,38.68834,0.3244599,0,48.92002,-8.766912,4740.709
52.8,-8.800112,-0.32566,0.007760748,0,0,0,0,0,8.799978,38.83486,0.32566,0,49.15927,-8.800112,4746.873
53,-8.833311,-0.3266168,0.007783551,0,0,0,0,0,8.833179,38.98137,0.3266169,0,49.39909,-8.833311,4749.416
53.2,-8.866779,-0.3279581,0.007815515,0,0,0,0,0,8.866646,39.12906,0.3279581,0,49.64143,-8.866779,4757.377
53.4,-8.900245,-0.3293089,0.007847706,0,0,0,0,0,8.900111,39.27675,0.3293089,0,49.88435,-8.900245,4765.382
53.6,-8.933579,-0.3305001,0.007876093,0,0,0,0,0,8.933445,39.42385,0.3305001,0,50.1269,-8.933579,4771.033
53.8,-8.966912,-0.3317621,0.007906168,0,0,0,0,0,8.966779,39.57095,0.3317621,0,50.37003,-8.966912,4777.622
54,-8.999978,-0.3328309,0.007931639,0,0,0,0,0,8.999845,39.71688,0.3328309,0,50.61181,-8.999978,4781.439
54.2,-9.033444,-0.3340961,0.007961788,0,0,0,0,0,9.033311,39.86457,0.3340961,0,50.8571,-9.033444,4787.856
54.4,-9.066911,-0.3355716,0.00799695,0,0,0,0,0,9.066778,40.01226,0.3355716,0,51.103,-9.066911,4797.19
54.6,-9.100111,-0.336513,0.008019384,0,0,0,0,0,9.099978,40.15877,0.336513,0,51.34754,-9.100111,4798.898
54.8,-9.133444,-0.3374722,0.008042244,0,0,0,0,0,9.133311,40.30587,0.3374723,0,51.59366,-9.133444,4800.748
55,-9.167044,-0.3388502,0.008075084,0,0,0,0,0,9.166911,40.45415,0.3388503,0,51.84236,-9.167044,4808.377
55.2,-9.200377,-0.3403022,0.008109686,0,0,0,0,0,9.200244,40.60125,0.3403023,0,52.08971,-9.200377,4817.052
55.4,-9.233311,-0.3414118,0.008136126,0,0,0,0,0,9.233177,40.74659,0.3414117,0,52.33469,-9.233311,4820.932
55.6,-9.266511,-0.3426986,0.008166793,0,0,0,0,0,9.266377,40.8931,0.3426986,0,52.58226,-9.266511,4827.138
55.8,-9.300244,-0.3443019,0.008205,0,0,0,0,0,9.300111,41.04197,0.3443018,0,52.83444,-9.300244,4837.506
56,-9.333444,-0.3455853,0.008235587,0,0,0,0,0,9.333311,41.18848,0.3455853,0,53.08325,-9.333444,4843.473
56.2,-9.366644,-0.3469906,0.008269076,0,0,0,0,0,9.366509,41.335,0.3469906,0,53.33268,-9.366644,4851.054
56.4,-9.400111,-0.348018,0.00829356,0,0,0,0,0,9.399978,41.48269,0.348018,0,53.58476,-9.400111,4853.168
56.6,-9.433577,-0.3494099,0.008326729,0,0,0,0,0,9.433444,41.63038,0.3494099,0,53.83746,-9.433577,4860.28
56.8,-9.467044,-0.3510353,0.008365463,0,0,0,0,0,9.46691,41.77807,0.3510353,0,54.09081,-9.467044,4870.534
57,-9.500244,-0.3518862,0.008385742,0,0,0,0,0,9.500111,41.92458,0.3518862,0,54.34277,-9.500244,4870.055
57.2,-9.53331,-0.3531584,0.008416059,0,0,0,0,0,9.533177,42.07051,0.3531584,0,54.59436,-9.53331,4875.38
57.4,-9.566911,-0.3546077,0.008450596,0,0,0,0,0,9.566777,42.21879,0.3546077,0,54.85065,-9.566911,4882.857
57.6,-9.600244,-0.3558761,0.008480825,0,0,0,0,0,9.60011,42.36589,0.3558761,0,55.10556,-9.600244,4887.848
57.8,-9.633443,-0.3569192,0.008505682,0,0,0,0,0,9.63331,42.5124,0.3569192,0,55.36009,-9.633443,4889.713
58,-9.666776,-0.3579825,0.008531021,0,0,0,0,0,9.666643,42.6595,0.3579825,0,55.6163,-9.666776,4891.73
58.2,-9.700243,-0.358865,0.00855205,0,0,0,0,0,9.70011,42.80719,0.358865,0,55.87421,-9.700243,4891.158
58.4,-9.73371,-0.3597494,0.008573129,0,0,0,0,0,9.733576,42.95488,0.3597494,0,56.13276,-9.73371,4890.552
58.6,-9.766776,-0.3601814,0.008583422,0,0,0,0,0,9.766643,43.10081,0.3601814,0,56.3889,-9.766776,4883.898
58.8,-9.799976,-0.360837,0.008599047,0,0,0,0,0,9.799843,43.24732,0.360837,0,56.64673,-9.799976,4880.189
59,-9.833443,-0.3616891,0.008619352,0,0,0,0,0,9.83331,43.39501,0.3616891,0,56.90731,-9.833443,4878.983
59.2,-9.866643,-0.3624496,0.008637475,0,0,0,0,0,9.866508,43.54152,0.3624496,0,57.16647,-9.866643,4876.587
59.4,-9.899976,-0.3633201,0.00865822,0,0,0,0,0,9.899842,43.68863,0.3633201,0,57.42736,-9.899976,4875.563
59.6,-9.933443,-0.3641207,0.008677299,0,0,0,0,0,9.93331,43.83632,0.3641207,0,57.68999,-9.933443,4873.491
59.8,-9.966909,-0.3650309,0.00869899,0,0,0,0,0,9.966776,43.984,0.3650309,0,57.95329,-9.966909,4872.826
60,-10.00038,-0.3658689,0.008718959,0,0,0,0,0,10.00024,44.1317,0.3658689,0,58.2173,-10.00038,4871.135
60.2,-10.03358,-0.3667501,0.00873996,0,0,0,0,0,10.03344,44.27821,0.3667501,0,58.47989,-10.03358,4870.062
60.4,-10.06664,-0.3677604,0.008764036,0,0,0,0,0,10.06651,44.42414,0.3677604,0,58.74212,-10.06664,4870.689
60.6,-10.10011,-0.3690489,0.008794743,0,0,0,0,0,10.09998,44.57182,0.3690489,0,59.00821,-10.10011,4874.765
60.8,-10.13358,-0.3703101,0.008824798,0,0,0,0,0,10.13344,44.71952,0.3703101,0,59.27503,-10.13358,4878.391
61,-10.16678,-0.3716456,0.008856624,0,0,0,0,0,10.16664,44.86603,0.3716456,0,59.54041,-10.16678,4883.009
61.2,-10.20011,-0.3728427,0.008885151,0,0,0,0,0,10.19998,45.01313,0.3728427,0,59.80758,-10.20011,4885.667
61.4,-10.23358,-0.3742017,0.008917539,0,0,0,0,0,10.23344,45.16082,0.3742017,0,60.07652,-10.23358,4890.305
61.6,-10.26704,-0.3759402,0.008958968,0,0,0,0,0,10.26691,45.30851,0.3759402,0,60.34621,-10.26704,4899.793
61.8,-10.29998,-0.3769596,0.008983261,0,0,0,0,0,10.29984,45.45385,0.3769596,0,60.6123,-10.29998,4900.023
62,-10.33331,-0.3780059,0.009008195,0,0,0,0,0,10.33317,45.60095,0.3780059,0,60.88235,-10.33331,4900.373
62.2,-10.36678,-0.3793777,0.009040887,0,0,0,0,0,10.36664,45.74864,0.3793777,0,61.15421,-10.36678,4904.804
62.4,-10.39997,-0.3804059,0.009065389,0,0,0,0,0,10.39984,45.89515,0.3804059,0,61.42464,-10.39997,4904.815
62.6,-10.43331,-0.3815409,0.009092438,0,0,0,0,0,10.43318,46.04225,0.3815409,0,61.69689,-10.43331,4906.075
62.8,-10.46677,-0.3828381,0.009123351,0,0,0,0,0,10.46664,46.18995,0.3828381,0,61.97099,-10.46677,4909.28
63,-10.50024,-0.3841466,0.009154534,0,0,0,0,0,10.50011,46.33764,0.3841466,0,62.24583,-10.50024,4912.539
63.2,-10.53357,-0.3854746,0.009186181,0,0,0,0,0,10.53344,46.48473,0.3854746,0,62.52032,-10.53357,4916.009
63.4,-10.56691,-0.3862562,0.009204807,0,0,0,0,0,10.56677,46.63184,0.3862562,0,62.79559,-10.56691,4912.436
63.6,-10.59984,-0.3876837,0.009238825,0,0,0,0,0,10.59971,46.77717,0.3876837,0,63.06828,-10.59984,4917.164
63.8,-10.63357,-0.3892695,0.009276616,0,0,0,0,0,10.63344,46.92604,0.3892695,0,63.34838,-10.63357,4923.468
64,-10.66691,-0.3911817,0.009322185,0,0,0,0,0,10.66677,47.07314,0.3911817,0,63.62593,-10.66691,4933.939
64.2,-10.70011,-0.3926236,0.009356548,0,0,0,0,0,10.69997,47.21966,0.3926236,0,63.90314,-10.70011,4938.418
64.4,-10.73331,-0.3935089,0.009377644,0,0,0,0,0,10.73317,47.36617,0.3935089,0,64.18111,-10.73331,4935.813
64.60001,-10.76704,-0.395176,0.009417373,0,0,0,0,0,10.76691,47.51504,0.395176,0,64.46435,-10.76704,4942.705
64.8,-10.80037,-0.3966255,0.009451916,0,0,0,0,0,10.80024,47.66214,0.3966255,0,64.74501,-10.80037,4946.931
65,-10.83331,-0.3982395,0.009490378,0,0,0,0,0,10.83317,47.80748,0.3982395,0,65.02309,-10.83331,4953.268
65.2,-10.86664,-0.4000157,0.009532707,0,0,0,0,0,10.86651,47.95457,0.4000157,0,65.30533,-10.86664,4961.338
65.4,-10.90024,-0.4016622,0.009571943,0,0,0,0,0,10.90011,48.10286,0.4016621,0,65.59064,-10.90024,4967.565
65.60001,-10.93331,-0.4031568,0.009607564,0,0,0,0,0,10.93317,48.24878,0.4031568,0,65.87222,-10.93331,4972.031
65.8,-10.96664,-0.4044224,0.009637723,0,0,0,0,0,10.96651,48.39588,0.4044224,0,66.15687,-10.96664,4973.462
66,-11.00011,-0.4060392,0.009676253,0,0,0,0,0,10.99997,48.54357,0.4060392,0,66.44347,-11.00011,4979.055
66.20001,-11.03357,-0.4077999,0.009718212,0,0,0,0,0,11.03344,48.69126,0.4077999,0,66.73091,-11.03357,4986.292
66.4,-11.06704,-0.4094664,0.009757925,0,0,0,0,0,11.06691,48.83895,0.4094664,0,67.01917,-11.06704,4992.257
66.60001,-11.10024,-0.4109003,0.009792097,0,0,0,0,0,11.10011,48.98547,0.4109003,0,67.30596,-11.10024,4995.392
66.8,-11.13331,-0.4125103,0.009830465,0,0,0,0,0,11.13317,49.13139,0.4125103,0,67.59242,-11.13331,5000.62
67,-11.16677,-0.4143822,0.009875072,0,0,0,0,0,11.16664,49.27908,0.4143822,0,67.88317,-11.16677,5008.727
67.20001,-11.20024,-0.4161691,0.009917656,0,0,0,0,0,11.20011,49.42677,0.4161691,0,68.17478,-11.20024,5015.679
67.4,-11.23331,-0.4175913,0.009951548,0,0,0,0,0,11.23317,49.57269,0.4175913,0,68.46374,-11.23331,5018.297
67.60001,-11.26664,-0.4193979,0.0099946,0,0,0,0,0,11.26651,49.7198,0.4193979,0,68.75588,-11.26664,5025.305
67.8,-11.30024,-0.4211467,0.01003628,0,0,0,0,0,11.30011,49.86807,0.4211467,0,69.05121,-11.30024,5031.378
68,-11.33384,-0.4227468,0.01007441,0,0,0,0,0,11.33371,50.01635,0.4227468,0,69.34743,-11.33384,5035.556
68.20001,-11.36677,-0.4244439,0.01011485,0,0,0,0,0,11.36664,50.16169,0.424444,0,69.63863,-11.36677,5041.071
68.4,-11.39997,-0.4260127,0.01015224,0,0,0,0,0,11.39984,50.3082,0.4260127,0,69.93303,-11.39997,5044.829
68.60001,-11.43357,-0.4279805,0.01019913,0,0,0,0,0,11.43344,50.45648,0.4279805,0,70.23187,-11.43357,5053.008
68.8,-11.46664,-0.4296511,0.01023894,0,0,0,0,0,11.46651,50.60241,0.4296511,0,70.52685,-11.46664,5057.791
69,-11.49984,-0.4311518,0.01027471,0,0,0,0,0,11.49971,50.74892,0.4311518,0,70.82389,-11.49984,5060.404
69.20001,-11.53331,-0.4328388,0.01031491,0,0,0,0,0,11.53317,50.89661,0.4328388,0,71.12421,-11.53331,5064.97
69.4,-11.56677,-0.4347974,0.01036158,0,0,0,0,0,11.56664,51.0443,0.4347974,0,71.42543,-11.56677,5072.586
69.60001,-11.60024,-0.4367022,0.01040698,0,0,0,0,0,11.60011,51.19199,0.4367022,0,71.72758,-11.60024,5079.438
69.8,-11.63357,-0.4385393,0.01045076,0,0,0,0,0,11.63344,51.33909,0.4385393,0,72.02942,-11.63357,5085.433
70,-11.66677,-0.4406283,0.01050054,0,0,0,0,0,11.66664,51.48561,0.4406283,0,72.33097,-11.66677,5094.273
[...]
52.4,-8.733446,-0.2218658,0.005776077,0,0,0,0,0,8.733313,40.79081,0.2218658,0,52.40934,-8.733446,3419.968
52.6,-8.767045,-0.2231378,0.005809191,0,0,0,0,0,8.766912,40.94774,0.2231378,0,52.67474,-8.767045,3430.458
52.8,-8.800112,-0.2245007,0.005844673,0,0,0,0,0,8.799978,41.10219,0.2245007,0,52.93663,-8.800112,3442.384
53,-8.833579,-0.2257824,0.005878041,0,0,0,0,0,8.833446,41.2585,0.2257824,0,53.20238,-8.833579,3452.849
53.2,-8.867045,-0.2272927,0.005917361,0,0,0,0,0,8.866912,41.41481,0.2272927,0,53.46883,-8.867045,3466.697
53.4,-8.900245,-0.2287422,0.005955097,0,0,0,0,0,8.900111,41.56988,0.2287422,0,53.73387,-8.900245,3479.571
53.6,-8.933311,-0.2300136,0.005988197,0,0,0,0,0,8.933177,41.72432,0.2300136,0,53.99854,-8.933311,3489.662
53.8,-8.966512,-0.2314111,0.00602458,0,0,0,0,0,8.966378,41.87939,0.2314111,0,54.26499,-8.966512,3501.522
54,-9.000111,-0.2331152,0.006068945,0,0,0,0,0,8.999977,42.03633,0.2331152,0,54.53537,-9.000111,3517.784
54.2,-9.033311,-0.2344176,0.00610285,0,0,0,0,0,9.033178,42.19139,0.2344176,0,54.80326,-9.033311,3527.973
54.4,-9.066645,-0.2358087,0.006139068,0,0,0,0,0,9.066512,42.34709,0.2358087,0,55.07295,-9.066645,3539.351
54.6,-9.100244,-0.2371462,0.006173887,0,0,0,0,0,9.100111,42.50402,0.2371462,0,55.34552,-9.100244,3549.737
54.8,-9.133444,-0.2386393,0.00621276,0,0,0,0,0,9.133311,42.65909,0.2386393,0,55.61558,-9.133444,3562.453
55,-9.166911,-0.2402408,0.006254453,0,0,0,0,0,9.166778,42.8154,0.2402408,0,55.88856,-9.166911,3576.584
55.2,-9.200244,-0.2416319,0.006290668,0,0,0,0,0,9.200111,42.97109,0.2416319,0,56.16119,-9.200244,3587.499
55.4,-9.233178,-0.2432481,0.006332746,0,0,0,0,0,9.233045,43.12492,0.2432481,0,56.43128,-9.233178,3601.754
55.6,-9.266911,-0.2449784,0.006377791,0,0,0,0,0,9.266778,43.28247,0.2449784,0,56.70869,-9.266911,3617.325
55.8,-9.300244,-0.2466669,0.00642175,0,0,0,0,0,9.300111,43.43816,0.2466669,0,56.98357,-9.300244,3632.26
56,-9.333311,-0.2484779,0.006468899,0,0,0,0,0,9.333178,43.59261,0.2484779,0,57.257,-9.333311,3648.937
56.2,-9.366778,-0.2502952,0.006516209,0,0,0,0,0,9.366645,43.74892,0.2502952,0,57.5345,-9.366778,3665.438
56.4,-9.400377,-0.2522374,0.006566774,0,0,0,0,0,9.400244,43.90586,0.2522374,0,57.81388,-9.400377,3683.576
56.6,-9.43371,-0.2541916,0.006617649,0,0,0,0,0,9.433577,44.06155,0.2541915,0,58.09181,-9.43371,3701.81
56.8,-9.466777,-0.255754,0.006658326,0,0,0,0,0,9.466643,44.21599,0.2557541,0,58.36829,-9.466777,3714.282
57,-9.499977,-0.2577879,0.006711277,0,0,0,0,0,9.499845,44.37106,0.2577879,0,58.64666,-9.499977,3733.412
57.2,-9.533577,-0.2595207,0.006756387,0,0,0,0,0,9.533443,44.52799,0.2595207,0,58.92917,-9.533577,3747.903
57.4,-9.566776,-0.2610473,0.006796132,0,0,0,0,0,9.566644,44.68306,0.2610473,0,59.2091,-9.566776,3759.412
57.6,-9.60011,-0.2628123,0.006842081,0,0,0,0,0,9.599977,44.83875,0.2628123,0,59.49095,-9.60011,3774.177
57.8,-9.633443,-0.264376,0.00688279,0,0,0,0,0,9.63331,44.99444,0.264376,0,59.7736,-9.633443,3785.917
58,-9.666909,-0.2662025,0.006930342,0,0,0,0,0,9.666777,45.15075,0.2662025,0,60.05817,-9.666909,3801.241
58.2,-9.700377,-0.2679212,0.006975086,0,0,0,0,0,9.700243,45.30707,0.2679212,0,60.34357,-9.700377,3814.879
58.4,-9.733576,-0.2694806,0.007015684,0,0,0,0,0,9.733443,45.46214,0.2694806,0,60.6275,-9.733576,3826.204
58.6,-9.766643,-0.2712069,0.007060627,0,0,0,0,0,9.76651,45.61658,0.2712069,0,60.91109,-9.766643,3839.811
58.8,-9.800109,-0.2729295,0.007105473,0,0,0,0,0,9.799975,45.77289,0.2729295,0,61.19892,-9.800109,3853.093
59,-9.833709,-0.2746608,0.007150548,0,0,0,0,0,9.833576,45.92983,0.2746608,0,61.48875,-9.833709,3866.313
59.2,-9.866643,-0.2761059,0.007188168,0,0,0,0,0,9.866509,46.08365,0.2761059,0,61.77364,-9.866643,3875.598
59.4,-9.900109,-0.2775906,0.007226821,0,0,0,0,0,9.899976,46.23996,0.2775906,0,62.06398,-9.900109,3885.142
59.6,-9.933709,-0.2791366,0.007267069,0,0,0,0,0,9.933575,46.3969,0.2791366,0,62.35632,-9.933709,3895.375
59.8,-9.966909,-0.2806953,0.007307649,0,0,0,0,0,9.966776,46.55196,0.2806953,0,62.64603,-9.966909,3905.795
60,-10.00011,-0.282015,0.007342007,0,0,0,0,0,9.999975,46.70703,0.282015,0,62.93658,-10.00011,3912.774
60.2,-10.03331,-0.2835047,0.00738079,0,0,0,0,0,10.03318,46.8621,0.2835047,0,63.22797,-10.03331,3921.997
60.4,-10.06678,-0.284879,0.007416568,0,0,0,0,0,10.06664,47.01841,0.284879,0,63.52258,-10.06678,3929.415
60.6,-10.10011,-0.2860171,0.007446197,0,0,0,0,0,10.09998,47.1741,0.2860171,0,63.81686,-10.10011,3933.521
60.8,-10.13344,-0.2875976,0.007487345,0,0,0,0,0,10.13331,47.3298,0.2875976,0,64.11203,-10.13344,3943.6
61,-10.16678,-0.2889225,0.007521837,0,0,0,0,0,10.16664,47.48549,0.2889225,0,64.40806,-10.16678,3950.056
61.2,-10.20037,-0.2899349,0.007548194,0,0,0,0,0,10.20024,47.64242,0.2899349,0,64.70734,-10.20037,3952.052
61.4,-10.23371,-0.2910447,0.007577086,0,0,0,0,0,10.23358,47.79811,0.2910447,0,65.00515,-10.23371,3955.382
61.6,-10.26691,-0.2922893,0.007609488,0,0,0,0,0,10.26678,47.95318,0.2922893,0,65.30264,-10.26691,3960.497
61.8,-10.29984,-0.2934916,0.007640791,0,0,0,0,0,10.29971,48.107,0.2934916,0,65.59863,-10.29984,3965.035
62,-10.33344,-0.2949643,0.00767913,0,0,0,0,0,10.33331,48.26393,0.2949643,0,65.9015,-10.33344,3972.88
62.2,-10.36691,-0.2965986,0.007721679,0,0,0,0,0,10.36678,48.42025,0.2965986,0,66.2041,-10.36691,3982.823
62.4,-10.39997,-0.2978775,0.007754974,0,0,0,0,0,10.39984,48.57469,0.2978775,0,66.50398,-10.39997,3988.019
62.6,-10.43357,-0.2992655,0.007791109,0,0,0,0,0,10.43344,48.73162,0.2992655,0,66.80961,-10.43357,3994.375
62.8,-10.46704,-0.3010111,0.007836554,0,0,0,0,0,10.46691,48.88794,0.3010111,0,67.11497,-10.46704,4005.424
63,-10.50037,-0.3029201,0.007886251,0,0,0,0,0,10.50024,49.04363,0.3029201,0,67.42004,-10.50037,4018.548
63.2,-10.53317,-0.3045855,0.00792961,0,0,0,0,0,10.53304,49.19683,0.3045855,0,67.72114,-10.53317,4028.493
63.4,-10.56664,-0.3064883,0.007979146,0,0,0,0,0,10.56651,49.35314,0.3064883,0,68.0293,-10.56664,4041.187
63.6,-10.60024,-0.3083443,0.008027467,0,0,0,0,0,10.60011,49.51008,0.3083443,0,68.33964,-10.60024,4053.062
63.8,-10.63344,-0.3102285,0.00807652,0,0,0,0,0,10.63331,49.66515,0.3102285,0,68.64724,-10.63344,4065.304
64,-10.66677,-0.3119948,0.008122504,0,0,0,0,0,10.66664,49.82083,0.3119948,0,68.95702,-10.66677,4075.805
64.2,-10.70011,-0.3139152,0.0081725,0,0,0,0,0,10.69997,49.97652,0.3139152,0,69.26777,-10.70011,4088.169
64.4,-10.73371,-0.3157706,0.008220804,0,0,0,0,0,10.73357,50.13346,0.3157706,0,69.58199,-10.73371,4099.431
64.60001,-10.76704,-0.3175043,0.008265939,0,0,0,0,0,10.76691,50.28915,0.3175043,0,69.89469,-10.76704,4109.069
64.8,-10.80024,-0.3190023,0.008304939,0,0,0,0,0,10.80011,50.44422,0.3190023,0,70.20713,-10.80024,4115.577
65,-10.83331,-0.3207024,0.008349199,0,0,0,0,0,10.83317,50.59866,0.3207024,0,70.51927,-10.83331,4124.616
65.2,-10.86677,-0.3220421,0.008384077,0,0,0,0,0,10.86664,50.75497,0.3220421,0,70.83618,-10.86677,4128.741
65.4,-10.90024,-0.3237072,0.008427426,0,0,0,0,0,10.90011,50.91129,0.3237072,0,71.15411,-10.90024,4136.915
65.60001,-10.93344,-0.3248735,0.00845779,0,0,0,0,0,10.93331,51.06636,0.3248735,0,71.4705,-10.93344,4138.705
65.8,-10.96677,-0.3257923,0.008481709,0,0,0,0,0,10.96664,51.22205,0.3257923,0,71.78917,-10.96677,4137.204
66,-11.00037,-0.3277366,0.008532328,0,0,0,0,0,11.00024,51.37898,0.3277366,0,72.11143,-11.00037,4148.504
66.20001,-11.03357,-0.3291557,0.008569271,0,0,0,0,0,11.03344,51.53405,0.3291557,0,72.43087,-11.03357,4153.179
66.4,-11.06677,-0.3309935,0.008617117,0,0,0,0,0,11.06664,51.68912,0.3309935,0,72.75133,-11.06677,4163.006
66.60001,-11.09997,-0.3324069,0.008653914,0,0,0,0,0,11.09984,51.84418,0.3324068,0,73.07282,-11.09997,4167.363
66.8,-11.13344,-0.3340633,0.008697037,0,0,0,0,0,11.13331,52.0005,0.3340633,0,73.39795,-11.13344,4174.534
67,-11.16664,-0.335925,0.008745506,0,0,0,0,0,11.16651,52.15556,0.335925,0,73.72154,-11.16664,4184.238
67.20001,-11.19997,-0.3373634,0.008782953,0,0,0,0,0,11.19984,52.31125,0.3373634,0,74.04747,-11.19997,4188.48
67.4,-11.23344,-0.3391175,0.008828619,0,0,0,0,0,11.23331,52.46757,0.3391175,0,74.37579,-11.23344,4196.457
67.60001,-11.26704,-0.3404968,0.008864528,0,0,0,0,0,11.26691,52.6245,0.3404968,0,74.7065,-11.26704,4199.615
67.8,-11.30037,-0.3419975,0.008903598,0,0,0,0,0,11.30024,52.78019,0.3419975,0,75.03568,-11.30037,4204.262
68,-11.33357,-0.3433042,0.008937617,0,0,0,0,0,11.33344,52.93526,0.3433042,0,75.36461,-11.33357,4206.466
68.20001,-11.36664,-0.344649,0.008972627,0,0,0,0,0,11.36651,53.08971,0.344649,0,75.69331,-11.36664,4209.086
68.4,-11.40024,-0.3462644,0.009014682,0,0,0,0,0,11.40011,53.24664,0.3462644,0,76.0284,-11.40024,4214.667
68.60001,-11.43357,-0.3477249,0.009052705,0,0,0,0,0,11.43344,53.40233,0.3477249,0,76.36197,-11.43357,4218.35
68.8,-11.46677,-0.3492325,0.009091955,0,0,0,0,0,11.46664,53.5574,0.3492325,0,76.6953,-11.46677,4222.54
69,-11.50011,-0.3505659,0.009126667,0,0,0,0,0,11.49997,53.71309,0.3505659,0,77.03108,-11.50011,4224.453
69.20001,-11.53371,-0.3520934,0.009166434,0,0,0,0,0,11.53357,53.87003,0.3520934,0,77.37072,-11.53371,4228.474
69.4,-11.56691,-0.3535081,0.009203264,0,0,0,0,0,11.56677,54.02509,0.3535081,0,77.70743,-11.56691,4231.193
69.60001,-11.60011,-0.3547683,0.009236074,0,0,0,0,0,11.59997,54.18016,0.3547683,0,78.0453,-11.60011,4231.955
69.8,-11.6333,-0.3565192,0.009281656,0,0,0,0,0,11.63317,54.33522,0.3565192,0,78.3843,-11.6333,4238.447
70,-11.66664,-0.3582058,0.009325567,0,0,0,0,0,11.6665,54.49091,0.3582058,0,78.72582,-11.66664,4243.98
70.20001,-11.7001,-0.3594711,0.009358508,0,0,0,0,0,11.69997,54.64723,0.3594711,0,79.06989,-11.7001,4244.343
70.4,-11.73344,-0.3610058,0.009398462,0,0,0,0,0,11.7333,54.80292,0.3610058,0,79.41377,-11.73344,4247.831
70.60001,-11.76677,-0.3623039,0.009432257,0,0,0,0,0,11.76664,54.95861,0.3623039,0,79.75884,-11.76677,4248.42
70.8,-11.80024,-0.3636851,0.009468214,0,0,0,0,0,11.80011,55.11492,0.3636851,0,80.10648,-11.80024,4249.815
71,-11.83384,-0.3651379,0.009506037,0,0,0,0,0,11.8337,55.27186,0.3651379,0,80.45673,-11.83384,4251.874
71.20001,-11.8669,-0.36624,0.00953473,0,0,0,0,0,11.86677,55.4263,0.36624,0,80.80263,-11.8669,4249.981
71.4,-11.89997,-0.3674913,0.009567305,0,0,0,0,0,11.89984,55.58075,0.3674913,0,81.14972,-11.89997,4249.725
71.60001,-11.93344,-0.3691255,0.009609851,0,0,0,0,0,11.9333,55.73706,0.3691255,0,81.50223,-11.93344,4253.603
71.8,-11.9669,-0.3712649,0.009665546,0,0,0,0,0,11.96677,55.89338,0.3712648,0,81.85602,-11.9669,4263.146
72,-12.0001,-0.3731991,0.009715904,0,0,0,0,0,11.99997,56.04844,0.3731991,0,82.20821,-12.0001,4270.291
72.20001,-12.03344,-0.375238,0.009768983,0,0,0,0,0,12.0333,56.20413,0.375238,0,82.56307,-12.03344,4278.411
72.4,-12.06704,-0.3774408,0.009826331,0,0,0,0,0,12.0669,56.36106,0.3774408,0,82.92205,-12.06704,4288.106
72.60001,-12.10037,-0.379332,0.009875567,0,0,0,0,0,12.10024,56.51675,0.379332,0,83.27945,-12.10037,4294.217
72.8,-12.13344,-0.3813993,0.009929387,0,0,0,0,0,12.1333,56.6712,0.3813993,0,83.63527,-12.13344,4302.284
73,-12.16664,-0.3835237,0.009984694,0,0,0,0,0,12.1665,56.82627,0.3835237,0,83.99379,-12.16664,4310.765
73.20001,-12.20024,-0.3857205,0.01004189,0,0,0,0,0,12.2001,56.9832,0.3857205,0,84.35796,-12.20024,4319.697
73.4,-12.23344,-0.3877742,0.01009535,0,0,0,0,0,12.2333,57.13827,0.3877742,0,84.71909,-12.23344,4327.043
73.60001,-12.26677,-0.3899368,0.01015165,0,0,0,0,0,12.26664,57.29396,0.3899368,0,85.08298,-12.26677,4335.369
73.8,-12.30024,-0.3922838,0.01021275,0,0,0,0,0,12.3001,57.45028,0.3922838,0,85.44968,-12.30024,4345.499
74,-12.3337,-0.3949336,0.01028174,0,0,0,0,0,12.33357,57.60659,0.3949336,0,85.81772,-12.3337,4358.781
74.20001,-12.36704,-0.3985281,0.01037532,0,0,0,0,0,12.3669,57.76228,0.3985281,0,86.18564,-12.36704,4382.3
74.4,-12.40024,-0.400858,0.01043598,0,0,0,0,0,12.4001,57.91734,0.400858,0,86.55344,-12.40024,4391.736
74.60001,-12.4333,-0.4035015,0.0105048,0,0,0,0,0,12.43317,58.07178,0.4035015,0,86.92112,-12.4333,4404.475
74.8,-12.4669,-0.4069331,0.01059414,0,0,0,0,0,12.46677,58.22872,0.4069331,0,87.29612,-12.4669,4425.306
75,-12.50037,-0.4100211,0.01067453,0,0,0,0,0,12.50024,58.38504,0.4100211,0,87.67104,-12.50037,4442.201
75.20001,-12.5333,-0.4128913,0.01074925,0,0,0,0,0,12.53317,58.53886,0.4128912,0,88.04135,-12.5333,4456.763
75.4,-12.5669,-0.4162416,0.01083647,0,0,0,0,0,12.56677,58.69579,0.4162416,0,88.42059,-12.5669,4475.92
75.60001,-12.60037,-0.4196018,0.01092396,0,0,0,0,0,12.60024,58.8521,0.4196018,0,88.79974,-12.60037,4494.978
75.8,-12.6337,-0.4228037,0.01100731,0,0,0,0,0,12.63357,59.0078,0.4228037,0,89.17883,-12.6337,4512.14
76,-12.66677,-0.4257619,0.01108433,0,0,0,0,0,12.66664,59.16224,0.4257619,0,89.55631,-12.66677,4526.591
76.20001,-12.69997,-0.4283539,0.01115181,0,0,0,0,0,12.69984,59.31731,0.4283539,0,89.93675,-12.69997,4536.856
76.4,-12.7337,-0.4315145,0.01123409,0,0,0,0,0,12.73357,59.47487,0.4315145,0,90.32479,-12.7337,4552.63
76.60001,-12.76677,-0.4339465,0.01129741,0,0,0,0,0,12.76664,59.62931,0.4339465,0,90.70662,-12.76677,4560.841
76.8,-12.8001,-0.4364746,0.01136322,0,0,0,0,0,12.79997,59.785,0.4364746,0,91.09301,-12.8001,4569.72
77,-12.83357,-0.4393544,0.0114382,0,0,0,0,0,12.83344,59.94131,0.4393544,0,91.48246,-12.83357,4581.992
77.20001,-12.8669,-0.4421988,0.01151225,0,0,0,0,0,12.86677,60.097,0.4421988,0,91.87188,-12.8669,4593.732
77.4,-12.90024,-0.4449325,0.01158342,0,0,0,0,0,12.9001,60.25269,0.4449325,0,92.26281,-12.90024,4604.096
77.60001,-12.93343,-0.4473262,0.01164573,0,0,0,0,0,12.9333,60.40776,0.4473262,0,92.65371,-12.93343,4610.807
77.8,-12.96663,-0.4497788,0.01170959,0,0,0,0,0,12.9665,60.56283,0.4497788,0,93.04614,-12.96663,4617.929
78,-13.0001,-0.4521796,0.01177209,0,0,0,0,0,12.99997,60.71914,0.4521796,0,93.44329,-13.0001,4624.177
78.20001,-13.0337,-0.4549011,0.01184294,0,0,0,0,0,13.03357,60.87608,0.454901,0,93.8436,-13.0337,4633.423
78.4,-13.06677,-0.4570668,0.01189932,0,0,0,0,0,13.06663,61.03052,0.4570669,0,94.23914,-13.06677,4637.105
78.60001,-13.1001,-0.458896,0.01194695,0,0,0,0,0,13.09997,61.18621,0.458896,0,94.63947,-13.1001,4637.062
78.8,-13.1337,-0.461621,0.01201789,0,0,0,0,0,13.13357,61.34315,0.461621,0,95.04461,-13.1337,4645.737
79,-13.16703,-0.4639771,0.01207922,0,0,0,0,0,13.1669,61.49884,0.4639771,0,95.44818,-13.16703,4650.642
79.20001,-13.19997,-0.465796,0.01212658,0,0,0,0,0,13.19983,61.65266,0.465796,0,95.8485,-13.19997,4650.221
79.4,-13.2333,-0.4684514,0.01219571,0,0,0,0,0,13.23317,61.80835,0.4684514,0,96.25533,-13.2333,4657.743
79.60001,-13.26677,-0.4707663,0.01225598,0,0,0,0,0,13.26663,61.96466,0.4707662,0,96.66545,-13.26677,4661.602
79.8,-13.3001,-0.4731992,0.01231932,0,0,0,0,0,13.29997,62.12035,0.4731992,0,97.07563,-13.3001,4666.513
80,-13.3333,-0.4753822,0.01237615,0,0,0,0,0,13.33317,62.27542,0.4753821,0,97.48584,-13.3333,4668.849
80.20001,-13.36677,-0.478036,0.01244524,0,0,0,0,0,13.36663,62.43173,0.478036,0,97.90105,-13.36677,4675.46
80.4,-13.40023,-0.4809445,0.01252096,0,0,0,0,0,13.4001,62.58805,0.4809445,0,98.318,-13.40023,4684.335
80.60001,-13.43357,-0.4841231,0.01260371,0,0,0,0,0,13.43343,62.74374,0.4841231,0,98.73501,-13.43357,4695.671
80.8,-13.46703,-0.4874093,0.01268926,0,0,0,0,0,13.4669,62.90005,0.4874093,0,99.15545,-13.46703,4707.711
81.00001,-13.49997,-0.49062,0.01277285,0,0,0,0,0,13.49983,63.05387,0.49062,0,99.57093,-13.49997,4719.074
81.20001,-13.53343,-0.494338,0.01286964,0,0,0,0,0,13.5333,63.21019,0.494338,0,99.99492,-13.53343,4734.718
81.4,-13.56703,-0.4979311,0.01296319,0,0,0,0,0,13.5669,63.36712,0.4979311,0,100.4224,-13.56703,4748.79
81.60001,-13.6001,-0.5013544,0.01305231,0,0,0,0,0,13.59997,63.52156,0.5013544,0,100.8449,-13.6001,4761.28
81.8,-13.63343,-0.5047104,0.01313968,0,0,0,0,0,13.6333,63.67725,0.5047104,0,101.2726,-13.63343,4772.694
82.00001,-13.66703,-0.508759,0.01324508,0,0,0,0,0,13.6669,63.83419,0.508759,0,101.7056,-13.66703,4790.192
82.20001,-13.70037,-0.5124963,0.01334238,0,0,0,0,0,13.70023,63.98988,0.5124962,0,102.137,-13.70037,4804.607
82.4,-13.7333,-0.515534,0.01342146,0,0,0,0,0,13.73317,64.1437,0.515534,0,102.5651,-13.7333,4812.441
82.60001,-13.76663,-0.5193127,0.01351984,0,0,0,0,0,13.7665,64.29939,0.5193127,0,103.0003,-13.76663,4826.665
82.8,-13.80023,-0.5241797,0.01364655,0,0,0,0,0,13.8001,64.45633,0.5241796,0,103.4408,-13.80023,4850.483
83.00001,-13.83343,-0.5286934,0.01376406,0,0,0,0,0,13.8333,64.61139,0.5286934,0,103.878,-13.83343,4870.909
83.20001,-13.86677,-0.5332955,0.01388387,0,0,0,0,0,13.86663,64.76708,0.5332955,0,104.3189,-13.86677,4891.692
83.4,-13.90023,-0.5386128,0.0140223,0,0,0,0,0,13.9001,64.92339,0.5386128,0,104.7636,-13.90023,4918.547
83.60001,-13.9337,-0.5443084,0.01417058,0,0,0,0,0,13.93357,65.07971,0.5443084,0,105.2102,-13.9337,4948.407
83.8,-13.96717,-0.5495982,0.01430829,0,0,0,0,0,13.96703,65.23602,0.5495982,0,105.6588,-13.96717,4974.132
84.00001,-14.00023,-0.5548723,0.0144456,0,0,0,0,0,14.0001,65.39046,0.5548723,0,106.1041,-14.00023,4999.555
84.20001,-14.0333,-0.5599937,0.01457893,0,0,0,0,0,14.03317,65.54491,0.5599937,0,106.5514,-14.0333,5023.184
84.4,-14.06677,-0.5652619,0.01471609,0,0,0,0,0,14.06663,65.70123,0.5652619,0,107.006,-14.06677,5047.437
84.60001,-14.10037,-0.5709099,0.01486312,0,0,0,0,0,14.10023,65.85816,0.5709099,0,107.4647,-14.10037,5074.544
84.8,-14.13343,-0.5762578,0.01500235,0,0,0,0,0,14.1333,66.0126,0.5762578,0,107.918,-14.13343,5098.909
85.00001,-14.16677,-0.5814858,0.01513846,0,0,0,0,0,14.16663,66.1683,0.5814858,0,108.3772,-14.16677,5121.598
85.20001,-14.20037,-0.5875689,0.01529683,0,0,0,0,0,14.20023,66.32523,0.5875689,0,108.8421,-14.20037,5151.171
85.4,-14.2337,-0.5935573,0.01545273,0,0,0,0,0,14.23357,66.48092,0.5935573,0,109.3055,-14.2337,5179.613
85.60001,-14.26676,-0.5994995,0.01560743,0,0,0,0,0,14.26663,66.63536,0.5994995,0,109.7674,-14.26676,5207.363
85.8,-14.29997,-0.6054125,0.01576137,0,0,0,0,0,14.29983,66.79044,0.6054125,0,110.2332,-14.29997,5234.282
86.00001,-14.33356,-0.6118204,0.01592819,0,0,0,0,0,14.33343,66.94736,0.6118204,0,110.7069,-14.33356,5264.688
86.20001,-14.3669,-0.6176184,0.01607914,0,0,0,0,0,14.36677,67.10306,0.6176184,0,111.179,-14.3669,5289.545
86.4,-14.4001,-0.6232913,0.01622683,0,0,0,0,0,14.39996,67.25813,0.6232913,0,111.6515,-14.4001,5312.968
86.60001,-14.43356,-0.6294078,0.01638607,0,0,0,0,0,14.43343,67.41444,0.6294078,0,112.1301,-14.43356,5339.492
86.8,-14.46703,-0.6357688,0.01655167,0,0,0,0,0,14.4669,67.57076,0.6357688,0,112.611,-14.46703,5367.581
87.00001,-14.5005,-0.6417642,0.01670775,0,0,0,0,0,14.50036,67.72707,0.6417642,0,113.0941,-14.5005,5392.082
87.20001,-14.53356,-0.6480116,0.0168704,0,0,0,0,0,14.53343,67.88151,0.6480116,0,113.5738,-14.53356,5418.518
87.4,-14.56676,-0.6542788,0.01703356,0,0,0,0,0,14.56663,68.03658,0.6542788,0,114.0578,-14.56676,5444.509
87.60001,-14.6001,-0.6609157,0.01720634,0,0,0,0,0,14.59997,68.19227,0.6609157,0,114.5461,-14.6001,5472.948
87.8,-14.63356,-0.66768,0.01738245,0,0,0,0,0,14.63343,68.34858,0.66768,0,115.0387,-14.63356,5501.792
88.00001,-14.66676,-0.6743645,0.01755647,0,0,0,0,0,14.66663,68.50365,0.6743645,0,115.5298,-14.66676,5529.649
88.20001,-14.70023,-0.6807517,0.01772276,0,0,0,0,0,14.7001,68.65997,0.6807517,0,116.0274,-14.70023,5554.318
88.4,-14.7337,-0.6878993,0.01790884,0,0,0,0,0,14.73356,68.81627,0.6878994,0,116.5274,-14.7337,5584.645
88.60001,-14.76703,-0.695136,0.01809724,0,0,0,0,0,14.7669,68.97196,0.695136,0,117.0279,-14.76703,5615.219
88.8,-14.8001,-0.7019416,0.01827442,0,0,0,0,0,14.79996,69.1264,0.7019415,0,117.5269,-14.8001,5641.97
89.00001,-14.83316,-0.7088763,0.01845496,0,0,0,0,0,14.83303,69.28085,0.7088764,0,118.0284,-14.83316,5669.206
89.20001,-14.8669,-0.7167543,0.01866005,0,0,0,0,0,14.86676,69.43841,0.7167543,0,118.5426,-14.8669,5702.809
89.4,-14.9001,-0.7235338,0.01883655,0,0,0,0,0,14.89996,69.59348,0.7235338,0,119.0513,-14.9001,5727.54
89.60001,-14.93343,-0.7305845,0.01902011,0,0,0,0,0,14.9333,69.74917,0.7305845,0,119.5647,-14.93343,5753.741
89.8,-14.9669,-0.7381764,0.01921776,0,0,0,0,0,14.96676,69.90548,0.7381763,0,120.0827,-14.9669,5783.492
90.00001,-15.00023,-0.7459457,0.01942002,0,0,0,0,0,15.0001,70.06117,0.7459456,0,120.6014,-15.00023,5814.127
90.036,-15.00623,-0.747212,0.01945299,0,0,0,0,0,15.0061,70.0892,0.747212,0,120.695,-15.00623,5818.546