File: GFBaking/data/misc/13Gluten_Compression_Misc/13gluten.is_comp.raw
"Test Type","Compression"
"Method Name","C:\Users\Public\Documents\Instron\Bluehill\Templates\Instron Examples\Bluehill\CompressionTest Bread.im_comp"
"Sample name","P:\+Courses\MatSci\Spring2016\GF Baking - Emily, Elizabeth, Frances\13gluten.is_comp"
"User",""
"Sample note 1",""
"Sample note 2",""
"Sample note 3",""
"Geometry","Circular"
"Specimen",1
"Specimen label","13gluten1"
"Width",50.000000,"mm"
"Thickness",50.000000,"mm"
"Anvil height",23.470000,"mm"
"Diameter",21.800000,"mm"
"Inner diameter",8.000000,"mm"
"Outer diameter",10.000000,"mm"
"Wall thickness",1.000000,"mm"
"Area",3.732526,"cm^2"
"Linear density",100.000000,"tex"
"Sled weight",10.000000,"N"
"Loading span",10.000000,"mm"
"Support span",100.000000,"mm"
"Span ratio","2"
"Fixture type","4-point"
"Included"
"Final width",50.000000,"mm"
"Final thickness",50.000000,"mm"
"Final anvil height",50.000000,"mm"
"Final diameter",1.000000,"mm"
"Final Inner diameter",0.000000,"mm"
"Final outer diameter",1.000000,"mm"
"Final wall thickness",0.500000,"mm"
"Final area",0.007854,"cm^2"
"Final linear density",1.000000,"tex"
"Operator ID","George"
"Company","ABC"
"Laboratory Name","Zyx"
"Comment",""
"Custom text input  5",""
"Custom text input  6",""
"Custom text input  7",""
"Custom text input  8",""
"Custom text input  9",""
"Custom text input 10",""
"Custom text input 11",""
"Custom text input 12",""
"Custom text input 13",""
"Custom text input 14",""
"Custom text input 15",""
"Custom text input 16",""
"Custom text input 17",""
"Custom text input 18",""
"Custom text input 19",""
"Custom text input 20",""
"Custom text input 21",""
"Custom text input 22",""
"Custom text input 23",""
"Custom text input 24",""
"Custom text input 25",""
"Custom text input 26",""
"Custom text input 27",""
"Custom text input 28",""
"Custom text input 29",""
"Custom text input 30",""
"Custom text input 31",""
"Custom text input 32",""
"Custom text input 33",""
"Custom text input 34",""
"Custom text input 35",""
"Custom text input 36",""
"Custom text input 37",""
"Custom text input 38",""
"Custom text input 39",""
"Custom text input 40",""
"Custom text input 41",""
"Custom text input 42",""
"Custom text input 43",""
"Custom text input 44",""
"Custom text input 45",""
"Custom text input 46",""
"Custom text input 47",""
"Custom text input 48",""
"Custom text input 49",""
"Custom text input 50",""
"Temperature (deg C)",18.000000,""
"Humidity (%)",50.000000,""
"Custom number input  3",0.000000,""
"Custom number input  4",0.000000,""
"Custom number input  5",0.000000,""
"Custom number input  6",0.000000,""
"Custom number input  7",0.000000,""
"Custom number input  8",0.000000,""
"Custom number input  9",0.000000,""
"Custom number input 10",0.000000,""
"Time sec","Extension mm","Load kgf","Compressive stress MPa","Cycle Count ","Total Cycle Count ","Repetitions Count ","Marked Data ","PIP Count ","Compressive extension mm","Compressive strain %","Compressive load kgf","Displacement (Strain 1) mm","True strain %","Corrected Position mm","True stress Pa"
0,-0.000266666,-0.01954255,0.0005134511,0,0,0,0,0,0,0,0.01954255,0,0,-0.000266666,513.4511
0.2,-0.02639994,-0.02127945,0.0005590855,0,0,0,0,0,0.02613327,0.1113475,0.02127945,0,0.1114096,-0.02639994,558.4629
0.4,-0.06466651,-0.02436829,0.00064024,0,0,0,0,0,0.06439985,0.2743922,0.02436829,0,0.2747693,-0.06466651,638.4832
0.6,-0.09959975,-0.02651325,0.0006965956,0,0,0,0,0,0.09933309,0.4232343,0.02651325,0,0.4241324,-0.09959975,693.6474
0.8,-0.133333,-0.02837884,0.0007456113,0,0,0,0,0,0.1330664,0.5669636,0.02837884,0,0.5685769,-0.133333,741.384
1,-0.1666663,-0.03009315,0.0007906522,0,0,0,0,0,0.1663996,0.7089885,0.03009315,0,0.7115137,-0.1666663,785.0466
1.2,-0.2001328,-0.03175572,0.0008343337,0,0,0,0,0,0.1998662,0.8515815,0.03175572,0,0.8552281,-0.2001328,827.2286
1.4,-0.2334661,-0.03341408,0.0008779047,0,0,0,0,0,0.2331994,0.9936064,0.03341408,0,0.9985757,-0.2334661,869.1818
1.6,-0.267066,-0.03476313,0.0009133489,0,0,0,0,0,0.2667994,1.136768,0.03476314,0,1.143278,-0.267066,902.9663
1.8,-0.3002659,-0.03641782,0.0009568234,0,0,0,0,0,0.2999993,1.278224,0.03641782,0,1.286464,-0.3002659,944.593
2,-0.3335992,-0.03780548,0.0009932821,0,0,0,0,0,0.3333325,1.420249,0.03780548,0,1.430431,-0.3335992,979.175
2.2,-0.3669325,-0.03923884,0.001030941,0,0,0,0,0,0.3666658,1.562274,0.03923884,0,1.574607,-0.3669325,1014.835
2.4,-0.400399,-0.04124399,0.001083624,0,0,0,0,0,0.4001324,1.704867,0.04124399,0,1.719568,-0.400399,1065.149
2.6,-0.4333323,-0.04256586,0.001118354,0,0,0,0,0,0.4330656,1.845188,0.04256586,0,1.862424,-0.4333323,1097.718
2.8,-0.4667989,-0.04401147,0.001156335,0,0,0,0,0,0.4665322,1.987781,0.04401147,0,2.007803,-0.4667989,1133.35
3,-0.5003988,-0.04564029,0.00119913,0,0,0,0,0,0.5001321,2.130942,0.04564029,0,2.153974,-0.5003988,1173.577
3.2,-0.5337321,-0.04693694,0.001233198,0,0,0,0,0,0.5334653,2.272967,0.04693694,0,2.299197,-0.5337321,1205.167
3.4,-0.566932,-0.04858025,0.001276373,0,0,0,0,0,0.5666653,2.414424,0.04858025,0,2.444049,-0.566932,1245.556
3.6,-0.6002652,-0.05017681,0.00131832,0,0,0,0,0,0.5999986,2.556449,0.05017681,0,2.589694,-0.6002652,1284.618
3.8,-0.6335985,-0.05164545,0.001356906,0,0,0,0,0,0.6333318,2.698474,0.05164545,0,2.735551,-0.6335985,1320.291
4,-0.6669317,-0.05332482,0.001401029,0,0,0,0,0,0.6666651,2.840499,0.05332482,0,2.881622,-0.6669317,1361.233
4.2,-0.6999983,-0.05491157,0.001442719,0,0,0,0,0,0.6997316,2.981387,0.05491157,0,3.026734,-0.6999983,1399.706
4.4,-0.7334649,-0.05667031,0.001488927,0,0,0,0,0,0.7331982,3.123981,0.05667031,0,3.173818,-0.7334649,1442.413
4.6,-0.7669315,-0.05823583,0.001530059,0,0,0,0,0,0.7666648,3.266573,0.05823583,0,3.321117,-0.7669315,1480.078
4.8,-0.8003981,-0.06000845,0.001576632,0,0,0,0,0,0.8001314,3.409167,0.06000845,0,3.468634,-0.8003981,1522.882
5,-0.833598,-0.06162715,0.001619161,0,0,0,0,0,0.8333313,3.550623,0.06162715,0,3.615191,-0.833598,1561.67
5.2,-0.8669312,-0.06315647,0.001659341,0,0,0,0,0,0.8666646,3.692648,0.06315646,0,3.762553,-0.8669312,1598.067
5.4,-0.9002645,-0.0649936,0.001707609,0,0,0,0,0,0.8999978,3.834673,0.06499361,0,3.910132,-0.9002645,1642.128
5.6,-0.9338644,-0.06665245,0.001751193,0,0,0,0,0,0.9335977,3.977834,0.06665245,0,4.059113,-0.9338644,1681.533
5.8,-0.9666643,-0.06842008,0.001797635,0,0,0,0,0,0.9663976,4.117587,0.06842008,0,4.204761,-0.9666643,1723.615
6,-0.9999976,-0.06997671,0.001838533,0,0,0,0,0,0.999731,4.259612,0.06997672,0,4.352995,-0.9999976,1760.218
6.2,-1.033731,-0.07152612,0.001879241,0,0,0,0,0,1.033464,4.403341,0.07152612,0,4.503231,-1.033731,1796.492
6.4,-1.067064,-0.0733619,0.001927473,0,0,0,0,0,1.066797,4.545366,0.0733619,0,4.651909,-1.067064,1839.863
6.6,-1.100264,-0.0748586,0.001966797,0,0,0,0,0,1.099997,4.686823,0.07485861,0,4.800211,-1.100264,1874.617
6.8,-1.133597,-0.07654508,0.002011107,0,0,0,0,0,1.133331,4.828848,0.07654507,0,4.949332,-1.133597,1913.993
7,-1.166931,-0.0780466,0.002050557,0,0,0,0,0,1.166664,4.970873,0.0780466,0,5.098674,-1.166931,1948.626
7.2,-1.20013,-0.07949322,0.002088564,0,0,0,0,0,1.199864,5.112329,0.07949322,0,5.247641,-1.20013,1981.79
7.4,-1.23333,-0.08115985,0.002132353,0,0,0,0,0,1.233064,5.253787,0.08115985,0,5.396831,-1.23333,2020.324
7.6,-1.266797,-0.08280259,0.002175513,0,0,0,0,0,1.26653,5.396379,0.08280259,0,5.547444,-1.266797,2058.114
7.8,-1.30013,-0.08454885,0.002221394,0,0,0,0,0,1.299864,5.538404,0.08454885,0,5.697683,-1.30013,2098.364
8,-1.333863,-0.08598519,0.002259131,0,0,0,0,0,1.333597,5.682134,0.08598519,0,5.849955,-1.333863,2130.764
8.200001,-1.367063,-0.08753328,0.002299805,0,0,0,0,0,1.366797,5.823591,0.08753329,0,6.000047,-1.367063,2165.874
8.400001,-1.40013,-0.08838545,0.002322194,0,0,0,0,0,1.399863,5.964479,0.08838545,0,6.149759,-1.40013,2183.688
8.6,-1.43373,-0.08919931,0.002343578,0,0,0,0,0,1.433463,6.107641,0.08919931,0,6.302118,-1.43373,2200.44
8.8,-1.467196,-0.09103255,0.002391743,0,0,0,0,0,1.46693,6.250233,0.09103256,0,6.454101,-1.467196,2242.254
9,-1.50013,-0.09288524,0.00244042,0,0,0,0,0,1.499863,6.390554,0.09288523,0,6.603889,-1.50013,2284.463
9.200001,-1.533463,-0.09429951,0.002477578,0,0,0,0,0,1.533196,6.532579,0.09429952,0,6.755725,-1.533463,2315.728
9.400001,-1.56693,-0.09591997,0.002520153,0,0,0,0,0,1.566663,6.675172,0.09591997,0,6.9084,-1.56693,2351.928
9.6,-1.600396,-0.09748194,0.002561191,0,0,0,0,0,1.600129,6.817765,0.09748194,0,7.06131,-1.600396,2386.575
9.8,-1.633596,-0.09896205,0.002600079,0,0,0,0,0,1.633329,6.959222,0.09896205,0,7.213231,-1.633596,2419.133
10,-1.666929,-0.1007382,0.002646745,0,0,0,0,0,1.666663,7.101246,0.1007382,0,7.365996,-1.666929,2458.793
10.2,-1.700396,-0.1032751,0.002713397,0,0,0,0,0,1.700129,7.24384,0.1032751,0,7.519607,-1.700396,2516.843
10.4,-1.733462,-0.1040489,0.002733729,0,0,0,0,0,1.733196,7.384728,0.1040489,0,7.671614,-1.733462,2531.851
10.6,-1.766796,-0.1052273,0.002764689,0,0,0,0,0,1.766529,7.526753,0.1052273,0,7.825081,-1.766796,2556.598
10.8,-1.800129,-0.1069552,0.002810085,0,0,0,0,0,1.799862,7.668778,0.1069551,0,7.978784,-1.800129,2594.586
11,-1.833596,-0.1084243,0.002848684,0,0,0,0,0,1.833329,7.811371,0.1084243,0,8.13334,-1.833596,2626.163
11.2,-1.866929,-0.1096434,0.002880714,0,0,0,0,0,1.866662,7.953396,0.1096434,0,8.287517,-1.866929,2651.599
11.4,-1.900262,-0.1119901,0.002942371,0,0,0,0,0,1.899995,8.095421,0.1119901,0,8.441933,-1.900262,2704.173
11.6,-1.933462,-0.113348,0.002978049,0,0,0,0,0,1.933195,8.236878,0.113348,0,8.59597,-1.933462,2732.75
11.8,-1.967062,-0.114555,0.003009761,0,0,0,0,0,1.966795,8.38004,0.114555,0,8.752104,-1.967062,2757.541
12,-2.000395,-0.1164301,0.003059026,0,0,0,0,0,2.000128,8.522064,0.1164301,0,8.907238,-2.000395,2798.334
12.2,-2.033328,-0.1172857,0.003081505,0,0,0,0,0,2.033062,8.662385,0.1172857,0,9.060749,-2.033328,2814.573
12.4,-2.066795,-0.1187718,0.003120551,0,0,0,0,0,2.066528,8.804978,0.1187719,0,9.216988,-2.066795,2845.787
12.6,-2.100395,-0.1201918,0.003157858,0,0,0,0,0,2.100128,8.948138,0.1201918,0,9.374093,-2.100395,2875.288
12.8,-2.133861,-0.1220178,0.003205833,0,0,0,0,0,2.133595,9.090732,0.1220177,0,9.530823,-2.133861,2914.399
13,-2.166928,-0.1234533,0.003243548,0,0,0,0,0,2.166662,9.231621,0.1234533,0,9.685921,-2.166928,2944.116
13.2,-2.200261,-0.1244085,0.003268645,0,0,0,0,0,2.199995,9.373646,0.1244085,0,9.842513,-2.200261,2962.254
13.4,-2.233595,-0.1255724,0.003299226,0,0,0,0,0,2.233328,9.515671,0.1255724,0,9.99935,-2.233595,2985.283
13.6,-2.266794,-0.1268288,0.003332235,0,0,0,0,0,2.266528,9.657127,0.1268288,0,10.15581,-2.266794,3010.437
13.8,-2.300128,-0.1279839,0.003362584,0,0,0,0,0,2.299861,9.799152,0.1279839,0,10.31314,-2.300128,3033.079
14,-2.333461,-0.1293425,0.003398279,0,0,0,0,0,2.333194,9.941177,0.1293425,0,10.47071,-2.333461,3060.45
14.2,-2.366794,-0.1303327,0.003424295,0,0,0,0,0,2.366528,10.0832,0.1303327,0,10.62854,-2.366794,3079.016
14.4,-2.400261,-0.131753,0.003461611,0,0,0,0,0,2.399994,10.2258,0.131753,0,10.78725,-2.400261,3107.634
14.6,-2.433594,-0.1329699,0.003493585,0,0,0,0,0,2.433327,10.36782,0.1329699,0,10.94558,-2.433594,3131.376
14.8,-2.466927,-0.1338616,0.003517013,0,0,0,0,0,2.46666,10.50984,0.1338616,0,11.10416,-2.466927,3147.38
15,-2.500394,-0.1353636,0.003556474,0,0,0,0,0,2.500127,10.65244,0.1353636,0,11.26362,-2.500394,3177.623
15.2,-2.533727,-0.136622,0.003589538,0,0,0,0,0,2.533461,10.79446,0.136622,0,11.42271,-2.533727,3202.066
15.4,-2.566661,-0.1380483,0.003627011,0,0,0,0,0,2.566394,10.93478,0.1380483,0,11.58013,-2.566661,3230.405
15.6,-2.600127,-0.1393816,0.00366204,0,0,0,0,0,2.59986,11.07738,0.1393816,0,11.74036,-2.600127,3256.382
15.8,-2.633594,-0.1404581,0.003690325,0,0,0,0,0,2.633327,11.21997,0.1404581,0,11.90084,-2.633594,3276.272
16,-2.667194,-0.1418081,0.003725794,0,0,0,0,0,2.666927,11.36313,0.1418081,0,12.06223,-2.667194,3302.427
16.2,-2.700393,-0.1428544,0.003753283,0,0,0,0,0,2.700126,11.50459,0.1428544,0,12.22195,-2.700393,3321.484
16.4,-2.733727,-0.1439618,0.00378238,0,0,0,0,0,2.73346,11.64661,0.1439618,0,12.38257,-2.733727,3341.861
16.6,-2.766927,-0.1450183,0.003810136,0,0,0,0,0,2.76666,11.78807,0.1450182,0,12.5428,-2.766927,3360.995
16.8,-2.800127,-0.1461598,0.003840129,0,0,0,0,0,2.79986,11.92953,0.1461598,0,12.70329,-2.800127,3382.02
17,-2.83346,-0.1473267,0.003870786,0,0,0,0,0,2.833193,12.07155,0.1473267,0,12.86468,-2.83346,3403.522
17.2,-2.866926,-0.1483403,0.003897418,0,0,0,0,0,2.86666,12.21414,0.1483403,0,13.02698,-2.866926,3421.382
17.4,-2.899993,-0.1495941,0.003930359,0,0,0,0,0,2.899726,12.35503,0.1495941,0,13.1876,-2.899993,3444.762
17.6,-2.933593,-0.1506348,0.003957703,0,0,0,0,0,2.933326,12.49819,0.1506348,0,13.35108,-2.933593,3463.061
17.8,-2.966926,-0.151697,0.00398561,0,0,0,0,0,2.96666,12.64022,0.151697,0,13.51352,-2.966926,3481.821
18,-3.000126,-0.1526964,0.004011868,0,0,0,0,0,2.999859,12.78168,0.1526964,0,13.67557,-3.000126,3499.084
18.2,-3.033726,-0.1538098,0.004041122,0,0,0,0,0,3.033459,12.92484,0.1538098,0,13.83985,-3.033726,3518.813
18.4,-3.067059,-0.1548474,0.004068382,0,0,0,0,0,3.066793,13.06686,0.1548474,0,14.00309,-3.067059,3536.772
18.6,-3.099992,-0.1558866,0.004095685,0,0,0,0,0,3.099726,13.20718,0.1558866,0,14.16463,-3.099992,3554.76
18.8,-3.133459,-0.1569689,0.00412412,0,0,0,0,0,3.133192,13.34978,0.1569689,0,14.32906,-3.133459,3573.559
19,-3.167059,-0.1580062,0.004151375,0,0,0,0,0,3.166792,13.49294,0.1580062,0,14.49441,-3.167059,3591.233
19.2,-3.200392,-0.1589484,0.004176129,0,0,0,0,0,3.200126,13.63496,0.1589483,0,14.65872,-3.200392,3606.715
19.4,-3.233592,-0.1599113,0.004201428,0,0,0,0,0,3.233325,13.77642,0.1599113,0,14.82265,-3.233592,3622.622
19.6,-3.266925,-0.1608878,0.004227086,0,0,0,0,0,3.266659,13.91844,0.1608878,0,14.9875,-3.266925,3638.741
19.8,-3.300259,-0.1620298,0.004257089,0,0,0,0,0,3.299992,14.06047,0.1620298,0,15.15263,-3.300259,3658.522
20,-3.333592,-0.1630411,0.004283658,0,0,0,0,0,3.333325,14.20249,0.1630411,0,15.31802,-3.333592,3675.272
20.2,-3.366792,-0.1639394,0.00430726,0,0,0,0,0,3.366525,14.34395,0.1639394,0,15.48303,-3.366792,3689.429
20.4,-3.399992,-0.1648447,0.004331047,0,0,0,0,0,3.399725,14.48541,0.1648447,0,15.64831,-3.399992,3703.677
20.6,-3.433458,-0.1659,0.004358771,0,0,0,0,0,3.433192,14.628,0.1658999,0,15.8152,-3.433458,3721.17
20.8,-3.467058,-0.1666193,0.00437767,0,0,0,0,0,3.466792,14.77116,0.1666193,0,15.98303,-3.467058,3731.037
21,-3.500391,-0.1677541,0.004407487,0,0,0,0,0,3.500125,14.91319,0.1677541,0,16.14981,-3.500391,3750.19
21.2,-3.533458,-0.1688813,0.004437101,0,0,0,0,0,3.533191,15.05408,0.1688813,0,16.31553,-3.533458,3769.137
21.4,-3.566925,-0.1700026,0.004466563,0,0,0,0,0,3.566658,15.19667,0.1700026,0,16.48354,-3.566925,3787.794
21.6,-3.600391,-0.1711698,0.004497228,0,0,0,0,0,3.600124,15.33926,0.1711698,0,16.65182,-3.600391,3807.387
21.8,-3.633458,-0.1722316,0.004525125,0,0,0,0,0,3.633191,15.48015,0.1722316,0,16.81838,-3.633458,3824.629
22,-3.666791,-0.173431,0.004556639,0,0,0,0,0,3.666525,15.62218,0.173431,0,16.98656,-3.666791,3844.792
22.2,-3.700391,-0.1745971,0.004587275,0,0,0,0,0,3.700124,15.76534,0.1745971,0,17.15637,-3.700391,3864.076
22.4,-3.733724,-0.1757367,0.004617217,0,0,0,0,0,3.733457,15.90736,0.1757367,0,17.32511,-3.733724,3882.739
22.6,-3.767058,-0.1768411,0.004646232,0,0,0,0,0,3.766791,16.04939,0.1768411,0,17.49415,-3.767058,3900.541
22.8,-3.800257,-0.1779062,0.004674217,0,0,0,0,0,3.79999,16.19084,0.1779062,0,17.66279,-3.800257,3917.422
23,-3.833724,-0.1792845,0.00471043,0,0,0,0,0,3.833457,16.33344,0.1792845,0,17.83307,-3.833724,3941.055
23.2,-3.866791,-0.1803448,0.004738287,0,0,0,0,0,3.866524,16.47432,0.1803448,0,18.00161,-3.866791,3957.686
23.4,-3.89999,-0.1814079,0.00476622,0,0,0,0,0,3.899724,16.61578,0.1814079,0,18.17111,-3.89999,3974.275
23.6,-3.933457,-0.1825642,0.004796599,0,0,0,0,0,3.933191,16.75838,0.1825642,0,18.34227,-3.933457,3992.767
23.8,-3.966924,-0.1835831,0.00482337,0,0,0,0,0,3.966657,16.90097,0.1835831,0,18.51371,-3.966924,4008.174
24,-4.00039,-0.184609,0.004850323,0,0,0,0,0,4.000124,17.04356,0.184609,0,18.68545,-4.00039,4023.656
24.2,-4.03359,-0.185656,0.004877831,0,0,0,0,0,4.033323,17.18502,0.185656,0,18.85612,-4.03359,4039.575
24.4,-4.066924,-0.1867442,0.004906422,0,0,0,0,0,4.066657,17.32704,0.1867442,0,19.02777,-4.066924,4056.284
24.6,-4.100257,-0.1878976,0.004936725,0,0,0,0,0,4.09999,17.46907,0.1878976,0,19.1997,-4.100257,4074.326
24.8,-4.133723,-0.1889005,0.004963076,0,0,0,0,0,4.133456,17.61166,0.1889005,0,19.37263,-4.133723,4088.996
25,-4.166657,-0.1899217,0.004989907,0,0,0,0,0,4.16639,17.75198,0.1899217,0,19.54309,-4.166657,4104.1
25.2,-4.200123,-0.190896,0.005015505,0,0,0,0,0,4.199857,17.89458,0.190896,0,19.71661,-4.200123,4118.002
25.4,-4.23359,-0.1919244,0.005042525,0,0,0,0,0,4.233323,18.03717,0.1919244,0,19.89043,-4.23359,4132.996
25.6,-4.267056,-0.1929754,0.005070138,0,0,0,0,0,4.266789,18.17976,0.1929754,0,20.06455,-4.267056,4148.399
25.8,-4.300389,-0.1938796,0.005093895,0,0,0,0,0,4.300123,18.32178,0.1938796,0,20.23829,-4.300389,4160.602
26,-4.333723,-0.194929,0.005121467,0,0,0,0,0,4.333456,18.46381,0.194929,0,20.41232,-4.333723,4175.849
26.2,-4.367056,-0.1961301,0.005153023,0,0,0,0,0,4.366789,18.60583,0.1961301,0,20.58666,-4.367056,4194.26
26.4,-4.400122,-0.1970329,0.005176741,0,0,0,0,0,4.399856,18.74672,0.1970329,0,20.7599,-4.400122,4206.272
26.6,-4.433323,-0.1980278,0.005202883,0,0,0,0,0,4.433056,18.88818,0.1980278,0,20.93415,-4.433323,4220.153
26.8,-4.466789,-0.1990261,0.005229109,0,0,0,0,0,4.466523,19.03077,0.199026,0,21.1101,-4.466789,4233.97
27,-4.500256,-0.2000607,0.005256293,0,0,0,0,0,4.499989,19.17337,0.2000607,0,21.28637,-4.500256,4248.485
27.2,-4.533723,-0.200974,0.00528029,0,0,0,0,0,4.533456,19.31596,0.200974,0,21.46294,-4.533723,4260.351
27.4,-4.566922,-0.2018705,0.005303843,0,0,0,0,0,4.566656,19.45742,0.2018705,0,21.63841,-4.566922,4271.852
27.6,-4.600122,-0.202801,0.00532829,0,0,0,0,0,4.599856,19.59887,0.202801,0,21.8142,-4.600122,4284.005
27.8,-4.633722,-0.2035689,0.005348466,0,0,0,0,0,4.633455,19.74203,0.2035689,0,21.99241,-4.633722,4292.57
28,-4.667055,-0.2044216,0.005370868,0,0,0,0,0,4.666789,19.88406,0.2044216,0,22.16954,-4.667055,4302.922
28.2,-4.700122,-0.2052193,0.005391827,0,0,0,0,0,4.699855,20.02495,0.2052193,0,22.34554,-4.700122,4312.116
28.4,-4.733455,-0.2060198,0.005412861,0,0,0,0,0,4.733189,20.16697,0.2060198,0,22.52329,-4.733455,4321.251
28.6,-4.766922,-0.2068685,0.005435158,0,0,0,0,0,4.766655,20.30957,0.2068685,0,22.70206,-4.766922,4331.301
28.8,-4.800388,-0.2076517,0.005455734,0,0,0,0,0,4.800121,20.45216,0.2076516,0,22.88115,-4.800388,4339.919
29,-4.833588,-0.2082641,0.005471824,0,0,0,0,0,4.833322,20.59362,0.2082641,0,23.05914,-4.833588,4344.978
29.2,-4.866921,-0.208856,0.005487377,0,0,0,0,0,4.866654,20.73564,0.208856,0,23.23816,-4.866921,4349.534
29.4,-4.900255,-0.209698,0.005509499,0,0,0,0,0,4.899989,20.87767,0.209698,0,23.4175,-4.900255,4359.244
29.6,-4.933455,-0.2105291,0.005531336,0,0,0,0,0,4.933188,21.01912,0.2105291,0,23.59644,-4.933455,4368.698
29.8,-4.966788,-0.2112395,0.005549998,0,0,0,0,0,4.966522,21.16115,0.2112395,0,23.77643,-4.966788,4375.555
30,-5.000121,-0.2120529,0.005571371,0,0,0,0,0,4.999854,21.30317,0.2120529,0,23.95673,-5.000121,4384.493
30.2,-5.033454,-0.2130758,0.005598246,0,0,0,0,0,5.033187,21.4452,0.2130758,0,24.13737,-5.033454,4397.691
30.4,-5.067054,-0.2138437,0.00561842,0,0,0,0,0,5.066788,21.58836,0.2138437,0,24.31978,-5.067054,4405.496
30.6,-5.100388,-0.2146856,0.005640542,0,0,0,0,0,5.100121,21.73038,0.2146856,0,24.50107,-5.100388,4414.83
30.8,-5.133587,-0.2159917,0.005674857,0,0,0,0,0,5.133321,21.87184,0.2159917,0,24.68196,-5.133587,4433.661
31,-5.167054,-0.2166551,0.005692285,0,0,0,0,0,5.166787,22.01443,0.2166551,0,24.86464,-5.167054,4439.161
31.2,-5.200387,-0.2174782,0.005713911,0,0,0,0,0,5.20012,22.15646,0.2174782,0,25.04692,-5.200387,4447.911
31.4,-5.233454,-0.2184677,0.005739911,0,0,0,0,0,5.233188,22.29735,0.2184677,0,25.22808,-5.233454,4460.063
31.6,-5.266654,-0.2191701,0.005758364,0,0,0,0,0,5.266387,22.4388,0.2191701,0,25.41029,-5.266654,4466.256
31.8,-5.30052,-0.2202906,0.005787803,0,0,0,0,0,5.300254,22.5831,0.2202906,0,25.59651,-5.30052,4480.737
32,-5.333854,-0.220985,0.005806047,0,0,0,0,0,5.333587,22.72513,0.220985,0,25.78013,-5.333854,4486.615
32.2,-5.367054,-0.2218819,0.005829613,0,0,0,0,0,5.366787,22.86658,0.2218819,0,25.96336,-5.367054,4496.58
32.4,-5.400253,-0.2226572,0.005849982,0,0,0,0,0,5.399987,23.00804,0.2226572,0,26.14692,-5.400253,4504.016
32.6,-5.433587,-0.2232505,0.005865572,0,0,0,0,0,5.43332,23.15006,0.2232505,0,26.33156,-5.433587,4507.688
32.8,-5.466787,-0.2237541,0.005878801,0,0,0,0,0,5.46652,23.29152,0.2237541,0,26.51579,-5.466787,4509.539
33,-5.499986,-0.224549,0.005899686,0,0,0,0,0,5.49972,23.43298,0.224549,0,26.70037,-5.499986,4517.214
33.2,-5.533453,-0.2253644,0.005921109,0,0,0,0,0,5.533187,23.57557,0.2253644,0,26.88678,-5.533453,4525.174
33.4,-5.56692,-0.2254523,0.00592342,0,0,0,0,0,5.566653,23.71816,0.2254523,0,27.07353,-5.56692,4518.493
33.6,-5.600386,-0.2262614,0.005944679,0,0,0,0,0,5.60012,23.86076,0.2262615,0,27.26064,-5.600386,4526.233
33.8,-5.63372,-0.2266795,0.005955661,0,0,0,0,0,5.633453,24.00278,0.2266795,0,27.44735,-5.63372,4526.137
34,-5.66692,-0.2272406,0.005970403,0,0,0,0,0,5.666653,24.14424,0.2272406,0,27.63365,-5.66692,4528.895
34.2,-5.700253,-0.2278033,0.005985189,0,0,0,0,0,5.699986,24.28626,0.2278033,0,27.82106,-5.700253,4531.61
34.4,-5.73372,-0.2279053,0.005987868,0,0,0,0,0,5.733453,24.42886,0.2279053,0,28.00957,-5.73372,4525.1
34.6,-5.766653,-0.2286201,0.006006648,0,0,0,0,0,5.766386,24.56918,0.2286201,0,28.19542,-5.766653,4530.864
34.8,-5.800119,-0.2286479,0.006007378,0,0,0,0,0,5.799853,24.71177,0.2286479,0,28.38464,-5.800119,4522.849
35,-5.833586,-0.2288655,0.006013095,0,0,0,0,0,5.833319,24.85436,0.2288655,0,28.57421,-5.833586,4518.579
35.2,-5.867052,-0.2297031,0.006035104,0,0,0,0,0,5.866786,24.99696,0.2297031,0,28.76415,-5.867052,4526.512
35.4,-5.900386,-0.2295204,0.006030302,0,0,0,0,0,5.900119,25.13898,0.2295204,0,28.95369,-5.900386,4514.345
35.6,-5.933586,-0.2301584,0.006047064,0,0,0,0,0,5.933319,25.28044,0.2301584,0,29.14283,-5.933586,4518.34
35.8,-5.967052,-0.2309082,0.006066766,0,0,0,0,0,5.966785,25.42303,0.2309082,0,29.33385,-5.967052,4524.41
36,-6.000252,-0.2315258,0.006082992,0,0,0,0,0,5.999985,25.56449,0.2315258,0,29.5237,-6.000252,4527.906
36.2,-6.033319,-0.2322681,0.006102494,0,0,0,0,0,6.033052,25.70538,0.2322681,0,29.71316,-6.033319,4533.825
36.4,-6.066785,-0.2325929,0.006111028,0,0,0,0,0,6.066518,25.84797,0.2325929,0,29.90527,-6.066785,4531.451
36.6,-6.100119,-0.2337116,0.006140419,0,0,0,0,0,6.099852,25.99,0.2337116,0,30.09699,-6.100119,4544.524
36.8,-6.133585,-0.2347368,0.006167355,0,0,0,0,0,6.133319,26.13259,0.2347368,0,30.28985,-6.133585,4555.665
37,-6.166918,-0.2356376,0.006191022,0,0,0,0,0,6.166651,26.27461,0.2356376,0,30.4823,-6.166918,4564.355
37.2,-6.200118,-0.2358183,0.006195771,0,0,0,0,0,6.199852,26.41607,0.2358183,0,30.67435,-6.200118,4559.092
37.4,-6.233718,-0.2360074,0.00620074,0,0,0,0,0,6.233451,26.55923,0.2360074,0,30.8691,-6.233718,4553.871
37.6,-6.266918,-0.2368659,0.006223293,0,0,0,0,0,6.266651,26.70069,0.2368658,0,31.06189,-6.266918,4561.631
37.8,-6.299985,-0.237093,0.006229262,0,0,0,0,0,6.299718,26.84158,0.237093,0,31.25429,-6.299985,4557.23
38,-6.333451,-0.2381905,0.006258097,0,0,0,0,0,6.333184,26.98417,0.2381905,0,31.44939,-6.333451,4569.401
38.2,-6.367051,-0.2388828,0.006276285,0,0,0,0,0,6.366785,27.12733,0.2388828,0,31.64565,-6.367051,4573.696
38.4,-6.400384,-0.2397877,0.00630006,0,0,0,0,0,6.400118,27.26936,0.2397877,0,31.84074,-6.400384,4582.074
38.6,-6.433584,-0.2396616,0.006296746,0,0,0,0,0,6.433318,27.41081,0.2396616,0,32.03542,-6.433584,4570.757
38.8,-6.466918,-0.2403766,0.006315533,0,0,0,0,0,6.466651,27.55284,0.2403766,0,32.23127,-6.466918,4575.424
39,-6.500384,-0.2405648,0.006320477,0,0,0,0,0,6.500117,27.69543,0.2405648,0,32.42829,-6.500384,4569.994
39.2,-6.533451,-0.2409644,0.006330977,0,0,0,0,0,6.533184,27.83632,0.2409644,0,32.62333,-6.533451,4568.666
39.4,-6.566651,-0.2419402,0.006356615,0,0,0,0,0,6.566384,27.97778,0.2419402,0,32.81954,-6.566651,4578.175
39.6,-6.599984,-0.2422214,0.006364003,0,0,0,0,0,6.599717,28.1198,0.2422214,0,33.01694,-6.599984,4574.458
39.8,-6.633584,-0.2433886,0.006394669,0,0,0,0,0,6.633317,28.26296,0.2433886,0,33.2163,-6.633584,4587.347
40,-6.667051,-0.2438102,0.006405745,0,0,0,0,0,6.666784,28.40556,0.2438102,0,33.41527,-6.667051,4586.158
40.2,-6.70025,-0.2447674,0.006430894,0,0,0,0,0,6.699984,28.54701,0.2447674,0,33.61305,-6.70025,4595.066
40.4,-6.733584,-0.2450536,0.006438413,0,0,0,0,0,6.733317,28.68904,0.2450536,0,33.81201,-6.733584,4591.294
40.6,-6.766917,-0.245601,0.006452797,0,0,0,0,0,6.76665,28.83106,0.245601,0,34.01137,-6.766917,4592.387
40.8,-6.80025,-0.2463789,0.006473235,0,0,0,0,0,6.799984,28.97309,0.2463789,0,34.21113,-6.80025,4597.739
41,-6.833317,-0.2462517,0.006469892,0,0,0,0,0,6.83305,29.11398,0.2462517,0,34.40969,-6.833317,4586.249
41.2,-6.866783,-0.2474646,0.006501759,0,0,0,0,0,6.866517,29.25657,0.2474646,0,34.61105,-6.866783,4599.568
41.4,-6.900383,-0.2472674,0.006496578,0,0,0,0,0,6.900116,29.39973,0.2472674,0,34.81362,-6.900383,4586.602
41.6,-6.933717,-0.2475554,0.006504146,0,0,0,0,0,6.93345,29.54176,0.2475554,0,35.01499,-6.933717,4582.707
41.8,-6.966916,-0.248481,0.006528464,0,0,0,0,0,6.96665,29.68321,0.248481,0,35.21596,-6.966916,4590.606
42,-7.000383,-0.2484495,0.006527637,0,0,0,0,0,7.000116,29.8258,0.2484495,0,35.41895,-7.000383,4580.717
42.2,-7.033716,-0.2488232,0.006537454,0,0,0,0,0,7.03345,29.96783,0.2488232,0,35.62155,-7.033716,4578.321
42.4,-7.066916,-0.2488008,0.006536867,0,0,0,0,0,7.06665,30.10929,0.2488008,0,35.82374,-7.066916,4568.663
42.6,-7.099983,-0.2487912,0.006536615,0,0,0,0,0,7.099716,30.25018,0.2487912,0,36.02553,-7.099983,4559.277
42.8,-7.133449,-0.2489726,0.006541379,0,0,0,0,0,7.133183,30.39277,0.2489726,0,36.23017,-7.133449,4553.273
43,-7.166916,-0.2493548,0.00655142,0,0,0,0,0,7.16665,30.53536,0.2493547,0,36.43524,-7.166916,4550.92
43.2,-7.200382,-0.2499047,0.00656587,0,0,0,0,0,7.200116,30.67795,0.2499047,0,36.64072,-7.200382,4551.596
43.4,-7.233716,-0.2507009,0.006586788,0,0,0,0,0,7.233449,30.81998,0.2507009,0,36.84581,-7.233716,4556.741
43.6,-7.266782,-0.2512088,0.006600133,0,0,0,0,0,7.266515,30.96087,0.2512088,0,37.04967,-7.266782,4556.675
43.8,-7.300382,-0.2520439,0.006622074,0,0,0,0,0,7.300116,31.10403,0.2520439,0,37.25725,-7.300382,4562.342
44,-7.333715,-0.2528421,0.006643044,0,0,0,0,0,7.333448,31.24605,0.2528421,0,37.4636,-7.333715,4567.355
44.2,-7.366649,-0.2534499,0.006659014,0,0,0,0,0,7.366383,31.38638,0.2534499,0,37.66791,-7.366649,4568.991
44.4,-7.400115,-0.2540719,0.006675357,0,0,0,0,0,7.399848,31.52897,0.2540719,0,37.87594,-7.400115,4570.686
44.6,-7.433715,-0.2545949,0.006689097,0,0,0,0,0,7.433448,31.67213,0.2545949,0,38.08524,-7.433715,4570.518
44.8,-7.467048,-0.2553565,0.006709106,0,0,0,0,0,7.466782,31.81415,0.2553565,0,38.29331,-7.467048,4574.661
45,-7.500382,-0.2562424,0.006732384,0,0,0,0,0,7.500115,31.95618,0.2562425,0,38.50183,-7.500382,4580.971
45.2,-7.533715,-0.2569757,0.006751649,0,0,0,0,0,7.533449,32.09821,0.2569757,0,38.71077,-7.533715,4584.491
45.4,-7.567048,-0.2578136,0.006773663,0,0,0,0,0,7.566781,32.24023,0.2578136,0,38.92015,-7.567048,4589.819
45.6,-7.600115,-0.2581861,0.00678345,0,0,0,0,0,7.599848,32.38111,0.2581861,0,39.12829,-7.600115,4586.893
45.8,-7.633314,-0.2584804,0.006791183,0,0,0,0,0,7.633048,32.52257,0.2584804,0,39.3377,-7.633314,4582.515
46,-7.666781,-0.2590312,0.006805655,0,0,0,0,0,7.666514,32.66516,0.2590312,0,39.54925,-7.666781,4582.576
46.2,-7.700115,-0.2595357,0.006818909,0,0,0,0,0,7.699848,32.80719,0.2595357,0,39.7604,-7.700115,4581.816
46.4,-7.733714,-0.2603521,0.00684036,0,0,0,0,0,7.733448,32.95035,0.2603521,0,39.97368,-7.733714,4586.437
46.6,-7.766915,-0.2609215,0.006855318,0,0,0,0,0,7.766648,33.09181,0.2609214,0,40.18488,-7.766915,4586.769
46.8,-7.800248,-0.2617684,0.00687757,0,0,0,0,0,7.799981,33.23383,0.2617684,0,40.39737,-7.800248,4591.89
47,-7.833715,-0.2623521,0.006892905,0,0,0,0,0,7.833448,33.37643,0.262352,0,40.61118,-7.833715,4592.299
47.2,-7.867048,-0.2630908,0.006912313,0,0,0,0,0,7.86678,33.51845,0.2630908,0,40.82457,-7.867048,4595.413
47.4,-7.900114,-0.2638045,0.006931065,0,0,0,0,0,7.899847,33.65934,0.2638045,0,41.03672,-7.900114,4598.114
47.6,-7.933314,-0.2645156,0.006949748,0,0,0,0,0,7.933047,33.8008,0.2645156,0,41.25017,-7.933314,4600.678
47.8,-7.967181,-0.2654902,0.006975355,0,0,0,0,0,7.966914,33.9451,0.2654902,0,41.46839,-7.967181,4607.564
48,-8.000247,-0.2660323,0.006989597,0,0,0,0,0,7.99998,34.08598,0.2660323,0,41.6819,-8.000247,4607.124
48.2,-8.03358,-0.2668126,0.007010098,0,0,0,0,0,8.033314,34.22801,0.2668126,0,41.89761,-8.03358,4610.681
48.4,-8.066914,-0.2676285,0.007031535,0,0,0,0,0,8.066648,34.37004,0.2676285,0,42.11378,-8.066914,4614.794
48.6,-8.10038,-0.2686016,0.007057102,0,0,0,0,0,8.100114,34.51263,0.2686016,0,42.33129,-8.10038,4621.511
48.8,-8.13358,-0.2692415,0.007073915,0,0,0,0,0,8.133313,34.65408,0.2692415,0,42.54752,-8.13358,4622.515
49,-8.166647,-0.2698846,0.007090811,0,0,0,0,0,8.16638,34.79497,0.2698846,0,42.76336,-8.166647,4623.565
49.2,-8.200114,-0.2709314,0.007118315,0,0,0,0,0,8.199847,34.93757,0.2709315,0,42.98229,-8.200114,4631.349
49.4,-8.23358,-0.271726,0.007139191,0,0,0,0,0,8.233314,35.08016,0.271726,0,43.20169,-8.23358,4634.751
49.6,-8.266914,-0.2729586,0.007171576,0,0,0,0,0,8.266647,35.22219,0.2729586,0,43.4207,-8.266914,4645.59
49.8,-8.300247,-0.273969,0.007198123,0,0,0,0,0,8.299979,35.36421,0.273969,0,43.64019,-8.300247,4652.564
50,-8.333446,-0.2752289,0.007231226,0,0,0,0,0,8.333179,35.50566,0.2752289,0,43.85928,-8.333446,4663.731
50.2,-8.367047,-0.2761928,0.007256551,0,0,0,0,0,8.366779,35.64883,0.2761928,0,44.0815,-8.367047,4669.676
50.4,-8.400513,-0.2773098,0.007285896,0,0,0,0,0,8.400247,35.79142,0.2773098,0,44.30334,-8.400513,4678.17
50.6,-8.433446,-0.2783091,0.007312152,0,0,0,0,0,8.433179,35.93174,0.2783091,0,44.52211,-8.433446,4684.768
50.8,-8.466779,-0.2791952,0.007335434,0,0,0,0,0,8.466513,36.07376,0.2791952,0,44.74404,-8.466779,4689.267
51,-8.50038,-0.280929,0.007380986,0,0,0,0,0,8.500113,36.21693,0.280929,0,44.96823,-8.50038,4707.82
51.2,-8.533712,-0.282752,0.007428883,0,0,0,0,0,8.533446,36.35895,0.282752,0,45.19115,-8.533712,4727.819
51.4,-8.566779,-0.2839202,0.007459576,0,0,0,0,0,8.566513,36.49984,0.2839202,0,45.41278,-8.566779,4736.843
51.6,-8.599979,-0.2848913,0.007485088,0,0,0,0,0,8.599712,36.6413,0.2848912,0,45.63579,-8.599979,4742.455
51.8,-8.633712,-0.286345,0.007523282,0,0,0,0,0,8.633446,36.78503,0.2863449,0,45.8629,-8.633712,4755.841
52,-8.666912,-0.2873462,0.007549588,0,0,0,0,0,8.666646,36.92648,0.2873462,0,46.08692,-8.666912,4761.791
52.2,-8.699979,-0.2876903,0.007558628,0,0,0,0,0,8.699713,37.06737,0.2876903,0,46.31054,-8.699979,4756.843
52.4,-8.733446,-0.289536,0.007607122,0,0,0,0,0,8.733178,37.20996,0.289536,0,46.53738,-8.733446,4776.515
52.6,-8.766912,-0.2911468,0.007649445,0,0,0,0,0,8.766645,37.35256,0.2911468,0,46.76473,-8.766912,4792.181
52.8,-8.800379,-0.2917568,0.00766547,0,0,0,0,0,8.800112,37.49515,0.2917568,0,46.9926,-8.800379,4791.291
53,-8.833712,-0.2931253,0.007701427,0,0,0,0,0,8.833446,37.63718,0.2931253,0,47.22009,-8.833712,4802.827
53.2,-8.866779,-0.2934137,0.007709002,0,0,0,0,0,8.866512,37.77806,0.2934137,0,47.44626,-8.866779,4796.69
53.4,-8.900379,-0.2947991,0.007745401,0,0,0,0,0,8.900111,37.92123,0.2947991,0,47.6766,-8.900379,4808.25
53.6,-8.933712,-0.2961246,0.007780229,0,0,0,0,0,8.933445,38.06325,0.2961246,0,47.90565,-8.933712,4818.821
53.8,-8.966645,-0.297232,0.007809323,0,0,0,0,0,8.966378,38.20357,0.297232,0,48.13246,-8.966645,4825.883
54,-9.000111,-0.2986964,0.007847797,0,0,0,0,0,8.999845,38.34616,0.2986964,0,48.36348,-9.000111,4838.468
54.2,-9.033712,-0.2993902,0.007866027,0,0,0,0,0,9.033445,38.48933,0.2993902,0,48.59595,-9.033712,4838.446
54.4,-9.067045,-0.3007576,0.007901954,0,0,0,0,0,9.066778,38.63135,0.3007576,0,48.82711,-9.067045,4849.322
54.6,-9.100378,-0.3016913,0.007926484,0,0,0,0,0,9.10011,38.77337,0.3016913,0,49.0588,-9.100378,4853.119
54.8,-9.133711,-0.3026225,0.007950949,0,0,0,0,0,9.133445,38.9154,0.3026225,0,49.29104,-9.133711,4856.805
55,-9.167044,-0.3039234,0.007985129,0,0,0,0,0,9.166778,39.05743,0.3039234,0,49.52382,-9.167044,4866.343
55.2,-9.200111,-0.3049216,0.008011357,0,0,0,0,0,9.199844,39.19831,0.3049217,0,49.75527,-9.200111,4871.04
55.4,-9.233311,-0.3064544,0.008051626,0,0,0,0,0,9.233045,39.33977,0.3064544,0,49.98819,-9.233311,4884.135
55.6,-9.266644,-0.3076095,0.008081976,0,0,0,0,0,9.266376,39.48179,0.3076095,0,50.22259,-9.266644,4891.067
55.8,-9.300111,-0.3088306,0.008114059,0,0,0,0,0,9.299845,39.62439,0.3088306,0,50.4585,-9.300111,4898.913
56,-9.333711,-0.3104795,0.008157382,0,0,0,0,0,9.333445,39.76755,0.3104795,0,50.6959,-9.333711,4913.391
56.2,-9.366911,-0.3115091,0.008184432,0,0,0,0,0,9.366645,39.90901,0.3115091,0,50.93103,-9.366911,4918.106
56.4,-9.400244,-0.3131607,0.008227827,0,0,0,0,0,9.399978,40.05103,0.3131607,0,51.16765,-9.400244,4932.497
56.6,-9.43371,-0.314654,0.008267059,0,0,0,0,0,9.433444,40.19362,0.314654,0,51.40579,-9.43371,4944.228
56.8,-9.467044,-0.3158079,0.008297378,0,0,0,0,0,9.466778,40.33565,0.3158079,0,51.64355,-9.467044,4950.576
57,-9.500111,-0.3171804,0.008333436,0,0,0,0,0,9.499845,40.47654,0.3171804,0,51.87997,-9.500111,4960.349
57.2,-9.533577,-0.318481,0.008367607,0,0,0,0,0,9.533309,40.61913,0.3184809,0,52.1198,-9.533577,4968.758
57.4,-9.567177,-0.3197314,0.00840046,0,0,0,0,0,9.566911,40.76229,0.3197314,0,52.36119,-9.567177,4976.24
57.6,-9.600377,-0.3214541,0.008445723,0,0,0,0,0,9.60011,40.90375,0.3214541,0,52.60027,-9.600377,4991.106
57.8,-9.633576,-0.3225706,0.008475057,0,0,0,0,0,9.633309,41.0452,0.3225706,0,52.83992,-9.633576,4996.452
58,-9.666909,-0.3236902,0.008504473,0,0,0,0,0,9.666643,41.18723,0.3236902,0,53.08112,-9.666909,5001.716
58.2,-9.700243,-0.3253112,0.008547061,0,0,0,0,0,9.699977,41.32926,0.3253112,0,53.3229,-9.700243,5014.624
58.4,-9.733443,-0.3264567,0.008577158,0,0,0,0,0,9.733177,41.47071,0.3264567,0,53.5643,-9.733443,5020.149
58.6,-9.766643,-0.3276263,0.008607888,0,0,0,0,0,9.766376,41.61217,0.3276263,0,53.80627,-9.766643,5025.959
58.8,-9.800109,-0.3290765,0.008645989,0,0,0,0,0,9.799843,41.75476,0.3290765,0,54.05079,-9.800109,5035.877
59,-9.833443,-0.3305174,0.008683846,0,0,0,0,0,9.833177,41.89679,0.3305174,0,54.29493,-9.833443,5045.594
59.2,-9.867042,-0.3318267,0.008718246,0,0,0,0,0,9.866776,42.03995,0.3318267,0,54.54162,-9.867042,5053.1
59.4,-9.900243,-0.3331714,0.008753577,0,0,0,0,0,9.899977,42.18141,0.3331714,0,54.78598,-9.900243,5061.195
59.6,-9.933443,-0.3345083,0.008788703,0,0,0,0,0,9.933176,42.32286,0.3345084,0,55.03094,-9.933443,5069.072
59.8,-9.967042,-0.3358475,0.008823887,0,0,0,0,0,9.966776,42.46602,0.3358475,0,55.27945,-9.967042,5076.733
60,-10.00051,-0.3372837,0.00886162,0,0,0,0,0,10.00024,42.60862,0.3372837,0,55.5276,-10.00051,5085.807
60.2,-10.03344,-0.3386712,0.008898075,0,0,0,0,0,10.03318,42.74894,0.3386711,0,55.7724,-10.03344,5094.242
60.4,-10.06678,-0.3400165,0.008933421,0,0,0,0,0,10.06651,42.89096,0.3400165,0,56.02078,-10.06678,5101.791
60.6,-10.10038,-0.3415387,0.008973415,0,0,0,0,0,10.10011,43.03413,0.3415387,0,56.27178,-10.10038,5111.784
60.8,-10.13384,-0.3426564,0.009002781,0,0,0,0,0,10.13358,43.17672,0.3426564,0,56.5224,-10.13384,5115.676
61,-10.16691,-0.3434347,0.009023231,0,0,0,0,0,10.16664,43.3176,0.3434348,0,56.77065,-10.16691,5114.583
61.2,-10.20024,-0.3448564,0.009060583,0,0,0,0,0,10.19998,43.45963,0.3448564,0,57.02153,-10.20024,5122.887
61.4,-10.23371,-0.3456156,0.009080528,0,0,0,0,0,10.23344,43.60222,0.3456156,0,57.27404,-10.23371,5121.216
61.6,-10.26678,-0.3464186,0.009101626,0,0,0,0,0,10.26651,43.74311,0.3464186,0,57.52417,-10.26678,5120.292
61.8,-10.29998,-0.3470593,0.009118461,0,0,0,0,0,10.29971,43.88457,0.3470593,0,57.77594,-10.29998,5116.863
62,-10.33344,-0.3484251,0.009154345,0,0,0,0,0,10.33317,44.02716,0.3484251,0,58.03036,-10.33344,5123.946
62.2,-10.36678,-0.3497456,0.009189038,0,0,0,0,0,10.36651,44.16919,0.3497456,0,58.28443,-10.36678,5130.314
62.4,-10.40037,-0.3509166,0.009219805,0,0,0,0,0,10.40011,44.31235,0.3509166,0,58.54118,-10.40037,5134.293
62.6,-10.43357,-0.3527325,0.009267516,0,0,0,0,0,10.43331,44.4538,0.3527325,0,58.79552,-10.43357,5147.752
62.8,-10.46677,-0.3545108,0.009314236,0,0,0,0,0,10.46651,44.59526,0.3545108,0,59.05051,-10.46677,5160.528
63,-10.50024,-0.3556691,0.00934467,0,0,0,0,0,10.49997,44.73785,0.3556691,0,59.30821,-10.50024,5164.065
63.2,-10.53371,-0.3570052,0.009379773,0,0,0,0,0,10.53344,44.88045,0.3570052,0,59.56657,-10.53371,5170.089
63.4,-10.56677,-0.3579046,0.009403403,0,0,0,0,0,10.56651,45.02134,0.3579046,0,59.82251,-10.56677,5169.865
63.6,-10.59997,-0.3594446,0.009443864,0,0,0,0,0,10.59971,45.1628,0.3594446,0,60.08013,-10.59997,5178.751
63.8,-10.63371,-0.3611167,0.009487798,0,0,0,0,0,10.63344,45.30652,0.3611167,0,60.34257,-10.63371,5189.207
64,-10.66704,-0.3619675,0.009510151,0,0,0,0,0,10.66677,45.44855,0.3619675,0,60.60258,-10.66704,5187.926
64.2,-10.70024,-0.3632509,0.00954387,0,0,0,0,0,10.69997,45.59,0.3632509,0,60.86223,-10.70024,5192.819
64.4,-10.73357,-0.3649108,0.009587482,0,0,0,0,0,10.73331,45.73203,0.3649108,0,61.1236,-10.73357,5202.932
64.60001,-10.76704,-0.3667561,0.009635963,0,0,0,0,0,10.76677,45.87462,0.3667561,0,61.3867,-10.76704,5215.502
64.8,-10.80011,-0.368626,0.009685094,0,0,0,0,0,10.79984,46.01551,0.368626,0,61.64734,-10.80011,5228.448
65,-10.83331,-0.3697062,0.009713475,0,0,0,0,0,10.83304,46.15697,0.3697062,0,61.90971,-10.83331,5230.029
65.2,-10.86677,-0.3716688,0.009765037,0,0,0,0,0,10.86651,46.29956,0.3716688,0,62.1749,-10.86677,5243.868
65.4,-10.90011,-0.3731609,0.00980424,0,0,0,0,0,10.89984,46.44159,0.3731609,0,62.43973,-10.90011,5250.996
65.60001,-10.93371,-0.3749087,0.00985016,0,0,0,0,0,10.93344,46.58475,0.3749087,0,62.70738,-10.93371,5261.488
65.8,-10.96704,-0.3766603,0.009896182,0,0,0,0,0,10.96677,46.72677,0.3766603,0,62.97363,-10.96704,5272.015
66,-11.00024,-0.3782811,0.009938766,0,0,0,0,0,10.99997,46.86823,0.3782811,0,63.23951,-11.00024,5280.643
66.20001,-11.03357,-0.3797876,0.009978347,0,0,0,0,0,11.03331,47.01025,0.3797876,0,63.50718,-11.03357,5287.5
66.4,-11.06704,-0.3816645,0.01002766,0,0,0,0,0,11.06677,47.15284,0.3816645,0,63.77663,-11.06704,5299.333
66.60001,-11.09997,-0.3831606,0.01006697,0,0,0,0,0,11.09971,47.29317,0.3831606,0,64.04251,-11.09997,5305.979
66.8,-11.13344,-0.3849437,0.01011382,0,0,0,0,0,11.13317,47.43576,0.3849438,0,64.31341,-11.13344,5316.251
67,-11.16691,-0.3866844,0.01015955,0,0,0,0,0,11.16664,47.57835,0.3866844,0,64.58506,-11.16691,5325.803
67.20001,-11.20051,-0.3882631,0.01020103,0,0,0,0,0,11.20024,47.72152,0.388263,0,64.85853,-11.20051,5332.942
67.4,-11.23344,-0.3896132,0.0102365,0,0,0,0,0,11.23317,47.86184,0.3896132,0,65.12729,-11.23344,5337.123
67.60001,-11.26691,-0.3913659,0.01028255,0,0,0,0,0,11.26664,48.00443,0.3913659,0,65.40116,-11.26691,5346.471
67.8,-11.30037,-0.3932574,0.01033225,0,0,0,0,0,11.30011,48.14702,0.3932574,0,65.67579,-11.30037,5357.577
68,-11.33357,-0.3950125,0.01037836,0,0,0,0,0,11.33331,48.28848,0.3950125,0,65.94896,-11.33357,5366.807
68.20001,-11.36677,-0.3966395,0.01042111,0,0,0,0,0,11.36651,48.42994,0.3966395,0,66.22288,-11.36677,5374.171
68.4,-11.40011,-0.3985443,0.01047115,0,0,0,0,0,11.39984,48.57196,0.3985443,0,66.49866,-11.40011,5385.108
68.60001,-11.43357,-0.4005391,0.01052356,0,0,0,0,0,11.43331,48.71455,0.4005391,0,66.77632,-11.43357,5397.055
68.8,-11.46691,-0.4024262,0.01057314,0,0,0,0,0,11.46664,48.85658,0.4024262,0,67.05363,-11.46691,5407.467
69,-11.50024,-0.4044225,0.01062559,0,0,0,0,0,11.49997,48.9986,0.4044225,0,67.33171,-11.50024,5419.201
69.20001,-11.53357,-0.4064508,0.01067888,0,0,0,0,0,11.53331,49.14063,0.4064508,0,67.61058,-11.53357,5431.213
69.4,-11.56704,-0.4085004,0.01073273,0,0,0,0,0,11.56677,49.28322,0.4085004,0,67.89134,-11.56704,5443.296
69.60001,-11.60037,-0.4106848,0.01079012,0,0,0,0,0,11.6001,49.42524,0.4106848,0,68.17176,-11.60037,5457.079
69.8,-11.63344,-0.4126015,0.01084048,0,0,0,0,0,11.63317,49.56613,0.4126015,0,68.45072,-11.63344,5467.275
70,-11.66677,-0.4146171,0.01089344,0,0,0,0,0,11.66651,49.70816,0.4146171,0,68.73274,-11.66677,5478.511
[...]
52.6,-8.767045,-0.1648741,0.004253417,0,0,0,0,0,8.767045,39.8502,0.1648741,0,50.83322,-8.767045,2558.422
52.8,-8.800245,-0.1653543,0.004265806,0,0,0,0,0,8.800245,40.00111,0.1653544,0,51.08442,-8.800245,2559.436
53,-8.833579,-0.1657901,0.004277048,0,0,0,0,0,8.833579,40.15263,0.1657901,0,51.33727,-8.833579,2559.701
53.2,-8.866645,-0.1661714,0.004286884,0,0,0,0,0,8.866646,40.30293,0.1661714,0,51.58873,-8.866645,2559.144
53.4,-8.900112,-0.1667042,0.004300628,0,0,0,0,0,8.900111,40.45505,0.1667042,0,51.84387,-8.900112,2560.807
53.6,-8.933445,-0.1670933,0.004310668,0,0,0,0,0,8.933445,40.60657,0.1670933,0,52.09866,-8.933445,2560.254
53.8,-8.966778,-0.1674436,0.004319705,0,0,0,0,0,8.966779,40.75808,0.1674436,0,52.35408,-8.966778,2559.076
54,-9.000245,-0.1678321,0.004329727,0,0,0,0,0,9.000244,40.9102,0.1678321,0,52.61119,-9.000245,2558.427
54.2,-9.033712,-0.1684113,0.004344669,0,0,0,0,0,9.033711,41.06232,0.1684113,0,52.86897,-9.033712,2560.647
54.4,-9.066911,-0.1688118,0.004355001,0,0,0,0,0,9.066912,41.21323,0.1688118,0,53.12534,-9.066911,2560.164
54.6,-9.099845,-0.1691022,0.004362492,0,0,0,0,0,9.099845,41.36293,0.1691022,0,53.38031,-9.099845,2558.037
54.8,-9.133444,-0.1695811,0.004374847,0,0,0,0,0,9.133444,41.51566,0.1695811,0,53.64111,-9.133444,2558.601
55,-9.167044,-0.1702357,0.004391735,0,0,0,0,0,9.167045,41.66838,0.1702357,0,53.90259,-9.167044,2561.77
55.2,-9.200111,-0.1707224,0.004404292,0,0,0,0,0,9.200111,41.81869,0.1707224,0,54.1606,-9.200111,2562.475
55.4,-9.233577,-0.171233,0.004417464,0,0,0,0,0,9.233577,41.97081,0.171233,0,54.42239,-9.233577,2563.419
55.6,-9.267177,-0.1720182,0.00443772,0,0,0,0,0,9.267178,42.12354,0.1720182,0,54.68593,-9.267177,2568.395
55.8,-9.300244,-0.1725173,0.004450595,0,0,0,0,0,9.300244,42.27384,0.1725173,0,54.94597,-9.300244,2569.158
56,-9.333577,-0.1731936,0.004468043,0,0,0,0,0,9.333577,42.42535,0.1731936,0,55.20878,-9.333577,2572.46
56.2,-9.366778,-0.1738913,0.004486043,0,0,0,0,0,9.366777,42.57626,0.1738914,0,55.47124,-9.366778,2576.053
56.4,-9.399978,-0.1745434,0.004502865,0,0,0,0,0,9.399978,42.72717,0.1745434,0,55.73439,-9.399978,2578.918
56.6,-9.433444,-0.1751975,0.004519738,0,0,0,0,0,9.433444,42.87929,0.1751975,0,56.00034,-9.433444,2581.706
56.8,-9.466777,-0.1758462,0.004536474,0,0,0,0,0,9.466777,43.0308,0.1758462,0,56.26595,-9.466777,2584.393
57,-9.500111,-0.1766875,0.004558178,0,0,0,0,0,9.500111,43.18232,0.1766875,0,56.53227,-9.500111,2589.851
57.2,-9.533443,-0.1774117,0.004576861,0,0,0,0,0,9.533443,43.33384,0.1774117,0,56.79929,-9.533443,2593.532
57.4,-9.566911,-0.1781953,0.004597077,0,0,0,0,0,9.566911,43.48596,0.1781953,0,57.0681,-9.566911,2597.994
57.6,-9.600244,-0.179065,0.004619511,0,0,0,0,0,9.600244,43.63747,0.179065,0,57.33656,-9.600244,2603.673
57.8,-9.633443,-0.1797165,0.004636319,0,0,0,0,0,9.633443,43.78838,0.1797165,0,57.60467,-9.633443,2606.15
58,-9.666909,-0.1806137,0.004659466,0,0,0,0,0,9.666909,43.9405,0.1806137,0,57.87565,-9.666909,2612.073
58.2,-9.700377,-0.1814443,0.004680894,0,0,0,0,0,9.700377,44.09262,0.1814443,0,58.14738,-9.700377,2616.965
58.4,-9.733576,-0.1823948,0.004705415,0,0,0,0,0,9.733577,44.24353,0.1823948,0,58.41767,-9.733576,2623.573
58.6,-9.766776,-0.1832208,0.004726724,0,0,0,0,0,9.766776,44.39444,0.1832208,0,58.68869,-9.766776,2628.321
58.8,-9.80051,-0.1842314,0.004752795,0,0,0,0,0,9.800509,44.54777,0.1842314,0,58.96483,-9.80051,2635.531
59,-9.833709,-0.1850463,0.004773817,0,0,0,0,0,9.83371,44.69868,0.1850463,0,59.23734,-9.833709,2639.984
59.2,-9.866909,-0.1858305,0.004794048,0,0,0,0,0,9.866909,44.84959,0.1858305,0,59.5106,-9.866909,2643.937
59.4,-9.900109,-0.1867077,0.004816679,0,0,0,0,0,9.900109,45.0005,0.1867077,0,59.7846,-9.900109,2649.15
59.6,-9.933443,-0.187767,0.004844006,0,0,0,0,0,9.933443,45.15201,0.187767,0,60.06047,-9.933443,2656.84
59.8,-9.966776,-0.1886008,0.004865516,0,0,0,0,0,9.966776,45.30353,0.1886008,0,60.33709,-9.966776,2661.266
60,-10.00024,-0.1896117,0.004891597,0,0,0,0,0,10.00024,45.45565,0.1896117,0,60.6156,-10.00024,2668.09
60.2,-10.03344,-0.1907649,0.004921347,0,0,0,0,0,10.03344,45.60656,0.1907649,0,60.89266,-10.03344,2676.89
60.4,-10.06678,-0.1918228,0.004948637,0,0,0,0,0,10.06678,45.75807,0.1918228,0,61.1716,-10.06678,2684.236
60.6,-10.10038,-0.1930062,0.004979168,0,0,0,0,0,10.10038,45.9108,0.1930062,0,61.45356,-10.10038,2693.192
60.8,-10.13358,-0.1941311,0.005008189,0,0,0,0,0,10.13358,46.06171,0.1941312,0,61.73295,-10.13358,2701.331
61,-10.16678,-0.1949115,0.005028319,0,0,0,0,0,10.16678,46.21262,0.1949115,0,62.01312,-10.16678,2704.601
61.2,-10.20011,-0.1958154,0.005051638,0,0,0,0,0,10.20011,46.36413,0.1958154,0,62.29521,-10.20011,2709.49
61.4,-10.23371,-0.1968691,0.005078823,0,0,0,0,0,10.23371,46.51686,0.1968691,0,62.58037,-10.23371,2716.314
61.6,-10.26678,-0.1976842,0.00509985,0,0,0,0,0,10.26678,46.66716,0.1976842,0,62.86179,-10.26678,2719.895
61.8,-10.30024,-0.1987154,0.005126453,0,0,0,0,0,10.30024,46.81928,0.1987154,0,63.14742,-10.30024,2726.285
62,-10.33384,-0.1999405,0.005158057,0,0,0,0,0,10.33384,46.97201,0.1999405,0,63.43503,-10.33384,2735.214
62.2,-10.36704,-0.2009391,0.005183819,0,0,0,0,0,10.36704,47.12292,0.2009391,0,63.72001,-10.36704,2741.052
62.4,-10.40024,-0.2017255,0.005204106,0,0,0,0,0,10.40024,47.27382,0.2017255,0,64.00582,-10.40024,2743.926
62.6,-10.43331,-0.2025335,0.005224953,0,0,0,0,0,10.43331,47.42413,0.2025335,0,64.29129,-10.43331,2747.065
62.8,-10.46677,-0.2034141,0.005247669,0,0,0,0,0,10.46677,47.57625,0.2034141,0,64.58104,-10.46677,2751.025
63,-10.50011,-0.2041987,0.005267911,0,0,0,0,0,10.50011,47.72776,0.2041987,0,64.87048,-10.50011,2753.655
63.2,-10.53344,-0.2050741,0.005290493,0,0,0,0,0,10.53344,47.87928,0.2050741,0,65.16076,-10.53344,2757.443
63.4,-10.56677,-0.2059519,0.005313139,0,0,0,0,0,10.56677,48.0308,0.2059519,0,65.45188,-10.56677,2761.196
63.6,-10.60024,-0.2067879,0.005334707,0,0,0,0,0,10.60024,48.18291,0.2067879,0,65.74502,-10.60024,2764.289
63.8,-10.63384,-0.2076702,0.005357469,0,0,0,0,0,10.63384,48.33564,0.2076702,0,66.0402,-10.63384,2767.902
64,-10.66691,-0.2086434,0.005382575,0,0,0,0,0,10.66691,48.48594,0.2086434,0,66.33155,-10.66691,2772.783
64.2,-10.69997,-0.2091954,0.005396815,0,0,0,0,0,10.69997,48.63625,0.2091954,0,66.62375,-10.69997,2772.007
64.4,-10.73344,-0.2099018,0.00541504,0,0,0,0,0,10.73344,48.78836,0.2099018,0,66.92035,-10.73344,2773.131
64.60001,-10.76717,-0.2107082,0.005435843,0,0,0,0,0,10.76717,48.9417,0.2107082,0,67.22021,-10.76717,2775.449
64.8,-10.80011,-0.2112752,0.005450471,0,0,0,0,0,10.80011,49.0914,0.2112752,0,67.51383,-10.80011,2774.758
65,-10.83357,-0.2119164,0.005467012,0,0,0,0,0,10.83357,49.24352,0.2119164,0,67.81308,-10.83357,2774.863
65.2,-10.86704,-0.2125663,0.005483777,0,0,0,0,0,10.86704,49.39564,0.2125663,0,68.11324,-10.86704,2775.03
65.4,-10.90037,-0.2132477,0.005501357,0,0,0,0,0,10.90037,49.54715,0.2132477,0,68.4131,-10.90037,2775.591
65.60001,-10.93357,-0.213847,0.005516818,0,0,0,0,0,10.93357,49.69806,0.213847,0,68.71266,-10.93357,2775.067
65.8,-10.96691,-0.2145496,0.005534944,0,0,0,0,0,10.96691,49.84958,0.2145496,0,69.01432,-10.96691,2775.798
66,-11.00011,-0.2151299,0.005549912,0,0,0,0,0,11.00011,50.00048,0.2151299,0,69.31568,-11.00011,2774.93
66.20001,-11.03344,-0.2157037,0.005564718,0,0,0,0,0,11.03344,50.152,0.2157037,0,69.61918,-11.03344,2773.9
66.4,-11.06677,-0.2163897,0.005582415,0,0,0,0,0,11.06677,50.30351,0.2163897,0,69.9236,-11.06677,2774.264
66.60001,-11.09997,-0.217089,0.005600455,0,0,0,0,0,11.09997,50.45442,0.217089,0,70.22772,-11.09997,2774.778
66.8,-11.13344,-0.2179374,0.005622341,0,0,0,0,0,11.13344,50.60654,0.2179374,0,70.53523,-11.13344,2777.069
67,-11.16704,-0.218802,0.005644645,0,0,0,0,0,11.16704,50.75927,0.2188019,0,70.8449,-11.16704,2779.464
67.20001,-11.20024,-0.2196977,0.005667753,0,0,0,0,0,11.20024,50.91018,0.2196977,0,71.15184,-11.20024,2782.29
67.4,-11.23344,-0.2202934,0.005683122,0,0,0,0,0,11.23344,51.06109,0.2202934,0,71.45974,-11.23344,2781.258
67.60001,-11.26691,-0.2211203,0.005704453,0,0,0,0,0,11.26691,51.21321,0.2211203,0,71.77106,-11.26691,2783.019
67.8,-11.30037,-0.2217877,0.005721671,0,0,0,0,0,11.30037,51.36533,0.2217877,0,72.08336,-11.30037,2782.716
68,-11.33357,-0.2221952,0.005732184,0,0,0,0,0,11.33357,51.51624,0.2221952,0,72.39413,-11.33357,2779.178
68.20001,-11.36691,-0.2226205,0.005743156,0,0,0,0,0,11.36691,51.66775,0.2226205,0,72.70712,-11.36691,2775.796
68.4,-11.40051,-0.2230309,0.005753742,0,0,0,0,0,11.40051,51.82048,0.2230309,0,73.02362,-11.40051,2772.125
68.60001,-11.43371,-0.2234219,0.005763832,0,0,0,0,0,11.43371,51.97139,0.2234219,0,73.33733,-11.43371,2768.288
68.8,-11.46691,-0.223668,0.005770179,0,0,0,0,0,11.46691,52.1223,0.223668,0,73.65203,-11.46691,2762.629
69,-11.50011,-0.2240636,0.005780385,0,0,0,0,0,11.5001,52.2732,0.2240636,0,73.96772,-11.50011,2758.792
69.20001,-11.53331,-0.2247277,0.005797516,0,0,0,0,0,11.53331,52.42411,0.2247276,0,74.28441,-11.53331,2758.22
69.4,-11.56677,-0.2254352,0.005815769,0,0,0,0,0,11.56677,52.57624,0.2254352,0,74.60468,-11.56677,2758.057
69.60001,-11.60011,-0.2260508,0.005831651,0,0,0,0,0,11.60011,52.72775,0.2260508,0,74.92468,-11.60011,2756.753
69.8,-11.63344,-0.2269181,0.005854024,0,0,0,0,0,11.63344,52.87926,0.2269181,0,75.2457,-11.63344,2758.459
70,-11.66691,-0.2278924,0.005879161,0,0,0,0,0,11.66691,53.03139,0.2278924,0,75.56906,-11.66691,2761.36
70.20001,-11.70024,-0.2289067,0.005905327,0,0,0,0,0,11.70024,53.1829,0.2289067,0,75.89217,-11.70024,2764.703
70.4,-11.73357,-0.2302986,0.005941235,0,0,0,0,0,11.73357,53.33442,0.2302986,0,76.21632,-11.73357,2772.512
70.60001,-11.76664,-0.2317199,0.005977901,0,0,0,0,0,11.76664,53.48472,0.2317199,0,76.53893,-11.76664,2780.637
70.8,-11.80024,-0.2333436,0.006019791,0,0,0,0,0,11.80024,53.63744,0.2333436,0,76.86781,-11.80024,2790.929
71,-11.8337,-0.2347218,0.006055345,0,0,0,0,0,11.8337,53.78956,0.2347218,0,77.19645,-11.8337,2798.201
71.20001,-11.8669,-0.2363443,0.006097201,0,0,0,0,0,11.86691,53.94048,0.2363442,0,77.52356,-11.8669,2808.342
71.4,-11.90024,-0.2376709,0.006131426,0,0,0,0,0,11.90024,54.09199,0.2376709,0,77.85306,-11.90024,2814.816
71.60001,-11.93384,-0.2395048,0.006178737,0,0,0,0,0,11.93384,54.24472,0.2395048,0,78.1863,-11.93384,2827.098
71.8,-11.96704,-0.2414347,0.006228525,0,0,0,0,0,11.96704,54.39563,0.2414348,0,78.51666,-11.96704,2840.48
72,-12.00024,-0.2430063,0.006269068,0,0,0,0,0,12.00024,54.54654,0.2430063,0,78.84811,-12.00024,2849.509
72.20001,-12.03357,-0.2448865,0.006317572,0,0,0,0,0,12.03357,54.69805,0.2448865,0,79.18201,-12.03357,2861.984
72.4,-12.0669,-0.2465474,0.00636042,0,0,0,0,0,12.0669,54.84956,0.2465474,0,79.51702,-12.0669,2871.758
72.60001,-12.10024,-0.248144,0.006401611,0,0,0,0,0,12.10024,55.00108,0.248144,0,79.85317,-12.10024,2880.656
72.8,-12.13344,-0.2500067,0.006449665,0,0,0,0,0,12.13344,55.15199,0.2500067,0,80.18909,-12.13344,2892.547
73,-12.16664,-0.2520749,0.006503019,0,0,0,0,0,12.16664,55.30289,0.2520749,0,80.52615,-12.16664,2906.661
73.20001,-12.2001,-0.2538679,0.006549274,0,0,0,0,0,12.2001,55.45501,0.2538679,0,80.86706,-12.2001,2917.373
73.4,-12.23357,-0.2559226,0.006602283,0,0,0,0,0,12.23357,55.60714,0.2559226,0,81.20915,-12.23357,2930.942
73.60001,-12.2669,-0.2580015,0.006655914,0,0,0,0,0,12.2669,55.75865,0.2580015,0,81.55103,-12.2669,2944.666
73.8,-12.29997,-0.2597368,0.006700681,0,0,0,0,0,12.29997,55.90895,0.2597368,0,81.89135,-12.29997,2954.4
74,-12.33344,-0.2613851,0.006743202,0,0,0,0,0,12.33344,56.06108,0.2613851,0,82.23696,-12.33344,2962.891
74.20001,-12.36704,-0.2630677,0.006786611,0,0,0,0,0,12.36704,56.2138,0.2630677,0,82.58515,-12.36704,2971.599
74.4,-12.4001,-0.2650999,0.006839038,0,0,0,0,0,12.4001,56.36411,0.2650999,0,82.92901,-12.4001,2984.276
74.60001,-12.43344,-0.2667807,0.006882399,0,0,0,0,0,12.43344,56.51562,0.2667807,0,83.27684,-12.43344,2992.768
74.8,-12.46704,-0.2689297,0.006937838,0,0,0,0,0,12.46704,56.66835,0.2689297,0,83.62868,-12.46704,3006.28
75,-12.50024,-0.2709193,0.006989167,0,0,0,0,0,12.50024,56.81925,0.2709193,0,83.97755,-12.50024,3017.974
75.20001,-12.5337,-0.2728356,0.007038604,0,0,0,0,0,12.5337,56.97138,0.2728356,0,84.33046,-12.5337,3028.614
75.4,-12.56677,-0.2746782,0.007086139,0,0,0,0,0,12.56677,57.12168,0.2746782,0,84.68038,-12.56677,3038.417
75.60001,-12.59997,-0.2767858,0.007140511,0,0,0,0,0,12.59997,57.27259,0.2767858,0,85.03295,-12.59997,3050.955
75.8,-12.63344,-0.2789824,0.007197179,0,0,0,0,0,12.63344,57.42471,0.2789824,0,85.38961,-12.63344,3064.22
76,-12.6669,-0.2809294,0.007247406,0,0,0,0,0,12.6669,57.57683,0.2809294,0,85.74755,-12.6669,3074.579
76.20001,-12.69997,-0.2830712,0.007302662,0,0,0,0,0,12.69997,57.72713,0.2830712,0,86.10247,-12.69997,3087.045
76.4,-12.73357,-0.2853957,0.007362628,0,0,0,0,0,12.73357,57.87986,0.2853957,0,86.46442,-12.73357,3101.149
76.60001,-12.76704,-0.2878218,0.007425218,0,0,0,0,0,12.76704,58.03198,0.2878219,0,86.82623,-12.76704,3116.217
76.8,-12.80037,-0.289959,0.007480351,0,0,0,0,0,12.80037,58.18349,0.289959,0,87.1879,-12.80037,3128.021
77,-12.83344,-0.2917991,0.007527824,0,0,0,0,0,12.83344,58.3338,0.2917991,0,87.54798,-12.83344,3136.558
77.20001,-12.86677,-0.2939114,0.007582315,0,0,0,0,0,12.86677,58.48531,0.2939114,0,87.91229,-12.86677,3147.774
77.4,-12.90037,-0.2960988,0.007638747,0,0,0,0,0,12.90037,58.63804,0.2960988,0,88.28085,-12.90037,3159.536
77.60001,-12.93343,-0.2981755,0.007692321,0,0,0,0,0,12.93343,58.78834,0.2981755,0,88.6449,-12.93343,3170.133
77.8,-12.9669,-0.2999793,0.007738856,0,0,0,0,0,12.9669,58.94046,0.2999793,0,89.01471,-12.9669,3177.538
78,-13.00037,-0.301952,0.007789747,0,0,0,0,0,13.00037,59.09258,0.301952,0,89.38588,-13.00037,3186.584
78.20001,-13.0337,-0.303921,0.007840542,0,0,0,0,0,13.0337,59.24409,0.303921,0,89.75695,-13.0337,3195.484
78.4,-13.0669,-0.3058604,0.007890576,0,0,0,0,0,13.0669,59.39501,0.3058604,0,90.12792,-13.0669,3203.968
78.60001,-13.1001,-0.3078074,0.007940804,0,0,0,0,0,13.1001,59.54592,0.3078074,0,90.50026,-13.1001,3212.379
78.8,-13.13343,-0.3099618,0.007996383,0,0,0,0,0,13.13343,59.69743,0.3099618,0,90.87549,-13.13343,3222.748
79,-13.1669,-0.3120545,0.008050372,0,0,0,0,0,13.1669,59.84955,0.3120545,0,91.25366,-13.1669,3232.26
79.20001,-13.2001,-0.3142485,0.008106971,0,0,0,0,0,13.2001,60.00046,0.3142485,0,91.63023,-13.2001,3242.751
79.4,-13.23343,-0.3163643,0.008161554,0,0,0,0,0,13.23343,60.15197,0.3163643,0,92.00973,-13.23343,3252.218
79.60001,-13.2669,-0.3186794,0.00822128,0,0,0,0,0,13.2669,60.30409,0.3186794,0,92.39221,-13.2669,3263.512
79.8,-13.3005,-0.3210563,0.0082826,0,0,0,0,0,13.3005,60.45682,0.3210563,0,92.7777,-13.3005,3275.203
80,-13.33343,-0.323042,0.008333826,0,0,0,0,0,13.33343,60.60652,0.323042,0,93.15698,-13.33343,3282.984
80.20001,-13.36663,-0.325289,0.008391795,0,0,0,0,0,13.36663,60.75743,0.325289,0,93.5408,-13.36663,3293.156
80.4,-13.4001,-0.3278779,0.008458583,0,0,0,0,0,13.4001,60.90955,0.3278779,0,93.92919,-13.4001,3306.498
80.60001,-13.4337,-0.3304309,0.008524446,0,0,0,0,0,13.4337,61.06227,0.3304309,0,94.32066,-13.4337,3319.225
80.8,-13.46677,-0.3325216,0.008578382,0,0,0,0,0,13.46677,61.21258,0.3325216,0,94.70742,-13.46677,3327.333
81.00001,-13.5001,-0.3347748,0.008636508,0,0,0,0,0,13.5001,61.36409,0.3347748,0,95.09881,-13.5001,3336.794
81.20001,-13.5337,-0.3373938,0.008704074,0,0,0,0,0,13.5337,61.51682,0.3373938,0,95.49489,-13.5337,3349.604
81.4,-13.5669,-0.3397336,0.008764436,0,0,0,0,0,13.5669,61.66773,0.3397336,0,95.8878,-13.5669,3359.607
81.60001,-13.60023,-0.3417821,0.008817282,0,0,0,0,0,13.60023,61.81924,0.3417821,0,96.28385,-13.60023,3366.505
81.8,-13.63343,-0.3437969,0.00886926,0,0,0,0,0,13.63343,61.97015,0.3437969,0,96.67989,-13.63343,3372.966
82.00001,-13.66663,-0.346254,0.008932648,0,0,0,0,0,13.66663,62.12106,0.346254,0,97.07749,-13.66663,3383.592
82.20001,-13.7001,-0.3486907,0.00899551,0,0,0,0,0,13.7001,62.27318,0.3486907,0,97.47989,-13.7001,3393.72
82.4,-13.73343,-0.3513034,0.009062911,0,0,0,0,0,13.73343,62.4247,0.3513034,0,97.88232,-13.73343,3405.416
82.60001,-13.76677,-0.3542721,0.009139499,0,0,0,0,0,13.76677,62.57621,0.3542721,0,98.28636,-13.76677,3420.347
82.8,-13.80023,-0.3566458,0.009200735,0,0,0,0,0,13.80023,62.72833,0.3566458,0,98.69367,-13.80023,3429.268
83.00001,-13.8337,-0.3595034,0.009274456,0,0,0,0,0,13.8337,62.88046,0.3595034,0,99.10265,-13.8337,3442.636
83.20001,-13.8669,-0.362413,0.009349517,0,0,0,0,0,13.8669,63.03136,0.362413,0,99.51002,-13.8669,3456.389
83.4,-13.89997,-0.3648031,0.009411177,0,0,0,0,0,13.89997,63.18166,0.3648031,0,99.91742,-13.89997,3465.039
83.60001,-13.93343,-0.3676536,0.009484714,0,0,0,0,0,13.93343,63.33378,0.3676535,0,100.3314,-13.93343,3477.686
83.8,-13.96703,-0.3705483,0.009559392,0,0,0,0,0,13.96703,63.48651,0.3705483,0,100.7488,-13.96703,3490.467
84.00001,-14.0001,-0.3732631,0.009629427,0,0,0,0,0,14.0001,63.63681,0.3732631,0,101.1613,-14.0001,3501.567
84.20001,-14.03357,-0.3761216,0.009703172,0,0,0,0,0,14.03357,63.78893,0.3761216,0,101.5805,-14.03357,3513.622
84.4,-14.06703,-0.3792423,0.009783679,0,0,0,0,0,14.06703,63.94106,0.3792423,0,102.0015,-14.06703,3527.891
84.60001,-14.10037,-0.3823777,0.009864566,0,0,0,0,0,14.10036,64.09257,0.3823777,0,102.4226,-14.10037,3542.113
84.8,-14.13357,-0.3853388,0.009940956,0,0,0,0,0,14.13356,64.24348,0.3853388,0,102.8437,-14.13357,3554.54
85.00001,-14.16677,-0.3884109,0.01002021,0,0,0,0,0,14.16677,64.39439,0.3884109,0,103.2667,-14.16677,3567.757
85.20001,-14.19997,-0.3919158,0.01011063,0,0,0,0,0,14.19996,64.5453,0.3919158,0,103.6914,-14.19997,3584.694
85.4,-14.23343,-0.3955521,0.01020444,0,0,0,0,0,14.23343,64.69742,0.3955521,0,104.1214,-14.23343,3602.43
85.60001,-14.26676,-0.3994145,0.01030408,0,0,0,0,0,14.26676,64.84893,0.3994145,0,104.5515,-14.26676,3621.995
85.8,-14.3001,-0.4034567,0.01040836,0,0,0,0,0,14.3001,65.00045,0.4034567,0,104.9835,-14.3001,3642.88
86.00001,-14.33356,-0.4076691,0.01051703,0,0,0,0,0,14.33356,65.15257,0.4076691,0,105.4191,-14.33356,3664.917
86.20001,-14.36703,-0.4123021,0.01063656,0,0,0,0,0,14.36703,65.30469,0.4123021,0,105.8566,-14.36703,3690.387
86.4,-14.40023,-0.4171865,0.01076256,0,0,0,0,0,14.40023,65.4556,0.4171865,0,106.2925,-14.40023,3717.863
86.60001,-14.4333,-0.4214654,0.01087295,0,0,0,0,0,14.4333,65.6059,0.4214654,0,106.7285,-14.4333,3739.653
86.8,-14.4669,-0.4265116,0.01100313,0,0,0,0,0,14.4669,65.75863,0.4265116,0,107.1736,-14.4669,3767.623
87.00001,-14.50036,-0.4314823,0.01113136,0,0,0,0,0,14.50037,65.91075,0.4314823,0,107.6188,-14.50036,3794.598
87.20001,-14.53356,-0.4363773,0.01125765,0,0,0,0,0,14.53356,66.06165,0.4363773,0,108.0625,-14.53356,3820.659
87.4,-14.5669,-0.4410151,0.01137729,0,0,0,0,0,14.5669,66.21317,0.4410151,0,108.5099,-14.5669,3844.026
87.60001,-14.60036,-0.4464971,0.01151872,0,0,0,0,0,14.60037,66.3653,0.4464971,0,108.9612,-14.60036,3874.286
87.8,-14.6337,-0.4511103,0.01163773,0,0,0,0,0,14.6337,66.51681,0.4511103,0,109.4127,-14.6337,3896.683
88.00001,-14.66676,-0.4560782,0.01176589,0,0,0,0,0,14.66676,66.66711,0.4560782,0,109.8625,-14.66676,3921.911
88.20001,-14.7001,-0.4609034,0.01189037,0,0,0,0,0,14.7001,66.81863,0.4609034,0,110.3182,-14.7001,3945.388
88.4,-14.73343,-0.4660309,0.01202265,0,0,0,0,0,14.73343,66.97014,0.4660309,0,110.7758,-14.73343,3971.064
88.60001,-14.76676,-0.4712553,0.01215743,0,0,0,0,0,14.76676,67.12165,0.4712553,0,111.2356,-14.76676,3997.162
88.8,-14.8001,-0.4763296,0.01228833,0,0,0,0,0,14.8001,67.27317,0.4763296,0,111.6975,-14.8001,4021.582
89.00001,-14.83343,-0.4812938,0.0124164,0,0,0,0,0,14.83343,67.42468,0.4812938,0,112.1615,-14.83343,4044.682
89.20001,-14.8669,-0.4863998,0.01254812,0,0,0,0,0,14.8669,67.57681,0.4863998,0,112.6296,-14.8669,4068.503
89.4,-14.90036,-0.4919221,0.01269059,0,0,0,0,0,14.90036,67.72893,0.4919221,0,113.0999,-14.90036,4095.389
89.60001,-14.93356,-0.4974252,0.01283256,0,0,0,0,0,14.93356,67.87984,0.4974252,0,113.5686,-14.93356,4121.839
89.8,-14.96663,-0.502522,0.01296404,0,0,0,0,0,14.96663,68.03014,0.502522,0,114.0377,-14.96663,4144.587
90.00001,-15.0001,-0.5081531,0.01310931,0,0,0,0,0,15.0001,68.18226,0.508153,0,114.5146,-15.0001,4171.088
90.106,-15.0181,-0.5116177,0.0131987,0,0,0,0,0,15.0181,68.26408,0.5116177,0,114.7721,-15.0181,4188.728