File: GFBaking/data/1TspPectin/1TspPectin_1.is_comp_RawData/Specimen_RawData_2.csv
Time,Extension,Load
(sec),(mm),(N)
0.00000,0.00000,-0.00142
0.10000,-0.00533,-0.00087
0.20000,-0.02467,-0.01050
0.30000,-0.04520,-0.02392
0.40000,-0.06400,-0.03409
0.50000,-0.08187,-0.04234
0.60000,-0.09933,-0.05502
0.70000,-0.11600,-0.06577
0.80000,-0.13293,-0.07613
0.90000,-0.14973,-0.08939
1.00000,-0.16640,-0.10250
1.10000,-0.18347,-0.11699
1.20000,-0.20013,-0.13047
1.30000,-0.21680,-0.14705
1.40000,-0.23333,-0.16313
1.50000,-0.25000,-0.18023
1.60000,-0.26640,-0.19891
1.70000,-0.28320,-0.21826
1.80000,-0.30013,-0.23728
1.90000,-0.31667,-0.25775
2.00000,-0.33347,-0.27949
2.10000,-0.34987,-0.30028
2.20000,-0.36667,-0.32378
2.30000,-0.38320,-0.34758
2.40000,-0.39987,-0.37114
2.50000,-0.41640,-0.39685
2.60000,-0.43333,-0.42291
2.70000,-0.45000,-0.44837
2.80000,-0.46653,-0.47592
2.90000,-0.48360,-0.50370
3.00000,-0.49973,-0.52951
3.10000,-0.51640,-0.55813
3.20000,-0.53320,-0.58614
3.30000,-0.54987,-0.61528
3.40000,-0.56653,-0.64424
3.50000,-0.58347,-0.67473
3.60000,-0.60013,-0.70471
3.70000,-0.61653,-0.73562
3.80000,-0.63360,-0.76630
3.90000,-0.64973,-0.79674
4.00000,-0.66653,-0.82927
4.10000,-0.68320,-0.86133
4.20000,-0.69986,-0.89360
4.30000,-0.71680,-0.92873
4.40000,-0.73346,-0.95889
4.50000,-0.75013,-0.99284
4.60000,-0.76680,-1.02626
4.70000,-0.78346,-1.05863
4.80000,-0.79986,-1.09196
4.90000,-0.81653,-1.12459
5.00000,-0.83346,-1.15755
5.10000,-0.84986,-1.19038
5.20000,-0.86693,-1.22356
5.30000,-0.88346,-1.25694
5.40000,-0.90013,-1.29010
5.50000,-0.91666,-1.32326
5.60000,-0.93346,-1.35612
5.70000,-0.94986,-1.38912
5.80000,-0.96666,-1.42305
5.90000,-0.98346,-1.45516
6.00000,-0.99986,-1.48925
6.10000,-1.01680,-1.52387
6.20000,-1.03320,-1.55826
6.30000,-1.04986,-1.59233
6.40000,-1.06653,-1.62579
6.50000,-1.08306,-1.65776
6.60000,-1.09986,-1.69072
6.70000,-1.11666,-1.72230
6.80000,-1.13333,-1.75296
6.90000,-1.14986,-1.78155
7.00000,-1.16680,-1.80894
7.10000,-1.18293,-1.83329
7.20000,-1.20000,-1.84454
7.30000,-1.21653,-1.86125
7.40000,-1.23320,-1.88940
7.50000,-1.25013,-1.91630
7.60000,-1.26680,-1.91789
7.70000,-1.28346,-1.94063
7.80000,-1.30000,-1.97558
7.90000,-1.31680,-2.01286
8.00000,-1.33306,-2.04502
8.10000,-1.35000,-2.07771
8.20000,-1.36680,-2.10473
8.30000,-1.38320,-2.13886
8.40000,-1.40026,-2.10201
8.50000,-1.41680,-2.12451
8.60000,-1.43333,-2.13541
8.70000,-1.45000,-2.14165
8.80000,-1.46666,-2.15018
8.90000,-1.48320,-2.18382
9.00000,-1.50000,-2.22124
9.10000,-1.51680,-2.25306
9.20000,-1.53333,-2.28330
9.30000,-1.55026,-2.31280
9.40000,-1.56653,-2.34509
9.50000,-1.58320,-2.37915
9.60000,-1.59986,-2.41175
9.70000,-1.61640,-2.44354
9.80000,-1.63320,-2.47735
9.90000,-1.65013,-2.51036
10.00000,-1.66666,-2.54145
10.10000,-1.68320,-2.57307
10.20000,-1.70026,-2.60357
10.30000,-1.71640,-2.63332
10.40000,-1.73320,-2.66412
10.50000,-1.74973,-2.69192
10.60000,-1.76653,-2.72162
10.70000,-1.78346,-2.75149
10.80000,-1.80013,-2.78045
10.90000,-1.81680,-2.80868
11.00000,-1.83333,-2.83676
11.10000,-1.84986,-2.86261
11.20000,-1.86653,-2.88903
11.30000,-1.88333,-2.91721
11.40000,-1.90013,-2.94389
11.50000,-1.91666,-2.97137
11.60000,-1.93360,-2.99789
11.70000,-1.95000,-3.02154
11.80000,-1.96680,-3.04680
11.90000,-1.98333,-3.07146
12.00000,-2.00000,-3.09709
12.10000,-2.01653,-3.12127
12.20000,-2.03333,-3.14480
12.30000,-2.05013,-3.16898
12.40000,-2.06653,-3.19272
12.50000,-2.08359,-3.21700
12.60000,-2.09986,-3.24151
12.70000,-2.11653,-3.26709
12.80000,-2.13319,-3.28984
12.90000,-2.14973,-3.31455
13.00000,-2.16653,-3.33903
13.10000,-2.18333,-3.36248
13.20000,-2.20013,-3.38482
13.30000,-2.21653,-3.40902
13.40000,-2.23346,-3.43417
13.50000,-2.24973,-3.45409
13.60000,-2.26653,-3.47925
13.70000,-2.28319,-3.49960
13.80000,-2.29999,-3.52435
13.90000,-2.31693,-3.54822
14.00000,-2.33346,-3.57156
14.10000,-2.35013,-3.59434
14.20000,-2.36666,-3.61749
14.30000,-2.38346,-3.63952
14.40000,-2.39986,-3.66185
14.50000,-2.41653,-3.68376
14.60000,-2.43333,-3.70467
14.70000,-2.44999,-3.72512
14.80000,-2.46693,-3.74644
14.90000,-2.48333,-3.76573
15.00000,-2.49986,-3.78406
15.10000,-2.51639,-3.80471
15.20000,-2.53333,-3.82360
15.30000,-2.54986,-3.84182
15.40000,-2.56666,-3.86315
15.50000,-2.58346,-3.88069
15.60000,-2.59986,-3.90101
15.70000,-2.61693,-3.91895
15.80000,-2.63319,-3.93676
15.90000,-2.64986,-3.95371
16.00000,-2.66653,-3.97206
16.10000,-2.68306,-3.98876
16.20000,-2.69986,-4.00734
16.30000,-2.71666,-4.02427
16.40000,-2.73333,-4.04160
16.50000,-2.74986,-4.06142
16.60000,-2.76679,-4.07936
16.70000,-2.78306,-4.09489
16.80000,-2.79986,-4.11199
16.90000,-2.81653,-4.12755
17.00000,-2.83319,-4.14513
17.10000,-2.85013,-4.16291
17.20000,-2.86666,-4.17896
17.30000,-2.88346,-4.19396
17.40000,-2.89999,-4.21012
17.50000,-2.91679,-4.22502
17.60000,-2.93306,-4.23980
17.70000,-2.94999,-4.25633
17.80000,-2.96666,-4.27177
17.90000,-2.98333,-4.28842
18.00000,-3.00026,-4.30280
18.10000,-3.01666,-4.31719
18.20000,-3.03346,-4.33329
18.30000,-3.04999,-4.34713
18.40000,-3.06666,-4.36157
18.50000,-3.08306,-4.37536
18.60000,-3.09999,-4.39102
18.70000,-3.11679,-4.40372
18.80000,-3.13333,-4.41813
18.90000,-3.15026,-4.43076
19.00000,-3.16639,-4.44109
19.10000,-3.18306,-4.45254
19.20000,-3.19986,-4.46515
19.30000,-3.21653,-4.47592
19.40000,-3.23319,-4.48727
19.50000,-3.25013,-4.49903
19.60000,-3.26666,-4.50960
19.70000,-3.28319,-4.52261
19.80000,-3.30013,-4.53417
19.90000,-3.31639,-4.54521
20.00000,-3.33319,-4.55910
20.10000,-3.34986,-4.57037
20.20000,-3.36653,-4.58266
20.30000,-3.38346,-4.59475
20.40000,-3.39999,-4.60652
20.50000,-3.41679,-4.61730
20.60000,-3.43332,-4.63002
20.70000,-3.45012,-4.64292
20.80000,-3.46652,-4.65161
20.90000,-3.48332,-4.66410
21.00000,-3.49999,-4.67429
21.10000,-3.51666,-4.68497
21.20000,-3.53359,-4.69632
21.30000,-3.54999,-4.70561
21.40000,-3.56679,-4.71528
21.50000,-3.58319,-4.72477
21.60000,-3.59986,-4.73393
21.70000,-3.61639,-4.74384
21.80000,-3.63332,-4.75645
21.90000,-3.64999,-4.76511
22.00000,-3.66652,-4.77438
22.10000,-3.68359,-4.78460
22.20000,-3.69986,-4.79284
22.30000,-3.71652,-4.80248
22.40000,-3.73319,-4.81016
22.50000,-3.74972,-4.81859
22.60000,-3.76639,-4.82833
22.70000,-3.78346,-4.83780
22.80000,-3.80012,-4.84588
22.90000,-3.81652,-4.85491
23.00000,-3.83346,-4.86327
23.10000,-3.84986,-4.87136
23.20000,-3.86666,-4.88215
23.30000,-3.88332,-4.88819
23.40000,-3.89999,-4.89746
23.50000,-3.91679,-4.90487
23.60000,-3.93332,-4.91155
23.70000,-3.95012,-4.91706
23.80000,-3.96666,-4.92285
23.90000,-3.98346,-4.92506
24.00000,-3.99986,-4.92799
24.10000,-4.01652,-4.93206
24.20000,-4.03332,-4.93585
24.30000,-4.04999,-4.94170
24.40000,-4.06692,-4.94569
24.50000,-4.08332,-4.94884
24.60000,-4.10012,-4.95189
24.70000,-4.11666,-4.95573
24.80000,-4.13332,-4.95854
24.90000,-4.14972,-4.95979
25.00000,-4.16666,-4.96285
25.10000,-4.18332,-4.96669
25.20000,-4.19972,-4.96802
25.30000,-4.21692,-4.97231
25.40000,-4.23319,-4.97315
25.50000,-4.24986,-4.97638
25.60000,-4.26652,-4.97838
25.70000,-4.28306,-4.98147
25.80000,-4.29972,-4.98572
25.90000,-4.31679,-4.99263
26.00000,-4.33332,-4.99408
26.10000,-4.34986,-4.99889
26.20000,-4.36679,-5.00250
26.30000,-4.38319,-5.00499
26.40000,-4.39986,-5.00996
26.50000,-4.41652,-5.01226
26.60000,-4.43306,-5.01674
26.70000,-4.44999,-5.02073
26.80000,-4.46679,-5.02412
26.90000,-4.48346,-5.02597
27.00000,-4.49986,-5.02901
27.10000,-4.51692,-5.03218
27.20000,-4.53319,-5.03245
27.30000,-4.55012,-5.03527
27.40000,-4.56666,-5.03620
27.50000,-4.58332,-5.03907
27.60000,-4.60026,-5.04196
27.70000,-4.61679,-5.04288
27.80000,-4.63332,-5.04425
27.90000,-4.64986,-5.04023
28.00000,-4.66666,-5.04228
28.10000,-4.68306,-5.04380
28.20000,-4.69999,-5.04709
28.30000,-4.71679,-5.04937
28.40000,-4.73319,-5.05321
28.50000,-4.75026,-5.05652
28.60000,-4.76652,-5.06076
28.70000,-4.78319,-5.06581
28.80000,-4.79985,-5.07061
28.90000,-4.81639,-5.07473
29.00000,-4.83319,-5.08123
29.10000,-4.85012,-5.08759
29.20000,-4.86679,-5.09465
29.30000,-4.88319,-5.09829
29.40000,-4.90012,-5.09984
29.50000,-4.91639,-5.10355
29.60000,-4.93319,-5.11118
29.70000,-4.94985,-5.11358
29.80000,-4.96652,-5.11845
29.90000,-4.98332,-5.12349
30.00000,-5.00012,-5.12526
30.10000,-5.01679,-5.12935
30.20000,-5.03332,-5.13172
30.30000,-5.05012,-5.13631
30.40000,-5.06652,-5.14020
30.50000,-5.08332,-5.14828
30.60000,-5.09999,-5.15565
30.70000,-5.11665,-5.16332
30.80000,-5.13359,-5.16743
30.90000,-5.14999,-5.17558
31.00000,-5.16665,-5.18253
31.10000,-5.18332,-5.19090
31.20000,-5.19999,-5.19738
31.30000,-5.21652,-5.20280
31.40000,-5.23332,-5.21109
31.50000,-5.25012,-5.21867
31.60000,-5.26652,-5.22559
31.70000,-5.28359,-5.23508
31.80000,-5.29985,-5.24215
31.90000,-5.31639,-5.24934
32.00000,-5.33319,-5.25623
32.10000,-5.34972,-5.26427
32.20000,-5.36652,-5.27303
32.30000,-5.38345,-5.28257
32.40000,-5.40012,-5.28925
32.50000,-5.41652,-5.29825
32.60000,-5.43345,-5.30639
32.70000,-5.44972,-5.31268
32.80000,-5.46652,-5.32238
32.90000,-5.48319,-5.33060
33.00000,-5.49999,-5.34000
33.10000,-5.51679,-5.34954
33.20000,-5.53332,-5.35638
33.30000,-5.55012,-5.36344
33.40000,-5.56665,-5.35651
33.50000,-5.58345,-5.36543
33.60000,-5.59972,-5.37311
33.70000,-5.61665,-5.38394
33.80000,-5.63345,-5.39089
33.90000,-5.64985,-5.39782
34.00000,-5.66692,-5.40873
34.10000,-5.68332,-5.41849
34.20000,-5.69999,-5.42781
34.30000,-5.71652,-5.43652
34.40000,-5.73319,-5.44462
34.50000,-5.74972,-5.45150
34.60000,-5.76665,-5.46141
34.70000,-5.78345,-5.46897
34.80000,-5.79985,-5.47702
34.90000,-5.81679,-5.48296
35.00000,-5.83319,-5.49083
35.10000,-5.84999,-5.50040
35.20000,-5.86665,-5.50607
35.30000,-5.88319,-5.51227
35.40000,-5.89985,-5.52051
35.50000,-5.91665,-5.52892
35.60000,-5.93332,-5.53577
35.70000,-5.94985,-5.54459
35.80000,-5.96679,-5.55259
35.90000,-5.98319,-5.55757
36.00000,-5.99985,-5.56802
36.10000,-6.01652,-5.57490
36.20000,-6.03305,-5.58693
36.30000,-6.05012,-5.59997
36.40000,-6.06665,-5.60426
36.50000,-6.08345,-5.60845
36.60000,-6.09998,-5.61551
36.70000,-6.11679,-5.62270
36.80000,-6.13319,-5.62748
36.90000,-6.14998,-5.63392
37.00000,-6.16665,-5.63965
37.10000,-6.18319,-5.64578
37.20000,-6.20025,-5.65435
37.30000,-6.21665,-5.65879
37.40000,-6.23345,-5.66680
37.50000,-6.24998,-5.67315
37.60000,-6.26665,-5.68063
37.70000,-6.28318,-5.68580
37.80000,-6.29998,-5.69459
37.90000,-6.31678,-5.70130
38.00000,-6.33332,-5.70904
38.10000,-6.35025,-5.71673
38.20000,-6.36652,-5.72169
38.30000,-6.38318,-5.72983
38.40000,-6.39985,-5.73622
38.50000,-6.41625,-5.74531
38.60000,-6.43305,-5.75325
38.70000,-6.45012,-5.76308
38.80000,-6.46665,-5.76991
38.90000,-6.48318,-5.77674
39.00000,-6.50012,-5.78566
39.10000,-6.51652,-5.79014
39.20000,-6.53305,-5.79867
39.30000,-6.54985,-5.80696
39.40000,-6.56652,-5.81482
39.50000,-6.58332,-5.82369
39.60000,-6.59998,-5.83220
39.70000,-6.61678,-5.84057
39.80000,-6.63332,-5.84925
39.90000,-6.65012,-5.85585
40.00000,-6.66652,-5.86179
40.10000,-6.68318,-5.87079
40.20000,-6.70012,-5.87857
40.30000,-6.71665,-5.88526
40.40000,-6.73358,-5.89289
40.50000,-6.75012,-5.89763
40.60000,-6.76678,-5.90556
40.70000,-6.78345,-5.91537
40.80000,-6.79998,-5.92255
40.90000,-6.81652,-5.93277
41.00000,-6.83332,-5.94092
41.10000,-6.85012,-5.94738
41.20000,-6.86665,-5.95442
41.30000,-6.88358,-5.96152
41.40000,-6.89985,-5.96868
41.50000,-6.91652,-5.97418
41.60000,-6.93318,-5.98072
41.70000,-6.94985,-5.98756
41.80000,-6.96652,-5.99357
41.90000,-6.98345,-6.00333
42.00000,-6.99998,-6.00658
42.10000,-7.01652,-6.01541
42.20000,-7.03358,-6.02196
42.30000,-7.04985,-6.02755
42.40000,-7.06652,-6.03434
42.50000,-7.08318,-6.03663
42.60000,-7.09985,-6.04521
42.70000,-7.11678,-6.05233
42.80000,-7.13332,-6.05830
42.90000,-7.15012,-6.06353
43.00000,-7.16665,-6.07271
43.10000,-7.18345,-6.08111
43.20000,-7.19972,-6.08580
43.30000,-7.21652,-6.09751
43.40000,-7.23332,-6.10148
43.50000,-7.24985,-6.11146
43.60000,-7.26692,-6.12105
43.70000,-7.28345,-6.12840
43.80000,-7.29998,-6.13657
43.90000,-7.31665,-6.14396
44.00000,-7.33332,-6.15094
44.10000,-7.34985,-6.15888
44.20000,-7.36678,-6.16686
44.30000,-7.38345,-6.17616
44.40000,-7.39985,-6.18205
44.50000,-7.41692,-6.18994
44.60000,-7.43318,-6.19683
44.70000,-7.44985,-6.20404
44.80000,-7.46652,-6.20832
44.90000,-7.48305,-6.21453
45.00000,-7.49985,-6.22294
45.10000,-7.51665,-6.23113
45.20000,-7.53332,-6.23852
45.30000,-7.54985,-6.24534
45.40000,-7.56678,-6.25197
45.50000,-7.58305,-6.25731
45.60000,-7.59998,-6.27033
45.70000,-7.61651,-6.27231
45.80000,-7.63318,-6.28088
45.90000,-7.65011,-6.28944
46.00000,-7.66678,-6.29460
46.10000,-7.68358,-6.30195
46.20000,-7.69998,-6.31189
46.30000,-7.71665,-6.32018
46.40000,-7.73305,-6.32541
46.50000,-7.74985,-6.33423
46.60000,-7.76678,-6.34326
46.70000,-7.78331,-6.34905
46.80000,-7.80025,-6.35856
46.90000,-7.81665,-6.36750
47.00000,-7.83345,-6.37348
47.10000,-7.84998,-6.38379
47.20000,-7.86665,-6.38838
47.30000,-7.88318,-6.39480
47.40000,-7.89998,-6.40529
47.50000,-7.91678,-6.40703
47.60000,-7.93318,-6.41535
47.70000,-7.95025,-6.42050
47.80000,-7.96651,-6.42450
47.90000,-7.98331,-6.43275
48.00000,-7.99985,-6.43793
48.10000,-8.01651,-6.44242
48.20000,-8.03305,-6.44819
48.30000,-8.04998,-6.45496
48.40000,-8.06665,-6.45720
48.50000,-8.08318,-6.46387
48.60000,-8.10011,-6.46935
48.70000,-8.11638,-6.47155
48.80000,-8.13318,-6.47955
48.90000,-8.14985,-6.48228
49.00000,-8.16665,-6.48750
49.10000,-8.18331,-6.49427
49.20000,-8.19998,-6.49851
49.30000,-8.21665,-6.50123
49.40000,-8.23318,-6.50581
49.50000,-8.24998,-6.50898
49.60000,-8.26651,-6.51235
49.70000,-8.28331,-6.52115
49.80000,-8.30011,-6.52602
49.90000,-8.31678,-6.53085
50.00000,-8.33358,-6.53549
50.10000,-8.35011,-6.53635
50.20000,-8.36678,-6.54001
50.30000,-8.38331,-6.54555
50.40000,-8.39998,-6.54853
50.50000,-8.41638,-6.55124
50.60000,-8.43318,-6.55617
50.70000,-8.45011,-6.55900
50.80000,-8.46651,-6.56364
50.90000,-8.48345,-6.56805
51.00000,-8.49998,-6.57201
51.10000,-8.51665,-6.57629
51.20000,-8.53318,-6.57808
51.30000,-8.54971,-6.58071
51.40000,-8.56651,-6.58402
51.50000,-8.58345,-6.58822
51.60000,-8.59998,-6.58970
51.70000,-8.61651,-6.59515
51.80000,-8.63358,-6.59749
51.90000,-8.64985,-6.59925
52.00000,-8.66651,-6.60300
52.10000,-8.68318,-6.60283
52.20000,-8.69985,-6.60575
52.30000,-8.71665,-6.60773
52.40000,-8.73345,-6.60818
52.50000,-8.75011,-6.60882
52.60000,-8.76665,-6.60952
52.70000,-8.78345,-6.61148
52.80000,-8.79985,-6.61149
52.90000,-8.81665,-6.61576
53.00000,-8.83331,-6.61543
53.10000,-8.84985,-6.61853
53.20000,-8.86691,-6.61941
53.30000,-8.88331,-6.62118
53.40000,-8.90011,-6.62180
53.50000,-8.91665,-6.62215
53.60000,-8.93331,-6.62212
53.70000,-8.94971,-6.62239
53.80000,-8.96665,-6.62678
53.90000,-8.98345,-6.62807
54.00000,-8.99998,-6.63148
54.10000,-9.01691,-6.63365
54.20000,-9.03318,-6.63571
54.30000,-9.04971,-6.63745
54.40000,-9.06638,-6.64179
54.50000,-9.08304,-6.64669
54.60000,-9.09971,-6.65161
54.70000,-9.11664,-6.65694
54.80000,-9.13331,-6.65777
54.90000,-9.14984,-6.66241
55.00000,-9.16691,-6.66823
55.10000,-9.18304,-6.67022
55.20000,-9.19984,-6.67590
55.30000,-9.21651,-6.67651
55.40000,-9.23318,-6.68163
55.50000,-9.25011,-6.68620
55.60000,-9.26664,-6.68937
55.70000,-9.28344,-6.69194
55.80000,-9.29998,-6.69654
55.90000,-9.31678,-6.69905
56.00000,-9.33318,-6.70124
56.10000,-9.34998,-6.70859
56.20000,-9.36678,-6.71294
56.30000,-9.38331,-6.71860
56.40000,-9.40024,-6.72234
56.50000,-9.41678,-6.72471
56.60000,-9.43344,-6.73183
56.70000,-9.44998,-6.73634
56.80000,-9.46664,-6.74148
56.90000,-9.48318,-6.74586
57.00000,-9.49998,-6.75449
57.10000,-9.51664,-6.75821
57.20000,-9.53304,-6.76553
57.30000,-9.55011,-6.77090
57.40000,-9.56651,-6.77653
57.50000,-9.58318,-6.78227
57.60000,-9.59984,-6.78620
57.70000,-9.61624,-6.78916
57.80000,-9.63304,-6.79430
57.90000,-9.65011,-6.80215
58.00000,-9.66664,-6.80451
58.10000,-9.68331,-6.81039
58.20000,-9.70011,-6.81208
58.30000,-9.71624,-6.81318
58.40000,-9.73318,-6.81871
58.50000,-9.74984,-6.82152
58.60000,-9.76664,-6.82744
58.70000,-9.78331,-6.83176
58.80000,-9.79998,-6.83507
58.90000,-9.81678,-6.84017
59.00000,-9.83344,-6.84720
59.10000,-9.85011,-6.85273
59.20000,-9.86638,-6.85867
59.30000,-9.88318,-6.86553
59.40000,-9.89998,-6.87272
59.50000,-9.91664,-6.88334
59.60000,-9.93358,-6.89510
59.70000,-9.95011,-6.90227
59.80000,-9.96691,-6.90853
59.90000,-9.98331,-6.91581
60.00000,-10.00011,-6.92366
60.10000,-10.01651,-6.93158
60.20000,-10.03331,-6.94166
60.30000,-10.04998,-6.94856
60.40000,-10.06664,-6.95716
60.50000,-10.08358,-6.96609
60.60000,-10.09998,-6.97573
60.70000,-10.11651,-6.98382
60.80000,-10.13318,-6.99055
60.90000,-10.14984,-7.00032
61.00000,-10.16637,-7.00993
61.10000,-10.18331,-7.02099
61.20000,-10.19998,-7.02963
61.30000,-10.21651,-7.03944
61.40000,-10.23344,-7.04753
61.50000,-10.24984,-7.05736
61.60000,-10.26651,-7.06895
61.70000,-10.28317,-7.07835
61.80000,-10.29998,-7.08971
61.90000,-10.31678,-7.09831
62.00000,-10.33358,-7.11027
62.10000,-10.35011,-7.11842
62.20000,-10.36664,-7.13109
62.30000,-10.38331,-7.14023
62.40000,-10.39984,-7.14890
62.50000,-10.41651,-7.16060
62.60000,-10.43344,-7.17014
62.70000,-10.44984,-7.18135
62.80000,-10.46677,-7.19023
62.90000,-10.48331,-7.19734
63.00000,-10.50011,-7.20723
63.10000,-10.51677,-7.21335
63.20000,-10.53344,-7.22066
63.30000,-10.54984,-7.22549
63.40000,-10.56664,-7.23217
63.50000,-10.58344,-7.23811
63.60000,-10.59984,-7.24532
63.70000,-10.61677,-7.25131
63.80000,-10.63317,-7.25680
63.90000,-10.64971,-7.26454
64.00000,-10.66651,-7.26996
64.10001,-10.68317,-7.27805
64.20000,-10.69984,-7.28452
64.30000,-10.71664,-7.29200
64.40000,-10.73331,-7.29716
64.50000,-10.74984,-7.30624
64.60001,-10.76691,-7.31529
64.70000,-10.78304,-7.31990
64.80000,-10.79984,-7.33029
64.90000,-10.81664,-7.33763
65.00000,-10.83331,-7.34753
65.10001,-10.85011,-7.35617
65.20000,-10.86664,-7.36496
65.30000,-10.88344,-7.37151
65.40000,-10.89997,-7.37933
65.50000,-10.91677,-7.38726
65.60001,-10.93317,-7.39354
65.70001,-10.94997,-7.40389
65.80000,-10.96664,-7.41126
65.90000,-10.98317,-7.41827
66.00000,-11.00037,-7.42749
66.10001,-11.01677,-7.43445
66.20001,-11.03344,-7.44083
66.30000,-11.04997,-7.44563
66.40000,-11.06664,-7.45085
66.50000,-11.08317,-7.45608
66.60001,-11.09997,-7.46458
66.70001,-11.11664,-7.47292
66.80000,-11.13304,-7.48041
66.90000,-11.15024,-7.48929
67.00000,-11.16664,-7.49511
67.10001,-11.18331,-7.50366
67.20001,-11.19984,-7.50986
67.30000,-11.21637,-7.51596
67.40000,-11.23304,-7.52523
67.50000,-11.24997,-7.53283
67.60001,-11.26664,-7.54254
67.70001,-11.28317,-7.55202
67.80000,-11.30024,-7.56092
67.90000,-11.31651,-7.56777
68.00000,-11.33317,-7.57615
68.10001,-11.34984,-7.58552
68.20001,-11.36651,-7.59600
68.30000,-11.38331,-7.60529
68.40000,-11.39997,-7.61453
68.50000,-11.41677,-7.62233
68.60001,-11.43331,-7.63307
68.70001,-11.45011,-7.64145
68.80000,-11.46651,-7.64873
68.90000,-11.48331,-7.65797
69.00000,-11.49997,-7.66676
69.10001,-11.51664,-7.67692
69.20001,-11.53357,-7.68714
69.30000,-11.55011,-7.69664
69.40000,-11.56677,-7.70684
69.50000,-11.58330,-7.71775
69.60001,-11.59997,-7.72949
69.70001,-11.61637,-7.73729
69.80000,-11.63330,-7.74789
69.90000,-11.64997,-7.75807
70.00000,-11.66664,-7.76979
70.10001,-11.68357,-7.78052
70.20001,-11.69997,-7.78672
70.30000,-11.71637,-7.79448
70.40000,-11.73304,-7.80392
70.50000,-11.74970,-7.81407
70.60001,-11.76637,-7.82219
70.70001,-11.78317,-7.83489
70.80000,-11.79997,-7.83745
70.90000,-11.81650,-7.85047
71.00000,-11.83344,-7.85775
71.10001,-11.84984,-7.86145
71.20001,-11.86650,-7.86920
71.30000,-11.88317,-7.87869
71.40000,-11.89984,-7.88381
71.50000,-11.91677,-7.89190
71.60001,-11.93344,-7.89632
71.70001,-11.95024,-7.90135
71.80000,-11.96664,-7.90837
71.90000,-11.98344,-7.91193
72.00000,-11.99984,-7.91259
72.10001,-12.01664,-7.91665
72.20001,-12.03344,-7.91642
72.30000,-12.04984,-7.91913
72.40000,-12.06690,-7.92293
72.50000,-12.08330,-7.92643
72.60001,-12.09997,-7.93121
72.70001,-12.11664,-7.93766
72.80000,-12.13317,-7.94267
72.90000,-12.14984,-7.94851
73.00000,-12.16664,-7.94952
73.10001,-12.18344,-7.95988
73.20001,-12.19984,-7.96425
73.30000,-12.21677,-7.96898
73.40000,-12.23317,-7.97101
73.50000,-12.24984,-7.97777
73.60001,-12.26650,-7.98056
73.70001,-12.28304,-7.98639
73.80000,-12.29970,-7.98936
73.90000,-12.31664,-7.99351
74.00000,-12.33344,-7.99453
74.10001,-12.34997,-7.99883
74.20001,-12.36677,-7.99950
74.30000,-12.38304,-7.99806
74.40000,-12.39984,-8.00494
74.50000,-12.41650,-8.00426
74.60001,-12.43330,-8.01199
74.70001,-12.44997,-8.01836
74.80000,-12.46677,-8.02199
74.90000,-12.48357,-8.02533
75.00000,-12.50010,-8.02927
75.10001,-12.51690,-8.03187
75.20001,-12.53317,-8.03408
75.30000,-12.54997,-8.03509
75.40000,-12.56690,-8.03847
75.50000,-12.58330,-8.03861
75.60001,-12.60024,-8.04137
75.70001,-12.61677,-8.04361
75.80000,-12.63344,-8.04840
75.90000,-12.64997,-8.04668
76.00000,-12.66677,-8.04666
76.10001,-12.68317,-8.04414
76.20001,-12.69997,-8.04688
76.30000,-12.71677,-8.04608
76.40000,-12.73330,-8.04861
76.50000,-12.75024,-8.04836
76.60001,-12.76650,-8.04788
76.70001,-12.78317,-8.04985
76.80000,-12.79984,-8.04708
76.90000,-12.81650,-8.05099
77.00000,-12.83317,-8.05407
77.10001,-12.84997,-8.06218
77.20001,-12.86663,-8.06091
77.30000,-12.88317,-8.06785
77.40000,-12.90010,-8.07378
77.50000,-12.91650,-8.07714
77.60001,-12.93330,-8.08815
77.70001,-12.94984,-8.09202
77.80000,-12.96663,-8.09937
77.90000,-12.98343,-8.10658
78.00000,-13.00010,-8.11036
78.10001,-13.01690,-8.11457
78.20001,-13.03330,-8.12066
78.30000,-13.05010,-8.12379
78.40000,-13.06650,-8.12708
78.50000,-13.08330,-8.13363
78.60001,-13.10010,-8.13814
78.70001,-13.11650,-8.14219
78.80000,-13.13357,-8.15077
78.90000,-13.15023,-8.15596
79.00000,-13.16677,-8.16238
79.10001,-13.18343,-8.16844
79.20001,-13.20010,-8.17483
79.30000,-13.21650,-8.17910
79.40000,-13.23317,-8.18684
79.50000,-13.25010,-8.19190
79.60001,-13.26650,-8.19857
79.70001,-13.28357,-8.20212
79.80000,-13.29983,-8.20774
79.90000,-13.31663,-8.21132
80.00000,-13.33317,-8.21524
80.10001,-13.34970,-8.21796
80.20001,-13.36650,-8.22499
80.30000,-13.38343,-8.23207
80.40000,-13.39997,-8.23521
80.50001,-13.41650,-8.24457
80.60001,-13.43357,-8.25042
80.70001,-13.44983,-8.25513
80.80000,-13.46663,-8.26516
80.90000,-13.48317,-8.27033
81.00001,-13.49983,-8.27927
81.10001,-13.51677,-8.28875
81.20001,-13.53343,-8.29701
81.30000,-13.55010,-8.30398
81.40000,-13.56663,-8.31458
81.50001,-13.58357,-8.32231
81.60001,-13.59983,-8.32829
81.70001,-13.61663,-8.33964
81.80000,-13.63343,-8.34984
81.90000,-13.65010,-8.36287
82.00001,-13.66703,-8.37510
82.10001,-13.68343,-8.38574
82.20001,-13.70023,-8.39671
82.30000,-13.71677,-8.40891
82.40000,-13.73330,-8.41897
82.50001,-13.74983,-8.42816
82.60001,-13.76663,-8.44213
82.70001,-13.78330,-8.45033
82.80000,-13.79997,-8.46447
82.90000,-13.81703,-8.47719
83.00001,-13.83330,-8.48785
83.10001,-13.84997,-8.50127
83.20001,-13.86650,-8.51342
83.30000,-13.88303,-8.52770
83.40000,-13.89970,-8.54058
83.50001,-13.91677,-8.55858
83.60001,-13.93343,-8.57066
83.70001,-13.94983,-8.58856
83.80000,-13.96690,-8.60530
83.90000,-13.98317,-8.61986
84.00001,-13.99997,-8.63544
84.10001,-14.01663,-8.64696
84.20001,-14.03330,-8.66285
84.30000,-14.05010,-8.67968
84.40000,-14.06677,-8.69469
84.50001,-14.08357,-8.71123
84.60001,-14.09997,-8.72900
84.70001,-14.11677,-8.74588
84.80000,-14.13317,-8.76192
84.90000,-14.14997,-8.78006
85.00001,-14.16677,-8.79876
85.10001,-14.18330,-8.81915
85.20001,-14.20023,-8.83996
85.30000,-14.21676,-8.85636
85.40000,-14.23330,-8.87560
85.50001,-14.24983,-8.89713
85.60001,-14.26663,-8.91668
85.70001,-14.28303,-8.93600
85.80000,-14.29997,-8.96224
85.90000,-14.31676,-8.98349
86.00001,-14.33330,-9.00732
86.10001,-14.35036,-9.03047
86.20001,-14.36663,-9.05173
86.30000,-14.38330,-9.07426
86.40000,-14.39983,-9.09409
86.50001,-14.41650,-9.11446
86.60001,-14.43303,-9.13934
86.70001,-14.44996,-9.16885
86.80000,-14.46676,-9.18930
86.90000,-14.48330,-9.21651
87.00001,-14.50010,-9.23652
87.10001,-14.51650,-9.26170
87.20001,-14.53330,-9.28644
87.30000,-14.54983,-9.30956
87.40000,-14.56650,-9.33548
87.50001,-14.58330,-9.36238
87.60001,-14.60010,-9.39001
87.70001,-14.61676,-9.41451
87.80000,-14.63330,-9.44232
87.90000,-14.65010,-9.46341
88.00001,-14.66650,-9.48679
88.10001,-14.68330,-9.51321
88.20001,-14.69996,-9.53489
88.30000,-14.71663,-9.56079
88.40000,-14.73356,-9.58615
88.50001,-14.75010,-9.60704
88.60001,-14.76690,-9.63014
88.70001,-14.78330,-9.65208
88.80000,-14.80010,-9.67336
88.90000,-14.81650,-9.69026
89.00001,-14.83343,-9.71832
89.10001,-14.85010,-9.73957
89.20001,-14.86663,-9.76661
89.30000,-14.88370,-9.79219
89.40000,-14.89996,-9.81790
89.50001,-14.91663,-9.84170
89.60001,-14.93316,-9.86625
89.70001,-14.94983,-9.89195
89.80000,-14.96636,-9.91756
89.90000,-14.98343,-9.94615
90.00001,-15.00010,-9.96546
90.06800,-15.01143,-9.98278