File: GFBaking/data/1TspPectin/1TspPectin_1.is_comp_RawData/Specimen_RawData_3.csv
Time,Extension,Load
(sec),(mm),(N)
0.00000,-0.00013,-0.00015
0.10000,-0.00467,-0.00027
0.20000,-0.02387,-0.00012
0.30000,-0.04440,0.00000
0.40000,-0.06360,-0.00022
0.50000,-0.08173,0.00046
0.60000,-0.09920,-0.00062
0.70000,-0.11640,-0.00014
0.80000,-0.13333,0.00055
0.90000,-0.15027,0.00069
1.00000,-0.16653,-0.00066
1.10000,-0.18347,-0.00090
1.20000,-0.19973,-0.00118
1.30000,-0.21680,-0.00241
1.40000,-0.23373,-0.00146
1.50000,-0.25040,-0.00203
1.60000,-0.26720,-0.00250
1.70000,-0.28373,-0.00192
1.80000,-0.30040,-0.00315
1.90000,-0.31680,-0.00302
2.00000,-0.33360,-0.00373
2.10000,-0.35013,-0.00408
2.20000,-0.36693,-0.00385
2.30000,-0.38373,-0.00398
2.40000,-0.40013,-0.00439
2.50000,-0.41693,-0.00446
2.60000,-0.43360,-0.00497
2.70000,-0.45013,-0.00529
2.80000,-0.46667,-0.00478
2.90000,-0.48360,-0.00536
3.00000,-0.50027,-0.00537
3.10000,-0.51680,-0.00617
3.20000,-0.53387,-0.00604
3.30000,-0.55000,-0.00748
3.40000,-0.56667,-0.00696
3.50000,-0.58347,-0.00787
3.60000,-0.60000,-0.00858
3.70000,-0.61680,-0.00997
3.80000,-0.63373,-0.01066
3.90000,-0.65027,-0.01120
4.00000,-0.66693,-0.01334
4.10000,-0.68373,-0.01484
4.20000,-0.70000,-0.01683
4.30000,-0.71680,-0.01846
4.40000,-0.73333,-0.02216
4.50000,-0.75013,-0.02493
4.60000,-0.76706,-0.02831
4.70000,-0.78360,-0.03215
4.80000,-0.80040,-0.03641
4.90000,-0.81706,-0.04282
5.00000,-0.83373,-0.04913
5.10000,-0.85013,-0.05532
5.20000,-0.86693,-0.06277
5.30000,-0.88360,-0.07125
5.40000,-0.90013,-0.07963
5.50000,-0.91720,-0.08811
5.60000,-0.93373,-0.09588
5.70000,-0.95040,-0.10528
5.80000,-0.96693,-0.11380
5.90000,-0.98360,-0.12342
6.00000,-1.00000,-0.13265
6.10000,-1.01693,-0.14292
6.20000,-1.03360,-0.15184
6.30000,-1.05013,-0.16246
6.40000,-1.06706,-0.17299
6.50000,-1.08346,-0.18390
6.60000,-1.10026,-0.19540
6.70000,-1.11666,-0.20569
6.80000,-1.13333,-0.21730
6.90000,-1.15013,-0.22892
7.00000,-1.16693,-0.24223
7.10000,-1.18360,-0.25465
7.20000,-1.20026,-0.26917
7.30000,-1.21706,-0.28330
7.40000,-1.23320,-0.29690
7.50000,-1.25026,-0.31160
7.60000,-1.26680,-0.32765
7.70000,-1.28360,-0.34433
7.80000,-1.30040,-0.36023
7.90000,-1.31693,-0.37686
8.00000,-1.33373,-0.39312
8.10000,-1.35040,-0.41029
8.20000,-1.36693,-0.42636
8.30000,-1.38333,-0.44350
8.40000,-1.40026,-0.46116
8.50000,-1.41693,-0.47875
8.60000,-1.43360,-0.49724
8.70000,-1.45053,-0.51376
8.80000,-1.46693,-0.53113
8.90000,-1.48360,-0.54954
9.00000,-1.50026,-0.56702
9.10000,-1.51693,-0.58539
9.20000,-1.53333,-0.60453
9.30000,-1.55026,-0.62424
9.40000,-1.56680,-0.64295
9.50000,-1.58346,-0.66074
9.60000,-1.60040,-0.67679
9.70000,-1.61680,-0.69994
9.80000,-1.63346,-0.72047
9.90000,-1.65000,-0.74043
10.00000,-1.66666,-0.76005
10.10000,-1.68346,-0.78017
10.20000,-1.70040,-0.80253
10.30000,-1.71693,-0.82364
10.40000,-1.73360,-0.84413
10.50000,-1.75040,-0.86580
10.60000,-1.76680,-0.88556
10.70000,-1.78360,-0.90849
10.80000,-1.79986,-0.92936
10.90000,-1.81680,-0.95012
11.00000,-1.83360,-0.97209
11.10000,-1.85026,-0.99365
11.20000,-1.86706,-1.01646
11.30000,-1.88373,-1.03870
11.40000,-1.90026,-1.05892
11.50000,-1.91666,-1.07877
11.60000,-1.93360,-1.10449
11.70000,-1.95026,-1.12373
11.80000,-1.96693,-1.14615
11.90000,-1.98386,-1.16876
12.00000,-2.00026,-1.18844
12.10000,-2.01706,-1.20967
12.20000,-2.03359,-1.23403
12.30000,-2.05026,-1.25590
12.40000,-2.06666,-1.27866
12.50000,-2.08359,-1.29919
12.60000,-2.10026,-1.31995
12.70000,-2.11679,-1.34301
12.80000,-2.13373,-1.36451
12.90000,-2.15013,-1.38631
13.00000,-2.16693,-1.40951
13.10000,-2.18346,-1.43006
13.20000,-2.19999,-1.45210
13.30000,-2.21666,-1.47424
13.40000,-2.23359,-1.49726
13.50000,-2.25013,-1.51911
13.60000,-2.26693,-1.54029
13.70000,-2.28373,-1.56347
13.80000,-2.29999,-1.58377
13.90000,-2.31693,-1.60734
14.00000,-2.33333,-1.62828
14.10000,-2.35026,-1.64990
14.20000,-2.36706,-1.67222
14.30000,-2.38359,-1.69179
14.40000,-2.40039,-1.71459
14.50000,-2.41706,-1.73461
14.60000,-2.43386,-1.75703
14.70000,-2.44999,-1.77583
14.80000,-2.46693,-1.79819
14.90000,-2.48346,-1.81493
15.00000,-2.50026,-1.83623
15.10000,-2.51719,-1.85449
15.20000,-2.53359,-1.87545
15.30000,-2.55026,-1.89785
15.40000,-2.56666,-1.91790
15.50000,-2.58359,-1.94266
15.60000,-2.59999,-1.96260
15.70000,-2.61693,-1.98620
15.80000,-2.63359,-2.00607
15.90000,-2.65026,-2.02803
16.00000,-2.66719,-2.04993
16.10000,-2.68346,-2.07076
16.20000,-2.70026,-2.09153
16.30000,-2.71666,-2.11193
16.40000,-2.73346,-2.13138
16.50000,-2.75013,-2.15234
16.60000,-2.76693,-2.16997
16.70000,-2.78359,-2.18141
16.80000,-2.80026,-2.18921
16.90000,-2.81706,-2.18708
17.00000,-2.83346,-2.21517
17.10000,-2.85026,-2.24306
17.20000,-2.86666,-2.26613
17.30000,-2.88346,-2.29029
17.40000,-2.90026,-2.31332
17.50000,-2.91693,-2.33993
17.60000,-2.93373,-2.35931
17.70000,-2.95039,-2.38317
17.80000,-2.96693,-2.40459
17.90000,-2.98319,-2.42633
18.00000,-3.00026,-2.44868
18.10000,-3.01679,-2.47080
18.20000,-3.03346,-2.49297
18.30000,-3.05039,-2.51347
18.40000,-3.06679,-2.53647
18.50000,-3.08373,-2.55415
18.60000,-3.10026,-2.57800
18.70000,-3.11706,-2.59781
18.80000,-3.13333,-2.61932
18.90000,-3.15039,-2.63796
19.00000,-3.16693,-2.65917
19.10000,-3.18359,-2.68068
19.20000,-3.20039,-2.69865
19.30000,-3.21666,-2.71845
19.40000,-3.23346,-2.73948
19.50000,-3.25013,-2.75938
19.60000,-3.26679,-2.78160
19.70000,-3.28346,-2.80106
19.80000,-3.30026,-2.81991
19.90000,-3.31679,-2.83998
20.00000,-3.33359,-2.85894
20.10000,-3.35039,-2.87940
20.20000,-3.36666,-2.89517
20.30000,-3.38373,-2.90990
20.40000,-3.39999,-2.92888
20.50000,-3.41679,-2.95004
20.60000,-3.43372,-2.96967
20.70000,-3.45026,-2.98880
20.80000,-3.46692,-3.00740
20.90000,-3.48372,-3.02809
21.00000,-3.50052,-3.04551
21.10000,-3.51666,-3.06561
21.20000,-3.53359,-3.08352
21.30000,-3.55026,-3.10050
21.40000,-3.56692,-3.11864
21.50000,-3.58386,-3.13520
21.60000,-3.60026,-3.15256
21.70000,-3.61706,-3.16933
21.80000,-3.63346,-3.18613
21.90000,-3.65012,-3.20513
22.00000,-3.66652,-3.22475
22.10000,-3.68359,-3.24157
22.20000,-3.70012,-3.25706
22.30000,-3.71679,-3.27433
22.40000,-3.73359,-3.28748
22.50000,-3.75012,-3.27729
22.60000,-3.76692,-3.29711
22.70000,-3.78332,-3.31324
22.80000,-3.79999,-3.32997
22.90000,-3.81679,-3.34405
23.00000,-3.83359,-3.35988
23.10000,-3.85039,-3.37145
23.20000,-3.86679,-3.32324
23.30000,-3.88359,-3.34162
23.40000,-3.89999,-3.36329
23.50000,-3.91706,-3.38709
23.60000,-3.93332,-3.40588
23.70000,-3.95026,-3.42600
23.80000,-3.96706,-3.44392
23.90000,-3.98359,-3.45988
24.00000,-4.00039,-3.47585
24.10000,-4.01706,-3.49338
24.20000,-4.03359,-3.51022
24.30000,-4.04999,-3.52485
24.40000,-4.06692,-3.54208
24.50000,-4.08346,-3.55669
24.60000,-4.10026,-3.57074
24.70000,-4.11719,-3.58556
24.80000,-4.13359,-3.60184
24.90000,-4.15039,-3.61399
25.00000,-4.16692,-3.62395
25.10000,-4.18372,-3.62946
25.20000,-4.19999,-3.64182
25.30000,-4.21692,-3.65221
25.40000,-4.23359,-3.66255
25.50000,-4.25012,-3.67783
25.60000,-4.26706,-3.69079
25.70000,-4.28346,-3.70312
25.80000,-4.30026,-3.71664
25.90000,-4.31679,-3.72873
26.00000,-4.33346,-3.74276
26.10000,-4.35012,-3.75512
26.20000,-4.36692,-3.76939
26.30000,-4.38346,-3.78138
26.40000,-4.40012,-3.79404
26.50000,-4.41706,-3.80329
26.60000,-4.43346,-3.81506
26.70000,-4.45026,-3.82677
26.80000,-4.46666,-3.83500
26.90000,-4.48359,-3.84904
27.00000,-4.50039,-3.86057
27.10000,-4.51706,-3.87220
27.20000,-4.53372,-3.88096
27.30000,-4.55026,-3.89311
27.40000,-4.56719,-3.90536
27.50000,-4.58346,-3.91787
27.60000,-4.60039,-3.92825
27.70000,-4.61692,-3.93749
27.80000,-4.63359,-3.94674
27.90000,-4.65039,-3.95810
28.00000,-4.66706,-3.96812
28.10000,-4.68359,-3.97785
28.20000,-4.70026,-3.98616
28.30000,-4.71679,-3.99268
28.40000,-4.73319,-4.00343
28.50000,-4.75026,-4.01232
28.60000,-4.76692,-4.01919
28.70000,-4.78359,-4.02734
28.80000,-4.80039,-4.03453
28.90000,-4.81679,-4.04158
29.00000,-4.83359,-4.04996
29.10000,-4.85012,-4.05682
29.20000,-4.86665,-4.06366
29.30000,-4.88345,-4.07130
29.40000,-4.90039,-4.07924
29.50000,-4.91705,-4.08571
29.60000,-4.93359,-4.09441
29.70000,-4.95039,-4.10070
29.80000,-4.96665,-4.10716
29.90000,-4.98359,-4.11448
30.00000,-4.99999,-4.11916
30.10000,-5.01679,-4.12486
30.20000,-5.03359,-4.12894
30.30000,-5.05039,-4.13772
30.40000,-5.06705,-4.14341
30.50000,-5.08372,-4.14996
30.60000,-5.10039,-4.15619
30.70000,-5.11665,-4.16113
30.80000,-5.13359,-4.16698
30.90000,-5.15012,-4.17282
31.00000,-5.16692,-4.17868
31.10000,-5.18385,-4.18347
31.20000,-5.20025,-4.18795
31.30000,-5.21692,-4.19178
31.40000,-5.23359,-4.19618
31.50000,-5.25025,-4.20086
31.60000,-5.26665,-4.20475
31.70000,-5.28359,-4.20985
31.80000,-5.30025,-4.21296
31.90000,-5.31679,-4.21785
32.00000,-5.33372,-4.22044
32.10000,-5.35012,-4.22539
32.20000,-5.36692,-4.22929
32.30000,-5.38332,-4.23311
32.40000,-5.39999,-4.23613
32.50000,-5.41679,-4.24068
32.60000,-5.43359,-4.24289
32.70000,-5.45025,-4.24580
32.80000,-5.46692,-4.25015
32.90000,-5.48372,-4.25227
33.00000,-5.49999,-4.25571
33.10000,-5.51692,-4.26030
33.20000,-5.53332,-4.26334
33.30000,-5.55025,-4.26785
33.40000,-5.56705,-4.27152
33.50000,-5.58359,-4.27458
33.60000,-5.60039,-4.27740
33.70000,-5.61705,-4.28066
33.80000,-5.63359,-4.28172
33.90000,-5.64999,-4.28366
34.00000,-5.66692,-4.28605
34.10000,-5.68359,-4.28713
34.20000,-5.70012,-4.28949
34.30000,-5.71719,-4.29057
34.40000,-5.73359,-4.29196
34.50000,-5.75025,-4.29286
34.60000,-5.76692,-4.29424
34.70000,-5.78359,-4.29431
34.80000,-5.79999,-4.29556
34.90000,-5.81692,-4.29575
35.00000,-5.83359,-4.29494
35.10000,-5.85012,-4.29494
35.20000,-5.86692,-4.29480
35.30000,-5.88345,-4.29632
35.40000,-5.90025,-4.29402
35.50000,-5.91679,-4.29264
35.60000,-5.93345,-4.29395
35.70000,-5.95012,-4.29206
35.80000,-5.96692,-4.28864
35.90000,-5.98359,-4.28504
36.00000,-6.00025,-4.28434
36.10000,-6.01705,-4.27722
36.20000,-6.03345,-4.26983
36.30000,-6.05025,-4.26914
36.40000,-6.06665,-4.26668
36.50000,-6.08332,-4.26442
36.60000,-6.10025,-4.26640
36.70000,-6.11692,-4.26643
36.80000,-6.13359,-4.26368
36.90000,-6.15025,-4.26424
37.00000,-6.16692,-4.26776
37.10000,-6.18345,-4.27049
37.20000,-6.20012,-4.27049
37.30000,-6.21692,-4.26981
37.40000,-6.23345,-4.26950
37.50000,-6.25038,-4.26761
37.60000,-6.26678,-4.26362
37.70000,-6.28372,-4.26522
37.80000,-6.30025,-4.26685
37.90000,-6.31692,-4.26401
38.00000,-6.33345,-4.25870
38.10000,-6.35038,-4.26038
38.20000,-6.36692,-4.26471
38.30000,-6.38345,-4.26728
38.40000,-6.40038,-4.26745
38.50000,-6.41678,-4.27168
38.60000,-6.43358,-4.27748
38.70000,-6.44998,-4.27885
38.80000,-6.46665,-4.28109
38.90000,-6.48345,-4.28752
39.00000,-6.50025,-4.29069
39.10000,-6.51692,-4.29113
39.20000,-6.53358,-4.29315
39.30000,-6.55038,-4.29362
39.40000,-6.56678,-4.29336
39.50000,-6.58358,-4.29353
39.60000,-6.59998,-4.29082
39.70000,-6.61692,-4.29201
39.80000,-6.63372,-4.29250
39.90000,-6.65038,-4.29441
40.00000,-6.66705,-4.29548
40.10000,-6.68372,-4.29790
40.20000,-6.70025,-4.29934
40.30000,-6.71665,-4.30102
40.40000,-6.73358,-4.30338
40.50000,-6.75025,-4.30592
40.60000,-6.76678,-4.31097
40.70000,-6.78385,-4.31563
40.80000,-6.80025,-4.31863
40.90000,-6.81705,-4.32211
41.00000,-6.83358,-4.32446
41.10000,-6.85025,-4.32665
41.20000,-6.86665,-4.32893
41.30000,-6.88372,-4.33187
41.40000,-6.90038,-4.33431
41.50000,-6.91692,-4.33672
41.60000,-6.93372,-4.33859
41.70000,-6.95012,-4.34211
41.80000,-6.96678,-4.34381
41.90000,-6.98345,-4.34702
42.00000,-6.99998,-4.34855
42.10000,-7.01678,-4.35351
42.20000,-7.03358,-4.35753
42.30000,-7.05025,-4.35908
42.40000,-7.06692,-4.36389
42.50000,-7.08372,-4.36596
42.60000,-7.10012,-4.36873
42.70000,-7.11692,-4.37263
42.80000,-7.13332,-4.37387
42.90000,-7.15025,-4.38022
43.00000,-7.16705,-4.38339
43.10000,-7.18358,-4.38721
43.20000,-7.20025,-4.39324
43.30000,-7.21705,-4.39911
43.40000,-7.23372,-4.40210
43.50000,-7.24998,-4.40713
43.60000,-7.26692,-4.41215
43.70000,-7.28358,-4.41379
43.80000,-7.30012,-4.42375
43.90000,-7.31718,-4.42847
44.00000,-7.33358,-4.43186
44.10000,-7.35038,-4.43684
44.20000,-7.36692,-4.44217
44.30000,-7.38358,-4.44133
44.40000,-7.39998,-4.44482
44.50000,-7.41705,-4.45038
44.60000,-7.43358,-4.45207
44.70000,-7.45025,-4.45632
44.80000,-7.46705,-4.45910
44.90000,-7.48345,-4.45647
45.00000,-7.50011,-4.45872
45.10000,-7.51665,-4.46061
45.20000,-7.53345,-4.46239
45.30000,-7.55011,-4.46586
45.40000,-7.56691,-4.46959
45.50000,-7.58358,-4.47339
45.60000,-7.60011,-4.47848
45.70000,-7.61705,-4.48202
45.80000,-7.63331,-4.48517
45.90000,-7.65025,-4.49122
46.00000,-7.66665,-4.49536
46.10000,-7.68345,-4.50402
46.20000,-7.70038,-4.50921
46.30000,-7.71691,-4.51045
46.40000,-7.73371,-4.51444
46.50000,-7.75038,-4.51892
46.60000,-7.76705,-4.51966
46.70000,-7.78331,-4.52240
46.80000,-7.80025,-4.52764
46.90000,-7.81678,-4.53409
47.00000,-7.83358,-4.53577
47.10000,-7.85051,-4.54174
47.20000,-7.86678,-4.54740
47.30000,-7.88371,-4.55219
47.40000,-7.90025,-4.55626
47.50000,-7.91691,-4.56049
47.60000,-7.93331,-4.56398
47.70000,-7.95038,-4.56665
47.80000,-7.96691,-4.57340
47.90000,-7.98345,-4.57912
48.00000,-8.00038,-4.58109
48.10000,-8.01678,-4.58687
48.20000,-8.03358,-4.59047
48.30000,-8.05011,-4.59484
48.40000,-8.06678,-4.60023
48.50000,-8.08345,-4.60333
48.60000,-8.10025,-4.60986
48.70000,-8.11678,-4.61277
48.80000,-8.13345,-4.61783
48.90000,-8.15038,-4.61818
49.00000,-8.16665,-4.61895
49.10000,-8.18371,-4.62773
49.20000,-8.19998,-4.63209
49.30000,-8.21691,-4.63874
49.40000,-8.23358,-4.64205
49.50000,-8.25025,-4.64960
49.60000,-8.26691,-4.65867
49.70000,-8.28358,-4.66803
49.80000,-8.30025,-4.67248
49.90000,-8.31665,-4.67787
50.00000,-8.33358,-4.68441
50.10000,-8.35011,-4.69061
50.20000,-8.36691,-4.69788
50.30000,-8.38385,-4.70384
50.40000,-8.40025,-4.70817
50.50000,-8.41705,-4.71458
50.60000,-8.43345,-4.72008
50.70000,-8.45038,-4.72747
50.80000,-8.46665,-4.73322
50.90000,-8.48358,-4.73665
51.00000,-8.50025,-4.74043
51.10000,-8.51678,-4.74683
51.20000,-8.53358,-4.75085
51.30000,-8.55025,-4.75654
51.40000,-8.56691,-4.76211
51.50000,-8.58345,-4.76592
51.60000,-8.59998,-4.76854
51.70000,-8.61678,-4.77533
51.80000,-8.63358,-4.78123
51.90000,-8.65025,-4.78766
52.00000,-8.66691,-4.79493
52.10000,-8.68371,-4.79945
52.20000,-8.70011,-4.80538
52.30000,-8.71691,-4.81209
52.40000,-8.73331,-4.81726
52.50000,-8.75011,-4.82379
52.60000,-8.76705,-4.83013
52.70000,-8.78358,-4.83572
52.80000,-8.80038,-4.84155
52.90000,-8.81705,-4.84790
53.00000,-8.83385,-4.85193
53.10000,-8.84998,-4.85739
53.20000,-8.86691,-4.86367
53.30000,-8.88358,-4.86898
53.40000,-8.90024,-4.87527
53.50000,-8.91704,-4.88014
53.60000,-8.93358,-4.88540
53.70000,-8.95024,-4.89079
53.80000,-8.96691,-4.89628
53.90000,-8.98358,-4.90043
54.00000,-8.99985,-4.90429
54.10000,-9.01691,-4.91061
54.20000,-9.03358,-4.91432
54.30000,-9.05024,-4.92046
54.40000,-9.06718,-4.92399
54.50000,-9.08344,-4.92785
54.60000,-9.10024,-4.93202
54.70000,-9.11664,-4.93678
54.80000,-9.13344,-4.94137
54.90000,-9.14998,-4.94544
55.00000,-9.16691,-4.95144
55.10000,-9.18344,-4.95463
55.20000,-9.20024,-4.96100
55.30000,-9.21718,-4.96478
55.40000,-9.23344,-4.96633
55.50000,-9.25024,-4.97083
55.60000,-9.26664,-4.97283
55.70000,-9.28358,-4.97822
55.80000,-9.30038,-4.98265
55.90000,-9.31704,-4.98657
56.00000,-9.33371,-4.98987
56.10000,-9.35038,-4.99419
56.20000,-9.36704,-4.99692
56.30000,-9.38331,-4.99964
56.40000,-9.40024,-5.00375
56.50000,-9.41678,-5.00531
56.60000,-9.43344,-5.01056
56.70000,-9.45038,-5.01324
56.80000,-9.46691,-5.01606
56.90000,-9.48371,-5.01717
57.00000,-9.50011,-5.01782
57.10000,-9.51691,-5.01946
57.20000,-9.53331,-5.02167
57.30000,-9.55038,-5.02556
57.40000,-9.56678,-5.02532
57.50000,-9.58344,-5.02839
57.60000,-9.60038,-5.02829
57.70000,-9.61664,-5.02941
57.80000,-9.63358,-5.03217
57.90000,-9.65011,-5.03304
58.00000,-9.66664,-5.03556
58.10000,-9.68331,-5.03874
58.20000,-9.70038,-5.04224
58.30000,-9.71691,-5.04240
58.40000,-9.73358,-5.04593
58.50000,-9.75038,-5.04902
58.60000,-9.76664,-5.05102
58.70000,-9.78358,-5.05535
58.80000,-9.79998,-5.05848
58.90000,-9.81691,-5.06274
59.00000,-9.83358,-5.06659
59.10000,-9.85024,-5.07101
59.20000,-9.86678,-5.07487
59.30000,-9.88371,-5.07968
59.40000,-9.90038,-5.08072
59.50000,-9.91664,-5.08453
59.60000,-9.93344,-5.08760
59.70000,-9.95011,-5.09163
59.80000,-9.96691,-5.09732
59.90000,-9.98371,-5.10068
60.00000,-10.00024,-5.10330
60.10000,-10.01704,-5.10674
60.20000,-10.03358,-5.11060
60.30000,-10.05024,-5.11270
60.40000,-10.06678,-5.11678
60.50000,-10.08371,-5.12004
60.60000,-10.10024,-5.12422
60.70000,-10.11691,-5.12927
60.80000,-10.13371,-5.13265
60.90000,-10.15024,-5.13762
61.00000,-10.16691,-5.14068
61.10000,-10.18331,-5.14308
61.20000,-10.20011,-5.14654
61.30000,-10.21691,-5.15133
61.40000,-10.23371,-5.15473
61.50000,-10.25024,-5.14678
61.60000,-10.26691,-5.15267
61.70000,-10.28358,-5.15538
61.80000,-10.30011,-5.15803
61.90000,-10.31691,-5.16259
62.00000,-10.33344,-5.16539
62.10000,-10.35011,-5.17081
62.20000,-10.36691,-5.17628
62.30000,-10.38371,-5.17846
62.40000,-10.40037,-5.18218
62.50000,-10.41691,-5.18643
62.60000,-10.43357,-5.18881
62.70000,-10.44997,-5.19207
62.80000,-10.46691,-5.19653
62.90000,-10.48357,-5.19798
63.00000,-10.50011,-5.20196
63.10000,-10.51691,-5.20449
63.20000,-10.53357,-5.20718
63.30000,-10.55051,-5.21248
63.40000,-10.56704,-5.21383
63.50000,-10.58371,-5.21709
63.60000,-10.59997,-5.21996
63.70000,-10.61704,-5.22476
63.80000,-10.63357,-5.22751
63.90000,-10.65011,-5.23215
64.00000,-10.66704,-5.23544
64.10001,-10.68344,-5.23864
64.20000,-10.70011,-5.24242
64.30000,-10.71651,-5.24475
64.40000,-10.73344,-5.24832
64.50000,-10.75011,-5.25397
64.60001,-10.76691,-5.25910
64.70000,-10.78357,-5.26403
64.80000,-10.80024,-5.27090
64.90000,-10.81704,-5.27356
65.00000,-10.83331,-5.27779
65.10001,-10.85024,-5.28234
65.20000,-10.86664,-5.28566
65.30000,-10.88357,-5.29087
65.40000,-10.90037,-5.29580
65.50000,-10.91704,-5.30050
65.60001,-10.93371,-5.30423
65.70001,-10.95037,-5.30878
65.80000,-10.96704,-5.31256
65.90000,-10.98331,-5.31627
66.00000,-11.00024,-5.32165
66.10001,-11.01691,-5.32569
66.20001,-11.03344,-5.33172
66.30000,-11.05051,-5.33681
66.40000,-11.06704,-5.34076
66.50000,-11.08371,-5.34572
66.60001,-11.10011,-5.34873
66.70001,-11.11691,-5.35217
66.80000,-11.13331,-5.35650
66.90000,-11.15024,-5.36097
67.00000,-11.16677,-5.36308
67.10001,-11.18344,-5.36736
67.20001,-11.20037,-5.36970
67.30000,-11.21691,-5.37287
67.40000,-11.23371,-5.37574
67.50000,-11.25011,-5.37810
67.60001,-11.26664,-5.37979
67.70001,-11.28331,-5.38445
67.80000,-11.30024,-5.38899
67.90000,-11.31677,-5.39098
68.00000,-11.33344,-5.39679
68.10001,-11.35037,-5.39974
68.20001,-11.36677,-5.40317
68.30000,-11.38357,-5.40782
68.40000,-11.40011,-5.40840
68.50000,-11.41691,-5.41142
68.60001,-11.43371,-5.41344
68.70001,-11.45024,-5.41481
68.80000,-11.46704,-5.41575
68.90000,-11.48371,-5.41798
69.00000,-11.50037,-5.41558
69.10001,-11.51677,-5.40983
69.20001,-11.53357,-5.40770
69.30000,-11.55024,-5.40549
69.40000,-11.56691,-5.40789
69.50000,-11.58384,-5.40897
69.60001,-11.60037,-5.41110
69.70001,-11.61704,-5.41240
69.80000,-11.63357,-5.41472
69.90000,-11.65024,-5.41495
70.00000,-11.66664,-5.41691
70.10001,-11.68357,-5.42064
70.20001,-11.70010,-5.42270
70.30000,-11.71691,-5.42899
70.40000,-11.73384,-5.43039
70.50000,-11.75010,-5.43189
70.60001,-11.76664,-5.43274
70.70001,-11.78317,-5.43361
70.80000,-11.79997,-5.43748
70.90000,-11.81677,-5.44132
71.00000,-11.83344,-5.44361
71.10001,-11.85010,-5.44567
71.20001,-11.86690,-5.45142
71.30000,-11.88384,-5.45272
71.40000,-11.90010,-5.45474
71.50000,-11.91690,-5.45838
71.60001,-11.93330,-5.46019
71.70001,-11.95024,-5.46519
71.80000,-11.96704,-5.47065
71.90000,-11.98357,-5.47504
72.00000,-12.00037,-5.48095
72.10001,-12.01704,-5.48684
72.20001,-12.03357,-5.49078
72.30000,-12.04997,-5.49526
72.40000,-12.06690,-5.50101
72.50000,-12.08357,-5.50528
72.60001,-12.10010,-5.51089
72.70001,-12.11717,-5.51557
72.80000,-12.13357,-5.51973
72.90000,-12.15024,-5.52550
73.00000,-12.16690,-5.53081
73.10001,-12.18357,-5.53535
73.20001,-12.19997,-5.54113
73.30000,-12.21704,-5.54629
73.40000,-12.23357,-5.54950
73.50000,-12.25010,-5.55443
73.60001,-12.26704,-5.55772
73.70001,-12.28344,-5.56048
73.80000,-12.30010,-5.56393
73.90000,-12.31664,-5.56584
74.00000,-12.33330,-5.56599
74.10001,-12.35010,-5.56808
74.20001,-12.36690,-5.57058
74.30000,-12.38357,-5.57141
74.40000,-12.40037,-5.57518
74.50000,-12.41704,-5.57599
74.60001,-12.43330,-5.57660
74.70001,-12.45024,-5.57970
74.80000,-12.46677,-5.58000
74.90000,-12.48357,-5.58294
75.00000,-12.50024,-5.58445
75.10001,-12.51690,-5.58659
75.20001,-12.53370,-5.58783
75.30000,-12.55037,-5.58903
75.40000,-12.56704,-5.58646
75.50000,-12.58344,-5.58657
75.60001,-12.60024,-5.58756
75.70001,-12.61690,-5.58781
75.80000,-12.63357,-5.59097
75.90000,-12.65050,-5.59155
76.00000,-12.66690,-5.59207
76.10001,-12.68370,-5.59446
76.20001,-12.70024,-5.59537
76.30000,-12.71690,-5.59647
76.40000,-12.73330,-5.59713
76.50000,-12.75024,-5.59993
76.60001,-12.76690,-5.59874
76.70001,-12.78344,-5.60111
76.80000,-12.80050,-5.60148
76.90000,-12.81677,-5.60050
77.00000,-12.83357,-5.60201
77.10001,-12.84997,-5.60043
77.20001,-12.86663,-5.60008
77.30000,-12.88330,-5.60040
77.40000,-12.90024,-5.60122
77.50000,-12.91690,-5.59897
77.60001,-12.93357,-5.59879
77.70001,-12.95037,-5.59334
77.80000,-12.96677,-5.58494
77.90000,-12.98357,-5.57510
78.00000,-12.99997,-5.57027
78.10001,-13.01677,-5.56930
78.20001,-13.03370,-5.57029
78.30000,-13.05037,-5.56954
78.40000,-13.06704,-5.57164
78.50000,-13.08370,-5.57518
78.60001,-13.10037,-5.57660
78.70001,-13.11663,-5.58030
78.80000,-13.13357,-5.58668
78.90000,-13.15023,-5.59049
79.00000,-13.16663,-5.59566
79.10001,-13.18383,-5.60182
79.20001,-13.20037,-5.60649
79.30000,-13.21703,-5.61058
79.40000,-13.23357,-5.61505
79.50000,-13.25023,-5.61973
79.60001,-13.26663,-5.62563
79.70001,-13.28357,-5.63206
79.80000,-13.30010,-5.63811
79.90000,-13.31677,-5.64534
80.00000,-13.33370,-5.64972
80.10001,-13.35010,-5.65600
80.20001,-13.36690,-5.66217
80.30000,-13.38330,-5.66593
80.40000,-13.40010,-5.67094
80.50001,-13.41677,-5.67793
80.60001,-13.43357,-5.68532
80.70001,-13.45010,-5.68923
80.80000,-13.46690,-5.69767
80.90000,-13.48370,-5.70074
81.00001,-13.49997,-5.70276
81.10001,-13.51690,-5.70726
81.20001,-13.53330,-5.70984
81.30000,-13.55010,-5.71452
81.40000,-13.56690,-5.71882
81.50001,-13.58370,-5.72367
81.60001,-13.60037,-5.72749
81.70001,-13.61703,-5.73159
81.80000,-13.63370,-5.73377
81.90000,-13.65010,-5.73567
82.00001,-13.66690,-5.73942
82.10001,-13.68343,-5.74360
82.20001,-13.70023,-5.74849
82.30000,-13.71717,-5.75034
82.40000,-13.73357,-5.75035
82.50001,-13.75037,-5.75127
82.60001,-13.76690,-5.75309
82.70001,-13.78357,-5.75489
82.80000,-13.79997,-5.75849
82.90000,-13.81690,-5.76394
83.00001,-13.83343,-5.76680
83.10001,-13.85010,-5.77348
83.20001,-13.86717,-5.77889
83.30000,-13.88343,-5.78351
83.40000,-13.90023,-5.78811
83.50001,-13.91663,-5.79195
83.60001,-13.93330,-5.79641
83.70001,-13.94997,-5.80295
83.80000,-13.96690,-5.80631
83.90000,-13.98343,-5.81095
84.00001,-14.00023,-5.82077
84.10001,-14.01717,-5.82599
84.20001,-14.03330,-5.83244
84.30000,-14.05023,-5.83999
84.40000,-14.06663,-5.84087
84.50001,-14.08357,-5.84953
84.60001,-14.10037,-5.85656
84.70001,-14.11703,-5.86493
84.80000,-14.13370,-5.87141
84.90000,-14.15023,-5.87702
85.00001,-14.16703,-5.88063
85.10001,-14.18343,-5.88653
85.20001,-14.20037,-5.89591
85.30000,-14.21690,-5.90242
85.40000,-14.23356,-5.91104
85.50001,-14.25037,-5.91767
85.60001,-14.26690,-5.92713
85.70001,-14.28370,-5.93617
85.80000,-14.30023,-5.94505
85.90000,-14.31690,-5.95056
86.00001,-14.33330,-5.95938
86.10001,-14.35023,-5.97123
86.20001,-14.36690,-5.97899
86.30000,-14.38356,-5.98843
86.40000,-14.40036,-5.99540
86.50001,-14.41676,-6.00253
86.60001,-14.43356,-6.00938
86.70001,-14.44996,-6.01775
86.80000,-14.46663,-6.02632
86.90000,-14.48330,-6.03278
87.00001,-14.50023,-6.04244
87.10001,-14.51690,-6.05034
87.20001,-14.53370,-6.06050
87.30000,-14.55036,-6.06385
87.40000,-14.56663,-6.07318
87.50001,-14.58356,-6.08615
87.60001,-14.60010,-6.09661
87.70001,-14.61690,-6.11111
87.80000,-14.63356,-6.12364
87.90000,-14.65036,-6.13610
88.00001,-14.66703,-6.14821
88.10001,-14.68370,-6.16572
88.20001,-14.70036,-6.18012
88.30000,-14.71663,-6.19626
88.40000,-14.73356,-6.21077
88.50001,-14.75010,-6.22466
88.60001,-14.76690,-6.24246
88.70001,-14.78383,-6.25645
88.80000,-14.80023,-6.27187
88.90000,-14.81703,-6.28674
89.00001,-14.83356,-6.29880
89.10001,-14.85036,-6.31274
89.20001,-14.86663,-6.32543
89.30000,-14.88370,-6.33771
89.40000,-14.90023,-6.34940
89.50001,-14.91676,-6.36403
89.60001,-14.93370,-6.37400
89.70001,-14.95010,-6.38894
89.80000,-14.96676,-6.40006
89.90000,-14.98330,-6.41149
90.00001,-15.00010,-6.42069
90.10001,-15.01676,-6.43137
90.20001,-15.03370,-6.44253
90.23400,-15.03930,-6.44612