File: GFBaking/data/1TspPectin/1TspPectin_1.is_comp_RawData/Specimen_RawData_1.csv
Time,Extension,Load
(sec),(mm),(N)
0.00000,0.50613,0.03304
0.10000,0.49747,0.03161
0.20000,0.47733,0.03174
0.30000,0.45867,0.03167
0.40000,0.44093,0.03326
0.50000,0.42373,0.03354
0.60000,0.40667,0.03110
0.70000,0.38973,0.03195
0.80000,0.37320,0.03372
0.90000,0.35627,0.03203
1.00000,0.33987,0.03242
1.10000,0.32320,0.03266
1.20000,0.30653,0.03313
1.30000,0.28973,0.03318
1.40000,0.27307,0.03355
1.50000,0.25627,0.03454
1.60000,0.23947,0.03457
1.70000,0.22320,0.03465
1.80000,0.20613,0.03550
1.90000,0.18987,0.03339
2.00000,0.17293,0.02899
2.10000,0.15600,0.02656
2.20000,0.13960,0.02183
2.30000,0.12293,0.01921
2.40000,0.10627,0.01422
2.50000,0.08947,0.01141
2.60000,0.07320,0.00859
2.70000,0.05627,0.00250
2.80000,0.03987,-0.00124
2.90000,0.02293,-0.00625
3.00000,0.00613,-0.01158
3.10000,-0.01040,-0.01512
3.20000,-0.02707,-0.02131
3.30000,-0.04347,-0.02735
3.40000,-0.06040,-0.03362
3.50000,-0.07680,-0.04009
3.60000,-0.09387,-0.04588
3.70000,-0.11040,-0.05301
3.80000,-0.12720,-0.05874
3.90000,-0.14387,-0.06342
4.00000,-0.16040,-0.06918
4.10000,-0.17720,-0.07490
4.20000,-0.19347,-0.07994
4.30000,-0.21027,-0.10248
4.40000,-0.22693,-0.10178
4.50000,-0.24373,-0.10042
4.60000,-0.26040,-0.10486
4.70000,-0.27720,-0.10930
4.80000,-0.29373,-0.11346
4.90000,-0.31013,-0.12199
5.00000,-0.32720,-0.13251
5.10000,-0.34333,-0.13523
5.20000,-0.36027,-0.13733
5.30000,-0.37707,-0.14369
5.40000,-0.39373,-0.15164
5.50000,-0.41040,-0.15756
5.60000,-0.42720,-0.16663
5.70000,-0.44373,-0.17503
5.80000,-0.46013,-0.18222
5.90000,-0.47707,-0.18643
6.00000,-0.49360,-0.19310
6.10000,-0.51040,-0.20058
6.20000,-0.52720,-0.20702
6.30000,-0.54373,-0.21272
6.40000,-0.56053,-0.21980
6.50000,-0.57707,-0.22757
6.60000,-0.59373,-0.23445
6.70000,-0.61027,-0.23881
6.80000,-0.62707,-0.24596
6.90000,-0.64373,-0.25376
7.00000,-0.66053,-0.26205
7.10000,-0.67706,-0.27013
7.20000,-0.69360,-0.27677
7.30000,-0.71040,-0.28617
7.40000,-0.72680,-0.29305
7.50000,-0.74360,-0.30013
7.60000,-0.76040,-0.31056
7.70000,-0.77706,-0.31796
7.80000,-0.79360,-0.32512
7.90000,-0.81053,-0.33180
8.00000,-0.82706,-0.34119
8.10000,-0.84346,-0.34865
8.20000,-0.86040,-0.35874
8.30000,-0.87666,-0.36647
8.40000,-0.89373,-0.37666
8.50000,-0.91040,-0.38471
8.60000,-0.92693,-0.39400
8.70000,-0.94373,-0.40348
8.80000,-0.96053,-0.41409
8.90000,-0.97720,-0.42479
9.00000,-0.99346,-0.43387
9.10000,-1.01040,-0.44380
9.20000,-1.02693,-0.45505
9.30000,-1.04386,-0.46594
9.40000,-1.06066,-0.47680
9.50000,-1.07706,-0.48682
9.60000,-1.09386,-0.49849
9.70000,-1.11040,-0.50886
9.80000,-1.12706,-0.51963
9.90000,-1.14346,-0.53040
10.00000,-1.16040,-0.54133
10.10000,-1.17693,-0.55321
10.20000,-1.19373,-0.56497
10.30000,-1.21040,-0.57719
10.40000,-1.22693,-0.58886
10.50000,-1.24373,-0.60050
10.60000,-1.26013,-0.60849
10.70000,-1.27693,-0.61503
10.80000,-1.29360,-0.62442
10.90000,-1.31040,-0.63739
11.00000,-1.32706,-0.65509
11.10000,-1.34386,-0.67198
11.20000,-1.36026,-0.68786
11.30000,-1.37680,-0.70609
11.40000,-1.39386,-0.72383
11.50000,-1.41013,-0.73801
11.60000,-1.42706,-0.75490
11.70000,-1.44373,-0.77064
11.80000,-1.46040,-0.78879
11.90000,-1.47706,-0.80451
12.00000,-1.49373,-0.82209
12.10000,-1.51053,-0.83779
12.20000,-1.52680,-0.85701
12.30000,-1.54373,-0.87417
12.40000,-1.56013,-0.89121
12.50000,-1.57693,-0.91242
12.60000,-1.59386,-0.93147
12.70000,-1.61026,-0.95076
12.80000,-1.62720,-0.96832
12.90000,-1.64373,-0.98981
13.00000,-1.66053,-1.00776
13.10000,-1.67680,-1.02889
13.20000,-1.69373,-1.04855
13.30000,-1.71040,-1.07115
13.40000,-1.72720,-1.09411
13.50000,-1.74373,-1.11861
13.60000,-1.76040,-1.14002
13.70000,-1.77706,-1.16187
13.80000,-1.79360,-1.18573
13.90000,-1.81026,-1.20809
14.00000,-1.82693,-1.23324
14.10000,-1.84373,-1.25691
14.20000,-1.86026,-1.28006
14.30000,-1.87706,-1.30345
14.40000,-1.89373,-1.32637
14.50000,-1.91013,-1.35022
14.60000,-1.92720,-1.37488
14.70000,-1.94346,-1.39749
14.80000,-1.96026,-1.42251
14.90000,-1.97706,-1.44612
15.00000,-1.99386,-1.47084
15.10000,-2.01053,-1.49650
15.20000,-2.02720,-1.52201
15.30000,-2.04386,-1.54573
15.40000,-2.06026,-1.57044
15.50000,-2.07719,-1.59583
15.60000,-2.09359,-1.61991
15.70000,-2.11026,-1.64677
15.80000,-2.12719,-1.67319
15.90000,-2.14386,-1.69741
16.00000,-2.16053,-1.72186
16.10000,-2.17693,-1.74654
16.20000,-2.19359,-1.77150
16.30000,-2.20999,-1.79410
16.40000,-2.22706,-1.81804
16.50000,-2.24373,-1.84389
16.60000,-2.26053,-1.84425
16.70000,-2.27719,-1.70064
16.80000,-2.29359,-1.75451
16.90000,-2.31039,-1.79881
17.00000,-2.32693,-1.83397
17.10000,-2.34359,-1.86662
17.20000,-2.36026,-1.90069
17.30000,-2.37706,-1.93268
17.40000,-2.39373,-1.95964
17.50000,-2.41053,-1.98555
17.60000,-2.42719,-2.01267
17.70000,-2.44346,-2.03937
17.80000,-2.46039,-2.06601
17.90000,-2.47679,-2.07415
18.00000,-2.49359,-2.07932
18.10000,-2.51039,-2.08519
18.20000,-2.52706,-2.10924
18.30000,-2.54386,-2.13264
18.40000,-2.56053,-2.15142
18.50000,-2.57706,-2.17368
18.60000,-2.59346,-2.20663
18.70000,-2.61039,-2.22801
18.80000,-2.62679,-2.24552
18.90000,-2.64373,-2.27073
19.00000,-2.66066,-2.29258
19.10000,-2.67706,-2.31249
19.20000,-2.69373,-2.33366
19.30000,-2.71039,-2.35280
19.40000,-2.72706,-2.37326
19.50000,-2.74359,-2.39609
19.60000,-2.76053,-2.42148
19.70000,-2.77706,-2.44587
19.80000,-2.79373,-2.47002
19.90000,-2.81053,-2.49599
20.00000,-2.82693,-2.52462
20.10000,-2.84373,-2.55340
20.20000,-2.86013,-2.57849
20.30000,-2.87693,-2.60774
20.40000,-2.89359,-2.63405
20.50000,-2.91039,-2.66129
20.60000,-2.92706,-2.68758
20.70000,-2.94373,-2.71383
20.80000,-2.96053,-2.74099
20.90000,-2.97679,-2.76716
21.00000,-2.99386,-2.79155
21.10000,-3.01013,-2.81675
21.20000,-3.02693,-2.84283
21.30000,-3.04373,-2.87042
21.40000,-3.06039,-2.89318
21.50000,-3.07706,-2.91673
21.60000,-3.09373,-2.94215
21.70000,-3.11039,-2.96706
21.80000,-3.12693,-2.99280
21.90000,-3.14373,-3.01662
22.00000,-3.16026,-3.03927
22.10000,-3.17693,-3.06597
22.20000,-3.19386,-3.09072
22.30000,-3.21039,-3.11637
22.40000,-3.22719,-3.14131
22.50000,-3.24373,-3.16493
22.60000,-3.26039,-3.18908
22.70000,-3.27679,-3.21287
22.80000,-3.29386,-3.23806
22.90000,-3.31026,-3.25975
23.00000,-3.32719,-3.28570
23.10000,-3.34373,-3.30863
23.20000,-3.36026,-3.33071
23.30000,-3.37719,-3.35420
23.40000,-3.39359,-3.37773
23.50000,-3.41026,-3.39920
23.60000,-3.42693,-3.42301
23.70000,-3.44372,-3.44755
23.80000,-3.46039,-3.47090
23.90000,-3.47706,-3.49528
24.00000,-3.49386,-3.51788
24.10000,-3.51012,-3.54174
24.20000,-3.52706,-3.56661
24.30000,-3.54332,-3.59036
24.40000,-3.56012,-3.61330
24.50000,-3.57706,-3.63830
24.60000,-3.59372,-3.66210
24.70000,-3.61039,-3.68346
24.80000,-3.62719,-3.70650
24.90000,-3.64386,-3.72931
25.00000,-3.66012,-3.75298
25.10000,-3.67706,-3.77580
25.20000,-3.69359,-3.79886
25.30000,-3.71039,-3.82844
25.40000,-3.72719,-3.84822
25.50000,-3.74359,-3.86892
25.60000,-3.76052,-3.89234
25.70000,-3.77706,-3.91362
25.80000,-3.79372,-3.93870
25.90000,-3.81012,-3.96189
26.00000,-3.82719,-3.97941
26.10000,-3.84372,-3.99474
26.20000,-3.86052,-4.01527
26.30000,-3.87719,-4.03445
26.40000,-3.89359,-4.05113
26.50000,-3.91052,-4.06760
26.60000,-3.92679,-4.08894
26.70000,-3.94346,-4.10619
26.80000,-3.96026,-4.12586
26.90000,-3.97706,-4.14665
27.00000,-3.99372,-4.16985
27.10000,-4.01039,-4.18817
27.20000,-4.02719,-4.20790
27.30000,-4.04346,-4.22849
27.40000,-4.06052,-4.24968
27.50000,-4.07679,-4.26804
27.60000,-4.09359,-4.28920
27.70000,-4.11039,-4.30670
27.80000,-4.12706,-4.32148
27.90000,-4.14372,-4.33922
28.00000,-4.16052,-4.35840
28.10000,-4.17706,-4.37621
28.20000,-4.19346,-4.39080
28.30000,-4.21039,-4.40678
28.40000,-4.22692,-4.42124
28.50000,-4.24372,-4.43945
28.60000,-4.26052,-4.45395
28.70000,-4.27706,-4.46875
28.80000,-4.29386,-4.48331
28.90000,-4.31039,-4.49652
29.00000,-4.32719,-4.50944
29.10000,-4.34359,-4.52258
29.20000,-4.36039,-4.53662
29.30000,-4.37706,-4.54893
29.40000,-4.39386,-4.56504
29.50000,-4.41052,-4.57590
29.60000,-4.42706,-4.58929
29.70000,-4.44372,-4.60252
29.80000,-4.46012,-4.61504
29.90000,-4.47692,-4.62848
30.00000,-4.49359,-4.64203
30.10000,-4.51039,-4.65494
30.20000,-4.52706,-4.66734
30.30000,-4.54372,-4.68129
30.40000,-4.56052,-4.69261
30.50000,-4.57679,-4.70535
30.60000,-4.59386,-4.71750
30.70000,-4.60999,-4.72833
30.80000,-4.62692,-4.74214
30.90000,-4.64372,-4.75594
31.00000,-4.66026,-4.76750
31.10000,-4.67692,-4.77934
31.20000,-4.69372,-4.79102
31.30000,-4.71052,-4.80337
31.40000,-4.72679,-4.81697
31.50000,-4.74372,-4.82871
31.60000,-4.76026,-4.83951
31.70000,-4.77706,-4.85178
31.80000,-4.79399,-4.86090
31.90000,-4.81039,-4.87199
32.00000,-4.82719,-4.88324
32.10000,-4.84372,-4.89236
32.20000,-4.86039,-4.90205
32.30000,-4.87679,-4.91165
32.40000,-4.89385,-4.92186
32.50000,-4.91039,-4.93029
32.60000,-4.92705,-4.94035
32.70000,-4.94372,-4.94753
32.80000,-4.96025,-4.95617
32.90000,-4.97705,-4.96360
33.00000,-4.99345,-4.97148
33.10000,-5.01012,-4.97904
33.20000,-5.02692,-4.98759
33.30000,-5.04372,-4.99673
33.40000,-5.06039,-5.00503
33.50000,-5.07705,-5.01479
33.60000,-5.09372,-5.02219
33.70000,-5.11012,-5.02840
33.80000,-5.12705,-5.03585
33.90000,-5.14345,-5.04195
34.00000,-5.16025,-5.05169
34.10000,-5.17719,-5.05938
34.20000,-5.19372,-5.06742
34.30000,-5.21039,-5.07560
34.40000,-5.22719,-5.08446
34.50000,-5.24372,-5.09076
34.60000,-5.26012,-5.09855
34.70000,-5.27705,-5.10709
34.80000,-5.29359,-5.11385
34.90000,-5.31039,-5.12442
35.00000,-5.32719,-5.13036
35.10000,-5.34359,-5.13756
35.20000,-5.36052,-5.14522
35.30000,-5.37705,-5.15321
35.40000,-5.39372,-5.16061
35.50000,-5.41012,-5.16757
35.60000,-5.42719,-5.17505
35.70000,-5.44359,-5.18193
35.80000,-5.46052,-5.19097
35.90000,-5.47705,-5.19569
36.00000,-5.49372,-5.20211
36.10000,-5.51052,-5.20834
36.20000,-5.52679,-5.21422
36.30000,-5.54359,-5.22083
36.40000,-5.56025,-5.22949
36.50000,-5.57705,-5.23544
36.60000,-5.59359,-5.23872
36.70000,-5.61039,-5.24751
36.80000,-5.62719,-5.25394
36.90000,-5.64345,-5.25840
37.00000,-5.66052,-5.26547
37.10000,-5.67679,-5.27074
37.20000,-5.69359,-5.27820
37.30000,-5.71025,-5.28353
37.40000,-5.72692,-5.28946
37.50000,-5.74359,-5.29487
37.60000,-5.76025,-5.30055
37.70000,-5.77705,-5.30571
37.80000,-5.79345,-5.31168
37.90000,-5.81039,-5.31692
38.00000,-5.82692,-5.32090
38.10000,-5.84372,-5.32836
38.20000,-5.86065,-5.33384
38.30000,-5.87705,-5.33926
38.40000,-5.89385,-5.34443
38.50000,-5.91039,-5.34852
38.60000,-5.92705,-5.35330
38.70000,-5.94345,-5.35911
38.80000,-5.96039,-5.36312
38.90000,-5.97692,-5.36834
39.00000,-5.99372,-5.37350
39.10000,-6.01039,-5.37557
39.20000,-6.02705,-5.38056
39.30000,-6.04385,-5.38514
39.40000,-6.06025,-5.38893
39.50000,-6.07692,-5.39414
39.60000,-6.09358,-5.39958
39.70000,-6.11039,-5.40546
39.80000,-6.12705,-5.41014
39.90000,-6.14372,-5.41741
40.00000,-6.16038,-5.42115
40.10000,-6.17679,-5.42609
40.20000,-6.19385,-5.43650
40.30000,-6.21012,-5.43585
40.40000,-6.22705,-5.44597
40.50000,-6.24385,-5.45047
40.60000,-6.26038,-5.45399
40.70000,-6.27705,-5.46145
40.80000,-6.29385,-5.46667
40.90000,-6.31052,-5.46962
41.00000,-6.32692,-5.47560
41.10000,-6.34385,-5.47969
41.20000,-6.36025,-5.48302
41.30000,-6.37705,-5.48908
41.40000,-6.39385,-5.49128
41.50000,-6.41025,-5.49533
41.60000,-6.42705,-5.49907
41.70000,-6.44372,-5.50442
41.80000,-6.46038,-5.50612
41.90000,-6.47678,-5.51296
42.00000,-6.49372,-5.51636
42.10000,-6.51025,-5.52164
42.20000,-6.52718,-5.52925
42.30000,-6.54385,-5.53435
42.40000,-6.56025,-5.53953
42.50000,-6.57705,-5.54417
42.60000,-6.59345,-5.54897
42.70000,-6.61012,-5.55446
42.80000,-6.62692,-5.56168
42.90000,-6.64372,-5.56724
43.00000,-6.66025,-5.57216
43.10000,-6.67705,-5.57918
43.20000,-6.69385,-5.58383
43.30000,-6.71025,-5.58796
43.40000,-6.72718,-5.59343
43.50000,-6.74332,-5.59625
43.60000,-6.76025,-5.60321
43.70000,-6.77705,-5.60820
43.80000,-6.79372,-5.61412
43.90000,-6.81038,-5.61893
44.00000,-6.82718,-5.62362
44.10000,-6.84385,-5.62682
44.20000,-6.86012,-5.63105
44.30000,-6.87705,-5.63570
44.40000,-6.89345,-5.63843
44.50000,-6.91038,-5.64585
44.60000,-6.92718,-5.64855
44.70000,-6.94372,-5.65272
44.80000,-6.96052,-5.65728
44.90000,-6.97692,-5.66126
45.00000,-6.99372,-5.66544
45.10000,-7.01012,-5.66960
45.20000,-7.02718,-5.67522
45.30000,-7.04358,-5.67729
45.40000,-7.06038,-5.68365
45.50000,-7.07705,-5.68459
45.60000,-7.09358,-5.68892
45.70000,-7.11052,-5.69292
45.80000,-7.12678,-5.69528
45.90000,-7.14345,-5.69851
46.00000,-7.16025,-5.70335
46.10000,-7.17705,-5.70750
46.20000,-7.19358,-5.70875
46.30000,-7.21052,-5.71366
46.40000,-7.22718,-5.71617
46.50000,-7.24345,-5.71848
46.60000,-7.26038,-5.72257
46.70000,-7.27678,-5.72498
46.80000,-7.29372,-5.72963
46.90000,-7.31038,-5.73364
47.00000,-7.32692,-5.73735
47.10000,-7.34358,-5.74307
47.20000,-7.36052,-5.74954
47.30000,-7.37732,-5.75424
47.40000,-7.39358,-5.75934
47.50000,-7.41038,-5.76427
47.60000,-7.42692,-5.76861
47.70000,-7.44372,-5.77700
47.80000,-7.46052,-5.78083
47.90000,-7.47705,-5.78646
48.00000,-7.49385,-5.79288
48.10000,-7.51038,-5.79739
48.20000,-7.52705,-5.80142
48.30000,-7.54345,-5.80617
48.40000,-7.56025,-5.81127
48.50000,-7.57691,-5.81578
48.60000,-7.59371,-5.82324
48.70000,-7.61051,-5.82648
48.80000,-7.62705,-5.83131
48.90000,-7.64371,-5.83536
49.00000,-7.66025,-5.83920
49.10000,-7.67705,-5.84526
49.20000,-7.69371,-5.85183
49.30000,-7.71051,-5.85902
49.40000,-7.72705,-5.86393
49.50000,-7.74385,-5.87111
49.60000,-7.76038,-5.87503
49.70000,-7.77691,-5.88061
49.80000,-7.79371,-5.88614
49.90000,-7.81011,-5.89135
50.00000,-7.82705,-5.89906
50.10000,-7.84385,-5.90473
50.20000,-7.86038,-5.90889
50.30000,-7.87705,-5.91530
50.40000,-7.89371,-5.92003
50.50000,-7.91038,-5.92462
50.60000,-7.92665,-5.93031
50.70000,-7.94371,-5.93717
50.80000,-7.96025,-5.94046
50.90000,-7.97705,-5.94797
51.00000,-7.99371,-5.95099
51.10000,-8.01038,-5.95610
51.20000,-8.02731,-5.96221
51.30000,-8.04385,-5.96636
51.40000,-8.06051,-5.97029
51.50000,-8.07691,-5.97510
51.60000,-8.09371,-5.97865
51.70000,-8.11038,-5.98153
51.80000,-8.12705,-5.98750
51.90000,-8.14371,-5.99078
52.00000,-8.16025,-5.99569
52.10000,-8.17718,-5.99938
52.20000,-8.19331,-6.00076
52.30000,-8.21038,-6.00473
52.40000,-8.22705,-6.00719
52.50000,-8.24371,-6.01063
52.60000,-8.26025,-6.01384
52.70000,-8.27705,-6.01979
52.80000,-8.29371,-6.02005
52.90000,-8.31011,-6.02353
53.00000,-8.32718,-6.02602
53.10000,-8.34345,-6.02680
53.20000,-8.36038,-6.02943
53.30000,-8.37718,-6.03278
53.40000,-8.39371,-6.03550
53.50000,-8.41051,-6.03643
53.60000,-8.42718,-6.03662
53.70000,-8.44385,-6.03717
53.80000,-8.46011,-6.03931
53.90000,-8.47705,-6.04166
54.00000,-8.49358,-6.04344
54.10000,-8.51038,-6.04959
54.20000,-8.52718,-6.05100
54.30000,-8.54371,-6.05382
54.40000,-8.56051,-6.05656
54.50000,-8.57705,-6.05794
54.60000,-8.59371,-6.05912
54.70000,-8.61011,-6.06038
54.80000,-8.62705,-6.06290
54.90000,-8.64358,-6.06219
55.00000,-8.66038,-6.06410
55.10000,-8.67718,-6.06177
55.20000,-8.69371,-6.06206
55.30000,-8.71051,-6.05923
55.40000,-8.72691,-6.05778
55.50000,-8.74358,-6.05559
55.60000,-8.76025,-6.05460
55.70000,-8.77705,-6.05502
55.80000,-8.79358,-6.05310
55.90000,-8.81038,-6.05355
56.00000,-8.82718,-6.05150
56.10000,-8.84358,-6.05100
56.20000,-8.86038,-6.04949
56.30000,-8.87678,-6.04913
56.40000,-8.89371,-6.04914
56.50000,-8.91038,-6.04768
56.60000,-8.92691,-6.04753
56.70000,-8.94371,-6.04926
56.80000,-8.96051,-6.05053
56.90000,-8.97718,-6.05085
57.00000,-8.99344,-6.05173
57.10000,-9.01038,-6.05338
57.20000,-9.02691,-6.05263
57.30000,-9.04371,-6.05689
57.40000,-9.06064,-6.05705
57.50000,-9.07704,-6.05766
57.60000,-9.09384,-6.05953
57.70000,-9.11038,-6.06004
57.80000,-9.12704,-6.06284
57.90000,-9.14344,-6.06527
58.00000,-9.16038,-6.06896
58.10000,-9.17691,-6.07089
58.20000,-9.19384,-6.07734
58.30000,-9.21051,-6.07804
58.40000,-9.22691,-6.08121
58.50000,-9.24371,-6.08310
58.60000,-9.25998,-6.08635
58.70000,-9.27691,-6.09199
58.80000,-9.29358,-6.09631
58.90000,-9.31038,-6.10069
59.00000,-9.32678,-6.10428
59.10000,-9.34371,-6.11083
59.20000,-9.36051,-6.11488
59.30000,-9.37691,-6.11960
59.40000,-9.39384,-6.12396
59.50000,-9.41011,-6.12964
59.60000,-9.42691,-6.13561
59.70000,-9.44384,-6.14320
59.80000,-9.46038,-6.14689
59.90000,-9.47718,-6.15417
60.00000,-9.49384,-6.16145
60.10000,-9.51051,-6.16462
60.20000,-9.52691,-6.16870
60.30000,-9.54371,-6.17444
60.40000,-9.56024,-6.17767
60.50000,-9.57691,-6.18427
60.60000,-9.59384,-6.18869
60.70000,-9.61038,-6.19345
60.80000,-9.62718,-6.20028
60.90000,-9.64371,-6.20025
61.00000,-9.66024,-6.20454
61.10000,-9.67678,-6.21189
61.20000,-9.69371,-6.21591
61.30000,-9.71038,-6.21493
61.40000,-9.72704,-6.22261
61.50000,-9.74384,-6.22410
61.60000,-9.76024,-6.22588
61.70000,-9.77704,-6.23400
61.80000,-9.79344,-6.24126
61.90000,-9.81024,-6.24629
62.00000,-9.82691,-6.25660
62.10000,-9.84371,-6.26387
62.20000,-9.86024,-6.27147
62.30000,-9.87718,-6.28489
62.40000,-9.89384,-6.28790
62.50000,-9.91011,-6.30106
62.60000,-9.92704,-6.30917
62.70000,-9.94331,-6.31807
62.80000,-9.96024,-6.32569
62.90000,-9.97704,-6.33866
63.00000,-9.99371,-6.34642
63.10000,-10.01051,-6.35648
63.20000,-10.02718,-6.36577
63.30000,-10.04384,-6.37398
63.40000,-10.06024,-6.38277
63.50000,-10.07718,-6.38967
63.60000,-10.09358,-6.40194
63.70000,-10.11038,-6.41362
63.80000,-10.12731,-6.42202
63.90000,-10.14371,-6.42865
64.00000,-10.16051,-6.44138
64.10001,-10.17691,-6.44956
64.20000,-10.19358,-6.45458
64.30000,-10.21011,-6.46423
64.40000,-10.22704,-6.47495
64.50000,-10.24358,-6.48040
64.60001,-10.26038,-6.49220
64.70000,-10.27704,-6.50226
64.80000,-10.29358,-6.51271
64.90000,-10.31038,-6.51964
65.00000,-10.32691,-6.53240
65.10001,-10.34357,-6.53933
65.20000,-10.36024,-6.55215
65.30000,-10.37704,-6.56909
65.40000,-10.39357,-6.57584
65.50000,-10.41051,-6.58812
65.60001,-10.42718,-6.59766
65.70001,-10.44357,-6.60932
65.80000,-10.46037,-6.61757
65.90000,-10.47677,-6.62661
66.00000,-10.49371,-6.63555
66.10001,-10.51037,-6.64382
66.20001,-10.52704,-6.65416
66.30000,-10.54384,-6.66270
66.40000,-10.56064,-6.67127
66.50000,-10.57717,-6.67510
66.60001,-10.59344,-6.68489
66.70001,-10.61037,-6.69563
66.80000,-10.62691,-6.70300
66.90000,-10.64371,-6.71558
67.00000,-10.66051,-6.72397
67.10001,-10.67717,-6.74058
67.20001,-10.69397,-6.75209
67.30000,-10.71037,-6.75534
67.40000,-10.72704,-6.76428
67.50000,-10.74344,-6.77259
67.60001,-10.76024,-6.77993
67.70001,-10.77691,-6.78412
67.80000,-10.79371,-6.79576
67.90000,-10.81051,-6.80156
68.00000,-10.82704,-6.80814
68.10001,-10.84384,-6.81525
68.20001,-10.86011,-6.82194
68.30000,-10.87691,-6.82995
68.40000,-10.89357,-6.83942
68.50000,-10.91037,-6.84764
68.60001,-10.92691,-6.85357
68.70001,-10.94371,-6.86148
68.80000,-10.96051,-6.86641
68.90000,-10.97677,-6.87819
69.00000,-10.99384,-6.88970
69.10001,-11.01011,-6.89772
69.20001,-11.02691,-6.90878
69.30000,-11.04371,-6.92040
69.40000,-11.06037,-6.93099
69.50000,-11.07704,-6.93986
69.60001,-11.09384,-6.95083
69.70001,-11.11051,-6.95774
69.80000,-11.12691,-6.96626
69.90000,-11.14371,-6.97343
70.00000,-11.16011,-6.98233
70.10001,-11.17704,-6.99591
70.20001,-11.19384,-7.00451
70.30000,-11.21051,-7.01207
70.40000,-11.22717,-7.02004
70.50000,-11.24371,-7.02838
70.60001,-11.26037,-7.03495
70.70001,-11.27677,-7.04412
70.80000,-11.29371,-7.05149
70.90000,-11.31011,-7.05837
71.00000,-11.32704,-7.07018
71.10001,-11.34384,-7.07555
71.20001,-11.36037,-7.08482
71.30000,-11.37717,-7.09293
71.40000,-11.39344,-7.09899
71.50000,-11.41024,-7.10666
71.60001,-11.42691,-7.11920
71.70001,-11.44384,-7.12856
71.80000,-11.46037,-7.13820
71.90000,-11.47704,-7.14934
72.00000,-11.49384,-7.15782
72.10001,-11.51010,-7.16995
72.20001,-11.52717,-7.18195
72.30000,-11.54344,-7.19136
72.40000,-11.56037,-7.20556
72.50000,-11.57717,-7.21561
72.60001,-11.59371,-7.22926
72.70001,-11.61051,-7.24351
72.80000,-11.62717,-7.25449
72.90000,-11.64384,-7.26450
73.00000,-11.66010,-7.27783
73.10001,-11.67717,-7.29008
73.20001,-11.69357,-7.30074
73.30000,-11.71037,-7.31875
73.40000,-11.72717,-7.32968
73.50000,-11.74370,-7.34079
73.60001,-11.76050,-7.35402
73.70001,-11.77704,-7.36571
73.80000,-11.79370,-7.37750
73.90000,-11.81010,-7.39071
74.00000,-11.82717,-7.40408
74.10001,-11.84370,-7.41418
74.20001,-11.86050,-7.42946
74.30000,-11.87717,-7.43953
74.40000,-11.89370,-7.45111
74.50000,-11.91050,-7.46089
74.60001,-11.92677,-7.46905
74.70001,-11.94357,-7.48010
74.80000,-11.96024,-7.49320
74.90000,-11.97704,-7.50607
75.00000,-11.99357,-7.51674
75.10001,-12.01050,-7.53218
75.20001,-12.02704,-7.53875
75.30000,-12.04344,-7.55136
75.40000,-12.06050,-7.56441
75.50000,-12.07677,-7.57531
75.60001,-12.09370,-7.59137
75.70001,-12.11050,-7.60343
75.80000,-12.12717,-7.61747
75.90000,-12.14370,-7.62919
76.00000,-12.16050,-7.64372
76.10001,-12.17704,-7.65519
76.20001,-12.19344,-7.67247
76.30000,-12.21050,-7.68456
76.40000,-12.22690,-7.69443
76.50000,-12.24370,-7.71195
76.60001,-12.26050,-7.72407
76.70001,-12.27704,-7.74003
76.80000,-12.29384,-7.75285
76.90000,-12.31037,-7.76224
77.00000,-12.32717,-7.77577
77.10001,-12.34357,-7.78950
77.20001,-12.36037,-7.80265
77.30000,-12.37690,-7.81521
77.40000,-12.39384,-7.82873
77.50000,-12.41050,-7.84170
77.60001,-12.42704,-7.85701
77.70001,-12.44384,-7.86948
77.80000,-12.46024,-7.88178
77.90000,-12.47690,-7.89380
78.00000,-12.49357,-7.90924
78.10001,-12.51037,-7.92439
78.20001,-12.52690,-7.93622
78.30000,-12.54384,-7.95489
78.40000,-12.56050,-7.96642
78.50000,-12.57690,-7.98244
78.60001,-12.59384,-7.99601
78.70001,-12.61010,-8.00767
78.80000,-12.62690,-8.02246
78.90000,-12.64370,-8.03498
79.00000,-12.66037,-8.05085
79.10001,-12.67704,-8.06533
79.20001,-12.69384,-8.07844
79.30000,-12.71050,-8.09134
79.40000,-12.72677,-8.10696
79.50000,-12.74370,-8.12124
79.60001,-12.76024,-8.13614
79.70001,-12.77690,-8.15147
79.80000,-12.79384,-8.16568
79.90000,-12.81037,-8.18120
80.00000,-12.82717,-8.19765
80.10001,-12.84370,-8.21393
80.20001,-12.86050,-8.22979
80.30000,-12.87690,-8.24835
80.40000,-12.89384,-8.26753
80.50001,-12.91023,-8.28092
80.60001,-12.92703,-8.30323
80.70001,-12.94370,-8.31551
80.80000,-12.96023,-8.33318
80.90000,-12.97703,-8.34899
81.00001,-12.99344,-8.36684
81.10001,-13.01023,-8.38348
81.20001,-13.02677,-8.40030
81.30000,-13.04370,-8.41960
81.40000,-13.06023,-8.43611
81.50001,-13.07703,-8.45630
81.60001,-13.09370,-8.47196
81.70001,-13.11010,-8.48897
81.80000,-13.12703,-8.50731
81.90000,-13.14330,-8.52088
82.00001,-13.16023,-8.54078
82.10001,-13.17703,-8.55835
82.20001,-13.19383,-8.57638
82.30000,-13.21037,-8.59388
82.40000,-13.22717,-8.61405
82.50001,-13.24383,-8.62714
82.60001,-13.26010,-8.64689
82.70001,-13.27703,-8.66296
82.80000,-13.29343,-8.67645
82.90000,-13.31037,-8.70026
83.00001,-13.32717,-8.71538
83.10001,-13.34370,-8.73090
83.20001,-13.36050,-8.74682
83.30000,-13.37717,-8.76242
83.40000,-13.39383,-8.77779
83.50001,-13.41023,-8.79570
83.60001,-13.42717,-8.81138
83.70001,-13.44357,-8.82366
83.80000,-13.46050,-8.84318
83.90000,-13.47717,-8.85737
84.00001,-13.49357,-8.87225
84.10001,-13.51050,-8.88899
84.20001,-13.52690,-8.90140
84.30000,-13.54357,-8.91827
84.40000,-13.56023,-8.93590
84.50001,-13.57703,-8.95318
84.60001,-13.59357,-8.96888
84.70001,-13.61037,-8.98720
84.80000,-13.62703,-9.00259
84.90000,-13.64357,-9.02001
85.00001,-13.66050,-9.03696
85.10001,-13.67677,-9.05140
85.20001,-13.69370,-9.07038
85.30000,-13.71050,-9.08752
85.40000,-13.72703,-9.10382
85.50001,-13.74383,-9.11713
85.60001,-13.76063,-9.13568
85.70001,-13.77717,-9.14869
85.80000,-13.79343,-9.16532
85.90000,-13.81037,-9.18325
86.00001,-13.82677,-9.19799
86.10001,-13.84370,-9.22288
86.20001,-13.86063,-9.23966
86.30000,-13.87703,-9.25660
86.40000,-13.89383,-9.27652
86.50001,-13.91037,-9.29275
86.60001,-13.92690,-9.30653
86.70001,-13.94330,-9.32624
86.80000,-13.96037,-9.34702
86.90000,-13.97690,-9.36596
87.00001,-13.99383,-9.38856
87.10001,-14.01037,-9.40088
87.20001,-14.02690,-9.41861
87.30000,-14.04383,-9.43799
87.40000,-14.06023,-9.45648
87.50001,-14.07703,-9.47315
87.60001,-14.09370,-9.49463
87.70001,-14.11037,-9.51367
87.80000,-14.12703,-9.53297
87.90000,-14.14383,-9.55522
88.00001,-14.16050,-9.56904
88.10001,-14.17690,-9.59073
88.20001,-14.19370,-9.60901
88.30000,-14.21010,-9.62732
88.40000,-14.22690,-9.65139
88.50001,-14.24357,-9.66973
88.60001,-14.26037,-9.69406
88.70001,-14.27703,-9.71729
88.80000,-14.29383,-9.74259
88.90000,-14.31050,-9.76339
89.00001,-14.32690,-9.78993
89.10001,-14.34370,-9.81373
89.20001,-14.36023,-9.83752
89.30000,-14.37703,-9.86857
89.40000,-14.39383,-9.89102
89.50001,-14.41036,-9.91784
89.60001,-14.42730,-9.94601
89.70001,-14.44370,-9.96913
89.80000,-14.46036,-9.99402
89.90000,-14.47690,-10.02338
90.00001,-14.49370,-10.05081
90.10001,-14.51023,-10.07734
90.13600,-14.51650,-10.08897