File: GFBaking/data/XG/XG_Bend_Data/XG_Bend_Specimen_RawData_3.csv
Time,Extension,Load
(sec),(mm),(N)
0.00000,0.00000,0.00060
0.05000,-0.00120,0.00027
0.10000,-0.00573,-0.00001
0.15000,-0.01467,0.00118
0.20000,-0.02560,0.00005
0.25000,-0.03560,0.00112
0.30000,-0.04520,0.00178
0.35000,-0.05480,-0.00032
0.40000,-0.06400,-0.00035
0.45000,-0.07280,0.00005
0.50000,-0.08173,0.00136
0.55000,-0.09040,0.00088
0.60000,-0.09893,0.00101
0.65000,-0.10747,0.00151
0.70000,-0.11613,-0.00236
0.75000,-0.12467,-0.00027
0.80000,-0.13293,0.00063
0.85000,-0.14147,0.00216
0.90000,-0.15000,-0.00019
0.95000,-0.15813,0.00015
1.00000,-0.16640,-0.00116
1.05000,-0.17493,-0.00124
1.10000,-0.18320,0.00304
1.15000,-0.19147,0.00078
1.20000,-0.19973,-0.00001
1.25000,-0.20827,0.00018
1.30000,-0.21640,-0.00156
1.35000,-0.22467,0.00067
1.40000,-0.23320,0.00131
1.45000,-0.24160,0.00024
1.50000,-0.24973,-0.00040
1.55000,-0.25827,-0.00001
1.60000,-0.26680,0.00001
1.65000,-0.27493,0.00044
1.70000,-0.28333,0.00017
1.75000,-0.29173,0.00091
1.80000,-0.30013,0.00006
1.85000,-0.30840,0.00045
1.90000,-0.31653,-0.00006
1.95000,-0.32507,-0.00017
2.00000,-0.33333,0.00123
2.05000,-0.34147,0.00013
2.10000,-0.34987,0.00004
2.15000,-0.35827,0.00055
2.20000,-0.36640,-0.00171
2.25000,-0.37467,0.00020
2.30000,-0.38320,0.00084
2.35000,-0.39160,-0.00078
2.40000,-0.39973,-0.00053
2.45000,-0.40827,-0.00033
2.50000,-0.41680,-0.00031
2.55000,-0.42507,0.00032
2.60000,-0.43333,-0.00019
2.65000,-0.44187,0.00007
2.70000,-0.45000,0.00036
2.75000,-0.45813,-0.00067
2.80000,-0.46640,-0.00112
2.85000,-0.47480,0.00022
2.90000,-0.48320,-0.00057
2.95000,-0.49133,0.00007
3.00000,-0.49987,-0.00058
3.05000,-0.50827,-0.00066
3.10000,-0.51653,-0.00067
3.15000,-0.52493,-0.00032
3.20000,-0.53333,-0.00025
3.25000,-0.54173,-0.00055
3.30000,-0.54987,-0.00117
3.35000,-0.55827,-0.00048
3.40000,-0.56680,-0.00056
3.45000,-0.57480,0.00003
3.50000,-0.58320,-0.00037
3.55000,-0.59173,-0.00068
3.60000,-0.59973,-0.00066
3.65000,-0.60813,-0.00102
3.70000,-0.61640,-0.00159
3.75000,-0.62467,0.00201
3.80000,-0.63293,-0.00246
3.85000,-0.64147,-0.00019
3.90000,-0.65000,0.00121
3.95000,-0.65827,-0.00504
4.00000,-0.66667,0.00265
4.05000,-0.67493,-0.00082
4.10000,-0.68333,-0.00215
4.15000,-0.69160,0.00213
4.20000,-0.70000,-0.00317
4.25000,-0.70840,0.00049
4.30000,-0.71680,0.00101
4.35000,-0.72493,-0.00205
4.40000,-0.73320,-0.00087
4.45000,-0.74160,-0.00007
4.50000,-0.74986,-0.00217
4.55000,-0.75800,0.00034
4.60000,-0.76653,-0.00015
4.65000,-0.77493,-0.00230
4.70000,-0.78320,-0.00030
4.75000,-0.79160,0.00009
4.80000,-0.80000,-0.00293
4.85000,-0.80840,0.00030
4.90000,-0.81680,-0.00057
4.95000,-0.82506,-0.00155
5.00000,-0.83346,0.00087
5.05000,-0.84186,-0.00181
5.10000,-0.84986,-0.00163
5.15000,-0.85840,0.00025
5.20000,-0.86653,-0.00188
5.25000,-0.87480,-0.00059
5.30000,-0.88320,-0.00109
5.35000,-0.89160,-0.00100
5.40000,-0.89973,-0.00187
5.45000,-0.90813,-0.00052
5.50000,-0.91666,-0.00192
5.55000,-0.92493,-0.00071
5.60000,-0.93320,-0.00137
5.65000,-0.94173,-0.00115
5.70000,-0.95013,-0.00108
5.75000,-0.95826,-0.00029
5.80000,-0.96666,-0.00218
5.85000,-0.97506,-0.00067
5.90000,-0.98333,-0.00184
5.95000,-0.99160,-0.00028
6.00000,-0.99986,-0.00273
6.05000,-1.00840,-0.00046
6.10000,-1.01653,-0.00110
6.15000,-1.02480,-0.00191
6.20000,-1.03320,-0.00040
6.25000,-1.04160,-0.00245
6.30000,-1.04986,-0.00045
6.35000,-1.05813,-0.00208
6.40000,-1.06666,-0.00156
6.45000,-1.07506,-0.00112
6.50000,-1.08333,-0.00244
6.55000,-1.09186,0.00035
6.60000,-1.10026,-0.00246
6.65000,-1.10826,-0.00044
6.70000,-1.11653,-0.00196
6.75000,-1.12506,-0.00194
6.80000,-1.13320,-0.00122
6.85000,-1.14133,-0.00318
6.90000,-1.14973,-0.00089
6.95000,-1.15813,-0.00151
7.00000,-1.16640,-0.00087
7.05000,-1.17480,-0.00164
7.10000,-1.18320,-0.00110
7.15000,-1.19160,-0.00308
7.20000,-1.19986,-0.00181
7.25000,-1.20826,-0.00108
7.30000,-1.21680,-0.00296
7.35000,-1.22493,-0.00043
7.40000,-1.23320,-0.00242
7.45000,-1.24160,-0.00282
7.50000,-1.25000,-0.00081
7.55000,-1.25813,-0.00163
7.60000,-1.26640,-0.00258
7.65000,-1.27493,-0.00055
7.70000,-1.28320,-0.00395
7.75000,-1.29133,-0.00224
7.80000,-1.29973,-0.00137
7.85000,-1.30826,-0.00250
7.90000,-1.31640,-0.00221
7.95000,-1.32493,-0.00286
8.00000,-1.33346,-0.00279
8.05000,-1.34173,-0.00104
8.10000,-1.35000,-0.00400
8.15000,-1.35826,-0.00076
8.20000,-1.36666,-0.00286
8.25000,-1.37493,-0.00360
8.30000,-1.38306,-0.00027
8.35000,-1.39173,-0.00555
8.40000,-1.40000,-0.00148
8.45000,-1.40813,-0.00141
8.50000,-1.41653,-0.00536
8.55000,-1.42493,0.00036
8.60000,-1.43306,-0.00503
8.65000,-1.44146,-0.00221
8.70000,-1.45000,-0.00230
8.75000,-1.45826,-0.00447
8.80000,-1.46653,-0.00162
8.85000,-1.47493,-0.00409
8.90000,-1.48346,-0.00243
8.95000,-1.49160,-0.00217
9.00000,-1.49986,-0.00464
9.05000,-1.50840,-0.00153
9.10000,-1.51666,-0.00320
9.15000,-1.52493,-0.00402
9.20000,-1.53320,-0.00197
9.25000,-1.54160,-0.00495
9.30000,-1.55000,-0.00304
9.35000,-1.55800,-0.00248
9.40000,-1.56653,-0.00542
9.45000,-1.57493,-0.00233
9.50000,-1.58320,-0.00316
9.55000,-1.59146,-0.00487
9.60000,-1.60013,-0.00240
9.65000,-1.60840,-0.00344
9.70000,-1.61653,-0.00445
9.75000,-1.62493,-0.00312
9.80000,-1.63346,-0.00446
9.85000,-1.64146,-0.00389
9.90000,-1.64986,-0.00328
9.95000,-1.65840,-0.00470
10.00000,-1.66653,-0.00398
10.05000,-1.67466,-0.00417
10.10000,-1.68320,-0.00402
10.15000,-1.69146,-0.00288
10.20000,-1.69960,-0.00584
10.25000,-1.70800,-0.00301
10.30000,-1.71640,-0.00481
10.35000,-1.72493,-0.00424
10.40000,-1.73333,-0.00436
10.45000,-1.74160,-0.00493
10.50000,-1.75013,-0.00385
10.55000,-1.75840,-0.00421
10.60000,-1.76653,-0.00533
10.65000,-1.77506,-0.00422
10.70000,-1.78333,-0.00455
10.75000,-1.79160,-0.00491
10.80000,-1.79986,-0.00464
10.85000,-1.80826,-0.00426
10.90000,-1.81653,-0.00605
10.95000,-1.82466,-0.00463
11.00000,-1.83320,-0.00522
11.05000,-1.84160,-0.00487
11.10000,-1.84973,-0.00363
11.15000,-1.85813,-0.00539
11.20000,-1.86666,-0.00525
11.25000,-1.87506,-0.00472
11.30000,-1.88333,-0.00600
11.35000,-1.89160,-0.00430
11.40000,-1.90013,-0.00511
11.45000,-1.90840,-0.00562
11.50000,-1.91653,-0.00528
11.55000,-1.92506,-0.00482
11.60000,-1.93333,-0.00585
11.65000,-1.94133,-0.00493
11.70000,-1.94973,-0.00575
11.75000,-1.95826,-0.00604
11.80000,-1.96640,-0.00515
11.85000,-1.97466,-0.00751
11.90000,-1.98333,-0.00501
11.95000,-1.99173,-0.00651
12.00000,-2.00000,-0.00587
12.05000,-2.00840,-0.00575
12.10000,-2.01680,-0.00589
12.15000,-2.02506,-0.00640
12.20000,-2.03333,-0.00605
12.25000,-2.04173,-0.00591
12.30000,-2.05000,-0.00734
12.35000,-2.05826,-0.00658
12.40000,-2.06653,-0.00612
12.45000,-2.07506,-0.00908
12.50000,-2.08333,-0.00526
12.55000,-2.09146,-0.00377
12.60000,-2.09999,-0.00785
12.65000,-2.10839,-0.01074
12.70000,-2.11653,-0.00594
12.75000,-2.12479,-0.00775
12.80000,-2.13333,-0.00713
12.85000,-2.14173,-0.00112
12.90000,-2.14999,-0.01473
12.95000,-2.15826,-0.00472
13.00000,-2.16693,-0.00716
13.05000,-2.17493,-0.00800
13.10000,-2.18306,-0.00629
13.15000,-2.19159,-0.00829
13.20000,-2.19986,-0.00817
13.25000,-2.20799,-0.00634
13.30000,-2.21653,-0.00901
13.35000,-2.22479,-0.00957
13.40000,-2.23306,-0.00627
13.45000,-2.24159,-0.00904
13.50000,-2.24986,-0.00791
13.55000,-2.25839,-0.00587
13.60000,-2.26666,-0.01200
13.65000,-2.27493,-0.00655
13.70000,-2.28333,-0.00959
13.75000,-2.29173,-0.00861
13.80000,-2.29999,-0.00882
13.85000,-2.30826,-0.00839
13.90000,-2.31679,-0.01047
13.95000,-2.32479,-0.00770
14.00000,-2.33319,-0.01004
14.05000,-2.34173,-0.00799
14.10000,-2.34986,-0.00842
14.15000,-2.35799,-0.01014
14.20000,-2.36639,-0.00922
14.25000,-2.37479,-0.00803
14.30000,-2.38306,-0.01063
14.35000,-2.39159,-0.00837
14.40000,-2.40013,-0.00927
14.45000,-2.40839,-0.01017
14.50000,-2.41666,-0.00928
14.55000,-2.42493,-0.00949
14.60000,-2.43359,-0.00961
14.65000,-2.44186,-0.00878
14.70000,-2.44986,-0.01054
14.75000,-2.45839,-0.00919
14.80000,-2.46679,-0.00922
14.85000,-2.47479,-0.01020
14.90000,-2.48319,-0.01044
14.95000,-2.49159,-0.00938
15.00000,-2.49973,-0.01165
15.05000,-2.50813,-0.00865
15.10000,-2.51679,-0.01067
15.15000,-2.52506,-0.01089
15.20000,-2.53319,-0.01011
15.25000,-2.54173,-0.00956
15.30000,-2.55026,-0.01086
15.35000,-2.55839,-0.00967
15.40000,-2.56666,-0.01120
15.45000,-2.57519,-0.01039
15.50000,-2.58346,-0.00922
15.55000,-2.59159,-0.01067
15.60000,-2.59986,-0.01186
15.65000,-2.60826,-0.00972
15.70000,-2.61653,-0.01177
15.75000,-2.62466,-0.00954
15.80000,-2.63319,-0.01052
15.85000,-2.64159,-0.01159
15.90000,-2.64986,-0.01093
15.95000,-2.65826,-0.01097
16.00000,-2.66666,-0.01157
16.05000,-2.67519,-0.00993
16.10000,-2.68333,-0.01129
16.15000,-2.69159,-0.01076
16.20000,-2.70026,-0.01078
16.25000,-2.70839,-0.01139
16.30000,-2.71653,-0.01188
16.35000,-2.72506,-0.01041
16.40000,-2.73319,-0.01137
16.45000,-2.74146,-0.01127
16.50000,-2.74986,-0.01094
16.55000,-2.75826,-0.01105
16.60000,-2.76639,-0.01117
16.65000,-2.77479,-0.01144
16.70000,-2.78319,-0.01154
16.75000,-2.79173,-0.01149
16.80000,-2.79999,-0.01238
16.85000,-2.80826,-0.01171
16.90000,-2.81679,-0.01114
16.95000,-2.82506,-0.01146
17.00000,-2.83319,-0.01208
17.05000,-2.84173,-0.01159
17.10000,-2.85013,-0.01150
17.15000,-2.85813,-0.01210
17.20000,-2.86639,-0.01197
17.25000,-2.87493,-0.01199
17.30000,-2.88306,-0.01235
17.35000,-2.89133,-0.01199
17.40000,-2.89986,-0.01212
17.45000,-2.90839,-0.01178
17.50000,-2.91653,-0.01258
17.55000,-2.92506,-0.01140
17.60000,-2.93333,-0.01277
17.65000,-2.94173,-0.01251
17.70000,-2.95013,-0.01281
17.75000,-2.95826,-0.01269
17.80000,-2.96679,-0.01288
17.85000,-2.97506,-0.01181
17.90000,-2.98319,-0.01298
17.95000,-2.99186,-0.01283
18.00000,-3.00013,-0.01232
18.05000,-3.00813,-0.01263
18.10000,-3.01653,-0.01217
18.15000,-3.02493,-0.01261
18.20000,-3.03293,-0.01260
18.25000,-3.04133,-0.01283
18.30000,-3.04999,-0.01260
18.35000,-3.05839,-0.01267
18.40000,-3.06653,-0.01337
18.45000,-3.07506,-0.01289
18.50000,-3.08359,-0.01283
18.55000,-3.09173,-0.01248
18.60000,-3.09999,-0.01335
18.65000,-3.10839,-0.01274
18.70000,-3.11666,-0.01276
18.75000,-3.12493,-0.01302
18.80000,-3.13306,-0.01297
18.85000,-3.14159,-0.01337
18.90000,-3.14999,-0.01328
18.95000,-3.15799,-0.01309
19.00000,-3.16653,-0.01321
19.05000,-3.17506,-0.01283
19.10000,-3.18319,-0.01306
19.15000,-3.19146,-0.01333
19.20000,-3.19999,-0.01303
19.25000,-3.20839,-0.01351
19.30000,-3.21653,-0.01367
19.35000,-3.22493,-0.01302
19.40000,-3.23359,-0.01354
19.45000,-3.24159,-0.01353
19.50000,-3.24986,-0.01350
19.55000,-3.25826,-0.01337
19.60000,-3.26653,-0.01333
19.65000,-3.27479,-0.01405
19.70000,-3.28319,-0.01376
19.75000,-3.29146,-0.01386
19.80000,-3.29973,-0.01385
19.85000,-3.30813,-0.01442
19.90000,-3.31639,-0.01341
19.95000,-3.32506,-0.01463
20.00000,-3.33333,-0.01441
20.05000,-3.34159,-0.01407
20.10000,-3.35013,-0.01387
20.15000,-3.35853,-0.01435
20.20000,-3.36666,-0.01404
20.25000,-3.37506,-0.01470
20.30000,-3.38346,-0.01426
20.35000,-3.39159,-0.01393
20.40000,-3.39986,-0.01456
20.45000,-3.40839,-0.01392
20.50000,-3.41652,-0.01516
20.55000,-3.42479,-0.01410
20.60000,-3.43332,-0.01485
20.65000,-3.44172,-0.01444
20.70000,-3.44986,-0.01523
20.75000,-3.45839,-0.01460
20.80000,-3.46679,-0.01407
20.85000,-3.47506,-0.01491
20.90000,-3.48346,-0.01467
20.95000,-3.49172,-0.01573
21.00000,-3.50026,-0.01428
21.05000,-3.50866,-0.01479
21.10000,-3.51652,-0.01418
21.15000,-3.52506,-0.01456
21.20000,-3.53346,-0.01512
21.25000,-3.54132,-0.01458
21.30000,-3.54972,-0.01518
21.35000,-3.55826,-0.01492
21.40000,-3.56666,-0.01543
21.45000,-3.57492,-0.01481
21.50000,-3.58332,-0.01564
21.55000,-3.59172,-0.01568
21.60000,-3.59986,-0.01538
21.65000,-3.60839,-0.01525
21.70000,-3.61679,-0.01503
21.75000,-3.62492,-0.01530
21.80000,-3.63319,-0.01594
21.85000,-3.64159,-0.01501
21.90000,-3.64999,-0.01647
21.95000,-3.65826,-0.01528
22.00000,-3.66652,-0.01665
22.05000,-3.67492,-0.01474
22.10000,-3.68306,-0.01569
22.15000,-3.69119,-0.01595
22.20000,-3.69972,-0.01589
22.25000,-3.70826,-0.01610
22.30000,-3.71652,-0.01643
22.35000,-3.72506,-0.01577
22.40000,-3.73346,-0.01662
22.45000,-3.74172,-0.01579
22.50000,-3.74986,-0.01691
22.55000,-3.75839,-0.01600
22.60000,-3.76692,-0.01616
22.65000,-3.77492,-0.01714
22.70000,-3.78319,-0.01644
22.75000,-3.79172,-0.01663
22.80000,-3.79986,-0.01714
22.85000,-3.80812,-0.01636
22.90000,-3.81652,-0.01647
22.95000,-3.82479,-0.01694
23.00000,-3.83306,-0.01671
23.05000,-3.84159,-0.01683
23.10000,-3.84999,-0.01699
23.15000,-3.85826,-0.01659
23.20000,-3.86666,-0.01800
23.25000,-3.87492,-0.01630
23.30000,-3.88346,-0.01772
23.35000,-3.89172,-0.01671
23.40000,-3.89986,-0.01725
23.45000,-3.90839,-0.01726
23.50000,-3.91679,-0.01676
23.55000,-3.92479,-0.01725
23.60000,-3.93319,-0.01696
23.65000,-3.94172,-0.01737
23.70000,-3.94972,-0.01769
23.75000,-3.95799,-0.01778
23.80000,-3.96652,-0.01687
23.85000,-3.97479,-0.01743
23.90000,-3.98306,-0.01712
23.95000,-3.99159,-0.01747
24.00000,-3.99999,-0.01805
24.05000,-4.00839,-0.01678
24.10000,-4.01692,-0.01754
24.15000,-4.02506,-0.01712
24.20000,-4.03346,-0.01676
24.25000,-4.04172,-0.01790
24.30000,-4.04986,-0.01779
24.35000,-4.05839,-0.01764
24.40000,-4.06666,-0.01732
24.45000,-4.07466,-0.01761
24.50000,-4.08319,-0.01760
24.55000,-4.09159,-0.01716
24.60000,-4.09972,-0.01837
24.65000,-4.10812,-0.01755
24.70000,-4.11679,-0.01794
24.75000,-4.12492,-0.01723
24.80000,-4.13319,-0.01800
24.85000,-4.14172,-0.01732
24.90000,-4.15012,-0.01716
24.95000,-4.15826,-0.01853
25.00000,-4.16666,-0.01779
25.05000,-4.17506,-0.01819
25.10000,-4.18332,-0.01727
25.15000,-4.19159,-0.01766
25.20000,-4.19986,-0.01858
25.25000,-4.20839,-0.01671
25.30000,-4.21666,-0.01818
25.35000,-4.22466,-0.01768
25.40000,-4.23319,-0.01785
25.45000,-4.24172,-0.01743
25.50000,-4.24986,-0.01778
25.55000,-4.25826,-0.01746
25.60000,-4.26666,-0.01780
25.65000,-4.27506,-0.01779
25.70000,-4.28319,-0.01734
25.75000,-4.29172,-0.01696
25.80000,-4.30026,-0.01661
25.85000,-4.30826,-0.01667
25.90000,-4.31652,-0.01714
25.95000,-4.32506,-0.01676
26.00000,-4.33319,-0.01713
26.05000,-4.34146,-0.01539
26.10000,-4.34986,-0.01563
26.15000,-4.35799,-0.01632
26.20000,-4.36626,-0.01558
26.25000,-4.37479,-0.01588
26.30000,-4.38319,-0.01545
26.35000,-4.39172,-0.01541
26.40000,-4.39999,-0.01497
26.45000,-4.40826,-0.01522
26.50000,-4.41679,-0.01521
26.55000,-4.42506,-0.01537
26.60000,-4.43319,-0.01509
26.65000,-4.44172,-0.01456
26.70000,-4.45012,-0.01501
26.75000,-4.45812,-0.01462
26.80000,-4.46652,-0.01510
26.85000,-4.47492,-0.01505
26.90000,-4.48306,-0.01512
26.95000,-4.49132,-0.01478
27.00000,-4.49986,-0.01484
27.05000,-4.50839,-0.01470
27.10000,-4.51666,-0.01484
27.15000,-4.52506,-0.01492
27.20000,-4.53346,-0.01432
27.25000,-4.54159,-0.01532
27.30000,-4.55012,-0.01494
27.35000,-4.55839,-0.01485
27.40000,-4.56679,-0.01414
27.45000,-4.57506,-0.01459
27.50000,-4.58319,-0.01458
27.55000,-4.59172,-0.01400
27.60000,-4.60012,-0.01515
27.65000,-4.60812,-0.01457
27.70000,-4.61639,-0.01450
27.75000,-4.62492,-0.01513
27.80000,-4.63306,-0.01445
27.85000,-4.64146,-0.01505
27.90000,-4.64999,-0.01470
27.95000,-4.65826,-0.01453
28.00000,-4.66652,-0.01523
28.05000,-4.67506,-0.01396
28.10000,-4.68359,-0.01431
28.15000,-4.69172,-0.01418
28.20000,-4.70012,-0.01504
28.25000,-4.70852,-0.01431
28.30000,-4.71666,-0.01390
28.35000,-4.72492,-0.01407
28.40000,-4.73319,-0.01489
28.45000,-4.74159,-0.01363
28.50000,-4.74986,-0.01459
28.55000,-4.75799,-0.01408
28.60000,-4.76652,-0.01394
28.65000,-4.77506,-0.01436
28.70000,-4.78332,-0.01476
28.75000,-4.79159,-0.01339
28.80000,-4.80012,-0.01477
28.85000,-4.80839,-0.01352
28.90000,-4.81666,-0.01422
28.95000,-4.82519,-0.01416
29.00000,-4.83345,-0.01393
29.05000,-4.84159,-0.01372
29.10000,-4.84985,-0.01373
29.15000,-4.85825,-0.01379
29.20000,-4.86652,-0.01408
29.25000,-4.87479,-0.01382
29.30000,-4.88319,-0.01452
29.35000,-4.89145,-0.01409
29.40000,-4.89985,-0.01357
29.45000,-4.90825,-0.01380
29.50000,-4.91665,-0.01398
29.55000,-4.92492,-0.01335
29.60000,-4.93332,-0.01365
29.65000,-4.94159,-0.01297
29.70000,-4.94999,-0.01299
29.75000,-4.95825,-0.01437
29.80000,-4.96639,-0.01195
29.85000,-4.97492,-0.01402
29.90000,-4.98332,-0.01385
29.95000,-4.99145,-0.01165
30.00000,-4.99972,-0.01453
30.05000,-5.00825,-0.01095
30.10000,-5.01625,-0.01314
30.15000,-5.02465,-0.01251
30.20000,-5.03319,-0.01339
30.25000,-5.04159,-0.01174
30.30000,-5.04985,-0.01386
30.35000,-5.05839,-0.01138
30.40000,-5.06679,-0.01266
30.45000,-5.07505,-0.01265
30.50000,-5.08345,-0.01230
30.55000,-5.09172,-0.01234
30.60000,-5.10012,-0.01198
30.65000,-5.10852,-0.01126
30.70000,-5.11652,-0.01228
30.75000,-5.12505,-0.01199
30.80000,-5.13332,-0.01181
30.85000,-5.14145,-0.01164
30.90000,-5.14985,-0.01093
30.95000,-5.15825,-0.01170
31.00000,-5.16625,-0.01244
31.05000,-5.17479,-0.01125
31.10000,-5.18332,-0.01303
31.15000,-5.19172,-0.01103
31.20000,-5.19985,-0.01243
31.25000,-5.20839,-0.01134
31.30000,-5.21679,-0.01117
31.35000,-5.22505,-0.01118
31.40000,-5.23332,-0.01212
31.45000,-5.24172,-0.01080
31.50000,-5.24999,-0.01107
31.55000,-5.25825,-0.01047
31.60000,-5.26652,-0.01037
31.65000,-5.27505,-0.01065
31.70000,-5.28332,-0.01180
31.75000,-5.29145,-0.00971
31.80000,-5.29985,-0.01117
31.85000,-5.30825,-0.01026
31.90000,-5.31665,-0.01080
31.95000,-5.32479,-0.01004
32.00000,-5.33332,-0.01098
32.05000,-5.34172,-0.00939
32.10000,-5.34985,-0.01066
32.15000,-5.35839,-0.00936
32.20000,-5.36679,-0.00973
32.25000,-5.37492,-0.00957
32.30000,-5.38319,-0.01013
32.35000,-5.39172,-0.00898
32.40000,-5.39985,-0.00963
32.45000,-5.40812,-0.00931
32.50000,-5.41652,-0.00901
32.55000,-5.42479,-0.00850
32.60000,-5.43305,-0.00826
32.65000,-5.44145,-0.00908
32.70000,-5.44999,-0.00832
32.75000,-5.45839,-0.00805
32.80000,-5.46665,-0.00901
32.85000,-5.47492,-0.00748
32.90000,-5.48345,-0.00812
32.95000,-5.49172,-0.00696
33.00000,-5.49985,-0.00798
33.05000,-5.50839,-0.00591
33.10000,-5.51665,-0.00681
33.15000,-5.52465,-0.00577
33.20000,-5.53305,-0.00606
33.25000,-5.54159,-0.00509
33.30000,-5.54972,-0.00580
33.35000,-5.55799,-0.00542
33.40000,-5.56652,-0.00417
33.45000,-5.57492,-0.00420
33.50000,-5.58319,-0.00482
33.55000,-5.59172,-0.00325
33.60000,-5.60012,-0.00323
33.65000,-5.60839,-0.00325
33.70000,-5.61679,-0.00353
33.75000,-5.62492,-0.00293
33.80000,-5.63345,-0.00254
33.85000,-5.64172,-0.00209
33.90000,-5.64985,-0.00200
33.95000,-5.65839,-0.00120
34.00000,-5.66679,-0.00224
34.05000,-5.67479,-0.00093
34.10000,-5.68305,-0.00098
34.15000,-5.69159,-0.00186
34.20000,-5.69959,-0.00048
34.25000,-5.70812,-0.00183
34.30000,-5.71679,-0.00155
34.35000,-5.72505,-0.00017
34.40000,-5.73332,-0.00169
34.45000,-5.74172,-0.00026
34.50000,-5.75012,-0.00013
34.55000,-5.75839,0.00205
34.60000,-5.76679,0.00102
34.65000,-5.77519,0.00086
34.70000,-5.78332,0.00104
34.75000,-5.79172,-0.00026
34.80000,-5.79999,-0.00008
34.85000,-5.80839,0.00068
34.90000,-5.81652,0.00105
34.95000,-5.82479,-0.00054
35.00000,-5.83319,-0.00049
35.05000,-5.84159,-0.00056
35.10000,-5.84999,-0.00001
35.15000,-5.85825,0.00003
35.20000,-5.86679,-0.00087
35.25000,-5.87505,0.00006
35.30000,-5.88332,-0.00151
35.35000,-5.89172,-0.00100
35.40000,-5.90012,0.00040
35.45000,-5.90825,-0.00045
35.50000,-5.91652,-0.00047
35.55000,-5.92505,-0.00091
35.60000,-5.93305,-0.00109
35.65000,-5.94145,-0.00180
35.70000,-5.94985,-0.00008
35.75000,-5.95812,-0.00160
35.80000,-5.96625,-0.00102
35.85000,-5.97479,-0.00106
35.90000,-5.98319,-0.00310
35.95000,-5.99172,-0.00055
36.00000,-5.99999,-0.00248
36.05000,-6.00825,-0.00096
36.10000,-6.01665,-0.00138
36.15000,-6.02505,-0.00297
36.20000,-6.03319,-0.00085
36.25000,-6.04172,-0.00240
36.30000,-6.04999,-0.00042
36.35000,-6.05812,-0.00111
36.40000,-6.06652,-0.00083
36.45000,-6.07505,-0.00180
36.50000,-6.08305,-0.00243
36.55000,-6.09132,0.00042
36.60000,-6.09998,-0.00012
36.65000,-6.10825,-0.00054
36.70000,-6.11652,-0.00227
36.75000,-6.12492,-0.00002
36.80000,-6.13345,-0.00051
36.85000,-6.14172,-0.00044
36.90000,-6.15012,-0.00039
36.95000,-6.15825,-0.00037
37.00000,-6.16679,0.00009
37.05000,-6.17505,-0.00026
37.10000,-6.18305,-0.00167
37.15000,-6.19172,0.00076
37.20000,-6.20012,-0.00054
37.25000,-6.20798,0.00100
37.30000,-6.21652,-0.00035
37.35000,-6.22505,0.00081
37.40000,-6.23305,0.00061
37.45000,-6.24145,0.00091
37.50000,-6.25012,-0.00010
37.55000,-6.25825,0.00214
37.60000,-6.26652,0.00118
37.65000,-6.27505,-0.00045
37.70000,-6.28345,0.00213
37.75000,-6.29158,0.00109
37.80000,-6.29998,0.00409
37.85000,-6.30852,0.00344
37.90000,-6.31665,-0.00013
37.95000,-6.32492,0.00292
38.00000,-6.33318,-0.00257
38.05000,-6.34158,-0.00010
38.10000,-6.34985,0.00335
38.15000,-6.35798,-0.00183
38.20000,-6.36652,0.00131
38.25000,-6.37505,0.00230
38.30000,-6.38332,-0.00175
38.35000,-6.39172,0.00210
38.40000,-6.40012,0.00261
38.45000,-6.40852,-0.00142
38.50000,-6.41665,0.00122
38.55000,-6.42505,0.00254
38.60000,-6.43345,-0.00081
38.65000,-6.44158,0.00247
38.70000,-6.44985,0.00118
38.75000,-6.45852,0.00032
38.80000,-6.46652,0.00190
38.85000,-6.47478,-0.00011
38.90000,-6.48318,0.00227
38.95000,-6.49132,0.00240
39.00000,-6.49972,0.00019
39.05000,-6.50812,0.00225
39.10000,-6.51665,0.00106
39.15000,-6.52505,0.00230
39.20000,-6.53345,0.00121
39.25000,-6.54158,-0.00626
39.30000,-6.55012,0.00166
39.35000,-6.55838,-0.00419
39.40000,-6.56652,-0.00091
39.45000,-6.57518,-0.00085
39.50000,-6.58345,-0.00119
39.55000,-6.59145,0.00040
39.60000,-6.59972,-0.00322
39.65000,-6.60825,-0.00053
39.70000,-6.61652,-0.00173
39.75000,-6.62478,-0.00077
39.80000,-6.63332,0.00034
39.85000,-6.64158,-0.00135
39.90000,-6.64985,-0.00118
39.95000,-6.65825,-0.00009
40.00000,-6.66665,-0.00166
40.05000,-6.67505,-0.00045
40.10000,-6.68345,0.00016
40.15000,-6.69158,-0.00152
40.20000,-6.70025,-0.00027
40.25000,-6.70852,-0.00104
40.30000,-6.71652,-0.00042
40.35000,-6.72492,-0.00040
40.40000,-6.73332,-0.00056
40.45000,-6.74145,-0.00191
40.50000,-6.74985,0.00005
40.55000,-6.75838,-0.00072
40.60000,-6.76652,-0.00189
40.65000,-6.77478,0.00013
40.70000,-6.78345,-0.00136
40.75000,-6.79172,-0.00092
40.80000,-6.79985,-0.00039
40.85000,-6.80852,-0.00184
40.90000,-6.81692,0.00041
40.95000,-6.82505,0.00002
41.00000,-6.83332,-0.00173
41.05000,-6.84172,-0.00089
41.10000,-6.84998,-0.00013
41.15000,-6.85825,-0.00145
41.20000,-6.86652,-0.00080
41.25000,-6.87505,-0.00029
41.30000,-6.88318,-0.00100
41.35000,-6.89132,-0.00028
41.40000,-6.89985,-0.00136
41.45000,-6.90838,-0.00103
41.50000,-6.91652,-0.00001
41.55000,-6.92492,-0.00024
41.60000,-6.93332,-0.00057
41.65000,-6.94172,-0.00128
41.70000,-6.94985,-0.00007
41.75000,-6.95838,-0.00064
41.80000,-6.96692,-0.00063
41.85000,-6.97505,-0.00048
41.90000,-6.98318,-0.00013
41.95000,-6.99172,-0.00093
42.00000,-6.99985,-0.00064
42.05000,-7.00812,-0.00054
42.10000,-7.01652,0.00033
42.15000,-7.02478,-0.00020
42.20000,-7.03305,-0.00088
42.25000,-7.04158,-0.00067
42.30000,-7.04998,0.00006
42.35000,-7.05838,-0.00064
42.40000,-7.06665,-0.00124
42.45000,-7.07492,-0.00100
42.50000,-7.08345,-0.00038
42.55000,-7.09172,-0.00023
42.60000,-7.09985,-0.00135
42.65000,-7.10838,-0.00054
42.70000,-7.11678,0.00051
42.75000,-7.12492,-0.00068
42.80000,-7.13318,-0.00018
42.85000,-7.14172,-0.00051
42.90000,-7.14985,-0.00033
42.95000,-7.15798,-0.00006
43.00000,-7.16652,-0.00147
43.05000,-7.17492,-0.00010
43.10000,-7.18318,-0.00001
43.15000,-7.19172,-0.00037
43.20000,-7.20012,-0.00105
43.25000,-7.20838,-0.00068
43.30000,-7.21678,-0.00021
43.35000,-7.22492,-0.00005
43.40000,-7.23345,-0.00086
43.45000,-7.24172,-0.00008
43.50000,-7.24985,0.00003
43.55000,-7.25825,-0.00002
43.60000,-7.26665,-0.00044
43.65000,-7.27478,-0.00013
43.70000,-7.28318,0.00035
43.75000,-7.29158,0.00013
43.80000,-7.29972,-0.00226
43.85000,-7.30812,0.00003
43.90000,-7.31678,-0.00001
43.95000,-7.32505,-0.00051
44.00000,-7.33318,-0.00056
44.05000,-7.34172,0.00003
44.10000,-7.35012,0.00019
44.15000,-7.35838,0.00055
44.20000,-7.36678,-0.00184
44.25000,-7.37505,0.00020
44.30000,-7.38332,0.00127
44.35000,-7.39158,-0.00106
44.40000,-7.39985,-0.00100
44.45000,-7.40838,0.00057
44.50000,-7.41652,-0.00035
44.55000,-7.42478,0.00087
44.60000,-7.43318,-0.00049
44.65000,-7.44158,0.00009
44.70000,-7.44985,-0.00026
44.75000,-7.45825,-0.00003
44.80000,-7.46678,-0.00029
44.85000,-7.47505,0.00045
44.90000,-7.48332,-0.00064
44.95000,-7.49172,0.00061
45.00000,-7.50025,-0.00032
45.05000,-7.50825,0.00007
45.10000,-7.51638,0.00054
45.15000,-7.52505,-0.00015
45.20000,-7.53318,-0.00080
45.25000,-7.54145,0.00019
45.30000,-7.54985,-0.00012
45.35000,-7.55811,0.00025
45.40000,-7.56638,-0.00015
45.45000,-7.57478,-0.00001
45.50000,-7.58318,0.00077
45.55000,-7.59171,0.00065
45.60000,-7.59998,-0.00024
45.65000,-7.60825,0.00011
45.70000,-7.61678,-0.00033
45.75000,-7.62505,0.00022
45.80000,-7.63318,-0.00030
45.85000,-7.64158,0.00055
45.90000,-7.64998,0.00036
45.95000,-7.65798,-0.00027
46.00000,-7.66625,0.00073
46.05000,-7.67491,0.00043
46.10000,-7.68305,0.00004
46.15000,-7.69131,0.00083
46.20000,-7.69998,0.00001
46.25000,-7.70838,-0.00034
46.30000,-7.71665,0.00081
46.35000,-7.72505,-0.00001
46.40000,-7.73358,0.00040
46.45000,-7.74171,0.00095
46.50000,-7.75011,0.00060
46.55000,-7.75838,0.00090
46.60000,-7.76678,0.00037
46.65000,-7.77518,0.00060
46.70000,-7.78318,0.00095
46.75000,-7.79171,0.00065
46.80000,-7.80011,0.00050
46.85000,-7.80798,0.00022
46.90000,-7.81638,0.00009
46.95000,-7.82491,0.00114
47.00000,-7.83305,-0.00035
47.05000,-7.84131,0.00065
47.10000,-7.84998,0.00010
47.15000,-7.85838,0.00010
47.20000,-7.86651,0.00021
47.25000,-7.87491,0.00022
47.30000,-7.88345,-0.00011
47.35000,-7.89158,0.00105
47.40000,-7.89998,-0.00051
47.45000,-7.90838,0.00075
47.50000,-7.91665,0.00099
47.55000,-7.92491,0.00043
47.60000,-7.93318,0.00036
47.65000,-7.94158,0.00004
47.70000,-7.94985,-0.00002
47.75000,-7.95798,0.00136
47.80000,-7.96651,0.00031
47.85000,-7.97505,0.00079
47.90000,-7.98318,-0.00013
47.95000,-7.99158,0.00009
48.00000,-8.00011,-0.00018
48.05000,-8.00838,0.00042
48.10000,-8.01651,-0.00001
48.15000,-8.02491,0.00057
48.20000,-8.03345,0.00084
48.25000,-8.04158,-0.00008
48.30000,-8.04985,0.00002
48.33000,-8.05505,-0.00020