File: GFBaking/data/2_8PercentGluten/2_8gluten_Compression_Continued.is_comp_RawData/Specimen_RawData_1.csv
Time,Extension,Load
(sec),(mm),(N)
0.00000,-0.00027,-0.34311
0.10000,-0.00707,-0.34877
0.20000,-0.02680,-0.37861
0.30000,-0.04653,-0.40854
0.40000,-0.06467,-0.43483
0.50000,-0.08253,-0.45937
0.60000,-0.09973,-0.48254
0.70000,-0.11653,-0.50511
0.80000,-0.13347,-0.52583
0.90000,-0.15013,-0.54710
1.00000,-0.16693,-0.56906
1.10000,-0.18333,-0.59091
1.20000,-0.20027,-0.61205
1.30000,-0.21680,-0.63244
1.40000,-0.23373,-0.65424
1.50000,-0.25040,-0.67471
1.60000,-0.26693,-0.69500
1.70000,-0.28373,-0.71594
1.80000,-0.30013,-0.73709
1.90000,-0.31680,-0.75761
2.00000,-0.33347,-0.77767
2.10000,-0.35027,-0.79905
2.20000,-0.36693,-0.82074
2.30000,-0.38373,-0.84194
2.40000,-0.40053,-0.86164
2.50000,-0.41680,-0.88253
2.60000,-0.43373,-0.90340
2.70000,-0.45000,-0.92345
2.80000,-0.46693,-0.94467
2.90000,-0.48373,-0.96544
3.00000,-0.50040,-0.98593
3.10000,-0.51693,-1.00755
3.20000,-0.53373,-1.02798
3.30000,-0.55040,-1.04898
3.40000,-0.56680,-1.06972
3.50000,-0.58360,-1.09015
3.60000,-0.60013,-1.11191
3.70000,-0.61707,-1.13354
3.80000,-0.63373,-1.15461
3.90000,-0.65027,-1.17476
4.00000,-0.66707,-1.19587
4.10000,-0.68360,-1.21717
4.20000,-0.70026,-1.23777
4.30000,-0.71666,-1.25858
4.40000,-0.73373,-1.28020
4.50000,-0.75026,-1.30087
4.60000,-0.76706,-1.32186
4.70000,-0.78386,-1.34216
4.80000,-0.80013,-1.36326
4.90000,-0.81706,-1.38404
5.00000,-0.83346,-1.40539
5.10000,-0.85013,-1.42637
5.20000,-0.86680,-1.44591
5.30000,-0.88373,-1.46869
5.40000,-0.90040,-1.48786
5.50000,-0.91720,-1.51017
5.60000,-0.93373,-1.52992
5.70000,-0.95013,-1.55038
5.80000,-0.96693,-1.57173
5.90000,-0.98333,-1.59214
6.00000,-1.00013,-1.61490
6.10000,-1.01706,-1.63592
6.20000,-1.03373,-1.65723
6.30000,-1.05040,-1.67791
6.40000,-1.06693,-1.69882
6.50000,-1.08360,-1.71969
6.60000,-1.10000,-1.74138
6.70000,-1.11693,-1.76184
6.80000,-1.13346,-1.78296
6.90000,-1.15040,-1.80493
7.00000,-1.16733,-1.82679
7.10000,-1.18373,-1.84693
7.20000,-1.20040,-1.86839
7.30000,-1.21706,-1.88998
7.40000,-1.23373,-1.90993
7.50000,-1.25013,-1.93030
7.60000,-1.26706,-1.95121
7.70000,-1.28360,-1.97181
7.80000,-1.30040,-1.99321
7.90000,-1.31693,-2.01296
8.00000,-1.33346,-2.03499
8.10000,-1.35040,-2.05595
8.20000,-1.36666,-2.07600
8.30000,-1.38346,-2.09677
8.40000,-1.40026,-2.11730
8.50000,-1.41706,-2.13839
8.60000,-1.43346,-2.15895
8.70000,-1.45040,-2.17942
8.80000,-1.46706,-2.19943
8.90000,-1.48346,-2.22018
9.00000,-1.50040,-2.23960
9.10000,-1.51680,-2.25923
9.20000,-1.53360,-2.28156
9.30000,-1.55040,-2.29915
9.40000,-1.56706,-2.31882
9.50000,-1.58373,-2.33879
9.60000,-1.60040,-2.35728
9.70000,-1.61706,-2.37575
9.80000,-1.63346,-2.39626
9.90000,-1.65026,-2.41342
10.00000,-1.66680,-2.43315
10.10000,-1.68346,-2.45193
10.20000,-1.70040,-2.47174
10.30000,-1.71693,-2.48975
10.40000,-1.73386,-2.50796
10.50000,-1.75040,-2.52776
10.60000,-1.76706,-2.54608
10.70000,-1.78346,-2.56419
10.80000,-1.80040,-2.58239
10.90000,-1.81693,-2.59608
11.00000,-1.83386,-2.58112
11.10000,-1.85040,-2.56514
11.20000,-1.86693,-2.57639
11.30000,-1.88360,-2.43197
11.40000,-1.90013,-2.45387
11.50000,-1.91680,-2.48553
11.60000,-1.93346,-2.51572
11.70000,-1.95040,-2.54099
11.80000,-1.96693,-2.56636
11.90000,-1.98360,-2.59049
12.00000,-2.00040,-2.61160
12.10000,-2.01680,-2.63303
12.20000,-2.03359,-2.65118
12.30000,-2.05000,-2.67235
12.40000,-2.06706,-2.69482
12.50000,-2.08373,-2.70257
12.60000,-2.10039,-2.72220
12.70000,-2.11706,-2.74421
12.80000,-2.13386,-2.76615
12.90000,-2.15039,-2.78578
13.00000,-2.16679,-2.80686
13.10000,-2.18373,-2.82841
13.20000,-2.20013,-2.84757
13.30000,-2.21693,-2.86846
13.40000,-2.23373,-2.88702
13.50000,-2.25013,-2.90317
13.60000,-2.26679,-2.92156
13.70000,-2.28333,-2.93748
13.80000,-2.30026,-2.95563
13.90000,-2.31666,-2.97190
14.00000,-2.33359,-2.98864
14.10000,-2.35026,-3.00268
14.20000,-2.36706,-3.01843
14.30000,-2.38386,-3.03298
14.40000,-2.40039,-3.04819
14.50000,-2.41706,-3.06293
14.60000,-2.43359,-3.07812
14.70000,-2.45013,-3.09302
14.80000,-2.46693,-3.10728
14.90000,-2.48373,-3.12221
15.00000,-2.50039,-3.13442
15.10000,-2.51706,-3.14895
15.20000,-2.53373,-3.15960
15.30000,-2.54999,-3.17235
15.40000,-2.56693,-3.18500
15.50000,-2.58333,-3.19871
15.60000,-2.60039,-3.21365
15.70000,-2.61719,-3.22829
15.80000,-2.63373,-3.24307
15.90000,-2.65039,-3.25894
16.00000,-2.66706,-3.27473
16.10000,-2.68359,-3.28877
16.20000,-2.69986,-3.30476
16.30000,-2.71706,-3.32265
16.40000,-2.73359,-3.33703
16.50000,-2.75039,-3.35490
16.60000,-2.76719,-3.36923
16.70000,-2.78359,-3.38405
16.80000,-2.80053,-3.40074
16.90000,-2.81693,-3.41578
17.00000,-2.83373,-3.43026
17.10000,-2.85026,-3.44756
17.20000,-2.86693,-3.46035
17.30000,-2.88359,-3.47605
17.40000,-2.90039,-3.49194
17.50000,-2.91719,-3.50564
17.60000,-2.93359,-3.52045
17.70000,-2.95039,-3.53343
17.80000,-2.96666,-3.54735
17.90000,-2.98346,-3.56097
18.00000,-3.00026,-3.57455
18.10000,-3.01706,-3.58878
18.20000,-3.03359,-3.60180
18.30000,-3.05039,-3.61514
18.40000,-3.06706,-3.62559
18.50000,-3.08346,-3.63741
18.60000,-3.10039,-3.64861
18.70000,-3.11666,-3.66040
18.80000,-3.13359,-3.67340
18.90000,-3.15039,-3.68432
19.00000,-3.16706,-3.69707
19.10000,-3.18373,-3.70904
19.20000,-3.20039,-3.72041
19.30000,-3.21706,-3.73245
19.40000,-3.23346,-3.74437
19.50000,-3.25026,-3.75588
19.60000,-3.26679,-3.76689
19.70000,-3.28373,-3.77950
19.80000,-3.30039,-3.79025
19.90000,-3.31706,-3.80294
20.00000,-3.33386,-3.81370
20.10000,-3.35013,-3.82624
20.20000,-3.36693,-3.83513
20.30000,-3.38346,-3.84759
20.40000,-3.40053,-3.85942
20.50000,-3.41692,-3.86875
20.60000,-3.43372,-3.87981
20.70000,-3.45039,-3.89083
20.80000,-3.46692,-3.90137
20.90000,-3.48372,-3.91080
21.00000,-3.50012,-3.92006
21.10000,-3.51679,-3.92959
21.20000,-3.53346,-3.94213
21.30000,-3.55039,-3.95408
21.40000,-3.56692,-3.96526
21.50000,-3.58372,-3.97806
21.60000,-3.60026,-3.98869
21.70000,-3.61666,-4.00033
21.80000,-3.63372,-4.01260
21.90000,-3.64999,-4.02304
22.00000,-3.66692,-4.03561
22.10000,-3.68359,-4.04631
22.20000,-3.70039,-4.05681
22.30000,-3.71706,-4.06833
22.40000,-3.73372,-4.07856
22.50000,-3.75039,-4.09025
22.60000,-3.76679,-4.09960
22.70000,-3.78372,-4.11042
22.80000,-3.80012,-4.11963
22.90000,-3.81706,-4.12948
23.00000,-3.83372,-4.13995
23.10000,-3.85026,-4.15012
23.20000,-3.86719,-4.15897
23.30000,-3.88359,-4.16931
23.40000,-3.90039,-4.17713
23.50000,-3.91679,-4.18672
23.60000,-3.93372,-4.19562
23.70000,-3.95026,-4.20355
23.80000,-3.96706,-4.21398
23.90000,-3.98372,-4.22168
24.00000,-4.00026,-4.23128
24.10000,-4.01692,-4.23944
24.20000,-4.03332,-4.24759
24.30000,-4.05026,-4.25652
24.40000,-4.06692,-4.26643
24.50000,-4.08372,-4.27285
24.60000,-4.10026,-4.28256
24.70000,-4.11706,-4.29192
24.80000,-4.13359,-4.29946
24.90000,-4.15012,-4.31013
25.00000,-4.16692,-4.31858
25.10000,-4.18332,-4.32729
25.20000,-4.20026,-4.33795
25.30000,-4.21692,-4.34557
25.40000,-4.23372,-4.35360
25.50000,-4.25039,-4.36141
25.60000,-4.26706,-4.36667
25.70000,-4.28359,-4.37749
25.80000,-4.30012,-4.38652
25.90000,-4.31719,-4.39538
26.00000,-4.33346,-4.40528
26.10000,-4.35039,-4.41440
26.20000,-4.36719,-4.42080
26.30000,-4.38372,-4.42735
26.40000,-4.40039,-4.43442
26.50000,-4.41706,-4.44423
26.60000,-4.43372,-4.45221
26.70000,-4.45012,-4.45984
26.80000,-4.46692,-4.46744
26.90000,-4.48359,-4.47492
27.00000,-4.50039,-4.48243
27.10000,-4.51692,-4.49286
27.20000,-4.53359,-4.50109
27.30000,-4.55026,-4.50996
27.40000,-4.56679,-4.51908
27.50000,-4.58346,-4.52487
27.60000,-4.60012,-4.53319
27.70000,-4.61706,-4.53837
27.80000,-4.63346,-4.54642
27.90000,-4.65039,-4.55666
28.00000,-4.66706,-4.56375
28.10000,-4.68332,-4.56662
28.20000,-4.70026,-4.57087
28.30000,-4.71666,-4.57615
28.40000,-4.73359,-4.58587
28.50000,-4.75039,-4.59335
28.60000,-4.76706,-4.60173
28.70000,-4.78372,-4.60885
28.80000,-4.80052,-4.62519
28.90000,-4.81706,-4.62870
29.00000,-4.83332,-4.63268
29.10000,-4.85039,-4.64156
29.20000,-4.86679,-4.64471
29.30000,-4.88372,-4.65199
29.40000,-4.90052,-4.65423
29.50000,-4.91705,-4.66068
29.60000,-4.93372,-4.66513
29.70000,-4.95025,-4.66520
29.80000,-4.96692,-4.67101
29.90000,-4.98332,-4.67442
30.00000,-5.00025,-4.67913
30.10000,-5.01679,-4.68997
30.20000,-5.03372,-4.69584
30.30000,-5.05025,-4.69752
30.40000,-5.06692,-4.70782
30.50000,-5.08372,-4.70915
30.60000,-5.10025,-4.71284
30.70000,-5.11679,-4.72817
30.80000,-5.13345,-4.72719
30.90000,-5.15039,-4.73069
31.00000,-5.16692,-4.73858
31.10000,-5.18372,-4.73832
31.20000,-5.20039,-4.74400
31.30000,-5.21679,-4.74676
31.40000,-5.23372,-4.75467
31.50000,-5.24999,-4.76638
31.60000,-5.26692,-4.76966
31.70000,-5.28372,-4.77563
31.80000,-5.30039,-4.78431
31.90000,-5.31705,-4.79334
32.00000,-5.33372,-4.79711
32.10000,-5.35025,-4.80028
32.20000,-5.36679,-4.80753
32.30000,-5.38372,-4.80920
32.40000,-5.40025,-4.81053
32.50000,-5.41705,-4.81769
32.60000,-5.43385,-4.82212
32.70000,-5.45039,-4.82669
32.80000,-5.46705,-4.82960
32.90000,-5.48359,-4.83523
33.00000,-5.50025,-4.83801
33.10000,-5.51665,-4.83998
33.20000,-5.53372,-4.84280
33.30000,-5.55025,-4.84605
33.40000,-5.56705,-4.85277
33.50000,-5.58372,-4.85480
33.60000,-5.60025,-4.86171
33.70000,-5.61705,-4.86301
33.80000,-5.63345,-4.86784
33.90000,-5.65012,-4.87041
34.00000,-5.66679,-4.87752
34.10000,-5.68372,-4.88375
34.20000,-5.70025,-4.88833
34.30000,-5.71705,-4.89300
34.40000,-5.73372,-4.89873
34.50000,-5.75012,-4.90525
34.60000,-5.76705,-4.90943
34.70000,-5.78332,-4.90944
34.80000,-5.79999,-4.91774
34.90000,-5.81692,-4.92842
35.00000,-5.83372,-4.93218
35.10000,-5.85039,-4.93894
35.20000,-5.86705,-4.94485
35.30000,-5.88359,-4.94867
35.40000,-5.90012,-4.95150
35.50000,-5.91705,-4.95870
35.60000,-5.93359,-4.96500
35.70000,-5.95025,-4.96977
35.80000,-5.96705,-4.97304
35.90000,-5.98359,-4.98123
36.00000,-6.00039,-4.98476
36.10000,-6.01679,-4.98986
36.20000,-6.03372,-4.99686
36.30000,-6.05025,-5.00109
36.40000,-6.06705,-5.00697
36.50000,-6.08359,-5.01186
36.60000,-6.10038,-5.02033
36.70000,-6.11705,-5.02557
36.80000,-6.13359,-5.03257
36.90000,-6.15038,-5.03261
37.00000,-6.16679,-5.03732
37.10000,-6.18345,-5.04468
37.20000,-6.20012,-5.04937
37.30000,-6.21705,-5.05496
37.40000,-6.23358,-5.06095
37.50000,-6.25038,-5.06787
37.60000,-6.26705,-5.07276
37.70000,-6.28345,-5.07859
37.80000,-6.30052,-5.08465
37.90000,-6.31665,-5.09239
38.00000,-6.33358,-5.09840
38.10000,-6.35025,-5.10593
38.20000,-6.36705,-5.11214
38.30000,-6.38372,-5.11867
38.40000,-6.40038,-5.12401
38.50000,-6.41705,-5.13016
38.60000,-6.43345,-5.13674
38.70000,-6.45038,-5.14257
38.80000,-6.46692,-5.14838
38.90000,-6.48358,-5.15576
39.00000,-6.50038,-5.16142
39.10000,-6.51705,-5.16726
39.20000,-6.53385,-5.17385
39.30000,-6.55025,-5.17984
39.40000,-6.56705,-5.18666
39.50000,-6.58345,-5.19320
39.60000,-6.60025,-5.19935
39.70000,-6.61692,-5.20532
39.80000,-6.63372,-5.21252
39.90000,-6.65052,-5.21811
40.00000,-6.66692,-5.22428
40.10000,-6.68358,-5.23042
40.20000,-6.69998,-5.23677
40.30000,-6.71678,-5.24348
40.40000,-6.73345,-5.24954
40.50000,-6.75025,-5.25327
40.60000,-6.76692,-5.26145
40.70000,-6.78372,-5.26920
40.80000,-6.80038,-5.27615
40.90000,-6.81678,-5.28303
41.00000,-6.83372,-5.28950
41.10000,-6.84998,-5.29514
41.20000,-6.86692,-5.30298
41.30000,-6.88372,-5.31533
41.40000,-6.90038,-5.32321
41.50000,-6.91705,-5.32688
41.60000,-6.93372,-5.33547
41.70000,-6.95038,-5.34040
41.80000,-6.96678,-5.34791
41.90000,-6.98358,-5.35408
42.00000,-7.00012,-5.36042
42.10000,-7.01705,-5.36771
42.20000,-7.03372,-5.37072
42.30000,-7.05025,-5.37933
42.40000,-7.06718,-5.38646
42.50000,-7.08372,-5.39264
42.60000,-7.10038,-5.39887
42.70000,-7.11678,-5.40582
42.80000,-7.13372,-5.41251
42.90000,-7.15025,-5.41632
43.00000,-7.16705,-5.42472
43.10000,-7.18372,-5.43034
43.20000,-7.20025,-5.43611
43.30000,-7.21705,-5.44374
43.40000,-7.23332,-5.44406
43.50000,-7.25012,-5.45039
43.60000,-7.26678,-5.45862
43.70000,-7.28358,-5.46442
43.80000,-7.30025,-5.47259
43.90000,-7.31705,-5.47815
44.00000,-7.33358,-5.48393
44.10000,-7.34998,-5.49040
44.20000,-7.36705,-5.49516
44.30000,-7.38332,-5.50153
44.40000,-7.40025,-5.50728
44.50000,-7.41705,-5.51259
44.60000,-7.43372,-5.51849
44.70000,-7.45038,-5.52415
44.80000,-7.46705,-5.52841
44.90000,-7.48358,-5.53237
45.00000,-7.50011,-5.53927
45.10000,-7.51705,-5.54394
45.20000,-7.53345,-5.54911
45.30000,-7.55025,-5.55556
45.40000,-7.56705,-5.56168
45.50000,-7.58372,-5.56681
45.60000,-7.60051,-5.57201
45.70000,-7.61705,-5.57786
45.80000,-7.63371,-5.58297
45.90000,-7.65011,-5.58670
46.00000,-7.66691,-5.59201
46.10000,-7.68358,-5.59552
46.20000,-7.70051,-5.60378
46.30000,-7.71705,-5.60793
46.40000,-7.73358,-5.61298
46.50000,-7.75038,-5.61789
46.60000,-7.76691,-5.62106
46.70000,-7.78358,-5.62442
46.80000,-7.80025,-5.63235
46.90000,-7.81705,-5.63901
47.00000,-7.83358,-5.64382
47.10000,-7.85038,-5.64968
47.20000,-7.86705,-5.65384
47.30000,-7.88358,-5.65722
47.40000,-7.90038,-5.66500
47.50000,-7.91665,-5.67031
47.60000,-7.93358,-5.67441
47.70000,-7.95025,-5.67918
47.80000,-7.96678,-5.68296
47.90000,-7.98345,-5.68722
48.00000,-8.00011,-5.69360
48.10000,-8.01691,-5.69804
48.20000,-8.03331,-5.70328
48.30000,-8.05025,-5.71016
48.40000,-8.06691,-5.71188
48.50000,-8.08371,-5.71852
48.60000,-8.10038,-5.72162
48.70000,-8.11691,-5.72634
48.80000,-8.13385,-5.73178
48.90000,-8.15025,-5.73451
49.00000,-8.16718,-5.73784
49.10000,-8.18358,-5.73977
49.20000,-8.20038,-5.73988
49.30000,-8.21691,-5.74741
49.40000,-8.23371,-5.75121
49.50000,-8.25038,-5.75427
49.60000,-8.26691,-5.75713
49.70000,-8.28371,-5.75894
49.80000,-8.30011,-5.76124
49.90000,-8.31678,-5.76518
50.00000,-8.33358,-5.76976
50.10000,-8.35038,-5.77195
50.20000,-8.36691,-5.77291
50.30000,-8.38371,-5.77641
50.40000,-8.40038,-5.77916
50.50000,-8.41678,-5.78321
50.60000,-8.43371,-5.78624
50.70000,-8.45011,-5.78996
50.80000,-8.46691,-5.79302
50.90000,-8.48371,-5.79351
51.00000,-8.50038,-5.80045
51.10000,-8.51691,-5.80400
51.20000,-8.53371,-5.80840
51.30000,-8.55038,-5.80990
51.40000,-8.56678,-5.81481
51.50000,-8.58371,-5.81630
51.60000,-8.60011,-5.82213
51.70000,-8.61705,-5.82723
51.80000,-8.63371,-5.83170
51.90000,-8.65025,-5.83672
52.00000,-8.66705,-5.84002
52.10000,-8.68371,-5.84584
52.20000,-8.70038,-5.85002
52.30000,-8.71678,-5.84818
52.40000,-8.73371,-5.85695
52.50000,-8.75025,-5.86025
52.60000,-8.76705,-5.86560
52.70000,-8.78371,-5.86939
52.80000,-8.80024,-5.87116
52.90000,-8.81705,-5.87437
53.00000,-8.83345,-5.87873
53.10000,-8.85011,-5.88259
53.20000,-8.86691,-5.88662
53.30000,-8.88371,-5.89087
53.40000,-8.90024,-5.89798
53.50000,-8.91704,-5.90206
53.60000,-8.93371,-5.90645
53.70000,-8.95011,-5.90773
53.80000,-8.96691,-5.90902
53.90000,-8.98331,-5.91640
54.00000,-9.00024,-5.92282
54.10000,-9.01704,-5.92937
54.20000,-9.03371,-5.93365
54.30000,-9.05024,-5.93632
54.40000,-9.06704,-5.94253
54.50000,-9.08371,-5.94684
54.60000,-9.10011,-5.95426
54.70000,-9.11704,-5.95987
54.80000,-9.13358,-5.96241
54.90000,-9.15038,-5.96706
55.00000,-9.16718,-5.96925
55.10000,-9.18358,-5.97507
55.20000,-9.20051,-5.97959
55.30000,-9.21704,-5.98308
55.40000,-9.23371,-5.98790
55.50000,-9.25011,-5.99122
55.60000,-9.26704,-5.99416
55.70000,-9.28344,-5.99897
55.80000,-9.30038,-6.00578
55.90000,-9.31691,-6.00860
56.00000,-9.33344,-6.01349
56.10000,-9.35011,-6.01830
56.20000,-9.36678,-6.02836
56.30000,-9.38344,-6.03022
56.40000,-9.40011,-6.03562
56.50000,-9.41704,-6.03988
56.60000,-9.43358,-6.04430
56.70000,-9.45051,-6.05188
56.80000,-9.46704,-6.05300
56.90000,-9.48358,-6.05922
57.00000,-9.50051,-6.05993
57.10000,-9.51678,-6.06294
57.20000,-9.53371,-6.06469
57.30000,-9.55038,-6.07084
57.40000,-9.56704,-6.07905
57.50000,-9.58371,-6.07965
57.60000,-9.60051,-6.08617
57.70000,-9.61704,-6.08790
57.80000,-9.63344,-6.09228
57.90000,-9.65038,-6.09997
58.00000,-9.66678,-6.10422
58.10000,-9.68371,-6.10871
58.20000,-9.70038,-6.11153
58.30000,-9.71704,-6.11111
58.40000,-9.73371,-6.12343
58.50000,-9.75038,-6.12671
58.60000,-9.76704,-6.13095
58.70000,-9.78344,-6.13578
58.80000,-9.80038,-6.13953
58.90000,-9.81691,-6.14522
59.00000,-9.83371,-6.15138
59.10000,-9.85024,-6.15856
59.20000,-9.86691,-6.15979
59.30000,-9.88371,-6.16195
59.40000,-9.90011,-6.16859
59.50000,-9.91678,-6.17417
59.60000,-9.93358,-6.18079
59.70000,-9.95038,-6.18182
59.80000,-9.96678,-6.18805
59.90000,-9.98371,-6.19548
60.00000,-10.00024,-6.19700
60.10000,-10.01664,-6.20463
60.20000,-10.03384,-6.20896
60.30000,-10.05011,-6.21421
60.40000,-10.06691,-6.22426
60.50000,-10.08371,-6.22713
60.60000,-10.10051,-6.23442
60.70000,-10.11704,-6.23499
60.80000,-10.13371,-6.23862
60.90000,-10.15038,-6.24143
61.00000,-10.16678,-6.24434
61.10000,-10.18371,-6.24795
61.20000,-10.20011,-6.24786
61.30000,-10.21704,-6.25424
61.40000,-10.23371,-6.25739
61.50000,-10.25024,-6.26125
61.60000,-10.26717,-6.26607
61.70000,-10.28358,-6.26597
61.80000,-10.30024,-6.26959
61.90000,-10.31678,-6.27686
62.00000,-10.33371,-6.28179
62.10000,-10.35011,-6.28553
62.20000,-10.36691,-6.28978
62.30000,-10.38371,-6.29129
62.40000,-10.40024,-6.29804
62.50000,-10.41717,-6.30457
62.60000,-10.43357,-6.30929
62.70000,-10.45024,-6.31477
62.80000,-10.46691,-6.31997
62.90000,-10.48371,-6.32730
63.00000,-10.50024,-6.33174
63.10000,-10.51704,-6.33620
63.20000,-10.53371,-6.33914
63.30000,-10.54997,-6.34451
63.40000,-10.56691,-6.34928
63.50000,-10.58317,-6.35250
63.60000,-10.60024,-6.35772
63.70000,-10.61691,-6.36091
63.80000,-10.63357,-6.36595
63.90000,-10.65011,-6.37135
64.00000,-10.66704,-6.37714
64.10001,-10.68371,-6.38035
64.20000,-10.70011,-6.38634
64.30000,-10.71691,-6.39024
64.40000,-10.73344,-6.39519
64.50000,-10.75051,-6.40285
64.60001,-10.76717,-6.40636
64.70000,-10.78371,-6.41143
64.80000,-10.80051,-6.41634
64.90000,-10.81704,-6.42146
65.00000,-10.83371,-6.42634
65.10001,-10.85011,-6.43205
65.20000,-10.86691,-6.43546
65.30000,-10.88357,-6.44238
65.40000,-10.90051,-6.44982
65.50000,-10.91717,-6.45369
65.60001,-10.93357,-6.45995
65.70001,-10.95037,-6.46455
65.80000,-10.96677,-6.46967
65.90000,-10.98344,-6.47475
66.00000,-11.00024,-6.48313
66.10001,-11.01704,-6.48813
66.20001,-11.03357,-6.49414
66.30000,-11.05051,-6.50184
66.40000,-11.06704,-6.50683
66.50000,-11.08344,-6.51131
66.60001,-11.10024,-6.51649
66.70001,-11.11677,-6.52118
66.80000,-11.13357,-6.52758
66.90000,-11.15037,-6.53359
67.00000,-11.16704,-6.53902
67.10001,-11.18371,-6.54460
67.20001,-11.20037,-6.54957
67.30000,-11.21704,-6.55337
67.40000,-11.23344,-6.55849
67.50000,-11.25024,-6.56271
67.60001,-11.26677,-6.56688
67.70001,-11.28371,-6.57456
67.80000,-11.30037,-6.57920
67.90000,-11.31691,-6.58139
68.00000,-11.33384,-6.58633
68.10001,-11.35037,-6.58904
68.20001,-11.36731,-6.59376
68.30000,-11.38344,-6.59471
68.40000,-11.40037,-6.59857
68.50000,-11.41691,-6.60330
68.60001,-11.43371,-6.60803
68.70001,-11.45037,-6.61075
68.80000,-11.46691,-6.61402
68.90000,-11.48371,-6.61657
69.00000,-11.49997,-6.61894
69.10001,-11.51691,-6.62338
69.20001,-11.53357,-6.62895
69.30000,-11.55037,-6.63328
69.40000,-11.56677,-6.63630
69.50000,-11.58371,-6.64135
69.60001,-11.60037,-6.64440
69.70001,-11.61677,-6.64572
69.80000,-11.63371,-6.64882
69.90000,-11.64997,-6.65101
70.00000,-11.66691,-6.65513
70.10001,-11.68371,-6.65843
70.20001,-11.70037,-6.65986
70.30000,-11.71691,-6.66104
70.40000,-11.73384,-6.66441
70.50000,-11.75024,-6.66428
70.60001,-11.76664,-6.66821
70.70001,-11.78371,-6.67168
70.80000,-11.80024,-6.67277
70.90000,-11.81704,-6.67651
71.00000,-11.83384,-6.67854
71.10001,-11.85037,-6.68045
71.20001,-11.86717,-6.68549
71.30000,-11.88370,-6.68759
71.40000,-11.90037,-6.68839
71.50000,-11.91677,-6.69054
71.60001,-11.93370,-6.69195
71.70001,-11.95024,-6.69373
71.80000,-11.96704,-6.69647
71.90000,-11.98357,-6.69587
72.00000,-12.00024,-6.69904
72.10001,-12.01704,-6.70105
72.20001,-12.03357,-6.70229
72.30000,-12.05010,-6.70261
72.40000,-12.06677,-6.70306
72.50000,-12.08370,-6.70378
72.60001,-12.10024,-6.70427
72.70001,-12.11704,-6.70681
72.80000,-12.13370,-6.70615
72.90000,-12.15010,-6.70932
73.00000,-12.16704,-6.71135
73.10001,-12.18330,-6.71297
73.20001,-12.20024,-6.71590
73.30000,-12.21704,-6.71664
73.40000,-12.23357,-6.71745
73.50000,-12.25024,-6.71972
73.60001,-12.26704,-6.72218
73.70001,-12.28384,-6.72367
73.80000,-12.30010,-6.72553
73.90000,-12.31690,-6.72580
74.00000,-12.33357,-6.72547
74.10001,-12.35037,-6.72800
74.20001,-12.36717,-6.72673
74.30000,-12.38357,-6.72644
74.40000,-12.40037,-6.72766
74.50000,-12.41704,-6.72934
74.60001,-12.43370,-6.73152
74.70001,-12.45010,-6.73465
74.80000,-12.46704,-6.73723
74.90000,-12.48357,-6.73742
75.00000,-12.50037,-6.74073
75.10001,-12.51717,-6.74159
75.20001,-12.53357,-6.74477
75.30000,-12.55050,-6.74808
75.40000,-12.56677,-6.74977
75.50000,-12.58344,-6.75137
75.60001,-12.60010,-6.75304
75.70001,-12.61690,-6.75568
75.80000,-12.63344,-6.75668
75.90000,-12.65024,-6.76045
76.00000,-12.66704,-6.76387
76.10001,-12.68344,-6.76841
76.20001,-12.70037,-6.77200
76.30000,-12.71677,-6.77463
76.40000,-12.73357,-6.77916
76.50000,-12.75024,-6.78281
76.60001,-12.76704,-6.78673
76.70001,-12.78370,-6.79023
76.80000,-12.80037,-6.79310
76.90000,-12.81704,-6.79587
77.00000,-12.83344,-6.79923
77.10001,-12.85037,-6.80300
77.20001,-12.86690,-6.80518
77.30000,-12.88357,-6.80925
77.40000,-12.90037,-6.81117
77.50000,-12.91690,-6.81294
77.60001,-12.93384,-6.81636
77.70001,-12.95037,-6.81916
77.80000,-12.96690,-6.82106
77.90000,-12.98343,-6.82531
78.00000,-13.00050,-6.82777
78.10001,-13.01690,-6.82888
78.20001,-13.03370,-6.83176
78.30000,-13.05037,-6.83269
78.40000,-13.06690,-6.83553
78.50000,-13.08370,-6.83770
78.60001,-13.10023,-6.84141
78.70001,-13.11690,-6.84446
78.80000,-13.13343,-6.84667
78.90000,-13.15023,-6.84974
79.00000,-13.16677,-6.85143
79.10001,-13.18370,-6.85816
79.20001,-13.20037,-6.85969
79.30000,-13.21677,-6.86347
79.40000,-13.23370,-6.86689
79.50000,-13.24997,-6.86847
79.60001,-13.26690,-6.87495
79.70001,-13.28370,-6.87802
79.80000,-13.30023,-6.88115
79.90000,-13.31703,-6.88371
80.00000,-13.33383,-6.88852
80.10001,-13.35050,-6.89041
80.20001,-13.36690,-6.89345
80.30000,-13.38370,-6.89566
80.40000,-13.40010,-6.89577
80.50001,-13.41703,-6.90105
80.60001,-13.43383,-6.90249
80.70001,-13.45037,-6.90574
80.80000,-13.46703,-6.90913
80.90000,-13.48370,-6.91168
81.00001,-13.50050,-6.91456
81.10001,-13.51690,-6.91703
81.20001,-13.53370,-6.91919
81.30000,-13.55023,-6.92190
81.40000,-13.56703,-6.92460
81.50001,-13.58370,-6.92530
81.60001,-13.60023,-6.92711
81.70001,-13.61690,-6.92794
81.80000,-13.63343,-6.92937
81.90000,-13.64997,-6.93010
82.00001,-13.66677,-6.93257
82.10001,-13.68370,-6.93638
82.20001,-13.70010,-6.93618
82.30000,-13.71703,-6.93868
82.40000,-13.73370,-6.93842
82.50001,-13.75010,-6.93822
82.60001,-13.76703,-6.93909
82.70001,-13.78330,-6.93932
82.80000,-13.80023,-6.94138
82.90000,-13.81703,-6.94263
83.00001,-13.83370,-6.94448
83.10001,-13.85037,-6.94633
83.20001,-13.86717,-6.94802
83.30000,-13.88370,-6.94732
83.40000,-13.90023,-6.94992
83.50001,-13.91690,-6.95199
83.60001,-13.93357,-6.95163
83.70001,-13.95023,-6.95573
83.80000,-13.96690,-6.95622
83.90000,-13.98357,-6.95793
84.00001,-14.00050,-6.96151
84.10001,-14.01703,-6.96092
84.20001,-14.03370,-6.96209
84.30000,-14.05010,-6.96428
84.40000,-14.06703,-6.96584
84.50001,-14.08357,-6.96855
84.60001,-14.10037,-6.97240
84.70001,-14.11703,-6.97454
84.80000,-14.13357,-6.97917
84.90000,-14.15037,-6.98285
85.00001,-14.16663,-6.98695
85.10001,-14.18357,-6.99176
85.20001,-14.20010,-6.99737
85.30000,-14.21703,-7.00314
85.40000,-14.23356,-7.00719
85.50001,-14.25037,-7.01508
85.60001,-14.26703,-7.01910
85.70001,-14.28343,-7.02690
85.80000,-14.30037,-7.03373
85.90000,-14.31676,-7.03957
86.00001,-14.33356,-7.04970
86.10001,-14.35023,-7.05767
86.20001,-14.36703,-7.06574
86.30000,-14.38370,-7.07426
86.40000,-14.40036,-7.08215
86.50001,-14.41703,-7.08860
86.60001,-14.43343,-7.09729
86.70001,-14.45036,-7.10482
86.80000,-14.46676,-7.11140
86.90000,-14.48356,-7.12284
87.00001,-14.50050,-7.13025
87.10001,-14.51703,-7.13861
87.20001,-14.53383,-7.14572
87.30000,-14.55036,-7.15200
87.40000,-14.56703,-7.15816
87.50001,-14.58343,-7.16615
87.60001,-14.60036,-7.17423
87.70001,-14.61690,-7.18107
87.80000,-14.63370,-7.19014
87.90000,-14.65036,-7.19833
88.00001,-14.66690,-7.20903
88.10001,-14.68370,-7.21671
88.20001,-14.69996,-7.22380
88.30000,-14.71676,-7.23118
88.40000,-14.73356,-7.23978
88.50001,-14.75036,-7.24861
88.60001,-14.76690,-7.25622
88.70001,-14.78370,-7.26605
88.80000,-14.80023,-7.27149
88.90000,-14.81676,-7.28042
89.00001,-14.83383,-7.28934
89.10001,-14.85023,-7.29678
89.20001,-14.86690,-7.30638
89.30000,-14.88356,-7.31453
89.40000,-14.90023,-7.32291
89.50001,-14.91690,-7.33294
89.60001,-14.93370,-7.34293
89.70001,-14.95036,-7.35020
89.80000,-14.96676,-7.36066
89.90000,-14.98356,-7.37052
90.00001,-15.00023,-7.38086
90.10001,-15.01703,-7.39317
90.10800,-15.01836,-7.39397