File: GFBaking/data/2_8PercentGluten/2_8gluten_Compression_Continued.is_comp_RawData/Specimen_RawData_5.csv
Time,Extension,Load
(sec),(mm),(N)
0.00000,0.00000,-0.61797
0.10000,-0.00560,-0.62538
0.20000,-0.02520,-0.66931
0.30000,-0.04560,-0.71830
0.40000,-0.06440,-0.75986
0.50000,-0.08200,-0.79687
0.60000,-0.09947,-0.83372
0.70000,-0.11627,-0.86718
0.80000,-0.13320,-0.89802
0.90000,-0.15000,-0.93266
1.00000,-0.16653,-0.96402
1.10000,-0.18333,-0.99582
1.20000,-0.20000,-1.02805
1.30000,-0.21680,-1.05884
1.40000,-0.23333,-1.08693
1.50000,-0.25027,-1.11927
1.60000,-0.26680,-1.15027
1.70000,-0.28347,-1.18118
1.80000,-0.30013,-1.22762
1.90000,-0.31653,-1.23726
2.00000,-0.33360,-1.26250
2.10000,-0.35000,-1.30926
2.20000,-0.36693,-1.33594
2.30000,-0.38360,-1.37303
2.40000,-0.40027,-1.39649
2.50000,-0.41680,-1.41067
2.60000,-0.43347,-1.43226
2.70000,-0.45013,-1.46466
2.80000,-0.46653,-1.49744
2.90000,-0.48360,-1.52494
3.00000,-0.50013,-1.54733
3.10000,-0.51680,-1.57080
3.20000,-0.53360,-1.59636
3.30000,-0.55013,-1.61971
3.40000,-0.56667,-1.64848
3.50000,-0.58320,-1.67728
3.60000,-0.60000,-1.70284
3.70000,-0.61667,-1.72921
3.80000,-0.63360,-1.75220
3.90000,-0.65013,-1.77736
4.00000,-0.66693,-1.80291
4.10000,-0.68346,-1.82730
4.20000,-0.69986,-1.85497
4.30000,-0.71666,-1.87591
4.40000,-0.73333,-1.90341
4.50000,-0.75026,-1.92649
4.60000,-0.76680,-1.95641
4.70000,-0.78360,-1.98125
4.80000,-0.80000,-2.00294
4.90000,-0.81680,-2.02696
5.00000,-0.83346,-2.04971
5.10000,-0.84986,-2.07273
5.20000,-0.86680,-2.09153
5.30000,-0.88333,-2.09465
5.40000,-0.90026,-2.09464
5.50000,-0.91693,-2.09686
5.60000,-0.93360,-2.09243
5.70000,-0.95013,-2.09264
5.80000,-0.96680,-2.09481
5.90000,-0.98346,-2.09334
6.00000,-1.00000,-2.09878
6.10000,-1.01693,-2.10263
6.20000,-1.03346,-2.09924
6.30000,-1.05013,-2.11806
6.40000,-1.06706,-2.14353
6.50000,-1.08346,-2.16968
6.60000,-1.10013,-2.19643
6.70000,-1.11666,-2.21611
6.80000,-1.13346,-2.24151
6.90000,-1.14986,-2.26973
7.00000,-1.16693,-2.29293
7.10000,-1.18333,-2.31564
7.20000,-1.20000,-2.34149
7.30000,-1.21666,-2.36386
7.40000,-1.23320,-2.38877
7.50000,-1.25013,-2.41456
7.60000,-1.26653,-2.43735
7.70000,-1.28346,-2.46129
7.80000,-1.30000,-2.48427
7.90000,-1.31693,-2.50476
8.00000,-1.33346,-2.52826
8.10000,-1.35000,-2.55181
8.20000,-1.36666,-2.57561
8.30000,-1.38333,-2.60043
8.40000,-1.40040,-2.62360
8.50000,-1.41680,-2.64576
8.60000,-1.43360,-2.66900
8.70000,-1.45026,-2.69242
8.80000,-1.46693,-2.71608
8.90000,-1.48346,-2.73936
9.00000,-1.50013,-2.76532
9.10000,-1.51680,-2.79041
9.20000,-1.53320,-2.81113
9.30000,-1.55013,-2.83298
9.40000,-1.56666,-2.85488
9.50000,-1.58346,-2.87565
9.60000,-1.60026,-2.90102
9.70000,-1.61666,-2.92345
9.80000,-1.63333,-2.94323
9.90000,-1.64986,-2.96185
10.00000,-1.66680,-2.98227
10.10000,-1.68320,-3.00798
10.20000,-1.70026,-3.03049
10.30000,-1.71666,-3.05388
10.40000,-1.73346,-3.07523
10.50000,-1.75000,-3.09399
10.60000,-1.76666,-3.11336
10.70000,-1.78333,-3.13164
10.80000,-1.79986,-3.14567
10.90000,-1.81680,-3.16498
11.00000,-1.83346,-3.18635
11.10000,-1.85026,-3.20715
11.20000,-1.86680,-3.22652
11.30000,-1.88333,-3.24685
11.40000,-1.90013,-3.25975
11.50000,-1.91653,-3.27904
11.60000,-1.93346,-3.30315
11.70000,-1.95013,-3.32663
11.80000,-1.96693,-3.34969
11.90000,-1.98360,-3.36825
12.00000,-2.00026,-3.38244
12.10000,-2.01666,-3.40058
12.20000,-2.03319,-3.42333
12.30000,-2.05013,-3.44562
12.40000,-2.06666,-3.46735
12.50000,-2.08359,-3.48713
12.60000,-2.10013,-3.50483
12.70000,-2.11679,-3.52451
12.80000,-2.13359,-3.54370
12.90000,-2.15013,-3.56597
13.00000,-2.16666,-3.58709
13.10000,-2.18346,-3.60903
13.20000,-2.20013,-3.63145
13.30000,-2.21666,-3.65135
13.40000,-2.23359,-3.67006
13.50000,-2.25013,-3.68824
13.60000,-2.26679,-3.70787
13.70000,-2.28333,-3.72722
13.80000,-2.29986,-3.74938
13.90000,-2.31666,-3.76559
14.00000,-2.33319,-3.78287
14.10000,-2.35013,-3.80010
14.20000,-2.36666,-3.81980
14.30000,-2.38359,-3.83877
14.40000,-2.40013,-3.85621
14.50000,-2.41679,-3.87408
14.60000,-2.43346,-3.89087
14.70000,-2.44999,-3.90718
14.80000,-2.46679,-3.92469
14.90000,-2.48346,-3.94417
15.00000,-2.50026,-3.96468
15.10000,-2.51679,-3.98167
15.20000,-2.53359,-3.99968
15.30000,-2.54999,-4.01599
15.40000,-2.56679,-4.03400
15.50000,-2.58346,-4.05249
15.60000,-2.59986,-4.06852
15.70000,-2.61706,-4.08693
15.80000,-2.63346,-4.10372
15.90000,-2.65026,-4.12090
16.00000,-2.66693,-4.13848
16.10000,-2.68333,-4.15422
16.20000,-2.69986,-4.17138
16.30000,-2.71666,-4.18952
16.40000,-2.73346,-4.20616
16.50000,-2.74986,-4.22405
16.60000,-2.76693,-4.24146
16.70000,-2.78333,-4.25571
16.80000,-2.80013,-4.27315
16.90000,-2.81666,-4.28848
17.00000,-2.83319,-4.30501
17.10000,-2.84986,-4.32213
17.20000,-2.86653,-4.33906
17.30000,-2.88346,-4.35790
17.40000,-2.89999,-4.37463
17.50000,-2.91693,-4.38708
17.60000,-2.93333,-4.40272
17.70000,-2.95013,-4.41972
17.80000,-2.96666,-4.43462
17.90000,-2.98333,-4.45226
18.00000,-3.00026,-4.46865
18.10000,-3.01666,-4.48382
18.20000,-3.03359,-4.49983
18.30000,-3.05013,-4.51650
18.40000,-3.06693,-4.53108
18.50000,-3.08346,-4.54719
18.60000,-3.10013,-4.56329
18.70000,-3.11679,-4.57864
18.80000,-3.13319,-4.59310
18.90000,-3.15026,-4.60949
19.00000,-3.16679,-4.62418
19.10000,-3.18346,-4.63887
19.20000,-3.20026,-4.65308
19.30000,-3.21679,-4.66804
19.40000,-3.23346,-4.68281
19.50000,-3.25013,-4.69791
19.60000,-3.26693,-4.71117
19.70000,-3.28333,-4.72659
19.80000,-3.30026,-4.74148
19.90000,-3.31666,-4.75607
20.00000,-3.33346,-4.77009
20.10000,-3.34986,-4.78262
20.20000,-3.36653,-4.79605
20.30000,-3.38333,-4.81039
20.40000,-3.39999,-4.82428
20.50000,-3.41679,-4.83709
20.60000,-3.43332,-4.85205
20.70000,-3.45026,-4.86634
20.80000,-3.46679,-4.88041
20.90000,-3.48346,-4.89347
21.00000,-3.50012,-4.90661
21.10000,-3.51652,-4.92077
21.20000,-3.53359,-4.93441
21.30000,-3.54999,-4.94857
21.40000,-3.56692,-4.96081
21.50000,-3.58346,-4.97444
21.60000,-3.60026,-4.98811
21.70000,-3.61666,-5.00251
21.80000,-3.63346,-5.01600
21.90000,-3.65026,-5.02958
22.00000,-3.66652,-5.04425
22.10000,-3.68359,-5.05768
22.20000,-3.70012,-5.07140
22.30000,-3.71692,-5.08627
22.40000,-3.73359,-5.10128
22.50000,-3.75012,-5.11142
22.60000,-3.76679,-5.12166
22.70000,-3.78332,-5.13486
22.80000,-3.79999,-5.14785
22.90000,-3.81652,-5.15999
23.00000,-3.83359,-5.17589
23.10000,-3.84999,-5.18960
23.20000,-3.86679,-5.20319
23.30000,-3.88332,-5.21229
23.40000,-3.89986,-5.22578
23.50000,-3.91666,-5.23652
23.60000,-3.93319,-5.24648
23.70000,-3.94999,-5.25763
23.80000,-3.96666,-5.27064
23.90000,-3.98359,-5.28232
24.00000,-3.99999,-5.29383
24.10000,-4.01666,-5.30333
24.20000,-4.03332,-5.31132
24.30000,-4.04986,-5.32529
24.40000,-4.06692,-5.33856
24.50000,-4.08346,-5.35089
24.60000,-4.10026,-5.36409
24.70000,-4.11679,-5.37910
24.80000,-4.13372,-5.39000
24.90000,-4.14999,-5.39917
25.00000,-4.16666,-5.41204
25.10000,-4.18346,-5.42258
25.20000,-4.19986,-5.43316
25.30000,-4.21692,-5.44332
25.40000,-4.23346,-5.45425
25.50000,-4.25026,-5.46457
25.60000,-4.26692,-5.47451
25.70000,-4.28346,-5.48752
25.80000,-4.29999,-5.50277
25.90000,-4.31666,-5.51272
26.00000,-4.33332,-5.52035
26.10000,-4.34972,-5.53212
26.20000,-4.36679,-5.54306
26.30000,-4.38332,-5.55358
26.40000,-4.40026,-5.56450
26.50000,-4.41692,-5.57352
26.60000,-4.43332,-5.58081
26.70000,-4.44999,-5.59021
26.80000,-4.46666,-5.59989
26.90000,-4.48346,-5.60910
27.00000,-4.50012,-5.62139
27.10000,-4.51679,-5.63088
27.20000,-4.53332,-5.63824
27.30000,-4.55026,-5.64815
27.40000,-4.56679,-5.65716
27.50000,-4.58319,-5.66580
27.60000,-4.60012,-5.67590
27.70000,-4.61666,-5.68619
27.80000,-4.63359,-5.69458
27.90000,-4.65026,-5.70392
28.00000,-4.66692,-5.71201
28.10000,-4.68332,-5.71974
28.20000,-4.70026,-5.72788
28.30000,-4.71679,-5.73565
28.40000,-4.73332,-5.74459
28.50000,-4.75026,-5.75421
28.60000,-4.76679,-5.76055
28.70000,-4.78359,-5.76994
28.80000,-4.80025,-5.77779
28.90000,-4.81679,-5.78500
29.00000,-4.83332,-5.79102
29.10000,-4.84999,-5.79722
29.20000,-4.86665,-5.80482
29.30000,-4.88319,-5.81458
29.40000,-4.90025,-5.82356
29.50000,-4.91665,-5.82893
29.60000,-4.93345,-5.83714
29.70000,-4.94999,-5.84497
29.80000,-4.96665,-5.85208
29.90000,-4.98332,-5.86037
30.00000,-4.99999,-5.86874
30.10000,-5.01679,-5.87665
30.20000,-5.03345,-5.88647
30.30000,-5.05025,-5.89407
30.40000,-5.06665,-5.90280
30.50000,-5.08345,-5.91127
30.60000,-5.10012,-5.91852
30.70000,-5.11652,-5.92656
30.80000,-5.13345,-5.93553
30.90000,-5.14985,-5.94414
31.00000,-5.16692,-5.95200
31.10000,-5.18359,-5.96021
31.20000,-5.20012,-5.96818
31.30000,-5.21665,-5.97513
31.40000,-5.23345,-5.98419
31.50000,-5.25012,-5.99208
31.60000,-5.26652,-5.99963
31.70000,-5.28359,-6.00885
31.80000,-5.30012,-6.01531
31.90000,-5.31692,-6.02373
32.00000,-5.33359,-6.03016
32.10000,-5.35012,-6.03684
32.20000,-5.36665,-6.04421
32.30000,-5.38345,-6.05230
32.40000,-5.40012,-6.05868
32.50000,-5.41665,-6.06728
32.60000,-5.43359,-6.07484
32.70000,-5.45012,-6.08212
32.80000,-5.46679,-6.09013
32.90000,-5.48332,-6.09716
33.00000,-5.49985,-6.10377
33.10000,-5.51665,-6.11041
33.20000,-5.53319,-6.11762
33.30000,-5.55012,-6.12611
33.40000,-5.56665,-6.13546
33.50000,-5.58359,-6.14171
33.60000,-5.59999,-6.14840
33.70000,-5.61679,-6.15523
33.80000,-5.63345,-6.16197
33.90000,-5.64985,-6.16756
34.00000,-5.66679,-6.17454
34.10000,-5.68332,-6.18065
34.20000,-5.70012,-6.18812
34.30000,-5.71679,-6.19495
34.40000,-5.73359,-6.20164
34.50000,-5.74999,-6.20834
34.60000,-5.76679,-6.21509
34.70000,-5.78359,-6.22192
34.80000,-5.79999,-6.22751
34.90000,-5.81692,-6.23604
35.00000,-5.83332,-6.24127
35.10000,-5.85012,-6.24907
35.20000,-5.86692,-6.25624
35.30000,-5.88332,-6.26182
35.40000,-5.89999,-6.26710
35.50000,-5.91665,-6.27411
35.60000,-5.93345,-6.27961
35.70000,-5.94999,-6.28590
35.80000,-5.96692,-6.29438
35.90000,-5.98332,-6.29825
36.00000,-5.99985,-6.30292
36.10000,-6.01652,-6.30720
36.20000,-6.03319,-6.31417
36.30000,-6.04999,-6.32181
36.40000,-6.06665,-6.32794
36.50000,-6.08345,-6.33549
36.60000,-6.09998,-6.34275
36.70000,-6.11692,-6.34890
36.80000,-6.13345,-6.35544
36.90000,-6.15012,-6.36324
37.00000,-6.16679,-6.36907
37.10000,-6.18332,-6.37700
37.20000,-6.20012,-6.38532
37.30000,-6.21665,-6.39205
37.40000,-6.23345,-6.39957
37.50000,-6.25025,-6.40661
37.60000,-6.26692,-6.41403
37.70000,-6.28345,-6.42078
37.80000,-6.30012,-6.42790
37.90000,-6.31678,-6.43475
38.00000,-6.33318,-6.44152
38.10000,-6.35025,-6.44976
38.20000,-6.36678,-6.45571
38.30000,-6.38345,-6.46352
38.40000,-6.40025,-6.47138
38.50000,-6.41678,-6.47799
38.60000,-6.43345,-6.48519
38.70000,-6.45012,-6.49181
38.80000,-6.46678,-6.49817
38.90000,-6.48332,-6.50483
39.00000,-6.50025,-6.51141
39.10000,-6.51678,-6.51735
39.20000,-6.53345,-6.52404
39.30000,-6.55012,-6.53020
39.40000,-6.56652,-6.53441
39.50000,-6.58332,-6.54079
39.60000,-6.59985,-6.54716
39.70000,-6.61678,-6.55375
39.80000,-6.63345,-6.56213
39.90000,-6.65038,-6.56762
40.00000,-6.66665,-6.57199
40.10000,-6.68332,-6.58013
40.20000,-6.70012,-6.58689
40.30000,-6.71665,-6.59442
40.40000,-6.73345,-6.60061
40.50000,-6.74998,-6.60901
40.60000,-6.76692,-6.61912
40.70000,-6.78358,-6.62596
40.80000,-6.80025,-6.63225
40.90000,-6.81665,-6.63851
41.00000,-6.83345,-6.64602
41.10000,-6.85025,-6.65188
41.20000,-6.86652,-6.65815
41.30000,-6.88372,-6.66543
41.40000,-6.90012,-6.67167
41.50000,-6.91678,-6.67958
41.60000,-6.93358,-6.68866
41.70000,-6.95012,-6.69685
41.80000,-6.96678,-6.70417
41.90000,-6.98345,-6.70806
42.00000,-7.00012,-6.71380
42.10000,-7.01678,-6.72079
42.20000,-7.03358,-6.72703
42.30000,-7.04998,-6.73388
42.40000,-7.06678,-6.74132
42.50000,-7.08332,-6.74589
42.60000,-7.09998,-6.75308
42.70000,-7.11665,-6.75942
42.80000,-7.13332,-6.76318
42.90000,-7.15012,-6.77142
43.00000,-7.16665,-6.78114
43.10000,-7.18372,-6.78686
43.20000,-7.19998,-6.79243
43.30000,-7.21678,-6.79959
43.40000,-7.23345,-6.80578
43.50000,-7.24985,-6.81126
43.60000,-7.26678,-6.81929
43.70000,-7.28332,-6.82762
43.80000,-7.30025,-6.83631
43.90000,-7.31665,-6.84217
44.00000,-7.33345,-6.84929
44.10000,-7.34985,-6.85554
44.20000,-7.36678,-6.86343
44.30000,-7.38345,-6.86645
44.40000,-7.39998,-6.87437
44.50000,-7.41705,-6.88353
44.60000,-7.43332,-6.88815
44.70000,-7.45025,-6.89553
44.80000,-7.46692,-6.90098
44.90000,-7.48332,-6.90675
45.00000,-7.50011,-6.91208
45.10000,-7.51678,-6.91753
45.20000,-7.53345,-6.92406
45.30000,-7.54998,-6.92958
45.40000,-7.56691,-6.93637
45.50000,-7.58332,-6.94185
45.60000,-7.60011,-6.95022
45.70000,-7.61665,-6.95506
45.80000,-7.63331,-6.96143
45.90000,-7.64998,-6.96790
46.00000,-7.66665,-6.97396
46.10000,-7.68345,-6.97969
46.20000,-7.69998,-6.98544
46.30000,-7.71678,-6.99615
46.40000,-7.73331,-7.00083
46.50000,-7.75011,-7.00575
46.60000,-7.76678,-7.00979
46.70000,-7.78331,-7.01599
46.80000,-7.80011,-7.01890
46.90000,-7.81665,-7.02558
47.00000,-7.83358,-7.03092
47.10000,-7.85011,-7.03664
47.20000,-7.86691,-7.04371
47.30000,-7.88345,-7.04547
47.40000,-7.90011,-7.05175
47.50000,-7.91678,-7.05603
47.60000,-7.93318,-7.06048
47.70000,-7.95025,-7.06666
47.80000,-7.96678,-7.07037
47.90000,-7.98345,-7.07601
48.00000,-8.00011,-7.07982
48.10000,-8.01678,-7.08359
48.20000,-8.03345,-7.08888
48.30000,-8.04998,-7.09251
48.40000,-8.06691,-7.09597
48.50000,-8.08331,-7.10012
48.60000,-8.10025,-7.10485
48.70000,-8.11665,-7.10786
48.80000,-8.13345,-7.11198
48.90000,-8.15011,-7.11485
49.00000,-8.16665,-7.11746
49.10000,-8.18331,-7.12131
49.20000,-8.19985,-7.12399
49.30000,-8.21678,-7.12819
49.40000,-8.23331,-7.13293
49.50000,-8.25011,-7.13745
49.60000,-8.26665,-7.14061
49.70000,-8.28345,-7.14485
49.80000,-8.30011,-7.14733
49.90000,-8.31665,-7.14959
50.00000,-8.33345,-7.15385
50.10000,-8.34998,-7.15650
50.20000,-8.36678,-7.16076
50.30000,-8.38358,-7.16585
50.40000,-8.40025,-7.17096
50.50000,-8.41665,-7.17297
50.60000,-8.43345,-7.17903
50.70000,-8.45025,-7.18388
50.80000,-8.46665,-7.18835
50.90000,-8.48371,-7.19148
51.00000,-8.50011,-7.19332
51.10000,-8.51678,-7.19848
51.20000,-8.53358,-7.20124
51.30000,-8.55011,-7.20364
51.40000,-8.56665,-7.20588
51.50000,-8.58345,-7.20962
51.60000,-8.59998,-7.21049
51.70000,-8.61638,-7.21265
51.80000,-8.63371,-7.21831
51.90000,-8.64998,-7.21963
52.00000,-8.66678,-7.22463
52.10000,-8.68345,-7.22583
52.20000,-8.69998,-7.22802
52.30000,-8.71665,-7.23043
52.40000,-8.73318,-7.23082
52.50000,-8.75011,-7.23213
52.60000,-8.76665,-7.23643
52.70000,-8.78358,-7.23806
52.80000,-8.79998,-7.23979
52.90000,-8.81678,-7.24199
53.00000,-8.83345,-7.24254
53.10000,-8.84998,-7.24609
53.20000,-8.86678,-7.24766
53.30000,-8.88345,-7.25075
53.40000,-8.90024,-7.25379
53.50000,-8.91678,-7.25599
53.60000,-8.93371,-7.25889
53.70000,-8.94998,-7.26008
53.80000,-8.96665,-7.26293
53.90000,-8.98331,-7.26495
54.00000,-8.99985,-7.26925
54.10000,-9.01704,-7.27399
54.20000,-9.03344,-7.27725
54.30000,-9.05024,-7.28083
54.40000,-9.06691,-7.28486
54.50000,-9.08358,-7.28775
54.60000,-9.10011,-7.29156
54.70000,-9.11678,-7.29647
54.80000,-9.13344,-7.29897
54.90000,-9.14998,-7.30500
55.00000,-9.16704,-7.30873
55.10000,-9.18331,-7.31289
55.20000,-9.20011,-7.31829
55.30000,-9.21664,-7.32080
55.40000,-9.23318,-7.32389
55.50000,-9.24998,-7.32870
55.60000,-9.26651,-7.33265
55.70000,-9.28344,-7.33643
55.80000,-9.29998,-7.34262
55.90000,-9.31691,-7.34640
56.00000,-9.33331,-7.34990
56.10000,-9.35011,-7.35615
56.20000,-9.36678,-7.35868
56.30000,-9.38331,-7.36284
56.40000,-9.40011,-7.36760
56.50000,-9.41664,-7.37234
56.60000,-9.43358,-7.37679
56.70000,-9.45024,-7.38269
56.80000,-9.46691,-7.38650
56.90000,-9.48331,-7.39041
57.00000,-9.50011,-7.39652
57.10000,-9.51678,-7.39907
57.20000,-9.53318,-7.40420
57.30000,-9.55038,-7.41008
57.40000,-9.56664,-7.41435
57.50000,-9.58344,-7.41902
57.60000,-9.60024,-7.42307
57.70000,-9.61691,-7.42703
57.80000,-9.63331,-7.43065
57.90000,-9.64998,-7.43639
58.00000,-9.66678,-7.44087
58.10000,-9.68331,-7.44766
58.20000,-9.70024,-7.45269
58.30000,-9.71664,-7.45720
58.40000,-9.73344,-7.46405
58.50000,-9.74998,-7.46770
58.60000,-9.76664,-7.47444
58.70000,-9.78331,-7.48063
58.80000,-9.79998,-7.48516
58.90000,-9.81664,-7.49092
59.00000,-9.83318,-7.49694
59.10000,-9.85011,-7.50333
59.20000,-9.86678,-7.50854
59.30000,-9.88344,-7.51458
59.40000,-9.89998,-7.51791
59.50000,-9.91651,-7.52344
59.60000,-9.93344,-7.52936
59.70000,-9.94998,-7.53403
59.80000,-9.96678,-7.53984
59.90000,-9.98318,-7.54444
60.00000,-10.00024,-7.54966
60.10000,-10.01678,-7.55432
60.20000,-10.03358,-7.55948
60.30000,-10.05011,-7.56138
60.40000,-10.06651,-7.56599
60.50000,-10.08371,-7.57198
60.60000,-10.10011,-7.57551
60.70000,-10.11691,-7.58024
60.80000,-10.13358,-7.58369
60.90000,-10.15011,-7.58745
61.00000,-10.16664,-7.58854
61.10000,-10.18344,-7.59302
61.20000,-10.20011,-7.59539
61.30000,-10.21651,-7.60011
61.40000,-10.23358,-7.60537
61.50000,-10.25011,-7.60770
61.60000,-10.26678,-7.61422
61.70000,-10.28344,-7.61622
61.80000,-10.29998,-7.62035
61.90000,-10.31664,-7.62438
62.00000,-10.33331,-7.62947
62.10000,-10.35024,-7.63410
62.20000,-10.36664,-7.63931
62.30000,-10.38358,-7.64372
62.40000,-10.40011,-7.64681
62.50000,-10.41678,-7.65320
62.60000,-10.43344,-7.65731
62.70000,-10.44997,-7.66037
62.80000,-10.46691,-7.66825
62.90000,-10.48331,-7.67276
63.00000,-10.50011,-7.67803
63.10000,-10.51677,-7.68448
63.20000,-10.53357,-7.68880
63.30000,-10.54997,-7.69185
63.40000,-10.56664,-7.69787
63.50000,-10.58344,-7.69944
63.60000,-10.59984,-7.70468
63.70000,-10.61691,-7.71022
63.80000,-10.63331,-7.71271
63.90000,-10.65011,-7.71761
64.00000,-10.66691,-7.72116
64.10001,-10.68357,-7.72366
64.20000,-10.70024,-7.72819
64.30000,-10.71677,-7.73235
64.40000,-10.73344,-7.73510
64.50000,-10.74997,-7.74126
64.60001,-10.76704,-7.74684
64.70000,-10.78344,-7.74947
64.80000,-10.80011,-7.75466
64.90000,-10.81677,-7.75893
65.00000,-10.83317,-7.76250
65.10001,-10.84997,-7.76817
65.20000,-10.86664,-7.77282
65.30000,-10.88331,-7.77714
65.40000,-10.89984,-7.78220
65.50000,-10.91677,-7.78796
65.60001,-10.93331,-7.79292
65.70001,-10.95011,-7.80067
65.80000,-10.96664,-7.80377
65.90000,-10.98317,-7.80876
66.00000,-11.00024,-7.81533
66.10001,-11.01677,-7.82126
66.20001,-11.03357,-7.82726
66.30000,-11.05024,-7.83327
66.40000,-11.06691,-7.83949
66.50000,-11.08344,-7.84363
66.60001,-11.10011,-7.85082
66.70001,-11.11677,-7.85472
66.80000,-11.13317,-7.86052
66.90000,-11.15024,-7.86813
67.00000,-11.16677,-7.87447
67.10001,-11.18357,-7.88074
67.20001,-11.20024,-7.88647
67.30000,-11.21677,-7.89171
67.40000,-11.23331,-7.89674
67.50000,-11.25011,-7.90458
67.60001,-11.26677,-7.90961
67.70001,-11.28317,-7.91697
67.80000,-11.30011,-7.92288
67.90000,-11.31664,-7.92889
68.00000,-11.33344,-7.93733
68.10001,-11.35024,-7.94185
68.20001,-11.36664,-7.94772
68.30000,-11.38317,-7.95341
68.40000,-11.39984,-7.96020
68.50000,-11.41677,-7.96746
68.60001,-11.43344,-7.97608
68.70001,-11.45024,-7.98275
68.80000,-11.46651,-7.98799
68.90000,-11.48344,-7.99667
69.00000,-11.50011,-8.00171
69.10001,-11.51650,-8.00793
69.20001,-11.53357,-8.01591
69.30000,-11.55011,-8.02334
69.40000,-11.56691,-8.03263
69.50000,-11.58357,-8.03808
69.60001,-11.60024,-8.04438
69.70001,-11.61677,-8.05199
69.80000,-11.63344,-8.05884
69.90000,-11.65011,-8.06395
70.00000,-11.66664,-8.07202
70.10001,-11.68357,-8.08194
70.20001,-11.70010,-8.08819
70.30000,-11.71677,-8.09469
70.40000,-11.73357,-8.10273
70.50000,-11.75010,-8.11001
70.60001,-11.76677,-8.11436
70.70001,-11.78344,-8.12213
70.80000,-11.80010,-8.13047
70.90000,-11.81650,-8.13792
71.00000,-11.83357,-8.14699
71.10001,-11.85010,-8.15411
71.20001,-11.86677,-8.16156
71.30000,-11.88344,-8.16713
71.40000,-11.89984,-8.17510
71.50000,-11.91650,-8.18417
71.60001,-11.93330,-8.19253
71.70001,-11.95010,-8.20065
71.80000,-11.96664,-8.21133
71.90000,-11.98344,-8.21918
72.00000,-11.99997,-8.22618
72.10001,-12.01677,-8.23550
72.20001,-12.03344,-8.24199
72.30000,-12.04984,-8.24974
72.40000,-12.06677,-8.25840
72.50000,-12.08344,-8.26817
72.60001,-12.10024,-8.27718
72.70001,-12.11690,-8.28619
72.80000,-12.13370,-8.29506
72.90000,-12.14997,-8.30124
73.00000,-12.16677,-8.31162
73.10001,-12.18344,-8.31846
73.20001,-12.19984,-8.32618
73.30000,-12.21690,-8.33601
73.40000,-12.23344,-8.34086
73.50000,-12.25010,-8.34305
73.60001,-12.26690,-8.35244
73.70001,-12.28344,-8.35962
73.80000,-12.29997,-8.36870
73.90000,-12.31664,-8.37703
74.00000,-12.33357,-8.38407
74.10001,-12.34997,-8.39303
74.20001,-12.36690,-8.40165
74.30000,-12.38330,-8.40928
74.40000,-12.39997,-8.41958
74.50000,-12.41664,-8.42472
74.60001,-12.43317,-8.43184
74.70001,-12.44997,-8.44059
74.80000,-12.46650,-8.44936
74.90000,-12.48344,-8.45761
75.00000,-12.49997,-8.46771
75.10001,-12.51690,-8.47608
75.20001,-12.53344,-8.48246
75.30000,-12.55010,-8.49140
75.40000,-12.56677,-8.49825
75.50000,-12.58317,-8.50666
75.60001,-12.60024,-8.51575
75.70001,-12.61664,-8.52456
75.80000,-12.63330,-8.53309
75.90000,-12.65024,-8.54365
76.00000,-12.66704,-8.55356
76.10001,-12.68344,-8.56107
76.20001,-12.70024,-8.57216
76.30000,-12.71677,-8.57891
76.40000,-12.73330,-8.58705
76.50000,-12.75024,-8.59785
76.60001,-12.76690,-8.60582
76.70001,-12.78357,-8.61638
76.80000,-12.80037,-8.62473
76.90000,-12.81677,-8.63237
77.00000,-12.83344,-8.64189
77.10001,-12.85010,-8.65138
77.20001,-12.86677,-8.65906
77.30000,-12.88330,-8.66841
77.40000,-12.90024,-8.67911
77.50000,-12.91677,-8.68697
77.60001,-12.93343,-8.69776
77.70001,-12.94997,-8.70517
77.80000,-12.96650,-8.71317
77.90000,-12.98317,-8.72242
78.00000,-12.99983,-8.73172
78.10001,-13.01677,-8.74114
78.20001,-13.03330,-8.75276
78.30000,-13.05010,-8.76224
78.40000,-13.06677,-8.77154
78.50000,-13.08343,-8.78132
78.60001,-13.10010,-8.78743
78.70001,-13.11663,-8.79592
78.80000,-13.13343,-8.80310
78.90000,-13.14997,-8.81084
79.00000,-13.16677,-8.82084
79.10001,-13.18357,-8.83166
79.20001,-13.20037,-8.84004
79.30000,-13.21663,-8.84546
79.40000,-13.23357,-8.85634
79.50000,-13.25010,-8.86422
79.60001,-13.26663,-8.87588
79.70001,-13.28357,-8.88886
79.80000,-13.29997,-8.89713
79.90000,-13.31677,-8.90967
80.00000,-13.33357,-8.92051
80.10001,-13.35010,-8.92783
80.20001,-13.36677,-8.93760
80.30000,-13.38343,-8.94828
80.40000,-13.40010,-8.95665
80.50001,-13.41650,-8.96694
80.60001,-13.43357,-8.97741
80.70001,-13.45010,-8.98660
80.80000,-13.46677,-8.99714
80.90000,-13.48343,-9.00602
81.00001,-13.49997,-9.01453
81.10001,-13.51663,-9.02435
81.20001,-13.53330,-9.03500
81.30000,-13.55010,-9.04260
81.40000,-13.56663,-9.05462
81.50001,-13.58343,-9.06619
81.60001,-13.59997,-9.07633
81.70001,-13.61677,-9.08922
81.80000,-13.63343,-9.09711
81.90000,-13.64983,-9.10742
82.00001,-13.66677,-9.11933
82.10001,-13.68317,-9.13046
82.20001,-13.70023,-9.14322
82.30000,-13.71690,-9.15326
82.40000,-13.73357,-9.16320
82.50001,-13.75010,-9.17193
82.60001,-13.76690,-9.18356
82.70001,-13.78357,-9.19297
82.80000,-13.79983,-9.20385
82.90000,-13.81703,-9.21900
83.00001,-13.83343,-9.22838
83.10001,-13.85010,-9.23995
83.20001,-13.86690,-9.25157
83.30000,-13.88343,-9.26235
83.40000,-13.89997,-9.27019
83.50001,-13.91663,-9.28260
83.60001,-13.93343,-9.29212
83.70001,-13.94983,-9.30575
83.80000,-13.96690,-9.31822
83.90000,-13.98330,-9.33044
84.00001,-14.00023,-9.34641
84.10001,-14.01677,-9.35518
84.20001,-14.03330,-9.36640
84.30000,-14.04997,-9.37894
84.40000,-14.06663,-9.39323
84.50001,-14.08343,-9.40607
84.60001,-14.09997,-9.42102
84.70001,-14.11690,-9.43318
84.80000,-14.13330,-9.44410
84.90000,-14.15010,-9.45887
85.00001,-14.16677,-9.46871
85.10001,-14.18317,-9.48213
85.20001,-14.20010,-9.49570
85.30000,-14.21676,-9.51019
85.40000,-14.23356,-9.52521
85.50001,-14.25010,-9.53883
85.60001,-14.26690,-9.55360
85.70001,-14.28343,-9.56684
85.80000,-14.29997,-9.58143
85.90000,-14.31676,-9.59364
86.00001,-14.33330,-9.61028
86.10001,-14.35036,-9.62702
86.20001,-14.36663,-9.63923
86.30000,-14.38343,-9.65515
86.40000,-14.40010,-9.66734
86.50001,-14.41676,-9.68155
86.60001,-14.43330,-9.69476
86.70001,-14.44996,-9.70961
86.80000,-14.46676,-9.72121
86.90000,-14.48330,-9.73797
87.00001,-14.50023,-9.75240
87.10001,-14.51676,-9.76542
87.20001,-14.53356,-9.78173
87.30000,-14.55010,-9.79346
87.40000,-14.56650,-9.80721
87.50001,-14.58330,-9.82203
87.60001,-14.59996,-9.83815
87.70001,-14.61663,-9.85217
87.80000,-14.63316,-9.86981
87.90000,-14.65023,-9.88763
88.00001,-14.66663,-9.90191
88.10001,-14.68343,-9.91841
88.20001,-14.70010,-9.93029
88.30000,-14.71650,-9.94521
88.40000,-14.73343,-9.96226
88.50001,-14.75010,-9.98056
88.60001,-14.76690,-9.99604
88.70001,-14.78356,-10.01495
88.80000,-14.80023,-10.03025
88.90000,-14.81676,-10.04358
89.00001,-14.83343,-10.06105
89.10001,-14.85010,-10.07508
89.20001,-14.86650,-10.09236
89.30000,-14.88356,-10.10958
89.40000,-14.90010,-10.12403
89.50001,-14.91690,-10.14198
89.60001,-14.93356,-10.15624
89.70001,-14.95023,-10.17238
89.80000,-14.96676,-10.18780
89.90000,-14.98356,-10.20516
90.00001,-15.00010,-10.21761
90.10001,-15.01663,-10.23490
90.14201,-15.02383,-10.23942