File: GFBaking/data/2_8PercentGluten/2_8gluten_Compression_Continued.is_comp_RawData/Specimen_RawData_3.csv
Time,Extension,Load
(sec),(mm),(N)
0.00000,0.00000,-0.66507
0.10000,-0.00693,-0.67310
0.20000,-0.02627,-0.71429
0.30000,-0.04613,-0.75739
0.40000,-0.06467,-0.79617
0.50000,-0.08227,-0.83233
0.60000,-0.09947,-0.86569
0.70000,-0.11640,-0.89976
0.80000,-0.13320,-0.92893
0.90000,-0.14947,-0.95752
1.00000,-0.16640,-0.98647
1.10000,-0.18320,-1.01516
1.20000,-0.19987,-1.04347
1.30000,-0.21680,-1.07182
1.40000,-0.23320,-1.09989
1.50000,-0.25000,-1.12810
1.60000,-0.26667,-1.15434
1.70000,-0.28320,-1.18094
1.80000,-0.29973,-1.20639
1.90000,-0.31653,-1.23273
2.00000,-0.33320,-1.25849
2.10000,-0.34987,-1.28528
2.20000,-0.36680,-1.31091
2.30000,-0.38320,-1.33700
2.40000,-0.40000,-1.36200
2.50000,-0.41640,-1.38641
2.60000,-0.43307,-1.41082
2.70000,-0.44987,-1.43551
2.80000,-0.46653,-1.46059
2.90000,-0.48320,-1.48509
3.00000,-0.49987,-1.51088
3.10000,-0.51680,-1.53490
3.20000,-0.53320,-1.55843
3.30000,-0.55000,-1.58181
3.40000,-0.56627,-1.60512
3.50000,-0.58320,-1.62921
3.60000,-0.60000,-1.65417
3.70000,-0.61667,-1.67827
3.80000,-0.63347,-1.70208
3.90000,-0.65000,-1.72609
4.00000,-0.66667,-1.74922
4.10000,-0.68306,-1.77216
4.20000,-0.69986,-1.79567
4.30000,-0.71653,-1.81880
4.40000,-0.73333,-1.84217
4.50000,-0.75026,-1.86562
4.60000,-0.76666,-1.88901
4.70000,-0.78346,-1.91241
4.80000,-0.79986,-1.93499
4.90000,-0.81653,-1.95696
5.00000,-0.83293,-1.98000
5.10000,-0.85000,-2.00336
5.20000,-0.86653,-2.02553
5.30000,-0.88320,-2.04870
5.40000,-0.90013,-2.07097
5.50000,-0.91640,-2.09378
5.60000,-0.93333,-2.11702
5.70000,-0.94973,-2.13978
5.80000,-0.96626,-2.16094
5.90000,-0.98306,-2.18367
6.00000,-1.00000,-2.20615
6.10000,-1.01666,-2.22810
6.20000,-1.03333,-2.25116
6.30000,-1.05000,-2.27233
6.40000,-1.06640,-2.29474
6.50000,-1.08333,-2.31747
6.60000,-1.09973,-2.33861
6.70000,-1.11653,-2.36107
6.80000,-1.13333,-2.38254
6.90000,-1.15013,-2.40495
7.00000,-1.16680,-2.42664
7.10000,-1.18333,-2.44941
7.20000,-1.20000,-2.47092
7.30000,-1.21640,-2.49187
7.40000,-1.23306,-2.51350
7.50000,-1.24986,-2.53403
7.60000,-1.26653,-2.55543
7.70000,-1.28346,-2.57671
7.80000,-1.30013,-2.33295
7.90000,-1.31666,-2.31603
8.00000,-1.33333,-2.36313
8.10000,-1.34986,-2.40127
8.20000,-1.36640,-2.43523
8.30000,-1.38333,-2.46735
8.40000,-1.40000,-2.49703
8.50000,-1.41653,-2.52486
8.60000,-1.43346,-2.54804
8.70000,-1.44986,-2.57159
8.80000,-1.46640,-2.59649
8.90000,-1.48293,-2.61943
9.00000,-1.49973,-2.64345
9.10000,-1.51653,-2.66835
9.20000,-1.53333,-2.69094
9.30000,-1.55000,-2.71398
9.40000,-1.56666,-2.73676
9.50000,-1.58346,-2.75800
9.60000,-1.59973,-2.77833
9.70000,-1.61653,-2.80089
9.80000,-1.63306,-2.82203
9.90000,-1.64986,-2.84499
10.00000,-1.66666,-2.86674
10.10000,-1.68333,-2.88922
10.20000,-1.70000,-2.91140
10.30000,-1.71680,-2.93284
10.40000,-1.73333,-2.95420
10.50000,-1.74973,-2.97461
10.60000,-1.76653,-2.99605
10.70000,-1.78333,-3.01568
10.80000,-1.79986,-3.03620
10.90000,-1.81680,-3.05467
11.00000,-1.83333,-3.07561
11.10000,-1.85013,-3.09598
11.20000,-1.86666,-3.11631
11.30000,-1.88333,-3.13537
11.40000,-1.89960,-3.15518
11.50000,-1.91653,-3.17525
11.60000,-1.93320,-3.19401
11.70000,-1.94986,-3.21411
11.80000,-1.96680,-3.23265
11.90000,-1.98320,-3.25269
12.00000,-1.99973,-3.27222
12.10000,-2.01640,-3.29153
12.20000,-2.03306,-3.31141
12.30000,-2.04973,-3.33193
12.40000,-2.06666,-3.35137
12.50000,-2.08333,-3.37012
12.60000,-2.09986,-3.39021
12.70000,-2.11679,-3.40904
12.80000,-2.13306,-3.42781
12.90000,-2.14986,-3.44634
13.00000,-2.16653,-3.46484
13.10000,-2.18333,-3.48362
13.20000,-2.20013,-3.50205
13.30000,-2.21666,-3.51936
13.40000,-2.23346,-3.53747
13.50000,-2.25013,-3.55598
13.60000,-2.26679,-3.57438
13.70000,-2.28306,-3.59180
13.80000,-2.29986,-3.61137
13.90000,-2.31653,-3.62988
14.00000,-2.33306,-3.64904
14.10000,-2.35013,-3.66706
14.20000,-2.36653,-3.68493
14.30000,-2.38319,-3.70385
14.40000,-2.39986,-3.72225
14.50000,-2.41653,-3.74044
14.60000,-2.43279,-3.75830
14.70000,-2.44986,-3.77647
14.80000,-2.46653,-3.79336
14.90000,-2.48319,-3.81142
15.00000,-2.50013,-3.82964
15.10000,-2.51653,-3.84773
15.20000,-2.53333,-3.86545
15.30000,-2.54973,-3.88428
15.40000,-2.56639,-3.90073
15.50000,-2.58306,-3.91886
15.60000,-2.59999,-3.93460
15.70000,-2.61666,-3.95019
15.80000,-2.63333,-3.96604
15.90000,-2.65013,-3.98283
16.00000,-2.66639,-4.00010
16.10000,-2.68333,-4.01747
16.20000,-2.69959,-4.03286
16.30000,-2.71653,-4.04867
16.40000,-2.73333,-4.06476
16.50000,-2.74999,-4.08050
16.60000,-2.76679,-4.09780
16.70000,-2.78346,-4.11648
16.80000,-2.79986,-4.13352
16.90000,-2.81626,-4.15095
17.00000,-2.83319,-4.16784
17.10000,-2.84999,-4.18306
17.20000,-2.86666,-4.19900
17.30000,-2.88346,-4.21497
17.40000,-2.89986,-4.23140
17.50000,-2.91679,-4.24965
17.60000,-2.93333,-4.26587
17.70000,-2.94999,-4.28083
17.80000,-2.96639,-4.29509
17.90000,-2.98333,-4.30968
18.00000,-2.99999,-4.32365
18.10000,-3.01653,-4.34002
18.20000,-3.03359,-4.35646
18.30000,-3.04986,-4.37236
18.40000,-3.06653,-4.38631
18.50000,-3.08306,-4.39931
18.60000,-3.09973,-4.41143
18.70000,-3.11639,-4.42587
18.80000,-3.13333,-4.44148
18.90000,-3.14999,-4.45532
19.00000,-3.16666,-4.47060
19.10000,-3.18346,-4.48307
19.20000,-3.19973,-4.49496
19.30000,-3.21653,-4.50802
19.40000,-3.23306,-4.52147
19.50000,-3.24999,-4.53739
19.60000,-3.26666,-4.55177
19.70000,-3.28333,-4.56488
19.80000,-3.30013,-4.57731
19.90000,-3.31666,-4.59005
20.00000,-3.33333,-4.60357
20.10000,-3.34973,-4.61700
20.20000,-3.36653,-4.63184
20.30000,-3.38319,-4.64496
20.40000,-3.39986,-4.65809
20.50000,-3.41679,-4.67012
20.60000,-3.43319,-4.68248
20.70000,-3.44999,-4.69630
20.80000,-3.46652,-4.71018
20.90000,-3.48319,-4.72326
21.00000,-3.49959,-4.73528
21.10000,-3.51679,-4.74788
21.20000,-3.53332,-4.75902
21.30000,-3.54986,-4.77328
21.40000,-3.56679,-4.78620
21.50000,-3.58319,-4.79909
21.60000,-3.59986,-4.81085
21.70000,-3.61639,-4.82252
21.80000,-3.63306,-4.83231
21.90000,-3.64972,-4.84639
22.00000,-3.66666,-4.86015
22.10000,-3.68332,-4.87282
22.20000,-3.69999,-4.88568
22.30000,-3.71666,-4.89639
22.40000,-3.73306,-4.90707
22.50000,-3.74999,-4.91914
22.60000,-3.76639,-4.93006
22.70000,-3.78319,-4.94352
22.80000,-3.79999,-4.95479
22.90000,-3.81666,-4.96707
23.00000,-3.83332,-4.97645
23.10000,-3.84999,-4.98893
23.20000,-3.86679,-4.99936
23.30000,-3.88306,-5.00954
23.40000,-3.89999,-5.02124
23.50000,-3.91666,-5.03151
23.60000,-3.93332,-5.04167
23.70000,-3.95026,-5.05200
23.80000,-3.96666,-5.06156
23.90000,-3.98346,-5.07175
24.00000,-3.99999,-5.08114
24.10000,-4.01679,-5.09088
24.20000,-4.03306,-5.10102
24.30000,-4.05012,-5.11098
24.40000,-4.06652,-5.11902
24.50000,-4.08319,-5.12917
24.60000,-4.10012,-5.13759
24.70000,-4.11652,-5.14728
24.80000,-4.13306,-5.15604
24.90000,-4.14972,-5.16539
25.00000,-4.16652,-5.17371
25.10000,-4.18319,-5.18311
25.20000,-4.19999,-5.19167
25.30000,-4.21666,-5.20059
25.40000,-4.23332,-5.20991
25.50000,-4.24999,-5.21758
25.60000,-4.26652,-5.22658
25.70000,-4.28332,-5.23619
25.80000,-4.29986,-5.24449
25.90000,-4.31666,-5.25399
26.00000,-4.33332,-5.26296
26.10000,-4.35012,-5.27139
26.20000,-4.36679,-5.27931
26.30000,-4.38332,-5.28919
26.40000,-4.40012,-5.29689
26.50000,-4.41639,-5.30475
26.60000,-4.43332,-5.31393
26.70000,-4.44999,-5.32162
26.80000,-4.46666,-5.32978
26.90000,-4.48359,-5.33847
27.00000,-4.49999,-5.34626
27.10000,-4.51679,-5.35490
27.20000,-4.53332,-5.36324
27.30000,-4.54999,-5.37124
27.40000,-4.56639,-5.37873
27.50000,-4.58332,-5.38722
27.60000,-4.59999,-5.39531
27.70000,-4.61666,-5.40210
27.80000,-4.63346,-5.40903
27.90000,-4.64986,-5.41700
28.00000,-4.66652,-5.42418
28.10000,-4.68306,-5.42904
28.20000,-4.69972,-5.43564
28.30000,-4.71639,-5.44366
28.40000,-4.73332,-5.45150
28.50000,-4.74999,-5.45855
28.60000,-4.76666,-5.46722
28.70000,-4.78346,-5.47463
28.80000,-4.79959,-5.48100
28.90000,-4.81666,-5.48901
29.00000,-4.83319,-5.49586
29.10000,-4.84999,-5.50377
29.20000,-4.86679,-5.51110
29.30000,-4.88332,-5.51845
29.40000,-4.90012,-5.52591
29.50000,-4.91665,-5.53400
29.60000,-4.93332,-5.54005
29.70000,-4.94972,-5.54777
29.80000,-4.96665,-5.55530
29.90000,-4.98319,-5.56183
30.00000,-4.99999,-5.56930
30.10000,-5.01692,-5.57678
30.20000,-5.03332,-5.58258
30.30000,-5.05012,-5.58842
30.40000,-5.06652,-5.59468
30.50000,-5.08332,-5.59928
30.60000,-5.09959,-5.60521
30.70000,-5.11665,-5.61227
30.80000,-5.13319,-5.61926
30.90000,-5.14985,-5.62734
31.00000,-5.16679,-5.63376
31.10000,-5.18319,-5.63306
31.20000,-5.19985,-5.63755
31.30000,-5.21639,-5.64464
31.40000,-5.23305,-5.65086
31.50000,-5.24972,-5.65831
31.60000,-5.26679,-5.66585
31.70000,-5.28332,-5.67189
31.80000,-5.29999,-5.67838
31.90000,-5.31665,-5.68322
32.00000,-5.33319,-5.68966
32.10000,-5.34999,-5.69665
32.20000,-5.36639,-5.70152
32.30000,-5.38332,-5.70791
32.40000,-5.40012,-5.71410
32.50000,-5.41679,-5.72042
32.60000,-5.43359,-5.72684
32.70000,-5.44999,-5.73264
32.80000,-5.46665,-5.73849
32.90000,-5.48319,-5.74493
33.00000,-5.49999,-5.75189
33.10000,-5.51665,-5.75629
33.20000,-5.53332,-5.76238
33.30000,-5.55025,-5.76889
33.40000,-5.56665,-5.77400
33.50000,-5.58332,-5.77800
33.60000,-5.59985,-5.78296
33.70000,-5.61652,-5.78714
33.80000,-5.63292,-5.79190
33.90000,-5.64999,-5.79825
34.00000,-5.66665,-5.80371
34.10000,-5.68319,-5.80974
34.20000,-5.70025,-5.81436
34.30000,-5.71652,-5.81958
34.40000,-5.73332,-5.82479
34.50000,-5.74985,-5.82991
34.60000,-5.76652,-5.83502
34.70000,-5.78319,-5.84018
34.80000,-5.79999,-5.84635
34.90000,-5.81665,-5.85161
35.00000,-5.83332,-5.85736
35.10000,-5.85012,-5.86203
35.20000,-5.86639,-5.86742
35.30000,-5.88332,-5.87306
35.40000,-5.89972,-5.87814
35.50000,-5.91652,-5.88393
35.60000,-5.93332,-5.88962
35.70000,-5.94999,-5.89438
35.80000,-5.96679,-5.89879
35.90000,-5.98332,-5.90404
36.00000,-5.99999,-5.90862
36.10000,-6.01639,-5.91463
36.20000,-6.03332,-5.92016
36.30000,-6.04999,-5.92570
36.40000,-6.06652,-5.93191
36.50000,-6.08359,-5.93753
36.60000,-6.09998,-5.94229
36.70000,-6.11665,-5.94655
36.80000,-6.13319,-5.95247
36.90000,-6.14998,-5.95733
37.00000,-6.16639,-5.96248
37.10000,-6.18345,-5.96824
37.20000,-6.19998,-5.97226
37.30000,-6.21665,-5.97946
37.40000,-6.23345,-5.98427
37.50000,-6.24998,-5.98858
37.60000,-6.26665,-5.99281
37.70000,-6.28305,-5.99594
37.80000,-6.29972,-5.99971
37.90000,-6.31652,-6.00382
38.00000,-6.33332,-6.01232
38.10000,-6.34998,-6.01862
38.20000,-6.36652,-6.02608
38.30000,-6.38345,-6.03028
38.40000,-6.39985,-6.03355
38.50000,-6.41665,-6.04100
38.60000,-6.43305,-6.04443
38.70000,-6.44985,-6.04869
38.80000,-6.46678,-6.05206
38.90000,-6.48332,-6.05376
39.00000,-6.49998,-6.05762
39.10000,-6.51678,-6.06724
39.20000,-6.53345,-6.07353
39.30000,-6.54972,-6.07852
39.40000,-6.56665,-6.08545
39.50000,-6.58332,-6.09382
39.60000,-6.59985,-6.09600
39.70000,-6.61665,-6.10122
39.80000,-6.63332,-6.10994
39.90000,-6.65012,-6.11847
40.00000,-6.66665,-6.11952
40.10000,-6.68332,-6.12344
40.20000,-6.69985,-6.13154
40.30000,-6.71678,-6.13594
40.40000,-6.73332,-6.13957
40.50000,-6.74985,-6.14547
40.60000,-6.76678,-6.15032
40.70000,-6.78305,-6.15384
40.80000,-6.79972,-6.15944
40.90000,-6.81638,-6.16450
41.00000,-6.83305,-6.17036
41.10000,-6.84972,-6.17289
41.20000,-6.86665,-6.17858
41.30000,-6.88345,-6.18458
41.40000,-6.89998,-6.19216
41.50000,-6.91692,-6.19560
41.60000,-6.93318,-6.20038
41.70000,-6.94998,-6.20702
41.80000,-6.96638,-6.21105
41.90000,-6.98318,-6.21828
42.00000,-7.00012,-6.22313
42.10000,-7.01678,-6.22767
42.20000,-7.03345,-6.23317
42.30000,-7.05012,-6.23880
42.40000,-7.06678,-6.24430
42.50000,-7.08318,-6.24907
42.60000,-7.09985,-6.25283
42.70000,-7.11665,-6.25627
42.80000,-7.13318,-6.26276
42.90000,-7.15012,-6.26828
43.00000,-7.16665,-6.27339
43.10000,-7.18345,-6.27949
43.20000,-7.19998,-6.28345
43.30000,-7.21665,-6.28820
43.40000,-7.23305,-6.29283
43.50000,-7.24998,-6.29900
43.60000,-7.26665,-6.30421
43.70000,-7.28318,-6.31084
43.80000,-7.30012,-6.31558
43.90000,-7.31652,-6.32027
44.00000,-7.33318,-6.32660
44.10000,-7.34972,-6.33231
44.20000,-7.36625,-6.33711
44.30000,-7.38305,-6.34324
44.40000,-7.39998,-6.34960
44.50000,-7.41678,-6.35430
44.60000,-7.43318,-6.36038
44.70000,-7.44998,-6.36577
44.80000,-7.46638,-6.37169
44.90000,-7.48332,-6.37882
45.00000,-7.49971,-6.38356
45.10000,-7.51665,-6.39016
45.20000,-7.53332,-6.39638
45.30000,-7.54998,-6.40319
45.40000,-7.56678,-6.40913
45.50000,-7.58345,-6.41600
45.60000,-7.60011,-6.42111
45.70000,-7.61651,-6.42814
45.80000,-7.63331,-6.43491
45.90000,-7.64998,-6.43760
46.00000,-7.66665,-6.44511
46.10000,-7.68358,-6.45062
46.20000,-7.69998,-6.45499
46.30000,-7.71665,-6.46039
46.40000,-7.73331,-6.46391
46.50000,-7.75011,-6.46748
46.60000,-7.76638,-6.47249
46.70000,-7.78331,-6.47794
46.80000,-7.79998,-6.48238
46.90000,-7.81665,-6.48772
47.00000,-7.83345,-6.49132
47.10000,-7.84985,-6.49713
47.20000,-7.86665,-6.49748
47.30000,-7.88318,-6.50417
47.40000,-7.89985,-6.50995
47.50000,-7.91651,-6.51545
47.60000,-7.93331,-6.52283
47.70000,-7.94998,-6.52861
47.80000,-7.96665,-6.53622
47.90000,-7.98345,-6.54352
48.00000,-7.99985,-6.54836
48.10000,-8.01665,-6.55645
48.20000,-8.03305,-6.56150
48.30000,-8.04985,-6.56874
48.40000,-8.06665,-6.57219
48.50000,-8.08331,-6.57639
48.60000,-8.09998,-6.58444
48.70000,-8.11651,-6.59477
48.80000,-8.13331,-6.59881
48.90000,-8.14971,-6.60504
49.00000,-8.16651,-6.61403
49.10000,-8.18331,-6.62013
49.20000,-8.19998,-6.63037
49.30000,-8.21691,-6.63668
49.40000,-8.23331,-6.64333
49.50000,-8.24998,-6.64680
49.60000,-8.26651,-6.65358
49.70000,-8.28345,-6.65912
49.80000,-8.29985,-6.65819
49.90000,-8.31678,-6.66407
50.00000,-8.33331,-6.66803
50.10000,-8.34985,-6.67612
50.20000,-8.36691,-6.67939
50.30000,-8.38318,-6.67728
50.40000,-8.39985,-6.68422
50.50000,-8.41651,-6.69146
50.60000,-8.43318,-6.70126
50.70000,-8.44985,-6.70468
50.80000,-8.46665,-6.71447
50.90000,-8.48331,-6.72157
51.00000,-8.49985,-6.72922
51.10000,-8.51678,-6.73636
51.20000,-8.53318,-6.74304
51.30000,-8.54998,-6.75850
51.40000,-8.56638,-6.75831
51.50000,-8.58331,-6.76474
51.60000,-8.59998,-6.76989
51.70000,-8.61678,-6.77087
51.80000,-8.63345,-6.77086
51.90000,-8.64998,-6.77282
52.00000,-8.66665,-6.77723
52.10000,-8.68305,-6.78062
52.20000,-8.69998,-6.79059
52.30000,-8.71665,-6.79603
52.40000,-8.73331,-6.81079
52.50000,-8.75025,-6.81901
52.60000,-8.76651,-6.82957
52.70000,-8.78331,-6.84154
52.80000,-8.79998,-6.84653
52.90000,-8.81665,-6.85085
53.00000,-8.83305,-6.85638
53.10000,-8.84998,-6.86624
53.20000,-8.86665,-6.87246
53.30000,-8.88331,-6.87920
53.40000,-8.90011,-6.88327
53.50000,-8.91651,-6.88988
53.60000,-8.93318,-6.89050
53.70000,-8.94971,-6.89346
53.80000,-8.96638,-6.90082
53.90000,-8.98318,-6.90653
54.00000,-8.99998,-6.91267
54.10000,-9.01665,-6.91562
54.20000,-9.03331,-6.92036
54.30000,-9.05011,-6.92793
54.40000,-9.06638,-6.93277
54.50000,-9.08331,-6.94049
54.60000,-9.09984,-6.94486
54.70000,-9.11651,-6.95053
54.80000,-9.13331,-6.95617
54.90000,-9.15011,-6.96514
55.00000,-9.16678,-6.97134
55.10000,-9.18344,-6.97953
55.20000,-9.20011,-6.98332
55.30000,-9.21651,-6.99032
55.40000,-9.23318,-6.99790
55.50000,-9.24998,-7.00386
55.60000,-9.26664,-7.01209
55.70000,-9.28344,-7.01464
55.80000,-9.29998,-7.01882
55.90000,-9.31664,-7.02558
56.00000,-9.33318,-7.03072
56.10000,-9.34998,-7.03487
56.20000,-9.36638,-7.03837
56.30000,-9.38331,-7.04063
56.40000,-9.39998,-7.04334
56.50000,-9.41664,-7.04768
56.60000,-9.43344,-7.04736
56.70000,-9.44984,-7.05192
56.80000,-9.46664,-7.05721
56.90000,-9.48318,-7.06005
57.00000,-9.49971,-7.06239
57.10000,-9.51638,-7.06712
57.20000,-9.53331,-7.07112
57.30000,-9.54998,-7.07206
57.40000,-9.56664,-7.07748
57.50000,-9.58344,-7.07842
57.60000,-9.59971,-7.08208
57.70000,-9.61678,-7.08660
57.80000,-9.63304,-7.09068
57.90000,-9.64998,-7.09600
58.00000,-9.66678,-7.10080
58.10000,-9.68331,-7.10524
58.20000,-9.70011,-7.10881
58.30000,-9.71678,-7.11535
58.40000,-9.73344,-7.11926
58.50000,-9.74971,-7.12213
58.60000,-9.76664,-7.12852
58.70000,-9.78331,-7.13125
58.80000,-9.79998,-7.13608
58.90000,-9.81678,-7.14147
59.00000,-9.83331,-7.14553
59.10000,-9.85011,-7.14832
59.20000,-9.86664,-7.15326
59.30000,-9.88331,-7.15506
59.40000,-9.89958,-7.15940
59.50000,-9.91664,-7.16428
59.60000,-9.93331,-7.16658
59.70000,-9.94984,-7.17146
59.80000,-9.96678,-7.17493
59.90000,-9.98331,-7.17907
60.00000,-9.99998,-7.18454
60.10000,-10.01638,-7.18854
60.20000,-10.03318,-7.19265
60.30000,-10.04971,-7.19790
60.40000,-10.06664,-7.20318
60.50000,-10.08318,-7.20607
60.60000,-10.09984,-7.21129
60.70000,-10.11678,-7.21436
60.80000,-10.13318,-7.21972
60.90000,-10.15011,-7.22473
61.00000,-10.16637,-7.22912
61.10000,-10.18331,-7.23422
61.20000,-10.20011,-7.23867
61.30000,-10.21678,-7.24412
61.40000,-10.23344,-7.24734
61.50000,-10.24998,-7.25335
61.60000,-10.26678,-7.25690
61.70000,-10.28304,-7.26083
61.80000,-10.29998,-7.26626
61.90000,-10.31664,-7.26941
62.00000,-10.33331,-7.27492
62.10000,-10.35024,-7.27906
62.20000,-10.36664,-7.28248
62.30000,-10.38344,-7.28624
62.40000,-10.39997,-7.28996
62.50000,-10.41664,-7.29348
62.60000,-10.43304,-7.29598
62.70000,-10.45011,-7.30184
62.80000,-10.46664,-7.30428
62.90000,-10.48317,-7.30902
63.00000,-10.50011,-7.31175
63.10000,-10.51651,-7.31500
63.20000,-10.53317,-7.31838
63.30000,-10.54984,-7.32289
63.40000,-10.56637,-7.32616
63.50000,-10.58304,-7.33084
63.60000,-10.59997,-7.33508
63.70000,-10.61664,-7.33807
63.80000,-10.63331,-7.34420
63.90000,-10.65011,-7.34707
64.00000,-10.66651,-7.35016
64.10001,-10.68331,-7.35531
64.20000,-10.69971,-7.35779
64.30000,-10.71664,-7.36322
64.40000,-10.73331,-7.36809
64.50000,-10.74997,-7.37262
64.60001,-10.76664,-7.37687
64.70000,-10.78331,-7.38337
64.80000,-10.80011,-7.38732
64.90000,-10.81637,-7.39260
65.00000,-10.83331,-7.39660
65.10001,-10.84984,-7.40056
65.20000,-10.86664,-7.40619
65.30000,-10.88344,-7.40981
65.40000,-10.89997,-7.41422
65.50000,-10.91664,-7.41772
65.60001,-10.93331,-7.42296
65.70001,-10.95011,-7.42765
65.80000,-10.96637,-7.43164
65.90000,-10.98344,-7.43689
66.00000,-10.99997,-7.44003
66.10001,-11.01664,-7.44605
66.20001,-11.03357,-7.45024
66.30000,-11.04984,-7.45462
66.40000,-11.06651,-7.45921
66.50000,-11.08304,-7.46297
66.60001,-11.09984,-7.46697
66.70001,-11.11651,-7.47324
66.80000,-11.13331,-7.47825
66.90000,-11.14984,-7.48190
67.00000,-11.16651,-7.48881
67.10001,-11.18331,-7.49238
67.20001,-11.19984,-7.49621
67.30000,-11.21664,-7.50265
67.40000,-11.23317,-7.50628
67.50000,-11.24997,-7.51269
67.60001,-11.26664,-7.51813
67.70001,-11.28344,-7.52406
67.80000,-11.29997,-7.52879
67.90000,-11.31677,-7.53506
68.00000,-11.33344,-7.53975
68.10001,-11.34971,-7.54314
68.20001,-11.36651,-7.54794
68.30000,-11.38331,-7.55143
68.40000,-11.39984,-7.55730
68.50000,-11.41677,-7.56092
68.60001,-11.43331,-7.56480
68.70001,-11.45011,-7.56846
68.80000,-11.46677,-7.57377
68.90000,-11.48344,-7.57726
69.00000,-11.49971,-7.57991
69.10001,-11.51677,-7.58428
69.20001,-11.53331,-7.58745
69.30000,-11.54984,-7.59318
69.40000,-11.56691,-7.59648
69.50000,-11.58304,-7.59980
69.60001,-11.59970,-7.60457
69.70001,-11.61637,-7.60855
69.80000,-11.63317,-7.61183
69.90000,-11.64970,-7.61668
70.00000,-11.66650,-7.62083
70.10001,-11.68317,-7.62409
70.20001,-11.69984,-7.62919
70.30000,-11.71677,-7.63270
70.40000,-11.73317,-7.63539
70.50000,-11.74997,-7.63893
70.60001,-11.76637,-7.64057
70.70001,-11.78330,-7.64667
70.80000,-11.80010,-7.65113
70.90000,-11.81664,-7.65451
71.00000,-11.83344,-7.65721
71.10001,-11.85010,-7.66088
71.20001,-11.86677,-7.66171
71.30000,-11.88317,-7.66489
71.40000,-11.89997,-7.66837
71.50000,-11.91664,-7.67045
71.60001,-11.93330,-7.67571
71.70001,-11.95024,-7.68001
71.80000,-11.96664,-7.68316
71.90000,-11.98344,-7.68666
72.00000,-11.99997,-7.68977
72.10001,-12.01664,-7.69128
72.20001,-12.03304,-7.69438
72.30000,-12.04997,-7.69961
72.40000,-12.06650,-7.70098
72.50000,-12.08317,-7.70607
72.60001,-12.10010,-7.70788
72.70001,-12.11650,-7.71172
72.80000,-12.13317,-7.71406
72.90000,-12.14984,-7.71707
73.00000,-12.16637,-7.71939
73.10001,-12.18304,-7.72561
73.20001,-12.19997,-7.73277
73.30000,-12.21664,-7.73450
73.40000,-12.23330,-7.73991
73.50000,-12.25010,-7.74078
73.60001,-12.26650,-7.74418
73.70001,-12.28330,-7.75002
73.80000,-12.29984,-7.75347
73.90000,-12.31650,-7.75792
74.00000,-12.33330,-7.76189
74.10001,-12.34997,-7.76511
74.20001,-12.36677,-7.77040
74.30000,-12.38344,-7.78173
74.40000,-12.40010,-7.78514
74.50000,-12.41650,-7.78593
74.60001,-12.43330,-7.79126
74.70001,-12.44997,-7.79610
74.80000,-12.46650,-7.80223
74.90000,-12.48344,-7.80626
75.00000,-12.49997,-7.80732
75.10001,-12.51664,-7.80932
75.20001,-12.53330,-7.81250
75.30000,-12.54997,-7.81590
75.40000,-12.56650,-7.81709
75.50000,-12.58317,-7.82078
75.60001,-12.59997,-7.82065
75.70001,-12.61650,-7.82507
75.80000,-12.63357,-7.82588
75.90000,-12.64997,-7.82701
76.00000,-12.66664,-7.83009
76.10001,-12.68304,-7.82580
76.20001,-12.69984,-7.82214
76.30000,-12.71650,-7.82833
76.40000,-12.73330,-7.83252
76.50000,-12.74984,-7.83320
76.60001,-12.76650,-7.83938
76.70001,-12.78344,-7.84116
76.80000,-12.79970,-7.84754
76.90000,-12.81663,-7.85385
77.00000,-12.83304,-7.85592
77.10001,-12.84997,-7.86261
77.20001,-12.86677,-7.86777
77.30000,-12.88344,-7.87109
77.40000,-12.90010,-7.87578
77.50000,-12.91663,-7.88078
77.60001,-12.93343,-7.88429
77.70001,-12.94984,-7.88845
77.80000,-12.96663,-7.89374
77.90000,-12.98330,-7.89771
78.00000,-12.99997,-7.90242
78.10001,-13.01690,-7.90720
78.20001,-13.03330,-7.90940
78.30000,-13.04997,-7.91300
78.40000,-13.06663,-7.91464
78.50000,-13.08330,-7.91679
78.60001,-13.09983,-7.92150
78.70001,-13.11677,-7.92551
78.80000,-13.13330,-7.92635
78.90000,-13.14983,-7.93091
79.00000,-13.16677,-7.93383
79.10001,-13.18317,-7.93614
79.20001,-13.19983,-7.93765
79.30000,-13.21650,-7.94006
79.40000,-13.23317,-7.94273
79.50000,-13.24983,-7.94721
79.60001,-13.26663,-7.95336
79.70001,-13.28317,-7.95632
79.80000,-13.29983,-7.96302
79.90000,-13.31677,-7.96548
80.00000,-13.33317,-7.97002
80.10001,-13.34983,-7.97721
80.20001,-13.36637,-7.97845
80.30000,-13.38330,-7.98426
80.40000,-13.40010,-7.99032
80.50001,-13.41663,-7.99488
80.60001,-13.43343,-7.99901
80.70001,-13.45023,-8.00487
80.80000,-13.46677,-8.00757
80.90000,-13.48303,-8.00949
81.00001,-13.49997,-8.01677
81.10001,-13.51677,-8.02195
81.20001,-13.53330,-8.02968
81.30000,-13.55023,-8.03418
81.40000,-13.56677,-8.03834
81.50001,-13.58343,-8.04210
81.60001,-13.59997,-8.04716
81.70001,-13.61663,-8.05069
81.80000,-13.63303,-8.05455
81.90000,-13.65010,-8.06204
82.00001,-13.66663,-8.06706
82.10001,-13.68317,-8.07434
82.20001,-13.70010,-8.07814
82.30000,-13.71650,-8.08371
82.40000,-13.73303,-8.08871
82.50001,-13.74970,-8.09381
82.60001,-13.76637,-8.09918
82.70001,-13.78290,-8.10769
82.80000,-13.79997,-8.11210
82.90000,-13.81650,-8.11780
83.00001,-13.83330,-8.12503
83.10001,-13.85010,-8.12781
83.20001,-13.86650,-8.13169
83.30000,-13.88330,-8.13869
83.40000,-13.89970,-8.14214
83.50001,-13.91650,-8.14805
83.60001,-13.93343,-8.15465
83.70001,-13.95010,-8.16141
83.80000,-13.96677,-8.16588
83.90000,-13.98343,-8.17465
84.00001,-14.00023,-8.17962
84.10001,-14.01650,-8.18435
84.20001,-14.03330,-8.18968
84.30000,-14.04997,-8.19532
84.40000,-14.06650,-8.20415
84.50001,-14.08343,-8.20941
84.60001,-14.09997,-8.21632
84.70001,-14.11677,-8.22459
84.80000,-14.13330,-8.22873
84.90000,-14.14997,-8.23403
85.00001,-14.16623,-8.23911
85.10001,-14.18330,-8.24714
85.20001,-14.19997,-8.25222
85.30000,-14.21650,-8.25971
85.40000,-14.23343,-8.26511
85.50001,-14.24983,-8.26946
85.60001,-14.26650,-8.27545
85.70001,-14.28317,-8.28151
85.80000,-14.29983,-8.28776
85.90000,-14.31637,-8.29621
86.00001,-14.33343,-8.30464
86.10001,-14.34997,-8.31293
86.20001,-14.36650,-8.32255
86.30000,-14.38343,-8.32897
86.40000,-14.39970,-8.33643
86.50001,-14.41663,-8.34615
86.60001,-14.43303,-8.35178
86.70001,-14.44996,-8.36201
86.80000,-14.46676,-8.37181
86.90000,-14.48330,-8.38063
87.00001,-14.50010,-8.38919
87.10001,-14.51663,-8.39756
87.20001,-14.53343,-8.40363
87.30000,-14.54970,-8.41101
87.40000,-14.56650,-8.42096
87.50001,-14.58330,-8.42897
87.60001,-14.59996,-8.43992
87.70001,-14.61690,-8.44897
87.80000,-14.63330,-8.45430
87.90000,-14.65010,-8.46159
88.00001,-14.66663,-8.46959
88.10001,-14.68316,-8.47771
88.20001,-14.69956,-8.48477
88.30000,-14.71663,-8.49485
88.40000,-14.73316,-8.50167
88.50001,-14.74983,-8.51285
88.60001,-14.76676,-8.52270
88.70001,-14.78330,-8.53383
88.80000,-14.79996,-8.54613
88.90000,-14.81650,-8.55211
89.00001,-14.83316,-8.55798
89.10001,-14.84983,-8.56979
89.20001,-14.86663,-8.58078
89.30000,-14.88330,-8.58858
89.40000,-14.89983,-8.59680
89.50001,-14.91676,-8.60233
89.60001,-14.93303,-8.61174
89.70001,-14.95010,-8.62329
89.80000,-14.96650,-8.62973
89.90000,-14.98316,-8.64051
90.00001,-15.00010,-8.64942
90.08200,-15.01356,-8.65407