File: GFBaking/data/2_8PercentGluten/2_8gluten_Compression_Continued.is_comp_RawData/Specimen_RawData_4.csv
Time,Extension,Load
(sec),(mm),(N)
0.00000,0.00000,-0.45702
0.10000,-0.00547,-0.46368
0.20000,-0.02493,-0.50763
0.30000,-0.04560,-0.55346
0.40000,-0.06427,-0.59212
0.50000,-0.08173,-0.62521
0.60000,-0.09920,-0.65874
0.70000,-0.11600,-0.68901
0.80000,-0.13280,-0.71887
0.90000,-0.14973,-0.74675
1.00000,-0.16653,-0.77530
1.10000,-0.18333,-0.80230
1.20000,-0.19987,-0.83030
1.30000,-0.21667,-0.85764
1.40000,-0.23293,-0.88349
1.50000,-0.24987,-0.91120
1.60000,-0.26640,-0.93532
1.70000,-0.28320,-0.96220
1.80000,-0.30013,-0.98701
1.90000,-0.31680,-1.01345
2.00000,-0.33347,-1.03874
2.10000,-0.35000,-1.06473
2.20000,-0.36667,-1.08907
2.30000,-0.38307,-1.11456
2.40000,-0.39987,-1.13812
2.50000,-0.41653,-1.16339
2.60000,-0.43333,-1.18870
2.70000,-0.45027,-1.21353
2.80000,-0.46667,-1.23806
2.90000,-0.48333,-1.26187
3.00000,-0.50000,-1.28606
3.10000,-0.51653,-1.30923
3.20000,-0.53293,-1.33371
3.30000,-0.54987,-1.35755
3.40000,-0.56653,-1.38169
3.50000,-0.58307,-1.40577
3.60000,-0.60013,-1.43093
3.70000,-0.61640,-1.45496
3.80000,-0.63307,-1.47897
3.90000,-0.64960,-1.50181
4.00000,-0.66640,-1.52586
4.10000,-0.68320,-1.55052
4.20000,-0.70000,-1.57401
4.30000,-0.71666,-1.59785
4.40000,-0.73320,-1.62151
4.50000,-0.75013,-1.64531
4.60000,-0.76640,-1.66790
4.70000,-0.78320,-1.69170
4.80000,-0.79973,-1.71415
4.90000,-0.81653,-1.73738
5.00000,-0.83333,-1.76050
5.10000,-0.85000,-1.78395
5.20000,-0.86680,-1.80791
5.30000,-0.88346,-1.83159
5.40000,-0.90000,-1.85343
5.50000,-0.91640,-1.87641
5.60000,-0.93320,-1.90017
5.70000,-0.94986,-1.92431
5.80000,-0.96653,-1.94813
5.90000,-0.98346,-1.97167
6.00000,-1.00000,-1.99323
6.10000,-1.01680,-2.01449
6.20000,-1.03333,-2.03736
6.30000,-1.04986,-2.05951
6.40000,-1.06626,-2.08124
6.50000,-1.08333,-2.10424
6.60000,-1.10000,-2.12787
6.70000,-1.11653,-2.15071
6.80000,-1.13346,-2.17266
6.90000,-1.14973,-2.19486
7.00000,-1.16640,-2.21630
7.10000,-1.18306,-2.23687
7.20000,-1.19973,-2.25911
7.30000,-1.21640,-2.28190
7.40000,-1.23320,-2.30455
7.50000,-1.24986,-2.32585
7.60000,-1.26653,-2.34790
7.70000,-1.28333,-2.37074
7.80000,-1.29960,-2.39179
7.90000,-1.31653,-2.41283
8.00000,-1.33320,-2.43414
8.10000,-1.35000,-2.45625
8.20000,-1.36680,-2.47758
8.30000,-1.38346,-2.49776
8.40000,-1.40013,-2.51569
8.50000,-1.41666,-2.53528
8.60000,-1.43346,-2.50389
8.70000,-1.44973,-2.45951
8.80000,-1.46653,-2.48920
8.90000,-1.48320,-2.50008
9.00000,-1.49986,-2.36200
9.10000,-1.51680,-2.40143
9.20000,-1.53320,-2.42827
9.30000,-1.54986,-2.45967
9.40000,-1.56640,-2.48847
9.50000,-1.58306,-2.51775
9.60000,-1.59960,-2.54632
9.70000,-1.61666,-2.57214
9.80000,-1.63320,-2.59841
9.90000,-1.64973,-2.62387
10.00000,-1.66680,-2.64810
10.10000,-1.68320,-2.67107
10.20000,-1.70000,-2.69354
10.30000,-1.71640,-2.71465
10.40000,-1.73293,-2.73580
10.50000,-1.74973,-2.75570
10.60000,-1.76666,-2.77711
10.70000,-1.78333,-2.79615
10.80000,-1.80000,-2.81311
10.90000,-1.81693,-2.83245
11.00000,-1.83306,-2.84794
11.10000,-1.85000,-2.86939
11.20000,-1.86640,-2.88735
11.30000,-1.88320,-2.90762
11.40000,-1.90000,-2.92883
11.50000,-1.91666,-2.94752
11.60000,-1.93346,-2.96778
11.70000,-1.95000,-2.98724
11.80000,-1.96653,-3.00460
11.90000,-1.98293,-3.02380
12.00000,-2.00000,-3.04408
12.10000,-2.01680,-3.06048
12.20000,-2.03333,-3.07910
12.30000,-2.05026,-3.09719
12.40000,-2.06653,-3.11436
12.50000,-2.08333,-3.13466
12.60000,-2.09986,-3.15696
12.70000,-2.11666,-3.17380
12.80000,-2.13319,-3.19065
12.90000,-2.14999,-3.20739
13.00000,-2.16666,-3.22310
13.10000,-2.18333,-3.23892
13.20000,-2.20026,-3.25624
13.30000,-2.21653,-3.27227
13.40000,-2.23333,-3.28966
13.50000,-2.24973,-3.30418
13.60000,-2.26626,-3.31955
13.70000,-2.28306,-3.33877
13.80000,-2.29999,-3.35930
13.90000,-2.31653,-3.37362
14.00000,-2.33319,-3.39148
14.10000,-2.34999,-3.40909
14.20000,-2.36639,-3.42943
14.30000,-2.38319,-3.44775
14.40000,-2.39959,-3.46744
14.50000,-2.41666,-3.48521
14.60000,-2.43346,-3.50437
14.70000,-2.44999,-3.52171
14.80000,-2.46679,-3.54071
14.90000,-2.48333,-3.55928
15.00000,-2.49999,-3.57504
15.10000,-2.51639,-3.59349
15.20000,-2.53319,-3.61138
15.30000,-2.54986,-3.62726
15.40000,-2.56653,-3.64426
15.50000,-2.58346,-3.65998
15.60000,-2.59986,-3.67623
15.70000,-2.61666,-3.69376
15.80000,-2.63319,-3.70880
15.90000,-2.64986,-3.72463
16.00000,-2.66626,-3.73935
16.10000,-2.68333,-3.75644
16.20000,-2.69999,-3.77062
16.30000,-2.71639,-3.78699
16.40000,-2.73346,-3.80120
16.50000,-2.74986,-3.81844
16.60000,-2.76653,-3.83455
16.70000,-2.78293,-3.84890
16.80000,-2.79959,-3.86365
16.90000,-2.81639,-3.87713
17.00000,-2.83333,-3.89469
17.10000,-2.84999,-3.90689
17.20000,-2.86653,-3.92475
17.30000,-2.88333,-3.93849
17.40000,-2.89973,-3.95386
17.50000,-2.91653,-3.96948
17.60000,-2.93306,-3.98306
17.70000,-2.94986,-3.99784
17.80000,-2.96679,-4.01507
17.90000,-2.98333,-4.03107
18.00000,-3.00013,-4.04395
18.10000,-3.01666,-4.05692
18.20000,-3.03346,-4.07014
18.30000,-3.04973,-4.08503
18.40000,-3.06653,-4.10105
18.50000,-3.08319,-4.11354
18.60000,-3.09999,-4.12570
18.70000,-3.11679,-4.13755
18.80000,-3.13333,-4.14917
18.90000,-3.15013,-4.16588
19.00000,-3.16653,-4.17966
19.10000,-3.18346,-4.19506
19.20000,-3.19973,-4.20752
19.30000,-3.21666,-4.22322
19.40000,-3.23319,-4.23511
19.50000,-3.24986,-4.25050
19.60000,-3.26679,-4.26351
19.70000,-3.28306,-4.27692
19.80000,-3.29973,-4.28823
19.90000,-3.31639,-4.30107
20.00000,-3.33319,-4.31433
20.10000,-3.34986,-4.32709
20.20000,-3.36666,-4.34043
20.30000,-3.38319,-4.35378
20.40000,-3.39999,-4.36905
20.50000,-3.41679,-4.38016
20.60000,-3.43306,-4.39218
20.70000,-3.44986,-4.40460
20.80000,-3.46639,-4.41510
20.90000,-3.48332,-4.42643
21.00000,-3.49999,-4.43581
21.10000,-3.51666,-4.44825
21.20000,-3.53346,-4.45730
21.30000,-3.54999,-4.46880
21.40000,-3.56679,-4.47924
21.50000,-3.58306,-4.49138
21.60000,-3.59999,-4.50261
21.70000,-3.61652,-4.51430
21.80000,-3.63332,-4.52642
21.90000,-3.65026,-4.53677
22.00000,-3.66666,-4.54485
22.10000,-3.68332,-4.55584
22.20000,-3.69986,-4.56741
22.30000,-3.71666,-4.57695
22.40000,-3.73292,-4.58798
22.50000,-3.74999,-4.60044
22.60000,-3.76652,-4.61149
22.70000,-3.78319,-4.62111
22.80000,-3.80012,-4.63083
22.90000,-3.81652,-4.64036
23.00000,-3.83319,-4.64916
23.10000,-3.84972,-4.65952
23.20000,-3.86639,-4.66858
23.30000,-3.88306,-4.67916
23.40000,-3.89986,-4.68852
23.50000,-3.91652,-4.69744
23.60000,-3.93319,-4.70930
23.70000,-3.94999,-4.71729
23.80000,-3.96626,-4.72636
23.90000,-3.98332,-4.73683
24.00000,-3.99986,-4.74649
24.10000,-4.01652,-4.75635
24.20000,-4.03346,-4.76651
24.30000,-4.04999,-4.77335
24.40000,-4.06679,-4.78388
24.50000,-4.08332,-4.79173
24.60000,-4.09999,-4.80013
24.70000,-4.11639,-4.80764
24.80000,-4.13319,-4.81527
24.90000,-4.14986,-4.82302
25.00000,-4.16652,-4.83138
25.10000,-4.18346,-4.83745
25.20000,-4.19999,-4.84460
25.30000,-4.21666,-4.85328
25.40000,-4.23319,-4.85975
25.50000,-4.24999,-4.86871
25.60000,-4.26626,-4.87419
25.70000,-4.28319,-4.88348
25.80000,-4.29986,-4.88988
25.90000,-4.31652,-4.90139
26.00000,-4.33346,-4.90696
26.10000,-4.34986,-4.91353
26.20000,-4.36652,-4.92111
26.30000,-4.38319,-4.92400
26.40000,-4.39972,-4.93207
26.50000,-4.41639,-4.94155
26.60000,-4.43332,-4.95118
26.70000,-4.44986,-4.95724
26.80000,-4.46652,-4.96524
26.90000,-4.48346,-4.96882
27.00000,-4.49972,-4.97595
27.10000,-4.51666,-4.98692
27.20000,-4.53306,-4.99558
27.30000,-4.54986,-5.00483
27.40000,-4.56679,-5.01163
27.50000,-4.58332,-5.01782
27.60000,-4.60012,-5.02494
27.70000,-4.61666,-5.03564
27.80000,-4.63332,-5.04317
27.90000,-4.64986,-5.05329
28.00000,-4.66666,-5.06127
28.10000,-4.68332,-5.06473
28.20000,-4.69999,-5.06809
28.30000,-4.71692,-5.08085
28.40000,-4.73332,-5.08782
28.50000,-4.74999,-5.09574
28.60000,-4.76652,-5.10067
28.70000,-4.78319,-5.11037
28.80000,-4.79959,-5.11626
28.90000,-4.81666,-5.12649
29.00000,-4.83332,-5.13320
29.10000,-4.84972,-5.14003
29.20000,-4.86679,-5.14536
29.30000,-4.88305,-5.14603
29.40000,-4.89985,-5.15147
29.50000,-4.91652,-5.15861
29.60000,-4.93305,-5.16539
29.70000,-4.94972,-5.17120
29.80000,-4.96679,-5.17789
29.90000,-4.98332,-5.17663
30.00000,-4.99985,-5.18521
30.10000,-5.01679,-5.19271
30.20000,-5.03305,-5.20009
30.30000,-5.04985,-5.20545
30.40000,-5.06639,-5.21044
30.50000,-5.08319,-5.21728
30.60000,-5.09999,-5.22969
30.70000,-5.11665,-5.23692
30.80000,-5.13332,-5.24196
30.90000,-5.14985,-5.24642
31.00000,-5.16665,-5.25204
31.10000,-5.18305,-5.25731
31.20000,-5.19985,-5.27031
31.30000,-5.21652,-5.27303
31.40000,-5.23319,-5.27622
31.50000,-5.25012,-5.27856
31.60000,-5.26652,-5.28387
31.70000,-5.28319,-5.28985
31.80000,-5.29985,-5.29629
31.90000,-5.31652,-5.29998
32.00000,-5.33292,-5.30324
32.10000,-5.34999,-5.31056
32.20000,-5.36665,-5.31533
32.30000,-5.38319,-5.32411
32.40000,-5.40012,-5.32592
32.50000,-5.41652,-5.33005
32.60000,-5.43319,-5.33494
32.70000,-5.44972,-5.34248
32.80000,-5.46639,-5.34828
32.90000,-5.48305,-5.35426
33.00000,-5.49999,-5.35899
33.10000,-5.51665,-5.36015
33.20000,-5.53305,-5.36855
33.30000,-5.55012,-5.37359
33.40000,-5.56639,-5.37971
33.50000,-5.58319,-5.38382
33.60000,-5.59972,-5.38806
33.70000,-5.61652,-5.39242
33.80000,-5.63345,-5.39929
33.90000,-5.64999,-5.40125
34.00000,-5.66665,-5.40521
34.10000,-5.68332,-5.40884
34.20000,-5.70012,-5.41324
34.30000,-5.71625,-5.41779
34.40000,-5.73319,-5.42276
34.50000,-5.74999,-5.42808
34.60000,-5.76652,-5.43062
34.70000,-5.78345,-5.43660
34.80000,-5.79999,-5.43916
34.90000,-5.81679,-5.44449
35.00000,-5.83319,-5.44677
35.10000,-5.84985,-5.45039
35.20000,-5.86625,-5.45357
35.30000,-5.88332,-5.45715
35.40000,-5.89999,-5.46132
35.50000,-5.91652,-5.46609
35.60000,-5.93345,-5.46973
35.70000,-5.94972,-5.47123
35.80000,-5.96639,-5.47453
35.90000,-5.98319,-5.47907
36.00000,-5.99972,-5.48188
36.10000,-6.01652,-5.48707
36.20000,-6.03332,-5.49039
36.30000,-6.04999,-5.49243
36.40000,-6.06652,-5.49742
36.50000,-6.08345,-5.49977
36.60000,-6.09972,-5.50259
36.70000,-6.11665,-5.50642
36.80000,-6.13305,-5.50870
36.90000,-6.14972,-5.51177
37.00000,-6.16665,-5.51626
37.10000,-6.18332,-5.51908
37.20000,-6.19998,-5.52022
37.30000,-6.21665,-5.52348
37.40000,-6.23345,-5.52561
37.50000,-6.24972,-5.52745
37.60000,-6.26652,-5.53112
37.70000,-6.28318,-5.53439
37.80000,-6.29985,-5.53755
37.90000,-6.31678,-5.54101
38.00000,-6.33332,-5.54433
38.10000,-6.34998,-5.54825
38.20000,-6.36665,-5.55244
38.30000,-6.38332,-5.55544
38.40000,-6.39972,-5.55817
38.50000,-6.41665,-5.56249
38.60000,-6.43332,-5.56480
38.70000,-6.44985,-5.56905
38.80000,-6.46678,-5.57192
38.90000,-6.48305,-5.57426
39.00000,-6.49985,-5.57829
39.10000,-6.51638,-5.58000
39.20000,-6.53292,-5.58350
39.30000,-6.54972,-5.58715
39.40000,-6.56665,-5.59126
39.50000,-6.58345,-5.59345
39.60000,-6.59985,-5.59679
39.70000,-6.61665,-5.59872
39.80000,-6.63305,-5.60112
39.90000,-6.64985,-5.60474
40.00000,-6.66638,-5.60598
40.10000,-6.68318,-5.60999
40.20000,-6.70012,-5.61392
40.30000,-6.71665,-5.61761
40.40000,-6.73345,-5.62035
40.50000,-6.74998,-5.62380
40.60000,-6.76665,-5.62645
40.70000,-6.78305,-5.62984
40.80000,-6.79998,-5.63418
40.90000,-6.81665,-5.63684
41.00000,-6.83318,-5.64023
41.10000,-6.85025,-5.64418
41.20000,-6.86665,-5.64600
41.30000,-6.88332,-5.64876
41.40000,-6.89998,-5.65173
41.50000,-6.91665,-5.65470
41.60000,-6.93292,-5.65614
41.70000,-6.94985,-5.65999
41.80000,-6.96665,-5.66220
41.90000,-6.98318,-5.66485
42.00000,-7.00025,-5.66808
42.10000,-7.01665,-5.67101
42.20000,-7.03332,-5.67435
42.30000,-7.04985,-5.67614
42.40000,-7.06652,-5.67960
42.50000,-7.08318,-5.68279
42.60000,-7.09985,-5.68564
42.70000,-7.11652,-5.68791
42.80000,-7.13318,-5.69261
42.90000,-7.15012,-5.69496
43.00000,-7.16638,-5.69762
43.10000,-7.18332,-5.70183
43.20000,-7.19972,-5.70401
43.30000,-7.21638,-5.70826
43.40000,-7.23332,-5.71218
43.50000,-7.24985,-5.71540
43.60000,-7.26652,-5.71869
43.70000,-7.28318,-5.72259
43.80000,-7.29985,-5.72580
43.90000,-7.31638,-5.72934
44.00000,-7.33318,-5.73369
44.10000,-7.34985,-5.73647
44.20000,-7.36665,-5.74161
44.30000,-7.38358,-5.74367
44.40000,-7.39998,-5.74687
44.50000,-7.41665,-5.74960
44.60000,-7.43318,-5.75236
44.70000,-7.44998,-5.75554
44.80000,-7.46652,-5.75780
44.90000,-7.48345,-5.76139
45.00000,-7.49998,-5.76381
45.10000,-7.51665,-5.76821
45.20000,-7.53345,-5.77054
45.30000,-7.54985,-5.77413
45.40000,-7.56651,-5.77809
45.50000,-7.58305,-5.78163
45.60000,-7.59971,-5.78598
45.70000,-7.61638,-5.78981
45.80000,-7.63331,-5.79448
45.90000,-7.64998,-5.79692
46.00000,-7.66651,-5.80202
46.10000,-7.68331,-5.80465
46.20000,-7.69971,-5.80817
46.30000,-7.71665,-5.81274
46.40000,-7.73305,-5.81536
46.50000,-7.74985,-5.82058
46.60000,-7.76678,-5.82517
46.70000,-7.78331,-5.83027
46.80000,-7.80011,-5.83443
46.90000,-7.81678,-5.83969
47.00000,-7.83331,-5.84339
47.10000,-7.84971,-5.84738
47.20000,-7.86665,-5.85229
47.30000,-7.88331,-5.85612
47.40000,-7.89998,-5.86138
47.50000,-7.91691,-5.86600
47.60000,-7.93318,-5.86954
47.70000,-7.94998,-5.87426
47.80000,-7.96665,-5.87906
47.90000,-7.98331,-5.88255
48.00000,-7.99971,-5.88511
48.10000,-8.01665,-5.89079
48.20000,-8.03331,-5.89338
48.30000,-8.04985,-5.89867
48.40000,-8.06678,-5.90223
48.50000,-8.08318,-5.90690
48.60000,-8.09985,-5.91056
48.70000,-8.11638,-5.91266
48.80000,-8.13305,-5.91628
48.90000,-8.14971,-5.92100
49.00000,-8.16651,-5.92670
49.10000,-8.18331,-5.93188
49.20000,-8.19985,-5.93688
49.30000,-8.21691,-5.93973
49.40000,-8.23305,-5.94215
49.50000,-8.24998,-5.94771
49.60000,-8.26638,-5.95098
49.70000,-8.28318,-5.95607
49.80000,-8.29998,-5.96028
49.90000,-8.31665,-5.96461
50.00000,-8.33345,-5.96841
50.10000,-8.34998,-5.97411
50.20000,-8.36665,-5.97870
50.30000,-8.38305,-5.98191
50.40000,-8.39998,-5.98543
50.50000,-8.41665,-5.98925
50.60000,-8.43331,-5.99541
50.70000,-8.45011,-5.99953
50.80000,-8.46665,-6.00299
50.90000,-8.48345,-6.00419
51.00000,-8.49985,-6.00647
51.10000,-8.51665,-6.01082
51.20000,-8.53305,-6.01526
51.30000,-8.54998,-6.02170
51.40000,-8.56665,-6.02531
51.50000,-8.58318,-6.03051
51.60000,-8.60011,-6.03641
51.70000,-8.61638,-6.04151
51.80000,-8.63318,-6.04657
51.90000,-8.64985,-6.05084
52.00000,-8.66638,-6.05436
52.10000,-8.68291,-6.05903
52.20000,-8.69985,-6.06603
52.30000,-8.71665,-6.07100
52.40000,-8.73318,-6.07287
52.50000,-8.75011,-6.07698
52.60000,-8.76651,-6.08301
52.70000,-8.78331,-6.08765
52.80000,-8.79971,-6.09337
52.90000,-8.81651,-6.09999
53.00000,-8.83345,-6.10497
53.10000,-8.84998,-6.10996
53.20000,-8.86678,-6.11435
53.30000,-8.88331,-6.11947
53.40000,-8.90011,-6.12510
53.50000,-8.91638,-6.12822
53.60000,-8.93331,-6.13446
53.70000,-8.94998,-6.13908
53.80000,-8.96665,-6.14601
53.90000,-8.98345,-6.15105
54.00000,-9.00011,-6.15707
54.10000,-9.01678,-6.16014
54.20000,-9.03331,-6.16628
54.30000,-9.04998,-6.17064
54.40000,-9.06638,-6.17543
54.50000,-9.08331,-6.18273
54.60000,-9.09998,-6.18642
54.70000,-9.11651,-6.19238
54.80000,-9.13358,-6.19737
54.90000,-9.14984,-6.20158
55.00000,-9.16664,-6.20674
55.10000,-9.18304,-6.21027
55.20000,-9.19971,-6.21619
55.30000,-9.21638,-6.22146
55.40000,-9.23331,-6.22783
55.50000,-9.24984,-6.23155
55.60000,-9.26651,-6.23811
55.70000,-9.28344,-6.24268
55.80000,-9.29984,-6.24874
55.90000,-9.31664,-6.25495
56.00000,-9.33304,-6.25929
56.10000,-9.34984,-6.26650
56.20000,-9.36678,-6.27354
56.30000,-9.38331,-6.28011
56.40000,-9.40011,-6.28488
56.50000,-9.41664,-6.29178
56.60000,-9.43344,-6.29755
56.70000,-9.44971,-6.30252
56.80000,-9.46664,-6.30993
56.90000,-9.48331,-6.31531
57.00000,-9.49998,-6.32209
57.10000,-9.51691,-6.32748
57.20000,-9.53331,-6.33300
57.30000,-9.55011,-6.33936
57.40000,-9.56664,-6.34609
57.50000,-9.58331,-6.35184
57.60000,-9.59971,-6.35898
57.70000,-9.61664,-6.36483
57.80000,-9.63331,-6.37053
57.90000,-9.64984,-6.37897
58.00000,-9.66678,-6.38471
58.10000,-9.68304,-6.38897
58.20000,-9.69984,-6.39522
58.30000,-9.71638,-6.39994
58.40000,-9.73291,-6.40440
58.50000,-9.74971,-6.41132
58.60000,-9.76664,-6.41723
58.70000,-9.78331,-6.42289
58.80000,-9.79998,-6.42880
58.90000,-9.81678,-6.43290
59.00000,-9.83304,-6.43619
59.10000,-9.84998,-6.44221
59.20000,-9.86651,-6.44568
59.30000,-9.88331,-6.45292
59.40000,-9.90011,-6.45817
59.50000,-9.91664,-6.46363
59.60000,-9.93331,-6.46593
59.70000,-9.94984,-6.47213
59.80000,-9.96678,-6.47779
59.90000,-9.98304,-6.48038
60.00000,-9.99984,-6.48597
60.10000,-10.01651,-6.49186
60.20000,-10.03331,-6.49753
60.30000,-10.05011,-6.50297
60.40000,-10.06664,-6.50735
60.50000,-10.08344,-6.51236
60.60000,-10.09998,-6.51769
60.70000,-10.11678,-6.52245
60.80000,-10.13318,-6.52722
60.90000,-10.14998,-6.53252
61.00000,-10.16664,-6.53692
61.10000,-10.18331,-6.54415
61.20000,-10.20024,-6.54775
61.30000,-10.21651,-6.55348
61.40000,-10.23318,-6.55742
61.50000,-10.24971,-6.56107
61.60000,-10.26637,-6.56574
61.70000,-10.28317,-6.57118
61.80000,-10.29998,-6.57656
61.90000,-10.31664,-6.58028
62.00000,-10.33317,-6.58499
62.10000,-10.35011,-6.58813
62.20000,-10.36651,-6.59197
62.30000,-10.38331,-6.59886
62.40000,-10.39984,-6.60302
62.50000,-10.41664,-6.60967
62.60000,-10.43344,-6.61686
62.70000,-10.44997,-6.62150
62.80000,-10.46651,-6.62594
62.90000,-10.48317,-6.63275
63.00000,-10.50011,-6.63752
63.10000,-10.51637,-6.64164
63.20000,-10.53331,-6.64835
63.30000,-10.55011,-6.65194
63.40000,-10.56651,-6.65638
63.50000,-10.58344,-6.66025
63.60000,-10.60011,-6.66301
63.70000,-10.61677,-6.66595
63.80000,-10.63331,-6.66887
63.90000,-10.65011,-6.67281
64.00000,-10.66651,-6.67516
64.10001,-10.68331,-6.67950
64.20000,-10.69997,-6.68245
64.30000,-10.71651,-6.68619
64.40000,-10.73357,-6.68944
64.50000,-10.74984,-6.69197
64.60001,-10.76651,-6.69666
64.70000,-10.78291,-6.69911
64.80000,-10.79984,-6.70502
64.90000,-10.81651,-6.70966
65.00000,-10.83317,-6.71359
65.10001,-10.84984,-6.71577
65.20000,-10.86664,-6.72337
65.30000,-10.88344,-6.72744
65.40000,-10.89971,-6.73321
65.50000,-10.91651,-6.73759
65.60001,-10.93317,-6.74194
65.70001,-10.94997,-6.74804
65.80000,-10.96677,-6.75385
65.90000,-10.98331,-6.75771
66.00000,-11.00011,-6.76010
66.10001,-11.01677,-6.76161
66.20001,-11.03344,-6.76478
66.30000,-11.04971,-6.77103
66.40000,-11.06664,-6.77754
66.50000,-11.08331,-6.78120
66.60001,-11.09997,-6.78638
66.70001,-11.11691,-6.79317
66.80000,-11.13331,-6.79883
66.90000,-11.15011,-6.80538
67.00000,-11.16664,-6.81194
67.10001,-11.18331,-6.81762
67.20001,-11.19971,-6.82363
67.30000,-11.21664,-6.83108
67.40000,-11.23317,-6.83316
67.50000,-11.24984,-6.84083
67.60001,-11.26677,-6.84676
67.70001,-11.28331,-6.85319
67.80000,-11.29984,-6.85893
67.90000,-11.31637,-6.86503
68.00000,-11.33291,-6.87067
68.10001,-11.34971,-6.87768
68.20001,-11.36664,-6.88619
68.30000,-11.38331,-6.89053
68.40000,-11.39997,-6.89788
68.50000,-11.41677,-6.90153
68.60001,-11.43317,-6.90757
68.70001,-11.44984,-6.91386
68.80000,-11.46651,-6.91396
68.90000,-11.48331,-6.92385
69.00000,-11.50011,-6.92963
69.10001,-11.51664,-6.93808
69.20001,-11.53344,-6.94072
69.30000,-11.55011,-6.94762
69.40000,-11.56677,-6.94936
69.50000,-11.58304,-6.95586
69.60001,-11.59984,-6.96458
69.70001,-11.61664,-6.97310
69.80000,-11.63317,-6.97946
69.90000,-11.65011,-6.98595
70.00000,-11.66664,-6.99407
70.10001,-11.68330,-7.00433
70.20001,-11.69997,-7.01132
70.30000,-11.71664,-7.01905
70.40000,-11.73317,-7.02351
70.50000,-11.74997,-7.03085
70.60001,-11.76664,-7.03740
70.70001,-11.78330,-7.04639
70.80000,-11.80024,-7.05520
70.90000,-11.81650,-7.05763
71.00000,-11.83330,-7.06211
71.10001,-11.84970,-7.06400
71.20001,-11.86637,-7.06765
71.30000,-11.88317,-7.07409
71.40000,-11.89997,-7.08248
71.50000,-11.91650,-7.08732
71.60001,-11.93317,-7.09682
71.70001,-11.95010,-7.10276
71.80000,-11.96650,-7.11074
71.90000,-11.98330,-7.11797
72.00000,-11.99970,-7.12196
72.10001,-12.01650,-7.12932
72.20001,-12.03344,-7.13644
72.30000,-12.04997,-7.14184
72.40000,-12.06677,-7.14754
72.50000,-12.08330,-7.15080
72.60001,-12.09997,-7.15459
72.70001,-12.11650,-7.15726
72.80000,-12.13317,-7.16302
72.90000,-12.14997,-7.16758
73.00000,-12.16664,-7.17243
73.10001,-12.18344,-7.17768
73.20001,-12.20010,-7.18159
73.30000,-12.21664,-7.18593
73.40000,-12.23330,-7.18897
73.50000,-12.24997,-7.19296
73.60001,-12.26637,-7.19568
73.70001,-12.28330,-7.20243
73.80000,-12.29997,-7.20544
73.90000,-12.31650,-7.21236
74.00000,-12.33344,-7.21456
74.10001,-12.34984,-7.21909
74.20001,-12.36650,-7.22286
74.30000,-12.38317,-7.22836
74.40000,-12.39984,-7.23213
74.50000,-12.41637,-7.23892
74.60001,-12.43330,-7.24465
74.70001,-12.44997,-7.24818
74.80000,-12.46650,-7.25471
74.90000,-12.48344,-7.25928
75.00000,-12.49984,-7.26256
75.10001,-12.51650,-7.26767
75.20001,-12.53304,-7.27134
75.30000,-12.54997,-7.27651
75.40000,-12.56677,-7.28003
75.50000,-12.58330,-7.28369
75.60001,-12.60010,-7.28884
75.70001,-12.61677,-7.29474
75.80000,-12.63344,-7.29811
75.90000,-12.64984,-7.30152
76.00000,-12.66664,-7.30648
76.10001,-12.68330,-7.30910
76.20001,-12.69997,-7.31384
76.30000,-12.71690,-7.31842
76.40000,-12.73344,-7.32034
76.50000,-12.75010,-7.32353
76.60001,-12.76664,-7.32815
76.70001,-12.78330,-7.33143
76.80000,-12.79970,-7.33470
76.90000,-12.81677,-7.34001
77.00000,-12.83330,-7.34175
77.10001,-12.84984,-7.34480
77.20001,-12.86677,-7.34892
77.30000,-12.88317,-7.35302
77.40000,-12.89984,-7.35644
77.50000,-12.91637,-7.35861
77.60001,-12.93304,-7.36206
77.70001,-12.94970,-7.36503
77.80000,-12.96663,-7.37056
77.90000,-12.98330,-7.37314
78.00000,-12.99983,-7.37967
78.10001,-13.01677,-7.38350
78.20001,-13.03317,-7.38645
78.30000,-13.04997,-7.39052
78.40000,-13.06650,-7.39234
78.50000,-13.08317,-7.39612
78.60001,-13.09997,-7.40133
78.70001,-13.11677,-7.40713
78.80000,-13.13357,-7.41038
78.90000,-13.15010,-7.41661
79.00000,-13.16677,-7.42146
79.10001,-13.18317,-7.42423
79.20001,-13.19983,-7.42814
79.30000,-13.21663,-7.43270
79.40000,-13.23317,-7.43857
79.50000,-13.25010,-7.44235
79.60001,-13.26677,-7.44869
79.70001,-13.28343,-7.45314
79.80000,-13.29997,-7.45734
79.90000,-13.31663,-7.46178
80.00000,-13.33303,-7.46587
80.10001,-13.34983,-7.47247
80.20001,-13.36663,-7.47863
80.30000,-13.38317,-7.48624
80.40000,-13.40023,-7.49273
80.50001,-13.41650,-7.49566
80.60001,-13.43317,-7.50289
80.70001,-13.44970,-7.50725
80.80000,-13.46637,-7.51379
80.90000,-13.48317,-7.51987
81.00001,-13.49997,-7.52672
81.10001,-13.51663,-7.52981
81.20001,-13.53317,-7.53690
81.30000,-13.55010,-7.54129
81.40000,-13.56637,-7.54415
81.50001,-13.58330,-7.55120
81.60001,-13.59983,-7.55498
81.70001,-13.61650,-7.56153
81.80000,-13.63343,-7.56882
81.90000,-13.64997,-7.57340
82.00001,-13.66677,-7.57957
82.10001,-13.68330,-7.58569
82.20001,-13.70010,-7.59182
82.30000,-13.71650,-7.59550
82.40000,-13.73317,-7.60050
82.50001,-13.74997,-7.60404
82.60001,-13.76663,-7.61141
82.70001,-13.78357,-7.61743
82.80000,-13.79997,-7.62054
82.90000,-13.81677,-7.62374
83.00001,-13.83330,-7.62858
83.10001,-13.84997,-7.63094
83.20001,-13.86637,-7.63402
83.30000,-13.88330,-7.63816
83.40000,-13.89983,-7.63989
83.50001,-13.91650,-7.64583
83.60001,-13.93357,-7.64965
83.70001,-13.94997,-7.65386
83.80000,-13.96650,-7.65643
83.90000,-13.98303,-7.65984
84.00001,-13.99957,-7.66249
84.10001,-14.01637,-7.66827
84.20001,-14.03343,-7.67551
84.30000,-14.04997,-7.67867
84.40000,-14.06650,-7.68569
84.50001,-14.08343,-7.69127
84.60001,-14.09970,-7.69453
84.70001,-14.11663,-7.70072
84.80000,-14.13317,-7.70464
84.90000,-14.14997,-7.71163
85.00001,-14.16677,-7.71774
85.10001,-14.18330,-7.72584
85.20001,-14.20010,-7.73286
85.30000,-14.21663,-7.74229
85.40000,-14.23343,-7.74841
85.50001,-14.24970,-7.75543
85.60001,-14.26650,-7.76362
85.70001,-14.28330,-7.77209
85.80000,-14.29983,-7.77947
85.90000,-14.31676,-7.78929
86.00001,-14.33330,-7.79566
86.10001,-14.35010,-7.80597
86.20001,-14.36650,-7.81189
86.30000,-14.38330,-7.82099
86.40000,-14.39970,-7.82672
86.50001,-14.41663,-7.83834
86.60001,-14.43330,-7.84544
86.70001,-14.44983,-7.85756
86.80000,-14.46690,-7.86415
86.90000,-14.48316,-7.87377
87.00001,-14.49983,-7.88128
87.10001,-14.51650,-7.89238
87.20001,-14.53316,-7.90124
87.30000,-14.54970,-7.91235
87.40000,-14.56663,-7.92224
87.50001,-14.58316,-7.92956
87.60001,-14.59996,-7.94372
87.70001,-14.61676,-7.95105
87.80000,-14.63303,-7.95970
87.90000,-14.64983,-7.96940
88.00001,-14.66636,-7.97805
88.10001,-14.68330,-7.99097
88.20001,-14.69996,-8.00206
88.30000,-14.71663,-8.01218
88.40000,-14.73343,-8.02237
88.50001,-14.74996,-8.03388
88.60001,-14.76676,-8.04409
88.70001,-14.78303,-8.05284
88.80000,-14.79996,-8.06628
88.90000,-14.81663,-8.07629
89.00001,-14.83316,-8.08940
89.10001,-14.85010,-8.10061
89.20001,-14.86663,-8.11241
89.30000,-14.88343,-8.12324
89.40000,-14.89996,-8.13461
89.50001,-14.91676,-8.14580
89.60001,-14.93303,-8.15556
89.70001,-14.94996,-8.16880
89.80000,-14.96676,-8.17858
89.90000,-14.98330,-8.19215
90.00001,-15.00023,-8.20283
90.10001,-15.01650,-8.21410
90.20001,-15.03330,-8.22634
90.22401,-15.03730,-8.22652