File: GFBaking/data/2_8PercentGluten/2_8gluten_Compression_Continued.is_comp_RawData/Specimen_RawData_2.csv
Time,Extension,Load
(sec),(mm),(N)
0.00000,-0.00013,-0.50341
0.10000,-0.00480,-0.50681
0.20000,-0.02440,-0.54400
0.30000,-0.04520,-0.58462
0.40000,-0.06413,-0.61733
0.50000,-0.08187,-0.64555
0.60000,-0.09920,-0.67536
0.70000,-0.11627,-0.70265
0.80000,-0.13320,-0.73056
0.90000,-0.15000,-0.75471
1.00000,-0.16693,-0.78204
1.10000,-0.18360,-0.80477
1.20000,-0.20000,-0.82926
1.30000,-0.21680,-0.85337
1.40000,-0.23320,-0.87756
1.50000,-0.25027,-0.90228
1.60000,-0.26707,-0.92565
1.70000,-0.28360,-0.94767
1.80000,-0.30027,-0.97042
1.90000,-0.31707,-0.99262
2.00000,-0.33347,-1.01385
2.10000,-0.34987,-1.03614
2.20000,-0.36680,-1.05788
2.30000,-0.38333,-1.07975
2.40000,-0.40013,-1.10177
2.50000,-0.41707,-1.12311
2.60000,-0.43347,-1.14468
2.70000,-0.45027,-1.16662
2.80000,-0.46693,-1.18643
2.90000,-0.48360,-1.20743
3.00000,-0.50000,-1.22719
3.10000,-0.51680,-1.24820
3.20000,-0.53347,-1.26805
3.30000,-0.55027,-1.29023
3.40000,-0.56693,-1.30970
3.50000,-0.58347,-1.32992
3.60000,-0.60027,-1.34971
3.70000,-0.61667,-1.37065
3.80000,-0.63333,-1.39108
3.90000,-0.65013,-1.41330
4.00000,-0.66693,-1.43434
4.10000,-0.68346,-1.45598
4.20000,-0.70013,-1.47560
4.30000,-0.71706,-1.49550
4.40000,-0.73346,-1.51528
4.50000,-0.75026,-1.53440
4.60000,-0.76666,-1.55297
4.70000,-0.78346,-1.57243
4.80000,-0.80026,-1.59239
4.90000,-0.81680,-1.61127
5.00000,-0.83360,-1.62933
5.10000,-0.85026,-1.64840
5.20000,-0.86693,-1.66758
5.30000,-0.88333,-1.68637
5.40000,-0.90013,-1.70522
5.50000,-0.91666,-1.72460
5.60000,-0.93360,-1.74599
5.70000,-0.95026,-1.76481
5.80000,-0.96680,-1.78478
5.90000,-0.98360,-1.80439
6.00000,-1.00013,-1.82289
6.10000,-1.01666,-1.84043
6.20000,-1.03320,-1.85978
6.30000,-1.05040,-1.88034
6.40000,-1.06693,-1.89831
6.50000,-1.08360,-1.91669
6.60000,-1.10040,-1.93406
6.70000,-1.11666,-1.95296
6.80000,-1.13360,-1.96940
6.90000,-1.15000,-1.98818
7.00000,-1.16666,-2.00628
7.10000,-1.18333,-2.02499
7.20000,-1.20026,-2.04288
7.30000,-1.21680,-2.06109
7.40000,-1.23360,-2.07984
7.50000,-1.25040,-2.09605
7.60000,-1.26653,-2.10199
7.70000,-1.28360,-2.10316
7.80000,-1.29986,-2.10423
7.90000,-1.31680,-2.10247
8.00000,-1.33360,-2.10093
8.10000,-1.35040,-2.10603
8.20000,-1.36693,-2.11005
8.30000,-1.38360,-2.11025
8.40000,-1.40026,-2.10830
8.50000,-1.41666,-2.10635
8.60000,-1.43346,-2.11230
8.70000,-1.45013,-2.11625
8.80000,-1.46680,-2.12158
8.90000,-1.48386,-2.12344
9.00000,-1.50026,-2.11974
9.10000,-1.51693,-2.12540
9.20000,-1.53346,-2.15180
9.30000,-1.55026,-2.17775
9.40000,-1.56653,-2.20164
9.50000,-1.58360,-2.22426
9.60000,-1.60013,-2.24749
9.70000,-1.61693,-2.27009
9.80000,-1.63360,-2.28968
9.90000,-1.65013,-2.30987
10.00000,-1.66693,-2.33074
10.10000,-1.68320,-2.35041
10.20000,-1.70000,-2.36951
10.30000,-1.71680,-2.38977
10.40000,-1.73360,-2.40878
10.50000,-1.75013,-2.42799
10.60000,-1.76693,-2.44671
10.70000,-1.78373,-2.46572
10.80000,-1.80013,-2.48499
10.90000,-1.81693,-2.50363
11.00000,-1.83333,-2.52094
11.10000,-1.85013,-2.54122
11.20000,-1.86693,-2.55874
11.30000,-1.88360,-2.57715
11.40000,-1.90026,-2.59540
11.50000,-1.91706,-2.61407
11.60000,-1.93360,-2.63105
11.70000,-1.95000,-2.64791
11.80000,-1.96693,-2.66614
11.90000,-1.98346,-2.68479
12.00000,-2.00013,-2.70224
12.10000,-2.01706,-2.71909
12.20000,-2.03359,-2.73714
12.30000,-2.05026,-2.75457
12.40000,-2.06680,-2.77049
12.50000,-2.08346,-2.78658
12.60000,-2.09986,-2.80367
12.70000,-2.11679,-2.82004
12.80000,-2.13346,-2.83652
12.90000,-2.15026,-2.85514
13.00000,-2.16706,-2.87305
13.10000,-2.18346,-2.88884
13.20000,-2.20026,-2.90479
13.30000,-2.21666,-2.92013
13.40000,-2.23333,-2.93667
13.50000,-2.25013,-2.95313
13.60000,-2.26693,-2.97096
13.70000,-2.28346,-2.98809
13.80000,-2.30026,-3.00294
13.90000,-2.31706,-3.01859
14.00000,-2.33333,-3.03364
14.10000,-2.35013,-3.04983
14.20000,-2.36666,-3.06615
14.30000,-2.38359,-3.08228
14.40000,-2.40039,-3.09893
14.50000,-2.41693,-3.11486
14.60000,-2.43359,-3.12906
14.70000,-2.45026,-3.14448
14.80000,-2.46693,-3.16097
14.90000,-2.48333,-3.17581
15.00000,-2.50026,-3.19202
15.10000,-2.51679,-3.20649
15.20000,-2.53346,-3.22332
15.30000,-2.55039,-3.23897
15.40000,-2.56679,-3.25484
15.50000,-2.58359,-3.26770
15.60000,-2.59999,-3.28468
15.70000,-2.61679,-3.29950
15.80000,-2.63319,-3.31383
15.90000,-2.65026,-3.33173
16.00000,-2.66679,-3.34497
16.10000,-2.68359,-3.35781
16.20000,-2.70026,-3.37361
16.30000,-2.71679,-3.38564
16.40000,-2.73359,-3.40114
16.50000,-2.74999,-3.41647
16.60000,-2.76666,-3.42918
16.70000,-2.78333,-3.44610
16.80000,-2.80026,-3.46076
16.90000,-2.81693,-3.47435
17.00000,-2.83359,-3.49121
17.10000,-2.85039,-3.50341
17.20000,-2.86666,-3.51832
17.30000,-2.88359,-3.53269
17.40000,-2.89986,-3.54416
17.50000,-2.91679,-3.55939
17.60000,-2.93359,-3.57148
17.70000,-2.95026,-3.58682
17.80000,-2.96693,-3.59944
17.90000,-2.98373,-3.61218
18.00000,-3.00026,-3.62557
18.10000,-3.01639,-3.63804
18.20000,-3.03346,-3.65353
18.30000,-3.05026,-3.66595
18.40000,-3.06679,-3.67956
18.50000,-3.08373,-3.69490
18.60000,-3.10013,-3.70514
18.70000,-3.11693,-3.71987
18.80000,-3.13359,-3.73238
18.90000,-3.15026,-3.74395
19.00000,-3.16666,-3.75692
19.10000,-3.18359,-3.77024
19.20000,-3.20013,-3.78405
19.30000,-3.21693,-3.79661
19.40000,-3.23373,-3.80887
19.50000,-3.25026,-3.82022
19.60000,-3.26693,-3.83248
19.70000,-3.28333,-3.84347
19.80000,-3.29999,-3.85771
19.90000,-3.31666,-3.87036
20.00000,-3.33359,-3.88380
20.10000,-3.35026,-3.89527
20.20000,-3.36693,-3.90673
20.30000,-3.38373,-3.91860
20.40000,-3.39999,-3.93147
20.50000,-3.41692,-3.94716
20.60000,-3.43319,-3.95767
20.70000,-3.45012,-3.97055
20.80000,-3.46692,-3.98194
20.90000,-3.48359,-3.99362
21.00000,-3.50026,-4.00194
21.10000,-3.51692,-4.01312
21.20000,-3.53359,-4.02366
21.30000,-3.54999,-4.03466
21.40000,-3.56692,-4.04604
21.50000,-3.58332,-4.05617
21.60000,-3.60026,-4.06841
21.70000,-3.61706,-4.07847
21.80000,-3.63346,-4.09058
21.90000,-3.65026,-4.10107
22.00000,-3.66679,-4.11323
22.10000,-3.68346,-4.12446
22.20000,-3.69999,-4.13897
22.30000,-3.71692,-4.14849
22.40000,-3.73346,-4.15848
22.50000,-3.75012,-4.17174
22.60000,-3.76692,-4.18741
22.70000,-3.78346,-4.19779
22.80000,-3.80026,-4.20455
22.90000,-3.81666,-4.21383
23.00000,-3.83332,-4.22215
23.10000,-3.84999,-4.23015
23.20000,-3.86692,-4.23925
23.30000,-3.88346,-4.24853
23.40000,-3.90012,-4.25781
23.50000,-3.91679,-4.26456
23.60000,-3.93319,-4.27071
23.70000,-3.95012,-4.28002
23.80000,-3.96652,-4.28894
23.90000,-3.98346,-4.29971
24.00000,-4.00026,-4.30967
24.10000,-4.01692,-4.32020
24.20000,-4.03359,-4.33033
24.30000,-4.05039,-4.33885
24.40000,-4.06706,-4.34917
24.50000,-4.08319,-4.36004
24.60000,-4.10012,-4.36786
24.70000,-4.11666,-4.37879
24.80000,-4.13359,-4.38949
24.90000,-4.15039,-4.39824
25.00000,-4.16679,-4.40221
25.10000,-4.18372,-4.41063
25.20000,-4.20012,-4.41746
25.30000,-4.21692,-4.42394
25.40000,-4.23332,-4.43069
25.50000,-4.25026,-4.44079
25.60000,-4.26666,-4.44693
25.70000,-4.28346,-4.45426
25.80000,-4.30012,-4.46101
25.90000,-4.31679,-4.47174
26.00000,-4.33332,-4.47920
26.10000,-4.34999,-4.48587
26.20000,-4.36679,-4.49391
26.30000,-4.38346,-4.50102
26.40000,-4.40026,-4.50613
26.50000,-4.41679,-4.51114
26.60000,-4.43359,-4.52084
26.70000,-4.45039,-4.52941
26.80000,-4.46679,-4.53695
26.90000,-4.48359,-4.54495
27.00000,-4.49999,-4.55086
27.10000,-4.51692,-4.55329
27.20000,-4.53359,-4.56175
27.30000,-4.55026,-4.56845
27.40000,-4.56692,-4.57710
27.50000,-4.58372,-4.58480
27.60000,-4.60026,-4.58816
27.70000,-4.61652,-4.59520
27.80000,-4.63359,-4.60573
27.90000,-4.65012,-4.60767
28.00000,-4.66692,-4.61650
28.10000,-4.68372,-4.62104
28.20000,-4.70026,-4.62525
28.30000,-4.71706,-4.63232
28.40000,-4.73346,-4.63810
28.50000,-4.75026,-4.64607
28.60000,-4.76652,-4.65269
28.70000,-4.78359,-4.65817
28.80000,-4.80012,-4.66395
28.90000,-4.81692,-4.66868
29.00000,-4.83359,-4.67380
29.10000,-4.84999,-4.68182
29.20000,-4.86679,-4.68845
29.30000,-4.88332,-4.69361
29.40000,-4.89999,-4.69655
29.50000,-4.91665,-4.70556
29.60000,-4.93359,-4.71376
29.70000,-4.95012,-4.71915
29.80000,-4.96692,-4.72419
29.90000,-4.98359,-4.72989
30.00000,-4.99985,-4.73675
30.10000,-5.01679,-4.74259
30.20000,-5.03332,-4.74959
30.30000,-5.05012,-4.75678
30.40000,-5.06692,-4.76325
30.50000,-5.08359,-4.76911
30.60000,-5.10039,-4.77431
30.70000,-5.11705,-4.78181
30.80000,-5.13372,-4.78533
30.90000,-5.14999,-4.78970
31.00000,-5.16692,-4.79485
31.10000,-5.18332,-4.79972
31.20000,-5.20025,-4.80555
31.30000,-5.21705,-4.81030
31.40000,-5.23359,-4.81512
31.50000,-5.25025,-4.81906
31.60000,-5.26665,-4.82342
31.70000,-5.28345,-4.82694
31.80000,-5.29985,-4.83314
31.90000,-5.31679,-4.83660
32.00000,-5.33332,-4.84133
32.10000,-5.35025,-4.84758
32.20000,-5.36692,-4.85140
32.30000,-5.38345,-4.85488
32.40000,-5.40025,-4.86019
32.50000,-5.41679,-4.86462
32.60000,-5.43345,-4.86961
32.70000,-5.44999,-4.87336
32.80000,-5.46692,-4.87885
32.90000,-5.48345,-4.88378
33.00000,-5.50025,-4.88926
33.10000,-5.51692,-4.89297
33.20000,-5.53345,-4.89793
33.30000,-5.55025,-4.90410
33.40000,-5.56665,-4.90783
33.50000,-5.58345,-4.91253
33.60000,-5.60025,-4.91865
33.70000,-5.61692,-4.92290
33.80000,-5.63372,-4.92762
33.90000,-5.65025,-4.93271
34.00000,-5.66692,-4.93657
34.10000,-5.68332,-4.94061
34.20000,-5.70025,-4.94549
34.30000,-5.71679,-4.94995
34.40000,-5.73359,-4.95535
34.50000,-5.75039,-4.95874
34.60000,-5.76679,-4.96276
34.70000,-5.78359,-4.96858
34.80000,-5.80012,-4.97292
34.90000,-5.81679,-4.97682
35.00000,-5.83319,-4.98153
35.10000,-5.85025,-4.98758
35.20000,-5.86679,-4.99144
35.30000,-5.88345,-4.99669
35.40000,-5.90039,-5.00104
35.50000,-5.91665,-5.00658
35.60000,-5.93359,-5.01191
35.70000,-5.94999,-5.01519
35.80000,-5.96679,-5.02043
35.90000,-5.98345,-5.02528
36.00000,-6.00025,-5.02946
36.10000,-6.01692,-5.03408
36.20000,-6.03359,-5.04057
36.30000,-6.05025,-5.04434
36.40000,-6.06665,-5.04887
36.50000,-6.08359,-5.05453
36.60000,-6.09998,-5.05935
36.70000,-6.11665,-5.06456
36.80000,-6.13345,-5.06985
36.90000,-6.15025,-5.07545
37.00000,-6.16692,-5.07993
37.10000,-6.18359,-5.08428
37.20000,-6.20025,-5.08884
37.30000,-6.21665,-5.09558
37.40000,-6.23358,-5.09921
37.50000,-6.25012,-5.10251
37.60000,-6.26678,-5.10832
37.70000,-6.28372,-5.11266
37.80000,-6.30025,-5.11698
37.90000,-6.31678,-5.12094
38.00000,-6.33345,-5.12496
38.10000,-6.35025,-5.12877
38.20000,-6.36665,-5.13283
38.30000,-6.38358,-5.13770
38.40000,-6.40012,-5.14165
38.50000,-6.41692,-5.14599
38.60000,-6.43372,-5.14887
38.70000,-6.45012,-5.15316
38.80000,-6.46692,-5.15663
38.90000,-6.48332,-5.15979
39.00000,-6.49998,-5.16330
39.10000,-6.51678,-5.16788
39.20000,-6.53358,-5.17163
39.30000,-6.55012,-5.17496
39.40000,-6.56692,-5.17959
39.50000,-6.58358,-5.18245
39.60000,-6.59998,-5.18668
39.70000,-6.61692,-5.18992
39.80000,-6.63332,-5.19258
39.90000,-6.65012,-5.19660
40.00000,-6.66692,-5.19929
40.10000,-6.68358,-5.20304
40.20000,-6.70025,-5.20634
40.30000,-6.71692,-5.21044
40.40000,-6.73345,-5.21232
40.50000,-6.74998,-5.21666
40.60000,-6.76692,-5.21991
40.70000,-6.78345,-5.22307
40.80000,-6.80012,-5.22652
40.90000,-6.81692,-5.22939
41.00000,-6.83358,-5.23285
41.10000,-6.85038,-5.23594
41.20000,-6.86678,-5.23892
41.30000,-6.88358,-5.24293
41.40000,-6.89985,-5.24560
41.50000,-6.91678,-5.24889
41.60000,-6.93332,-5.25248
41.70000,-6.95012,-5.25666
41.80000,-6.96705,-5.25966
41.90000,-6.98345,-5.26286
42.00000,-7.00012,-5.26576
42.10000,-7.01665,-5.26869
42.20000,-7.03345,-5.27264
42.30000,-7.05012,-5.27687
42.40000,-7.06678,-5.27975
42.50000,-7.08358,-5.28312
42.60000,-7.10025,-5.28655
42.70000,-7.11705,-5.28993
42.80000,-7.13332,-5.29325
42.90000,-7.15025,-5.29504
43.00000,-7.16652,-5.29721
43.10000,-7.18345,-5.30040
43.20000,-7.20025,-5.30329
43.30000,-7.21692,-5.30632
43.40000,-7.23358,-5.30944
43.50000,-7.25038,-5.31211
43.60000,-7.26692,-5.31411
43.70000,-7.28332,-5.31691
43.80000,-7.30012,-5.31934
43.90000,-7.31678,-5.32155
44.00000,-7.33345,-5.32586
44.10000,-7.35038,-5.32793
44.20000,-7.36678,-5.33075
44.30000,-7.38358,-5.33508
44.40000,-7.40025,-5.33778
44.50000,-7.41692,-5.34002
44.60000,-7.43332,-5.34261
44.70000,-7.45025,-5.34556
44.80000,-7.46678,-5.34765
44.90000,-7.48358,-5.35094
45.00000,-7.50025,-5.35211
45.10000,-7.51665,-5.35515
45.20000,-7.53358,-5.35670
45.30000,-7.54998,-5.35724
45.40000,-7.56665,-5.35855
45.50000,-7.58332,-5.36013
45.60000,-7.60011,-5.36275
45.70000,-7.61691,-5.36503
45.80000,-7.63358,-5.36692
45.90000,-7.65025,-5.36669
46.00000,-7.66665,-5.36892
46.10000,-7.68345,-5.37047
46.20000,-7.69985,-5.37104
46.30000,-7.71678,-5.37312
46.40000,-7.73358,-5.37492
46.50000,-7.75025,-5.37558
46.60000,-7.76691,-5.37614
46.70000,-7.78358,-5.37677
46.80000,-7.80038,-5.37643
46.90000,-7.81665,-5.37735
47.00000,-7.83358,-5.37841
47.10000,-7.84998,-5.37826
47.20000,-7.86678,-5.37877
47.30000,-7.88371,-5.37832
47.40000,-7.90025,-5.37795
47.50000,-7.91691,-5.37716
47.60000,-7.93358,-5.37599
47.70000,-7.95025,-5.37418
47.80000,-7.96665,-5.37338
47.90000,-7.98358,-5.37252
48.00000,-8.00025,-5.37224
48.10000,-8.01691,-5.37096
48.20000,-8.03358,-5.36890
48.30000,-8.05025,-5.36861
48.40000,-8.06705,-5.36768
48.50000,-8.08331,-5.36755
48.60000,-8.10011,-5.36655
48.70000,-8.11678,-5.36690
48.80000,-8.13358,-5.36785
48.90000,-8.15011,-5.36696
49.00000,-8.16691,-5.36811
49.10000,-8.18371,-5.36873
49.20000,-8.19998,-5.36869
49.30000,-8.21691,-5.37065
49.40000,-8.23318,-5.36959
49.50000,-8.24998,-5.37185
49.60000,-8.26678,-5.37352
49.70000,-8.28345,-5.37508
49.80000,-8.29998,-5.37623
49.90000,-8.31665,-5.37938
50.00000,-8.33345,-5.38043
50.10000,-8.34998,-5.38379
50.20000,-8.36678,-5.38535
50.30000,-8.38345,-5.38659
50.40000,-8.40025,-5.39023
50.50000,-8.41705,-5.39159
50.60000,-8.43345,-5.39336
50.70000,-8.45038,-5.39661
50.80000,-8.46691,-5.39842
50.90000,-8.48371,-5.40123
51.00000,-8.49998,-5.40383
51.10000,-8.51691,-5.40723
51.20000,-8.53345,-5.41021
51.30000,-8.55025,-5.41382
51.40000,-8.56691,-5.41630
51.50000,-8.58345,-5.41950
51.60000,-8.60025,-5.42229
51.70000,-8.61665,-5.42544
51.80000,-8.63331,-5.42829
51.90000,-8.65011,-5.43242
52.00000,-8.66691,-5.43651
52.10000,-8.68345,-5.43931
52.20000,-8.70025,-5.44333
52.30000,-8.71691,-5.44690
52.40000,-8.73331,-5.45016
52.50000,-8.75025,-5.45512
52.60000,-8.76665,-5.45832
52.70000,-8.78358,-5.46308
52.80000,-8.80024,-5.46658
52.90000,-8.81691,-5.47142
53.00000,-8.83358,-5.47609
53.10000,-8.85024,-5.48029
53.20000,-8.86704,-5.48403
53.30000,-8.88331,-5.48750
53.40000,-8.90024,-5.49153
53.50000,-8.91665,-5.49463
53.60000,-8.93345,-5.49956
53.70000,-8.95038,-5.50341
53.80000,-8.96678,-5.50542
53.90000,-8.98345,-5.50926
54.00000,-9.00024,-5.51206
54.10000,-9.01691,-5.51556
54.20000,-9.03331,-5.51798
54.30000,-9.05024,-5.52055
54.40000,-9.06678,-5.52201
54.50000,-9.08358,-5.52439
54.60000,-9.10024,-5.52597
54.70000,-9.11664,-5.52804
54.80000,-9.13358,-5.53031
54.90000,-9.15011,-5.53367
55.00000,-9.16664,-5.53606
55.10000,-9.18331,-5.53816
55.20000,-9.20011,-5.54183
55.30000,-9.21678,-5.54279
55.40000,-9.23358,-5.54712
55.50000,-9.25038,-5.54875
55.60000,-9.26678,-5.55126
55.70000,-9.28358,-5.55289
55.80000,-9.29998,-5.55388
55.90000,-9.31678,-5.55630
56.00000,-9.33358,-5.55797
56.10000,-9.35024,-5.56037
56.20000,-9.36691,-5.56301
56.30000,-9.38371,-5.56726
56.40000,-9.40038,-5.56679
56.50000,-9.41638,-5.56403
56.60000,-9.43344,-5.56481
56.70000,-9.45024,-5.56685
56.80000,-9.46691,-5.57110
56.90000,-9.48358,-5.57157
57.00000,-9.49998,-5.57484
57.10000,-9.51691,-5.57634
57.20000,-9.53344,-5.57895
57.30000,-9.55011,-5.58241
57.40000,-9.56678,-5.58754
57.50000,-9.58358,-5.58833
57.60000,-9.60011,-5.58907
57.70000,-9.61691,-5.59241
57.80000,-9.63358,-5.59299
57.90000,-9.64998,-5.59412
58.00000,-9.66691,-5.59596
58.10000,-9.68331,-5.59727
58.20000,-9.69998,-5.59765
58.30000,-9.71664,-5.59774
58.40000,-9.73358,-5.59876
58.50000,-9.74984,-5.59940
58.60000,-9.76678,-5.60214
58.70000,-9.78371,-5.60182
58.80000,-9.80011,-5.60355
58.90000,-9.81704,-5.60327
59.00000,-9.83331,-5.60294
59.10000,-9.85024,-5.60531
59.20000,-9.86691,-5.60575
59.30000,-9.88358,-5.60211
59.40000,-9.90024,-5.60030
59.50000,-9.91704,-5.60401
59.60000,-9.93371,-5.60398
59.70000,-9.94998,-5.60467
59.80000,-9.96691,-5.60621
59.90000,-9.98344,-5.60748
60.00000,-10.00011,-5.60893
60.10000,-10.01691,-5.60972
60.20000,-10.03344,-5.61192
60.30000,-10.05024,-5.61269
60.40000,-10.06691,-5.61399
60.50000,-10.08358,-5.61604
60.60000,-10.09984,-5.61811
60.70000,-10.11691,-5.62099
60.80000,-10.13331,-5.62269
60.90000,-10.15011,-5.62557
61.00000,-10.16691,-5.62819
61.10000,-10.18358,-5.63351
61.20000,-10.20037,-5.63572
61.30000,-10.21678,-5.63741
61.40000,-10.23344,-5.63812
61.50000,-10.25011,-5.64163
61.60000,-10.26691,-5.64442
61.70000,-10.28331,-5.64746
61.80000,-10.30024,-5.65298
61.90000,-10.31691,-5.65613
62.00000,-10.33331,-5.66067
62.10000,-10.35024,-5.66507
62.20000,-10.36664,-5.66842
62.30000,-10.38344,-5.67380
62.40000,-10.40024,-5.67831
62.50000,-10.41704,-5.68274
62.60000,-10.43357,-5.68592
62.70000,-10.45024,-5.69122
62.80000,-10.46691,-5.69378
62.90000,-10.48331,-5.69769
63.00000,-10.50024,-5.70184
63.10000,-10.51677,-5.70471
63.20000,-10.53344,-5.70969
63.30000,-10.55037,-5.71218
63.40000,-10.56691,-5.71692
63.50000,-10.58371,-5.71981
63.60000,-10.60024,-5.72361
63.70000,-10.61691,-5.72711
63.80000,-10.63317,-5.73055
63.90000,-10.65037,-5.73625
64.00000,-10.66677,-5.73914
64.10001,-10.68357,-5.74314
64.20000,-10.70024,-5.74695
64.30000,-10.71677,-5.75020
64.40000,-10.73357,-5.75507
64.50000,-10.74997,-5.75928
64.60001,-10.76677,-5.76457
64.70000,-10.78344,-5.77110
64.80000,-10.80024,-5.77595
64.90000,-10.81677,-5.78122
65.00000,-10.83357,-5.78629
65.10001,-10.85024,-5.79046
65.20000,-10.86664,-5.79503
65.30000,-10.88357,-5.80074
65.40000,-10.89997,-5.80577
65.50000,-10.91691,-5.81108
65.60001,-10.93344,-5.81510
65.70001,-10.95024,-5.82221
65.80000,-10.96664,-5.82392
65.90000,-10.98344,-5.83196
66.00000,-11.00024,-5.83832
66.10001,-11.01651,-5.84470
66.20001,-11.03344,-5.85216
66.30000,-11.04997,-5.85778
66.40000,-11.06691,-5.86413
66.50000,-11.08371,-5.86699
66.60001,-11.10024,-5.87117
66.70001,-11.11691,-5.87661
66.80000,-11.13371,-5.88299
66.90000,-11.15037,-5.88690
67.00000,-11.16677,-5.89223
67.10001,-11.18371,-5.89887
67.20001,-11.20024,-5.90429
67.30000,-11.21704,-5.91278
67.40000,-11.23371,-5.91673
67.50000,-11.25024,-5.92217
67.60001,-11.26691,-5.92850
67.70001,-11.28331,-5.93231
67.80000,-11.29997,-5.93754
67.90000,-11.31677,-5.94506
68.00000,-11.33357,-5.95014
68.10001,-11.35024,-5.95548
68.20001,-11.36704,-5.96211
68.30000,-11.38371,-5.96605
68.40000,-11.40011,-5.97103
68.50000,-11.41677,-5.97596
68.60001,-11.43331,-5.97940
68.70001,-11.45024,-5.98738
68.80000,-11.46704,-5.99289
68.90000,-11.48357,-5.99955
69.00000,-11.50024,-6.00497
69.10001,-11.51704,-6.01070
69.20001,-11.53371,-6.01537
69.30000,-11.54997,-6.02115
69.40000,-11.56691,-6.02619
69.50000,-11.58344,-6.03011
69.60001,-11.60011,-6.03697
69.70001,-11.61704,-6.04134
69.80000,-11.63357,-6.04748
69.90000,-11.65037,-6.05301
70.00000,-11.66691,-6.05825
70.10001,-11.68384,-6.06238
70.20001,-11.69997,-6.06812
70.30000,-11.71691,-6.07160
70.40000,-11.73357,-6.07532
70.50000,-11.75024,-6.08160
70.60001,-11.76690,-6.08345
70.70001,-11.78344,-6.08874
70.80000,-11.80024,-6.09264
70.90000,-11.81664,-6.09696
71.00000,-11.83344,-6.10329
71.10001,-11.85010,-6.10692
71.20001,-11.86677,-6.11231
71.30000,-11.88344,-6.11751
71.40000,-11.90024,-6.12361
71.50000,-11.91704,-6.12887
71.60001,-11.93344,-6.13270
71.70001,-11.95024,-6.13748
71.80000,-11.96664,-6.14206
71.90000,-11.98357,-6.14755
72.00000,-12.00037,-6.15531
72.10001,-12.01690,-6.16026
72.20001,-12.03357,-6.16600
72.30000,-12.05037,-6.17433
72.40000,-12.06704,-6.17795
72.50000,-12.08330,-6.18500
72.60001,-12.10037,-6.19096
72.70001,-12.11677,-6.19563
72.80000,-12.13357,-6.20325
72.90000,-12.15037,-6.20956
73.00000,-12.16690,-6.21348
73.10001,-12.18370,-6.22157
73.20001,-12.20024,-6.22725
73.30000,-12.21690,-6.23266
73.40000,-12.23330,-6.23927
73.50000,-12.25024,-6.24545
73.60001,-12.26677,-6.25156
73.70001,-12.28344,-6.25812
73.80000,-12.30024,-6.26296
73.90000,-12.31677,-6.26849
74.00000,-12.33357,-6.27453
74.10001,-12.34997,-6.27934
74.20001,-12.36664,-6.28554
74.30000,-12.38344,-6.29206
74.40000,-12.40024,-6.29996
74.50000,-12.41690,-6.30660
74.60001,-12.43370,-6.31464
74.70001,-12.45037,-6.31976
74.80000,-12.46677,-6.32432
74.90000,-12.48357,-6.33073
75.00000,-12.49997,-6.33688
75.10001,-12.51690,-6.34476
75.20001,-12.53357,-6.35152
75.30000,-12.55024,-6.35692
75.40000,-12.56704,-6.36367
75.50000,-12.58370,-6.37041
75.60001,-12.60037,-6.37406
75.70001,-12.61664,-6.37984
75.80000,-12.63344,-6.38387
75.90000,-12.65010,-6.38994
76.00000,-12.66677,-6.39739
76.10001,-12.68384,-6.40367
76.20001,-12.70024,-6.40836
76.30000,-12.71690,-6.41400
76.40000,-12.73357,-6.41956
76.50000,-12.75024,-6.42427
76.60001,-12.76664,-6.42941
76.70001,-12.78357,-6.43730
76.80000,-12.80024,-6.44211
76.90000,-12.81690,-6.44870
77.00000,-12.83370,-6.45353
77.10001,-12.85024,-6.45768
77.20001,-12.86690,-6.46299
77.30000,-12.88330,-6.46673
77.40000,-12.89997,-6.47065
77.50000,-12.91677,-6.47715
77.60001,-12.93343,-6.48312
77.70001,-12.95010,-6.48818
77.80000,-12.96677,-6.49625
77.90000,-12.98357,-6.50162
78.00000,-13.00010,-6.50858
78.10001,-13.01690,-6.51535
78.20001,-13.03330,-6.51969
78.30000,-13.05010,-6.52673
78.40000,-13.06690,-6.53317
78.50000,-13.08370,-6.53917
78.60001,-13.10037,-6.54491
78.70001,-13.11690,-6.55184
78.80000,-13.13357,-6.55638
78.90000,-13.14997,-6.56316
79.00000,-13.16690,-6.56941
79.10001,-13.18343,-6.57400
79.20001,-13.20010,-6.58174
79.30000,-13.21703,-6.58692
79.40000,-13.23357,-6.59216
79.50000,-13.25037,-6.59924
79.60001,-13.26690,-6.60345
79.70001,-13.28357,-6.60790
79.80000,-13.29997,-6.61336
79.90000,-13.31690,-6.61934
80.00000,-13.33343,-6.62393
80.10001,-13.35023,-6.62996
80.20001,-13.36703,-6.63428
80.30000,-13.38343,-6.63982
80.40000,-13.40023,-6.64371
80.50001,-13.41663,-6.64872
80.60001,-13.43343,-6.65400
80.70001,-13.44997,-6.66028
80.80000,-13.46677,-6.66590
80.90000,-13.48343,-6.67040
81.00001,-13.50023,-6.67869
81.10001,-13.51703,-6.68400
81.20001,-13.53343,-6.69158
81.30000,-13.55023,-6.69801
81.40000,-13.56663,-6.70359
81.50001,-13.58357,-6.71186
81.60001,-13.60023,-6.71781
81.70001,-13.61690,-6.72494
81.80000,-13.63357,-6.73132
81.90000,-13.65037,-6.74065
82.00001,-13.66703,-6.74719
82.10001,-13.68343,-6.75421
82.20001,-13.70037,-6.76072
82.30000,-13.71690,-6.76605
82.40000,-13.73357,-6.77609
82.50001,-13.75037,-6.78403
82.60001,-13.76690,-6.79248
82.70001,-13.78370,-6.80197
82.80000,-13.80023,-6.80978
82.90000,-13.81690,-6.81744
83.00001,-13.83343,-6.82554
83.10001,-13.85023,-6.83353
83.20001,-13.86677,-6.84017
83.30000,-13.88357,-6.84975
83.40000,-13.90037,-6.85706
83.50001,-13.91677,-6.86583
83.60001,-13.93357,-6.87409
83.70001,-13.94997,-6.88147
83.80000,-13.96650,-6.88982
83.90000,-13.98330,-6.89884
84.00001,-14.00023,-6.90787
84.10001,-14.01663,-6.91566
84.20001,-14.03343,-6.92655
84.30000,-14.05037,-6.93518
84.40000,-14.06677,-6.94489
84.50001,-14.08370,-6.95486
84.60001,-14.09997,-6.96152
84.70001,-14.11677,-6.97199
84.80000,-14.13357,-6.98055
84.90000,-14.15037,-6.98970
85.00001,-14.16703,-6.99869
85.10001,-14.18370,-7.00839
85.20001,-14.20037,-7.01366
85.30000,-14.21663,-7.02203
85.40000,-14.23343,-7.02937
85.50001,-14.25023,-7.03900
85.60001,-14.26676,-7.04998
85.70001,-14.28356,-7.05801
85.80000,-14.30023,-7.06819
85.90000,-14.31703,-7.07708
86.00001,-14.33356,-7.08626
86.10001,-14.35023,-7.09455
86.20001,-14.36663,-7.10386
86.30000,-14.38356,-7.11253
86.40000,-14.40010,-7.12079
86.50001,-14.41690,-7.13076
86.60001,-14.43370,-7.13773
86.70001,-14.45010,-7.14657
86.80000,-14.46690,-7.15390
86.90000,-14.48330,-7.16186
87.00001,-14.50010,-7.16811
87.10001,-14.51676,-7.17706
87.20001,-14.53356,-7.18465
87.30000,-14.55023,-7.19011
87.40000,-14.56690,-7.20019
87.50001,-14.58370,-7.20523
87.60001,-14.60010,-7.21255
87.70001,-14.61690,-7.22012
87.80000,-14.63316,-7.22542
87.90000,-14.65010,-7.23671
88.00001,-14.66690,-7.24419
88.10001,-14.68356,-7.25204
88.20001,-14.70023,-7.26023
88.30000,-14.71703,-7.26675
88.40000,-14.73370,-7.27276
88.50001,-14.75010,-7.27973
88.60001,-14.76690,-7.28795
88.70001,-14.78343,-7.29529
88.80000,-14.80010,-7.30474
88.90000,-14.81716,-7.31206
89.00001,-14.83356,-7.31836
89.10001,-14.85036,-7.32551
89.20001,-14.86690,-7.33295
89.30000,-14.88343,-7.33859
89.40000,-14.89996,-7.34677
89.50001,-14.91690,-7.35439
89.60001,-14.93343,-7.36067
89.70001,-14.95010,-7.36994
89.80000,-14.96690,-7.37659
89.90000,-14.98356,-7.38699
90.00001,-15.00036,-7.39377
90.04201,-15.00716,-7.39556