File: GFBaking/data/3TspPectin/1TspPectin_4PointBend.is_flex_RawData/Specimen_RawData_4.csv
Time,Extension,Load
(sec),(mm),(N)
0.00000,0.00000,0.00008
0.05000,-0.00107,0.00000
0.10000,-0.00840,0.00000
0.15000,-0.01880,0.00000
0.20000,-0.02893,-0.00001
0.25000,-0.03840,-0.00002
0.30000,-0.04773,0.00002
0.35000,-0.05667,0.00001
0.40000,-0.06533,0.00003
0.45000,-0.07427,0.00000
0.50000,-0.08280,0.00002
0.55000,-0.09107,-0.00001
0.60000,-0.09973,0.00001
0.65000,-0.10840,0.00001
0.70000,-0.11653,0.00002
0.75000,-0.12480,0.00001
0.80000,-0.13347,0.00003
0.85000,-0.14173,0.00003
0.90000,-0.15000,0.00004
0.95000,-0.15840,0.00002
1.00000,-0.16667,0.00004
1.05000,-0.17480,-0.00001
1.10000,-0.18320,0.00002
1.15000,-0.19160,0.00002
1.20000,-0.20000,0.00005
1.25000,-0.20827,0.00004
1.30000,-0.21653,0.00002
1.35000,-0.22520,0.00001
1.40000,-0.23360,0.00004
1.45000,-0.24160,0.00001
1.50000,-0.25013,0.00002
1.55000,-0.25867,-0.00001
1.60000,-0.26667,0.00002
1.65000,-0.27493,0.00001
1.70000,-0.28360,0.00004
1.75000,-0.29160,0.00002
1.80000,-0.30000,0.00003
1.85000,-0.30840,0.00003
1.90000,-0.31653,0.00006
1.95000,-0.32480,-0.00001
2.00000,-0.33333,0.00002
2.05000,-0.34160,0.00000
2.10000,-0.35013,0.00004
2.15000,-0.35853,0.00002
2.20000,-0.36667,0.00004
2.25000,-0.37520,0.00003
2.30000,-0.38360,0.00004
2.35000,-0.39173,-0.00001
2.40000,-0.40013,0.00004
2.45000,-0.40853,0.00001
2.50000,-0.41653,0.00004
2.55000,-0.42493,0.00001
2.60000,-0.43360,0.00004
2.65000,-0.44160,0.00002
2.70000,-0.44987,0.00002
2.75000,-0.45840,0.00000
2.80000,-0.46667,0.00004
2.85000,-0.47493,0.00004
2.90000,-0.48333,0.00005
2.95000,-0.49173,0.00004
3.00000,-0.50013,0.00004
3.05000,-0.50853,0.00001
3.10000,-0.51680,0.00003
3.15000,-0.52533,0.00001
3.20000,-0.53373,0.00004
3.25000,-0.54173,0.00001
3.30000,-0.55027,0.00005
3.35000,-0.55853,0.00002
3.40000,-0.56667,0.00005
3.45000,-0.57493,0.00001
3.50000,-0.58347,0.00005
3.55000,-0.59160,0.00001
3.60000,-0.59987,0.00002
3.65000,-0.60867,0.00004
3.70000,-0.61680,0.00004
3.75000,-0.62493,0.00003
3.80000,-0.63347,0.00005
3.85000,-0.64200,0.00002
3.90000,-0.65013,0.00005
3.95000,-0.65853,0.00003
4.00000,-0.66707,0.00004
4.05000,-0.67520,0.00000
4.10000,-0.68333,0.00006
4.15000,-0.69173,0.00004
4.20000,-0.70013,0.00005
4.25000,-0.70826,0.00005
4.30000,-0.71653,0.00005
4.35000,-0.72493,0.00001
4.40000,-0.73333,0.00006
4.45000,-0.74173,0.00004
4.50000,-0.74986,0.00004
4.55000,-0.75853,0.00002
4.60000,-0.76693,0.00003
4.65000,-0.77506,0.00005
4.70000,-0.78360,0.00006
4.75000,-0.79200,0.00002
4.80000,-0.79986,0.00004
4.85000,-0.80826,0.00002
4.90000,-0.81680,0.00006
4.95000,-0.82506,0.00004
5.00000,-0.83333,0.00005
5.05000,-0.84173,0.00003
5.10000,-0.85000,0.00006
5.15000,-0.85826,0.00002
5.20000,-0.86653,0.00005
5.25000,-0.87493,0.00004
5.30000,-0.88346,0.00006
5.35000,-0.89173,0.00003
5.40000,-0.90000,0.00006
5.45000,-0.90853,0.00003
5.50000,-0.91693,0.00005
5.55000,-0.92506,0.00002
5.60000,-0.93346,0.00006
5.65000,-0.94200,0.00004
5.70000,-0.94986,0.00005
5.75000,-0.95826,0.00003
5.80000,-0.96680,0.00007
5.85000,-0.97493,0.00008
5.90000,-0.98306,0.00005
5.95000,-0.99173,0.00003
6.00000,-1.00000,0.00008
6.05000,-1.00826,0.00004
6.10000,-1.01680,0.00007
6.15000,-1.02520,0.00004
6.20000,-1.03360,0.00005
6.25000,-1.04186,0.00006
6.30000,-1.05026,0.00005
6.35000,-1.05866,0.00005
6.40000,-1.06693,0.00007
6.45000,-1.07506,0.00004
6.50000,-1.08346,0.00008
6.55000,-1.09186,0.00005
6.60000,-1.10000,0.00009
6.65000,-1.10840,0.00005
6.70000,-1.11680,0.00010
6.75000,-1.12506,0.00008
6.80000,-1.13333,0.00009
6.85000,-1.14186,0.00006
6.90000,-1.15013,0.00008
6.95000,-1.15826,0.00008
7.00000,-1.16680,0.00010
7.05000,-1.17533,0.00003
7.10000,-1.18360,0.00008
7.15000,-1.19186,0.00006
7.20000,-1.20040,0.00009
7.25000,-1.20853,0.00007
7.30000,-1.21680,0.00009
7.35000,-1.22506,0.00009
7.40000,-1.23346,0.00011
7.45000,-1.24173,0.00010
7.50000,-1.25000,0.00010
7.55000,-1.25826,0.00006
7.60000,-1.26680,0.00010
7.65000,-1.27506,0.00011
7.70000,-1.28333,0.00011
7.75000,-1.29186,0.00010
7.80000,-1.30026,0.00008
7.85000,-1.30840,0.00009
7.90000,-1.31680,0.00010
7.95000,-1.32533,0.00009
8.00000,-1.33333,0.00011
8.05000,-1.34160,0.00008
8.10000,-1.35026,0.00010
8.15000,-1.35826,0.00009
8.20000,-1.36653,0.00011
8.25000,-1.37493,0.00009
8.30000,-1.38320,0.00012
8.35000,-1.39146,0.00008
8.40000,-1.40000,0.00008
8.45000,-1.40840,0.00011
8.50000,-1.41680,0.00013
8.55000,-1.42520,0.00009
8.60000,-1.43333,0.00012
8.65000,-1.44186,0.00013
8.70000,-1.45026,0.00011
8.75000,-1.45826,0.00011
8.80000,-1.46680,0.00012
8.85000,-1.47533,0.00011
8.90000,-1.48320,0.00016
8.95000,-1.49160,0.00007
9.00000,-1.50026,0.00014
9.05000,-1.50826,0.00009
9.10000,-1.51653,0.00011
9.15000,-1.52506,0.00011
9.20000,-1.53333,0.00014
9.25000,-1.54160,0.00013
9.30000,-1.55013,0.00014
9.35000,-1.55853,0.00009
9.40000,-1.56666,0.00014
9.45000,-1.57520,0.00014
9.50000,-1.58346,0.00015
9.55000,-1.59186,0.00010
9.60000,-1.60026,0.00014
9.65000,-1.60840,0.00011
9.70000,-1.61680,0.00016
9.75000,-1.62520,0.00013
9.80000,-1.63320,0.00016
9.85000,-1.64160,0.00013
9.90000,-1.65000,0.00016
9.95000,-1.65826,0.00014
10.00000,-1.66653,0.00014
10.05000,-1.67520,0.00011
10.10000,-1.68360,0.00015
10.15000,-1.69173,0.00014
10.20000,-1.70026,0.00015
10.25000,-1.70866,0.00011
10.30000,-1.71680,0.00015
10.35000,-1.72533,0.00013
10.40000,-1.73373,0.00015
10.45000,-1.74173,0.00014
10.50000,-1.75000,0.00017
10.55000,-1.75840,0.00012
10.60000,-1.76680,0.00016
10.65000,-1.77493,0.00015
10.70000,-1.78320,0.00017
10.75000,-1.79160,0.00014
10.80000,-1.80000,0.00017
10.85000,-1.80826,0.00016
10.90000,-1.81653,0.00015
10.95000,-1.82506,0.00014
11.00000,-1.83360,0.00017
11.05000,-1.84173,0.00012
11.10000,-1.85026,0.00018
11.15000,-1.85866,0.00013
11.20000,-1.86680,0.00016
11.25000,-1.87506,0.00016
11.30000,-1.88360,0.00017
11.35000,-1.89173,0.00015
11.40000,-1.90000,0.00017
11.45000,-1.90840,0.00016
11.50000,-1.91653,0.00018
11.55000,-1.92480,0.00015
11.60000,-1.93333,0.00016
11.65000,-1.94173,0.00015
11.70000,-1.95013,0.00018
11.75000,-1.95840,0.00017
11.80000,-1.96653,0.00018
11.85000,-1.97520,0.00015
11.90000,-1.98360,0.00015
11.95000,-1.99160,0.00014
12.00000,-2.00013,0.00018
12.05000,-2.00866,0.00014
12.10000,-2.01653,0.00017
12.15000,-2.02493,0.00015
12.20000,-2.03346,0.00018
12.25000,-2.04160,0.00016
12.30000,-2.04986,0.00015
12.35000,-2.05853,0.00015
12.40000,-2.06680,0.00018
12.45000,-2.07493,0.00015
12.50000,-2.08346,0.00017
12.55000,-2.09186,0.00012
12.60000,-2.10013,0.00019
12.65000,-2.10853,0.00017
12.70000,-2.11679,0.00017
12.75000,-2.12519,0.00014
12.80000,-2.13359,0.00016
12.85000,-2.14159,0.00013
12.90000,-2.15013,0.00018
12.95000,-2.15853,0.00015
13.00000,-2.16666,0.00019
13.05000,-2.17506,0.00014
13.10000,-2.18359,0.00016
13.15000,-2.19173,0.00014
13.20000,-2.19999,0.00018
13.25000,-2.20853,0.00018
13.30000,-2.21679,0.00014
13.35000,-2.22493,0.00015
13.40000,-2.23346,0.00015
13.45000,-2.24199,0.00014
13.50000,-2.25013,0.00017
13.55000,-2.25853,0.00014
13.60000,-2.26706,0.00014
13.65000,-2.27519,0.00013
13.70000,-2.28346,0.00016
13.75000,-2.29186,0.00016
13.80000,-2.30013,0.00016
13.85000,-2.30839,0.00014
13.90000,-2.31653,0.00017
13.95000,-2.32506,0.00013
14.00000,-2.33346,0.00018
14.05000,-2.34173,0.00013
14.10000,-2.34999,0.00015
14.15000,-2.35853,0.00014
14.20000,-2.36693,0.00015
14.25000,-2.37493,0.00014
14.30000,-2.38346,0.00016
14.35000,-2.39199,0.00013
14.40000,-2.39999,0.00014
14.45000,-2.40839,0.00014
14.50000,-2.41693,0.00016
14.55000,-2.42506,0.00011
14.60000,-2.43333,0.00018
14.65000,-2.44173,0.00014
14.70000,-2.44999,0.00015
14.75000,-2.45826,0.00012
14.80000,-2.46653,0.00013
14.85000,-2.47479,0.00012
14.90000,-2.48333,0.00013
14.95000,-2.49173,0.00013
15.00000,-2.49999,0.00015
15.05000,-2.50866,0.00010
15.10000,-2.51706,0.00012
15.15000,-2.52506,0.00012
15.20000,-2.53346,0.00015
15.25000,-2.54199,0.00010
15.30000,-2.54999,0.00014
15.35000,-2.55826,0.00012
15.40000,-2.56693,0.00013
15.45000,-2.57493,0.00011
15.50000,-2.58319,0.00011
15.55000,-2.59173,0.00011
15.60000,-2.60013,0.00013
15.65000,-2.60839,0.00012
15.70000,-2.61679,0.00014
15.75000,-2.62519,0.00012
15.80000,-2.63346,0.00012
15.85000,-2.64186,0.00012
15.90000,-2.65013,0.00012
15.95000,-2.65866,0.00009
16.00000,-2.66693,0.00012
16.05000,-2.67506,0.00008
16.10000,-2.68346,0.00014
16.15000,-2.69186,0.00011
16.20000,-2.69986,0.00013
16.25000,-2.70826,0.00010
16.30000,-2.71679,0.00013
16.35000,-2.72493,0.00013
16.40000,-2.73333,0.00011
16.45000,-2.74199,0.00011
16.50000,-2.75026,0.00012
16.55000,-2.75839,0.00010
16.60000,-2.76679,0.00012
16.65000,-2.77533,0.00011
16.70000,-2.78346,0.00013
16.75000,-2.79186,0.00011
16.80000,-2.80026,0.00013
16.85000,-2.80853,0.00009
16.90000,-2.81679,0.00012
16.95000,-2.82506,0.00011
17.00000,-2.83346,0.00012
17.05000,-2.84186,0.00008
17.10000,-2.84999,0.00011
17.15000,-2.85826,0.00009
17.20000,-2.86679,0.00013
17.25000,-2.87506,0.00012
17.30000,-2.88333,0.00012
17.35000,-2.89186,0.00011
17.40000,-2.90026,0.00009
17.45000,-2.90839,0.00010
17.50000,-2.91693,0.00012
17.55000,-2.92546,0.00008
17.60000,-2.93346,0.00011
17.65000,-2.94173,0.00011
17.70000,-2.95026,0.00012
17.75000,-2.95839,0.00011
17.80000,-2.96653,0.00011
17.85000,-2.97506,0.00010
17.90000,-2.98333,0.00011
17.95000,-2.99159,0.00008
18.00000,-2.99999,0.00010
18.05000,-3.00839,0.00008
18.10000,-3.01679,0.00013
18.15000,-3.02506,0.00010
18.20000,-3.03333,0.00012
18.25000,-3.04186,0.00012
18.30000,-3.05013,0.00009
18.35000,-3.05826,0.00011
18.40000,-3.06679,0.00011
18.45000,-3.07519,0.00009
18.50000,-3.08319,0.00011
18.55000,-3.09159,0.00009
18.60000,-3.10026,0.00014
18.65000,-3.10826,0.00010
18.70000,-3.11653,0.00013
18.75000,-3.12506,0.00010
18.80000,-3.13333,0.00013
18.85000,-3.14159,0.00011
18.90000,-3.14999,0.00010
18.95000,-3.15853,0.00011
19.00000,-3.16679,0.00010
19.05000,-3.17519,0.00009
19.10000,-3.18359,0.00011
19.15000,-3.19199,0.00010
19.20000,-3.20026,0.00010
19.25000,-3.20839,0.00009
19.30000,-3.21679,0.00015
19.35000,-3.22519,0.00009
19.40000,-3.23333,0.00012
19.45000,-3.24159,0.00010
19.50000,-3.25013,0.00012
19.55000,-3.25826,0.00010
19.60000,-3.26653,0.00011
19.65000,-3.27519,0.00012
19.70000,-3.28359,0.00010
19.75000,-3.29173,0.00013
19.80000,-3.30013,0.00013
19.85000,-3.30866,0.00009
19.90000,-3.31679,0.00013
19.95000,-3.32506,0.00012
20.00000,-3.33359,0.00012
20.05000,-3.34186,0.00009
20.10000,-3.35013,0.00014
20.15000,-3.35826,0.00012
20.20000,-3.36679,0.00014
20.25000,-3.37506,0.00012
20.30000,-3.38319,0.00014
20.35000,-3.39159,0.00011
20.40000,-3.40013,0.00012
20.45000,-3.40839,0.00012
20.50000,-3.41666,0.00013
20.55000,-3.42533,0.00010
20.60000,-3.43372,0.00012
20.65000,-3.44172,0.00010
20.70000,-3.45012,0.00014
20.75000,-3.45879,0.00009
20.80000,-3.46666,0.00014
20.85000,-3.47506,0.00010
20.90000,-3.48359,0.00014
20.95000,-3.49172,0.00011
21.00000,-3.49986,0.00013
21.05000,-3.50839,0.00009
21.10000,-3.51652,0.00013
21.15000,-3.52492,0.00011
21.20000,-3.53332,0.00011
21.25000,-3.54172,0.00012
21.30000,-3.55012,0.00012
21.35000,-3.55852,0.00009
21.40000,-3.56652,0.00011
21.45000,-3.57519,0.00009
21.50000,-3.58359,0.00011
21.55000,-3.59159,0.00008
21.60000,-3.60012,0.00011
21.65000,-3.60866,0.00010
21.70000,-3.61652,0.00010
21.75000,-3.62479,0.00008
21.80000,-3.63332,0.00010
21.85000,-3.64146,0.00009
21.90000,-3.64972,0.00009
21.95000,-3.65826,0.00005
22.00000,-3.66666,0.00009
22.05000,-3.67492,0.00005
22.10000,-3.68332,0.00011
22.15000,-3.69186,0.00011
22.20000,-3.70012,0.00013
22.25000,-3.70852,0.00007
22.30000,-3.71679,0.00007
22.35000,-3.72519,0.00006
22.40000,-3.73359,0.00006
22.45000,-3.74172,0.00011
22.50000,-3.75012,0.00014
22.55000,-3.75852,0.00006
22.60000,-3.76666,0.00008
22.65000,-3.77492,0.00002
22.70000,-3.78332,0.00011
22.75000,-3.79146,0.00008
22.80000,-3.79972,0.00010
22.85000,-3.80839,0.00003
22.90000,-3.81679,0.00008
22.95000,-3.82506,0.00006
23.00000,-3.83359,0.00008
23.05000,-3.84212,0.00007
23.10000,-3.85026,0.00007
23.15000,-3.85866,0.00006
23.20000,-3.86692,0.00005
23.25000,-3.87519,0.00006
23.30000,-3.88346,0.00009
23.35000,-3.89172,0.00007
23.40000,-3.90012,0.00006
23.45000,-3.90839,0.00004
23.50000,-3.91679,0.00008
23.55000,-3.92492,0.00005
23.60000,-3.93359,0.00008
23.65000,-3.94186,0.00005
23.70000,-3.94999,0.00006
23.75000,-3.95852,0.00006
23.80000,-3.96692,0.00004
23.85000,-3.97506,0.00003
23.90000,-3.98346,0.00007
23.95000,-3.99199,0.00003
24.00000,-3.99999,0.00006
24.05000,-4.00826,0.00002
24.10000,-4.01679,0.00006
24.15000,-4.02506,0.00006
24.20000,-4.03319,0.00005
24.25000,-4.04159,0.00002
24.30000,-4.04986,0.00004
24.35000,-4.05826,0.00001
24.40000,-4.06666,0.00003
24.45000,-4.07492,0.00004
24.50000,-4.08346,0.00006
24.55000,-4.09186,0.00003
24.60000,-4.09999,0.00005
24.65000,-4.10852,0.00005
24.70000,-4.11692,0.00005
24.75000,-4.12492,0.00004
24.80000,-4.13332,0.00005
24.85000,-4.14199,0.00003
24.90000,-4.14999,0.00005
24.95000,-4.15826,0.00004
25.00000,-4.16679,0.00004
25.05000,-4.17492,0.00001
25.10000,-4.18306,0.00004
25.15000,-4.19172,0.00002
25.20000,-4.20012,0.00004
25.25000,-4.20826,0.00004
25.30000,-4.21679,0.00005
25.35000,-4.22519,0.00003
25.40000,-4.23346,0.00003
25.45000,-4.24172,0.00003
25.50000,-4.24999,0.00006
25.55000,-4.25866,0.00000
25.60000,-4.26692,0.00003
25.65000,-4.27506,0.00002
25.70000,-4.28346,0.00006
25.75000,-4.29199,0.00002
25.80000,-4.29986,0.00004
25.85000,-4.30826,0.00002
25.90000,-4.31692,0.00005
25.95000,-4.32506,0.00002
26.00000,-4.33332,0.00005
26.05000,-4.34199,0.00001
26.10000,-4.35026,0.00003
26.15000,-4.35839,0.00003
26.20000,-4.36692,0.00005
26.25000,-4.37546,0.00001
26.30000,-4.38346,0.00002
26.35000,-4.39186,0.00003
26.40000,-4.40026,0.00005
26.45000,-4.40852,0.00000
26.50000,-4.41679,0.00005
26.55000,-4.42506,0.00000
26.60000,-4.43359,0.00005
26.65000,-4.44172,0.00005
26.70000,-4.44999,0.00005
26.75000,-4.45812,0.00002
26.80000,-4.46666,0.00004
26.85000,-4.47492,0.00003
26.90000,-4.48319,0.00002
26.95000,-4.49186,0.00003
27.00000,-4.50039,0.00002
27.05000,-4.50839,0.00000
27.10000,-4.51679,0.00005
27.15000,-4.52532,0.00002
27.20000,-4.53332,0.00003
27.25000,-4.54159,0.00003
27.30000,-4.55012,0.00005
27.35000,-4.55826,0.00003
27.40000,-4.56652,0.00002
27.45000,-4.57506,-0.00001
27.50000,-4.58332,0.00004
27.55000,-4.59159,0.00000
27.60000,-4.60012,0.00005
27.65000,-4.60826,0.00003
27.70000,-4.61679,0.00005
27.75000,-4.62506,0.00006
27.80000,-4.63319,0.00003
27.85000,-4.64186,0.00001
27.90000,-4.65026,0.00002
27.95000,-4.65826,0.00003
28.00000,-4.66679,0.00006
28.05000,-4.67519,0.00001
28.10000,-4.68319,0.00005
28.15000,-4.69159,0.00001
28.20000,-4.70026,0.00005
28.25000,-4.70826,0.00002
28.30000,-4.71639,0.00004
28.35000,-4.72506,0.00000
28.40000,-4.73332,0.00003
28.45000,-4.74159,0.00001
28.50000,-4.75012,0.00006
28.55000,-4.75852,0.00002
28.60000,-4.76692,0.00004
28.65000,-4.77519,0.00001
28.70000,-4.78346,0.00004
28.75000,-4.79185,0.00002
28.80000,-4.80025,0.00001
28.85000,-4.80839,0.00002
28.90000,-4.81692,0.00006
28.95000,-4.82519,0.00001
29.00000,-4.83332,0.00004
29.05000,-4.84159,0.00001
29.10000,-4.85012,0.00005
29.15000,-4.85825,0.00005
29.20000,-4.86652,0.00003
29.25000,-4.87519,0.00005
29.30000,-4.88359,0.00005
29.35000,-4.89172,0.00004
29.40000,-4.90025,0.00004
29.45000,-4.90879,0.00001
29.50000,-4.91679,0.00003
29.55000,-4.92519,0.00002
29.60000,-4.93359,0.00004
29.65000,-4.94185,0.00004
29.70000,-4.94999,0.00005
29.75000,-4.95825,0.00005
29.80000,-4.96665,0.00004
29.85000,-4.97505,0.00004
29.90000,-4.98319,0.00007
29.95000,-4.99159,0.00003
30.00000,-5.00012,0.00005
30.05000,-5.00839,0.00001
30.10000,-5.01665,0.00003
30.15000,-5.02519,0.00005
30.20000,-5.03359,0.00004
30.25000,-5.04172,0.00005
30.30000,-5.04999,0.00006
30.35000,-5.05865,0.00004
30.40000,-5.06665,0.00005
30.45000,-5.07492,0.00017
30.50000,-5.08345,0.00008
30.55000,-5.09172,0.00009
30.60000,-5.09999,0.00012
30.65000,-5.10839,0.00005
30.70000,-5.11652,0.00013
30.75000,-5.12479,0.00005
30.80000,-5.13319,0.00006
30.85000,-5.14145,0.00007
30.90000,-5.15012,0.00007
30.95000,-5.15852,0.00005
31.00000,-5.16665,0.00010
31.05000,-5.17519,0.00003
31.10000,-5.18359,0.00006
31.15000,-5.19172,0.00005
31.20000,-5.19999,0.00007
31.25000,-5.20865,0.00007
31.30000,-5.21665,0.00008
31.35000,-5.22492,0.00006
31.40000,-5.23345,0.00009
31.45000,-5.24159,0.00004
31.50000,-5.24985,0.00008
31.55000,-5.25839,0.00005
31.60000,-5.26679,0.00006
31.65000,-5.27492,0.00007
31.70000,-5.28345,0.00007
31.75000,-5.29185,0.00005
31.80000,-5.30012,0.00008
31.85000,-5.30852,0.00004
31.90000,-5.31679,0.00007
31.95000,-5.32532,0.00005
32.00000,-5.33359,0.00005
32.05000,-5.34172,0.00002
32.10000,-5.35012,0.00009
32.15000,-5.35865,0.00004
32.20000,-5.36665,0.00005
32.25000,-5.37492,0.00005
32.30000,-5.38345,0.00006
32.35000,-5.39172,0.00006
32.40000,-5.39999,0.00005
32.45000,-5.40852,0.00004
32.50000,-5.41692,0.00005
32.55000,-5.42519,0.00002
32.60000,-5.43372,0.00005
32.65000,-5.44199,0.00003
32.70000,-5.45012,0.00006
32.75000,-5.45852,0.00006
32.80000,-5.46692,0.00005
32.85000,-5.47519,0.00005
32.90000,-5.48345,0.00006
32.95000,-5.49172,0.00005
33.00000,-5.50012,0.00007
33.05000,-5.50825,0.00002
33.10000,-5.51652,0.00005
33.15000,-5.52492,0.00002
33.20000,-5.53345,0.00005
33.25000,-5.54172,0.00005
33.30000,-5.54999,0.00006
33.35000,-5.55852,0.00006
33.40000,-5.56692,0.00005
33.45000,-5.57492,0.00004
33.50000,-5.58345,0.00006
33.55000,-5.59199,0.00002
33.60000,-5.59999,0.00006
33.65000,-5.60839,0.00004
33.70000,-5.61692,0.00007
33.75000,-5.62505,0.00005
33.80000,-5.63319,0.00007
33.85000,-5.64172,0.00004
33.90000,-5.64999,0.00005
33.95000,-5.65825,0.00005
34.00000,-5.66665,0.00007
34.05000,-5.67505,0.00004
34.10000,-5.68345,0.00006
34.15000,-5.69185,0.00006
34.20000,-5.69999,0.00006
34.25000,-5.70852,0.00005
34.30000,-5.71679,0.00005
34.35000,-5.72492,0.00005
34.40000,-5.73332,0.00008
34.45000,-5.74199,0.00004
34.50000,-5.74999,0.00006
34.55000,-5.75825,0.00003
34.60000,-5.76692,0.00007
34.65000,-5.77492,0.00004
34.70000,-5.78305,0.00004
34.75000,-5.79159,0.00002
34.80000,-5.79985,0.00007
34.85000,-5.80799,0.00002
34.90000,-5.81665,0.00003
34.95000,-5.82519,0.00005
35.00000,-5.83359,0.00005
35.05000,-5.84199,0.00002
35.10000,-5.85012,0.00005
35.15000,-5.85852,0.00003
35.20000,-5.86692,0.00004
35.25000,-5.87505,0.00003
35.30000,-5.88345,0.00008
35.35000,-5.89185,0.00007
35.40000,-5.89985,0.00006
35.45000,-5.90825,0.00002
35.50000,-5.91679,0.00006
35.55000,-5.92505,0.00003
35.60000,-5.93332,0.00006
35.65000,-5.94185,0.00006
35.70000,-5.95025,0.00005
35.75000,-5.95839,0.00006
35.80000,-5.96692,0.00006
35.85000,-5.97532,0.00002
35.90000,-5.98345,0.00004
35.95000,-5.99185,0.00005
36.00000,-6.00025,0.00006
36.05000,-6.00852,0.00003
36.10000,-6.01679,0.00005
36.15000,-6.02505,0.00007
36.20000,-6.03345,0.00007
36.25000,-6.04172,0.00006
36.30000,-6.04999,0.00007
36.35000,-6.05825,0.00004
36.40000,-6.06679,0.00008
36.45000,-6.07505,0.00004
36.50000,-6.08332,0.00006
36.55000,-6.09185,0.00003
36.60000,-6.10038,0.00005
36.65000,-6.10839,0.00006
36.70000,-6.11679,0.00007
36.75000,-6.12545,0.00002
36.80000,-6.13332,0.00004
36.85000,-6.14172,0.00006
36.90000,-6.15012,0.00009
36.95000,-6.15825,0.00005
37.00000,-6.16652,0.00007
37.05000,-6.17505,0.00002
37.10000,-6.18332,0.00007
37.15000,-6.19158,0.00003
37.20000,-6.19998,0.00007
37.25000,-6.20825,0.00006
37.30000,-6.21678,0.00007
37.35000,-6.22519,0.00005
37.40000,-6.23332,0.00006
37.45000,-6.24185,0.00004
37.50000,-6.25025,0.00006
37.55000,-6.25825,0.00003
37.60000,-6.26678,0.00007
37.65000,-6.27532,0.00003
37.70000,-6.28318,0.00007
37.75000,-6.29158,0.00004
37.80000,-6.30012,0.00007
37.85000,-6.30825,0.00006
37.90000,-6.31638,0.00005
37.95000,-6.32505,0.00004
38.00000,-6.33345,0.00006
38.05000,-6.34158,0.00003
38.10000,-6.35012,0.00006
38.15000,-6.35852,0.00004
38.20000,-6.36678,0.00006
38.25000,-6.37505,0.00006
38.30000,-6.38345,0.00006
38.35000,-6.39172,0.00005
38.40000,-6.40012,0.00006
38.45000,-6.40825,0.00005
38.50000,-6.41678,0.00006
38.55000,-6.42518,0.00002
38.60000,-6.43318,0.00008
38.65000,-6.44158,0.00003
38.70000,-6.44998,0.00007
38.75000,-6.45812,0.00006
38.80000,-6.46638,0.00006
38.85000,-6.47518,0.00005
38.90000,-6.48358,0.00006
38.95000,-6.49172,0.00004
39.00000,-6.50025,0.00008
39.05000,-6.50865,0.00002
39.10000,-6.51678,0.00008
39.15000,-6.52518,0.00006
39.20000,-6.53358,0.00003
39.25000,-6.54185,0.00002
39.30000,-6.55012,0.00005
39.35000,-6.55838,0.00006
39.40000,-6.56678,0.00007
39.45000,-6.57518,0.00007
39.50000,-6.58332,0.00007
39.55000,-6.59172,0.00001
39.60000,-6.60025,0.00006
39.65000,-6.60852,0.00003
39.70000,-6.61665,0.00007
39.75000,-6.62532,0.00007
39.80000,-6.63358,0.00006
39.85000,-6.64172,0.00004
39.90000,-6.65012,0.00007
39.95000,-6.65865,0.00003
40.00000,-6.66665,0.00008
40.05000,-6.67505,0.00003
40.10000,-6.68358,0.00006
40.15000,-6.69158,0.00005
40.20000,-6.69985,0.00006
40.25000,-6.70825,0.00003
40.30000,-6.71652,0.00004
40.35000,-6.72492,0.00003
40.40000,-6.73332,0.00007
40.45000,-6.74158,0.00004
40.50000,-6.75012,0.00007
40.55000,-6.75852,0.00002
40.60000,-6.76665,0.00006
40.65000,-6.77518,0.00006
40.70000,-6.78358,0.00006
40.75000,-6.79172,0.00005
40.80000,-6.80012,0.00007
40.85000,-6.80865,0.00003
40.90000,-6.81665,0.00005
40.95000,-6.82492,0.00004
41.00000,-6.83358,0.00007
41.05000,-6.84158,0.00002
41.10000,-6.84985,0.00006
41.15000,-6.85838,0.00003
41.20000,-6.86665,0.00005
41.25000,-6.87492,0.00005
41.30000,-6.88345,0.00006
41.35000,-6.89185,0.00004
41.40000,-6.90012,0.00003
41.45000,-6.90852,0.00001
41.50000,-6.91678,0.00006
41.55000,-6.92518,0.00002
41.60000,-6.93358,0.00006
41.65000,-6.94172,0.00004
41.70000,-6.95012,0.00007
41.75000,-6.95838,0.00005
41.80000,-6.96665,0.00006
41.85000,-6.97492,0.00002
41.90000,-6.98345,0.00006
41.95000,-6.99158,0.00006
42.00000,-6.99998,0.00004
42.05000,-7.00865,0.00002
42.10000,-7.01692,0.00003
42.15000,-7.02505,0.00006
42.20000,-7.03345,0.00005
42.25000,-7.04198,0.00002
42.30000,-7.05012,0.00005
42.35000,-7.05852,0.00004
42.40000,-7.06692,0.00004
42.45000,-7.07505,0.00005
42.50000,-7.08332,0.00007
42.55000,-7.09172,0.00004
42.60000,-7.09998,0.00006
42.65000,-7.10838,0.00006
42.70000,-7.11652,0.00005
42.75000,-7.12478,0.00002
42.80000,-7.13332,0.00005
42.85000,-7.14172,0.00005
42.90000,-7.14998,0.00005
42.95000,-7.15865,0.00004
43.00000,-7.16705,0.00004
43.05000,-7.17505,0.00003
43.10000,-7.18345,0.00006
43.15000,-7.19212,0.00003
43.20000,-7.19998,0.00005
43.25000,-7.20825,0.00003
43.30000,-7.21678,0.00006
43.35000,-7.22492,0.00005
43.40000,-7.23318,0.00005
43.45000,-7.24158,0.00003
43.50000,-7.24985,0.00006
43.55000,-7.25812,0.00003
43.60000,-7.26652,0.00004
43.65000,-7.27492,0.00002
43.70000,-7.28345,0.00006
43.75000,-7.29172,0.00005
43.80000,-7.29998,0.00006
43.85000,-7.30865,0.00004
43.90000,-7.31692,0.00004
43.95000,-7.32505,0.00005
44.00000,-7.33345,0.00007
44.05000,-7.34198,0.00001
44.10000,-7.34985,0.00006
44.15000,-7.35825,0.00003
44.20000,-7.36692,0.00005
44.25000,-7.37492,0.00006
44.30000,-7.38318,0.00006
44.35000,-7.39172,0.00003
44.40000,-7.39998,0.00006
44.45000,-7.40825,0.00003
44.50000,-7.41678,0.00006
44.55000,-7.42518,0.00003
44.60000,-7.43345,0.00007
44.65000,-7.44185,0.00003
44.70000,-7.45011,0.00004
44.75000,-7.45865,0.00003
44.80000,-7.46692,0.00003
44.85000,-7.47505,0.00004
44.90000,-7.48345,0.00006
44.95000,-7.49185,0.00002
45.00000,-7.49998,0.00004
45.05000,-7.50825,0.00002
45.10000,-7.51678,0.00006
45.15000,-7.52492,0.00006
45.20000,-7.53318,0.00005
45.25000,-7.54198,0.00004
45.30000,-7.55025,0.00004
45.35000,-7.55838,0.00006
45.40000,-7.56691,0.00006
45.45000,-7.57545,0.00002
45.50000,-7.58345,0.00005
45.55000,-7.59185,0.00002
45.60000,-7.60025,0.00004
45.65000,-7.60851,0.00002
45.70000,-7.61678,0.00005
45.75000,-7.62518,0.00002
45.80000,-7.63345,0.00005
45.85000,-7.64185,0.00004
45.90000,-7.64998,0.00006
45.95000,-7.65825,0.00001
46.00000,-7.66678,0.00007
46.05000,-7.67518,0.00001
46.10000,-7.68331,0.00005
46.15000,-7.69185,0.00005
46.20000,-7.70038,0.00004
46.25000,-7.70838,0.00004
46.30000,-7.71691,0.00006
46.35000,-7.72545,0.00002
46.40000,-7.73331,0.00005
46.45000,-7.74171,0.00005
46.50000,-7.75025,0.00006
46.55000,-7.75825,0.00001
46.60000,-7.76651,0.00004
46.65000,-7.77491,0.00001
46.70000,-7.78318,0.00004
46.75000,-7.79145,0.00002
46.80000,-7.79985,0.00004
46.85000,-7.80838,0.00003
46.90000,-7.81691,0.00008
46.95000,-7.82518,0.00001
47.00000,-7.83331,0.00005
47.05000,-7.84185,0.00000
47.10000,-7.85025,0.00004
47.15000,-7.85838,0.00003
47.20000,-7.86678,0.00006
47.25000,-7.87531,0.00003
47.30000,-7.88331,0.00006
47.35000,-7.89158,0.00003
47.40000,-7.90011,0.00006
47.45000,-7.90811,0.00002
47.50000,-7.91638,0.00004
47.55000,-7.92491,0.00001
47.60000,-7.93331,0.00005
47.65000,-7.94158,0.00004
47.70000,-7.95011,0.00006
47.75000,-7.95851,0.00003
47.80000,-7.96678,0.00006
47.85000,-7.97518,0.00006
47.90000,-7.98345,0.00006
47.95000,-7.99198,0.00003
48.00000,-8.00025,0.00005
48.05000,-8.00838,0.00002
48.10000,-8.01678,0.00006
48.15000,-8.02518,0.00006
48.20000,-8.03318,0.00006
48.22000,-8.03651,0.00005