File: GFBaking/data/3TspPectin/1TspPectin_4PointBend.is_flex_RawData/Specimen_RawData_3.csv
Time,Extension,Load
(sec),(mm),(N)
0.00000,0.00000,0.00003
0.05000,-0.00120,-0.00002
0.10000,-0.00600,-0.00002
0.15000,-0.01520,0.00000
0.20000,-0.02573,-0.00002
0.25000,-0.03587,0.00001
0.30000,-0.04587,-0.00003
0.35000,-0.05547,0.00001
0.40000,-0.06427,-0.00002
0.45000,-0.07333,0.00001
0.50000,-0.08227,-0.00002
0.55000,-0.09067,-0.00001
0.60000,-0.09920,-0.00002
0.65000,-0.10787,0.00000
0.70000,-0.11613,-0.00001
0.75000,-0.12453,0.00000
0.80000,-0.13307,0.00000
0.85000,-0.14133,-0.00001
0.90000,-0.14973,0.00002
0.95000,-0.15813,-0.00001
1.00000,-0.16640,0.00000
1.05000,-0.17493,-0.00001
1.10000,-0.18320,0.00002
1.15000,-0.19160,0.00000
1.20000,-0.20013,0.00001
1.25000,-0.20840,0.00000
1.30000,-0.21653,0.00000
1.35000,-0.22507,0.00001
1.40000,-0.23347,0.00001
1.45000,-0.24147,0.00002
1.50000,-0.25000,-0.00002
1.55000,-0.25853,0.00009
1.60000,-0.26640,0.00002
1.65000,-0.27453,0.00003
1.70000,-0.28320,0.00004
1.75000,-0.29147,0.00002
1.80000,-0.29973,-0.00002
1.85000,-0.30840,0.00001
1.90000,-0.31680,0.00000
1.95000,-0.32493,0.00002
2.00000,-0.33347,0.00001
2.05000,-0.34173,0.00000
2.10000,-0.35013,-0.00001
2.15000,-0.35853,0.00000
2.20000,-0.36653,0.00000
2.25000,-0.37507,0.00002
2.30000,-0.38347,-0.00002
2.35000,-0.39160,0.00002
2.40000,-0.39987,0.00000
2.45000,-0.40840,0.00004
2.50000,-0.41640,-0.00001
2.55000,-0.42467,-0.00001
2.60000,-0.43347,0.00000
2.65000,-0.44173,0.00000
2.70000,-0.45000,0.00002
2.75000,-0.45853,0.00003
2.80000,-0.46680,-0.00002
2.85000,-0.47493,0.00002
2.90000,-0.48347,0.00002
2.95000,-0.49173,0.00002
3.00000,-0.50000,0.00001
3.05000,-0.50827,0.00000
3.10000,-0.51653,0.00001
3.15000,-0.52493,0.00002
3.20000,-0.53333,0.00001
3.25000,-0.54147,0.00005
3.30000,-0.54987,-0.00002
3.35000,-0.55840,0.00003
3.40000,-0.56653,0.00002
3.45000,-0.57493,0.00000
3.50000,-0.58347,0.00010
3.55000,-0.59173,0.00004
3.60000,-0.59987,0.00003
3.65000,-0.60840,0.00016
3.70000,-0.61680,0.00005
3.75000,-0.62493,0.00013
3.80000,-0.63320,0.00003
3.85000,-0.64173,0.00005
3.90000,-0.64987,-0.00001
3.95000,-0.65827,0.00002
4.00000,-0.66653,0.00001
4.05000,-0.67480,0.00001
4.10000,-0.68293,0.00007
4.15000,-0.69133,-0.00001
4.20000,-0.69986,0.00000
4.25000,-0.70840,0.00003
4.30000,-0.71666,0.00001
4.35000,-0.72493,0.00005
4.40000,-0.73360,-0.00001
4.45000,-0.74173,0.00000
4.50000,-0.74986,0.00002
4.55000,-0.75840,0.00000
4.60000,-0.76680,-0.00002
4.65000,-0.77480,0.00006
4.70000,-0.78320,-0.00002
4.75000,-0.79173,0.00001
4.80000,-0.79973,0.00000
4.85000,-0.80800,0.00001
4.90000,-0.81666,0.00001
4.95000,-0.82493,0.00003
5.00000,-0.83320,0.00000
5.05000,-0.84160,0.00000
5.10000,-0.85000,0.00002
5.15000,-0.85826,0.00004
5.20000,-0.86680,0.00003
5.25000,-0.87506,0.00002
5.30000,-0.88346,0.00000
5.35000,-0.89186,0.00002
5.40000,-0.89986,0.00001
5.45000,-0.90840,0.00005
5.50000,-0.91680,0.00005
5.55000,-0.92480,0.00001
5.60000,-0.93320,0.00000
5.65000,-0.94160,0.00003
5.70000,-0.94973,0.00002
5.75000,-0.95813,0.00002
5.80000,-0.96666,0.00001
5.85000,-0.97493,0.00009
5.90000,-0.98320,0.00002
5.95000,-0.99186,0.00002
6.00000,-1.00013,0.00000
6.05000,-1.00826,0.00001
6.10000,-1.01680,0.00010
6.15000,-1.02506,0.00003
6.20000,-1.03333,0.00006
6.25000,-1.04173,0.00002
6.30000,-1.05000,0.00003
6.35000,-1.05840,0.00004
6.40000,-1.06666,0.00003
6.45000,-1.07480,0.00003
6.50000,-1.08320,0.00001
6.55000,-1.09173,0.00002
6.60000,-1.09986,0.00002
6.65000,-1.10826,0.00004
6.70000,-1.11666,0.00003
6.75000,-1.12506,0.00003
6.80000,-1.13320,0.00004
6.85000,-1.14173,0.00004
6.90000,-1.15026,0.00002
6.95000,-1.15826,0.00003
7.00000,-1.16653,0.00003
7.05000,-1.17506,0.00004
7.10000,-1.18306,0.00003
7.15000,-1.19146,0.00004
7.20000,-1.19986,0.00001
7.25000,-1.20813,0.00000
7.30000,-1.21640,0.00000
7.35000,-1.22480,0.00003
7.40000,-1.23333,0.00001
7.45000,-1.24173,0.00006
7.50000,-1.25000,0.00002
7.55000,-1.25840,0.00002
7.60000,-1.26680,0.00003
7.65000,-1.27506,0.00000
7.70000,-1.28320,0.00002
7.75000,-1.29173,0.00004
7.80000,-1.30013,0.00003
7.85000,-1.30813,0.00004
7.90000,-1.31653,0.00000
7.95000,-1.32506,0.00005
8.00000,-1.33306,0.00002
8.05000,-1.34133,0.00003
8.10000,-1.34986,0.00000
8.15000,-1.35800,0.00005
8.20000,-1.36626,0.00002
8.25000,-1.37493,0.00005
8.30000,-1.38333,0.00007
8.35000,-1.39173,0.00002
8.40000,-1.40013,0.00001
8.45000,-1.40840,0.00002
8.50000,-1.41666,0.00007
8.55000,-1.42506,0.00007
8.60000,-1.43306,0.00003
8.65000,-1.44173,0.00003
8.70000,-1.45000,0.00003
8.75000,-1.45800,0.00004
8.80000,-1.46653,0.00003
8.85000,-1.47506,0.00005
8.90000,-1.48306,0.00002
8.95000,-1.49146,0.00001
9.00000,-1.50013,0.00004
9.05000,-1.50826,0.00003
9.10000,-1.51653,0.00005
9.15000,-1.52520,0.00003
9.20000,-1.53333,-0.00001
9.25000,-1.54160,0.00003
9.30000,-1.55013,0.00005
9.35000,-1.55840,0.00004
9.40000,-1.56666,0.00003
9.45000,-1.57506,0.00003
9.50000,-1.58320,0.00003
9.55000,-1.59173,0.00004
9.60000,-1.60000,0.00005
9.65000,-1.60813,0.00003
9.70000,-1.61653,-0.00001
9.75000,-1.62493,0.00004
9.80000,-1.63320,0.00003
9.85000,-1.64160,0.00004
9.90000,-1.65013,0.00004
9.95000,-1.65840,0.00005
10.00000,-1.66653,0.00003
10.05000,-1.67506,0.00001
10.10000,-1.68346,0.00004
10.15000,-1.69160,0.00004
10.20000,-1.69986,0.00006
10.25000,-1.70853,0.00004
10.30000,-1.71653,0.00002
10.35000,-1.72480,0.00005
10.40000,-1.73320,0.00003
10.45000,-1.74146,0.00004
10.50000,-1.74973,0.00000
10.55000,-1.75813,0.00003
10.60000,-1.76653,0.00003
10.65000,-1.77506,0.00004
10.70000,-1.78333,0.00004
10.75000,-1.79160,0.00004
10.80000,-1.80013,0.00002
10.85000,-1.80840,0.00004
10.90000,-1.81653,0.00003
10.95000,-1.82506,0.00005
11.00000,-1.83346,0.00003
11.05000,-1.84146,0.00003
11.10000,-1.84986,0.00000
11.15000,-1.85840,0.00006
11.20000,-1.86640,0.00004
11.25000,-1.87466,0.00002
11.30000,-1.88333,0.00002
11.35000,-1.89160,0.00004
11.40000,-1.89986,0.00003
11.45000,-1.90840,0.00005
11.50000,-1.91666,0.00004
11.55000,-1.92493,0.00002
11.60000,-1.93333,0.00004
11.65000,-1.94160,0.00005
11.70000,-1.95000,0.00004
11.75000,-1.95840,0.00006
11.80000,-1.96640,0.00003
11.85000,-1.97493,0.00003
11.90000,-1.98333,0.00004
11.95000,-1.99146,0.00002
12.00000,-1.99986,0.00000
12.05000,-2.00826,0.00003
12.10000,-2.01626,0.00002
12.15000,-2.02466,0.00002
12.20000,-2.03346,0.00002
12.25000,-2.04160,0.00003
12.30000,-2.04986,0.00005
12.35000,-2.05853,0.00006
12.40000,-2.06680,0.00002
12.45000,-2.07506,0.00005
12.50000,-2.08346,0.00002
12.55000,-2.09186,0.00002
12.60000,-2.09999,0.00003
12.65000,-2.10826,0.00007
12.70000,-2.11653,0.00003
12.75000,-2.12493,0.00005
12.80000,-2.13333,0.00003
12.85000,-2.14146,0.00005
12.90000,-2.14986,0.00002
12.95000,-2.15839,0.00003
13.00000,-2.16666,0.00002
13.05000,-2.17493,0.00001
13.10000,-2.18359,0.00002
13.15000,-2.19173,0.00003
13.20000,-2.19986,0.00002
13.25000,-2.20839,0.00004
13.30000,-2.21679,0.00000
13.35000,-2.22493,0.00003
13.40000,-2.23319,0.00004
13.45000,-2.24173,0.00004
13.50000,-2.24986,0.00002
13.55000,-2.25813,0.00000
13.60000,-2.26653,0.00003
13.65000,-2.27479,0.00003
13.70000,-2.28306,0.00001
13.75000,-2.29159,0.00004
13.80000,-2.29986,0.00000
13.85000,-2.30826,0.00004
13.90000,-2.31666,0.00004
13.95000,-2.32493,0.00004
14.00000,-2.33346,0.00003
14.05000,-2.34173,0.00002
14.10000,-2.34986,0.00002
14.15000,-2.35839,0.00005
14.20000,-2.36679,0.00001
14.25000,-2.37479,0.00006
14.30000,-2.38319,0.00002
14.35000,-2.39159,0.00004
14.40000,-2.39973,0.00000
14.45000,-2.40799,0.00002
14.50000,-2.41666,0.00001
14.55000,-2.42479,0.00001
14.60000,-2.43319,0.00002
14.65000,-2.44173,0.00004
14.70000,-2.44999,0.00002
14.75000,-2.45839,0.00004
14.80000,-2.46679,0.00001
14.85000,-2.47493,0.00004
14.90000,-2.48333,0.00003
14.95000,-2.49186,0.00004
15.00000,-2.49986,0.00003
15.05000,-2.50839,0.00003
15.10000,-2.51666,0.00003
15.15000,-2.52479,0.00004
15.20000,-2.53319,0.00001
15.25000,-2.54159,0.00002
15.30000,-2.54973,0.00004
15.35000,-2.55813,0.00004
15.40000,-2.56679,0.00002
15.45000,-2.57493,0.00003
15.50000,-2.58319,0.00002
15.55000,-2.59186,0.00001
15.60000,-2.60013,0.00002
15.65000,-2.60826,0.00004
15.70000,-2.61679,0.00002
15.75000,-2.62506,0.00003
15.80000,-2.63319,0.00003
15.85000,-2.64159,0.00004
15.90000,-2.64999,0.00003
15.95000,-2.65826,0.00003
16.00000,-2.66653,0.00003
16.05000,-2.67466,0.00002
16.10000,-2.68306,0.00003
16.15000,-2.69159,0.00002
16.20000,-2.69986,0.00002
16.25000,-2.70826,0.00003
16.30000,-2.71693,0.00004
16.35000,-2.72519,0.00003
16.40000,-2.73319,0.00002
16.45000,-2.74173,0.00002
16.50000,-2.75026,0.00001
16.55000,-2.75826,0.00001
16.60000,-2.76653,0.00001
16.65000,-2.77506,0.00004
16.70000,-2.78319,0.00003
16.75000,-2.79146,0.00000
16.80000,-2.79986,-0.00001
16.85000,-2.80813,0.00002
16.90000,-2.81626,0.00000
16.95000,-2.82479,0.00001
17.00000,-2.83319,0.00000
17.05000,-2.84173,0.00006
17.10000,-2.84999,0.00001
17.15000,-2.85826,0.00002
17.20000,-2.86679,0.00001
17.25000,-2.87506,0.00001
17.30000,-2.88319,0.00002
17.35000,-2.89186,0.00005
17.40000,-2.90013,0.00002
17.45000,-2.90813,0.00000
17.50000,-2.91653,0.00001
17.55000,-2.92506,0.00000
17.60000,-2.93306,0.00003
17.65000,-2.94133,0.00002
17.70000,-2.94999,0.00000
17.75000,-2.95813,0.00002
17.80000,-2.96653,-0.00001
17.85000,-2.97506,0.00003
17.90000,-2.98333,0.00001
17.95000,-2.99159,0.00002
18.00000,-3.00013,0.00001
18.05000,-3.00839,0.00000
18.10000,-3.01679,0.00000
18.15000,-3.02506,0.00003
18.20000,-3.03319,0.00001
18.25000,-3.04173,0.00002
18.30000,-3.04999,0.00001
18.35000,-3.05799,0.00003
18.40000,-3.06653,0.00000
18.45000,-3.07493,0.00004
18.50000,-3.08306,0.00000
18.55000,-3.09146,0.00001
18.60000,-3.10013,-0.00001
18.65000,-3.10826,0.00000
18.70000,-3.11653,0.00001
18.75000,-3.12506,0.00003
18.80000,-3.13346,-0.00001
18.85000,-3.14173,0.00001
18.90000,-3.15013,0.00003
18.95000,-3.15839,0.00002
19.00000,-3.16666,0.00001
19.05000,-3.17506,0.00001
19.10000,-3.18333,-0.00001
19.15000,-3.19173,0.00002
19.20000,-3.19986,0.00002
19.25000,-3.20813,0.00002
19.30000,-3.21666,0.00000
19.35000,-3.22506,0.00004
19.40000,-3.23333,0.00000
19.45000,-3.24159,0.00002
19.50000,-3.25013,0.00000
19.55000,-3.25839,-0.00001
19.60000,-3.26666,0.00001
19.65000,-3.27506,0.00002
19.70000,-3.28346,-0.00001
19.75000,-3.29146,0.00002
19.80000,-3.29973,-0.00001
19.85000,-3.30826,0.00002
19.90000,-3.31639,0.00000
19.95000,-3.32466,0.00001
20.00000,-3.33306,0.00000
20.05000,-3.34133,-0.00001
20.10000,-3.34959,-0.00001
20.15000,-3.35813,0.00000
20.20000,-3.36653,-0.00001
20.25000,-3.37506,0.00002
20.30000,-3.38346,0.00000
20.35000,-3.39173,0.00002
20.40000,-3.40026,-0.00002
20.45000,-3.40852,-0.00001
20.50000,-3.41652,0.00000
20.55000,-3.42519,0.00000
20.60000,-3.43346,-0.00001
20.65000,-3.44146,0.00001
20.70000,-3.44986,-0.00002
20.75000,-3.45826,0.00002
20.80000,-3.46626,0.00001
20.85000,-3.47466,-0.00001
20.90000,-3.48332,0.00001
20.95000,-3.49159,0.00002
21.00000,-3.49986,-0.00001
21.05000,-3.50839,0.00000
21.10000,-3.51679,-0.00001
21.15000,-3.52506,0.00002
21.20000,-3.53346,0.00001
21.25000,-3.54172,0.00002
21.30000,-3.55012,-0.00001
21.35000,-3.55839,0.00002
21.40000,-3.56652,0.00000
21.45000,-3.57506,0.00002
21.50000,-3.58346,-0.00001
21.55000,-3.59132,-0.00001
21.60000,-3.59986,-0.00001
21.65000,-3.60826,0.00002
21.70000,-3.61639,0.00001
21.75000,-3.62479,0.00000
21.80000,-3.63346,0.00000
21.85000,-3.64159,0.00000
21.90000,-3.64986,0.00000
21.95000,-3.65852,0.00002
22.00000,-3.66666,-0.00001
22.05000,-3.67492,0.00000
22.10000,-3.68332,0.00000
22.15000,-3.69186,0.00000
22.20000,-3.69999,0.00000
22.25000,-3.70839,0.00002
22.30000,-3.71666,0.00000
22.35000,-3.72492,0.00002
22.40000,-3.73332,0.00000
22.45000,-3.74146,0.00002
22.50000,-3.74999,-0.00002
22.55000,-3.75826,0.00000
22.60000,-3.76666,0.00000
22.65000,-3.77492,0.00002
22.70000,-3.78346,0.00000
22.75000,-3.79172,0.00000
22.80000,-3.79986,-0.00001
22.85000,-3.80839,0.00001
22.90000,-3.81679,-0.00001
22.95000,-3.82479,-0.00002
23.00000,-3.83319,-0.00001
23.05000,-3.84172,0.00000
23.10000,-3.84986,0.00000
23.15000,-3.85812,0.00000
23.20000,-3.86666,-0.00002
23.25000,-3.87479,0.00000
23.30000,-3.88306,-0.00003
23.35000,-3.89146,0.00001
23.40000,-3.89999,-0.00002
23.45000,-3.90826,0.00001
23.50000,-3.91666,0.00000
23.55000,-3.92479,-0.00002
23.60000,-3.93332,0.00000
23.65000,-3.94172,-0.00001
23.70000,-3.94986,0.00000
23.75000,-3.95839,0.00002
23.80000,-3.96679,-0.00004
23.85000,-3.97479,0.00000
23.90000,-3.98319,-0.00004
23.95000,-3.99172,0.00000
24.00000,-3.99959,-0.00001
24.05000,-4.00786,-0.00001
24.10000,-4.01666,-0.00002
24.15000,-4.02479,0.00000
24.20000,-4.03306,-0.00003
24.25000,-4.04172,0.00001
24.30000,-4.05012,-0.00002
24.35000,-4.05839,0.00000
24.40000,-4.06679,-0.00001
24.45000,-4.07506,0.00002
24.50000,-4.08346,0.00001
24.55000,-4.09186,-0.00002
24.60000,-4.09986,0.00001
24.65000,-4.10839,0.00001
24.70000,-4.11679,0.00000
24.75000,-4.12479,0.00001
24.80000,-4.13319,-0.00002
24.85000,-4.14172,0.00000
24.90000,-4.14972,-0.00001
24.95000,-4.15812,-0.00003
25.00000,-4.16692,-0.00002
25.05000,-4.17506,-0.00001
25.10000,-4.18332,0.00001
25.15000,-4.19186,0.00001
25.20000,-4.20012,-0.00003
25.25000,-4.20839,0.00001
25.30000,-4.21679,0.00000
25.35000,-4.22506,0.00000
25.40000,-4.23332,-0.00001
25.45000,-4.24172,0.00000
25.50000,-4.24999,-0.00001
25.55000,-4.25839,-0.00001
25.60000,-4.26652,-0.00002
25.65000,-4.27479,0.00001
25.70000,-4.28332,-0.00003
25.75000,-4.29172,0.00001
25.80000,-4.29999,0.00000
25.85000,-4.30826,0.00000
25.90000,-4.31679,0.00000
25.95000,-4.32506,-0.00002
26.00000,-4.33319,-0.00001
26.05000,-4.34172,-0.00002
26.10000,-4.35026,-0.00002
26.15000,-4.35826,0.00000
26.20000,-4.36652,0.00000
26.25000,-4.37506,-0.00001
26.30000,-4.38319,-0.00001
26.35000,-4.39146,-0.00002
26.40000,-4.39986,-0.00002
26.45000,-4.40812,-0.00002
26.50000,-4.41639,-0.00003
26.55000,-4.42492,-0.00002
26.60000,-4.43332,-0.00003
26.65000,-4.44159,-0.00001
26.70000,-4.44999,0.00001
26.75000,-4.45826,-0.00001
26.80000,-4.46679,-0.00001
26.85000,-4.47506,-0.00002
26.90000,-4.48319,0.00000
26.95000,-4.49172,-0.00001
27.00000,-4.50012,-0.00001
27.05000,-4.50799,-0.00002
27.10000,-4.51639,-0.00002
27.15000,-4.52506,0.00000
27.20000,-4.53306,0.00000
27.25000,-4.54132,-0.00001
27.30000,-4.55012,-0.00002
27.35000,-4.55826,0.00000
27.40000,-4.56652,-0.00002
27.45000,-4.57506,0.00000
27.50000,-4.58332,-0.00001
27.55000,-4.59159,-0.00001
27.60000,-4.59999,-0.00001
27.65000,-4.60826,0.00000
27.70000,-4.61679,-0.00001
27.75000,-4.62506,-0.00001
27.80000,-4.63319,-0.00001
27.85000,-4.64172,-0.00002
27.90000,-4.64999,-0.00001
27.95000,-4.65799,-0.00002
28.00000,-4.66652,-0.00002
28.05000,-4.67492,-0.00003
28.10000,-4.68306,-0.00001
28.15000,-4.69146,0.00000
28.20000,-4.70026,0.00000
28.25000,-4.70839,-0.00002
28.30000,-4.71652,-0.00002
28.35000,-4.72519,-0.00001
28.40000,-4.73346,-0.00001
28.45000,-4.74172,-0.00001
28.50000,-4.75012,-0.00002
28.55000,-4.75852,-0.00004
28.60000,-4.76666,-0.00002
28.65000,-4.77492,0.00001
28.70000,-4.78319,-0.00001
28.75000,-4.79172,-0.00001
28.80000,-4.79999,0.00000
28.85000,-4.80812,0.00000
28.90000,-4.81652,-0.00003
28.95000,-4.82492,0.00001
29.00000,-4.83319,0.00000
29.05000,-4.84145,-0.00003
29.10000,-4.85012,0.00000
29.15000,-4.85852,0.00001
29.20000,-4.86719,-0.00005
29.25000,-4.87572,-0.00002
29.30000,-4.88399,-0.00006
29.35000,-4.89185,-0.00006
29.40000,-4.89945,-0.00003
29.45000,-4.90799,-0.00002
29.50000,-4.91625,-0.00003
29.55000,-4.92452,-0.00003
29.60000,-4.93305,-0.00004
29.65000,-4.94132,-0.00003
29.70000,-4.94959,-0.00003
29.75000,-4.95812,-0.00002
29.80000,-4.96652,-0.00004
29.85000,-4.97505,0.00000
29.90000,-4.98332,0.00000
29.95000,-4.99145,-0.00003
30.00000,-4.99999,-0.00001
30.05000,-5.00839,-0.00002
30.10000,-5.01665,-0.00001
30.15000,-5.02505,0.00000
30.20000,-5.03345,-0.00004
30.25000,-5.04132,0.00000
30.30000,-5.04985,-0.00005
30.35000,-5.05839,0.00000
30.40000,-5.06639,-0.00001
30.45000,-5.07465,-0.00001
30.50000,-5.08332,-0.00003
30.55000,-5.09159,-0.00002
30.60000,-5.09985,-0.00002
30.65000,-5.10839,-0.00001
30.70000,-5.11679,-0.00002
30.75000,-5.12505,0.00000
30.80000,-5.13345,-0.00002
30.85000,-5.14172,-0.00001
30.90000,-5.15012,-0.00002
30.95000,-5.15852,0.00000
31.00000,-5.16652,-0.00001
31.05000,-5.17505,-0.00002
31.10000,-5.18345,-0.00003
31.15000,-5.19132,-0.00001
31.20000,-5.19972,-0.00003
31.25000,-5.20839,0.00000
31.30000,-5.21639,-0.00002
31.35000,-5.22479,0.00000
31.40000,-5.23359,-0.00001
31.45000,-5.24159,-0.00002
31.50000,-5.24972,-0.00002
31.55000,-5.25839,-0.00002
31.60000,-5.26665,-0.00003
31.65000,-5.27492,-0.00001
31.70000,-5.28332,0.00001
31.75000,-5.29172,-0.00001
31.80000,-5.29999,-0.00003
31.85000,-5.30839,0.00000
31.90000,-5.31652,-0.00002
31.95000,-5.32492,-0.00002
32.00000,-5.33319,0.00000
32.05000,-5.34132,-0.00003
32.10000,-5.34972,-0.00002
32.15000,-5.35825,0.00000
32.20000,-5.36652,0.00000
32.25000,-5.37479,-0.00001
32.30000,-5.38332,-0.00002
32.35000,-5.39172,-0.00002
32.40000,-5.39985,-0.00002
32.45000,-5.40839,0.00000
32.50000,-5.41692,-0.00003
32.55000,-5.42492,-0.00002
32.60000,-5.43319,-0.00002
32.65000,-5.44172,-0.00001
32.70000,-5.44985,-0.00002
32.75000,-5.45812,-0.00002
32.80000,-5.46652,-0.00003
32.85000,-5.47479,-0.00002
32.90000,-5.48305,-0.00003
32.95000,-5.49159,-0.00002
33.00000,-5.49985,-0.00003
33.05000,-5.50839,-0.00003
33.10000,-5.51665,-0.00002
33.15000,-5.52492,-0.00001
33.20000,-5.53345,-0.00001
33.25000,-5.54185,-0.00002
33.30000,-5.54999,0.00000
33.35000,-5.55839,0.00000
33.40000,-5.56679,-0.00002
33.45000,-5.57479,-0.00001
33.50000,-5.58319,-0.00004
33.55000,-5.59172,-0.00003
33.60000,-5.59985,-0.00002
33.65000,-5.60799,-0.00002
33.70000,-5.61665,-0.00004
33.75000,-5.62492,0.00002
33.80000,-5.63305,-0.00002
33.85000,-5.64159,-0.00002
33.90000,-5.64999,0.00000
33.95000,-5.65825,-0.00003
34.00000,-5.66665,0.00000
34.05000,-5.67505,-0.00001
34.10000,-5.68345,-0.00005
34.15000,-5.69172,-0.00001
34.20000,-5.69985,-0.00002
34.25000,-5.70839,0.00001
34.30000,-5.71665,0.00000
34.35000,-5.72465,0.00000
34.40000,-5.73319,-0.00002
34.45000,-5.74159,0.00000
34.50000,-5.74972,-0.00001
34.55000,-5.75812,-0.00004
34.60000,-5.76679,0.00000
34.65000,-5.77505,-0.00001
34.70000,-5.78319,0.00001
34.75000,-5.79172,0.00004
34.80000,-5.80012,-0.00004
34.85000,-5.80825,-0.00002
34.90000,-5.81665,-0.00002
34.95000,-5.82505,0.00002
35.00000,-5.83332,-0.00003
35.05000,-5.84172,-0.00001
35.10000,-5.84985,0.00001
35.15000,-5.85825,0.00000
35.20000,-5.86652,0.00000
35.25000,-5.87465,-0.00001
35.30000,-5.88319,0.00000
35.35000,-5.89172,0.00001
35.40000,-5.89999,-0.00001
35.45000,-5.90825,0.00001
35.50000,-5.91679,-0.00001
35.55000,-5.92505,-0.00001
35.60000,-5.93319,-0.00003
35.65000,-5.94172,0.00000
35.70000,-5.95025,-0.00001
35.75000,-5.95825,-0.00002
35.80000,-5.96665,-0.00003
35.85000,-5.97505,-0.00001
35.90000,-5.98305,-0.00001
35.95000,-5.99132,-0.00003
36.00000,-5.99972,-0.00004
36.05000,-6.00812,-0.00001
36.10000,-6.01652,-0.00002
36.15000,-6.02492,0.00000
36.20000,-6.03332,-0.00002
36.25000,-6.04172,0.00000
36.30000,-6.04999,-0.00002
36.35000,-6.05825,0.00003
36.40000,-6.06679,-0.00001
36.45000,-6.07505,0.00000
36.50000,-6.08319,-0.00003
36.55000,-6.09172,-0.00003
36.60000,-6.10012,-0.00002
36.65000,-6.10812,-0.00001
36.70000,-6.11652,-0.00003
36.75000,-6.12505,0.00000
36.80000,-6.13305,-0.00002
36.85000,-6.14132,-0.00002
36.90000,-6.14998,-0.00002
36.95000,-6.15825,0.00001
37.00000,-6.16652,0.00000
37.05000,-6.17519,0.00000
37.10000,-6.18345,-0.00002
37.15000,-6.19172,-0.00001
37.20000,-6.20012,0.00000
37.25000,-6.20838,0.00000
37.30000,-6.21678,-0.00003
37.35000,-6.22519,-0.00001
37.40000,-6.23318,-0.00001
37.45000,-6.24158,-0.00002
37.50000,-6.24998,-0.00001
37.55000,-6.25812,-0.00003
37.60000,-6.26638,-0.00003
37.65000,-6.27492,0.00000
37.70000,-6.28305,0.00000
37.75000,-6.29145,-0.00002
37.80000,-6.30012,-0.00003
37.85000,-6.30838,-0.00002
37.90000,-6.31652,-0.00002
37.95000,-6.32505,0.00000
38.00000,-6.33345,-0.00003
38.05000,-6.34172,-0.00001
38.10000,-6.35012,-0.00001
38.15000,-6.35838,-0.00002
38.20000,-6.36665,-0.00001
38.25000,-6.37492,0.00001
38.30000,-6.38318,-0.00001
38.35000,-6.39158,-0.00001
38.40000,-6.39998,0.00000
38.45000,-6.40812,-0.00002
38.50000,-6.41652,-0.00002
38.55000,-6.42505,-0.00003
38.60000,-6.43318,0.00000
38.65000,-6.44158,-0.00001
38.70000,-6.45012,0.00000
38.75000,-6.45852,-0.00001
38.80000,-6.46665,-0.00001
38.85000,-6.47505,-0.00001
38.90000,-6.48358,-0.00002
38.95000,-6.49145,0.00000
39.00000,-6.49985,-0.00003
39.05000,-6.50838,-0.00002
39.10000,-6.51652,-0.00001
39.15000,-6.52478,-0.00002
39.20000,-6.53332,0.00000
39.25000,-6.54158,0.00005
39.30000,-6.54985,0.00002
39.35000,-6.55825,0.00004
39.40000,-6.56665,-0.00001
39.45000,-6.57505,-0.00001
39.50000,-6.58332,-0.00001
39.55000,-6.59158,0.00004
39.60000,-6.60012,0.00000
39.65000,-6.60852,0.00000
39.70000,-6.61665,0.00000
39.75000,-6.62518,0.00000
39.80000,-6.63345,-0.00004
39.85000,-6.64145,0.00000
39.90000,-6.64985,-0.00003
39.95000,-6.65825,0.00000
40.00000,-6.66625,-0.00003
40.05000,-6.67452,-0.00002
40.10000,-6.68332,-0.00003
40.15000,-6.69158,0.00001
40.20000,-6.69998,-0.00002
40.25000,-6.70838,0.00000
40.30000,-6.71665,-0.00002
40.35000,-6.72505,-0.00001
40.40000,-6.73345,-0.00001
40.45000,-6.74172,-0.00001
40.50000,-6.75012,-0.00002
40.55000,-6.75838,-0.00003
40.60000,-6.76638,-0.00001
40.65000,-6.77505,0.00000
40.70000,-6.78332,-0.00001
40.75000,-6.79145,0.00000
40.80000,-6.79998,-0.00002
40.85000,-6.80838,0.00000
40.90000,-6.81638,0.00000
40.95000,-6.82478,-0.00001
41.00000,-6.83345,0.00001
41.05000,-6.84172,-0.00004
41.10000,-6.84985,-0.00001
41.15000,-6.85852,0.00000
41.20000,-6.86678,-0.00003
41.25000,-6.87492,0.00000
41.30000,-6.88345,-0.00002
41.35000,-6.89185,-0.00002
41.40000,-6.89998,-0.00002
41.45000,-6.90838,0.00000
41.50000,-6.91665,0.00000
41.55000,-6.92518,-0.00003
41.60000,-6.93332,0.00000
41.65000,-6.94145,0.00000
41.70000,-6.94998,-0.00002
41.75000,-6.95852,0.00000
41.80000,-6.96652,-0.00001
41.85000,-6.97492,-0.00001
41.90000,-6.98345,-0.00001
41.95000,-6.99172,0.00000
42.00000,-6.99985,0.00000
42.05000,-7.00838,0.00000
42.10000,-7.01692,-0.00003
42.15000,-7.02492,0.00000
42.20000,-7.03318,-0.00002
42.25000,-7.04172,0.00000
42.30000,-7.04972,-0.00003
42.35000,-7.05798,-0.00002
42.40000,-7.06652,-0.00003
42.45000,-7.07478,-0.00002
42.50000,-7.08305,-0.00003
42.55000,-7.09145,-0.00002
42.60000,-7.09985,-0.00004
42.65000,-7.10825,0.00000
42.70000,-7.11665,0.00001
42.75000,-7.12492,0.00000
42.80000,-7.13345,0.00000
42.85000,-7.14172,0.00000
42.90000,-7.14972,-0.00002
42.95000,-7.15825,0.00000
43.00000,-7.16665,-0.00004
43.05000,-7.17478,-0.00002
43.10000,-7.18318,-0.00002
43.15000,-7.19172,0.00002
43.20000,-7.19972,-0.00001
43.25000,-7.20812,-0.00002
43.30000,-7.21678,-0.00004
43.35000,-7.22505,0.00002
43.40000,-7.23318,-0.00001
43.45000,-7.24172,0.00002
43.50000,-7.25012,-0.00001
43.55000,-7.25825,-0.00001
43.60000,-7.26665,-0.00001
43.65000,-7.27505,0.00000
43.70000,-7.28345,-0.00004
43.75000,-7.29172,-0.00002
43.80000,-7.29985,0.00000
43.85000,-7.30825,0.00001
43.90000,-7.31665,-0.00001
43.95000,-7.32465,0.00000
44.00000,-7.33318,-0.00003
44.05000,-7.34158,-0.00001
44.10000,-7.34972,0.00000
44.15000,-7.35812,-0.00004
44.20000,-7.36692,-0.00002
44.25000,-7.37505,-0.00002
44.30000,-7.38318,-0.00001
44.35000,-7.39185,0.00000
44.40000,-7.40012,-0.00003
44.45000,-7.40838,0.00000
44.50000,-7.41678,-0.00002
44.55000,-7.42505,-0.00002
44.60000,-7.43332,-0.00002
44.65000,-7.44158,-0.00001
44.70000,-7.44998,-0.00001
44.75000,-7.45838,-0.00001
44.80000,-7.46665,-0.00002
44.85000,-7.47478,0.00002
44.90000,-7.48318,-0.00002
44.95000,-7.49172,0.00001
45.00000,-7.49985,-0.00001
45.05000,-7.50825,-0.00002
45.10000,-7.51678,0.00001
45.15000,-7.52518,-0.00001
45.20000,-7.53332,-0.00001
45.25000,-7.54171,0.00000
45.30000,-7.55025,-0.00003
45.35000,-7.55825,0.00002
45.40000,-7.56651,0.00000
45.45000,-7.57505,0.00000
45.50000,-7.58318,-0.00002
45.55000,-7.59145,-0.00003
45.60000,-7.59985,-0.00002
45.65000,-7.60811,-0.00001
45.70000,-7.61638,-0.00003
45.75000,-7.62491,0.00002
45.80000,-7.63318,-0.00003
45.85000,-7.64145,-0.00001
45.90000,-7.64971,-0.00004
45.95000,-7.65811,-0.00002
46.00000,-7.66665,-0.00003
46.05000,-7.67505,-0.00002
46.10000,-7.68318,-0.00001
46.15000,-7.69171,0.00002
46.20000,-7.70011,-0.00003
46.25000,-7.70811,0.00000
46.30000,-7.71651,-0.00002
46.35000,-7.72505,0.00000
46.40000,-7.73305,0.00000
46.45000,-7.74145,-0.00003
46.50000,-7.74998,-0.00002
46.55000,-7.75825,-0.00002
46.60000,-7.76651,0.00000
46.65000,-7.77505,-0.00001
46.70000,-7.78331,-0.00002
46.75000,-7.79171,-0.00002
46.80000,-7.80011,-0.00002
46.85000,-7.80838,-0.00001
46.90000,-7.81678,0.00000
46.95000,-7.82505,0.00000
47.00000,-7.83318,-0.00003
47.05000,-7.84171,-0.00003
47.10000,-7.85011,-0.00003
47.15000,-7.85811,0.00000
47.20000,-7.86665,-0.00002
47.25000,-7.87491,0.00000
47.30000,-7.88305,-0.00001
47.35000,-7.89158,-0.00002
47.40000,-7.90011,-0.00001
47.45000,-7.90825,-0.00001
47.50000,-7.91651,-0.00002
47.55000,-7.92505,-0.00003
47.60000,-7.93331,-0.00004
47.65000,-7.94158,0.00002
47.70000,-7.95011,-0.00001
47.75000,-7.95851,-0.00002
47.80000,-7.96665,-0.00003
47.85000,-7.97491,-0.00001
47.90000,-7.98318,-0.00001
47.95000,-7.99158,-0.00001
48.00000,-7.99998,-0.00003
48.05000,-8.00811,-0.00001
48.10000,-8.01665,0.00002
48.15000,-8.02505,0.00478
48.20000,-8.03318,0.00831
48.25000,-8.04158,0.00070
48.30000,-8.05011,0.00289
48.31400,-8.05251,0.00283