File: GFBaking/data/2_13PercentGluten/2_13gluten_4Point.is_flex_RawData/Specimen_RawData_3.csv
Time,Extension,Load
(sec),(mm),(N)
0.00000,-0.00027,-0.00003
0.05000,-0.00133,-0.00010
0.10000,-0.00587,-0.00009
0.15000,-0.01480,-0.00010
0.20000,-0.02560,-0.00010
0.25000,-0.03573,-0.00008
0.30000,-0.04573,-0.00007
0.35000,-0.05533,-0.00009
0.40000,-0.06440,-0.00008
0.45000,-0.07347,-0.00008
0.50000,-0.08240,-0.00008
0.55000,-0.09080,-0.00009
0.60000,-0.09933,-0.00008
0.65000,-0.10800,-0.00009
0.70000,-0.11627,-0.00008
0.75000,-0.12467,-0.00009
0.80000,-0.13320,-0.00009
0.85000,-0.14147,-0.00008
0.90000,-0.14987,-0.00009
0.95000,-0.15840,-0.00011
1.00000,-0.16680,-0.00007
1.05000,-0.17507,-0.00009
1.10000,-0.18347,-0.00008
1.15000,-0.19173,-0.00009
1.20000,-0.20013,-0.00006
1.25000,-0.20853,-0.00006
1.30000,-0.21667,-0.00006
1.35000,-0.22533,-0.00010
1.40000,-0.23360,-0.00008
1.45000,-0.24173,-0.00009
1.50000,-0.25013,-0.00008
1.55000,-0.25853,-0.00009
1.60000,-0.26653,-0.00007
1.65000,-0.27493,-0.00009
1.70000,-0.28360,-0.00007
1.75000,-0.29173,-0.00007
1.80000,-0.30000,-0.00007
1.85000,-0.30853,-0.00008
1.90000,-0.31680,-0.00005
1.95000,-0.32507,-0.00008
2.00000,-0.33347,-0.00006
2.05000,-0.34187,-0.00009
2.10000,-0.35027,-0.00006
2.15000,-0.35867,-0.00007
2.20000,-0.36680,-0.00007
2.25000,-0.37533,-0.00006
2.30000,-0.38360,-0.00007
2.35000,-0.39173,-0.00009
2.40000,-0.40027,-0.00005
2.45000,-0.40853,-0.00007
2.50000,-0.41667,-0.00007
2.55000,-0.42507,-0.00007
2.60000,-0.43360,-0.00005
2.65000,-0.44187,-0.00007
2.70000,-0.45013,-0.00005
2.75000,-0.45867,-0.00006
2.80000,-0.46707,-0.00007
2.85000,-0.47520,-0.00007
2.90000,-0.48360,-0.00003
2.95000,-0.49200,-0.00008
3.00000,-0.50027,-0.00009
3.05000,-0.50853,-0.00009
3.10000,-0.51693,-0.00005
3.15000,-0.52520,-0.00007
3.20000,-0.53347,-0.00005
3.25000,-0.54160,-0.00005
3.30000,-0.55013,-0.00006
3.35000,-0.55853,-0.00008
3.40000,-0.56680,-0.00005
3.45000,-0.57520,-0.00007
3.50000,-0.58373,-0.00006
3.55000,-0.59187,-0.00008
3.60000,-0.60000,-0.00005
3.65000,-0.60853,-0.00004
3.70000,-0.61707,-0.00007
3.75000,-0.62507,-0.00006
3.80000,-0.63333,-0.00005
3.85000,-0.64200,-0.00005
3.90000,-0.65000,-0.00005
3.95000,-0.65827,-0.00007
4.00000,-0.66680,-0.00007
4.05000,-0.67493,-0.00008
4.10000,-0.68320,-0.00006
4.15000,-0.69173,-0.00008
4.20000,-0.70013,-0.00007
4.25000,-0.70853,-0.00007
4.30000,-0.71680,-0.00005
4.35000,-0.72520,-0.00007
4.40000,-0.73373,-0.00005
4.45000,-0.74200,-0.00006
4.50000,-0.75013,-0.00005
4.55000,-0.75866,-0.00008
4.60000,-0.76706,-0.00005
4.65000,-0.77506,-0.00004
4.70000,-0.78346,-0.00006
4.75000,-0.79186,-0.00007
4.80000,-0.79986,-0.00004
4.85000,-0.80813,-0.00007
4.90000,-0.81693,-0.00005
4.95000,-0.82520,-0.00007
5.00000,-0.83346,-0.00004
5.05000,-0.84186,-0.00006
5.10000,-0.85026,-0.00005
5.15000,-0.85853,-0.00005
5.20000,-0.86693,-0.00005
5.25000,-0.87533,-0.00005
5.30000,-0.88373,-0.00006
5.35000,-0.89200,-0.00007
5.40000,-0.90013,-0.00006
5.45000,-0.90853,-0.00004
5.50000,-0.91693,-0.00005
5.55000,-0.92493,-0.00007
5.60000,-0.93346,-0.00006
5.65000,-0.94186,-0.00005
5.70000,-0.94986,-0.00006
5.75000,-0.95840,-0.00005
5.80000,-0.96693,-0.00004
5.85000,-0.97520,-0.00005
5.90000,-0.98346,-0.00006
5.95000,-0.99200,-0.00006
6.00000,-1.00026,-0.00005
6.05000,-1.00853,-0.00008
6.10000,-1.01706,-0.00007
6.15000,-1.02533,-0.00005
6.20000,-1.03346,-0.00006
6.25000,-1.04173,-0.00006
6.30000,-1.05013,-0.00006
6.35000,-1.05853,-0.00007
6.40000,-1.06680,-0.00003
6.45000,-1.07493,-0.00007
6.50000,-1.08346,-0.00006
6.55000,-1.09186,-0.00007
6.60000,-1.10013,-0.00005
6.65000,-1.10853,-0.00006
6.70000,-1.11693,-0.00003
6.75000,-1.12533,-0.00005
6.80000,-1.13346,-0.00005
6.85000,-1.14200,-0.00005
6.90000,-1.15040,-0.00005
6.95000,-1.15853,-0.00005
7.00000,-1.16680,-0.00004
7.05000,-1.17533,-0.00006
7.10000,-1.18346,-0.00004
7.15000,-1.19173,-0.00006
7.20000,-1.20013,-0.00004
7.25000,-1.20840,-0.00004
7.30000,-1.21666,-0.00006
7.35000,-1.22506,-0.00005
7.40000,-1.23360,-0.00004
7.45000,-1.24200,-0.00005
7.50000,-1.25026,-0.00004
7.55000,-1.25853,-0.00005
7.60000,-1.26706,-0.00006
7.65000,-1.27533,-0.00005
7.70000,-1.28346,-0.00004
7.75000,-1.29200,-0.00004
7.80000,-1.30026,-0.00004
7.85000,-1.30840,-0.00004
7.90000,-1.31680,-0.00005
7.95000,-1.32520,-0.00006
8.00000,-1.33333,-0.00005
8.05000,-1.34160,-0.00006
8.10000,-1.35013,-0.00005
8.15000,-1.35826,-0.00005
8.20000,-1.36666,-0.00005
8.25000,-1.37520,-0.00004
8.30000,-1.38360,-0.00003
8.35000,-1.39186,-0.00003
8.40000,-1.40026,-0.00005
8.45000,-1.40866,-0.00006
8.50000,-1.41706,-0.00005
8.55000,-1.42533,-0.00006
8.60000,-1.43346,-0.00005
8.65000,-1.44200,-0.00004
8.70000,-1.45013,-0.00005
8.75000,-1.45826,-0.00006
8.80000,-1.46680,-0.00005
8.85000,-1.47520,-0.00005
8.90000,-1.48333,-0.00004
8.95000,-1.49173,-0.00006
9.00000,-1.50040,-0.00003
9.05000,-1.50853,-0.00006
9.10000,-1.51680,-0.00004
9.15000,-1.52533,-0.00005
9.20000,-1.53373,-0.00005
9.25000,-1.54186,-0.00004
9.30000,-1.55026,-0.00003
9.35000,-1.55866,-0.00005
9.40000,-1.56693,-0.00005
9.45000,-1.57520,-0.00003
9.50000,-1.58346,-0.00003
9.55000,-1.59186,-0.00007
9.60000,-1.60013,-0.00004
9.65000,-1.60826,-0.00005
9.70000,-1.61680,-0.00007
9.75000,-1.62520,-0.00005
9.80000,-1.63346,-0.00004
9.85000,-1.64186,-0.00005
9.90000,-1.65040,-0.00006
9.95000,-1.65866,-0.00006
10.00000,-1.66680,-0.00001
10.05000,-1.67533,-0.00005
10.10000,-1.68373,-0.00005
10.15000,-1.69186,-0.00005
10.20000,-1.70013,-0.00003
10.25000,-1.70866,-0.00004
10.30000,-1.71680,-0.00004
10.35000,-1.72493,-0.00005
10.40000,-1.73346,-0.00006
10.45000,-1.74173,-0.00005
10.50000,-1.75000,-0.00006
10.55000,-1.75840,-0.00005
10.60000,-1.76693,-0.00004
10.65000,-1.77520,-0.00003
10.70000,-1.78346,-0.00003
10.75000,-1.79186,-0.00004
10.80000,-1.80040,-0.00003
10.85000,-1.80853,-0.00003
10.90000,-1.81680,-0.00002
10.95000,-1.82533,-0.00003
11.00000,-1.83360,-0.00004
11.05000,-1.84160,-0.00005
11.10000,-1.85000,-0.00006
11.15000,-1.85866,-0.00004
11.20000,-1.86666,-0.00001
11.25000,-1.87493,-0.00004
11.30000,-1.88360,-0.00005
11.35000,-1.89186,-0.00003
11.40000,-1.90013,-0.00003
11.45000,-1.90853,-0.00003
11.50000,-1.91693,-0.00003
11.55000,-1.92520,-0.00006
11.60000,-1.93360,-0.00004
11.65000,-1.94186,-0.00005
11.70000,-1.95026,-0.00004
11.75000,-1.95853,-0.00003
11.80000,-1.96666,-0.00004
11.85000,-1.97533,-0.00006
11.90000,-1.98360,-0.00006
11.95000,-1.99173,-0.00005
12.00000,-2.00013,-0.00004
12.05000,-2.00853,-0.00004
12.10000,-2.01653,-0.00005
12.15000,-2.02493,-0.00007
12.20000,-2.03359,-0.00003
12.25000,-2.04186,-0.00003
12.30000,-2.05013,-0.00001
12.35000,-2.05879,-0.00003
12.40000,-2.06706,-0.00005
12.45000,-2.07520,-0.00005
12.50000,-2.08359,-0.00004
12.55000,-2.09199,-0.00005
12.60000,-2.10013,-0.00003
12.65000,-2.10853,-0.00004
12.70000,-2.11679,-0.00005
12.75000,-2.12519,-0.00004
12.80000,-2.13346,-0.00003
12.85000,-2.14173,-0.00003
12.90000,-2.15026,-0.00002
12.95000,-2.15866,-0.00005
13.00000,-2.16679,-0.00003
13.05000,-2.17506,-0.00003
13.10000,-2.18359,-0.00003
13.15000,-2.19186,-0.00002
13.20000,-2.20013,-0.00002
13.25000,-2.20853,-0.00004
13.30000,-2.21706,-0.00005
13.35000,-2.22519,-0.00004
13.40000,-2.23346,-0.00002
13.45000,-2.24199,-0.00002
13.50000,-2.25013,-0.00001
13.55000,-2.25826,-0.00004
13.60000,-2.26679,-0.00005
13.65000,-2.27506,-0.00002
13.70000,-2.28319,-0.00004
13.75000,-2.29173,-0.00004
13.80000,-2.30026,-0.00003
13.85000,-2.30853,-0.00005
13.90000,-2.31693,-0.00002
13.95000,-2.32519,-0.00004
14.00000,-2.33373,-0.00002
14.05000,-2.34186,-0.00004
14.10000,-2.34999,-0.00004
14.15000,-2.35866,-0.00003
14.20000,-2.36693,-0.00003
14.25000,-2.37506,0.00000
14.30000,-2.38333,-0.00005
14.35000,-2.39186,-0.00005
14.40000,-2.39999,-0.00003
14.45000,-2.40826,-0.00004
14.50000,-2.41693,-0.00002
14.55000,-2.42519,-0.00004
14.60000,-2.43333,-0.00002
14.65000,-2.44186,-0.00003
14.70000,-2.45026,-0.00003
14.75000,-2.45853,-0.00002
14.80000,-2.46693,-0.00001
14.85000,-2.47519,-0.00003
14.90000,-2.48373,-0.00004
14.95000,-2.49199,-0.00005
15.00000,-2.49999,-0.00003
15.05000,-2.50866,-0.00003
15.10000,-2.51679,-0.00001
15.15000,-2.52506,-0.00002
15.20000,-2.53346,-0.00002
15.25000,-2.54186,-0.00001
15.30000,-2.54986,0.00000
15.35000,-2.55839,-0.00003
15.40000,-2.56693,-0.00003
15.45000,-2.57519,-0.00005
15.50000,-2.58346,-0.00003
15.55000,-2.59199,-0.00007
15.60000,-2.60039,-0.00003
15.65000,-2.60853,-0.00002
15.70000,-2.61693,-0.00001
15.75000,-2.62546,-0.00003
15.80000,-2.63359,-0.00003
15.85000,-2.64186,-0.00002
15.90000,-2.65013,-0.00001
15.95000,-2.65853,-0.00003
16.00000,-2.66693,-0.00002
16.05000,-2.67506,-0.00006
16.10000,-2.68346,-0.00004
16.15000,-2.69186,-0.00001
16.20000,-2.70013,-0.00001
16.25000,-2.70839,-0.00004
16.30000,-2.71706,-0.00002
16.35000,-2.72533,-0.00005
16.40000,-2.73359,-0.00002
16.45000,-2.74199,-0.00002
16.50000,-2.75039,-0.00003
16.55000,-2.75839,-0.00005
16.60000,-2.76666,-0.00003
16.65000,-2.77519,-0.00001
16.70000,-2.78346,-0.00002
16.75000,-2.79159,-0.00004
16.80000,-2.79999,-0.00002
16.85000,-2.80839,-0.00004
16.90000,-2.81666,-0.00002
16.95000,-2.82506,-0.00005
17.00000,-2.83333,-0.00003
17.05000,-2.84186,-0.00007
17.10000,-2.85013,0.00000
17.15000,-2.85839,-0.00004
17.20000,-2.86693,-0.00001
17.25000,-2.87519,-0.00002
17.30000,-2.88346,0.00000
17.35000,-2.89199,-0.00002
17.40000,-2.90026,-0.00002
17.45000,-2.90839,-0.00002
17.50000,-2.91679,-0.00001
17.55000,-2.92519,-0.00003
17.60000,-2.93319,-0.00002
17.65000,-2.94146,-0.00003
17.70000,-2.94999,-0.00003
17.75000,-2.95839,-0.00002
17.80000,-2.96666,-0.00003
17.85000,-2.97519,-0.00002
17.90000,-2.98346,-0.00001
17.95000,-2.99186,-0.00004
18.00000,-3.00026,0.00000
18.05000,-3.00853,-0.00003
18.10000,-3.01706,-0.00003
18.15000,-3.02533,-0.00002
18.20000,-3.03346,-0.00001
18.25000,-3.04213,-0.00003
18.30000,-3.05039,-0.00003
18.35000,-3.05853,-0.00003
18.40000,-3.06693,0.00000
18.45000,-3.07533,-0.00002
18.50000,-3.08333,-0.00002
18.55000,-3.09173,-0.00003
18.60000,-3.10026,-0.00001
18.65000,-3.10853,-0.00002
18.70000,-3.11679,0.00000
18.75000,-3.12533,0.00000
18.80000,-3.13373,-0.00003
18.85000,-3.14199,-0.00002
18.90000,-3.15026,-0.00002
18.95000,-3.15866,-0.00003
19.00000,-3.16693,-0.00002
19.05000,-3.17519,-0.00002
19.10000,-3.18346,-0.00001
19.15000,-3.19173,0.00000
19.20000,-3.19999,-0.00001
19.25000,-3.20826,0.00000
19.30000,-3.21666,-0.00002
19.35000,-3.22506,-0.00002
19.40000,-3.23319,-0.00002
19.45000,-3.24173,0.00000
19.50000,-3.25026,0.00000
19.55000,-3.25853,-0.00003
19.60000,-3.26666,0.00000
19.65000,-3.27519,0.00001
19.70000,-3.28373,0.00000
19.75000,-3.29173,0.00001
19.80000,-3.30013,-0.00001
19.85000,-3.30866,0.00000
19.90000,-3.31679,0.00000
19.95000,-3.32493,-0.00001
20.00000,-3.33333,-0.00001
20.05000,-3.34159,-0.00003
20.10000,-3.34986,-0.00002
20.15000,-3.35826,-0.00001
20.20000,-3.36666,0.00000
20.25000,-3.37533,0.00000
20.30000,-3.38359,-0.00001
20.35000,-3.39186,0.00000
20.40000,-3.40039,-0.00002
20.45000,-3.40879,-0.00002
20.50000,-3.41679,-0.00001
20.55000,-3.42533,-0.00003
20.60000,-3.43372,-0.00001
20.65000,-3.44172,0.00000
20.70000,-3.45012,-0.00002
20.75000,-3.45866,-0.00001
20.80000,-3.46666,0.00001
20.85000,-3.47492,0.00000
20.90000,-3.48359,0.00000
20.95000,-3.49186,-0.00003
21.00000,-3.49999,0.00000
21.05000,-3.50852,-0.00003
21.10000,-3.51692,-0.00002
21.15000,-3.52519,-0.00003
21.20000,-3.53359,0.00000
21.25000,-3.54199,0.00000
21.30000,-3.55039,-0.00004
21.35000,-3.55852,-0.00002
21.40000,-3.56666,-0.00001
21.45000,-3.57546,-0.00002
21.50000,-3.58359,-0.00002
21.55000,-3.59172,-0.00004
21.60000,-3.60012,-0.00001
21.65000,-3.60852,-0.00003
21.70000,-3.61652,-0.00001
21.75000,-3.62492,-0.00003
21.80000,-3.63372,-0.00003
21.85000,-3.64199,-0.00003
21.90000,-3.65012,0.00000
21.95000,-3.65866,-0.00003
22.00000,-3.66706,-0.00003
22.05000,-3.67519,-0.00004
22.10000,-3.68359,-0.00001
22.15000,-3.69199,-0.00003
22.20000,-3.70026,-0.00003
22.25000,-3.70852,-0.00003
22.30000,-3.71679,-0.00001
22.35000,-3.72519,-0.00002
22.40000,-3.73346,-0.00002
22.45000,-3.74172,-0.00002
22.50000,-3.75012,-0.00002
22.55000,-3.75852,-0.00003
22.60000,-3.76679,-0.00002
22.65000,-3.77506,-0.00002
22.70000,-3.78359,-0.00001
22.75000,-3.79186,-0.00002
22.80000,-3.79999,-0.00004
22.85000,-3.80852,-0.00002
22.90000,-3.81706,-0.00003
22.95000,-3.82519,-0.00005
23.00000,-3.83346,-0.00001
23.05000,-3.84199,-0.00004
23.10000,-3.85012,-0.00002
23.15000,-3.85826,-0.00006
23.20000,-3.86679,-0.00005
23.25000,-3.87506,-0.00002
23.30000,-3.88332,-0.00004
23.35000,-3.89172,-0.00005
23.40000,-3.90012,-0.00006
23.45000,-3.90866,-0.00003
23.50000,-3.91692,-0.00004
23.55000,-3.92519,-0.00005
23.60000,-3.93372,-0.00004
23.65000,-3.94186,-0.00002
23.70000,-3.94999,-0.00002
23.75000,-3.95852,-0.00002
23.80000,-3.96692,-0.00003
23.85000,-3.97506,-0.00003
23.90000,-3.98346,-0.00002
23.95000,-3.99199,-0.00004
24.00000,-3.99999,-0.00004
24.05000,-4.00812,-0.00003
24.10000,-4.01666,-0.00005
24.15000,-4.02506,-0.00003
24.20000,-4.03332,-0.00003
24.25000,-4.04186,-0.00004
24.30000,-4.05039,-0.00004
24.35000,-4.05866,-0.00004
24.40000,-4.06692,-0.00003
24.45000,-4.07519,-0.00003
24.50000,-4.08372,-0.00005
24.55000,-4.09199,-0.00005
24.60000,-4.10012,-0.00003
24.65000,-4.10866,-0.00003
24.70000,-4.11692,-0.00005
24.75000,-4.12506,-0.00004
24.80000,-4.13346,-0.00002
24.85000,-4.14186,-0.00002
24.90000,-4.15012,-0.00003
24.95000,-4.15852,-0.00003
25.00000,-4.16692,-0.00003
25.05000,-4.17519,-0.00005
25.10000,-4.18346,-0.00002
25.15000,-4.19199,-0.00004
25.20000,-4.20026,-0.00004
25.25000,-4.20852,-0.00003
25.30000,-4.21692,-0.00003
25.35000,-4.22532,-0.00004
25.40000,-4.23359,-0.00003
25.45000,-4.24186,-0.00003
25.50000,-4.25012,-0.00002
25.55000,-4.25852,-0.00005
25.60000,-4.26666,-0.00004
25.65000,-4.27492,-0.00005
25.70000,-4.28346,-0.00004
25.75000,-4.29186,-0.00004
25.80000,-4.30012,-0.00002
25.85000,-4.30852,-0.00005
25.90000,-4.31706,-0.00004
25.95000,-4.32532,-0.00006
26.00000,-4.33346,-0.00003
26.05000,-4.34186,-0.00005
26.10000,-4.35039,-0.00005
26.15000,-4.35839,-0.00005
26.20000,-4.36666,-0.00003
26.25000,-4.37532,-0.00003
26.30000,-4.38346,-0.00004
26.35000,-4.39159,-0.00005
26.40000,-4.40012,-0.00004
26.45000,-4.40826,-0.00004
26.50000,-4.41666,-0.00005
26.55000,-4.42506,-0.00006
26.60000,-4.43359,-0.00004
26.65000,-4.44199,-0.00004
26.70000,-4.45026,-0.00004
26.75000,-4.45839,-0.00004
26.80000,-4.46706,-0.00004
26.85000,-4.47532,-0.00004
26.90000,-4.48346,-0.00004
26.95000,-4.49212,-0.00005
27.00000,-4.50026,-0.00006
27.05000,-4.50826,-0.00005
27.10000,-4.51679,-0.00006
27.15000,-4.52519,-0.00003
27.20000,-4.53332,-0.00002
27.25000,-4.54159,-0.00005
27.30000,-4.55026,-0.00004
27.35000,-4.55839,-0.00004
27.40000,-4.56652,-0.00005
27.45000,-4.57506,-0.00005
27.50000,-4.58359,-0.00003
27.55000,-4.59199,-0.00006
27.60000,-4.60039,-0.00004
27.65000,-4.60866,-0.00005
27.70000,-4.61692,-0.00005
27.75000,-4.62519,-0.00005
27.80000,-4.63332,-0.00003
27.85000,-4.64199,-0.00005
27.90000,-4.65012,-0.00003
27.95000,-4.65826,-0.00005
28.00000,-4.66666,-0.00007
28.05000,-4.67506,-0.00007
28.10000,-4.68306,-0.00005
28.15000,-4.69159,-0.00006
28.20000,-4.70039,-0.00005
28.25000,-4.70852,-0.00005
28.30000,-4.71692,-0.00005
28.35000,-4.72546,-0.00006
28.40000,-4.73372,-0.00009
28.45000,-4.74199,-0.00007
28.50000,-4.75026,-0.00006
28.55000,-4.75866,-0.00010
28.60000,-4.76692,-0.00007
28.65000,-4.77519,-0.00006
28.70000,-4.78346,-0.00004
28.75000,-4.79185,-0.00006
28.80000,-4.80012,-0.00004
28.85000,-4.80839,-0.00005
28.90000,-4.81679,-0.00007
28.95000,-4.82519,-0.00007
29.00000,-4.83345,-0.00005
29.05000,-4.84185,-0.00008
29.10000,-4.85039,-0.00006
29.15000,-4.85865,-0.00007
29.20000,-4.86679,-0.00005
29.25000,-4.87519,-0.00006
29.30000,-4.88372,-0.00008
29.35000,-4.89185,-0.00006
29.40000,-4.90012,-0.00007
29.45000,-4.90865,-0.00006
29.50000,-4.91679,-0.00005
29.55000,-4.92492,-0.00007
29.60000,-4.93345,-0.00007
29.65000,-4.94172,-0.00006
29.70000,-4.94999,-0.00008
29.75000,-4.95839,-0.00008
29.80000,-4.96679,-0.00006
29.85000,-4.97519,-0.00006
29.90000,-4.98345,-0.00005
29.95000,-4.99172,-0.00006
30.00000,-5.00025,-0.00005
30.05000,-5.00852,-0.00009
30.10000,-5.01665,-0.00006
30.15000,-5.02519,-0.00007
30.20000,-5.03359,-0.00007
30.25000,-5.04172,-0.00007
30.30000,-5.05012,-0.00006
30.35000,-5.05852,-0.00007
30.40000,-5.06665,-0.00006
30.45000,-5.07492,-0.00007
30.50000,-5.08359,-0.00008
30.55000,-5.09172,-0.00008
30.60000,-5.09999,-0.00006
30.65000,-5.10852,-0.00006
30.70000,-5.11692,-0.00006
30.75000,-5.12519,-0.00008
30.80000,-5.13359,-0.00005
30.85000,-5.14185,-0.00005
30.90000,-5.15039,-0.00008
30.95000,-5.15865,-0.00007
31.00000,-5.16665,-0.00005
31.05000,-5.17519,-0.00007
31.10000,-5.18359,-0.00005
31.15000,-5.19172,-0.00005
31.20000,-5.20012,-0.00005
31.25000,-5.20852,-0.00005
31.30000,-5.21652,-0.00005
31.35000,-5.22505,-0.00008
31.40000,-5.23372,-0.00007
31.45000,-5.24185,-0.00007
31.50000,-5.24999,-0.00004
31.55000,-5.25865,-0.00008
31.60000,-5.26692,-0.00008
31.65000,-5.27519,-0.00006
31.70000,-5.28372,-0.00005
31.75000,-5.29212,-0.00008
31.80000,-5.30025,-0.00006
31.85000,-5.30852,-0.00005
31.90000,-5.31679,-0.00003
31.95000,-5.32519,-0.00006
32.00000,-5.33332,-0.00007
32.05000,-5.34159,-0.00009
32.10000,-5.35012,-0.00006
32.15000,-5.35852,-0.00005
32.20000,-5.36692,-0.00004
32.25000,-5.37532,-0.00005
32.30000,-5.38372,-0.00006
32.35000,-5.39199,-0.00008
32.40000,-5.40025,-0.00005
32.45000,-5.40865,-0.00006
32.50000,-5.41705,-0.00006
32.55000,-5.42519,-0.00007
32.60000,-5.43345,-0.00005
32.65000,-5.44199,-0.00005
32.70000,-5.45012,-0.00005
32.75000,-5.45839,-0.00007
32.80000,-5.46679,-0.00006
32.85000,-5.47505,-0.00006
32.90000,-5.48332,-0.00006
32.95000,-5.49172,-0.00007
33.00000,-5.50012,-0.00006
33.05000,-5.50852,-0.00008
33.10000,-5.51679,-0.00003
33.15000,-5.52519,-0.00005
33.20000,-5.53359,-0.00006
33.25000,-5.54199,-0.00004
33.30000,-5.55012,-0.00005
33.35000,-5.55879,-0.00006
33.40000,-5.56692,-0.00007
33.45000,-5.57505,-0.00005
33.50000,-5.58345,-0.00003
33.55000,-5.59185,-0.00007
33.60000,-5.59999,-0.00006
33.65000,-5.60825,-0.00008
33.70000,-5.61679,-0.00005
33.75000,-5.62505,-0.00004
33.80000,-5.63332,-0.00006
33.85000,-5.64199,-0.00005
33.90000,-5.65025,-0.00007
33.95000,-5.65852,-0.00006
34.00000,-5.66692,-0.00006
34.05000,-5.67532,-0.00008
34.10000,-5.68359,-0.00006
34.15000,-5.69199,-0.00005
34.20000,-5.69999,-0.00005
34.25000,-5.70852,-0.00005
34.30000,-5.71692,-0.00005
34.35000,-5.72492,-0.00004
34.40000,-5.73345,-0.00005
34.45000,-5.74185,-0.00007
34.50000,-5.74999,-0.00004
34.55000,-5.75839,-0.00008
34.60000,-5.76705,-0.00007
34.65000,-5.77519,-0.00007
34.70000,-5.78345,-0.00005
34.75000,-5.79199,-0.00008
34.80000,-5.80025,-0.00007
34.85000,-5.80852,-0.00006
34.90000,-5.81705,-0.00007
34.95000,-5.82532,-0.00008
35.00000,-5.83345,-0.00007
35.05000,-5.84185,-0.00008
35.10000,-5.85012,-0.00006
35.15000,-5.85852,-0.00005
35.20000,-5.86679,-0.00005
35.25000,-5.87492,-0.00005
35.30000,-5.88345,-0.00005
35.35000,-5.89185,-0.00004
35.40000,-5.90012,-0.00003
35.45000,-5.90839,-0.00007
35.50000,-5.91692,-0.00004
35.55000,-5.92532,-0.00008
35.60000,-5.93345,-0.00004
35.65000,-5.94199,-0.00006
35.70000,-5.95039,-0.00007
35.75000,-5.95839,-0.00007
35.80000,-5.96679,-0.00005
35.85000,-5.97532,-0.00005
35.90000,-5.98332,-0.00003
35.95000,-5.99159,-0.00006
36.00000,-6.00012,-0.00008
36.05000,-6.00825,-0.00008
36.10000,-6.01652,-0.00006
36.15000,-6.02505,-0.00007
36.20000,-6.03359,-0.00005
36.25000,-6.04199,-0.00005
36.30000,-6.05025,-0.00005
36.35000,-6.05852,-0.00005
36.40000,-6.06705,-0.00006
36.45000,-6.07532,-0.00007
36.50000,-6.08345,-0.00006
36.55000,-6.09199,-0.00007
36.60000,-6.10025,-0.00005
36.65000,-6.10839,-0.00006
36.70000,-6.11679,-0.00006
36.75000,-6.12519,-0.00005
36.80000,-6.13332,-0.00006
36.85000,-6.14158,-0.00007
36.90000,-6.15012,-0.00007
36.95000,-6.15852,-0.00006
37.00000,-6.16665,-0.00006
37.05000,-6.17519,-0.00006
37.10000,-6.18359,-0.00005
37.15000,-6.19185,-0.00005
37.20000,-6.20025,-0.00005
37.25000,-6.20865,-0.00006
37.30000,-6.21692,-0.00005
37.35000,-6.22519,-0.00006
37.40000,-6.23345,-0.00005
37.45000,-6.24185,-0.00005
37.50000,-6.25025,-0.00005
37.55000,-6.25825,-0.00008
37.60000,-6.26678,-0.00005
37.65000,-6.27518,-0.00005
37.70000,-6.28332,-0.00004
37.75000,-6.29172,-0.00005
37.80000,-6.30038,-0.00004
37.85000,-6.30852,-0.00006
37.90000,-6.31678,-0.00004
37.95000,-6.32545,-0.00007
38.00000,-6.33372,-0.00007
38.05000,-6.34198,-0.00007
38.10000,-6.35038,-0.00007
38.15000,-6.35865,-0.00007
38.20000,-6.36692,-0.00006
38.25000,-6.37518,-0.00004
38.30000,-6.38345,-0.00003
38.35000,-6.39185,-0.00006
38.40000,-6.40012,-0.00004
38.45000,-6.40825,-0.00008
38.50000,-6.41678,-0.00006
38.55000,-6.42518,-0.00007
38.60000,-6.43345,-0.00005
38.65000,-6.44185,-0.00005
38.70000,-6.45038,-0.00005
38.75000,-6.45865,-0.00007
38.80000,-6.46678,-0.00005
38.85000,-6.47532,-0.00007
38.90000,-6.48372,-0.00006
38.95000,-6.49172,-0.00006
39.00000,-6.49998,-0.00006
39.05000,-6.50865,-0.00008
39.10000,-6.51678,-0.00004
39.15000,-6.52492,-0.00006
39.20000,-6.53345,-0.00005
39.25000,-6.54172,-0.00006
39.30000,-6.54998,-0.00008
39.35000,-6.55838,-0.00006
39.40000,-6.56678,-0.00005
39.45000,-6.57518,-0.00005
39.50000,-6.58345,-0.00004
39.55000,-6.59172,-0.00007
39.60000,-6.60038,-0.00005
39.65000,-6.60865,-0.00005
39.70000,-6.61678,-0.00005
39.75000,-6.62532,-0.00005
39.80000,-6.63358,-0.00006
39.85000,-6.64158,-0.00006
39.90000,-6.64998,-0.00007
39.95000,-6.65852,-0.00006
40.00000,-6.66652,-0.00007
40.05000,-6.67478,-0.00007
40.10000,-6.68345,-0.00007
40.15000,-6.69185,-0.00006
40.20000,-6.70025,-0.00004
40.25000,-6.70865,-0.00006
40.30000,-6.71705,-0.00008
40.35000,-6.72518,-0.00007
40.40000,-6.73358,-0.00005
40.45000,-6.74185,-0.00005
40.50000,-6.75025,-0.00007
40.55000,-6.75852,-0.00007
40.60000,-6.76678,-0.00005
40.65000,-6.77532,-0.00005
40.70000,-6.78358,-0.00006
40.75000,-6.79172,-0.00005
40.80000,-6.80012,-0.00007
40.85000,-6.80852,-0.00005
40.90000,-6.81665,-0.00005
40.95000,-6.82505,-0.00007
41.00000,-6.83372,-0.00006
41.05000,-6.84185,-0.00008
41.10000,-6.85012,-0.00007
41.15000,-6.85865,-0.00006
41.20000,-6.86692,-0.00006
41.25000,-6.87518,-0.00005
41.30000,-6.88358,-0.00004
41.35000,-6.89198,-0.00006
41.40000,-6.90012,-0.00004
41.45000,-6.90852,-0.00006
41.50000,-6.91692,-0.00005
41.55000,-6.92532,-0.00005
41.60000,-6.93358,-0.00006
41.65000,-6.94172,-0.00006
41.70000,-6.95025,-0.00005
41.75000,-6.95865,-0.00006
41.80000,-6.96692,-0.00005
41.85000,-6.97518,-0.00005
41.90000,-6.98372,-0.00003
41.95000,-6.99198,-0.00007
42.00000,-7.00012,-0.00006
42.05000,-7.00865,-0.00007
42.10000,-7.01705,-0.00007
42.15000,-7.02505,-0.00003
42.20000,-7.03332,-0.00003
42.25000,-7.04198,-0.00006
42.30000,-7.04998,-0.00004
42.35000,-7.05825,-0.00007
42.40000,-7.06678,-0.00006
42.45000,-7.07505,-0.00006
42.50000,-7.08332,-0.00006
42.55000,-7.09172,-0.00007
42.60000,-7.10012,-0.00007
42.65000,-7.10852,-0.00005
42.70000,-7.11692,-0.00004
42.75000,-7.12518,-0.00006
42.80000,-7.13372,-0.00005
42.85000,-7.14185,-0.00007
42.90000,-7.14998,-0.00004
42.95000,-7.15865,-0.00007
43.00000,-7.16692,-0.00006
43.05000,-7.17492,-0.00007
43.10000,-7.18332,-0.00008
43.15000,-7.19185,-0.00005
43.20000,-7.19998,-0.00005
43.25000,-7.20825,-0.00007
43.30000,-7.21678,-0.00006
43.35000,-7.22505,-0.00006
43.40000,-7.23332,-0.00006
43.45000,-7.24172,-0.00007
43.50000,-7.25012,-0.00005
43.55000,-7.25852,-0.00007
43.60000,-7.26692,-0.00005
43.65000,-7.27532,-0.00005
43.70000,-7.28372,-0.00007
43.75000,-7.29198,-0.00007
43.80000,-7.30012,-0.00007
43.85000,-7.30865,-0.00006
43.90000,-7.31678,-0.00006
43.95000,-7.32478,-0.00005
44.00000,-7.33332,-0.00007
44.05000,-7.34172,-0.00008
44.10000,-7.34985,-0.00007
44.15000,-7.35838,-0.00007
44.20000,-7.36718,-0.00006
44.25000,-7.37532,-0.00008
44.30000,-7.38358,-0.00005
44.35000,-7.39212,-0.00007
44.40000,-7.40038,-0.00008
44.45000,-7.40852,-0.00006
44.50000,-7.41692,-0.00005
44.55000,-7.42532,-0.00008
44.60000,-7.43358,-0.00007
44.65000,-7.44185,-0.00006
44.70000,-7.45011,-0.00005
44.75000,-7.45865,-0.00006
44.80000,-7.46678,-0.00006
44.85000,-7.47492,-0.00006
44.90000,-7.48345,-0.00006
44.95000,-7.49185,-0.00007
45.00000,-7.50011,-0.00007
45.05000,-7.50851,-0.00008
45.10000,-7.51705,-0.00007
45.15000,-7.52532,-0.00008
45.20000,-7.53345,-0.00005
45.25000,-7.54185,-0.00004
45.30000,-7.55038,-0.00006
45.35000,-7.55838,-0.00006
45.40000,-7.56665,-0.00005
45.45000,-7.57518,-0.00008
45.50000,-7.58345,-0.00004
45.55000,-7.59171,-0.00008
45.60000,-7.60011,-0.00006
45.65000,-7.60838,-0.00004
45.70000,-7.61665,-0.00006
45.75000,-7.62505,-0.00008
45.80000,-7.63345,-0.00006
45.85000,-7.64185,-0.00006
45.90000,-7.65011,-0.00005
45.95000,-7.65838,-0.00006
46.00000,-7.66705,-0.00006
46.05000,-7.67531,-0.00009
46.10000,-7.68345,-0.00006
46.15000,-7.69198,-0.00005
46.20000,-7.70025,-0.00008
46.25000,-7.70825,-0.00006
46.30000,-7.71665,-0.00005
46.35000,-7.72531,-0.00006
46.40000,-7.73331,-0.00005
46.45000,-7.74158,-0.00008
46.50000,-7.75011,-0.00008
46.55000,-7.75851,-0.00008
46.60000,-7.76678,-0.00004
46.65000,-7.77518,-0.00003
46.70000,-7.78358,-0.00005
46.75000,-7.79198,-0.00004
46.80000,-7.80025,-0.00004
46.85000,-7.80851,-0.00005
46.90000,-7.81705,-0.00006
46.95000,-7.82531,-0.00007
47.00000,-7.83331,-0.00005
47.05000,-7.84198,-0.00008
47.10000,-7.85025,-0.00005
47.15000,-7.85838,-0.00006
47.20000,-7.86691,-0.00005
47.25000,-7.87518,-0.00004
47.30000,-7.88331,-0.00004
47.35000,-7.89171,-0.00007
47.40000,-7.90038,-0.00004
47.45000,-7.90851,-0.00006
47.50000,-7.91678,-0.00003
47.55000,-7.92531,-0.00006
47.60000,-7.93371,-0.00007
47.65000,-7.94198,-0.00006
47.70000,-7.95025,-0.00004
47.75000,-7.95865,-0.00006
47.80000,-7.96691,-0.00005
47.85000,-7.97518,-0.00004
47.90000,-7.98345,-0.00004
47.95000,-7.99185,-0.00006
48.00000,-7.99998,-0.00005
48.05000,-8.00825,-0.00008
48.09200,-8.01545,-0.00007