File: GFBaking/data/2_13PercentGluten/2_13gluten_4Point.is_flex_RawData/Specimen_RawData_1.csv
Time,Extension,Load
(sec),(mm),(N)
0.00000,-0.00027,0.00008
0.05000,-0.00173,0.00000
0.10000,-0.00693,0.00001
0.15000,-0.01627,0.00001
0.20000,-0.02680,0.00001
0.25000,-0.03667,0.00004
0.30000,-0.04627,0.00002
0.35000,-0.05573,0.00003
0.40000,-0.06467,0.00002
0.45000,-0.07347,0.00002
0.50000,-0.08240,0.00003
0.55000,-0.09093,0.00003
0.60000,-0.09933,0.00001
0.65000,-0.10800,0.00004
0.70000,-0.11653,0.00002
0.75000,-0.12480,0.00002
0.80000,-0.13320,0.00002
0.85000,-0.14187,0.00003
0.90000,-0.15013,0.00004
0.95000,-0.15840,0.00004
1.00000,-0.16680,0.00003
1.05000,-0.17547,0.00001
1.10000,-0.18360,0.00002
1.15000,-0.19187,0.00002
1.20000,-0.20040,0.00003
1.25000,-0.20867,0.00002
1.30000,-0.21680,0.00004
1.35000,-0.22520,0.00006
1.40000,-0.23373,0.00005
1.45000,-0.24187,0.00003
1.50000,-0.25027,0.00005
1.55000,-0.25867,0.00002
1.60000,-0.26707,0.00004
1.65000,-0.27520,0.00006
1.70000,-0.28360,0.00005
1.75000,-0.29227,0.00002
1.80000,-0.30040,0.00004
1.85000,-0.30853,0.00004
1.90000,-0.31707,0.00004
1.95000,-0.32533,0.00004
2.00000,-0.33360,0.00005
2.05000,-0.34200,0.00002
2.10000,-0.35040,0.00003
2.15000,-0.35867,0.00002
2.20000,-0.36680,0.00004
2.25000,-0.37507,0.00004
2.30000,-0.38360,0.00005
2.35000,-0.39200,0.00005
2.40000,-0.40013,0.00004
2.45000,-0.40867,0.00006
2.50000,-0.41707,0.00005
2.55000,-0.42507,0.00004
2.60000,-0.43360,0.00003
2.65000,-0.44213,0.00007
2.70000,-0.45027,0.00005
2.75000,-0.45853,0.00005
2.80000,-0.46693,0.00005
2.85000,-0.47507,0.00005
2.90000,-0.48333,0.00005
2.95000,-0.49173,0.00005
3.00000,-0.50000,0.00004
3.05000,-0.50840,0.00004
3.10000,-0.51680,0.00004
3.15000,-0.52507,0.00002
3.20000,-0.53360,0.00006
3.25000,-0.54187,0.00005
3.30000,-0.55000,0.00005
3.35000,-0.55853,0.00005
3.40000,-0.56707,0.00007
3.45000,-0.57520,0.00006
3.50000,-0.58360,0.00006
3.55000,-0.59213,0.00005
3.60000,-0.60013,0.00004
3.65000,-0.60840,0.00003
3.70000,-0.61693,0.00004
3.75000,-0.62520,0.00005
3.80000,-0.63333,0.00005
3.85000,-0.64173,0.00006
3.90000,-0.65027,0.00006
3.95000,-0.65853,0.00005
4.00000,-0.66693,0.00007
4.05000,-0.67533,0.00003
4.10000,-0.68360,0.00005
4.15000,-0.69186,0.00004
4.20000,-0.70026,0.00008
4.25000,-0.70880,0.00005
4.30000,-0.71706,0.00005
4.35000,-0.72520,0.00006
4.40000,-0.73373,0.00007
4.45000,-0.74200,0.00005
4.50000,-0.75026,0.00006
4.55000,-0.75853,0.00004
4.60000,-0.76693,0.00006
4.65000,-0.77520,0.00008
4.70000,-0.78346,0.00004
4.75000,-0.79200,0.00007
4.80000,-0.80040,0.00006
4.85000,-0.80853,0.00008
4.90000,-0.81693,0.00007
4.95000,-0.82546,0.00005
5.00000,-0.83360,0.00006
5.05000,-0.84200,0.00005
5.10000,-0.85040,0.00006
5.15000,-0.85880,0.00006
5.20000,-0.86693,0.00007
5.25000,-0.87533,0.00006
5.30000,-0.88373,0.00007
5.35000,-0.89200,0.00006
5.40000,-0.90013,0.00008
5.45000,-0.90853,0.00007
5.50000,-0.91706,0.00005
5.55000,-0.92533,0.00005
5.60000,-0.93360,0.00006
5.65000,-0.94200,0.00008
5.70000,-0.95053,0.00007
5.75000,-0.95853,0.00008
5.80000,-0.96693,0.00007
5.85000,-0.97546,0.00007
5.90000,-0.98346,0.00006
5.95000,-0.99186,0.00008
6.00000,-1.00040,0.00008
6.05000,-1.00853,0.00004
6.10000,-1.01680,0.00006
6.15000,-1.02520,0.00005
6.20000,-1.03333,0.00006
6.25000,-1.04160,0.00005
6.30000,-1.05000,0.00007
6.35000,-1.05840,0.00005
6.40000,-1.06693,0.00008
6.45000,-1.07520,0.00008
6.50000,-1.08333,0.00009
6.55000,-1.09200,0.00004
6.60000,-1.10040,0.00006
6.65000,-1.10853,0.00006
6.70000,-1.11693,0.00009
6.75000,-1.12533,0.00007
6.80000,-1.13333,0.00007
6.85000,-1.14173,0.00006
6.90000,-1.15026,0.00007
6.95000,-1.15840,0.00007
7.00000,-1.16653,0.00007
7.05000,-1.17520,0.00005
7.10000,-1.18360,0.00008
7.15000,-1.19186,0.00007
7.20000,-1.20026,0.00008
7.25000,-1.20866,0.00007
7.30000,-1.21693,0.00009
7.35000,-1.22520,0.00009
7.40000,-1.23360,0.00009
7.45000,-1.24213,0.00007
7.50000,-1.25053,0.00006
7.55000,-1.25866,0.00006
7.60000,-1.26706,0.00009
7.65000,-1.27533,0.00007
7.70000,-1.28346,0.00008
7.75000,-1.29186,0.00008
7.80000,-1.30026,0.00009
7.85000,-1.30853,0.00009
7.90000,-1.31680,0.00007
7.95000,-1.32546,0.00007
8.00000,-1.33373,0.00007
8.05000,-1.34200,0.00007
8.10000,-1.35040,0.00007
8.15000,-1.35880,0.00007
8.20000,-1.36680,0.00008
8.25000,-1.37520,0.00009
8.30000,-1.38373,0.00008
8.35000,-1.39213,0.00008
8.40000,-1.40026,0.00009
8.45000,-1.40853,0.00009
8.50000,-1.41693,0.00010
8.55000,-1.42520,0.00006
8.60000,-1.43346,0.00006
8.65000,-1.44173,0.00009
8.70000,-1.45026,0.00009
8.75000,-1.45853,0.00010
8.80000,-1.46680,0.00008
8.85000,-1.47520,0.00009
8.90000,-1.48373,0.00009
8.95000,-1.49186,0.00010
9.00000,-1.50013,0.00009
9.05000,-1.50866,0.00008
9.10000,-1.51680,0.00009
9.15000,-1.52506,0.00009
9.20000,-1.53373,0.00009
9.25000,-1.54186,0.00009
9.30000,-1.55013,0.00008
9.35000,-1.55853,0.00008
9.40000,-1.56680,0.00010
9.45000,-1.57506,0.00008
9.50000,-1.58346,0.00008
9.55000,-1.59173,0.00007
9.60000,-1.60026,0.00010
9.65000,-1.60853,0.00010
9.70000,-1.61666,0.00010
9.75000,-1.62533,0.00010
9.80000,-1.63373,0.00009
9.85000,-1.64173,0.00009
9.90000,-1.65026,0.00009
9.95000,-1.65880,0.00010
10.00000,-1.66680,0.00009
10.05000,-1.67506,0.00008
10.10000,-1.68373,0.00009
10.15000,-1.69186,0.00010
10.20000,-1.69986,0.00009
10.25000,-1.70840,0.00008
10.30000,-1.71693,0.00010
10.35000,-1.72520,0.00012
10.40000,-1.73360,0.00011
10.45000,-1.74200,0.00009
10.50000,-1.75026,0.00012
10.55000,-1.75866,0.00009
10.60000,-1.76706,0.00010
10.65000,-1.77546,0.00009
10.70000,-1.78373,0.00011
10.75000,-1.79186,0.00012
10.80000,-1.80040,0.00012
10.85000,-1.80866,0.00012
10.90000,-1.81680,0.00012
10.95000,-1.82520,0.00010
11.00000,-1.83373,0.00011
11.05000,-1.84173,0.00008
11.10000,-1.85013,0.00010
11.15000,-1.85866,0.00012
11.20000,-1.86693,0.00012
11.25000,-1.87520,0.00010
11.30000,-1.88360,0.00013
11.35000,-1.89213,0.00011
11.40000,-1.90040,0.00011
11.45000,-1.90866,0.00014
11.50000,-1.91706,0.00012
11.55000,-1.92533,0.00008
11.60000,-1.93346,0.00012
11.65000,-1.94173,0.00013
11.70000,-1.95026,0.00013
11.75000,-1.95853,0.00014
11.80000,-1.96680,0.00012
11.85000,-1.97520,0.00012
11.90000,-1.98360,0.00013
11.95000,-1.99200,0.00012
12.00000,-2.00026,0.00014
12.05000,-2.00880,0.00010
12.10000,-2.01706,0.00013
12.15000,-2.02520,0.00014
12.20000,-2.03373,0.00014
12.25000,-2.04226,0.00011
12.30000,-2.05026,0.00015
12.35000,-2.05853,0.00014
12.40000,-2.06706,0.00013
12.45000,-2.07520,0.00015
12.50000,-2.08346,0.00015
12.55000,-2.09186,0.00013
12.60000,-2.10013,0.00014
12.65000,-2.10826,0.00013
12.70000,-2.11679,0.00013
12.75000,-2.12519,0.00015
12.80000,-2.13346,0.00015
12.85000,-2.14186,0.00016
12.90000,-2.15013,0.00018
12.95000,-2.15866,0.00016
13.00000,-2.16706,0.00016
13.05000,-2.17519,0.00013
13.10000,-2.18359,0.00015
13.15000,-2.19213,0.00016
13.20000,-2.20013,0.00016
13.25000,-2.20839,0.00019
13.30000,-2.21693,0.00019
13.35000,-2.22506,0.00018
13.40000,-2.23319,0.00015
13.45000,-2.24186,0.00016
13.50000,-2.25026,0.00017
13.55000,-2.25839,0.00016
13.60000,-2.26693,0.00016
13.65000,-2.27533,0.00019
13.70000,-2.28359,0.00018
13.75000,-2.29199,0.00018
13.80000,-2.30026,0.00016
13.85000,-2.30879,0.00017
13.90000,-2.31706,0.00016
13.95000,-2.32519,0.00018
14.00000,-2.33373,0.00019
14.05000,-2.34199,0.00019
14.10000,-2.35013,0.00019
14.15000,-2.35853,0.00021
14.20000,-2.36706,0.00019
14.25000,-2.37519,0.00021
14.30000,-2.38359,0.00017
14.35000,-2.39213,0.00020
14.40000,-2.40039,0.00018
14.45000,-2.40866,0.00020
14.50000,-2.41706,0.00018
14.55000,-2.42546,0.00021
14.60000,-2.43359,0.00020
14.65000,-2.44199,0.00022
14.70000,-2.45053,0.00018
14.75000,-2.45866,0.00020
14.80000,-2.46693,0.00020
14.85000,-2.47519,0.00022
14.90000,-2.48359,0.00022
14.95000,-2.49186,0.00023
15.00000,-2.50013,0.00020
15.05000,-2.50839,0.00019
15.10000,-2.51693,0.00021
15.15000,-2.52506,0.00028
15.20000,-2.53333,0.00022
15.25000,-2.54186,0.00022
15.30000,-2.55026,0.00023
15.35000,-2.55853,0.00023
15.40000,-2.56693,0.00025
15.45000,-2.57546,0.00023
15.50000,-2.58346,0.00022
15.55000,-2.59186,0.00018
15.60000,-2.60026,0.00020
15.65000,-2.60839,0.00023
15.70000,-2.61666,0.00027
15.75000,-2.62506,0.00022
15.80000,-2.63333,0.00025
15.85000,-2.64173,0.00019
15.90000,-2.65013,0.00023
15.95000,-2.65853,0.00019
16.00000,-2.66693,0.00027
16.05000,-2.67533,0.00022
16.10000,-2.68346,0.00026
16.15000,-2.69199,0.00023
16.20000,-2.70039,0.00025
16.25000,-2.70853,0.00022
16.30000,-2.71693,0.00027
16.35000,-2.72546,0.00022
16.40000,-2.73346,0.00027
16.45000,-2.74173,0.00023
16.50000,-2.75026,0.00027
16.55000,-2.75839,0.00020
16.60000,-2.76653,0.00024
16.65000,-2.77519,0.00022
16.70000,-2.78346,0.00029
16.75000,-2.79173,0.00024
16.80000,-2.80013,0.00029
16.85000,-2.80853,0.00024
16.90000,-2.81679,0.00027
16.95000,-2.82519,0.00022
17.00000,-2.83346,0.00024
17.05000,-2.84199,0.00021
17.10000,-2.85026,0.00027
17.15000,-2.85839,0.00025
17.20000,-2.86706,0.00029
17.25000,-2.87533,0.00023
17.30000,-2.88346,0.00024
17.35000,-2.89186,0.00025
17.40000,-2.90026,0.00027
17.45000,-2.90839,0.00026
17.50000,-2.91679,0.00024
17.55000,-2.92546,0.00026
17.60000,-2.93373,0.00023
17.65000,-2.94199,0.00027
17.70000,-2.95026,0.00027
17.75000,-2.95879,0.00025
17.80000,-2.96706,0.00026
17.85000,-2.97533,0.00028
17.90000,-2.98386,0.00023
17.95000,-2.99213,0.00022
18.00000,-3.00026,0.00025
18.05000,-3.00866,0.00024
18.10000,-3.01693,0.00026
18.15000,-3.02519,0.00024
18.20000,-3.03333,0.00027
18.25000,-3.04173,0.00023
18.30000,-3.05026,0.00028
18.35000,-3.05853,0.00027
18.40000,-3.06679,0.00023
18.45000,-3.07533,0.00024
18.50000,-3.08373,0.00024
18.55000,-3.09186,0.00025
18.60000,-3.10026,0.00027
18.65000,-3.10879,0.00025
18.70000,-3.11679,0.00027
18.75000,-3.12519,0.00024
18.80000,-3.13373,0.00029
18.85000,-3.14173,0.00025
18.90000,-3.14999,0.00027
18.95000,-3.15839,0.00024
19.00000,-3.16666,0.00027
19.05000,-3.17506,0.00023
19.10000,-3.18333,0.00025
19.15000,-3.19173,0.00021
19.20000,-3.20013,0.00027
19.25000,-3.20839,0.00022
19.30000,-3.21666,0.00028
19.35000,-3.22546,0.00025
19.40000,-3.23386,0.00026
19.45000,-3.24186,0.00028
19.50000,-3.25039,0.00028
19.55000,-3.25879,0.00023
19.60000,-3.26679,0.00024
19.65000,-3.27519,0.00024
19.70000,-3.28373,0.00030
19.75000,-3.29173,0.00025
19.80000,-3.29986,0.00026
19.85000,-3.30853,0.00022
19.90000,-3.31693,0.00026
19.95000,-3.32519,0.00023
20.00000,-3.33359,0.00028
20.05000,-3.34199,0.00023
20.10000,-3.35039,0.00024
20.15000,-3.35866,0.00024
20.20000,-3.36706,0.00023
20.25000,-3.37546,0.00023
20.30000,-3.38373,0.00023
20.35000,-3.39186,0.00021
20.40000,-3.40039,0.00025
20.45000,-3.40866,0.00021
20.50000,-3.41679,0.00025
20.55000,-3.42519,0.00020
20.60000,-3.43359,0.00023
20.65000,-3.44172,0.00020
20.70000,-3.45012,0.00022
20.75000,-3.45866,0.00020
20.80000,-3.46706,0.00021
20.85000,-3.47519,0.00019
20.90000,-3.48359,0.00022
20.95000,-3.49212,0.00018
21.00000,-3.50026,0.00022
21.05000,-3.50866,0.00018
21.10000,-3.51706,0.00021
21.15000,-3.52532,0.00018
21.20000,-3.53346,0.00018
21.25000,-3.54172,0.00018
21.30000,-3.55026,0.00016
21.35000,-3.55839,0.00016
21.40000,-3.56666,0.00014
21.45000,-3.57492,0.00015
21.50000,-3.58359,0.00016
21.55000,-3.59186,0.00015
21.60000,-3.60012,0.00016
21.65000,-3.60879,0.00017
21.70000,-3.61719,0.00016
21.75000,-3.62532,0.00013
21.80000,-3.63372,0.00017
21.85000,-3.64226,0.00012
21.90000,-3.65026,0.00015
21.95000,-3.65852,0.00013
22.00000,-3.66706,0.00013
22.05000,-3.67506,0.00011
22.10000,-3.68332,0.00012
22.15000,-3.69186,0.00014
22.20000,-3.70012,0.00013
22.25000,-3.70839,0.00012
22.30000,-3.71679,0.00012
22.35000,-3.72519,0.00014
22.40000,-3.73359,0.00015
22.45000,-3.74199,0.00013
22.50000,-3.75012,0.00015
22.55000,-3.75879,0.00012
22.60000,-3.76706,0.00012
22.65000,-3.77519,0.00013
22.70000,-3.78359,0.00013
22.75000,-3.79212,0.00011
22.80000,-3.80012,0.00010
22.85000,-3.80852,0.00012
22.90000,-3.81692,0.00013
22.95000,-3.82506,0.00012
23.00000,-3.83319,0.00010
23.05000,-3.84172,0.00010
23.10000,-3.85012,0.00011
23.15000,-3.85852,0.00012
23.20000,-3.86679,0.00009
23.25000,-3.87532,0.00012
23.30000,-3.88372,0.00012
23.35000,-3.89199,0.00010
23.40000,-3.90026,0.00011
23.45000,-3.90879,0.00011
23.50000,-3.91706,0.00010
23.55000,-3.92519,0.00010
23.60000,-3.93372,0.00010
23.65000,-3.94186,0.00013
23.70000,-3.94999,0.00014
23.75000,-3.95839,0.00010
23.80000,-3.96692,0.00011
23.85000,-3.97506,0.00012
23.90000,-3.98346,0.00009
23.95000,-3.99199,0.00010
24.00000,-4.00026,0.00011
24.05000,-4.00852,0.00008
24.10000,-4.01692,0.00010
24.15000,-4.02546,0.00009
24.20000,-4.03359,0.00009
24.25000,-4.04199,0.00012
24.30000,-4.05052,0.00009
24.35000,-4.05879,0.00008
24.40000,-4.06692,0.00008
24.45000,-4.07519,0.00010
24.50000,-4.08372,0.00010
24.55000,-4.09199,0.00007
24.60000,-4.10012,0.00010
24.65000,-4.10852,0.00008
24.70000,-4.11692,0.00008
24.75000,-4.12519,0.00008
24.80000,-4.13346,0.00008
24.85000,-4.14212,0.00009
24.90000,-4.15039,0.00007
24.95000,-4.15839,0.00010
25.00000,-4.16692,0.00007
25.05000,-4.17559,0.00007
25.10000,-4.18359,0.00007
25.15000,-4.19186,0.00010
25.20000,-4.20039,0.00008
25.25000,-4.20852,0.00010
25.30000,-4.21679,0.00007
25.35000,-4.22519,0.00007
25.40000,-4.23332,0.00008
25.45000,-4.24159,0.00008
25.50000,-4.24999,0.00007
25.55000,-4.25839,0.00006
25.60000,-4.26692,0.00009
25.65000,-4.27519,0.00008
25.70000,-4.28346,0.00009
25.75000,-4.29212,0.00009
25.80000,-4.30039,0.00007
25.85000,-4.30852,0.00008
25.90000,-4.31706,0.00009
25.95000,-4.32546,0.00007
26.00000,-4.33346,0.00008
26.05000,-4.34172,0.00007
26.10000,-4.35039,0.00008
26.15000,-4.35852,0.00009
26.20000,-4.36666,0.00008
26.25000,-4.37519,0.00007
26.30000,-4.38359,0.00010
26.35000,-4.39186,0.00010
26.40000,-4.40026,0.00007
26.45000,-4.40866,0.00006
26.50000,-4.41706,0.00007
26.55000,-4.42519,0.00006
26.60000,-4.43359,0.00006
26.65000,-4.44212,0.00008
26.70000,-4.45026,0.00006
26.75000,-4.45852,0.00007
26.80000,-4.46706,0.00009
26.85000,-4.47532,0.00008
26.90000,-4.48346,0.00008
26.95000,-4.49186,0.00007
27.00000,-4.50026,0.00007
27.05000,-4.50839,0.00004
27.10000,-4.51666,0.00005
27.15000,-4.52532,0.00007
27.20000,-4.53359,0.00005
27.25000,-4.54186,0.00007
27.30000,-4.55039,0.00006
27.35000,-4.55892,0.00005
27.40000,-4.56706,0.00006
27.45000,-4.57532,0.00005
27.50000,-4.58372,0.00006
27.55000,-4.59199,0.00003
27.60000,-4.60012,0.00005
27.65000,-4.60852,0.00005
27.70000,-4.61692,0.00005
27.75000,-4.62519,0.00006
27.80000,-4.63346,0.00006
27.85000,-4.64172,0.00004
27.90000,-4.65039,0.00006
27.95000,-4.65852,0.00006
28.00000,-4.66679,0.00004
28.05000,-4.67532,0.00002
28.10000,-4.68372,0.00004
28.15000,-4.69186,0.00006
28.20000,-4.70026,0.00004
28.25000,-4.70892,0.00004
28.30000,-4.71692,0.00004
28.35000,-4.72519,0.00006
28.40000,-4.73372,0.00005
28.45000,-4.74185,0.00004
28.50000,-4.75012,0.00003
28.55000,-4.75852,0.00002
28.60000,-4.76679,0.00004
28.65000,-4.77506,0.00004
28.70000,-4.78346,0.00002
28.75000,-4.79185,0.00005
28.80000,-4.80039,0.00004
28.85000,-4.80866,0.00003
28.90000,-4.81679,0.00005
28.95000,-4.82532,0.00003
29.00000,-4.83359,0.00003
29.05000,-4.84172,0.00002
29.10000,-4.85025,0.00003
29.15000,-4.85865,0.00004
29.20000,-4.86679,0.00002
29.25000,-4.87506,0.00003
29.30000,-4.88359,0.00002
29.35000,-4.89185,0.00004
29.40000,-4.89999,0.00003
29.45000,-4.90852,0.00001
29.50000,-4.91679,0.00003
29.55000,-4.92505,0.00001
29.60000,-4.93345,0.00002
29.65000,-4.94185,0.00005
29.70000,-4.95025,0.00005
29.75000,-4.95852,0.00003
29.80000,-4.96692,0.00004
29.85000,-4.97545,0.00003
29.90000,-4.98372,0.00003
29.95000,-4.99185,0.00003
30.00000,-5.00039,0.00002
30.05000,-5.00865,0.00002
30.10000,-5.01679,0.00002
30.15000,-5.02505,0.00002
30.20000,-5.03359,0.00004
30.25000,-5.04172,0.00004
30.30000,-5.05012,0.00002
30.35000,-5.05865,0.00004
30.40000,-5.06705,0.00002
30.45000,-5.07519,0.00003
30.50000,-5.08359,0.00004
30.55000,-5.09212,0.00002
30.60000,-5.10025,0.00002
30.65000,-5.10865,0.00003
30.70000,-5.11719,0.00003
30.75000,-5.12545,0.00001
30.80000,-5.13359,0.00003
30.85000,-5.14185,0.00004
30.90000,-5.15025,0.00005
30.95000,-5.15865,0.00003
31.00000,-5.16692,0.00003
31.05000,-5.17505,-0.00001
31.10000,-5.18359,0.00002
31.15000,-5.19185,0.00003
31.20000,-5.20012,0.00003
31.25000,-5.20865,0.00002
31.30000,-5.21719,0.00002
31.35000,-5.22519,0.00000
31.40000,-5.23359,0.00003
31.45000,-5.24225,0.00001
31.50000,-5.25025,0.00002
31.55000,-5.25852,0.00002
31.60000,-5.26692,0.00002
31.65000,-5.27519,0.00002
31.70000,-5.28345,0.00002
31.75000,-5.29172,0.00000
31.80000,-5.29999,0.00002
31.85000,-5.30839,0.00002
31.90000,-5.31679,0.00002
31.95000,-5.32505,0.00003
32.00000,-5.33359,0.00002
32.05000,-5.34199,0.00001
32.10000,-5.35012,0.00002
32.15000,-5.35865,0.00003
32.20000,-5.36705,0.00002
32.25000,-5.37519,0.00002
32.30000,-5.38359,0.00001
32.35000,-5.39212,0.00001
32.40000,-5.40012,0.00001
32.45000,-5.40839,0.00001
32.50000,-5.41692,0.00000
32.55000,-5.42505,-0.00001
32.60000,-5.43319,0.00001
32.65000,-5.44185,0.00001
32.70000,-5.45012,0.00003
32.75000,-5.45839,0.00004
32.80000,-5.46679,0.00003
32.85000,-5.47532,0.00003
32.90000,-5.48359,0.00003
32.95000,-5.49185,0.00004
33.00000,-5.50025,0.00002
33.05000,-5.50879,-0.00001
33.10000,-5.51705,-0.00001
33.15000,-5.52519,0.00000
33.20000,-5.53372,0.00003
33.25000,-5.54212,0.00002
33.30000,-5.55025,0.00001
33.35000,-5.55852,0.00003
33.40000,-5.56692,0.00002
33.45000,-5.57519,0.00001
33.50000,-5.58345,0.00002
33.55000,-5.59199,0.00000
33.60000,-5.60039,-0.00001
33.65000,-5.60865,0.00003
33.70000,-5.61692,0.00002
33.75000,-5.62545,0.00002
33.80000,-5.63372,0.00001
33.85000,-5.64199,0.00003
33.90000,-5.65052,0.00000
33.95000,-5.65879,0.00000
34.00000,-5.66692,0.00001
34.05000,-5.67519,-0.00001
34.10000,-5.68359,0.00001
34.15000,-5.69185,0.00003
34.20000,-5.69999,0.00000
34.25000,-5.70839,0.00002
34.30000,-5.71679,0.00002
34.35000,-5.72505,0.00000
34.40000,-5.73332,-0.00001
34.45000,-5.74185,0.00000
34.50000,-5.75039,0.00003
34.55000,-5.75839,0.00000
34.60000,-5.76692,0.00002
34.65000,-5.77545,0.00000
34.70000,-5.78345,0.00002
34.75000,-5.79185,0.00003
34.80000,-5.80025,0.00003
34.85000,-5.80852,0.00002
34.90000,-5.81665,0.00001
34.95000,-5.82505,0.00002
35.00000,-5.83332,0.00001
35.05000,-5.84159,0.00000
35.10000,-5.84999,-0.00001
35.15000,-5.85839,0.00000
35.20000,-5.86692,0.00002
35.25000,-5.87532,0.00002
35.30000,-5.88359,0.00000
35.35000,-5.89212,0.00001
35.40000,-5.90052,0.00000
35.45000,-5.90865,0.00001
35.50000,-5.91705,0.00000
35.55000,-5.92559,-0.00002
35.60000,-5.93345,0.00000
35.65000,-5.94185,0.00001
35.70000,-5.95039,0.00002
35.75000,-5.95839,0.00001
35.80000,-5.96665,-0.00001
35.85000,-5.97519,0.00001
35.90000,-5.98359,0.00001
35.95000,-5.99185,0.00002
36.00000,-6.00025,0.00001
36.05000,-6.00865,0.00000
36.10000,-6.01692,0.00000
36.15000,-6.02532,0.00003
36.20000,-6.03372,0.00002
36.25000,-6.04225,0.00000
36.30000,-6.05039,0.00000
36.35000,-6.05852,0.00001
36.40000,-6.06719,0.00001
36.45000,-6.07532,-0.00001
36.50000,-6.08345,0.00000
36.55000,-6.09185,0.00000
36.60000,-6.10025,0.00002
36.65000,-6.10839,0.00001
36.70000,-6.11679,0.00000
36.75000,-6.12532,0.00002
36.80000,-6.13372,0.00002
36.85000,-6.14198,0.00002
36.90000,-6.15025,0.00001
36.95000,-6.15892,0.00000
37.00000,-6.16705,0.00001
37.05000,-6.17532,0.00000
37.10000,-6.18372,0.00000
37.15000,-6.19198,0.00000
37.20000,-6.20012,0.00002
37.25000,-6.20852,0.00001
37.30000,-6.21692,-0.00001
37.35000,-6.22519,0.00001
37.40000,-6.23332,0.00002
37.45000,-6.24172,-0.00001
37.50000,-6.25025,0.00002
37.55000,-6.25852,-0.00001
37.60000,-6.26678,-0.00001
37.65000,-6.27532,0.00000
37.70000,-6.28358,0.00000
37.75000,-6.29185,0.00002
37.80000,-6.30012,0.00001
37.85000,-6.30878,0.00001
37.90000,-6.31692,0.00000
37.95000,-6.32518,0.00002
38.00000,-6.33358,0.00001
38.05000,-6.34185,0.00000
38.10000,-6.34998,0.00000
38.15000,-6.35838,-0.00001
38.20000,-6.36678,0.00001
38.25000,-6.37505,0.00000
38.30000,-6.38345,-0.00001
38.35000,-6.39172,-0.00001
38.40000,-6.40025,0.00000
38.45000,-6.40865,0.00003
38.50000,-6.41678,0.00001
38.55000,-6.42532,-0.00003
38.60000,-6.43372,0.00000
38.65000,-6.44185,-0.00001
38.70000,-6.45025,0.00002
38.75000,-6.45878,0.00000
38.80000,-6.46678,0.00001
38.85000,-6.47505,0.00001
38.90000,-6.48358,0.00000
38.95000,-6.49172,0.00000
39.00000,-6.49985,-0.00002
39.05000,-6.50838,-0.00002
39.10000,-6.51678,0.00001
39.15000,-6.52518,0.00001
39.20000,-6.53358,0.00000
39.25000,-6.54212,0.00000
39.30000,-6.55038,-0.00001
39.35000,-6.55865,0.00000
39.40000,-6.56705,-0.00001
39.45000,-6.57545,0.00000
39.50000,-6.58372,0.00000
39.55000,-6.59198,-0.00002
39.60000,-6.60038,0.00001
39.65000,-6.60878,0.00000
39.70000,-6.61692,0.00000
39.75000,-6.62518,0.00000
39.80000,-6.63358,0.00001
39.85000,-6.64185,0.00001
39.90000,-6.65025,0.00001
39.95000,-6.65865,0.00000
40.00000,-6.66705,-0.00001
40.05000,-6.67532,-0.00002
40.10000,-6.68358,0.00000
40.15000,-6.69212,-0.00002
40.20000,-6.70038,0.00000
40.25000,-6.70865,-0.00002
40.30000,-6.71705,0.00000
40.35000,-6.72532,0.00000
40.40000,-6.73358,0.00001
40.45000,-6.74185,0.00001
40.50000,-6.75025,-0.00001
40.55000,-6.75838,-0.00002
40.60000,-6.76665,-0.00001
40.65000,-6.77505,-0.00002
40.70000,-6.78358,0.00001
40.75000,-6.79185,0.00001
40.80000,-6.80012,0.00000
40.85000,-6.80865,0.00000
40.90000,-6.81705,-0.00001
40.95000,-6.82518,0.00001
41.00000,-6.83358,0.00001
41.05000,-6.84225,-0.00002
41.10000,-6.85025,0.00000
41.15000,-6.85838,0.00000
41.20000,-6.86692,0.00001
41.25000,-6.87518,0.00000
41.30000,-6.88345,0.00002
41.35000,-6.89172,-0.00002
41.40000,-6.89998,-0.00003
41.45000,-6.90825,-0.00003
41.50000,-6.91678,-0.00003
41.55000,-6.92518,0.00000
41.60000,-6.93372,0.00000
41.65000,-6.94198,0.00002
41.70000,-6.95012,0.00000
41.75000,-6.95865,0.00001
41.80000,-6.96705,0.00000
41.85000,-6.97505,-0.00001
41.90000,-6.98358,-0.00001
41.95000,-6.99212,-0.00002
42.00000,-7.00012,-0.00002
42.05000,-7.00838,-0.00002
42.10000,-7.01692,-0.00003
42.15000,-7.02505,-0.00001
42.20000,-7.03332,-0.00002
42.25000,-7.04185,-0.00002
42.30000,-7.05012,0.00000
42.35000,-7.05838,-0.00001
42.40000,-7.06678,-0.00001
42.45000,-7.07532,0.00000
42.50000,-7.08372,-0.00001
42.55000,-7.09198,-0.00003
42.60000,-7.10038,-0.00001
42.65000,-7.10865,0.00001
42.70000,-7.11692,0.00000
42.75000,-7.12518,0.00002
42.80000,-7.13372,-0.00001
42.85000,-7.14198,0.00001
42.90000,-7.15012,0.00001
42.95000,-7.15838,-0.00001
43.00000,-7.16678,0.00001
43.05000,-7.17492,-0.00002
43.10000,-7.18332,-0.00002
43.15000,-7.19198,0.00001
43.20000,-7.20038,-0.00001
43.25000,-7.20865,0.00001
43.30000,-7.21705,0.00001
43.35000,-7.22558,0.00000
43.40000,-7.23372,0.00000
43.45000,-7.24198,0.00000
43.50000,-7.25038,0.00000
43.55000,-7.25865,-0.00002
43.60000,-7.26692,0.00001
43.65000,-7.27518,0.00000
43.70000,-7.28372,0.00000
43.75000,-7.29185,0.00001
43.80000,-7.30012,0.00002
43.85000,-7.30852,-0.00001
43.90000,-7.31705,0.00003
43.95000,-7.32518,0.00001
44.00000,-7.33345,0.00000
44.05000,-7.34198,-0.00002
44.10000,-7.35038,-0.00001
44.15000,-7.35852,0.00002
44.20000,-7.36692,0.00002
44.25000,-7.37545,0.00001
44.30000,-7.38358,0.00001
44.35000,-7.39185,0.00001
44.40000,-7.40038,0.00002
44.45000,-7.40852,0.00000
44.50000,-7.41678,0.00001
44.55000,-7.42505,-0.00001
44.60000,-7.43332,-0.00001
44.65000,-7.44172,-0.00001
44.70000,-7.45011,-0.00002
44.75000,-7.45851,0.00000
44.80000,-7.46705,0.00001
44.85000,-7.47532,0.00002
44.90000,-7.48345,0.00001
44.95000,-7.49198,0.00002
45.00000,-7.50038,0.00000
45.05000,-7.50851,-0.00001
45.10000,-7.51691,-0.00001
45.15000,-7.52545,0.00000
45.20000,-7.53345,0.00002
45.25000,-7.54171,0.00000
45.30000,-7.55038,0.00002
45.35000,-7.55838,-0.00001
45.40000,-7.56665,0.00000
45.45000,-7.57505,0.00000
45.50000,-7.58358,0.00002
45.55000,-7.59185,0.00000
45.60000,-7.60025,0.00001
45.65000,-7.60865,0.00000
45.70000,-7.61691,0.00001
45.75000,-7.62518,0.00003
45.80000,-7.63358,0.00002
45.85000,-7.64211,0.00001
45.90000,-7.65038,0.00001
45.95000,-7.65851,0.00002
46.00000,-7.66691,0.00001
46.05000,-7.67518,-0.00001
46.10000,-7.68345,0.00001
46.15000,-7.69171,0.00000
46.20000,-7.70025,0.00002
46.25000,-7.70851,0.00001
46.30000,-7.71678,0.00000
46.35000,-7.72545,0.00002
46.40000,-7.73358,0.00001
46.45000,-7.74171,0.00002
46.50000,-7.75025,0.00003
46.55000,-7.75878,-0.00001
46.60000,-7.76705,0.00000
46.65000,-7.77531,0.00002
46.70000,-7.78385,0.00002
46.75000,-7.79198,0.00001
46.80000,-7.80025,0.00002
46.85000,-7.80865,0.00004
46.90000,-7.81691,0.00003
46.95000,-7.82518,0.00000
47.00000,-7.83345,0.00002
47.05000,-7.84171,0.00000
47.10000,-7.85025,0.00002
47.15000,-7.85865,0.00003
47.20000,-7.86691,0.00003
47.25000,-7.87545,0.00001
47.30000,-7.88371,0.00002
47.35000,-7.89185,0.00001
47.40000,-7.90025,0.00003
47.45000,-7.90878,0.00000
47.50000,-7.91678,0.00002
47.55000,-7.92518,0.00000
47.60000,-7.93358,0.00000
47.65000,-7.94171,0.00003
47.70000,-7.95011,0.00001
47.75000,-7.95851,0.00001
47.80000,-7.96678,0.00003
47.85000,-7.97505,0.00002
47.90000,-7.98345,0.00000
47.95000,-7.99185,0.00001
48.00000,-8.00025,0.00001
48.05000,-8.00865,-0.00001
48.10000,-8.01678,0.00002
48.15000,-8.02531,0.00001
48.20000,-8.03371,0.00002
48.25000,-8.04185,0.00002
48.30000,-8.05025,0.00003
48.32600,-8.05478,0.00002