File: GFBaking/data/1TspPectin/1TspPectin_2.is_comp_RawData/Specimen_RawData_2.csv
Time,Extension,Load
(sec),(mm),(N)
0.00000,-0.00013,0.01982
0.10000,-0.00587,0.01745
0.20000,-0.02533,0.00742
0.30000,-0.04560,-0.00161
0.40000,-0.06440,-0.00947
0.50000,-0.08187,-0.01658
0.60000,-0.09920,-0.02328
0.70000,-0.11627,-0.02886
0.80000,-0.13320,-0.03560
0.90000,-0.14987,-0.04297
1.00000,-0.16693,-0.04772
1.10000,-0.18333,-0.05514
1.20000,-0.19987,-0.06194
1.30000,-0.21680,-0.06983
1.40000,-0.23307,-0.07721
1.50000,-0.24987,-0.08844
1.60000,-0.26653,-0.09715
1.70000,-0.28333,-0.10474
1.80000,-0.29987,-0.11511
1.90000,-0.31693,-0.12441
2.00000,-0.33333,-0.13512
2.10000,-0.35000,-0.14792
2.20000,-0.36680,-0.16047
2.30000,-0.38307,-0.17107
2.40000,-0.40000,-0.18576
2.50000,-0.41653,-0.20001
2.60000,-0.43320,-0.21621
2.70000,-0.45000,-0.22481
2.80000,-0.46680,-0.24038
2.90000,-0.48333,-0.25877
3.00000,-0.50013,-0.27583
3.10000,-0.51680,-0.29336
3.20000,-0.53333,-0.31157
3.30000,-0.55027,-0.33309
3.40000,-0.56667,-0.35389
3.50000,-0.58333,-0.37338
3.60000,-0.60013,-0.39766
3.70000,-0.61653,-0.42035
3.80000,-0.63333,-0.44091
3.90000,-0.65000,-0.46610
4.00000,-0.66680,-0.48677
4.10000,-0.68320,-0.51011
4.20000,-0.70026,-0.53391
4.30000,-0.71680,-0.56266
4.40000,-0.73320,-0.58922
4.50000,-0.75000,-0.61459
4.60000,-0.76653,-0.64280
4.70000,-0.78320,-0.67905
4.80000,-0.79986,-0.71249
4.90000,-0.81680,-0.73747
5.00000,-0.83320,-0.76559
5.10000,-0.85013,-0.79520
5.20000,-0.86666,-0.83076
5.30000,-0.88333,-0.86651
5.40000,-0.90013,-0.89127
5.50000,-0.91640,-0.92193
5.60000,-0.93333,-0.95113
5.70000,-0.95013,-0.98436
5.80000,-0.96666,-1.01663
5.90000,-0.98346,-1.04875
6.00000,-1.00013,-1.07744
6.10000,-1.01680,-1.10864
6.20000,-1.03346,-1.13948
6.30000,-1.05013,-1.16996
6.40000,-1.06653,-1.20374
6.50000,-1.08346,-1.24018
6.60000,-1.10013,-1.27029
6.70000,-1.11680,-1.30119
6.80000,-1.13360,-1.33140
6.90000,-1.15000,-1.36212
7.00000,-1.16680,-1.39697
7.10000,-1.18333,-1.43402
7.20000,-1.20013,-1.46383
7.30000,-1.21666,-1.48668
7.40000,-1.23346,-1.50916
7.50000,-1.25000,-1.53871
7.60000,-1.26666,-1.56538
7.70000,-1.28346,-1.58477
7.80000,-1.29986,-1.60624
7.90000,-1.31653,-1.63186
8.00000,-1.33320,-1.64803
8.10000,-1.35000,-1.67634
8.20000,-1.36653,-1.71134
8.30000,-1.38346,-1.73972
8.40000,-1.39986,-1.75689
8.50000,-1.41640,-1.77119
8.60000,-1.43346,-1.80321
8.70000,-1.44986,-1.84003
8.80000,-1.46666,-1.87516
8.90000,-1.48333,-1.90086
9.00000,-1.50013,-1.92061
9.10000,-1.51680,-1.95748
9.20000,-1.53346,-1.99032
9.30000,-1.55000,-2.02132
9.40000,-1.56666,-2.05156
9.50000,-1.58346,-2.07697
9.60000,-1.59986,-2.08288
9.70000,-1.61693,-2.09345
9.80000,-1.63333,-2.10508
9.90000,-1.65000,-2.09986
10.00000,-1.66693,-2.10971
10.10000,-1.68333,-2.12242
10.20000,-1.70013,-2.14172
10.30000,-1.71666,-2.18079
10.40000,-1.73346,-2.21829
10.50000,-1.74986,-2.25141
10.60000,-1.76680,-2.28176
10.70000,-1.78333,-2.31236
10.80000,-1.80000,-2.34099
10.90000,-1.81680,-2.37199
11.00000,-1.83320,-2.40730
11.10000,-1.84986,-2.44117
11.20000,-1.86653,-2.47461
11.30000,-1.88333,-2.50946
11.40000,-1.89986,-2.54065
11.50000,-1.91680,-2.57344
11.60000,-1.93333,-2.60318
11.70000,-1.95000,-2.63636
11.80000,-1.96680,-2.66684
11.90000,-1.98306,-2.69514
12.00000,-2.00013,-2.73054
12.10000,-2.01666,-2.76186
12.20000,-2.03346,-2.79126
12.30000,-2.05013,-2.81975
12.40000,-2.06680,-2.85036
12.50000,-2.08319,-2.87388
12.60000,-2.09986,-2.90577
12.70000,-2.11679,-2.93408
12.80000,-2.13319,-2.96081
12.90000,-2.15039,-2.98990
13.00000,-2.16679,-3.01666
13.10000,-2.18346,-3.04480
13.20000,-2.20026,-3.07128
13.30000,-2.21666,-3.09706
13.40000,-2.23333,-3.12637
13.50000,-2.24999,-3.15479
13.60000,-2.26679,-3.17902
13.70000,-2.28333,-3.20402
13.80000,-2.30026,-3.23530
13.90000,-2.31679,-3.25851
14.00000,-2.33333,-3.28374
14.10000,-2.35013,-3.31056
14.20000,-2.36653,-3.33588
14.30000,-2.38319,-3.36245
14.40000,-2.39986,-3.39066
14.50000,-2.41666,-3.41885
14.60000,-2.43319,-3.44439
14.70000,-2.45013,-3.47366
14.80000,-2.46666,-3.50052
14.90000,-2.48319,-3.52970
15.00000,-2.50013,-3.55701
15.10000,-2.51639,-3.58370
15.20000,-2.53346,-3.61462
15.30000,-2.55013,-3.64374
15.40000,-2.56679,-3.67329
15.50000,-2.58346,-3.70130
15.60000,-2.60013,-3.72779
15.70000,-2.61679,-3.75416
15.80000,-2.63333,-3.78266
15.90000,-2.65013,-3.80911
16.00000,-2.66653,-3.83572
16.10000,-2.68359,-3.86452
16.20000,-2.70013,-3.89032
16.30000,-2.71679,-3.91723
16.40000,-2.73346,-3.94428
16.50000,-2.74986,-3.96965
16.60000,-2.76666,-3.99480
16.70000,-2.78333,-4.01948
16.80000,-2.80013,-4.04351
16.90000,-2.81653,-4.06911
17.00000,-2.83359,-4.09515
17.10000,-2.85013,-4.11817
17.20000,-2.86666,-4.14425
17.30000,-2.88346,-4.16737
17.40000,-2.89986,-4.19084
17.50000,-2.91653,-4.21577
17.60000,-2.93319,-4.23991
17.70000,-2.95013,-4.26515
17.80000,-2.96653,-4.28947
17.90000,-2.98346,-4.31308
18.00000,-2.99999,-4.33489
18.10000,-3.01653,-4.35941
18.20000,-3.03346,-4.38089
18.30000,-3.04973,-4.40356
18.40000,-3.06666,-4.42543
18.50000,-3.08333,-4.44811
18.60000,-3.10013,-4.46946
18.70000,-3.11666,-4.49407
18.80000,-3.13346,-4.51456
18.90000,-3.15013,-4.53626
19.00000,-3.16653,-4.55772
19.10000,-3.18346,-4.57923
19.20000,-3.19986,-4.59829
19.30000,-3.21693,-4.62121
19.40000,-3.23333,-4.64103
19.50000,-3.25013,-4.66118
19.60000,-3.26693,-4.67857
19.70000,-3.28333,-4.69751
19.80000,-3.29999,-4.71610
19.90000,-3.31666,-4.73581
20.00000,-3.33346,-4.75467
20.10000,-3.34999,-4.77492
20.20000,-3.36693,-4.79386
20.30000,-3.38333,-4.80887
20.40000,-3.39986,-4.82719
20.50000,-3.41666,-4.84203
20.60000,-3.43319,-4.85938
20.70000,-3.44986,-4.87513
20.80000,-3.46652,-4.89169
20.90000,-3.48346,-4.90820
21.00000,-3.49986,-4.92547
21.10000,-3.51692,-4.94184
21.20000,-3.53332,-4.95692
21.30000,-3.54986,-4.97309
21.40000,-3.56666,-4.98710
21.50000,-3.58306,-5.00309
21.60000,-3.60012,-5.01776
21.70000,-3.61666,-5.03257
21.80000,-3.63346,-5.04658
21.90000,-3.64999,-5.06207
22.00000,-3.66692,-5.07574
22.10000,-3.68332,-5.08829
22.20000,-3.69999,-5.10305
22.30000,-3.71679,-5.11587
22.40000,-3.73319,-5.12768
22.50000,-3.75026,-5.14241
22.60000,-3.76679,-5.15310
22.70000,-3.78346,-5.16580
22.80000,-3.80012,-5.17874
22.90000,-3.81679,-5.18853
23.00000,-3.83332,-5.20065
23.10000,-3.84986,-5.21418
23.20000,-3.86679,-5.22478
23.30000,-3.88319,-5.23762
23.40000,-3.90012,-5.25442
23.50000,-3.91666,-5.26421
23.60000,-3.93332,-5.27716
23.70000,-3.95012,-5.28870
23.80000,-3.96652,-5.29922
23.90000,-3.98319,-5.31554
24.00000,-3.99986,-5.32770
24.10000,-4.01679,-5.33892
24.20000,-4.03332,-5.34769
24.30000,-4.05012,-5.35791
24.40000,-4.06652,-5.36114
24.50000,-4.08319,-5.37543
24.60000,-4.10012,-5.38312
24.70000,-4.11652,-5.39544
24.80000,-4.13332,-5.40758
24.90000,-4.14999,-5.41360
25.00000,-4.16679,-5.42295
25.10000,-4.18346,-5.43601
25.20000,-4.20012,-5.44557
25.30000,-4.21666,-5.45209
25.40000,-4.23332,-5.46236
25.50000,-4.25012,-5.46907
25.60000,-4.26652,-5.47526
25.70000,-4.28359,-5.48700
25.80000,-4.29999,-5.49222
25.90000,-4.31679,-5.49973
26.00000,-4.33359,-5.50252
26.10000,-4.35012,-5.50960
26.20000,-4.36666,-5.51524
26.30000,-4.38332,-5.52071
26.40000,-4.40012,-5.52725
26.50000,-4.41652,-5.52916
26.60000,-4.43346,-5.54176
26.70000,-4.44999,-5.54781
26.80000,-4.46666,-5.56007
26.90000,-4.48346,-5.56783
27.00000,-4.49986,-5.57321
27.10000,-4.51652,-5.58406
27.20000,-4.53319,-5.59730
27.30000,-4.54999,-5.60509
27.40000,-4.56652,-5.61432
27.50000,-4.58346,-5.62259
27.60000,-4.59986,-5.62808
27.70000,-4.61652,-5.64298
27.80000,-4.63346,-5.65200
27.90000,-4.64972,-5.66413
28.00000,-4.66666,-5.67217
28.10000,-4.68332,-5.68658
28.20000,-4.70012,-5.70854
28.30000,-4.71679,-5.71740
28.40000,-4.73346,-5.72765
28.50000,-4.75012,-5.73508
28.60000,-4.76679,-5.74553
28.70000,-4.78346,-5.75302
28.80000,-4.79999,-5.76312
28.90000,-4.81679,-5.77065
29.00000,-4.83332,-5.77520
29.10000,-4.85012,-5.78208
29.20000,-4.86692,-5.78888
29.30000,-4.88332,-5.79737
29.40000,-4.89999,-5.80583
29.50000,-4.91652,-5.81396
29.60000,-4.93332,-5.82236
29.70000,-4.94985,-5.83001
29.80000,-4.96692,-5.84212
29.90000,-4.98332,-5.84885
30.00000,-4.99985,-5.85938
30.10000,-5.01679,-5.87081
30.20000,-5.03319,-5.87874
30.30000,-5.04985,-5.88824
30.40000,-5.06652,-5.89690
30.50000,-5.08345,-5.90673
30.60000,-5.09985,-5.91768
30.70000,-5.11679,-5.92592
30.80000,-5.13332,-5.93304
30.90000,-5.14985,-5.94280
31.00000,-5.16679,-5.95048
31.10000,-5.18305,-5.96205
31.20000,-5.19999,-5.97144
31.30000,-5.21652,-5.98108
31.40000,-5.23345,-5.98587
31.50000,-5.25012,-5.99470
31.60000,-5.26679,-6.00719
31.70000,-5.28345,-6.01356
31.80000,-5.29999,-6.02246
31.90000,-5.31679,-6.02983
32.00000,-5.33319,-6.03336
32.10000,-5.35025,-6.04664
32.20000,-5.36679,-6.05156
32.30000,-5.38332,-6.05759
32.40000,-5.40012,-6.06405
32.50000,-5.41665,-6.07033
32.60000,-5.43345,-6.07910
32.70000,-5.44999,-6.08840
32.80000,-5.46679,-6.09136
32.90000,-5.48332,-6.09969
33.00000,-5.50025,-6.10627
33.10000,-5.51665,-6.11166
33.20000,-5.53332,-6.12412
33.30000,-5.55012,-6.12754
33.40000,-5.56652,-6.13235
33.50000,-5.58319,-6.13805
33.60000,-5.59985,-6.14555
33.70000,-5.61665,-6.15467
33.80000,-5.63319,-6.16103
33.90000,-5.65025,-6.16660
34.00000,-5.66665,-6.17235
34.10000,-5.68319,-6.17944
34.20000,-5.69999,-6.18144
34.30000,-5.71639,-6.18751
34.40000,-5.73332,-6.19594
34.50000,-5.74999,-6.20191
34.60000,-5.76665,-6.20528
34.70000,-5.78345,-6.21222
34.80000,-5.80012,-6.21446
34.90000,-5.81665,-6.21858
35.00000,-5.83332,-6.22558
35.10000,-5.85012,-6.23202
35.20000,-5.86652,-6.23765
35.30000,-5.88359,-6.24395
35.40000,-5.90012,-6.24863
35.50000,-5.91679,-6.25394
35.60000,-5.93345,-6.25953
35.70000,-5.94999,-6.26306
35.80000,-5.96679,-6.26781
35.90000,-5.98332,-6.27058
36.00000,-6.00012,-6.27275
36.10000,-6.01665,-6.27761
36.20000,-6.03359,-6.28234
36.30000,-6.04999,-6.28367
36.40000,-6.06665,-6.28805
36.50000,-6.08345,-6.29406
36.60000,-6.09985,-6.29499
36.70000,-6.11665,-6.29924
36.80000,-6.13319,-6.29884
36.90000,-6.14998,-6.30037
37.00000,-6.16652,-6.30418
37.10000,-6.18345,-6.30756
37.20000,-6.19985,-6.30929
37.30000,-6.21652,-6.31189
37.40000,-6.23345,-6.31494
37.50000,-6.24972,-6.31662
37.60000,-6.26665,-6.32086
37.70000,-6.28318,-6.32193
37.80000,-6.30012,-6.32496
37.90000,-6.31678,-6.32852
38.00000,-6.33345,-6.33074
38.10000,-6.34998,-6.33285
38.20000,-6.36665,-6.33900
38.30000,-6.38345,-6.33823
38.40000,-6.39985,-6.34205
38.50000,-6.41678,-6.34837
38.60000,-6.43332,-6.35035
38.70000,-6.44998,-6.35293
38.80000,-6.46692,-6.35740
38.90000,-6.48332,-6.36184
39.00000,-6.50012,-6.36182
39.10000,-6.51665,-6.36340
39.20000,-6.53345,-6.36879
39.30000,-6.54998,-6.37323
39.40000,-6.56692,-6.38085
39.50000,-6.58332,-6.37986
39.60000,-6.59985,-6.38126
39.70000,-6.61678,-6.38532
39.80000,-6.63318,-6.38525
39.90000,-6.64985,-6.38850
40.00000,-6.66652,-6.39360
40.10000,-6.68332,-6.39746
40.20000,-6.69985,-6.39878
40.30000,-6.71678,-6.40273
40.40000,-6.73332,-6.40509
40.50000,-6.74998,-6.41195
40.60000,-6.76678,-6.41090
40.70000,-6.78318,-6.41377
40.80000,-6.79998,-6.41853
40.90000,-6.81665,-6.42278
41.00000,-6.83345,-6.42591
41.10000,-6.85012,-6.43021
41.20000,-6.86678,-6.43249
41.30000,-6.88332,-6.43453
41.40000,-6.89998,-6.43960
41.50000,-6.91678,-6.44181
41.60000,-6.93318,-6.44357
41.70000,-6.95012,-6.45154
41.80000,-6.96665,-6.45615
41.90000,-6.98345,-6.46020
42.00000,-7.00025,-6.46576
42.10000,-7.01678,-6.46910
42.20000,-7.03345,-6.47448
42.30000,-7.04998,-6.47933
42.40000,-7.06678,-6.48125
42.50000,-7.08332,-6.48455
42.60000,-7.10025,-6.49141
42.70000,-7.11678,-6.49530
42.80000,-7.13332,-6.49928
42.90000,-7.14998,-6.50177
43.00000,-7.16652,-6.50740
43.10000,-7.18332,-6.51421
43.20000,-7.19985,-6.51892
43.30000,-7.21678,-6.52449
43.40000,-7.23332,-6.53075
43.50000,-7.25012,-6.53401
43.60000,-7.26652,-6.53666
43.70000,-7.28332,-6.54268
43.80000,-7.29998,-6.54697
43.90000,-7.31638,-6.55229
44.00000,-7.33345,-6.55903
44.10000,-7.35012,-6.56405
44.20000,-7.36678,-6.56807
44.30000,-7.38332,-6.57226
44.40000,-7.40012,-6.57708
44.50000,-7.41678,-6.57904
44.60000,-7.43332,-6.58308
44.70000,-7.44998,-6.58438
44.80000,-7.46652,-6.58687
44.90000,-7.48358,-6.59235
45.00000,-7.50011,-6.59475
45.10000,-7.51678,-6.59831
45.20000,-7.53358,-6.60168
45.30000,-7.54998,-6.60592
45.40000,-7.56678,-6.60819
45.50000,-7.58332,-6.61530
45.60000,-7.60011,-6.61621
45.70000,-7.61665,-6.61968
45.80000,-7.63358,-6.62332
45.90000,-7.65011,-6.62571
46.00000,-7.66665,-6.62908
46.10000,-7.68345,-6.63344
46.20000,-7.69985,-6.63734
46.30000,-7.71651,-6.64187
46.40000,-7.73318,-6.64759
46.50000,-7.74998,-6.65074
46.60000,-7.76651,-6.65774
46.70000,-7.78345,-6.66021
46.80000,-7.79985,-6.66463
46.90000,-7.81651,-6.66844
47.00000,-7.83345,-6.66849
47.10000,-7.84971,-6.67224
47.20000,-7.86665,-6.67562
47.30000,-7.88331,-6.67864
47.40000,-7.90011,-6.68338
47.50000,-7.91678,-6.68542
47.60000,-7.93358,-6.68890
47.70000,-7.94998,-6.68748
47.80000,-7.96665,-6.69195
47.90000,-7.98345,-6.69265
48.00000,-7.99985,-6.69508
48.10000,-8.01691,-6.69798
48.20000,-8.03331,-6.69890
48.30000,-8.04998,-6.70263
48.40000,-8.06691,-6.70422
48.50000,-8.08331,-6.70494
48.60000,-8.09998,-6.70468
48.70000,-8.11651,-6.70634
48.80000,-8.13345,-6.70627
48.90000,-8.14985,-6.70710
49.00000,-8.16691,-6.70921
49.10000,-8.18345,-6.70650
49.20000,-8.19998,-6.70634
49.30000,-8.21678,-6.70470
49.40000,-8.23318,-6.70385
49.50000,-8.24985,-6.70128
49.60000,-8.26651,-6.69799
49.70000,-8.28331,-6.69624
49.80000,-8.29971,-6.69449
49.90000,-8.31678,-6.69596
50.00000,-8.33331,-6.69481
50.10000,-8.34985,-6.69730
50.20000,-8.36678,-6.69967
50.30000,-8.38305,-6.70139
50.40000,-8.40011,-6.70537
50.50000,-8.41665,-6.70759
50.60000,-8.43345,-6.71018
50.70000,-8.44998,-6.71303
50.80000,-8.46678,-6.71614
50.90000,-8.48331,-6.71940
51.00000,-8.49998,-6.72485
51.10000,-8.51678,-6.72808
51.20000,-8.53318,-6.72883
51.30000,-8.55025,-6.73604
51.40000,-8.56678,-6.74108
51.50000,-8.58345,-6.74739
51.60000,-8.60025,-6.75508
51.70000,-8.61665,-6.76070
51.80000,-8.63331,-6.76689
51.90000,-8.64998,-6.77523
52.00000,-8.66665,-6.78010
52.10000,-8.68318,-6.78869
52.20000,-8.70011,-6.79694
52.30000,-8.71665,-6.80354
52.40000,-8.73345,-6.81406
52.50000,-8.75011,-6.82194
52.60000,-8.76651,-6.82924
52.70000,-8.78318,-6.83598
52.80000,-8.79985,-6.84371
52.90000,-8.81665,-6.85043
53.00000,-8.83318,-6.85886
53.10000,-8.85011,-6.86757
53.20000,-8.86665,-6.87292
53.30000,-8.88331,-6.88092
53.40000,-8.90011,-6.88782
53.50000,-8.91638,-6.89417
53.60000,-8.93331,-6.90155
53.70000,-8.94998,-6.90886
53.80000,-8.96678,-6.91661
53.90000,-8.98345,-6.92458
54.00000,-9.00024,-6.93259
54.10000,-9.01665,-6.93709
54.20000,-9.03331,-6.94772
54.30000,-9.05011,-6.95372
54.40000,-9.06651,-6.96218
54.50000,-9.08358,-6.97287
54.60000,-9.10011,-6.97853
54.70000,-9.11678,-6.98642
54.80000,-9.13358,-6.99373
54.90000,-9.15011,-6.99915
55.00000,-9.16678,-7.00611
55.10000,-9.18318,-7.01381
55.20000,-9.20011,-7.02156
55.30000,-9.21651,-7.02971
55.40000,-9.23358,-7.02866
55.50000,-9.25011,-7.03562
55.60000,-9.26664,-7.04497
55.70000,-9.28331,-7.05081
55.80000,-9.29984,-7.05958
55.90000,-9.31651,-7.06728
56.00000,-9.33318,-7.07623
56.10000,-9.35011,-7.08507
56.20000,-9.36651,-7.09499
56.30000,-9.38344,-7.10512
56.40000,-9.39998,-7.11121
56.50000,-9.41664,-7.12112
56.60000,-9.43344,-7.13117
56.70000,-9.44971,-7.13747
56.80000,-9.46664,-7.14731
56.90000,-9.48331,-7.15702
57.00000,-9.50011,-7.16565
57.10000,-9.51678,-7.17537
57.20000,-9.53344,-7.18490
57.30000,-9.54998,-7.19028
57.40000,-9.56664,-7.19928
57.50000,-9.58344,-7.20531
57.60000,-9.59984,-7.21160
57.70000,-9.61678,-7.22155
57.80000,-9.63331,-7.22742
57.90000,-9.64998,-7.23478
58.00000,-9.66691,-7.24192
58.10000,-9.68331,-7.24674
58.20000,-9.69998,-7.25148
58.30000,-9.71664,-7.25916
58.40000,-9.73344,-7.26293
58.50000,-9.74984,-7.26707
58.60000,-9.76691,-7.27170
58.70000,-9.78331,-7.27358
58.80000,-9.79998,-7.27917
58.90000,-9.81678,-7.27845
59.00000,-9.83304,-7.27507
59.10000,-9.84984,-7.28215
59.20000,-9.86651,-7.28845
59.30000,-9.88344,-7.29414
59.40000,-9.89998,-7.30113
59.50000,-9.91691,-7.30936
59.60000,-9.93331,-7.31153
59.70000,-9.94984,-7.31953
59.80000,-9.96664,-7.32462
59.90000,-9.98304,-7.33142
60.00000,-10.00011,-7.33890
60.10000,-10.01664,-7.34328
60.20000,-10.03331,-7.35028
60.30000,-10.04998,-7.35702
60.40000,-10.06678,-7.36288
60.50000,-10.08331,-7.36488
60.60000,-10.09998,-7.37154
60.70000,-10.11664,-7.37358
60.80000,-10.13304,-7.37807
60.90000,-10.15024,-7.38345
61.00000,-10.16664,-7.38822
61.10000,-10.18344,-7.39561
61.20000,-10.20011,-7.40090
61.30000,-10.21664,-7.40550
61.40000,-10.23331,-7.40817
61.50000,-10.24998,-7.41575
61.60000,-10.26678,-7.41807
61.70000,-10.28317,-7.42402
61.80000,-10.30024,-7.43152
61.90000,-10.31664,-7.43613
62.00000,-10.33331,-7.44247
62.10000,-10.35011,-7.44947
62.20000,-10.36651,-7.45532
62.30000,-10.38317,-7.46202
62.40000,-10.39997,-7.46739
62.50000,-10.41678,-7.47488
62.60000,-10.43317,-7.48284
62.70000,-10.45024,-7.49057
62.80000,-10.46651,-7.49568
62.90000,-10.48331,-7.50460
63.00000,-10.49997,-7.51164
63.10000,-10.51637,-7.51930
63.20000,-10.53344,-7.53030
63.30000,-10.55011,-7.53711
63.40000,-10.56677,-7.54814
63.50000,-10.58344,-7.55702
63.60000,-10.60011,-7.56490
63.70000,-10.61651,-7.57052
63.80000,-10.63331,-7.58129
63.90000,-10.65011,-7.58564
64.00000,-10.66651,-7.59140
64.10001,-10.68357,-7.60395
64.20000,-10.69997,-7.60892
64.30000,-10.71677,-7.61763
64.40000,-10.73371,-7.62654
64.50000,-10.75011,-7.63367
64.60001,-10.76691,-7.64036
64.70000,-10.78331,-7.65007
64.80000,-10.80011,-7.65995
64.90000,-10.81637,-7.66765
65.00000,-10.83344,-7.67880
65.10001,-10.84997,-7.68439
65.20000,-10.86664,-7.69436
65.30000,-10.88344,-7.70288
65.40000,-10.89984,-7.71378
65.50000,-10.91651,-7.72319
65.60001,-10.93344,-7.73212
65.70001,-10.95011,-7.73842
65.80000,-10.96664,-7.74859
65.90000,-10.98357,-7.75782
66.00000,-10.99997,-7.76462
66.10001,-11.01664,-7.77463
66.20001,-11.03344,-7.78155
66.30000,-11.04984,-7.79005
66.40000,-11.06677,-7.79958
66.50000,-11.08344,-7.80846
66.60001,-11.10011,-7.81820
66.70001,-11.11677,-7.82510
66.80000,-11.13344,-7.83596
66.90000,-11.14997,-7.83883
67.00000,-11.16664,-7.84891
67.10001,-11.18331,-7.85594
67.20001,-11.19984,-7.86078
67.30000,-11.21691,-7.87216
67.40000,-11.23344,-7.87691
67.50000,-11.25011,-7.88532
67.60001,-11.26691,-7.89557
67.70001,-11.28331,-7.89792
67.80000,-11.29997,-7.90424
67.90000,-11.31651,-7.91107
68.00000,-11.33344,-7.90898
68.10001,-11.34971,-7.90286
68.20001,-11.36677,-7.91523
68.30000,-11.38331,-7.92280
68.40000,-11.40011,-7.93209
68.50000,-11.41677,-7.94272
68.60001,-11.43317,-7.95029
68.70001,-11.44984,-7.96098
68.80000,-11.46651,-7.97168
68.90000,-11.48331,-7.98140
69.00000,-11.49971,-7.98670
69.10001,-11.51677,-7.99735
69.20001,-11.53317,-8.00515
69.30000,-11.54997,-8.01705
69.40000,-11.56677,-8.02659
69.50000,-11.58304,-8.03983
69.60001,-11.59997,-8.04820
69.70001,-11.61677,-8.05649
69.80000,-11.63344,-8.06342
69.90000,-11.65011,-8.07431
70.00000,-11.66677,-8.08637
70.10001,-11.68344,-8.09935
70.20001,-11.70010,-8.10497
70.30000,-11.71677,-8.10810
70.40000,-11.73317,-8.11968
70.50000,-11.75024,-8.13425
70.60001,-11.76677,-8.14664
70.70001,-11.78344,-8.15812
70.80000,-11.80024,-8.16710
70.90000,-11.81677,-8.17148
71.00000,-11.83344,-8.18041
71.10001,-11.84997,-8.18978
71.20001,-11.86677,-8.19657
71.30000,-11.88317,-8.20794
71.40000,-11.90024,-8.22192
71.50000,-11.91677,-8.22582
71.60001,-11.93330,-8.23690
71.70001,-11.94997,-8.24240
71.80000,-11.96637,-8.24759
71.90000,-11.98317,-8.25802
72.00000,-11.99984,-8.27066
72.10001,-12.01650,-8.27883
72.20001,-12.03317,-8.29118
72.30000,-12.05010,-8.30126
72.40000,-12.06664,-8.30821
72.50000,-12.08330,-8.32002
72.60001,-12.10010,-8.33110
72.70001,-12.11637,-8.34246
72.80000,-12.13330,-8.35391
72.90000,-12.14997,-8.36407
73.00000,-12.16677,-8.37441
73.10001,-12.18344,-8.38426
73.20001,-12.20024,-8.39543
73.30000,-12.21664,-8.40291
73.40000,-12.23330,-8.41525
73.50000,-12.25010,-8.42430
73.60001,-12.26664,-8.43231
73.70001,-12.28357,-8.44465
73.80000,-12.30010,-8.45171
73.90000,-12.31677,-8.46152
74.00000,-12.33344,-8.47409
74.10001,-12.34997,-8.47703
74.20001,-12.36677,-8.48329
74.30000,-12.38344,-8.49259
74.40000,-12.40010,-8.50079
74.50000,-12.41664,-8.51122
74.60001,-12.43344,-8.52351
74.70001,-12.45010,-8.53584
74.80000,-12.46650,-8.54210
74.90000,-12.48330,-8.54940
75.00000,-12.49984,-8.55702
75.10001,-12.51650,-8.56739
75.20001,-12.53317,-8.57694
75.30000,-12.54997,-8.58635
75.40000,-12.56650,-8.59368
75.50000,-12.58357,-8.60614
75.60001,-12.59997,-8.61137
75.70001,-12.61650,-8.62151
75.80000,-12.63330,-8.62908
75.90000,-12.64970,-8.63717
76.00000,-12.66664,-8.65109
76.10001,-12.68330,-8.66005
76.20001,-12.70010,-8.66988
76.30000,-12.71690,-8.68223
76.40000,-12.73344,-8.69042
76.50000,-12.74997,-8.69864
76.60001,-12.76664,-8.71339
76.70001,-12.78344,-8.71901
76.80000,-12.79984,-8.72996
76.90000,-12.81690,-8.74601
77.00000,-12.83344,-8.75729
77.10001,-12.84997,-8.76831
77.20001,-12.86690,-8.77546
77.30000,-12.88344,-8.78628
77.40000,-12.90010,-8.79827
77.50000,-12.91663,-8.81359
77.60001,-12.93343,-8.82704
77.70001,-12.94984,-8.83845
77.80000,-12.96690,-8.85452
77.90000,-12.98343,-8.86471
78.00000,-12.99997,-8.88292
78.10001,-13.01677,-8.89243
78.20001,-13.03317,-8.90603
78.30000,-13.04997,-8.92003
78.40000,-13.06650,-8.93343
78.50000,-13.08330,-8.94918
78.60001,-13.09983,-8.96924
78.70001,-13.11690,-8.98520
78.80000,-13.13330,-8.99449
78.90000,-13.14983,-9.01076
79.00000,-13.16677,-9.02565
79.10001,-13.18317,-9.04114
79.20001,-13.19997,-9.05708
79.30000,-13.21663,-9.07022
79.40000,-13.23343,-9.08545
79.50000,-13.25010,-9.10203
79.60001,-13.26690,-9.11595
79.70001,-13.28343,-9.12722
79.80000,-13.29997,-9.14516
79.90000,-13.31677,-9.15947
80.00000,-13.33317,-9.17544
80.10001,-13.34997,-9.19507
80.20001,-13.36677,-9.21377
80.30000,-13.38343,-9.23824
80.40000,-13.40023,-9.25448
80.50001,-13.41663,-9.26684
80.60001,-13.43343,-9.28216
80.70001,-13.44997,-9.29759
80.80000,-13.46677,-9.31204
80.90000,-13.48317,-9.32648
81.00001,-13.50010,-9.34377
81.10001,-13.51663,-9.35628
81.20001,-13.53330,-9.37464
81.30000,-13.55010,-9.38760
81.40000,-13.56650,-9.40143
81.50001,-13.58317,-9.41378
81.60001,-13.59983,-9.42868
81.70001,-13.61663,-9.44429
81.80000,-13.63317,-9.46078
81.90000,-13.65010,-9.47665
82.00001,-13.66663,-9.48795
82.10001,-13.68330,-9.50591
82.20001,-13.70010,-9.51748
82.30000,-13.71650,-9.53314
82.40000,-13.73330,-9.54697
82.50001,-13.74997,-9.56111
82.60001,-13.76677,-9.57719
82.70001,-13.78330,-9.59482
82.80000,-13.80010,-9.60841
82.90000,-13.81677,-9.62238
83.00001,-13.83330,-9.64063
83.10001,-13.84997,-9.65501
83.20001,-13.86637,-9.67006
83.30000,-13.88357,-9.69381
83.40000,-13.90010,-9.70786
83.50001,-13.91690,-9.72411
83.60001,-13.93357,-9.74010
83.70001,-13.95010,-9.75249
83.80000,-13.96677,-9.76724
83.90000,-13.98330,-9.78391
84.00001,-14.00010,-9.79684
84.10001,-14.01637,-9.81130
84.20001,-14.03357,-9.82891
84.30000,-14.05010,-9.84247
84.40000,-14.06677,-9.86008
84.50001,-14.08343,-9.87302
84.60001,-14.09970,-9.88682
84.70001,-14.11650,-9.90308
84.80000,-14.13317,-9.91934
84.90000,-14.15010,-9.93460
85.00001,-14.16650,-9.94855
85.10001,-14.18357,-9.96421
85.20001,-14.19997,-9.97654
85.30000,-14.21650,-9.99376
85.40000,-14.23343,-10.00506
85.50001,-14.24970,-10.01796
85.60001,-14.26663,-10.03303
85.70001,-14.28330,-10.04896
85.80000,-14.30023,-10.06743
85.90000,-14.31676,-10.08340
86.00001,-14.33343,-10.09511
86.10001,-14.35010,-10.10348
86.20001,-14.36663,-10.11900
86.30000,-14.38343,-10.13291
86.40000,-14.39983,-10.14817
86.50001,-14.41690,-10.15821
86.60001,-14.43343,-10.15900
86.70001,-14.45010,-10.17011
86.80000,-14.46690,-10.18699
86.90000,-14.48330,-10.19691
87.00001,-14.49996,-10.20601
87.10001,-14.51650,-10.22103
87.20001,-14.53343,-10.23820
87.30000,-14.54983,-10.25094
87.40000,-14.56690,-10.26694
87.50001,-14.58330,-10.27625
87.60001,-14.59996,-10.29180
87.70001,-14.61676,-10.30200
87.80000,-14.63316,-10.31289
87.90000,-14.64983,-10.32627
88.00001,-14.66636,-10.34151
88.10001,-14.68330,-10.35523
88.20001,-14.69996,-10.37139
88.30000,-14.71690,-10.38341
88.40000,-14.73330,-10.39408
88.50001,-14.74996,-10.41219
88.60001,-14.76663,-10.42215
88.70001,-14.78303,-10.43491
88.80000,-14.79996,-10.44887
88.90000,-14.81663,-10.45996
89.00001,-14.83356,-10.47311
89.10001,-14.85010,-10.48888
89.17600,-14.86290,-10.50030