File: GFBaking/data/1TspPectin/1TspPectin_2.is_comp_RawData/Specimen_RawData_1.csv
Time,Extension,Load
(sec),(mm),(N)
0.00000,0.35520,0.02819
0.10000,0.34613,0.02995
0.20000,0.32613,0.02823
0.30000,0.30733,0.02879
0.40000,0.28973,0.02880
0.50000,0.27267,0.03113
0.60000,0.25560,0.03008
0.70000,0.23853,0.02661
0.80000,0.22173,0.02535
0.90000,0.20533,0.02278
1.00000,0.18840,0.02055
1.10000,0.17187,0.01778
1.20000,0.15533,0.01502
1.30000,0.13840,0.01272
1.40000,0.12187,0.00805
1.50000,0.10507,0.00605
1.60000,0.08840,0.00299
1.70000,0.07160,-0.00614
1.80000,0.05533,-0.00949
1.90000,0.03840,-0.01546
2.00000,0.02187,-0.02159
2.10000,0.00520,-0.03016
2.20000,-0.01173,-0.03657
2.30000,-0.02813,-0.03719
2.40000,-0.04493,-0.04366
2.50000,-0.06173,-0.04952
2.60000,-0.07827,-0.05458
2.70000,-0.09480,-0.06491
2.80000,-0.11160,-0.07041
2.90000,-0.12827,-0.07330
3.00000,-0.14493,-0.08054
3.10000,-0.16187,-0.09299
3.20000,-0.17827,-0.09543
3.30000,-0.19507,-0.10354
3.40000,-0.21147,-0.11287
3.50000,-0.22813,-0.11516
3.60000,-0.24480,-0.12363
3.70000,-0.26147,-0.13390
3.80000,-0.27827,-0.14084
3.90000,-0.29493,-0.15279
4.00000,-0.31173,-0.15920
4.10000,-0.32827,-0.16990
4.20000,-0.34493,-0.17465
4.30000,-0.36147,-0.18765
4.40000,-0.37800,-0.20182
4.50000,-0.39493,-0.21151
4.60000,-0.41147,-0.22374
4.70000,-0.42840,-0.23749
4.80000,-0.44507,-0.25239
4.90000,-0.46173,-0.26095
5.00000,-0.47813,-0.27579
5.10000,-0.49507,-0.28465
5.20000,-0.51160,-0.29697
5.30000,-0.52813,-0.31237
5.40000,-0.54520,-0.33084
5.50000,-0.56160,-0.34729
5.60000,-0.57827,-0.36461
5.70000,-0.59493,-0.38261
5.80000,-0.61160,-0.40329
5.90000,-0.62813,-0.42287
6.00000,-0.64480,-0.44018
6.10000,-0.66147,-0.46288
6.20000,-0.67827,-0.48322
6.30000,-0.69506,-0.50862
6.40000,-0.71160,-0.52878
6.50000,-0.72840,-0.55633
6.60000,-0.74480,-0.57931
6.70000,-0.76133,-0.60288
6.80000,-0.77826,-0.62648
6.90000,-0.79480,-0.65262
7.00000,-0.81160,-0.67885
7.10000,-0.82826,-0.70508
7.20000,-0.84506,-0.72891
7.30000,-0.86146,-0.75547
7.40000,-0.87840,-0.78226
7.50000,-0.89480,-0.80927
7.60000,-0.91133,-0.83671
7.70000,-0.92826,-0.86396
7.80000,-0.94493,-0.89389
7.90000,-0.96160,-0.92265
8.00000,-0.97840,-0.95139
8.10000,-0.99506,-0.97894
8.20000,-1.01146,-1.00622
8.30000,-1.02840,-1.03382
8.40000,-1.04493,-1.06231
8.50000,-1.06133,-1.08693
8.60000,-1.07840,-1.11632
8.70000,-1.09480,-1.14083
8.80000,-1.11173,-1.17040
8.90000,-1.12840,-1.19648
9.00000,-1.14493,-1.22697
9.10000,-1.16160,-1.25072
9.20000,-1.17826,-1.28088
9.30000,-1.19493,-1.30699
9.40000,-1.21160,-1.33753
9.50000,-1.22840,-1.36608
9.60000,-1.24480,-1.39338
9.70000,-1.26173,-1.42437
9.80000,-1.27813,-1.45128
9.90000,-1.29493,-1.48040
10.00000,-1.31133,-1.50877
10.10000,-1.32813,-1.53926
10.20000,-1.34493,-1.56481
10.30000,-1.36160,-1.59673
10.40000,-1.37840,-1.62436
10.50000,-1.39480,-1.65526
10.60000,-1.41160,-1.68665
10.70000,-1.42813,-1.71361
10.80000,-1.44480,-1.73724
10.90000,-1.46160,-1.75642
11.00000,-1.47813,-1.77013
11.10000,-1.49493,-1.77809
11.20000,-1.51173,-1.79087
11.30000,-1.52840,-1.80827
11.40000,-1.54480,-1.82070
11.50000,-1.56160,-1.85647
11.60000,-1.57813,-1.88372
11.70000,-1.59466,-1.91271
11.80000,-1.61173,-1.94752
11.90000,-1.62813,-1.97885
12.00000,-1.64493,-2.00865
12.10000,-1.66173,-2.03966
12.20000,-1.67826,-2.06440
12.30000,-1.69480,-2.07357
12.40000,-1.71160,-2.07814
12.50000,-1.72826,-2.08347
12.60000,-1.74480,-2.09583
12.70000,-1.76173,-2.10094
12.80000,-1.77826,-2.12387
12.90000,-1.79506,-2.15614
13.00000,-1.81146,-2.18007
13.10000,-1.82800,-2.20211
13.20000,-1.84480,-2.22137
13.30000,-1.86133,-2.25033
13.40000,-1.87826,-2.28190
13.50000,-1.89493,-2.30915
13.60000,-1.91173,-2.34037
13.70000,-1.92813,-2.36584
13.80000,-1.94506,-2.39644
13.90000,-1.96146,-2.42681
14.00000,-1.97800,-2.45262
14.10000,-1.99480,-2.48259
14.20000,-2.01146,-2.51655
14.30000,-2.02826,-2.52479
14.40000,-2.04506,-2.54947
14.50000,-2.06159,-2.58879
14.60000,-2.07813,-2.61783
14.70000,-2.09493,-2.64927
14.80000,-2.11159,-2.67264
14.90000,-2.12813,-2.69704
15.00000,-2.14519,-2.72685
15.10000,-2.16146,-2.75318
15.20000,-2.17839,-2.77860
15.30000,-2.19506,-2.80843
15.40000,-2.21159,-2.83050
15.50000,-2.22813,-2.85707
15.60000,-2.24493,-2.88469
15.70000,-2.26146,-2.90925
15.80000,-2.27813,-2.93774
15.90000,-2.29506,-2.96344
16.00000,-2.31159,-2.98310
16.10000,-2.32839,-3.01279
16.20000,-2.34479,-3.03895
16.30000,-2.36146,-3.05832
16.40000,-2.37813,-3.08318
16.50000,-2.39466,-3.10970
16.60000,-2.41159,-3.12649
16.70000,-2.42813,-3.15496
16.80000,-2.44506,-3.18174
16.90000,-2.46146,-3.20401
17.00000,-2.47839,-3.23080
17.10000,-2.49479,-3.25264
17.20000,-2.51133,-3.27489
17.30000,-2.52826,-3.29949
17.40000,-2.54493,-3.32302
17.50000,-2.56173,-3.34936
17.60000,-2.57839,-3.37332
17.70000,-2.59506,-3.39215
17.80000,-2.61146,-3.41845
17.90000,-2.62826,-3.44057
18.00000,-2.64479,-3.46107
18.10000,-2.66133,-3.48682
18.20000,-2.67839,-3.50977
18.30000,-2.69479,-3.53267
18.40000,-2.71173,-3.55826
18.50000,-2.72826,-3.58124
18.60000,-2.74479,-3.60341
18.70000,-2.76133,-3.62863
18.80000,-2.77839,-3.64921
18.90000,-2.79493,-3.67401
19.00000,-2.81159,-3.70153
19.10000,-2.82853,-3.72685
19.20000,-2.84493,-3.75001
19.30000,-2.86186,-3.77475
19.40000,-2.87826,-3.79949
19.50000,-2.89479,-3.82418
19.60000,-2.91146,-3.84703
19.70000,-2.92799,-3.86999
19.80000,-2.94479,-3.89266
19.90000,-2.96159,-3.91705
20.00000,-2.97839,-3.93911
20.10000,-2.99479,-3.95916
20.20000,-3.01173,-3.98381
20.30000,-3.02813,-4.00454
20.40000,-3.04466,-4.02610
20.50000,-3.06159,-4.04741
20.60000,-3.07813,-4.06883
20.70000,-3.09493,-4.09333
20.80000,-3.11159,-4.11373
20.90000,-3.12839,-4.13422
21.00000,-3.14479,-4.15339
21.10000,-3.16159,-4.17447
21.20000,-3.17813,-4.19576
21.30000,-3.19466,-4.21466
21.40000,-3.21186,-4.23189
21.50000,-3.22813,-4.24936
21.60000,-3.24506,-4.26710
21.70000,-3.26173,-4.28520
21.80000,-3.27826,-4.30322
21.90000,-3.29493,-4.32175
22.00000,-3.31159,-4.33774
22.10000,-3.32813,-4.35248
22.20000,-3.34479,-4.37117
22.30000,-3.36173,-4.38697
22.40000,-3.37813,-4.40437
22.50000,-3.39506,-4.42073
22.60000,-3.41132,-4.43595
22.70000,-3.42813,-4.45307
22.80000,-3.44479,-4.47010
22.90000,-3.46146,-4.48697
23.00000,-3.47812,-4.50005
23.10000,-3.49492,-4.51849
23.20000,-3.51172,-4.53360
23.30000,-3.52812,-4.55051
23.40000,-3.54492,-4.56588
23.50000,-3.56132,-4.58104
23.60000,-3.57799,-4.59578
23.70000,-3.59492,-4.60940
23.80000,-3.61146,-4.62342
23.90000,-3.62839,-4.63749
24.00000,-3.64492,-4.65160
24.10000,-3.66172,-4.66445
24.20000,-3.67812,-4.67821
24.30000,-3.69506,-4.69112
24.40000,-3.71146,-4.70276
24.50000,-3.72799,-4.71308
24.60000,-3.74519,-4.72582
24.70000,-3.76146,-4.73782
24.80000,-3.77839,-4.74844
24.90000,-3.79506,-4.75895
25.00000,-3.81159,-4.77075
25.10000,-3.82812,-4.78003
25.20000,-3.84479,-4.79012
25.30000,-3.86146,-4.79815
25.40000,-3.87812,-4.80969
25.50000,-3.89506,-4.81879
25.60000,-3.91146,-4.82799
25.70000,-3.92839,-4.83751
25.80000,-3.94492,-4.84673
25.90000,-3.96146,-4.85516
26.00000,-3.97812,-4.86465
26.10000,-3.99466,-4.87292
26.20000,-4.01146,-4.88141
26.30000,-4.02826,-4.89116
26.40000,-4.04506,-4.89735
26.50000,-4.06132,-4.90649
26.60000,-4.07826,-4.91654
26.70000,-4.09479,-4.92192
26.80000,-4.11146,-4.93112
26.90000,-4.12839,-4.93838
27.00000,-4.14479,-4.94458
27.10000,-4.16172,-4.95599
27.20000,-4.17826,-4.96213
27.30000,-4.19506,-4.96812
27.40000,-4.21146,-4.97180
27.50000,-4.22826,-4.97889
27.60000,-4.24479,-4.98538
27.70000,-4.26132,-4.98693
27.80000,-4.27839,-4.99286
27.90000,-4.29479,-4.99719
28.00000,-4.31172,-5.00448
28.10000,-4.32839,-5.00682
28.20000,-4.34492,-5.01218
28.30000,-4.36159,-5.01408
28.40000,-4.37826,-5.01909
28.50000,-4.39479,-5.02831
28.60000,-4.41146,-5.03197
28.70000,-4.42839,-5.03535
28.80000,-4.44479,-5.03442
28.90000,-4.46172,-5.04052
29.00000,-4.47812,-5.04448
29.10000,-4.49479,-5.04383
29.20000,-4.51146,-5.04755
29.30000,-4.52812,-5.05049
29.40000,-4.54479,-5.05156
29.50000,-4.56159,-5.05752
29.60000,-4.57839,-5.05995
29.70000,-4.59479,-5.06258
29.80000,-4.61172,-5.06518
29.90000,-4.62812,-5.06648
30.00000,-4.64466,-5.06948
30.10000,-4.66146,-5.06974
30.20000,-4.67812,-5.07232
30.30000,-4.69492,-5.07073
30.40000,-4.71159,-5.06845
30.50000,-4.72826,-5.06438
30.60000,-4.74479,-5.06883
30.70000,-4.76172,-5.07345
30.80000,-4.77826,-5.07542
30.90000,-4.79479,-5.08034
31.00000,-4.81172,-5.08259
31.10000,-4.82826,-5.08547
31.20000,-4.84505,-5.08894
31.30000,-4.86172,-5.09156
31.40000,-4.87825,-5.09368
31.50000,-4.89479,-5.09630
31.60000,-4.91145,-5.09978
31.70000,-4.92812,-5.10140
31.80000,-4.94492,-5.10607
31.90000,-4.96185,-5.10714
32.00000,-4.97812,-5.10733
32.10000,-4.99505,-5.10961
32.20000,-5.01145,-5.10719
32.30000,-5.02812,-5.10813
32.40000,-5.04492,-5.10817
32.50000,-5.06132,-5.11123
32.60000,-5.07825,-5.10861
32.70000,-5.09505,-5.10763
32.80000,-5.11172,-5.10864
32.90000,-5.12812,-5.10783
33.00000,-5.14492,-5.10982
33.10000,-5.16145,-5.10920
33.20000,-5.17799,-5.11164
33.30000,-5.19492,-5.10920
33.40000,-5.21145,-5.10857
33.50000,-5.22839,-5.10708
33.60000,-5.24505,-5.10614
33.70000,-5.26172,-5.10225
33.80000,-5.27812,-5.10006
33.90000,-5.29492,-5.09822
34.00000,-5.31145,-5.09390
34.10000,-5.32799,-5.09127
34.20000,-5.34505,-5.09027
34.30000,-5.36145,-5.08595
34.40000,-5.37839,-5.08740
34.50000,-5.39492,-5.08313
34.60000,-5.41159,-5.08202
34.70000,-5.42812,-5.08113
34.80000,-5.44492,-5.07711
34.90000,-5.46159,-5.07671
35.00000,-5.47812,-5.07349
35.10000,-5.49505,-5.07125
35.20000,-5.51159,-5.06965
35.30000,-5.52852,-5.06821
35.40000,-5.54479,-5.04653
35.50000,-5.56145,-5.03796
35.60000,-5.57812,-5.03503
35.70000,-5.59465,-5.03430
35.80000,-5.61159,-5.03529
35.90000,-5.62825,-5.03751
36.00000,-5.64505,-5.03658
36.10000,-5.66145,-5.03624
36.20000,-5.67825,-5.03632
36.30000,-5.69479,-5.03422
36.40000,-5.71132,-5.03097
36.50000,-5.72825,-5.03062
36.60000,-5.74479,-5.02729
36.70000,-5.76172,-5.02678
36.80000,-5.77825,-5.02298
36.90000,-5.79492,-5.01943
37.00000,-5.81145,-5.01705
37.10000,-5.82839,-5.01543
37.20000,-5.84479,-5.00492
37.30000,-5.86145,-5.00211
37.40000,-5.87852,-4.99122
37.50000,-5.89479,-4.98671
37.60000,-5.91172,-4.98539
37.70000,-5.92839,-4.97982
37.80000,-5.94492,-4.97287
37.90000,-5.96159,-4.96657
38.00000,-5.97812,-4.96456
38.10000,-5.99479,-4.95800
38.20000,-6.01145,-4.95119
38.30000,-6.02852,-4.94306
38.40000,-6.04479,-4.93169
38.50000,-6.06172,-4.92400
38.60000,-6.07812,-4.90815
38.70000,-6.09478,-4.89833
38.80000,-6.11159,-4.88769
38.90000,-6.12812,-4.87732
39.00000,-6.14478,-4.86439
39.10000,-6.16145,-4.85528
39.20000,-6.17839,-4.84860
39.30000,-6.19478,-4.84116
39.40000,-6.21172,-4.83328
39.50000,-6.22812,-4.82522
39.60000,-6.24465,-4.81425
39.70000,-6.26158,-4.80092
39.80000,-6.27798,-4.79961
39.90000,-6.29492,-4.79149
40.00000,-6.31158,-4.79567
40.10000,-6.32825,-4.78915
40.20000,-6.34465,-4.78774
40.30000,-6.36158,-4.78537
40.40000,-6.37812,-4.78334
40.50000,-6.39465,-4.78048
40.60000,-6.41185,-4.77836
40.70000,-6.42812,-4.77345
40.80000,-6.44492,-4.76939
40.90000,-6.46172,-4.76662
41.00000,-6.47825,-4.76539
41.10000,-6.49492,-4.75669
41.20000,-6.51158,-4.75038
41.30000,-6.52825,-4.75679
41.40000,-6.54478,-4.75222
41.50000,-6.56172,-4.75009
41.60000,-6.57825,-4.74563
41.70000,-6.59505,-4.74023
41.80000,-6.61145,-4.73985
41.90000,-6.62812,-4.74112
42.00000,-6.64478,-4.73415
42.10000,-6.66132,-4.72965
42.20000,-6.67825,-4.72887
42.30000,-6.69492,-4.72609
42.40000,-6.71172,-4.72438
42.50000,-6.72812,-4.72208
42.60000,-6.74492,-4.72217
42.70000,-6.76158,-4.72113
42.80000,-6.77798,-4.71779
42.90000,-6.79492,-4.71439
43.00000,-6.81145,-4.71178
43.10000,-6.82825,-4.71052
43.20000,-6.84505,-4.70704
43.30000,-6.86172,-4.69754
43.40000,-6.87812,-4.68610
43.50000,-6.89492,-4.67864
43.60000,-6.91158,-4.66940
43.70000,-6.92798,-4.66178
43.80000,-6.94505,-4.65843
43.90000,-6.96145,-4.65492
44.00000,-6.97838,-4.65763
44.10000,-6.99505,-4.65833
44.20000,-7.01158,-4.64555
44.30000,-7.02838,-4.64675
44.40000,-7.04492,-4.61616
44.50000,-7.06158,-4.61529
44.60000,-7.07825,-4.61452
44.70000,-7.09518,-4.58044
44.80000,-7.11158,-4.57326
44.90000,-7.12838,-4.57549
45.00000,-7.14478,-4.57098
45.10000,-7.16145,-4.56093
45.20000,-7.17812,-4.55529
45.30000,-7.19465,-4.55825
45.40000,-7.21158,-4.56050
45.50000,-7.22825,-4.55632
45.60000,-7.24505,-4.55600
45.70000,-7.26158,-4.55571
45.80000,-7.27838,-4.55670
45.90000,-7.29478,-4.55738
46.00000,-7.31118,-4.56030
46.10000,-7.32825,-4.55722
46.20000,-7.34478,-4.56181
46.30000,-7.36172,-4.56459
46.40000,-7.37825,-4.56623
46.50000,-7.39492,-4.56965
46.60000,-7.41145,-4.57170
46.70000,-7.42838,-4.56922
46.80000,-7.44478,-4.56919
46.90000,-7.46132,-4.57200
47.00000,-7.47838,-4.57350
47.10000,-7.49478,-4.58014
47.20000,-7.51171,-4.58155
47.30000,-7.52838,-4.57623
47.40000,-7.54491,-4.57880
47.50000,-7.56158,-4.57970
47.60000,-7.57825,-4.57904
47.70000,-7.59491,-4.57856
47.80000,-7.61158,-4.57799
47.90000,-7.62838,-4.57460
48.00000,-7.64478,-4.57359
48.10000,-7.66171,-4.57419
48.20000,-7.67811,-4.56903
48.30000,-7.69478,-4.56780
48.40000,-7.71145,-4.56721
48.50000,-7.72798,-4.56417
48.60000,-7.74491,-4.56047
48.70000,-7.76158,-4.56015
48.80000,-7.77838,-4.55458
48.90000,-7.79465,-4.55040
49.00000,-7.81171,-4.54599
49.10000,-7.82811,-4.53941
49.20000,-7.84465,-4.53401
49.30000,-7.86158,-4.53174
49.40000,-7.87811,-4.52937
49.50000,-7.89491,-4.52306
49.60000,-7.91171,-4.51999
49.70000,-7.92838,-4.51586
49.80000,-7.94478,-4.51266
49.90000,-7.96158,-4.50975
50.00000,-7.97811,-4.50720
50.10000,-7.99465,-4.50264
50.20000,-8.01185,-4.49994
50.30000,-8.02811,-4.49588
50.40000,-8.04491,-4.49048
50.50000,-8.06158,-4.48420
50.60000,-8.07825,-4.48255
50.70000,-8.09478,-4.47325
50.80000,-8.11158,-4.46683
50.90000,-8.12825,-4.45760
51.00000,-8.14478,-4.45323
51.10000,-8.16185,-4.44470
51.20000,-8.17811,-4.43718
51.30000,-8.19518,-4.43342
51.40000,-8.21145,-4.42316
51.50000,-8.22811,-4.41683
51.60000,-8.24491,-4.41157
51.70000,-8.26145,-4.40136
51.80000,-8.27811,-4.39764
51.90000,-8.29478,-4.39931
52.00000,-8.31171,-4.39340
52.10000,-8.32811,-4.39154
52.20000,-8.34505,-4.38686
52.30000,-8.36158,-4.38710
52.40000,-8.37798,-4.38448
52.50000,-8.39491,-4.38313
52.60000,-8.41145,-4.38199
52.70000,-8.42825,-4.37968
52.80000,-8.44491,-4.37733
52.90000,-8.46158,-4.37814
53.00000,-8.47798,-4.37429
53.10000,-8.49491,-4.36829
53.20000,-8.51158,-4.36903
53.30000,-8.52798,-4.36734
53.40000,-8.54518,-4.36693
53.50000,-8.56158,-4.36929
53.60000,-8.57838,-4.36879
53.70000,-8.59505,-4.36374
53.80000,-8.61158,-4.36962
53.90000,-8.62825,-4.37209
54.00000,-8.64491,-4.37594
54.10000,-8.66145,-4.37719
54.20000,-8.67811,-4.37927
54.30000,-8.69505,-4.38229
54.40000,-8.71131,-4.38904
54.50000,-8.72851,-4.38921
54.60000,-8.74491,-4.39182
54.70000,-8.76145,-4.39169
54.80000,-8.77825,-4.38988
54.90000,-8.79465,-4.39229
55.00000,-8.81144,-4.39820
55.10000,-8.82825,-4.39701
55.20000,-8.84505,-4.39814
55.30000,-8.86144,-4.39718
55.40000,-8.87838,-4.39886
55.50000,-8.89478,-4.40457
55.60000,-8.91144,-4.40376
55.70000,-8.92824,-4.40073
55.80000,-8.94478,-4.40508
55.90000,-8.96158,-4.40404
56.00000,-8.97838,-4.40710
56.10000,-8.99518,-4.40756
56.20000,-9.01144,-4.40475
56.30000,-9.02838,-4.40748
56.40000,-9.04478,-4.40442
56.50000,-9.06131,-4.40659
56.60000,-9.07851,-4.40445
56.70000,-9.09478,-4.40791
56.80000,-9.11171,-4.40694
56.90000,-9.12824,-4.40914
57.00000,-9.14491,-4.41119
57.10000,-9.16158,-4.40974
57.20000,-9.17824,-4.41031
57.30000,-9.19478,-4.40840
57.40000,-9.21144,-4.41225
57.50000,-9.22838,-4.41369
57.60000,-9.24491,-4.40883
57.70000,-9.26171,-4.41270
57.80000,-9.27811,-4.41252
57.90000,-9.29464,-4.41325
58.00000,-9.31144,-4.41710
58.10000,-9.32811,-4.42195
58.20000,-9.34478,-4.42246
58.30000,-9.36158,-4.42932
58.40000,-9.37824,-4.43161
58.50000,-9.39478,-4.43792
58.60000,-9.41184,-4.44528
58.70000,-9.42811,-4.45090
58.80000,-9.44464,-4.45714
58.90000,-9.46144,-4.46371
59.00000,-9.47811,-4.47154
59.10000,-9.49491,-4.48085
59.20000,-9.51158,-4.48722
59.30000,-9.52838,-4.49434
59.40000,-9.54478,-4.50092
59.50000,-9.56171,-4.50880
59.60000,-9.57811,-4.51412
59.70000,-9.59464,-4.52000
59.80000,-9.61171,-4.52323
59.90000,-9.62811,-4.52717
60.00000,-9.64504,-4.53949
60.10000,-9.66171,-4.54264
60.20000,-9.67824,-4.55207
60.30000,-9.69478,-4.55585
60.40000,-9.71158,-4.55524
60.50000,-9.72824,-4.55946
60.60000,-9.74491,-4.57166
60.70000,-9.76171,-4.58071
60.80000,-9.77811,-4.58644
60.90000,-9.79518,-4.59597
61.00000,-9.81144,-4.60598
61.10000,-9.82811,-4.61138
61.20000,-9.84491,-4.61604
61.30000,-9.86131,-4.62361
61.40000,-9.87811,-4.62795
61.50000,-9.89478,-4.63141
61.60000,-9.91171,-4.63982
61.70000,-9.92811,-4.64682
61.80000,-9.94491,-4.64962
61.90000,-9.96144,-4.65238
62.00000,-9.97798,-4.65792
62.10000,-9.99491,-4.66165
62.20000,-10.01144,-4.66857
62.30000,-10.02811,-4.67929
62.40000,-10.04491,-4.68707
62.50000,-10.06171,-4.69128
62.60000,-10.07811,-4.69799
62.70000,-10.09504,-4.70195
62.80000,-10.11131,-4.70476
62.90000,-10.12784,-4.71927
63.00000,-10.14504,-4.72598
63.10000,-10.16144,-4.73287
63.20000,-10.17838,-4.74152
63.30000,-10.19504,-4.74528
63.40000,-10.21157,-4.75086
63.50000,-10.22811,-4.75787
63.60000,-10.24504,-4.76831
63.70000,-10.26157,-4.77149
63.80000,-10.27824,-4.78063
63.90000,-10.29518,-4.78754
64.00000,-10.31157,-4.79397
64.10001,-10.32851,-4.80179
64.20000,-10.34477,-4.80775
64.30000,-10.36144,-4.81538
64.40000,-10.37811,-4.82232
64.50000,-10.39477,-4.82860
64.60001,-10.41157,-4.83673
64.70000,-10.42824,-4.84527
64.80000,-10.44504,-4.85134
64.90000,-10.46144,-4.85731
65.00000,-10.47837,-4.86426
65.10001,-10.49477,-4.86696
65.20000,-10.51131,-4.86922
65.30000,-10.52824,-4.87354
65.40000,-10.54477,-4.87853
65.50000,-10.56157,-4.88158
65.60001,-10.57837,-4.88504
65.70001,-10.59504,-4.88800
65.80000,-10.61131,-4.89299
65.90000,-10.62824,-4.89866
66.00000,-10.64464,-4.89992
66.10001,-10.66131,-4.90684
66.20001,-10.67851,-4.91183
66.30000,-10.69464,-4.91573
66.40000,-10.71171,-4.92350
66.50000,-10.72851,-4.92939
66.60001,-10.74504,-4.93498
66.70001,-10.76157,-4.93862
66.80000,-10.77837,-4.94638
66.90000,-10.79491,-4.95065
67.00000,-10.81157,-4.96106
67.10001,-10.82837,-4.96657
67.20001,-10.84477,-4.97368
67.30000,-10.86171,-4.98340
67.40000,-10.87811,-4.99053
67.50000,-10.89464,-4.99962
67.60001,-10.91157,-5.01035
67.70001,-10.92824,-5.02016
67.80000,-10.94491,-5.02895
67.90000,-10.96144,-5.04044
68.00000,-10.97837,-5.05102
68.10001,-10.99477,-5.06125
68.20001,-11.01157,-5.07234
68.30000,-11.02811,-5.08041
68.40000,-11.04464,-5.09110
68.50000,-11.06157,-5.09948
68.60001,-11.07811,-5.10921
68.70001,-11.09504,-5.11987
68.80000,-11.11171,-5.12818
68.90000,-11.12837,-5.13655
69.00000,-11.14477,-5.14497
69.10001,-11.16171,-5.15329
69.20001,-11.17797,-5.15869
69.30000,-11.19464,-5.16774
69.40000,-11.21184,-5.17846
69.50000,-11.22824,-5.18682
69.60001,-11.24517,-5.19598
69.70001,-11.26184,-5.20179
69.80000,-11.27824,-5.20689
69.90000,-11.29464,-5.21384
70.00000,-11.31157,-5.22230
70.10001,-11.32811,-5.22887
70.20001,-11.34477,-5.23830
70.30000,-11.36157,-5.24414
70.40000,-11.37811,-5.25149
70.50000,-11.39517,-5.26001
70.60001,-11.41157,-5.26590
70.70001,-11.42824,-5.27226
70.80000,-11.44491,-5.27707
70.90000,-11.46144,-5.28240
71.00000,-11.47811,-5.28784
71.10001,-11.49477,-5.29616
71.20001,-11.51157,-5.30169
71.30000,-11.52811,-5.30932
71.40000,-11.54504,-5.31727
71.50000,-11.56157,-5.32116
71.60001,-11.57797,-5.32778
71.70001,-11.59491,-5.33474
71.80000,-11.61144,-5.34196
71.90000,-11.62824,-5.34891
72.00000,-11.64504,-5.35531
72.10001,-11.66170,-5.35963
72.20001,-11.67811,-5.36456
72.30000,-11.69504,-5.36899
72.40000,-11.71144,-5.37106
72.50000,-11.72797,-5.37571
72.60001,-11.74517,-5.37889
72.70001,-11.76144,-5.38058
72.80000,-11.77837,-5.38410
72.90000,-11.79504,-5.38460
73.00000,-11.81157,-5.38499
73.10001,-11.82824,-5.38760
73.20001,-11.84477,-5.38794
73.30000,-11.86144,-5.38871
73.40000,-11.87810,-5.39226
73.50000,-11.89504,-5.39280
73.60001,-11.91157,-5.39348
73.70001,-11.92850,-5.39576
73.80000,-11.94477,-5.39486
73.90000,-11.96117,-5.39380
74.00000,-11.97810,-5.39573
74.10001,-11.99464,-5.39570
74.20001,-12.01144,-5.39683
74.30000,-12.02810,-5.40013
74.40000,-12.04490,-5.40208
74.50000,-12.06144,-5.40601
74.60001,-12.07837,-5.40995
74.70001,-12.09490,-5.41043
74.80000,-12.11130,-5.41331
74.90000,-12.12810,-5.41461
75.00000,-12.14490,-5.42031
75.10001,-12.16157,-5.42402
75.20001,-12.17837,-5.42842
75.30000,-12.19504,-5.43236
75.40000,-12.21144,-5.43649
75.50000,-12.22837,-5.44020
75.60001,-12.24477,-5.44148
75.70001,-12.26144,-5.44665
75.80000,-12.27837,-5.44895
75.90000,-12.29477,-5.45151
76.00000,-12.31170,-5.45518
76.10001,-12.32837,-5.45699
76.20001,-12.34490,-5.45858
76.30000,-12.36144,-5.46214
76.40000,-12.37824,-5.46600
76.50000,-12.39477,-5.46873
76.60001,-12.41157,-5.47236
76.70001,-12.42837,-5.47715
76.80000,-12.44477,-5.47984
76.90000,-12.46170,-5.48300
77.00000,-12.47810,-5.48557
77.10001,-12.49477,-5.48772
77.20001,-12.51144,-5.49075
77.30000,-12.52797,-5.49025
77.40000,-12.54477,-5.49217
77.50000,-12.56170,-5.49639
77.60001,-12.57837,-5.49399
77.70001,-12.59490,-5.49364
77.80000,-12.61170,-5.49314
77.90000,-12.62810,-5.48961
78.00000,-12.64464,-5.49101
78.10001,-12.66157,-5.49166
78.20001,-12.67810,-5.49211
78.30000,-12.69490,-5.49183
78.40000,-12.71170,-5.49436
78.50000,-12.72837,-5.49531
78.60001,-12.74477,-5.49374
78.70001,-12.76170,-5.49101
78.80000,-12.77824,-5.48832
78.90000,-12.79477,-5.49001
79.00000,-12.81170,-5.49239
79.10001,-12.82824,-5.49406
79.20001,-12.84504,-5.49684
79.30000,-12.86170,-5.49783
79.40000,-12.87824,-5.49992
79.50000,-12.89490,-5.50188
79.60001,-12.91157,-5.50033
79.70001,-12.92824,-5.49795
79.80000,-12.94490,-5.50164
79.90000,-12.96170,-5.50333
80.00000,-12.97810,-5.50514
80.10001,-12.99504,-5.50974
80.20001,-13.01144,-5.51016
80.30000,-13.02810,-5.51121
80.40000,-13.04490,-5.51343
80.50001,-13.06130,-5.51605
80.60001,-13.07810,-5.51841
80.70001,-13.09477,-5.51977
80.80000,-13.11170,-5.52024
80.90000,-13.12810,-5.52077
81.00001,-13.14490,-5.52185
81.10001,-13.16143,-5.52366
81.20001,-13.17797,-5.52438
81.30000,-13.19490,-5.52313
81.40000,-13.21143,-5.52106
81.50001,-13.22837,-5.52161
81.60001,-13.24503,-5.52036
81.70001,-13.26170,-5.52221
81.80000,-13.27810,-5.52379
81.90000,-13.29490,-5.52360
82.00001,-13.31143,-5.52143
82.10001,-13.32797,-5.52331
82.20001,-13.34503,-5.52611
82.30000,-13.36130,-5.52673
82.40000,-13.37837,-5.53548
82.50001,-13.39503,-5.53642
82.60001,-13.41170,-5.53800
82.70001,-13.42823,-5.54627
82.80000,-13.44490,-5.55205
82.90000,-13.46143,-5.55651
83.00001,-13.47810,-5.55952
83.10001,-13.49503,-5.56457
83.20001,-13.51143,-5.57098
83.30000,-13.52837,-5.58174
83.40000,-13.54477,-5.58893
83.50001,-13.56143,-5.59622
83.60001,-13.57810,-5.60505
83.70001,-13.59463,-5.61586
83.80000,-13.61157,-5.62644
83.90000,-13.62823,-5.63939
84.00001,-13.64503,-5.65255
84.10001,-13.66143,-5.66594
84.20001,-13.67837,-5.68083
84.30000,-13.69477,-5.67167
84.40000,-13.71143,-5.69241
84.50001,-13.72823,-5.70970
84.60001,-13.74477,-5.72715
84.70001,-13.76157,-5.74223
84.80000,-13.77823,-5.75768
84.90000,-13.79503,-5.77027
85.00001,-13.81143,-5.78703
85.10001,-13.82837,-5.80494
85.20001,-13.84477,-5.81676
85.30000,-13.86130,-5.83508
85.40000,-13.87850,-5.84945
85.50001,-13.89477,-5.86684
85.60001,-13.91170,-5.88597
85.70001,-13.92837,-5.90056
85.80000,-13.94490,-5.91275
85.90000,-13.96157,-5.93014
86.00001,-13.97823,-5.94717
86.10001,-13.99477,-5.96167
86.20001,-14.01143,-5.98156
86.30000,-14.02837,-6.00035
86.40000,-14.04490,-6.02074
86.50001,-14.06183,-6.04161
86.60001,-14.07810,-6.05808
86.70001,-14.09477,-6.07363
86.80000,-14.11143,-6.08985
86.90000,-14.12797,-6.10601
87.00001,-14.14477,-6.12455
87.10001,-14.16157,-6.14696
87.20001,-14.17837,-6.16726
87.30000,-14.19477,-6.18838
87.40000,-14.21170,-6.20555
87.50001,-14.22810,-6.22326
87.60001,-14.24477,-6.24535
87.70001,-14.26157,-6.26540
87.80000,-14.27810,-6.28587
87.90000,-14.29503,-6.30139
88.00001,-14.31170,-6.32083
88.10001,-14.32837,-6.34228
88.20001,-14.34476,-6.36341
88.30000,-14.36170,-6.38181
88.40000,-14.37810,-6.39652
88.50001,-14.39476,-6.41595
88.60001,-14.41183,-6.43728
88.70001,-14.42810,-6.45603
88.80000,-14.44503,-6.47707
88.90000,-14.46170,-6.49513
89.00001,-14.47823,-6.51277
89.10001,-14.49476,-6.53233
89.20001,-14.51143,-6.55257
89.30000,-14.52810,-6.56874
89.40000,-14.54476,-6.59142
89.50001,-14.56170,-6.60990
89.60001,-14.57823,-6.63098
89.70001,-14.59516,-6.65115
89.80000,-14.61143,-6.66610
89.90000,-14.62810,-6.68482
90.00001,-14.64476,-6.70192
90.10001,-14.66130,-6.72123
90.20001,-14.67796,-6.74117
90.26000,-14.68823,-6.75501