File: GFBaking/data/2_13PercentGluten/2_13gluten_Compression.is_comp_RawData/Specimen_RawData_8.csv
Time,Extension,Load
(sec),(mm),(N)
0.00000,0.00000,-0.11696
0.10000,-0.00560,-0.11940
0.20000,-0.02520,-0.13867
0.30000,-0.04533,-0.15920
0.40000,-0.06400,-0.17638
0.50000,-0.08160,-0.19192
0.60000,-0.09933,-0.20672
0.70000,-0.11613,-0.22048
0.80000,-0.13307,-0.23392
0.90000,-0.14987,-0.24814
1.00000,-0.16653,-0.26139
1.10000,-0.18307,-0.27618
1.20000,-0.19973,-0.29110
1.30000,-0.21653,-0.30590
1.40000,-0.23307,-0.32207
1.50000,-0.25000,-0.33798
1.60000,-0.26653,-0.35257
1.70000,-0.28320,-0.36770
1.80000,-0.29987,-0.38266
1.90000,-0.31627,-0.39767
2.00000,-0.33293,-0.41585
2.10000,-0.34973,-0.43223
2.20000,-0.36667,-0.44859
2.30000,-0.38320,-0.46472
2.40000,-0.40013,-0.48233
2.50000,-0.41653,-0.49989
2.60000,-0.43320,-0.51778
2.70000,-0.45000,-0.53649
2.80000,-0.46640,-0.55467
2.90000,-0.48320,-0.57191
3.00000,-0.49987,-0.59109
3.10000,-0.51653,-0.61085
3.20000,-0.53347,-0.63047
3.30000,-0.55000,-0.65014
3.40000,-0.56653,-0.66912
3.50000,-0.58333,-0.68864
3.60000,-0.59987,-0.70863
3.70000,-0.61640,-0.72648
3.80000,-0.63347,-0.74786
3.90000,-0.64987,-0.76698
4.00000,-0.66680,-0.78741
4.10000,-0.68346,-0.80825
4.20000,-0.69986,-0.82725
4.30000,-0.71653,-0.84778
4.40000,-0.73320,-0.86902
4.50000,-0.74986,-0.88890
4.60000,-0.76640,-0.90985
4.70000,-0.78333,-0.93063
4.80000,-0.79986,-0.95087
4.90000,-0.81640,-0.97222
5.00000,-0.83333,-0.99238
5.10000,-0.84973,-1.01252
5.20000,-0.86640,-1.03333
5.30000,-0.88306,-1.05411
5.40000,-0.89986,-1.07513
5.50000,-0.91640,-1.09604
5.60000,-0.93320,-1.11783
5.70000,-0.94973,-1.13839
5.80000,-0.96653,-1.16066
5.90000,-0.98320,-1.18006
6.00000,-0.99960,-1.20106
6.10000,-1.01666,-1.22261
6.20000,-1.03333,-1.24362
6.30000,-1.05013,-1.26456
6.40000,-1.06680,-1.28461
6.50000,-1.08333,-1.30565
6.60000,-1.09986,-1.32471
6.70000,-1.11666,-1.34611
6.80000,-1.13333,-1.36616
6.90000,-1.14960,-1.38714
7.00000,-1.16680,-1.40878
7.10000,-1.18320,-1.42895
7.20000,-1.20000,-1.44985
7.30000,-1.21666,-1.47008
7.40000,-1.23306,-1.48999
7.50000,-1.24973,-1.51022
7.60000,-1.26640,-1.53132
7.70000,-1.28320,-1.55164
7.80000,-1.29973,-1.57246
7.90000,-1.31666,-1.59255
8.00000,-1.33320,-1.61149
8.10000,-1.34986,-1.63109
8.20000,-1.36653,-1.64999
8.30000,-1.38293,-1.66902
8.40000,-1.39973,-1.68846
8.50000,-1.41640,-1.70688
8.60000,-1.43320,-1.72637
8.70000,-1.44986,-1.74606
8.80000,-1.46680,-1.76540
8.90000,-1.48320,-1.78426
9.00000,-1.49986,-1.80493
9.10000,-1.51653,-1.82361
9.20000,-1.53293,-1.84310
9.30000,-1.55000,-1.86256
9.40000,-1.56640,-1.88183
9.50000,-1.58333,-1.90150
9.60000,-1.60013,-1.91992
9.70000,-1.61666,-1.93704
9.80000,-1.63320,-1.95486
9.90000,-1.64973,-1.97290
10.00000,-1.66653,-1.99114
10.10000,-1.68306,-2.01052
10.20000,-1.70013,-2.03046
10.30000,-1.71666,-2.04721
10.40000,-1.73333,-2.06437
10.50000,-1.75013,-2.08177
10.60000,-1.76666,-2.09729
10.70000,-1.78333,-2.11480
10.80000,-1.79986,-2.13209
10.90000,-1.81666,-2.14988
11.00000,-1.83306,-2.16702
11.10000,-1.85013,-2.18481
11.20000,-1.86653,-2.20212
11.30000,-1.88333,-2.21788
11.40000,-1.89986,-2.23277
11.50000,-1.91626,-2.24973
11.60000,-1.93320,-2.26637
11.70000,-1.94973,-2.28226
11.80000,-1.96653,-2.29780
11.90000,-1.98320,-2.31429
12.00000,-2.00013,-2.33049
12.10000,-2.01640,-2.34414
12.20000,-2.03319,-2.36073
12.30000,-2.05000,-2.37556
12.40000,-2.06640,-2.39232
12.50000,-2.08333,-2.40743
12.60000,-2.09986,-2.42248
12.70000,-2.11666,-2.43842
12.80000,-2.13333,-2.45414
12.90000,-2.14999,-2.47019
13.00000,-2.16653,-2.48388
13.10000,-2.18319,-2.49996
13.20000,-2.19999,-2.51540
13.30000,-2.21639,-2.52913
13.40000,-2.23346,-2.54306
13.50000,-2.24986,-2.55766
13.60000,-2.26653,-2.57309
13.70000,-2.28333,-2.58755
13.80000,-2.29986,-2.60041
13.90000,-2.31639,-2.61411
14.00000,-2.33306,-2.62758
14.10000,-2.34999,-2.64146
14.20000,-2.36639,-2.65549
14.30000,-2.38346,-2.66924
14.40000,-2.39986,-2.68161
14.50000,-2.41653,-2.69541
14.60000,-2.43333,-2.70870
14.70000,-2.44973,-2.72092
14.80000,-2.46639,-2.73333
14.90000,-2.48293,-2.74606
15.00000,-2.49986,-2.75850
15.10000,-2.51653,-2.75177
15.20000,-2.53333,-2.75479
15.30000,-2.54986,-2.75050
15.40000,-2.56653,-2.76289
15.50000,-2.58319,-2.77801
15.60000,-2.59973,-2.78824
15.70000,-2.61666,-2.80279
15.80000,-2.63306,-2.81543
15.90000,-2.64999,-2.82903
16.00000,-2.66666,-2.84128
16.10000,-2.68346,-2.85278
16.20000,-2.69986,-2.85692
16.30000,-2.71653,-2.78772
16.40000,-2.73319,-2.71699
16.50000,-2.74973,-2.75242
16.60000,-2.76679,-2.77236
16.70000,-2.78333,-2.77650
16.80000,-2.79999,-2.78549
16.90000,-2.81666,-2.80936
17.00000,-2.83319,-2.82969
17.10000,-2.84986,-2.84471
17.20000,-2.86653,-2.85913
17.30000,-2.88333,-2.87259
17.40000,-2.89986,-2.88817
17.50000,-2.91679,-2.85539
17.60000,-2.93319,-2.88061
17.70000,-2.94986,-2.90290
17.80000,-2.96653,-2.91977
17.90000,-2.98293,-2.93498
18.00000,-2.99973,-2.95141
18.10000,-3.01639,-2.96717
18.20000,-3.03333,-2.98052
18.30000,-3.04986,-2.99212
18.40000,-3.06666,-3.00516
18.50000,-3.08319,-3.01721
18.60000,-3.09986,-3.03080
18.70000,-3.11653,-3.04072
18.80000,-3.13293,-3.05379
18.90000,-3.14999,-3.06437
19.00000,-3.16653,-3.07488
19.10000,-3.18333,-3.08625
19.20000,-3.19999,-3.09857
19.30000,-3.21679,-3.10841
19.40000,-3.23319,-3.11618
19.50000,-3.24986,-3.12657
19.60000,-3.26666,-3.13604
19.70000,-3.28306,-3.14592
19.80000,-3.30013,-3.15583
19.90000,-3.31653,-3.16494
20.00000,-3.33333,-3.17491
20.10000,-3.35013,-3.18283
20.20000,-3.36666,-3.19057
20.30000,-3.38319,-3.19929
20.40000,-3.39986,-3.20719
20.50000,-3.41666,-3.21480
20.60000,-3.43292,-3.22150
20.70000,-3.44999,-3.23033
20.80000,-3.46652,-3.23746
20.90000,-3.48319,-3.24454
21.00000,-3.49986,-3.25101
21.10000,-3.51626,-3.25754
21.20000,-3.53306,-3.26518
21.30000,-3.54972,-3.27036
21.40000,-3.56652,-3.27638
21.50000,-3.58319,-3.28286
21.60000,-3.60012,-3.28741
21.70000,-3.61652,-3.29225
21.80000,-3.63319,-3.29937
21.90000,-3.64972,-3.30492
22.00000,-3.66626,-3.31017
22.10000,-3.68332,-3.31596
22.20000,-3.69986,-3.32264
22.30000,-3.71679,-3.32855
22.40000,-3.73332,-3.33419
22.50000,-3.74999,-3.33786
22.60000,-3.76666,-3.34274
22.70000,-3.78332,-3.34648
22.80000,-3.79986,-3.35149
22.90000,-3.81639,-3.35511
23.00000,-3.83346,-3.36154
23.10000,-3.84986,-3.36306
23.20000,-3.86679,-3.36802
23.30000,-3.88346,-3.37043
23.40000,-3.89999,-3.37470
23.50000,-3.91652,-3.37620
23.60000,-3.93319,-3.37997
23.70000,-3.94986,-3.38200
23.80000,-3.96639,-3.38640
23.90000,-3.98332,-3.38934
24.00000,-3.99986,-3.39118
24.10000,-4.01652,-3.39559
24.20000,-4.03319,-3.40003
24.30000,-4.04972,-3.40568
24.40000,-4.06639,-3.40977
24.50000,-4.08292,-3.41449
24.60000,-4.09986,-3.41887
24.70000,-4.11652,-3.42373
24.80000,-4.13332,-3.42664
24.90000,-4.14972,-3.43052
25.00000,-4.16652,-3.43464
25.10000,-4.18319,-3.43716
25.20000,-4.19959,-3.44024
25.30000,-4.21666,-3.44284
25.40000,-4.23319,-3.44642
25.50000,-4.24999,-3.45004
25.60000,-4.26679,-3.45472
25.70000,-4.28346,-3.45804
25.80000,-4.29986,-3.46215
25.90000,-4.31666,-3.46599
26.00000,-4.33319,-3.46927
26.10000,-4.34986,-3.47415
26.20000,-4.36679,-3.47901
26.30000,-4.38332,-3.48334
26.40000,-4.39999,-3.48846
26.50000,-4.41679,-3.49243
26.60000,-4.43319,-3.49634
26.70000,-4.44986,-3.50018
26.80000,-4.46639,-3.50589
26.90000,-4.48319,-3.50929
27.00000,-4.49972,-3.51351
27.10000,-4.51679,-3.51780
27.20000,-4.53332,-3.52093
27.30000,-4.54986,-3.52533
27.40000,-4.56652,-3.52670
27.50000,-4.58306,-3.53029
27.60000,-4.59986,-3.53360
27.70000,-4.61639,-3.53628
27.80000,-4.63332,-3.53999
27.90000,-4.64986,-3.54297
28.00000,-4.66679,-3.54646
28.10000,-4.68319,-3.54850
28.20000,-4.69986,-3.55407
28.30000,-4.71666,-3.55686
28.40000,-4.73306,-3.55998
28.50000,-4.74986,-3.56333
28.60000,-4.76639,-3.56659
28.70000,-4.78332,-3.57130
28.80000,-4.80012,-3.57463
28.90000,-4.81666,-3.57798
29.00000,-4.83319,-3.58028
29.10000,-4.84985,-3.58332
29.20000,-4.86665,-3.58611
29.30000,-4.88305,-3.58944
29.40000,-4.90012,-3.59293
29.50000,-4.91652,-3.59444
29.60000,-4.93332,-3.59765
29.70000,-4.95012,-3.60026
29.80000,-4.96639,-3.60170
29.90000,-4.98319,-3.60344
30.00000,-4.99985,-3.60568
30.10000,-5.01679,-3.60716
30.20000,-5.03305,-3.61000
30.30000,-5.05012,-3.61220
30.40000,-5.06652,-3.61389
30.50000,-5.08319,-3.61596
30.60000,-5.09985,-3.61689
30.70000,-5.11639,-3.61892
30.80000,-5.13305,-3.62132
30.90000,-5.14972,-3.62453
31.00000,-5.16652,-3.62814
31.10000,-5.18305,-3.62866
31.20000,-5.19999,-3.62994
31.30000,-5.21652,-3.63045
31.40000,-5.23319,-3.63374
31.50000,-5.24985,-3.63545
31.60000,-5.26639,-3.63731
31.70000,-5.28332,-3.64002
31.80000,-5.29985,-3.64216
31.90000,-5.31665,-3.64314
32.00000,-5.33332,-3.64414
32.10000,-5.34999,-3.64575
32.20000,-5.36652,-3.64627
32.30000,-5.38319,-3.64773
32.40000,-5.39999,-3.64984
32.50000,-5.41639,-3.65097
32.60000,-5.43332,-3.65332
32.70000,-5.44985,-3.65397
32.80000,-5.46665,-3.65574
32.90000,-5.48345,-3.65593
33.00000,-5.49999,-3.65691
33.10000,-5.51652,-3.65755
33.20000,-5.53319,-3.65809
33.30000,-5.54999,-3.65895
33.40000,-5.56639,-3.65977
33.50000,-5.58332,-3.66056
33.60000,-5.59985,-3.66132
33.70000,-5.61652,-3.66529
33.80000,-5.63319,-3.66577
33.90000,-5.64959,-3.66370
34.00000,-5.66652,-3.66673
34.10000,-5.68305,-3.66794
34.20000,-5.69985,-3.66700
34.30000,-5.71639,-3.66645
34.40000,-5.73332,-3.66839
34.50000,-5.74985,-3.66914
34.60000,-5.76652,-3.67188
34.70000,-5.78319,-3.67229
34.80000,-5.79972,-3.67315
34.90000,-5.81665,-3.67186
35.00000,-5.83319,-3.67414
35.10000,-5.84999,-3.67745
35.20000,-5.86679,-3.68016
35.30000,-5.88332,-3.68371
35.40000,-5.89985,-3.68393
35.50000,-5.91652,-3.68672
35.60000,-5.93319,-3.68771
35.70000,-5.94959,-3.68946
35.80000,-5.96665,-3.69603
35.90000,-5.98332,-3.70103
36.00000,-5.99999,-3.70435
36.10000,-6.01679,-3.70761
36.20000,-6.03319,-3.70866
36.30000,-6.04985,-3.71122
36.40000,-6.06652,-3.71115
36.50000,-6.08332,-3.71503
36.60000,-6.09972,-3.72141
36.70000,-6.11679,-3.72512
36.80000,-6.13319,-3.72759
36.90000,-6.14985,-3.73099
37.00000,-6.16652,-3.73254
37.10000,-6.18305,-3.72966
37.20000,-6.19972,-3.73315
37.30000,-6.21638,-3.73631
37.40000,-6.23318,-3.74210
37.50000,-6.24972,-3.74820
37.60000,-6.26665,-3.75653
37.70000,-6.28318,-3.76177
37.80000,-6.29972,-3.76443
37.90000,-6.31652,-3.76834
38.00000,-6.33305,-3.77681
38.10000,-6.34998,-3.78195
38.20000,-6.36665,-3.78196
38.30000,-6.38332,-3.78367
38.40000,-6.39998,-3.78755
38.50000,-6.41665,-3.78983
38.60000,-6.43332,-3.79320
38.70000,-6.44998,-3.79923
38.80000,-6.46665,-3.80014
38.90000,-6.48305,-3.80164
39.00000,-6.49998,-3.80910
39.10000,-6.51665,-3.81328
39.20000,-6.53332,-3.82034
39.30000,-6.55012,-3.82186
39.40000,-6.56665,-3.82322
39.50000,-6.58318,-3.82463
39.60000,-6.59985,-3.83020
39.70000,-6.61665,-3.83299
39.80000,-6.63305,-3.83887
39.90000,-6.65012,-3.84311
40.00000,-6.66652,-3.84588
40.10000,-6.68318,-3.84956
40.20000,-6.69998,-3.84945
40.30000,-6.71638,-3.85363
40.40000,-6.73318,-3.85868
40.50000,-6.74972,-3.86378
40.60000,-6.76665,-3.86486
40.70000,-6.78318,-3.86649
40.80000,-6.79998,-3.86989
40.90000,-6.81665,-3.87361
41.00000,-6.83318,-3.87844
41.10000,-6.84985,-3.88211
41.20000,-6.86625,-3.88549
41.30000,-6.88318,-3.89197
41.40000,-6.89972,-3.89557
41.50000,-6.91638,-3.90077
41.60000,-6.93318,-3.90538
41.70000,-6.94985,-3.90793
41.80000,-6.96638,-3.91108
41.90000,-6.98318,-3.91690
42.00000,-6.99985,-3.91848
42.10000,-7.01638,-3.92308
42.20000,-7.03345,-3.92643
42.30000,-7.04998,-3.92986
42.40000,-7.06665,-3.93186
42.50000,-7.08345,-3.93432
42.60000,-7.09985,-3.93770
42.70000,-7.11665,-3.93973
42.80000,-7.13318,-3.94354
42.90000,-7.14998,-3.94572
43.00000,-7.16652,-3.94827
43.10000,-7.18345,-3.95220
43.20000,-7.19985,-3.95237
43.30000,-7.21652,-3.96035
43.40000,-7.23332,-3.96061
43.50000,-7.24958,-3.96517
43.60000,-7.26638,-3.96714
43.70000,-7.28305,-3.97041
43.80000,-7.29985,-3.97470
43.90000,-7.31638,-3.98060
44.00000,-7.33332,-3.98414
44.10000,-7.34972,-3.99032
44.20000,-7.36652,-3.99532
44.30000,-7.38332,-4.00246
44.40000,-7.39972,-4.00535
44.50000,-7.41665,-4.01214
44.60000,-7.43318,-4.01543
44.70000,-7.44998,-4.02103
44.80000,-7.46665,-4.02481
44.90000,-7.48332,-4.02859
45.00000,-7.49985,-4.03119
45.10000,-7.51665,-4.03690
45.20000,-7.53318,-4.04001
45.30000,-7.54971,-4.04589
45.40000,-7.56678,-4.05187
45.50000,-7.58318,-4.05609
45.60000,-7.59998,-4.06154
45.70000,-7.61665,-4.06645
45.80000,-7.63318,-4.06747
45.90000,-7.64985,-4.07260
46.00000,-7.66651,-4.07766
46.10000,-7.68331,-4.08043
46.20000,-7.69971,-4.08441
46.30000,-7.71665,-4.08658
46.40000,-7.73318,-4.08916
46.50000,-7.74985,-4.10235
46.60000,-7.76651,-4.10670
46.70000,-7.78291,-4.11038
46.80000,-7.79985,-4.11565
46.90000,-7.81638,-4.11716
47.00000,-7.83331,-4.12178
47.10000,-7.84971,-4.12585
47.20000,-7.86678,-4.13632
47.30000,-7.88318,-4.14068
47.40000,-7.89985,-4.14632
47.50000,-7.91651,-4.14820
47.60000,-7.93291,-4.15157
47.70000,-7.94998,-4.15597
47.80000,-7.96651,-4.16429
47.90000,-7.98331,-4.17189
48.00000,-7.99998,-4.17560
48.10000,-8.01678,-4.18009
48.20000,-8.03318,-4.18472
48.30000,-8.04985,-4.19213
48.40000,-8.06665,-4.19838
48.50000,-8.08305,-4.20311
48.60000,-8.09998,-4.21279
48.70000,-8.11651,-4.21701
48.80000,-8.13318,-4.22044
48.90000,-8.14998,-4.22420
49.00000,-8.16678,-4.22878
49.10000,-8.18345,-4.23299
49.20000,-8.19985,-4.23914
49.30000,-8.21665,-4.24468
49.40000,-8.23305,-4.25672
49.50000,-8.25011,-4.26079
49.60000,-8.26651,-4.26683
49.70000,-8.28318,-4.27179
49.80000,-8.29971,-4.27497
49.90000,-8.31638,-4.28065
50.00000,-8.33305,-4.28574
50.10000,-8.34958,-4.28749
50.20000,-8.36651,-4.29473
50.30000,-8.38318,-4.29988
50.40000,-8.40025,-4.30593
50.50000,-8.41651,-4.30888
50.60000,-8.43318,-4.31462
50.70000,-8.44985,-4.32073
50.80000,-8.46625,-4.32856
50.90000,-8.48318,-4.33441
51.00000,-8.49998,-4.34121
51.10000,-8.51678,-4.34768
51.20000,-8.53345,-4.35261
51.30000,-8.55011,-4.35809
51.40000,-8.56638,-4.36266
51.50000,-8.58331,-4.37017
51.60000,-8.59985,-4.37575
51.70000,-8.61638,-4.38323
51.80000,-8.63345,-4.38863
51.90000,-8.64985,-4.39201
52.00000,-8.66665,-4.39944
52.10000,-8.68331,-4.40322
52.20000,-8.69985,-4.40886
52.30000,-8.71638,-4.41234
52.40000,-8.73305,-4.41637
52.50000,-8.74998,-4.41772
52.60000,-8.76638,-4.42418
52.70000,-8.78358,-4.42771
52.80000,-8.79998,-4.43184
52.90000,-8.81665,-4.43377
53.00000,-8.83345,-4.43628
53.10000,-8.84971,-4.43668
53.20000,-8.86638,-4.44019
53.30000,-8.88305,-4.44272
53.40000,-8.89985,-4.44582
53.50000,-8.91638,-4.44777
53.60000,-8.93331,-4.45326
53.70000,-8.94971,-4.45205
53.80000,-8.96638,-4.45893
53.90000,-8.98331,-4.46228
54.00000,-8.99985,-4.46498
54.10000,-9.01665,-4.47015
54.20000,-9.03318,-4.47166
54.30000,-9.04998,-4.47442
54.40000,-9.06665,-4.47897
54.50000,-9.08331,-4.48161
54.60000,-9.09971,-4.48238
54.70000,-9.11651,-4.49043
54.80000,-9.13331,-4.49261
54.90000,-9.14971,-4.49779
55.00000,-9.16691,-4.50065
55.10000,-9.18318,-4.50524
55.20000,-9.19998,-4.50716
55.30000,-9.21664,-4.51227
55.40000,-9.23331,-4.51409
55.50000,-9.24998,-4.51566
55.60000,-9.26651,-4.51919
55.70000,-9.28331,-4.52154
55.80000,-9.29971,-4.52371
55.90000,-9.31678,-4.52886
56.00000,-9.33304,-4.53147
56.10000,-9.34984,-4.53706
56.20000,-9.36651,-4.53898
56.30000,-9.38304,-4.54277
56.40000,-9.39971,-4.55018
56.50000,-9.41638,-4.55441
56.60000,-9.43318,-4.56027
56.70000,-9.44971,-4.56385
56.80000,-9.46678,-4.56834
56.90000,-9.48318,-4.57050
57.00000,-9.49984,-4.57596
57.10000,-9.51651,-4.57691
57.20000,-9.53291,-4.58105
57.30000,-9.54984,-4.58556
57.40000,-9.56651,-4.58914
57.50000,-9.58318,-4.59314
57.60000,-9.59971,-4.59755
57.70000,-9.61651,-4.60127
57.80000,-9.63291,-4.60429
57.90000,-9.64984,-4.61047
58.00000,-9.66651,-4.61243
58.10000,-9.68304,-4.61642
58.20000,-9.70011,-4.62223
58.30000,-9.71651,-4.62713
58.40000,-9.73344,-4.63223
58.50000,-9.75011,-4.63520
58.60000,-9.76664,-4.63748
58.70000,-9.78318,-4.64002
58.80000,-9.79998,-4.64404
58.90000,-9.81664,-4.64650
59.00000,-9.83304,-4.65216
59.10000,-9.85011,-4.65384
59.20000,-9.86651,-4.65387
59.30000,-9.88318,-4.65779
59.40000,-9.89984,-4.65773
59.50000,-9.91638,-4.66012
59.60000,-9.93304,-4.66367
59.70000,-9.94984,-4.66711
59.80000,-9.96664,-4.66798
59.90000,-9.98304,-4.67059
60.00000,-10.00011,-4.67311
60.10000,-10.01651,-4.67477
60.20000,-10.03318,-4.67704
60.30000,-10.04984,-4.67916
60.40000,-10.06638,-4.68206
60.50000,-10.08331,-4.68662
60.60000,-10.09998,-4.69042
60.70000,-10.11664,-4.69415
60.80000,-10.13331,-4.69904
60.90000,-10.14998,-4.70207
61.00000,-10.16651,-4.70552
61.10000,-10.18331,-4.71025
61.20000,-10.19984,-4.71360
61.30000,-10.21624,-4.71553
61.40000,-10.23344,-4.72227
61.50000,-10.24998,-4.72473
61.60000,-10.26678,-4.72997
61.70000,-10.28331,-4.73252
61.80000,-10.29998,-4.73704
61.90000,-10.31664,-4.74119
62.00000,-10.33331,-4.74608
62.10000,-10.34984,-4.74838
62.20000,-10.36624,-4.75238
62.30000,-10.38344,-4.75708
62.40000,-10.39984,-4.75970
62.50000,-10.41651,-4.76632
62.60000,-10.43317,-4.76978
62.70000,-10.44957,-4.77368
62.80000,-10.46637,-4.77818
62.90000,-10.48304,-4.78099
63.00000,-10.49984,-4.78377
63.10000,-10.51637,-4.78878
63.20000,-10.53344,-4.79242
63.30000,-10.54984,-4.79536
63.40000,-10.56651,-4.80036
63.50000,-10.58331,-4.80205
63.60000,-10.59971,-4.80559
63.70000,-10.61664,-4.81098
63.80000,-10.63331,-4.81562
63.90000,-10.64997,-4.82078
64.00000,-10.66677,-4.82662
64.10001,-10.68331,-4.82957
64.20000,-10.69997,-4.83257
64.30000,-10.71651,-4.83563
64.40000,-10.73317,-4.83771
64.50000,-10.74971,-4.84156
64.60001,-10.76677,-4.84728
64.70000,-10.78317,-4.84998
64.80000,-10.79997,-4.85489
64.90000,-10.81664,-4.85796
65.00000,-10.83331,-4.86179
65.10001,-10.84997,-4.86557
65.20000,-10.86651,-4.87136
65.30000,-10.88317,-4.87480
65.40000,-10.89971,-4.88027
65.50000,-10.91677,-4.88504
65.60001,-10.93304,-4.88749
65.70001,-10.94984,-4.89430
65.80000,-10.96651,-4.89762
65.90000,-10.98304,-4.90115
66.00000,-10.99984,-4.90533
66.10001,-11.01624,-4.91042
66.20001,-11.03317,-4.91760
66.30000,-11.04984,-4.92436
66.40000,-11.06677,-4.93005
66.50000,-11.08304,-4.93433
66.60001,-11.09984,-4.94142
66.70001,-11.11664,-4.94667
66.80000,-11.13291,-4.95316
66.90000,-11.14997,-4.96014
67.00000,-11.16651,-4.96567
67.10001,-11.18331,-4.97210
67.20001,-11.19997,-4.97920
67.30000,-11.21664,-4.98596
67.40000,-11.23317,-4.99123
67.50000,-11.24997,-5.00012
67.60001,-11.26664,-5.00498
67.70001,-11.28304,-5.01250
67.80000,-11.30011,-5.02220
67.90000,-11.31664,-5.02840
68.00000,-11.33331,-5.03655
68.10001,-11.34997,-5.04341
68.20001,-11.36664,-5.04926
68.30000,-11.38331,-5.05558
68.40000,-11.39984,-5.06091
68.50000,-11.41664,-5.06706
68.60001,-11.43304,-5.07453
68.70001,-11.45011,-5.08225
68.80000,-11.46651,-5.08711
68.90000,-11.48317,-5.09429
69.00000,-11.49984,-5.09874
69.10001,-11.51637,-5.10433
69.20001,-11.53304,-5.11187
69.30000,-11.54971,-5.11861
69.40000,-11.56650,-5.12651
69.50000,-11.58304,-5.13440
69.60001,-11.59984,-5.14017
69.70001,-11.61637,-5.14515
69.80000,-11.63317,-5.15299
69.90000,-11.64997,-5.15768
70.00000,-11.66637,-5.16326
70.10001,-11.68330,-5.17132
70.20001,-11.69970,-5.17642
70.30000,-11.71664,-5.18266
70.40000,-11.73344,-5.18860
70.50000,-11.74997,-5.19259
70.60001,-11.76650,-5.19705
70.70001,-11.78317,-5.20430
70.80000,-11.79984,-5.20871
70.90000,-11.81637,-5.21453
71.00000,-11.83330,-5.22073
71.10001,-11.84984,-5.22497
71.20001,-11.86650,-5.22952
71.30000,-11.88330,-5.23525
71.40000,-11.89997,-5.24067
71.50000,-11.91650,-5.24631
71.60001,-11.93317,-5.25361
71.70001,-11.94997,-5.25929
71.80000,-11.96650,-5.26382
71.90000,-11.98344,-5.26874
72.00000,-11.99997,-5.27056
72.10001,-12.01650,-5.27424
72.20001,-12.03317,-5.27648
72.30000,-12.04970,-5.28003
72.40000,-12.06650,-5.28286
72.50000,-12.08304,-5.28731
72.60001,-12.09984,-5.28880
72.70001,-12.11637,-5.29490
72.80000,-12.13330,-5.29796
72.90000,-12.14984,-5.29951
73.00000,-12.16650,-5.30446
73.10001,-12.18317,-5.30501
73.20001,-12.19944,-5.30861
73.30000,-12.21650,-5.31259
73.40000,-12.23317,-5.31595
73.50000,-12.24997,-5.31965
73.60001,-12.26664,-5.32230
73.70001,-12.28344,-5.32594
73.80000,-12.29997,-5.32799
73.90000,-12.31664,-5.33338
74.00000,-12.33330,-5.33577
74.10001,-12.34970,-5.33913
74.20001,-12.36677,-5.34583
74.30000,-12.38330,-5.34909
74.40000,-12.39997,-5.35481
74.50000,-12.41677,-5.35892
74.60001,-12.43330,-5.36248
74.70001,-12.44984,-5.36637
74.80000,-12.46650,-5.37190
74.90000,-12.48330,-5.37663
75.00000,-12.49970,-5.38155
75.10001,-12.51677,-5.38786
75.20001,-12.53317,-5.39206
75.30000,-12.54984,-5.39742
75.40000,-12.56650,-5.40187
75.50000,-12.58304,-5.40610
75.60001,-12.59957,-5.41297
75.70001,-12.61637,-5.41909
75.80000,-12.63317,-5.42541
75.90000,-12.64970,-5.43069
76.00000,-12.66664,-5.43725
76.10001,-12.68317,-5.44362
76.20001,-12.69970,-5.45037
76.30000,-12.71650,-5.45561
76.40000,-12.73304,-5.46143
76.50000,-12.74997,-5.46760
76.60001,-12.76650,-5.47380
76.70001,-12.78344,-5.48276
76.80000,-12.79997,-5.49013
76.90000,-12.81677,-5.49826
77.00000,-12.83330,-5.50341
77.10001,-12.84997,-5.51118
77.20001,-12.86663,-5.51842
77.30000,-12.88304,-5.52381
77.40000,-12.90010,-5.53550
77.50000,-12.91650,-5.53967
77.60001,-12.93317,-5.54655
77.70001,-12.94997,-5.55229
77.80000,-12.96677,-5.56089
77.90000,-12.98317,-5.56344
78.00000,-12.99983,-5.56977
78.10001,-13.01650,-5.57515
78.20001,-13.03304,-5.58108
78.30000,-13.05010,-5.58887
78.40000,-13.06650,-5.59235
78.50000,-13.08317,-5.60266
78.60001,-13.09983,-5.60624
78.70001,-13.11637,-5.61196
78.80000,-13.13304,-5.62033
78.90000,-13.14970,-5.62711
79.00000,-13.16650,-5.63033
79.10001,-13.18303,-5.63787
79.20001,-13.19997,-5.64183
79.30000,-13.21650,-5.64794
79.40000,-13.23317,-5.65351
79.50000,-13.24997,-5.65948
79.60001,-13.26637,-5.66499
79.70001,-13.28330,-5.67146
79.80000,-13.29983,-5.67721
79.90000,-13.31650,-5.68233
80.00000,-13.33330,-5.69083
80.10001,-13.34997,-5.69612
80.20001,-13.36650,-5.70307
80.30000,-13.38330,-5.71210
80.40000,-13.39997,-5.72037
80.50001,-13.41637,-5.72721
80.60001,-13.43343,-5.74000
80.70001,-13.44997,-5.74812
80.80000,-13.46677,-5.75882
80.90000,-13.48330,-5.76684
81.00001,-13.49997,-5.77564
81.10001,-13.51650,-5.78430
81.20001,-13.53317,-5.79532
81.30000,-13.54997,-5.80384
81.40000,-13.56637,-5.81374
81.50001,-13.58330,-5.82479
81.60001,-13.59970,-5.83183
81.70001,-13.61650,-5.84390
81.80000,-13.63330,-5.85235
81.90000,-13.64970,-5.86142
82.00001,-13.66637,-5.87039
82.10001,-13.68303,-5.88011
82.20001,-13.69983,-5.88878
82.30000,-13.71637,-5.90108
82.40000,-13.73343,-5.91157
82.50001,-13.74983,-5.92002
82.60001,-13.76650,-5.93263
82.70001,-13.78330,-5.94136
82.80000,-13.79970,-5.95188
82.90000,-13.81650,-5.96327
83.00001,-13.83303,-5.97501
83.10001,-13.84997,-5.98658
83.20001,-13.86663,-5.99669
83.30000,-13.88343,-6.00758
83.40000,-13.89983,-6.01501
83.50001,-13.91650,-6.02731
83.60001,-13.93330,-6.03692
83.70001,-13.94970,-6.04874
83.80000,-13.96677,-6.05916
83.90000,-13.98317,-6.06852
84.00001,-13.99997,-6.07988
84.10001,-14.01663,-6.09304
84.20001,-14.03317,-6.10337
84.30000,-14.04983,-6.11606
84.40000,-14.06650,-6.13236
84.50001,-14.08330,-6.14760
84.60001,-14.09970,-6.16244
84.70001,-14.11677,-6.17811
84.80000,-14.13317,-6.18823
84.90000,-14.14997,-6.20022
85.00001,-14.16650,-6.20707
85.10001,-14.18303,-6.21826
85.20001,-14.19970,-6.23189
85.30000,-14.21637,-6.24614
85.40000,-14.23317,-6.25927
85.50001,-14.24957,-6.27299
85.60001,-14.26663,-6.28720
85.70001,-14.28303,-6.29860
85.80000,-14.29997,-6.31536
85.90000,-14.31650,-6.33082
86.00001,-14.33303,-6.35593
86.10001,-14.34983,-6.36844
86.20001,-14.36637,-6.38132
86.30000,-14.38330,-6.39615
86.40000,-14.39996,-6.41921
86.50001,-14.41676,-6.44095
86.60001,-14.43317,-6.45388
86.70001,-14.44996,-6.46793
86.80000,-14.46663,-6.47606
86.90000,-14.48303,-6.49507
87.00001,-14.50010,-6.51850
87.10001,-14.51650,-6.53329
87.20001,-14.53330,-6.54726
87.30000,-14.55010,-6.55798
87.40000,-14.56663,-6.57231
87.50001,-14.58316,-6.58654
87.60001,-14.59983,-6.60550
87.70001,-14.61663,-6.61579
87.80000,-14.63303,-6.62761
87.90000,-14.65023,-6.64261
88.00001,-14.66650,-6.66260
88.10001,-14.68316,-6.68008
88.20001,-14.69983,-6.69056
88.30000,-14.71636,-6.70316
88.40000,-14.73303,-6.72020
88.50001,-14.74970,-6.74020
88.60001,-14.76650,-6.75406
88.70001,-14.78303,-6.77113
88.80000,-14.80010,-6.78434
88.90000,-14.81650,-6.80030
89.00001,-14.83316,-6.81926
89.10001,-14.84983,-6.83581
89.20001,-14.86623,-6.84787
89.30000,-14.88330,-6.86645
89.40000,-14.89983,-6.88176
89.50001,-14.91650,-6.89739
89.60001,-14.93316,-6.91284
89.70001,-14.95010,-6.92524
89.80000,-14.96663,-6.93721
89.90000,-14.98316,-6.95795
90.00001,-14.99983,-6.97085
90.10001,-15.01623,-6.99075
90.20001,-15.03343,-7.01137
90.30000,-15.04983,-7.02796
90.30601,-15.05090,-7.03066