File: GFBaking/data/2_13PercentGluten/2_13gluten_Compression.is_comp_RawData/Specimen_RawData_5.csv
Time,Extension,Load
(sec),(mm),(N)
0.00000,-0.00027,-1.02753
0.10000,-0.00573,-1.03442
0.20000,-0.02547,-1.08209
0.30000,-0.04573,-1.13404
0.40000,-0.06440,-1.17810
0.50000,-0.08227,-1.21583
0.60000,-0.09960,-1.25089
0.70000,-0.11653,-1.28553
0.80000,-0.13320,-1.31777
0.90000,-0.14987,-1.34952
1.00000,-0.16693,-1.37771
1.10000,-0.18333,-1.40825
1.20000,-0.20040,-1.43781
1.30000,-0.21693,-1.46604
1.40000,-0.23360,-1.49482
1.50000,-0.25040,-1.52173
1.60000,-0.26667,-1.54769
1.70000,-0.28333,-1.57554
1.80000,-0.29987,-1.60316
1.90000,-0.31693,-1.62792
2.00000,-0.33360,-1.65477
2.10000,-0.35040,-1.67874
2.20000,-0.36693,-1.70154
2.30000,-0.38360,-1.72419
2.40000,-0.40027,-1.74856
2.50000,-0.41667,-1.77132
2.60000,-0.43360,-1.79351
2.70000,-0.45013,-1.81765
2.80000,-0.46693,-1.84054
2.90000,-0.48360,-1.86111
3.00000,-0.50040,-1.88363
3.10000,-0.51680,-1.90746
3.20000,-0.53347,-1.92983
3.30000,-0.55027,-1.94991
3.40000,-0.56667,-1.97145
3.50000,-0.58373,-1.99347
3.60000,-0.60027,-2.00876
3.70000,-0.61693,-2.03097
3.80000,-0.63360,-2.04949
3.90000,-0.65027,-2.06940
4.00000,-0.66693,-2.09152
4.10000,-0.68346,-2.11231
4.20000,-0.70026,-2.13419
4.30000,-0.71680,-2.15486
4.40000,-0.73386,-2.17552
4.50000,-0.75026,-2.19405
4.60000,-0.76680,-2.21577
4.70000,-0.78346,-2.23491
4.80000,-0.80000,-2.25382
4.90000,-0.81680,-2.27427
5.00000,-0.83346,-2.29344
5.10000,-0.85026,-2.31250
5.20000,-0.86693,-2.33280
5.30000,-0.88386,-2.35140
5.40000,-0.90026,-2.37156
5.50000,-0.91680,-2.38813
5.60000,-0.93360,-2.40477
5.70000,-0.95000,-2.42351
5.80000,-0.96693,-2.43942
5.90000,-0.98346,-2.45719
6.00000,-1.00040,-2.47636
6.10000,-1.01706,-2.49522
6.20000,-1.03373,-2.51404
6.30000,-1.05026,-2.53153
6.40000,-1.06693,-2.55015
6.50000,-1.08360,-2.56912
6.60000,-1.10000,-2.58639
6.70000,-1.11720,-2.60602
6.80000,-1.13346,-2.62305
6.90000,-1.15026,-2.64159
7.00000,-1.16706,-2.65997
7.10000,-1.18360,-2.67742
7.20000,-1.20026,-2.69426
7.30000,-1.21693,-2.71142
7.40000,-1.23360,-2.72763
7.50000,-1.25013,-2.74455
7.60000,-1.26706,-2.76144
7.70000,-1.28346,-2.77832
7.80000,-1.30013,-2.79526
7.90000,-1.31693,-2.81097
8.00000,-1.33333,-2.82682
8.10000,-1.35000,-2.84293
8.20000,-1.36666,-2.85884
8.30000,-1.38360,-2.87479
8.40000,-1.40013,-2.89111
8.50000,-1.41706,-2.90803
8.60000,-1.43346,-2.92293
8.70000,-1.45026,-2.93839
8.80000,-1.46693,-2.95382
8.90000,-1.48333,-2.96862
9.00000,-1.50026,-2.98433
9.10000,-1.51693,-3.00021
9.20000,-1.53360,-3.01395
9.30000,-1.55040,-3.03008
9.40000,-1.56706,-3.04533
9.50000,-1.58360,-3.05950
9.60000,-1.60040,-3.07432
9.70000,-1.61706,-3.08875
9.80000,-1.63346,-3.10287
9.90000,-1.65040,-3.11867
10.00000,-1.66693,-3.13100
10.10000,-1.68373,-3.14681
10.20000,-1.70053,-3.16035
10.30000,-1.71693,-3.17370
10.40000,-1.73360,-3.18683
10.50000,-1.75013,-3.20041
10.60000,-1.76693,-3.21287
10.70000,-1.78333,-3.22710
10.80000,-1.80026,-3.23961
10.90000,-1.81693,-3.25218
11.00000,-1.83346,-3.26663
11.10000,-1.85026,-3.27694
11.20000,-1.86666,-3.28896
11.30000,-1.88346,-3.30063
11.40000,-1.90000,-3.31261
11.50000,-1.91693,-3.32488
11.60000,-1.93346,-3.33670
11.70000,-1.95040,-3.34910
11.80000,-1.96680,-3.35959
11.90000,-1.98360,-3.37192
12.00000,-2.00026,-3.38197
12.10000,-2.01653,-3.39300
12.20000,-2.03373,-3.40404
12.30000,-2.05026,-3.41563
12.40000,-2.06706,-3.42553
12.50000,-2.08373,-3.43626
12.60000,-2.10039,-3.44617
12.70000,-2.11693,-3.45542
12.80000,-2.13359,-3.46615
12.90000,-2.15026,-3.47671
13.00000,-2.16666,-3.48706
13.10000,-2.18373,-3.49824
13.20000,-2.20026,-3.50738
13.30000,-2.21693,-3.51802
13.40000,-2.23373,-3.52782
13.50000,-2.25013,-3.53686
13.60000,-2.26679,-3.54668
13.70000,-2.28333,-3.55729
13.80000,-2.30026,-3.56657
13.90000,-2.31666,-3.57733
14.00000,-2.33373,-3.58764
14.10000,-2.35026,-3.59593
14.20000,-2.36693,-3.60585
14.30000,-2.38359,-3.61450
14.40000,-2.39999,-3.62373
14.50000,-2.41693,-3.63358
14.60000,-2.43333,-3.64267
14.70000,-2.45026,-3.65148
14.80000,-2.46679,-3.66072
14.90000,-2.48373,-3.66958
15.00000,-2.50026,-3.67840
15.10000,-2.51693,-3.68749
15.20000,-2.53359,-3.69498
15.30000,-2.54986,-3.70326
15.40000,-2.56693,-3.71211
15.50000,-2.58346,-3.72009
15.60000,-2.60039,-3.72862
15.70000,-2.61693,-3.73713
15.80000,-2.63373,-3.74460
15.90000,-2.65026,-3.75197
16.00000,-2.66679,-3.75885
16.10000,-2.68346,-3.76514
16.20000,-2.69999,-3.77263
16.30000,-2.71719,-3.78139
16.40000,-2.73373,-3.78800
16.50000,-2.75039,-3.79562
16.60000,-2.76706,-3.80273
16.70000,-2.78373,-3.80913
16.80000,-2.80026,-3.81477
16.90000,-2.81679,-3.82099
17.00000,-2.83359,-3.82754
17.10000,-2.85013,-3.83425
17.20000,-2.86719,-3.84203
17.30000,-2.88359,-3.84723
17.40000,-2.90026,-3.85367
17.50000,-2.91693,-3.85946
17.60000,-2.93333,-3.86489
17.70000,-2.95013,-3.87124
17.80000,-2.96679,-3.87606
17.90000,-2.98359,-3.88204
18.00000,-3.00013,-3.88869
18.10000,-3.01706,-3.89538
18.20000,-3.03359,-3.89942
18.30000,-3.05026,-3.90561
18.40000,-3.06693,-3.91097
18.50000,-3.08333,-3.91605
18.60000,-3.10039,-3.92032
18.70000,-3.11679,-3.92463
18.80000,-3.13373,-3.92978
18.90000,-3.15039,-3.93366
19.00000,-3.16706,-3.93697
19.10000,-3.18346,-3.94085
19.20000,-3.20026,-3.94589
19.30000,-3.21693,-3.94875
19.40000,-3.23333,-3.95236
19.50000,-3.25053,-3.95693
19.60000,-3.26693,-3.96038
19.70000,-3.28359,-3.96322
19.80000,-3.30039,-3.96370
19.90000,-3.31693,-3.96383
20.00000,-3.33346,-3.96433
20.10000,-3.34999,-3.96839
20.20000,-3.36693,-3.97131
20.30000,-3.38346,-3.97583
20.40000,-3.40053,-3.98005
20.50000,-3.41692,-3.98267
20.60000,-3.43359,-3.98650
20.70000,-3.45026,-3.98921
20.80000,-3.46666,-3.99209
20.90000,-3.48346,-3.99487
21.00000,-3.49999,-3.99733
21.10000,-3.51692,-4.00071
21.20000,-3.53346,-4.00341
21.30000,-3.55039,-4.00606
21.40000,-3.56692,-4.00778
21.50000,-3.58346,-4.01115
21.60000,-3.60012,-4.01245
21.70000,-3.61666,-4.01438
21.80000,-3.63359,-4.01601
21.90000,-3.65012,-4.01738
22.00000,-3.66679,-4.01989
22.10000,-3.68359,-4.02267
22.20000,-3.70039,-4.02465
22.30000,-3.71692,-4.02560
22.40000,-3.73359,-4.02778
22.50000,-3.75039,-4.02901
22.60000,-3.76679,-4.03094
22.70000,-3.78386,-4.03286
22.80000,-3.80026,-4.03413
22.90000,-3.81706,-4.03645
23.00000,-3.83386,-4.03745
23.10000,-3.85026,-4.03704
23.20000,-3.86692,-4.03719
23.30000,-3.88359,-4.03717
23.40000,-3.90039,-4.03734
23.50000,-3.91666,-4.03703
23.60000,-3.93372,-4.03697
23.70000,-3.95026,-4.03306
23.80000,-3.96692,-4.03128
23.90000,-3.98359,-4.02908
24.00000,-3.99999,-4.02880
24.10000,-4.01652,-4.02723
24.20000,-4.03346,-4.02579
24.30000,-4.05026,-4.02602
24.40000,-4.06679,-4.02553
24.50000,-4.08372,-4.02456
24.60000,-4.10012,-4.02261
24.70000,-4.11679,-4.02332
24.80000,-4.13359,-4.02212
24.90000,-4.14999,-4.01952
25.00000,-4.16692,-4.01811
25.10000,-4.18346,-4.01588
25.20000,-4.20026,-4.01408
25.30000,-4.21706,-4.01270
25.40000,-4.23386,-4.01011
25.50000,-4.25026,-4.00608
25.60000,-4.26692,-4.00436
25.70000,-4.28359,-4.00031
25.80000,-4.30012,-3.99793
25.90000,-4.31719,-3.99762
26.00000,-4.33359,-3.99307
26.10000,-4.35026,-3.99018
26.20000,-4.36706,-3.98764
26.30000,-4.38359,-3.98387
26.40000,-4.40012,-3.97988
26.50000,-4.41692,-3.97812
26.60000,-4.43359,-3.97410
26.70000,-4.44999,-3.97111
26.80000,-4.46719,-3.96734
26.90000,-4.48359,-3.96293
27.00000,-4.50026,-3.95972
27.10000,-4.51692,-3.95412
27.20000,-4.53332,-3.94902
27.30000,-4.54999,-3.94445
27.40000,-4.56666,-3.93831
27.50000,-4.58359,-3.93146
27.60000,-4.60012,-3.92600
27.70000,-4.61706,-3.92095
27.80000,-4.63346,-3.91287
27.90000,-4.65012,-3.90659
28.00000,-4.66692,-3.89918
28.10000,-4.68332,-3.89226
28.20000,-4.70039,-3.88564
28.30000,-4.71706,-3.87848
28.40000,-4.73372,-3.86844
28.50000,-4.75026,-3.86125
28.60000,-4.76706,-3.85193
28.70000,-4.78359,-3.84281
28.80000,-4.80025,-3.83341
28.90000,-4.81692,-3.82223
29.00000,-4.83332,-3.81292
29.10000,-4.85039,-3.80542
29.20000,-4.86692,-3.79493
29.30000,-4.88372,-3.78598
29.40000,-4.90039,-3.77598
29.50000,-4.91692,-3.76664
29.60000,-4.93345,-3.75995
29.70000,-4.94999,-3.75265
29.80000,-4.96692,-3.74672
29.90000,-4.98345,-3.74052
30.00000,-5.00039,-3.73390
30.10000,-5.01679,-3.72796
30.20000,-5.03359,-3.72375
30.30000,-5.05025,-3.71610
30.40000,-5.06679,-3.71054
30.50000,-5.08345,-3.70533
30.60000,-5.09999,-3.70024
30.70000,-5.11692,-3.70050
30.80000,-5.13345,-3.69687
30.90000,-5.15039,-3.68810
31.00000,-5.16679,-3.68403
31.10000,-5.18359,-3.67982
31.20000,-5.20012,-3.67529
31.30000,-5.21679,-3.67136
31.40000,-5.23359,-3.66746
31.50000,-5.25012,-3.66505
31.60000,-5.26705,-3.66053
31.70000,-5.28372,-3.65894
31.80000,-5.30039,-3.65742
31.90000,-5.31692,-3.65142
32.00000,-5.33359,-3.64790
32.10000,-5.35012,-3.64272
32.20000,-5.36679,-3.64090
32.30000,-5.38372,-3.63636
32.40000,-5.40025,-3.63307
32.50000,-5.41705,-3.63118
32.60000,-5.43372,-3.62813
32.70000,-5.45025,-3.62473
32.80000,-5.46692,-3.62426
32.90000,-5.48345,-3.62356
33.00000,-5.50025,-3.62150
33.10000,-5.51665,-3.62210
33.20000,-5.53372,-3.62296
33.30000,-5.55025,-3.62298
33.40000,-5.56692,-3.62440
33.50000,-5.58359,-3.62349
33.60000,-5.60012,-3.62686
33.70000,-5.61679,-3.62588
33.80000,-5.63345,-3.62711
33.90000,-5.65025,-3.62848
34.00000,-5.66679,-3.62841
34.10000,-5.68372,-3.62945
34.20000,-5.70012,-3.62904
34.30000,-5.71679,-3.62919
34.40000,-5.73359,-3.62896
34.50000,-5.74999,-3.62938
34.60000,-5.76692,-3.62926
34.70000,-5.78345,-3.63047
34.80000,-5.80039,-3.63316
34.90000,-5.81719,-3.63468
35.00000,-5.83372,-3.63718
35.10000,-5.85025,-3.63974
35.20000,-5.86679,-3.64173
35.30000,-5.88372,-3.64373
35.40000,-5.90012,-3.64586
35.50000,-5.91705,-3.64605
35.60000,-5.93359,-3.64950
35.70000,-5.95025,-3.65131
35.80000,-5.96705,-3.65299
35.90000,-5.98345,-3.65614
36.00000,-6.00012,-3.65684
36.10000,-6.01679,-3.65960
36.20000,-6.03372,-3.66130
36.30000,-6.05012,-3.66174
36.40000,-6.06719,-3.66509
36.50000,-6.08359,-3.66617
36.60000,-6.10012,-3.66852
36.70000,-6.11692,-3.67121
36.80000,-6.13332,-3.67267
36.90000,-6.14998,-3.67338
37.00000,-6.16665,-3.67534
37.10000,-6.18359,-3.67729
37.20000,-6.20012,-3.67890
37.30000,-6.21705,-3.67977
37.40000,-6.23345,-3.68001
37.50000,-6.25012,-3.68216
37.60000,-6.26692,-3.68295
37.70000,-6.28332,-3.68394
37.80000,-6.30025,-3.68529
37.90000,-6.31678,-3.68583
38.00000,-6.33358,-3.68698
38.10000,-6.35025,-3.68828
38.20000,-6.36705,-3.68823
38.30000,-6.38358,-3.68926
38.40000,-6.40025,-3.69124
38.50000,-6.41692,-3.69104
38.60000,-6.43345,-3.69187
38.70000,-6.45052,-3.69435
38.80000,-6.46692,-3.69546
38.90000,-6.48372,-3.69815
39.00000,-6.50038,-3.70071
39.10000,-6.51692,-3.70159
39.20000,-6.53372,-3.70236
39.30000,-6.55012,-3.70390
39.40000,-6.56705,-3.70523
39.50000,-6.58345,-3.70708
39.60000,-6.60025,-3.70886
39.70000,-6.61692,-3.71113
39.80000,-6.63358,-3.71384
39.90000,-6.65012,-3.71445
40.00000,-6.66652,-3.71573
40.10000,-6.68345,-3.71835
40.20000,-6.70012,-3.72003
40.30000,-6.71705,-3.72224
40.40000,-6.73345,-3.72436
40.50000,-6.75038,-3.72553
40.60000,-6.76692,-3.72616
40.70000,-6.78358,-3.72751
40.80000,-6.80025,-3.72652
40.90000,-6.81665,-3.72697
41.00000,-6.83372,-3.72766
41.10000,-6.85025,-3.72727
41.20000,-6.86705,-3.72969
41.30000,-6.88372,-3.73186
41.40000,-6.90038,-3.73093
41.50000,-6.91692,-3.72984
41.60000,-6.93358,-3.73036
41.70000,-6.95025,-3.72915
41.80000,-6.96665,-3.72769
41.90000,-6.98372,-3.72701
42.00000,-7.00025,-3.72598
42.10000,-7.01705,-3.72566
42.20000,-7.03372,-3.72377
42.30000,-7.05025,-3.71894
42.40000,-7.06692,-3.71652
42.50000,-7.08358,-3.71416
42.60000,-7.10025,-3.70913
42.70000,-7.11678,-3.70994
42.80000,-7.13372,-3.70862
42.90000,-7.15012,-3.70411
43.00000,-7.16692,-3.69936
43.10000,-7.18358,-3.69565
43.20000,-7.20012,-3.69279
43.30000,-7.21678,-3.68482
43.40000,-7.23332,-3.67557
43.50000,-7.25025,-3.66988
43.60000,-7.26665,-3.66273
43.70000,-7.28372,-3.65594
43.80000,-7.30025,-3.65028
43.90000,-7.31678,-3.64404
44.00000,-7.33358,-3.63840
44.10000,-7.34998,-3.63614
44.20000,-7.36692,-3.63380
44.30000,-7.38358,-3.63104
44.40000,-7.40038,-3.62857
44.50000,-7.41705,-3.62210
44.60000,-7.43358,-3.61681
44.70000,-7.45011,-3.61258
44.80000,-7.46692,-3.60799
44.90000,-7.48358,-3.60224
45.00000,-7.49998,-3.60026
45.10000,-7.51705,-3.59781
45.20000,-7.53358,-3.59377
45.30000,-7.55038,-3.59225
45.40000,-7.56705,-3.59097
45.50000,-7.58372,-3.59000
45.60000,-7.60025,-3.58698
45.70000,-7.61691,-3.58524
45.80000,-7.63371,-3.58419
45.90000,-7.65011,-3.58329
46.00000,-7.66705,-3.58297
46.10000,-7.68358,-3.58400
46.20000,-7.70025,-3.58331
46.30000,-7.71705,-3.58361
46.40000,-7.73345,-3.58299
46.50000,-7.75011,-3.58363
46.60000,-7.76678,-3.58478
46.70000,-7.78358,-3.58627
46.80000,-7.80025,-3.58819
46.90000,-7.81705,-3.58884
47.00000,-7.83358,-3.59037
47.10000,-7.85025,-3.59240
47.20000,-7.86691,-3.59386
47.30000,-7.88331,-3.59571
47.40000,-7.90038,-3.59871
47.50000,-7.91678,-3.60009
47.60000,-7.93345,-3.60138
47.70000,-7.95025,-3.60532
47.80000,-7.96691,-3.60841
47.90000,-7.98331,-3.60940
48.00000,-8.00011,-3.61377
48.10000,-8.01705,-3.61616
48.20000,-8.03345,-3.61909
48.30000,-8.05051,-3.62353
48.40000,-8.06691,-3.62707
48.50000,-8.08371,-3.63071
48.60000,-8.10051,-3.63468
48.70000,-8.11691,-3.63779
48.80000,-8.13358,-3.64098
48.90000,-8.15011,-3.64378
49.00000,-8.16705,-3.64745
49.10000,-8.18345,-3.65206
49.20000,-8.20051,-3.65584
49.30000,-8.21691,-3.65809
49.40000,-8.23358,-3.66274
49.50000,-8.25025,-3.66506
49.60000,-8.26665,-3.66782
49.70000,-8.28345,-3.67094
49.80000,-8.30011,-3.67367
49.90000,-8.31691,-3.67717
50.00000,-8.33345,-3.68055
50.10000,-8.35025,-3.68265
50.20000,-8.36678,-3.68475
50.30000,-8.38345,-3.68777
50.40000,-8.40025,-3.68935
50.50000,-8.41665,-3.69134
50.60000,-8.43358,-3.69296
50.70000,-8.45025,-3.69588
50.80000,-8.46705,-3.69811
50.90000,-8.48371,-3.70029
51.00000,-8.50038,-3.70184
51.10000,-8.51691,-3.70079
51.20000,-8.53358,-3.70365
51.30000,-8.55025,-3.70629
51.40000,-8.56678,-3.70976
51.50000,-8.58385,-3.71391
51.60000,-8.60025,-3.71579
51.70000,-8.61691,-3.72115
51.80000,-8.63371,-3.72461
51.90000,-8.65011,-3.72641
52.00000,-8.66678,-3.72879
52.10000,-8.68358,-3.73318
52.20000,-8.70025,-3.73574
52.30000,-8.71678,-3.73891
52.40000,-8.73371,-3.74164
52.50000,-8.75011,-3.74385
52.60000,-8.76691,-3.74669
52.70000,-8.78358,-3.74714
52.80000,-8.79998,-3.74788
52.90000,-8.81678,-3.75088
53.00000,-8.83331,-3.75306
53.10000,-8.85024,-3.75408
53.20000,-8.86678,-3.75790
53.30000,-8.88371,-3.76106
53.40000,-8.90011,-3.76388
53.50000,-8.91691,-3.76500
53.60000,-8.93358,-3.76653
53.70000,-8.94998,-3.77300
53.80000,-8.96691,-3.77359
53.90000,-8.98345,-3.77780
54.00000,-9.00024,-3.78236
54.10000,-9.01704,-3.78448
54.20000,-9.03371,-3.79085
54.30000,-9.05024,-3.79299
54.40000,-9.06691,-3.79697
54.50000,-9.08371,-3.79833
54.60000,-9.10011,-3.79994
54.70000,-9.11718,-3.80432
54.80000,-9.13358,-3.80567
54.90000,-9.15024,-3.80948
55.00000,-9.16704,-3.81158
55.10000,-9.18371,-3.81583
55.20000,-9.20024,-3.81917
55.30000,-9.21678,-3.82206
55.40000,-9.23358,-3.82639
55.50000,-9.25011,-3.83144
55.60000,-9.26704,-3.83520
55.70000,-9.28358,-3.83874
55.80000,-9.30024,-3.84392
55.90000,-9.31678,-3.84679
56.00000,-9.33331,-3.85065
56.10000,-9.35011,-3.85560
56.20000,-9.36664,-3.86013
56.30000,-9.38358,-3.86441
56.40000,-9.40011,-3.86876
56.50000,-9.41718,-3.87371
56.60000,-9.43344,-3.87634
56.70000,-9.45011,-3.87990
56.80000,-9.46691,-3.88185
56.90000,-9.48344,-3.88627
57.00000,-9.50024,-3.88872
57.10000,-9.51691,-3.89302
57.20000,-9.53371,-3.89679
57.30000,-9.55038,-3.90050
57.40000,-9.56704,-3.90453
57.50000,-9.58358,-3.90488
57.60000,-9.60024,-3.90940
57.70000,-9.61691,-3.91073
57.80000,-9.63331,-3.91346
57.90000,-9.65051,-3.91757
58.00000,-9.66691,-3.92118
58.10000,-9.68371,-3.92483
58.20000,-9.70038,-3.92807
58.30000,-9.71704,-3.93461
58.40000,-9.73358,-3.93521
58.50000,-9.75024,-3.93704
58.60000,-9.76691,-3.93828
58.70000,-9.78344,-3.94289
58.80000,-9.80038,-3.94564
58.90000,-9.81678,-3.94810
59.00000,-9.83358,-3.95275
59.10000,-9.85024,-3.95413
59.20000,-9.86664,-3.95647
59.30000,-9.88331,-3.95937
59.40000,-9.89998,-3.96169
59.50000,-9.91704,-3.96511
59.60000,-9.93344,-3.96970
59.70000,-9.95038,-3.97414
59.80000,-9.96664,-3.97698
59.90000,-9.98344,-3.98150
60.00000,-10.00024,-3.98532
60.10000,-10.01678,-3.99095
60.20000,-10.03371,-3.99466
60.30000,-10.05024,-3.99934
60.40000,-10.06704,-4.00403
60.50000,-10.08371,-4.00714
60.60000,-10.10038,-4.01049
60.70000,-10.11678,-4.01246
60.80000,-10.13358,-4.01529
60.90000,-10.15024,-4.01622
61.00000,-10.16664,-4.01817
61.10000,-10.18384,-4.02274
61.20000,-10.20024,-4.02569
61.30000,-10.21691,-4.02937
61.40000,-10.23371,-4.03307
61.50000,-10.25024,-4.03588
61.60000,-10.26691,-4.03824
61.70000,-10.28358,-4.04211
61.80000,-10.30037,-4.04417
61.90000,-10.31678,-4.04750
62.00000,-10.33371,-4.05107
62.10000,-10.35011,-4.05264
62.20000,-10.36678,-4.05643
62.30000,-10.38358,-4.05836
62.40000,-10.40011,-4.06110
62.50000,-10.41678,-4.06449
62.60000,-10.43331,-4.06747
62.70000,-10.45024,-4.07031
62.80000,-10.46677,-4.07367
62.90000,-10.48371,-4.07513
63.00000,-10.50024,-4.07699
63.10000,-10.51677,-4.07995
63.20000,-10.53357,-4.08102
63.30000,-10.54997,-4.08402
63.40000,-10.56691,-4.08597
63.50000,-10.58344,-4.08666
63.60000,-10.60024,-4.08930
63.70000,-10.61691,-4.09057
63.80000,-10.63357,-4.08887
63.90000,-10.64997,-4.08338
64.00000,-10.66691,-4.07896
64.10001,-10.68371,-4.07525
64.20000,-10.70011,-4.07353
64.30000,-10.71717,-4.07376
64.40000,-10.73357,-4.07246
64.50000,-10.75051,-4.07248
64.60001,-10.76717,-4.07182
64.70000,-10.78357,-4.07124
64.80000,-10.80024,-4.07090
64.90000,-10.81691,-4.07252
65.00000,-10.83371,-4.07261
65.10001,-10.85011,-4.07391
65.20000,-10.86717,-4.07487
65.30000,-10.88344,-4.07358
65.40000,-10.90024,-4.07699
65.50000,-10.91691,-4.07627
65.60001,-10.93344,-4.07851
65.70001,-10.95011,-4.07903
65.80000,-10.96677,-4.07917
65.90000,-10.98357,-4.07810
66.00000,-11.00011,-4.07840
66.10001,-11.01717,-4.07941
66.20001,-11.03357,-4.07945
66.30000,-11.05024,-4.08287
66.40000,-11.06691,-4.08475
66.50000,-11.08331,-4.08844
66.60001,-11.10037,-4.09144
66.70001,-11.11691,-4.09588
66.80000,-11.13371,-4.09794
66.90000,-11.15037,-4.10246
67.00000,-11.16704,-4.10479
67.10001,-11.18357,-4.10689
67.20001,-11.20037,-4.11198
67.30000,-11.21691,-4.11438
67.40000,-11.23331,-4.11901
67.50000,-11.25051,-4.12408
67.60001,-11.26691,-4.12730
67.70001,-11.28371,-4.13066
67.80000,-11.30037,-4.13337
67.90000,-11.31677,-4.13446
68.00000,-11.33357,-4.13773
68.10001,-11.35037,-4.14240
68.20001,-11.36717,-4.14466
68.30000,-11.38344,-4.14877
68.40000,-11.40051,-4.15423
68.50000,-11.41704,-4.15881
68.60001,-11.43371,-4.16447
68.70001,-11.45024,-4.16840
68.80000,-11.46677,-4.17419
68.90000,-11.48344,-4.18066
69.00000,-11.50011,-4.18490
69.10001,-11.51691,-4.19017
69.20001,-11.53344,-4.19550
69.30000,-11.55024,-4.20110
69.40000,-11.56677,-4.20562
69.50000,-11.58357,-4.21125
69.60001,-11.60024,-4.21479
69.70001,-11.61664,-4.21853
69.80000,-11.63371,-4.21973
69.90000,-11.65024,-4.21005
70.00000,-11.66717,-3.96715
70.10001,-11.68371,-4.03248
70.20001,-11.70037,-4.06782
70.30000,-11.71691,-4.09309
70.40000,-11.73357,-4.11587
70.50000,-11.75037,-4.13453
70.60001,-11.76677,-4.15098
70.70001,-11.78384,-4.16740
70.80000,-11.80024,-4.17898
70.90000,-11.81704,-4.19209
71.00000,-11.83370,-4.20284
71.10001,-11.85024,-4.21284
71.20001,-11.86690,-4.22103
71.30000,-11.88344,-4.22974
71.40000,-11.90024,-4.23641
71.50000,-11.91677,-4.24261
71.60001,-11.93384,-4.25035
71.70001,-11.95024,-4.25456
71.80000,-11.96677,-4.26206
71.90000,-11.98357,-4.26747
72.00000,-12.00010,-4.27376
72.10001,-12.01677,-4.27922
72.20001,-12.03344,-4.28444
72.30000,-12.05024,-4.28892
72.40000,-12.06677,-4.29414
72.50000,-12.08384,-4.30033
72.60001,-12.10024,-4.30293
72.70001,-12.11690,-4.30770
72.80000,-12.13370,-4.31205
72.90000,-12.14997,-4.31746
73.00000,-12.16704,-4.32066
73.10001,-12.18357,-4.32426
73.20001,-12.20024,-4.32884
73.30000,-12.21690,-4.33212
73.40000,-12.23370,-4.33699
73.50000,-12.25024,-4.33955
73.60001,-12.26704,-4.34457
73.70001,-12.28357,-4.34541
73.80000,-12.30010,-4.34877
73.90000,-12.31717,-4.35360
74.00000,-12.33370,-4.35593
74.10001,-12.35037,-4.35717
74.20001,-12.36704,-4.35833
74.30000,-12.38357,-4.36052
74.40000,-12.40037,-4.36176
74.50000,-12.41690,-4.36312
74.60001,-12.43370,-4.36572
74.70001,-12.45024,-4.36708
74.80000,-12.46704,-4.36759
74.90000,-12.48357,-4.36797
75.00000,-12.50024,-4.37006
75.10001,-12.51690,-4.37149
75.20001,-12.53344,-4.37227
75.30000,-12.55010,-4.37262
75.40000,-12.56664,-4.37346
75.50000,-12.58357,-4.37559
75.60001,-12.60010,-4.37903
75.70001,-12.61690,-4.38010
75.80000,-12.63330,-4.38226
75.90000,-12.65010,-4.38700
76.00000,-12.66704,-4.38996
76.10001,-12.68330,-4.39106
76.20001,-12.70024,-4.39540
76.30000,-12.71690,-4.39657
76.40000,-12.73370,-4.39950
76.50000,-12.75037,-4.40358
76.60001,-12.76717,-4.40504
76.70001,-12.78357,-4.40615
76.80000,-12.80024,-4.40875
76.90000,-12.81690,-4.40897
77.00000,-12.83344,-4.40981
77.10001,-12.85050,-4.41425
77.20001,-12.86690,-4.41387
77.30000,-12.88370,-4.41691
77.40000,-12.90037,-4.41896
77.50000,-12.91690,-4.42177
77.60001,-12.93357,-4.42348
77.70001,-12.95024,-4.42532
77.80000,-12.96704,-4.42614
77.90000,-12.98343,-4.42803
78.00000,-13.00050,-4.43183
78.10001,-13.01690,-4.43331
78.20001,-13.03343,-4.43625
78.30000,-13.05023,-4.43800
78.40000,-13.06677,-4.44070
78.50000,-13.08343,-4.44203
78.60001,-13.10010,-4.44338
78.70001,-13.11690,-4.44500
78.80000,-13.13343,-4.44708
78.90000,-13.15037,-4.44921
79.00000,-13.16690,-4.45059
79.10001,-13.18357,-4.45325
79.20001,-13.20037,-4.45326
79.30000,-13.21677,-4.45595
79.40000,-13.23357,-4.45825
79.50000,-13.25023,-4.46197
79.60001,-13.26703,-4.46476
79.70001,-13.28370,-4.46714
79.80000,-13.30037,-4.46996
79.90000,-13.31690,-4.47138
80.00000,-13.33370,-4.47443
80.10001,-13.35037,-4.47325
80.20001,-13.36690,-4.47479
80.30000,-13.38383,-4.47771
80.40000,-13.40037,-4.47887
80.50001,-13.41717,-4.47940
80.60001,-13.43383,-4.48132
80.70001,-13.45037,-4.48034
80.80000,-13.46703,-4.47929
80.90000,-13.48357,-4.47748
81.00001,-13.50037,-4.47726
81.10001,-13.51677,-4.47611
81.20001,-13.53383,-4.47638
81.30000,-13.55023,-4.47581
81.40000,-13.56677,-4.47745
81.50001,-13.58357,-4.47795
81.60001,-13.59983,-4.47724
81.70001,-13.61663,-4.48112
81.80000,-13.63317,-4.48265
81.90000,-13.65023,-4.48674
82.00001,-13.66677,-4.48904
82.10001,-13.68370,-4.49225
82.20001,-13.70010,-4.49345
82.30000,-13.71677,-4.49674
82.40000,-13.73357,-4.49794
82.50001,-13.75010,-4.50082
82.60001,-13.76703,-4.50267
82.70001,-13.78357,-4.50415
82.80000,-13.80037,-4.50673
82.90000,-13.81717,-4.51126
83.00001,-13.83383,-4.51484
83.10001,-13.85037,-4.51638
83.20001,-13.86703,-4.52332
83.30000,-13.88370,-4.52612
83.40000,-13.90010,-4.53049
83.50001,-13.91717,-4.53771
83.60001,-13.93357,-4.54378
83.70001,-13.95023,-4.54723
83.80000,-13.96703,-4.55126
83.90000,-13.98370,-4.55486
84.00001,-14.00037,-4.55932
84.10001,-14.01690,-4.56302
84.20001,-14.03370,-4.56796
84.30000,-14.04997,-4.57230
84.40000,-14.06703,-4.57701
84.50001,-14.08357,-4.58134
84.60001,-14.10023,-4.58400
84.70001,-14.11690,-4.58876
84.80000,-14.13343,-4.59451
84.90000,-14.15010,-4.60166
85.00001,-14.16677,-4.60883
85.10001,-14.18370,-4.61509
85.20001,-14.20010,-4.62188
85.30000,-14.21703,-4.62878
85.40000,-14.23343,-4.63514
85.50001,-14.25023,-4.64333
85.60001,-14.26703,-4.64807
85.70001,-14.28330,-4.65473
85.80000,-14.30037,-4.66271
85.90000,-14.31703,-4.66823
86.00001,-14.33370,-4.67388
86.10001,-14.35036,-4.68188
86.20001,-14.36703,-4.68633
86.30000,-14.38356,-4.68901
86.40000,-14.40023,-4.69376
86.50001,-14.41703,-4.69598
86.60001,-14.43343,-4.70765
86.70001,-14.45050,-4.71137
86.80000,-14.46690,-4.71034
86.90000,-14.48370,-4.71659
87.00001,-14.50050,-4.72203
87.10001,-14.51690,-4.72478
87.20001,-14.53370,-4.72974
87.30000,-14.55010,-4.73842
87.40000,-14.56690,-4.74149
87.50001,-14.58343,-4.74516
87.60001,-14.60050,-4.75298
87.70001,-14.61676,-4.75718
87.80000,-14.63356,-4.76505
87.90000,-14.65036,-4.77101
88.00001,-14.66676,-4.77874
88.10001,-14.68343,-4.78591
88.20001,-14.70010,-4.79317
88.30000,-14.71690,-4.79985
88.40000,-14.73356,-4.81024
88.50001,-14.75050,-4.81800
88.60001,-14.76676,-4.82567
88.70001,-14.78356,-4.83666
88.80000,-14.80023,-4.84360
88.90000,-14.81676,-4.85194
89.00001,-14.83370,-4.86248
89.10001,-14.85023,-4.87108
89.20001,-14.86703,-4.88210
89.30000,-14.88370,-4.89348
89.40000,-14.90050,-4.90427
89.50001,-14.91690,-4.91359
89.60001,-14.93356,-4.92624
89.70001,-14.95036,-4.93698
89.80000,-14.96676,-4.94948
89.90000,-14.98396,-4.96409
90.00001,-15.00023,-4.97464
90.10001,-15.01690,-4.98839
90.20001,-15.03370,-5.00129
90.23601,-15.03970,-5.00593