File: GFBaking/data/2_13PercentGluten/2_13gluten_Compression.is_comp_RawData/Specimen_RawData_4.csv
Time,Extension,Load
(sec),(mm),(N)
0.00000,-0.00027,-0.29696
0.10000,-0.00573,-0.30133
0.20000,-0.02533,-0.32971
0.30000,-0.04547,-0.35920
0.40000,-0.06427,-0.38444
0.50000,-0.08200,-0.40754
0.60000,-0.09960,-0.42745
0.70000,-0.11640,-0.44806
0.80000,-0.13307,-0.46702
0.90000,-0.15013,-0.48603
1.00000,-0.16640,-0.50456
1.10000,-0.18347,-0.52551
1.20000,-0.20013,-0.54298
1.30000,-0.21693,-0.56319
1.40000,-0.23347,-0.58124
1.50000,-0.25027,-0.60059
1.60000,-0.26693,-0.61966
1.70000,-0.28347,-0.63800
1.80000,-0.30027,-0.65671
1.90000,-0.31667,-0.67533
2.00000,-0.33373,-0.69454
2.10000,-0.35027,-0.71381
2.20000,-0.36680,-0.73263
2.30000,-0.38373,-0.75159
2.40000,-0.40027,-0.77036
2.50000,-0.41680,-0.78711
2.60000,-0.43333,-0.80625
2.70000,-0.45013,-0.82417
2.80000,-0.46667,-0.84156
2.90000,-0.48360,-0.86092
3.00000,-0.50027,-0.87833
3.10000,-0.51693,-0.89720
3.20000,-0.53360,-0.91438
3.30000,-0.55000,-0.93199
3.40000,-0.56667,-0.94911
3.50000,-0.58333,-0.96681
3.60000,-0.60013,-0.98475
3.70000,-0.61667,-1.00308
3.80000,-0.63373,-1.02066
3.90000,-0.65013,-1.03721
4.00000,-0.66680,-1.05479
4.10000,-0.68360,-1.07250
4.20000,-0.69986,-1.08849
4.30000,-0.71680,-1.10718
4.40000,-0.73346,-1.12465
4.50000,-0.75013,-1.14163
4.60000,-0.76693,-1.15925
4.70000,-0.78373,-1.17636
4.80000,-0.80013,-1.19207
4.90000,-0.81680,-1.20965
5.00000,-0.83346,-1.22739
5.10000,-0.84986,-1.24354
5.20000,-0.86706,-1.26178
5.30000,-0.88360,-1.27968
5.40000,-0.90013,-1.29528
5.50000,-0.91693,-1.31249
5.60000,-0.93346,-1.32908
5.70000,-0.95026,-1.34454
5.80000,-0.96666,-1.36149
5.90000,-0.98360,-1.37713
6.00000,-1.00013,-1.39268
6.10000,-1.01720,-1.40929
6.20000,-1.03360,-1.42396
6.30000,-1.05013,-1.43946
6.40000,-1.06693,-1.45406
6.50000,-1.08333,-1.47003
6.60000,-1.10000,-1.48517
6.70000,-1.11666,-1.49995
6.80000,-1.13360,-1.51599
6.90000,-1.15013,-1.53144
7.00000,-1.16706,-1.54626
7.10000,-1.18346,-1.55984
7.20000,-1.20000,-1.57458
7.30000,-1.21693,-1.59030
7.40000,-1.23320,-1.60527
7.50000,-1.25013,-1.62198
7.60000,-1.26693,-1.63491
7.70000,-1.28360,-1.64818
7.80000,-1.30026,-1.66200
7.90000,-1.31693,-1.67646
8.00000,-1.33360,-1.69088
8.10000,-1.35013,-1.70431
8.20000,-1.36693,-1.71726
8.30000,-1.38333,-1.72918
8.40000,-1.40040,-1.74409
8.50000,-1.41680,-1.75654
8.60000,-1.43346,-1.77083
8.70000,-1.45040,-1.78507
8.80000,-1.46693,-1.79685
8.90000,-1.48346,-1.80905
9.00000,-1.50000,-1.82182
9.10000,-1.51693,-1.83585
9.20000,-1.53346,-1.84853
9.30000,-1.55026,-1.86191
9.40000,-1.56693,-1.87421
9.50000,-1.58333,-1.88639
9.60000,-1.60013,-1.89856
9.70000,-1.61666,-1.90991
9.80000,-1.63320,-1.92198
9.90000,-1.65000,-1.93476
10.00000,-1.66693,-1.94689
10.10000,-1.68346,-1.95870
10.20000,-1.70040,-1.97076
10.30000,-1.71680,-1.98117
10.40000,-1.73333,-1.99286
10.50000,-1.75026,-2.00385
10.60000,-1.76653,-2.01451
10.70000,-1.78346,-2.02647
10.80000,-1.80026,-2.03695
10.90000,-1.81680,-2.04776
11.00000,-1.83360,-2.05915
11.10000,-1.85040,-2.07008
11.20000,-1.86693,-2.07963
11.30000,-1.88346,-2.09052
11.40000,-1.90013,-2.09999
11.50000,-1.91666,-2.11167
11.60000,-1.93360,-2.12207
11.70000,-1.95026,-2.13158
11.80000,-1.96693,-2.14155
11.90000,-1.98373,-2.15205
12.00000,-2.00026,-2.16059
12.10000,-2.01693,-2.16980
12.20000,-2.03333,-2.18057
12.30000,-2.05026,-2.18924
12.40000,-2.06666,-2.19860
12.50000,-2.08359,-2.20816
12.60000,-2.10026,-2.21742
12.70000,-2.11666,-2.22626
12.80000,-2.13359,-2.23421
12.90000,-2.14999,-2.24331
13.00000,-2.16666,-2.25199
13.10000,-2.18333,-2.26097
13.20000,-2.20026,-2.26942
13.30000,-2.21666,-2.27798
13.40000,-2.23373,-2.28677
13.50000,-2.25013,-2.29404
13.60000,-2.26666,-2.30193
13.70000,-2.28359,-2.30989
13.80000,-2.29973,-2.31689
13.90000,-2.31693,-2.32459
14.00000,-2.33359,-2.33265
14.10000,-2.35039,-2.34022
14.20000,-2.36706,-2.34758
14.30000,-2.38359,-2.35373
14.40000,-2.40026,-2.35970
14.50000,-2.41679,-2.36682
14.60000,-2.43346,-2.37317
14.70000,-2.44999,-2.37935
14.80000,-2.46693,-2.38710
14.90000,-2.48359,-2.39258
15.00000,-2.50013,-2.39932
15.10000,-2.51693,-2.40576
15.20000,-2.53333,-2.41098
15.30000,-2.55013,-2.41779
15.40000,-2.56666,-2.42435
15.50000,-2.58346,-2.43073
15.60000,-2.59999,-2.43683
15.70000,-2.61706,-2.44362
15.80000,-2.63346,-2.44839
15.90000,-2.65013,-2.45480
16.00000,-2.66693,-2.45975
16.10000,-2.68333,-2.46578
16.20000,-2.70013,-2.47153
16.30000,-2.71666,-2.47706
16.40000,-2.73359,-2.48225
16.50000,-2.75013,-2.48755
16.60000,-2.76706,-2.49275
16.70000,-2.78346,-2.49695
16.80000,-2.79999,-2.50288
16.90000,-2.81693,-2.50820
17.00000,-2.83319,-2.51217
17.10000,-2.85013,-2.51790
17.20000,-2.86693,-2.52232
17.30000,-2.88359,-2.52764
17.40000,-2.90026,-2.53205
17.50000,-2.91693,-2.53828
17.60000,-2.93359,-2.54210
17.70000,-2.94999,-2.54769
17.80000,-2.96679,-2.55198
17.90000,-2.98333,-2.55668
18.00000,-3.00039,-2.56212
18.10000,-3.01693,-2.56603
18.20000,-3.03359,-2.56941
18.30000,-3.05039,-2.57457
18.40000,-3.06693,-2.57788
18.50000,-3.08359,-2.58000
18.60000,-3.10013,-2.58546
18.70000,-3.11693,-2.58683
18.80000,-3.13346,-2.59071
18.90000,-3.15039,-2.59436
19.00000,-3.16693,-2.59748
19.10000,-3.18346,-2.60105
19.20000,-3.20026,-2.60522
19.30000,-3.21653,-2.60779
19.40000,-3.23333,-2.61058
19.50000,-3.24999,-2.61306
19.60000,-3.26693,-2.61633
19.70000,-3.28333,-2.61907
19.80000,-3.30039,-2.62282
19.90000,-3.31679,-2.62461
20.00000,-3.33333,-2.62481
20.10000,-3.35026,-2.62860
20.20000,-3.36653,-2.62991
20.30000,-3.38359,-2.63253
20.40000,-3.40013,-2.63406
20.50000,-3.41692,-2.63520
20.60000,-3.43359,-2.63686
20.70000,-3.45026,-2.63705
20.80000,-3.46679,-2.63837
20.90000,-3.48332,-2.63917
21.00000,-3.50012,-2.63949
21.10000,-3.51666,-2.64091
21.20000,-3.53372,-2.64157
21.30000,-3.55026,-2.64456
21.40000,-3.56692,-2.64547
21.50000,-3.58372,-2.64625
21.60000,-3.60012,-2.64599
21.70000,-3.61692,-2.64678
21.80000,-3.63332,-2.64627
21.90000,-3.65012,-2.64742
22.00000,-3.66679,-2.64615
22.10000,-3.68372,-2.64599
22.20000,-3.70026,-2.64539
22.30000,-3.71679,-2.64409
22.40000,-3.73372,-2.64673
22.50000,-3.74999,-2.64672
22.60000,-3.76652,-2.64726
22.70000,-3.78332,-2.65132
22.80000,-3.80012,-2.65110
22.90000,-3.81666,-2.65335
23.00000,-3.83372,-2.65580
23.10000,-3.85026,-2.65622
23.20000,-3.86679,-2.65904
23.30000,-3.88359,-2.65984
23.40000,-3.89986,-2.66169
23.50000,-3.91679,-2.66364
23.60000,-3.93346,-2.66401
23.70000,-3.95026,-2.66496
23.80000,-3.96679,-2.66800
23.90000,-3.98372,-2.66938
24.00000,-4.00012,-2.66854
24.10000,-4.01679,-2.67054
24.20000,-4.03359,-2.67052
24.30000,-4.04986,-2.67027
24.40000,-4.06706,-2.66972
24.50000,-4.08359,-2.66929
24.60000,-4.10039,-2.66665
24.70000,-4.11706,-2.66852
24.80000,-4.13359,-2.66527
24.90000,-4.15026,-2.66548
25.00000,-4.16692,-2.66300
25.10000,-4.18359,-2.65762
25.20000,-4.20012,-2.65618
25.30000,-4.21706,-2.65474
25.40000,-4.23346,-2.65175
25.50000,-4.25012,-2.64817
25.60000,-4.26692,-2.64354
25.70000,-4.28319,-2.64183
25.80000,-4.29986,-2.63776
25.90000,-4.31679,-2.63468
26.00000,-4.33359,-2.63319
26.10000,-4.34999,-2.63181
26.20000,-4.36692,-2.62884
26.30000,-4.38332,-2.62478
26.40000,-4.39999,-2.62302
26.50000,-4.41692,-2.61974
26.60000,-4.43319,-2.61688
26.70000,-4.45012,-2.61416
26.80000,-4.46679,-2.61251
26.90000,-4.48359,-2.61137
27.00000,-4.50026,-2.61005
27.10000,-4.51706,-2.60873
27.20000,-4.53346,-2.60709
27.30000,-4.54999,-2.60614
27.40000,-4.56692,-2.60434
27.50000,-4.58346,-2.60240
27.60000,-4.60039,-2.60104
27.70000,-4.61679,-2.59933
27.80000,-4.63359,-2.59798
27.90000,-4.65039,-2.59687
28.00000,-4.66679,-2.59556
28.10000,-4.68359,-2.59192
28.20000,-4.69999,-2.59011
28.30000,-4.71692,-2.58954
28.40000,-4.73332,-2.58776
28.50000,-4.75039,-2.58719
28.60000,-4.76692,-2.58565
28.70000,-4.78346,-2.58281
28.80000,-4.80025,-2.58262
28.90000,-4.81666,-2.58083
29.00000,-4.83332,-2.58032
29.10000,-4.84999,-2.57947
29.20000,-4.86679,-2.57715
29.30000,-4.88332,-2.57649
29.40000,-4.90025,-2.57351
29.50000,-4.91679,-2.56936
29.60000,-4.93332,-2.56995
29.70000,-4.95025,-2.56916
29.80000,-4.96652,-2.56716
29.90000,-4.98359,-2.56612
30.00000,-5.00039,-2.56406
30.10000,-5.01692,-2.56302
30.20000,-5.03359,-2.56080
30.30000,-5.05039,-2.55965
30.40000,-5.06692,-2.55729
30.50000,-5.08345,-2.55454
30.60000,-5.10025,-2.55033
30.70000,-5.11665,-2.55053
30.80000,-5.13372,-2.55027
30.90000,-5.15025,-2.54783
31.00000,-5.16692,-2.54487
31.10000,-5.18372,-2.54324
31.20000,-5.20012,-2.54015
31.30000,-5.21679,-2.53793
31.40000,-5.23332,-2.53502
31.50000,-5.25025,-2.53104
31.60000,-5.26665,-2.52852
31.70000,-5.28372,-2.52622
31.80000,-5.30012,-2.52316
31.90000,-5.31679,-2.52164
32.00000,-5.33359,-2.51945
32.10000,-5.34999,-2.51591
32.20000,-5.36665,-2.51499
32.30000,-5.38332,-2.51411
32.40000,-5.40012,-2.51344
32.50000,-5.41679,-2.51156
32.60000,-5.43372,-2.51118
32.70000,-5.45012,-2.50867
32.80000,-5.46679,-2.50809
32.90000,-5.48359,-2.50621
33.00000,-5.49999,-2.50492
33.10000,-5.51679,-2.50341
33.20000,-5.53345,-2.50173
33.30000,-5.55025,-2.50135
33.40000,-5.56692,-2.50045
33.50000,-5.58372,-2.50054
33.60000,-5.60025,-2.49852
33.70000,-5.61679,-2.49717
33.80000,-5.63345,-2.49451
33.90000,-5.65012,-2.49378
34.00000,-5.66705,-2.49287
34.10000,-5.68359,-2.48956
34.20000,-5.70025,-2.48821
34.30000,-5.71705,-2.48612
34.40000,-5.73359,-2.48481
34.50000,-5.75025,-2.48335
34.60000,-5.76665,-2.48306
34.70000,-5.78345,-2.48229
34.80000,-5.79999,-2.48164
34.90000,-5.81692,-2.48008
35.00000,-5.83359,-2.47729
35.10000,-5.85012,-2.47606
35.20000,-5.86692,-2.47305
35.30000,-5.88332,-2.47211
35.40000,-5.90012,-2.46857
35.50000,-5.91679,-2.46735
35.60000,-5.93359,-2.46683
35.70000,-5.95012,-2.46721
35.80000,-5.96692,-2.46632
35.90000,-5.98345,-2.46550
36.00000,-5.99999,-2.46520
36.10000,-6.01692,-2.46473
36.20000,-6.03319,-2.46398
36.30000,-6.05012,-2.46471
36.40000,-6.06679,-2.46387
36.50000,-6.08359,-2.46264
36.60000,-6.10025,-2.46175
36.70000,-6.11692,-2.46185
36.80000,-6.13345,-2.46082
36.90000,-6.14998,-2.46186
37.00000,-6.16692,-2.46226
37.10000,-6.18332,-2.46218
37.20000,-6.20038,-2.46287
37.30000,-6.21678,-2.46132
37.40000,-6.23345,-2.46091
37.50000,-6.25038,-2.46103
37.60000,-6.26678,-2.45989
37.70000,-6.28345,-2.45892
37.80000,-6.29998,-2.45932
37.90000,-6.31692,-2.45986
38.00000,-6.33345,-2.46171
38.10000,-6.35052,-2.46030
38.20000,-6.36692,-2.45962
38.30000,-6.38332,-2.45643
38.40000,-6.40025,-2.45606
38.50000,-6.41665,-2.45499
38.60000,-6.43332,-2.45407
38.70000,-6.44998,-2.45303
38.80000,-6.46692,-2.45279
38.90000,-6.48332,-2.45133
39.00000,-6.50038,-2.45116
39.10000,-6.51678,-2.45050
39.20000,-6.53332,-2.45068
39.30000,-6.55025,-2.45038
39.40000,-6.56652,-2.45012
39.50000,-6.58358,-2.44927
39.60000,-6.60012,-2.44768
39.70000,-6.61692,-2.44833
39.80000,-6.63358,-2.45095
39.90000,-6.65025,-2.45169
40.00000,-6.66678,-2.44998
40.10000,-6.68345,-2.45137
40.20000,-6.70025,-2.45267
40.30000,-6.71665,-2.45224
40.40000,-6.73358,-2.45703
40.50000,-6.75038,-2.45581
40.60000,-6.76692,-2.45558
40.70000,-6.78372,-2.45627
40.80000,-6.80012,-2.45549
40.90000,-6.81678,-2.45770
41.00000,-6.83332,-2.45905
41.10000,-6.85038,-2.45737
41.20000,-6.86678,-2.45781
41.30000,-6.88372,-2.45916
41.40000,-6.90025,-2.46055
41.50000,-6.91692,-2.46245
41.60000,-6.93358,-2.46660
41.70000,-6.94985,-2.46638
41.80000,-6.96652,-2.46759
41.90000,-6.98345,-2.47002
42.00000,-7.00038,-2.47069
42.10000,-7.01678,-2.47456
42.20000,-7.03372,-2.47650
42.30000,-7.05012,-2.47795
42.40000,-7.06665,-2.48120
42.50000,-7.08358,-2.48188
42.60000,-7.09985,-2.48453
42.70000,-7.11678,-2.48839
42.80000,-7.13345,-2.49249
42.90000,-7.15025,-2.49633
43.00000,-7.16692,-2.49926
43.10000,-7.18358,-2.50085
43.20000,-7.20012,-2.50363
43.30000,-7.21665,-2.50694
43.40000,-7.23345,-2.50967
43.50000,-7.24998,-2.51218
43.60000,-7.26692,-2.51502
43.70000,-7.28345,-2.51759
43.80000,-7.30038,-2.51961
43.90000,-7.31705,-2.52271
44.00000,-7.33345,-2.52400
44.10000,-7.35025,-2.52627
44.20000,-7.36678,-2.52961
44.30000,-7.38358,-2.53094
44.40000,-7.39998,-2.53320
44.50000,-7.41705,-2.53772
44.60000,-7.43358,-2.53922
44.70000,-7.45011,-2.54116
44.80000,-7.46692,-2.54256
44.90000,-7.48332,-2.54391
45.00000,-7.49998,-2.54653
45.10000,-7.51665,-2.54938
45.20000,-7.53345,-2.55311
45.30000,-7.54998,-2.55515
45.40000,-7.56705,-2.55762
45.50000,-7.58345,-2.56104
45.60000,-7.59998,-2.56369
45.70000,-7.61678,-2.56713
45.80000,-7.63318,-2.56885
45.90000,-7.65025,-2.57218
46.00000,-7.66705,-2.57535
46.10000,-7.68358,-2.57894
46.20000,-7.70025,-2.58182
46.30000,-7.71691,-2.58573
46.40000,-7.73358,-2.58807
46.50000,-7.75011,-2.59246
46.60000,-7.76678,-2.59506
46.70000,-7.78331,-2.59916
46.80000,-7.80025,-2.60259
46.90000,-7.81678,-2.60560
47.00000,-7.83358,-2.61037
47.10000,-7.85038,-2.61313
47.20000,-7.86678,-2.61648
47.30000,-7.88358,-2.61997
47.40000,-7.90011,-2.62394
47.50000,-7.91691,-2.62709
47.60000,-7.93345,-2.63139
47.70000,-7.95038,-2.63527
47.80000,-7.96691,-2.63856
47.90000,-7.98345,-2.64391
48.00000,-8.00038,-2.64719
48.10000,-8.01678,-2.65079
48.20000,-8.03331,-2.65387
48.30000,-8.05011,-2.65718
48.40000,-8.06691,-2.66053
48.50000,-8.08345,-2.66339
48.60000,-8.10038,-2.66760
48.70000,-8.11678,-2.66925
48.80000,-8.13331,-2.67299
48.90000,-8.15025,-2.67472
49.00000,-8.16651,-2.67664
49.10000,-8.18345,-2.67929
49.20000,-8.19998,-2.68299
49.30000,-8.21665,-2.68625
49.40000,-8.23345,-2.69051
49.50000,-8.25011,-2.69397
49.60000,-8.26665,-2.69664
49.70000,-8.28331,-2.70186
49.80000,-8.30038,-2.70467
49.90000,-8.31665,-2.70745
50.00000,-8.33371,-2.71134
50.10000,-8.35025,-2.71420
50.20000,-8.36691,-2.71602
50.30000,-8.38371,-2.71991
50.40000,-8.40025,-2.72077
50.50000,-8.41691,-2.72211
50.60000,-8.43345,-2.72371
50.70000,-8.45038,-2.72639
50.80000,-8.46678,-2.72863
50.90000,-8.48371,-2.73165
51.00000,-8.50025,-2.73404
51.10000,-8.51665,-2.73812
51.20000,-8.53358,-2.73980
51.30000,-8.54998,-2.74345
51.40000,-8.56665,-2.74578
51.50000,-8.58345,-2.75019
51.60000,-8.60025,-2.75270
51.70000,-8.61665,-2.75584
51.80000,-8.63358,-2.75793
51.90000,-8.64998,-2.75906
52.00000,-8.66678,-2.76105
52.10000,-8.68358,-2.76190
52.20000,-8.69985,-2.76332
52.30000,-8.71678,-2.76629
52.40000,-8.73345,-2.76831
52.50000,-8.75025,-2.76964
52.60000,-8.76691,-2.77188
52.70000,-8.78358,-2.77276
52.80000,-8.80024,-2.77257
52.90000,-8.81678,-2.77339
53.00000,-8.83358,-2.77353
53.10000,-8.84998,-2.77359
53.20000,-8.86704,-2.77489
53.30000,-8.88358,-2.77720
53.40000,-8.90024,-2.77860
53.50000,-8.91691,-2.77976
53.60000,-8.93345,-2.77914
53.70000,-8.95011,-2.78130
53.80000,-8.96678,-2.78202
53.90000,-8.98358,-2.78340
54.00000,-9.00011,-2.78562
54.10000,-9.01704,-2.78789
54.20000,-9.03358,-2.78744
54.30000,-9.05011,-2.78910
54.40000,-9.06691,-2.79047
54.50000,-9.08331,-2.79145
54.60000,-9.09998,-2.79204
54.70000,-9.11664,-2.79361
54.80000,-9.13358,-2.79447
54.90000,-9.14998,-2.79471
55.00000,-9.16704,-2.79430
55.10000,-9.18344,-2.79269
55.20000,-9.20011,-2.79281
55.30000,-9.21691,-2.79168
55.40000,-9.23318,-2.78954
55.50000,-9.25011,-2.79007
55.60000,-9.26678,-2.78957
55.70000,-9.28344,-2.79150
55.80000,-9.30024,-2.79235
55.90000,-9.31704,-2.79416
56.00000,-9.33358,-2.79543
56.10000,-9.35011,-2.79743
56.20000,-9.36691,-2.79792
56.30000,-9.38331,-2.79878
56.40000,-9.40038,-2.80190
56.50000,-9.41691,-2.80198
56.60000,-9.43358,-2.80321
56.70000,-9.45038,-2.80535
56.80000,-9.46691,-2.80695
56.90000,-9.48358,-2.80707
57.00000,-9.50011,-2.80793
57.10000,-9.51691,-2.80885
57.20000,-9.53344,-2.81102
57.30000,-9.55038,-2.81397
57.40000,-9.56691,-2.81480
57.50000,-9.58344,-2.81464
57.60000,-9.60011,-2.81646
57.70000,-9.61664,-2.81598
57.80000,-9.63344,-2.81633
57.90000,-9.64998,-2.81560
58.00000,-9.66691,-2.81617
58.10000,-9.68344,-2.81553
58.20000,-9.70038,-2.81600
58.30000,-9.71678,-2.81506
58.40000,-9.73331,-2.81669
58.50000,-9.75024,-2.81688
58.60000,-9.76664,-2.81708
58.70000,-9.78358,-2.81946
58.80000,-9.80038,-2.82118
58.90000,-9.81691,-2.82196
59.00000,-9.83358,-2.82389
59.10000,-9.85038,-2.82587
59.20000,-9.86691,-2.82651
59.30000,-9.88344,-2.82762
59.40000,-9.90024,-2.82807
59.50000,-9.91664,-2.82936
59.60000,-9.93371,-2.83284
59.70000,-9.95024,-2.83403
59.80000,-9.96691,-2.83527
59.90000,-9.98371,-2.83726
60.00000,-10.00038,-2.83781
60.10000,-10.01678,-2.83753
60.20000,-10.03344,-2.83867
60.30000,-10.05024,-2.84019
60.40000,-10.06678,-2.84038
60.50000,-10.08371,-2.83601
60.60000,-10.10024,-2.84062
60.70000,-10.11664,-2.84143
60.80000,-10.13358,-2.83374
60.90000,-10.14998,-2.83129
61.00000,-10.16664,-2.83376
61.10000,-10.18344,-2.83546
61.20000,-10.20024,-2.83705
61.30000,-10.21664,-2.83787
61.40000,-10.23371,-2.83892
61.50000,-10.25011,-2.83427
61.60000,-10.26664,-2.83373
61.70000,-10.28358,-2.83365
61.80000,-10.29998,-2.83601
61.90000,-10.31691,-2.83560
62.00000,-10.33358,-2.83516
62.10000,-10.35024,-2.83661
62.20000,-10.36691,-2.83469
62.30000,-10.38358,-2.83160
62.40000,-10.40011,-2.83136
62.50000,-10.41678,-2.83254
62.60000,-10.43344,-2.83327
62.70000,-10.44997,-2.83260
62.80000,-10.46704,-2.83587
62.90000,-10.48371,-2.83600
63.00000,-10.50024,-2.83547
63.10000,-10.51717,-2.83626
63.20000,-10.53357,-2.83592
63.30000,-10.55024,-2.83660
63.40000,-10.56691,-2.83379
63.50000,-10.58371,-2.83254
63.60000,-10.60011,-2.83248
63.70000,-10.61704,-2.83261
63.80000,-10.63357,-2.83059
63.90000,-10.64997,-2.82924
64.00000,-10.66691,-2.83025
64.10001,-10.68331,-2.83075
64.20000,-10.70011,-2.83170
64.30000,-10.71677,-2.83361
64.40000,-10.73357,-2.83487
64.50000,-10.74997,-2.83603
64.60001,-10.76704,-2.83768
64.70000,-10.78344,-2.83830
64.80000,-10.80011,-2.84142
64.90000,-10.81691,-2.84182
65.00000,-10.83317,-2.84245
65.10001,-10.85011,-2.84358
65.20000,-10.86691,-2.84478
65.30000,-10.88357,-2.84147
65.40000,-10.90024,-2.84277
65.50000,-10.91691,-2.84439
65.60001,-10.93344,-2.84369
65.70001,-10.94997,-2.84416
65.80000,-10.96691,-2.84344
65.90000,-10.98331,-2.84385
66.00000,-11.00037,-2.84404
66.10001,-11.01691,-2.84349
66.20001,-11.03371,-2.84261
66.30000,-11.05037,-2.84230
66.40000,-11.06677,-2.84166
66.50000,-11.08357,-2.84140
66.60001,-11.10024,-2.84256
66.70001,-11.11704,-2.81198
66.80000,-11.13357,-2.77709
66.90000,-11.15051,-2.79196
67.00000,-11.16691,-2.79853
67.10001,-11.18357,-2.78812
67.20001,-11.20037,-2.79369
67.30000,-11.21677,-2.78980
67.40000,-11.23344,-2.78155
67.50000,-11.24997,-2.74328
67.60001,-11.26691,-2.73215
67.70001,-11.28344,-2.72357
67.80000,-11.30037,-2.72165
67.90000,-11.31677,-2.70778
68.00000,-11.33344,-2.70175
68.10001,-11.35024,-2.70808
68.20001,-11.36651,-2.71869
68.30000,-11.38357,-2.72713
68.40000,-11.40037,-2.73156
68.50000,-11.41691,-2.74020
68.60001,-11.43357,-2.75328
68.70001,-11.45024,-2.76169
68.80000,-11.46691,-2.77050
68.90000,-11.48344,-2.77981
69.00000,-11.50024,-2.78561
69.10001,-11.51664,-2.79262
69.20001,-11.53371,-2.80040
69.30000,-11.55024,-2.80687
69.40000,-11.56691,-2.81271
69.50000,-11.58371,-2.81852
69.60001,-11.60011,-2.82221
69.70001,-11.61691,-2.82819
69.80000,-11.63357,-2.83516
69.90000,-11.65037,-2.83808
70.00000,-11.66677,-2.84293
70.10001,-11.68371,-2.84796
70.20001,-11.70024,-2.85333
70.30000,-11.71691,-2.85725
70.40000,-11.73357,-2.86295
70.50000,-11.74984,-2.86541
70.60001,-11.76677,-2.86956
70.70001,-11.78357,-2.87487
70.80000,-11.80024,-2.87891
70.90000,-11.81677,-2.88560
71.00000,-11.83357,-2.89002
71.10001,-11.85010,-2.89173
71.20001,-11.86677,-2.89632
71.30000,-11.88357,-2.89961
71.40000,-11.89984,-2.90315
71.50000,-11.91677,-2.90709
71.60001,-11.93344,-2.91151
71.70001,-11.95037,-2.91577
71.80000,-11.96690,-2.91895
71.90000,-11.98370,-2.92086
72.00000,-12.00024,-2.92222
72.10001,-12.01664,-2.92537
72.20001,-12.03344,-2.92643
72.30000,-12.05010,-2.92952
72.40000,-12.06717,-2.93783
72.50000,-12.08370,-2.93749
72.60001,-12.10037,-2.93994
72.70001,-12.11717,-2.94069
72.80000,-12.13344,-2.94459
72.90000,-12.15024,-2.94754
73.00000,-12.16677,-2.94896
73.10001,-12.18357,-2.95168
73.20001,-12.20010,-2.95482
73.30000,-12.21704,-2.95474
73.40000,-12.23344,-2.95194
73.50000,-12.24997,-2.95608
73.60001,-12.26690,-2.95672
73.70001,-12.28344,-2.95770
73.80000,-12.30010,-2.95831
73.90000,-12.31677,-2.95830
74.00000,-12.33357,-2.95856
74.10001,-12.34997,-2.95799
74.20001,-12.36704,-2.95967
74.30000,-12.38344,-2.95934
74.40000,-12.40010,-2.96075
74.50000,-12.41690,-2.95840
74.60001,-12.43317,-2.95777
74.70001,-12.45024,-2.95866
74.80000,-12.46690,-2.95846
74.90000,-12.48357,-2.96044
75.00000,-12.50024,-2.96007
75.10001,-12.51704,-2.96095
75.20001,-12.53357,-2.96131
75.30000,-12.55024,-2.96286
75.40000,-12.56677,-2.96565
75.50000,-12.58330,-2.96744
75.60001,-12.60037,-2.97053
75.70001,-12.61690,-2.97242
75.80000,-12.63357,-2.97422
75.90000,-12.65037,-2.97691
76.00000,-12.66690,-2.97765
76.10001,-12.68357,-2.97811
76.20001,-12.70010,-2.98150
76.30000,-12.71704,-2.98540
76.40000,-12.73344,-2.98644
76.50000,-12.75037,-2.99077
76.60001,-12.76690,-2.99338
76.70001,-12.78344,-2.99499
76.80000,-12.80037,-2.99738
76.90000,-12.81663,-2.99972
77.00000,-12.83344,-3.00221
77.10001,-12.84997,-3.00406
77.20001,-12.86690,-3.00543
77.30000,-12.88344,-3.00540
77.40000,-12.90037,-3.00670
77.50000,-12.91663,-3.00102
77.60001,-12.93343,-3.00191
77.70001,-12.95037,-3.00238
77.80000,-12.96650,-3.00227
77.90000,-12.98357,-3.00629
78.00000,-13.00023,-3.00619
78.10001,-13.01690,-3.01071
78.20001,-13.03357,-3.01130
78.30000,-13.05037,-3.01366
78.40000,-13.06690,-3.01438
78.50000,-13.08330,-3.01531
78.60001,-13.10010,-3.01504
78.70001,-13.11663,-3.01642
78.80000,-13.13370,-3.02069
78.90000,-13.15023,-3.02586
79.00000,-13.16690,-3.02753
79.10001,-13.18383,-3.03142
79.20001,-13.20023,-3.03441
79.30000,-13.21703,-3.03505
79.40000,-13.23357,-3.03457
79.50000,-13.25037,-3.04191
79.60001,-13.26677,-3.03838
79.70001,-13.28370,-3.04189
79.80000,-13.30023,-3.04255
79.90000,-13.31690,-3.04609
80.00000,-13.33357,-3.04932
80.10001,-13.34997,-3.04801
80.20001,-13.36663,-3.04905
80.30000,-13.38330,-3.04966
80.40000,-13.40010,-3.05053
80.50001,-13.41663,-3.05415
80.60001,-13.43370,-3.05929
80.70001,-13.45010,-3.06234
80.80000,-13.46663,-3.06272
80.90000,-13.48357,-3.06476
81.00001,-13.49983,-3.06758
81.10001,-13.51677,-3.07258
81.20001,-13.53357,-3.07422
81.30000,-13.55037,-3.07791
81.40000,-13.56690,-3.08296
81.50001,-13.58357,-3.08921
81.60001,-13.60023,-3.08277
81.70001,-13.61677,-3.08734
81.80000,-13.63370,-3.08874
81.90000,-13.65010,-3.09100
82.00001,-13.66703,-3.09597
82.10001,-13.68370,-3.09605
82.20001,-13.70037,-3.10000
82.30000,-13.71717,-3.10850
82.40000,-13.73357,-3.10074
82.50001,-13.75023,-3.10618
82.60001,-13.76677,-3.11104
82.70001,-13.78357,-3.11484
82.80000,-13.80010,-3.11784
82.90000,-13.81717,-3.12391
83.00001,-13.83357,-3.12683
83.10001,-13.85010,-3.12112
83.20001,-13.86703,-3.12532
83.30000,-13.88330,-3.12605
83.40000,-13.89983,-3.13086
83.50001,-13.91650,-3.13385
83.60001,-13.93357,-3.13460
83.70001,-13.94997,-3.13255
83.80000,-13.96703,-3.13309
83.90000,-13.98343,-3.13133
84.00001,-14.00010,-3.13841
84.10001,-14.01690,-3.13756
84.20001,-14.03330,-3.13950
84.30000,-14.05023,-3.14243
84.40000,-14.06690,-3.14340
84.50001,-14.08357,-3.14644
84.60001,-14.10037,-3.14790
84.70001,-14.11703,-3.15195
84.80000,-14.13370,-3.15303
84.90000,-14.15010,-3.15940
85.00001,-14.16703,-3.15996
85.10001,-14.18330,-3.16500
85.20001,-14.20037,-3.16749
85.30000,-14.21690,-3.17378
85.40000,-14.23343,-3.17665
85.50001,-14.25037,-3.17681
85.60001,-14.26690,-3.17890
85.70001,-14.28356,-3.17853
85.80000,-14.30023,-3.17428
85.90000,-14.31690,-3.18227
86.00001,-14.33343,-3.18347
86.10001,-14.35036,-3.18781
86.20001,-14.36690,-3.19133
86.30000,-14.38343,-3.19081
86.40000,-14.40023,-3.19929
86.50001,-14.41663,-3.21055
86.60001,-14.43330,-3.21549
86.70001,-14.44996,-3.22229
86.80000,-14.46690,-3.22549
86.90000,-14.48343,-3.22921
87.00001,-14.50036,-3.24139
87.10001,-14.51676,-3.24663
87.20001,-14.53343,-3.24784
87.30000,-14.55036,-3.25415
87.40000,-14.56663,-3.25607
87.50001,-14.58356,-3.26140
87.60001,-14.60023,-3.27726
87.70001,-14.61690,-3.27269
87.80000,-14.63356,-3.27212
87.90000,-14.65023,-3.28365
88.00001,-14.66690,-3.28674
88.10001,-14.68343,-3.29575
88.20001,-14.70023,-3.29861
88.30000,-14.71663,-3.29620
88.40000,-14.73370,-3.30966
88.50001,-14.75036,-3.31537
88.60001,-14.76703,-3.32257
88.70001,-14.78383,-3.32558
88.80000,-14.80023,-3.32887
88.90000,-14.81690,-3.33186
89.00001,-14.83343,-3.33228
89.10001,-14.85023,-3.34310
89.20001,-14.86663,-3.35255
89.30000,-14.88383,-3.36033
89.40000,-14.90010,-3.36592
89.50001,-14.91676,-3.36902
89.60001,-14.93370,-3.36791
89.70001,-14.94996,-3.37744
89.80000,-14.96663,-3.38259
89.90000,-14.98343,-3.39163
90.00001,-15.00023,-3.39307
90.10001,-15.01676,-3.39639
90.16601,-15.02796,-3.41563