File: GFBaking/data/2_13PercentGluten/2_13gluten_Compression.is_comp_RawData/Specimen_RawData_6.csv
Time,Extension,Load
(sec),(mm),(N)
0.00000,-0.00027,-0.12897
0.10000,-0.00560,-0.13111
0.20000,-0.02547,-0.14830
0.30000,-0.04547,-0.16690
0.40000,-0.06427,-0.18188
0.50000,-0.08187,-0.19540
0.60000,-0.09933,-0.20686
0.70000,-0.11627,-0.21821
0.80000,-0.13333,-0.22890
0.90000,-0.15040,-0.23964
1.00000,-0.16680,-0.24950
1.10000,-0.18373,-0.26009
1.20000,-0.20013,-0.27048
1.30000,-0.21680,-0.27937
1.40000,-0.23347,-0.28907
1.50000,-0.25000,-0.29822
1.60000,-0.26680,-0.30821
1.70000,-0.28360,-0.31858
1.80000,-0.30053,-0.32883
1.90000,-0.31680,-0.33885
2.00000,-0.33373,-0.34926
2.10000,-0.35000,-0.35905
2.20000,-0.36653,-0.36991
2.30000,-0.38347,-0.38054
2.40000,-0.40000,-0.39139
2.50000,-0.41707,-0.40169
2.60000,-0.43373,-0.41124
2.70000,-0.45040,-0.42184
2.80000,-0.46680,-0.43243
2.90000,-0.48360,-0.44381
3.00000,-0.50013,-0.45308
3.10000,-0.51667,-0.46337
3.20000,-0.53373,-0.47325
3.30000,-0.55013,-0.48428
3.40000,-0.56707,-0.49509
3.50000,-0.58373,-0.50538
3.60000,-0.60040,-0.51591
3.70000,-0.61693,-0.52709
3.80000,-0.63360,-0.53776
3.90000,-0.65013,-0.54902
4.00000,-0.66680,-0.55981
4.10000,-0.68373,-0.57052
4.20000,-0.70026,-0.58138
4.30000,-0.71706,-0.59201
4.40000,-0.73346,-0.60278
4.50000,-0.75013,-0.61448
4.60000,-0.76680,-0.62386
4.70000,-0.78333,-0.63471
4.80000,-0.80026,-0.64600
4.90000,-0.81706,-0.65784
5.00000,-0.83373,-0.66874
5.10000,-0.85013,-0.67982
5.20000,-0.86706,-0.69127
5.30000,-0.88333,-0.70128
5.40000,-0.90000,-0.71164
5.50000,-0.91680,-0.72285
5.60000,-0.93346,-0.73432
5.70000,-0.95026,-0.74563
5.80000,-0.96706,-0.75668
5.90000,-0.98386,-0.76718
6.00000,-1.00013,-0.77840
6.10000,-1.01720,-0.78828
6.20000,-1.03346,-0.79790
6.30000,-1.05000,-0.81000
6.40000,-1.06706,-0.82106
6.50000,-1.08346,-0.83139
6.60000,-1.10040,-0.84246
6.70000,-1.11706,-0.85382
6.80000,-1.13373,-0.86441
6.90000,-1.15026,-0.87409
7.00000,-1.16693,-0.88470
7.10000,-1.18346,-0.89520
7.20000,-1.20013,-0.90533
7.30000,-1.21706,-0.91458
7.40000,-1.23346,-0.92499
7.50000,-1.25053,-0.93555
7.60000,-1.26680,-0.94544
7.70000,-1.28346,-0.95500
7.80000,-1.30013,-0.96460
7.90000,-1.31666,-0.97360
8.00000,-1.33360,-0.98284
8.10000,-1.35026,-0.99263
8.20000,-1.36706,-1.00280
8.30000,-1.38346,-1.01303
8.40000,-1.40040,-1.02281
8.50000,-1.41680,-1.03170
8.60000,-1.43333,-1.04185
8.70000,-1.45013,-1.05147
8.80000,-1.46693,-1.06166
8.90000,-1.48386,-1.07203
9.00000,-1.50040,-1.08193
9.10000,-1.51706,-1.09082
9.20000,-1.53346,-1.10050
9.30000,-1.55040,-1.11002
9.40000,-1.56680,-1.11792
9.50000,-1.58333,-1.12677
9.60000,-1.60040,-1.13470
9.70000,-1.61680,-1.14372
9.80000,-1.63373,-1.15338
9.90000,-1.65040,-1.16306
10.00000,-1.66680,-1.17254
10.10000,-1.68333,-1.18097
10.20000,-1.70013,-1.19088
10.30000,-1.71666,-1.19884
10.40000,-1.73346,-1.20782
10.50000,-1.75040,-1.21519
10.60000,-1.76680,-1.22298
10.70000,-1.78373,-1.23097
10.80000,-1.80026,-1.23833
10.90000,-1.81693,-1.24632
11.00000,-1.83346,-1.25355
11.10000,-1.85000,-1.26171
11.20000,-1.86693,-1.26872
11.30000,-1.88360,-1.27867
11.40000,-1.90040,-1.28792
11.50000,-1.91680,-1.29817
11.60000,-1.93373,-1.30546
11.70000,-1.95013,-1.31249
11.80000,-1.96666,-1.31837
11.90000,-1.98360,-1.32671
12.00000,-2.00013,-1.33375
12.10000,-2.01706,-1.34119
12.20000,-2.03373,-1.34830
12.30000,-2.05040,-1.35437
12.40000,-2.06680,-1.36213
12.50000,-2.08359,-1.36892
12.60000,-2.09999,-1.37652
12.70000,-2.11666,-1.38549
12.80000,-2.13386,-1.39459
12.90000,-2.15026,-1.40197
13.00000,-2.16706,-1.40918
13.10000,-2.18359,-1.41593
13.20000,-2.20026,-1.42122
13.30000,-2.21693,-1.42776
13.40000,-2.23359,-1.43394
13.50000,-2.25013,-1.44059
13.60000,-2.26693,-1.44669
13.70000,-2.28386,-1.45232
13.80000,-2.30013,-1.45825
13.90000,-2.31719,-1.46425
14.00000,-2.33346,-1.46977
14.10000,-2.34999,-1.47519
14.20000,-2.36679,-1.48057
14.30000,-2.38346,-1.48569
14.40000,-2.40026,-1.49053
14.50000,-2.41693,-1.49614
14.60000,-2.43373,-1.50051
14.70000,-2.45013,-1.50489
14.80000,-2.46706,-1.50990
14.90000,-2.48346,-1.51203
15.00000,-2.50013,-1.51671
15.10000,-2.51693,-1.52035
15.20000,-2.53346,-1.52537
15.30000,-2.55039,-1.53020
15.40000,-2.56706,-1.53591
15.50000,-2.58373,-1.53977
15.60000,-2.60013,-1.54194
15.70000,-2.61706,-1.54602
15.80000,-2.63346,-1.54871
15.90000,-2.64999,-1.55357
16.00000,-2.66706,-1.55784
16.10000,-2.68346,-1.56316
16.20000,-2.70039,-1.56888
16.30000,-2.71693,-1.57432
16.40000,-2.73373,-1.57997
16.50000,-2.75013,-1.58609
16.60000,-2.76679,-1.58845
16.70000,-2.78346,-1.59325
16.80000,-2.80026,-1.59992
16.90000,-2.81719,-1.60487
17.00000,-2.83346,-1.60918
17.10000,-2.85053,-1.61333
17.20000,-2.86693,-1.61667
17.30000,-2.88346,-1.62100
17.40000,-2.90013,-1.62616
17.50000,-2.91666,-1.63388
17.60000,-2.93346,-1.64416
17.70000,-2.95026,-1.64399
17.80000,-2.96706,-1.64399
17.90000,-2.98346,-1.64734
18.00000,-3.00039,-1.65037
18.10000,-3.01679,-1.64619
18.20000,-3.03346,-1.64656
18.30000,-3.05026,-1.65141
18.40000,-3.06679,-1.65372
18.50000,-3.08359,-1.65612
18.60000,-3.10026,-1.66011
18.70000,-3.11706,-1.66306
18.80000,-3.13346,-1.66552
18.90000,-3.15039,-1.67372
19.00000,-3.16679,-1.67802
19.10000,-3.18346,-1.68319
19.20000,-3.20039,-1.68318
19.30000,-3.21679,-1.68588
19.40000,-3.23386,-1.68792
19.50000,-3.25039,-1.69009
19.60000,-3.26693,-1.69275
19.70000,-3.28359,-1.69566
19.80000,-3.30039,-1.69879
19.90000,-3.31693,-1.70268
20.00000,-3.33359,-1.71001
20.10000,-3.35039,-1.71240
20.20000,-3.36679,-1.71838
20.30000,-3.38386,-1.72495
20.40000,-3.40013,-1.72888
20.50000,-3.41679,-1.72835
20.60000,-3.43332,-1.73021
20.70000,-3.45012,-1.73398
20.80000,-3.46679,-1.73758
20.90000,-3.48359,-1.73756
21.00000,-3.50039,-1.73957
21.10000,-3.51679,-1.74726
21.20000,-3.53372,-1.75105
21.30000,-3.55012,-1.75518
21.40000,-3.56666,-1.76204
21.50000,-3.58346,-1.77184
21.60000,-3.59999,-1.77401
21.70000,-3.61692,-1.77742
21.80000,-3.63372,-1.78534
21.90000,-3.65052,-1.78894
22.00000,-3.66679,-1.79170
22.10000,-3.68372,-1.79309
22.20000,-3.69999,-1.79290
22.30000,-3.71679,-1.79866
22.40000,-3.73386,-1.80369
22.50000,-3.75026,-1.81023
22.60000,-3.76706,-1.81613
22.70000,-3.78372,-1.81709
22.80000,-3.80026,-1.82123
22.90000,-3.81679,-1.82885
23.00000,-3.83346,-1.83286
23.10000,-3.84999,-1.83631
23.20000,-3.86679,-1.83991
23.30000,-3.88372,-1.84154
23.40000,-3.90012,-1.84639
23.50000,-3.91719,-1.85358
23.60000,-3.93346,-1.85653
23.70000,-3.95012,-1.86008
23.80000,-3.96679,-1.86378
23.90000,-3.98332,-1.86905
24.00000,-4.00012,-1.87297
24.10000,-4.01692,-1.87835
24.20000,-4.03372,-1.88305
24.30000,-4.05012,-1.88681
24.40000,-4.06706,-1.88950
24.50000,-4.08332,-1.89486
24.60000,-4.09999,-1.89660
24.70000,-4.11692,-1.89959
24.80000,-4.13346,-1.90412
24.90000,-4.15039,-1.90742
25.00000,-4.16706,-1.91118
25.10000,-4.18359,-1.91145
25.20000,-4.20012,-1.91612
25.30000,-4.21706,-1.91731
25.40000,-4.23346,-1.92086
25.50000,-4.24999,-1.92515
25.60000,-4.26692,-1.93613
25.70000,-4.28346,-1.93937
25.80000,-4.30052,-1.93727
25.90000,-4.31706,-1.93859
26.00000,-4.33359,-1.94292
26.10000,-4.35012,-1.94107
26.20000,-4.36679,-1.94176
26.30000,-4.38346,-1.94397
26.40000,-4.40026,-1.94623
26.50000,-4.41706,-1.94621
26.60000,-4.43346,-1.94559
26.70000,-4.45052,-1.95073
26.80000,-4.46679,-1.94990
26.90000,-4.48346,-1.95345
27.00000,-4.50012,-1.95374
27.10000,-4.51666,-1.95718
27.20000,-4.53346,-1.95862
27.30000,-4.55026,-1.96034
27.40000,-4.56706,-1.96120
27.50000,-4.58346,-1.96336
27.60000,-4.60039,-1.96611
27.70000,-4.61666,-1.96764
27.80000,-4.63346,-1.96805
27.90000,-4.65026,-1.97111
28.00000,-4.66679,-1.97591
28.10000,-4.68359,-1.97578
28.20000,-4.70039,-1.97860
28.30000,-4.71719,-1.97997
28.40000,-4.73346,-1.98432
28.50000,-4.75026,-1.98494
28.60000,-4.76666,-1.98823
28.70000,-4.78346,-1.99096
28.80000,-4.80039,-1.99175
28.90000,-4.81692,-1.99027
29.00000,-4.83385,-1.99279
29.10000,-4.85025,-1.99413
29.20000,-4.86692,-1.99390
29.30000,-4.88359,-1.99724
29.40000,-4.90012,-1.99945
29.50000,-4.91665,-2.00070
29.60000,-4.93359,-2.00357
29.70000,-4.95052,-2.00664
29.80000,-4.96692,-2.00825
29.90000,-4.98385,-2.01084
30.00000,-5.00012,-2.01203
30.10000,-5.01692,-2.01535
30.20000,-5.03345,-2.01772
30.30000,-5.05012,-2.02074
30.40000,-5.06692,-2.02336
30.50000,-5.08359,-2.02679
30.60000,-5.10039,-2.02862
30.70000,-5.11665,-2.03120
30.80000,-5.13372,-2.03439
30.90000,-5.15012,-2.03733
31.00000,-5.16665,-2.03978
31.10000,-5.18359,-2.04329
31.20000,-5.19999,-2.04645
31.30000,-5.21692,-2.04954
31.40000,-5.23372,-2.05381
31.50000,-5.25039,-2.05707
31.60000,-5.26679,-2.06234
31.70000,-5.28359,-2.06595
31.80000,-5.30012,-2.06831
31.90000,-5.31692,-2.07235
32.00000,-5.33372,-2.07569
32.10000,-5.35012,-2.07791
32.20000,-5.36705,-2.08155
32.30000,-5.38372,-2.08543
32.40000,-5.40025,-2.08789
32.50000,-5.41679,-2.08933
32.60000,-5.43345,-2.09111
32.70000,-5.45025,-2.09039
32.80000,-5.46692,-2.08913
32.90000,-5.48385,-2.09082
33.00000,-5.50012,-2.09335
33.10000,-5.51705,-2.09624
33.20000,-5.53345,-2.09800
33.30000,-5.55012,-2.10305
33.40000,-5.56679,-2.10772
33.50000,-5.58332,-2.11206
33.60000,-5.60012,-2.11468
33.70000,-5.61692,-2.12008
33.80000,-5.63372,-2.12516
33.90000,-5.65012,-2.12815
34.00000,-5.66705,-2.13196
34.10000,-5.68345,-2.13391
34.20000,-5.70012,-2.13973
34.30000,-5.71692,-2.14163
34.40000,-5.73345,-2.14531
34.50000,-5.75039,-2.14842
34.60000,-5.76692,-2.15173
34.70000,-5.78359,-2.15265
34.80000,-5.80012,-2.15721
34.90000,-5.81705,-2.16029
35.00000,-5.83345,-2.16093
35.10000,-5.84999,-2.16283
35.20000,-5.86719,-2.16594
35.30000,-5.88359,-2.16820
35.40000,-5.90052,-2.17229
35.50000,-5.91705,-2.17446
35.60000,-5.93359,-2.17721
35.70000,-5.95012,-2.17957
35.80000,-5.96679,-2.18335
35.90000,-5.98345,-2.18593
36.00000,-6.00025,-2.19070
36.10000,-6.01705,-2.19161
36.20000,-6.03345,-2.19386
36.30000,-6.05052,-2.19775
36.40000,-6.06679,-2.20105
36.50000,-6.08332,-2.20343
36.60000,-6.10012,-2.20525
36.70000,-6.11679,-2.20808
36.80000,-6.13345,-2.21087
36.90000,-6.15025,-2.21359
37.00000,-6.16705,-2.21623
37.10000,-6.18332,-2.21780
37.20000,-6.20052,-2.22188
37.30000,-6.21678,-2.22292
37.40000,-6.23345,-2.22800
37.50000,-6.25025,-2.23100
37.60000,-6.26678,-2.23570
37.70000,-6.28372,-2.23925
37.80000,-6.30038,-2.24233
37.90000,-6.31705,-2.24693
38.00000,-6.33345,-2.24857
38.10000,-6.35025,-2.25183
38.20000,-6.36678,-2.25528
38.30000,-6.38332,-2.25688
38.40000,-6.40038,-2.25951
38.50000,-6.41692,-2.26123
38.60000,-6.43372,-2.26594
38.70000,-6.45038,-2.26619
38.80000,-6.46692,-2.26967
38.90000,-6.48358,-2.26904
39.00000,-6.50025,-2.26938
39.10000,-6.51678,-2.26885
39.20000,-6.53358,-2.27300
39.30000,-6.55052,-2.27590
39.40000,-6.56678,-2.27892
39.50000,-6.58372,-2.28305
39.60000,-6.60012,-2.28490
39.70000,-6.61678,-2.28790
39.80000,-6.63345,-2.28923
39.90000,-6.65012,-2.29255
40.00000,-6.66678,-2.29561
40.10000,-6.68358,-2.29965
40.20000,-6.70038,-2.30073
40.30000,-6.71678,-2.30512
40.40000,-6.73358,-2.30812
40.50000,-6.74998,-2.30964
40.60000,-6.76665,-2.31391
40.70000,-6.78358,-2.31814
40.80000,-6.80025,-2.32268
40.90000,-6.81705,-2.32591
41.00000,-6.83372,-2.32960
41.10000,-6.85038,-2.33145
41.20000,-6.86678,-2.33463
41.30000,-6.88358,-2.33525
41.40000,-6.90012,-2.33860
41.50000,-6.91665,-2.34257
41.60000,-6.93372,-2.34632
41.70000,-6.95012,-2.34963
41.80000,-6.96718,-2.35352
41.90000,-6.98358,-2.35482
42.00000,-7.00025,-2.35728
42.10000,-7.01692,-2.36040
42.20000,-7.03358,-2.36410
42.30000,-7.05025,-2.36645
42.40000,-7.06692,-2.37014
42.50000,-7.08372,-2.37233
42.60000,-7.10025,-2.37353
42.70000,-7.11718,-2.37551
42.80000,-7.13358,-2.37642
42.90000,-7.15025,-2.37951
43.00000,-7.16692,-2.38138
43.10000,-7.18345,-2.38523
43.20000,-7.20025,-2.38886
43.30000,-7.21692,-2.39184
43.40000,-7.23372,-2.39406
43.50000,-7.25012,-2.39687
43.60000,-7.26705,-2.40027
43.70000,-7.28332,-2.40235
43.80000,-7.30012,-2.40640
43.90000,-7.31678,-2.40888
44.00000,-7.33332,-2.41241
44.10000,-7.34998,-2.41500
44.20000,-7.36678,-2.41675
44.30000,-7.38358,-2.41832
44.40000,-7.39985,-2.42100
44.50000,-7.41678,-2.42360
44.60000,-7.43345,-2.42717
44.70000,-7.45011,-2.43059
44.80000,-7.46705,-2.43291
44.90000,-7.48358,-2.43403
45.00000,-7.50038,-2.43696
45.10000,-7.51705,-2.43876
45.20000,-7.53358,-2.44257
45.30000,-7.55025,-2.44683
45.40000,-7.56691,-2.45013
45.50000,-7.58358,-2.45412
45.60000,-7.60025,-2.45796
45.70000,-7.61718,-2.46121
45.80000,-7.63345,-2.46515
45.90000,-7.65038,-2.46925
46.00000,-7.66678,-2.47158
46.10000,-7.68345,-2.47640
46.20000,-7.70011,-2.47975
46.30000,-7.71678,-2.48175
46.40000,-7.73358,-2.48282
46.50000,-7.75025,-2.48845
46.60000,-7.76705,-2.48892
46.70000,-7.78345,-2.49106
46.80000,-7.80038,-2.49582
46.90000,-7.81678,-2.49792
47.00000,-7.83331,-2.50094
47.10000,-7.85025,-2.50349
47.20000,-7.86678,-2.50759
47.30000,-7.88371,-2.51072
47.40000,-7.90038,-2.51463
47.50000,-7.91705,-2.51943
47.60000,-7.93345,-2.52357
47.70000,-7.95025,-2.52688
47.80000,-7.96678,-2.52909
47.90000,-7.98345,-2.53320
48.00000,-8.00038,-2.53677
48.10000,-8.01678,-2.54014
48.20000,-8.03371,-2.54457
48.30000,-8.05038,-2.54810
48.40000,-8.06678,-2.55177
48.50000,-8.08345,-2.55463
48.60000,-8.10025,-2.55835
48.70000,-8.11678,-2.56005
48.80000,-8.13345,-2.56360
48.90000,-8.15038,-2.56498
49.00000,-8.16678,-2.56688
49.10000,-8.18385,-2.56944
49.20000,-8.20011,-2.57098
49.30000,-8.21678,-2.57328
49.40000,-8.23345,-2.57579
49.50000,-8.25011,-2.57970
49.60000,-8.26691,-2.58233
49.70000,-8.28358,-2.58533
49.80000,-8.30038,-2.58756
49.90000,-8.31678,-2.59116
50.00000,-8.33371,-2.59446
50.10000,-8.35011,-2.59707
50.20000,-8.36678,-2.60082
50.30000,-8.38345,-2.60335
50.40000,-8.40011,-2.60728
50.50000,-8.41691,-2.60948
50.60000,-8.43371,-2.61295
50.70000,-8.45038,-2.61485
50.80000,-8.46678,-2.61681
50.90000,-8.48358,-2.62043
51.00000,-8.50011,-2.62290
51.10000,-8.51665,-2.62781
51.20000,-8.53371,-2.63174
51.30000,-8.55025,-2.63599
51.40000,-8.56718,-2.64041
51.50000,-8.58358,-2.64440
51.60000,-8.60025,-2.64935
51.70000,-8.61691,-2.65426
51.80000,-8.63358,-2.66046
51.90000,-8.65011,-2.66441
52.00000,-8.66691,-2.67075
52.10000,-8.68371,-2.67490
52.20000,-8.70011,-2.68072
52.30000,-8.71718,-2.68378
52.40000,-8.73345,-2.68739
52.50000,-8.74998,-2.69177
52.60000,-8.76691,-2.69721
52.70000,-8.78345,-2.70274
52.80000,-8.80011,-2.70613
52.90000,-8.81691,-2.71192
53.00000,-8.83371,-2.71486
53.10000,-8.85011,-2.71913
53.20000,-8.86704,-2.72483
53.30000,-8.88331,-2.72703
53.40000,-8.90011,-2.73238
53.50000,-8.91678,-2.73489
53.60000,-8.93358,-2.74001
53.70000,-8.95038,-2.74355
53.80000,-8.96704,-2.74764
53.90000,-8.98371,-2.75134
54.00000,-9.00011,-2.75592
54.10000,-9.01704,-2.75985
54.20000,-9.03331,-2.76273
54.30000,-9.05011,-2.76672
54.40000,-9.06704,-2.77030
54.50000,-9.08358,-2.77366
54.60000,-9.10038,-2.77693
54.70000,-9.11704,-2.78001
54.80000,-9.13371,-2.78259
54.90000,-9.15024,-2.78548
55.00000,-9.16691,-2.78701
55.10000,-9.18344,-2.78893
55.20000,-9.20024,-2.79268
55.30000,-9.21704,-2.79421
55.40000,-9.23344,-2.79634
55.50000,-9.25051,-2.79979
55.60000,-9.26678,-2.80109
55.70000,-9.28344,-2.80313
55.80000,-9.29998,-2.80460
55.90000,-9.31664,-2.80617
56.00000,-9.33344,-2.80798
56.10000,-9.35024,-2.80827
56.20000,-9.36704,-2.80842
56.30000,-9.38344,-2.80960
56.40000,-9.40038,-2.81218
56.50000,-9.41678,-2.81411
56.60000,-9.43344,-2.81531
56.70000,-9.45024,-2.81556
56.80000,-9.46678,-2.81719
56.90000,-9.48358,-2.81922
57.00000,-9.50038,-2.82068
57.10000,-9.51704,-2.82218
57.20000,-9.53331,-2.82422
57.30000,-9.55024,-2.82751
57.40000,-9.56678,-2.82964
57.50000,-9.58344,-2.83250
57.60000,-9.60038,-2.83565
57.70000,-9.61691,-2.83945
57.80000,-9.63371,-2.84317
57.90000,-9.65011,-2.84612
58.00000,-9.66704,-2.85165
58.10000,-9.68358,-2.85507
58.20000,-9.70024,-2.85899
58.30000,-9.71691,-2.86091
58.40000,-9.73358,-2.86560
58.50000,-9.75038,-2.86878
58.60000,-9.76678,-2.87225
58.70000,-9.78384,-2.87695
58.80000,-9.80011,-2.88000
58.90000,-9.81678,-2.88316
59.00000,-9.83344,-2.88714
59.10000,-9.84998,-2.89009
59.20000,-9.86678,-2.89427
59.30000,-9.88358,-2.89991
59.40000,-9.90024,-2.90248
59.50000,-9.91664,-2.90649
59.60000,-9.93371,-2.91174
59.70000,-9.94998,-2.91340
59.80000,-9.96664,-2.91820
59.90000,-9.98358,-2.92141
60.00000,-10.00011,-2.92631
60.10000,-10.01704,-2.93065
60.20000,-10.03358,-2.93437
60.30000,-10.05038,-2.93792
60.40000,-10.06678,-2.94202
60.50000,-10.08371,-2.94600
60.60000,-10.10011,-2.94843
60.70000,-10.11678,-2.95318
60.80000,-10.13358,-2.95633
60.90000,-10.14998,-2.96081
61.00000,-10.16704,-2.96568
61.10000,-10.18371,-2.97116
61.20000,-10.20037,-2.97516
61.30000,-10.21678,-2.97859
61.40000,-10.23358,-2.98149
61.50000,-10.25011,-2.98392
61.60000,-10.26691,-2.98791
61.70000,-10.28371,-2.98818
61.80000,-10.30011,-2.87082
61.90000,-10.31717,-2.87194
62.00000,-10.33358,-2.87202
62.10000,-10.35024,-2.89280
62.20000,-10.36691,-2.91045
62.30000,-10.38344,-2.92543
62.40000,-10.40011,-2.93913
62.50000,-10.41691,-2.95172
62.60000,-10.43371,-2.96183
62.70000,-10.45024,-2.97167
62.80000,-10.46704,-2.98051
62.90000,-10.48344,-2.98755
63.00000,-10.49997,-2.99573
63.10000,-10.51677,-3.00312
63.20000,-10.53344,-3.01184
63.30000,-10.55024,-3.01876
63.40000,-10.56704,-3.02456
63.50000,-10.58371,-3.02954
63.60000,-10.60011,-3.03498
63.70000,-10.61704,-3.04083
63.80000,-10.63344,-3.04405
63.90000,-10.64997,-3.01510
64.00000,-10.66717,-2.85155
64.10001,-10.68357,-2.89530
64.20000,-10.70051,-2.92489
64.30000,-10.71704,-2.94492
64.40000,-10.73371,-2.96166
64.50000,-10.75024,-2.97619
64.60001,-10.76704,-2.99062
64.70000,-10.78357,-3.00241
64.80000,-10.80011,-3.01334
64.90000,-10.81704,-3.02418
65.00000,-10.83357,-3.03307
65.10001,-10.85051,-3.04384
65.20000,-10.86677,-3.05105
65.30000,-10.88331,-3.06005
65.40000,-10.90011,-3.06864
65.50000,-10.91677,-3.07644
65.60001,-10.93344,-3.08268
65.70001,-10.95024,-3.08974
65.80000,-10.96704,-3.09693
65.90000,-10.98344,-3.10372
66.00000,-11.00037,-3.11052
66.10001,-11.01677,-3.11624
66.20001,-11.03344,-3.12330
66.30000,-11.05024,-3.12770
66.40000,-11.06677,-3.13354
66.50000,-11.08371,-3.13984
66.60001,-11.10037,-3.14743
66.70001,-11.11704,-3.15340
66.80000,-11.13344,-3.15913
66.90000,-11.15037,-3.16544
67.00000,-11.16677,-3.17038
67.10001,-11.18331,-3.17591
67.20001,-11.20051,-3.18214
67.30000,-11.21691,-3.18895
67.40000,-11.23384,-3.19459
67.50000,-11.25024,-3.19914
67.60001,-11.26691,-3.20462
67.70001,-11.28357,-3.21077
67.80000,-11.30024,-3.21404
67.90000,-11.31677,-3.21552
68.00000,-11.33357,-3.22022
68.10001,-11.35037,-3.22365
68.20001,-11.36677,-3.22654
68.30000,-11.38371,-3.23038
68.40000,-11.40011,-3.23251
68.50000,-11.41677,-3.23420
68.60001,-11.43357,-3.23596
68.70001,-11.45011,-3.23869
68.80000,-11.46691,-3.24216
68.90000,-11.48357,-3.24344
69.00000,-11.50037,-3.24662
69.10001,-11.51677,-3.24967
69.20001,-11.53371,-3.25300
69.30000,-11.55011,-3.25153
69.40000,-11.56664,-3.25628
69.50000,-11.58357,-3.25886
69.60001,-11.60011,-3.26418
69.70001,-11.61691,-3.26701
69.80000,-11.63357,-3.27298
69.90000,-11.65037,-3.27780
70.00000,-11.66677,-3.28135
70.10001,-11.68371,-3.28590
70.20001,-11.70010,-3.28948
70.30000,-11.71664,-3.29455
70.40000,-11.73371,-3.29814
70.50000,-11.75024,-3.29916
70.60001,-11.76704,-3.30303
70.70001,-11.78371,-3.30557
70.80000,-11.80024,-3.30805
70.90000,-11.81690,-3.31118
71.00000,-11.83344,-3.31358
71.10001,-11.85010,-3.31555
71.20001,-11.86677,-3.32026
71.30000,-11.88370,-3.32367
71.40000,-11.90010,-3.32760
71.50000,-11.91717,-3.33122
71.60001,-11.93357,-3.33203
71.70001,-11.95010,-3.33429
71.80000,-11.96677,-3.33682
71.90000,-11.98330,-3.33855
72.00000,-12.00010,-3.34136
72.10001,-12.01690,-3.34554
72.20001,-12.03370,-3.34596
72.30000,-12.05010,-3.34667
72.40000,-12.06704,-3.34965
72.50000,-12.08344,-3.35047
72.60001,-12.09997,-3.35320
72.70001,-12.11690,-3.35488
72.80000,-12.13344,-3.35913
72.90000,-12.15024,-3.36283
73.00000,-12.16704,-3.36696
73.10001,-12.18370,-3.37018
73.20001,-12.20010,-3.37345
73.30000,-12.21690,-3.37675
73.40000,-12.23344,-3.37709
73.50000,-12.25010,-3.38116
73.60001,-12.26704,-3.38443
73.70001,-12.28357,-3.38770
73.80000,-12.30037,-3.39104
73.90000,-12.31704,-3.39341
74.00000,-12.33357,-3.39543
74.10001,-12.35024,-3.39735
74.20001,-12.36690,-3.40129
74.30000,-12.38357,-3.40478
74.40000,-12.40024,-3.40966
74.50000,-12.41717,-3.41314
74.60001,-12.43357,-3.41436
74.70001,-12.45037,-3.41773
74.80000,-12.46677,-3.41852
74.90000,-12.48344,-3.42151
75.00000,-12.50010,-3.42330
75.10001,-12.51677,-3.42531
75.20001,-12.53344,-3.42739
75.30000,-12.55010,-3.43000
75.40000,-12.56690,-3.43048
75.50000,-12.58330,-3.43206
75.60001,-12.60037,-3.43446
75.70001,-12.61677,-3.43453
75.80000,-12.63344,-3.43748
75.90000,-12.65010,-3.43733
76.00000,-12.66677,-3.43928
76.10001,-12.68370,-3.44105
76.20001,-12.70037,-3.44205
76.30000,-12.71690,-3.44076
76.40000,-12.73344,-3.44042
76.50000,-12.75037,-3.43972
76.60001,-12.76677,-3.43653
76.70001,-12.78344,-3.43611
76.80000,-12.80037,-3.43446
76.90000,-12.81690,-3.43404
77.00000,-12.83384,-3.43415
77.10001,-12.85037,-3.43210
77.20001,-12.86704,-3.43073
77.30000,-12.88357,-3.42954
77.40000,-12.90024,-3.42891
77.50000,-12.91677,-3.42537
77.60001,-12.93357,-3.42115
77.70001,-12.95037,-3.42203
77.80000,-12.96690,-3.42285
77.90000,-12.98384,-3.42367
78.00000,-13.00010,-3.42133
78.10001,-13.01677,-3.42127
78.20001,-13.03343,-3.42059
78.30000,-13.04997,-3.42064
78.40000,-13.06677,-3.42128
78.50000,-13.08343,-3.42391
78.60001,-13.10023,-3.42333
78.70001,-13.11677,-3.42579
78.80000,-13.13370,-3.42802
78.90000,-13.15010,-3.42921
79.00000,-13.16663,-3.43118
79.10001,-13.18357,-3.43246
79.20001,-13.20010,-3.43380
79.30000,-13.21703,-3.43634
79.40000,-13.23370,-3.43947
79.50000,-13.25050,-3.44190
79.60001,-13.26677,-3.44521
79.70001,-13.28370,-3.44748
79.80000,-13.30023,-3.44956
79.90000,-13.31677,-3.45312
80.00000,-13.33370,-3.45618
80.10001,-13.35023,-3.45934
80.20001,-13.36703,-3.46232
80.30000,-13.38357,-3.46276
80.40000,-13.40037,-3.46534
80.50001,-13.41690,-3.46775
80.60001,-13.43357,-3.46878
80.70001,-13.45023,-3.46931
80.80000,-13.46677,-3.47110
80.90000,-13.48370,-3.47301
81.00001,-13.50010,-3.47119
81.10001,-13.51717,-3.47221
81.20001,-13.53343,-3.47723
81.30000,-13.55010,-3.48066
81.40000,-13.56677,-3.48424
81.50001,-13.58330,-3.48673
81.60001,-13.60010,-3.49202
81.70001,-13.61690,-3.49742
81.80000,-13.63370,-3.49728
81.90000,-13.65010,-3.50474
82.00001,-13.66703,-3.51091
82.10001,-13.68343,-3.51226
82.20001,-13.69997,-3.51820
82.30000,-13.71690,-3.52373
82.40000,-13.73343,-3.52751
82.50001,-13.75037,-3.53099
82.60001,-13.76703,-3.53622
82.70001,-13.78370,-3.53998
82.80000,-13.80010,-3.54477
82.90000,-13.81690,-3.54861
83.00001,-13.83343,-3.55125
83.10001,-13.84997,-3.55619
83.20001,-13.86703,-3.56051
83.30000,-13.88343,-3.56208
83.40000,-13.90037,-3.56600
83.50001,-13.91690,-3.56572
83.60001,-13.93357,-3.56970
83.70001,-13.95010,-3.57391
83.80000,-13.96690,-3.57796
83.90000,-13.98343,-3.58081
84.00001,-14.00010,-3.58640
84.10001,-14.01703,-3.59099
84.20001,-14.03343,-3.59676
84.30000,-14.05050,-3.60325
84.40000,-14.06690,-3.60816
84.50001,-14.08357,-3.61424
84.60001,-14.10010,-3.61841
84.70001,-14.11677,-3.62231
84.80000,-14.13343,-3.62855
84.90000,-14.15023,-3.63443
85.00001,-14.16703,-3.63881
85.10001,-14.18343,-3.64415
85.20001,-14.20037,-3.64993
85.30000,-14.21663,-3.65373
85.40000,-14.23343,-3.66139
85.50001,-14.25010,-3.66508
85.60001,-14.26676,-3.67187
85.70001,-14.28356,-3.67749
85.80000,-14.30037,-3.68470
85.90000,-14.31703,-3.68916
86.00001,-14.33343,-3.69526
86.10001,-14.35036,-3.70203
86.20001,-14.36676,-3.70644
86.30000,-14.38343,-3.71407
86.40000,-14.40050,-3.71980
86.50001,-14.41690,-3.72541
86.60001,-14.43370,-3.73243
86.70001,-14.45023,-3.73885
86.80000,-14.46690,-3.74570
86.90000,-14.48356,-3.75097
87.00001,-14.50023,-3.75594
87.10001,-14.51690,-3.75991
87.20001,-14.53343,-3.76452
87.30000,-14.55036,-3.76893
87.40000,-14.56676,-3.77284
87.50001,-14.58383,-3.77866
87.60001,-14.60023,-3.78322
87.70001,-14.61676,-3.78826
87.80000,-14.63343,-3.79295
87.90000,-14.64996,-3.79805
88.00001,-14.66690,-3.80452
88.10001,-14.68356,-3.81324
88.20001,-14.70023,-3.81671
88.30000,-14.71663,-3.82385
88.40000,-14.73383,-3.83040
88.50001,-14.75010,-3.83451
88.60001,-14.76663,-3.84197
88.70001,-14.78343,-3.84592
88.80000,-14.80010,-3.85282
88.90000,-14.81690,-3.86031
89.00001,-14.83370,-3.86426
89.10001,-14.85036,-3.86765
89.20001,-14.86676,-3.87563
89.30000,-14.88370,-3.88101
89.40000,-14.90010,-3.88568
89.50001,-14.91676,-3.89375
89.60001,-14.93370,-3.89912
89.70001,-14.95010,-3.90505
89.80000,-14.96716,-3.91270
89.90000,-14.98370,-3.91925
90.00001,-15.00036,-3.92785
90.10001,-15.01690,-3.93606
90.20001,-15.03356,-3.94439
90.30000,-15.05010,-3.95252
90.36201,-15.06063,-3.96060