File: GFBaking/data/2_13PercentGluten/2_13gluten_Compression.is_comp_RawData/Specimen_RawData_1.csv
Time,Extension,Load
(sec),(mm),(N)
0.00000,-0.00027,-0.16152
0.10000,-0.00693,-0.16588
0.20000,-0.02667,-0.19498
0.30000,-0.04627,-0.22448
0.40000,-0.06467,-0.25282
0.50000,-0.08253,-0.27406
0.60000,-0.09933,-0.29431
0.70000,-0.11627,-0.31238
0.80000,-0.13333,-0.33208
0.90000,-0.14987,-0.35079
1.00000,-0.16693,-0.37115
1.10000,-0.18373,-0.38902
1.20000,-0.20040,-0.41054
1.30000,-0.21680,-0.42780
1.40000,-0.23360,-0.44633
1.50000,-0.25013,-0.46421
1.60000,-0.26653,-0.48234
1.70000,-0.28373,-0.50280
1.80000,-0.30013,-0.52154
1.90000,-0.31693,-0.54256
2.00000,-0.33360,-0.56258
2.10000,-0.35027,-0.58352
2.20000,-0.36680,-0.60167
2.30000,-0.38333,-0.62273
2.40000,-0.40013,-0.64471
2.50000,-0.41680,-0.66721
2.60000,-0.43373,-0.68722
2.70000,-0.45027,-0.71001
2.80000,-0.46720,-0.73091
2.90000,-0.48347,-0.75217
3.00000,-0.50000,-0.77286
3.10000,-0.51680,-0.79467
3.20000,-0.53333,-0.81628
3.30000,-0.55013,-0.83827
3.40000,-0.56693,-0.86067
3.50000,-0.58373,-0.88234
3.60000,-0.60000,-0.90360
3.70000,-0.61707,-0.92731
3.80000,-0.63347,-0.94718
3.90000,-0.65013,-0.97034
4.00000,-0.66707,-0.99115
4.10000,-0.68333,-1.01648
4.20000,-0.70026,-1.04107
4.30000,-0.71706,-1.06792
4.40000,-0.73373,-1.09333
4.50000,-0.75000,-1.11791
4.60000,-0.76706,-1.14182
4.70000,-0.78346,-1.16394
4.80000,-0.79986,-1.18965
4.90000,-0.81706,-1.21155
5.00000,-0.83346,-1.23583
5.10000,-0.85040,-1.26337
5.20000,-0.86693,-1.28748
5.30000,-0.88346,-1.31045
5.40000,-0.90013,-1.33746
5.50000,-0.91680,-1.36006
5.60000,-0.93333,-1.37965
5.70000,-0.95013,-1.40455
5.80000,-0.96720,-1.43163
5.90000,-0.98346,-1.45432
6.00000,-1.00040,-1.48076
6.10000,-1.01680,-1.50247
6.20000,-1.03333,-1.52430
6.30000,-1.05026,-1.54907
6.40000,-1.06666,-1.57143
6.50000,-1.08360,-1.59549
6.60000,-1.10013,-1.62143
6.70000,-1.11693,-1.64446
6.80000,-1.13346,-1.66711
6.90000,-1.15040,-1.69197
7.00000,-1.16666,-1.71408
7.10000,-1.18333,-1.73864
7.20000,-1.20040,-1.76112
7.30000,-1.21680,-1.78303
7.40000,-1.23360,-1.80717
7.50000,-1.25040,-1.83153
7.60000,-1.26693,-1.85311
7.70000,-1.28346,-1.87641
7.80000,-1.30040,-1.90091
7.90000,-1.31680,-1.92097
8.00000,-1.33346,-1.94441
8.10000,-1.35053,-1.96755
8.20000,-1.36680,-1.99038
8.30000,-1.38360,-2.01550
8.40000,-1.40040,-2.03489
8.50000,-1.41693,-2.05757
8.60000,-1.43360,-2.08164
8.70000,-1.45013,-2.10311
8.80000,-1.46680,-2.12415
8.90000,-1.48346,-2.14709
9.00000,-1.50040,-2.16961
9.10000,-1.51680,-2.19041
9.20000,-1.53373,-2.21308
9.30000,-1.55000,-2.23310
9.40000,-1.56680,-2.25520
9.50000,-1.58346,-2.27654
9.60000,-1.59986,-2.29588
9.70000,-1.61693,-2.31955
9.80000,-1.63373,-2.34196
9.90000,-1.65040,-2.36094
10.00000,-1.66680,-2.38233
10.10000,-1.68373,-2.40380
10.20000,-1.70013,-2.42321
10.30000,-1.71666,-2.44537
10.40000,-1.73360,-2.46524
10.50000,-1.75000,-2.48561
10.60000,-1.76693,-2.50639
10.70000,-1.78360,-2.52591
10.80000,-1.80040,-2.54723
10.90000,-1.81680,-2.56592
11.00000,-1.83373,-2.58608
11.10000,-1.85013,-2.60514
11.20000,-1.86666,-2.62476
11.30000,-1.88360,-2.64488
11.40000,-1.90013,-2.66460
11.50000,-1.91706,-2.68463
11.60000,-1.93373,-2.70315
11.70000,-1.95026,-2.72188
11.80000,-1.96693,-2.73995
11.90000,-1.98346,-2.75803
12.00000,-2.00013,-2.77633
12.10000,-2.01693,-2.79455
12.20000,-2.03359,-2.81270
12.30000,-2.05013,-2.82995
12.40000,-2.06706,-2.84864
12.50000,-2.08346,-2.86493
12.60000,-2.10013,-2.88357
12.70000,-2.11679,-2.90024
12.80000,-2.13333,-2.91831
12.90000,-2.15026,-2.93516
13.00000,-2.16693,-2.95162
13.10000,-2.18373,-2.96795
13.20000,-2.20026,-2.98429
13.30000,-2.21706,-2.72154
13.40000,-2.23346,-2.59618
13.50000,-2.24999,-2.66310
13.60000,-2.26679,-2.70828
13.70000,-2.28346,-2.75208
13.80000,-2.30053,-2.79166
13.90000,-2.31719,-2.82736
14.00000,-2.33373,-2.85926
14.10000,-2.35013,-2.88860
14.20000,-2.36693,-2.91624
14.30000,-2.38346,-2.94265
14.40000,-2.39999,-2.96831
14.50000,-2.41706,-2.99150
14.60000,-2.43346,-3.01488
14.70000,-2.45026,-3.03597
14.80000,-2.46679,-3.05551
14.90000,-2.48319,-3.07491
15.00000,-2.49999,-3.09427
15.10000,-2.51666,-3.11107
15.20000,-2.53333,-3.12758
15.30000,-2.54999,-3.14604
15.40000,-2.56706,-3.16313
15.50000,-2.58346,-3.17887
15.60000,-2.60053,-3.19530
15.70000,-2.61679,-3.20921
15.80000,-2.63346,-3.22313
15.90000,-2.65026,-3.23831
16.00000,-2.66666,-3.25198
16.10000,-2.68359,-3.26710
16.20000,-2.70026,-3.28244
16.30000,-2.71719,-3.29621
16.40000,-2.73359,-3.30987
16.50000,-2.75039,-3.32288
16.60000,-2.76679,-3.33430
16.70000,-2.78333,-3.34471
16.80000,-2.80026,-3.35622
16.90000,-2.81679,-3.36455
17.00000,-2.83373,-3.37491
17.10000,-2.85039,-3.38647
17.20000,-2.86706,-3.39455
17.30000,-2.88333,-3.40459
17.40000,-2.90026,-3.41554
17.50000,-2.91666,-3.42491
17.60000,-2.93319,-3.43681
17.70000,-2.95039,-3.45031
17.80000,-2.96693,-3.46274
17.90000,-2.98373,-3.47649
18.00000,-3.00039,-3.49052
18.10000,-3.01693,-3.50333
18.20000,-3.03346,-3.51783
18.30000,-3.05026,-3.53103
18.40000,-3.06679,-3.54337
18.50000,-3.08346,-3.55944
18.60000,-3.10039,-3.57273
18.70000,-3.11679,-3.58400
18.80000,-3.13386,-3.59871
18.90000,-3.15013,-3.61040
19.00000,-3.16679,-3.62412
19.10000,-3.18346,-3.63504
19.20000,-3.19999,-3.64770
19.30000,-3.21693,-3.66170
19.40000,-3.23359,-3.67296
19.50000,-3.25039,-3.68638
19.60000,-3.26693,-3.69850
19.70000,-3.28373,-3.70982
19.80000,-3.30013,-3.71984
19.90000,-3.31679,-3.73040
20.00000,-3.33359,-3.74155
20.10000,-3.35013,-3.75403
20.20000,-3.36706,-3.76578
20.30000,-3.38373,-3.77584
20.40000,-3.40026,-3.78655
20.50000,-3.41666,-3.79564
20.60000,-3.43359,-3.80521
20.70000,-3.45012,-3.81532
20.80000,-3.46666,-3.82646
20.90000,-3.48372,-3.83568
21.00000,-3.49999,-3.84535
21.10000,-3.51706,-3.85639
21.20000,-3.53359,-3.86569
21.30000,-3.55026,-3.87542
21.40000,-3.56692,-3.88454
21.50000,-3.58346,-3.89346
21.60000,-3.60012,-3.90196
21.70000,-3.61679,-3.91111
21.80000,-3.63372,-3.91886
21.90000,-3.65012,-3.92762
22.00000,-3.66719,-3.93613
22.10000,-3.68346,-3.94359
22.20000,-3.70012,-3.95204
22.30000,-3.71679,-3.96049
22.40000,-3.73332,-3.96846
22.50000,-3.75026,-3.97781
22.60000,-3.76692,-3.98559
22.70000,-3.78372,-3.99312
22.80000,-3.80012,-4.00177
22.90000,-3.81706,-4.00909
23.00000,-3.83332,-4.01593
23.10000,-3.84999,-4.02535
23.20000,-3.86679,-4.03191
23.30000,-3.88332,-4.03893
23.40000,-3.90026,-4.04640
23.50000,-3.91692,-4.05261
23.60000,-3.93372,-4.05850
23.70000,-3.95012,-4.06529
23.80000,-3.96692,-4.07013
23.90000,-3.98346,-4.07686
24.00000,-4.00012,-4.08370
24.10000,-4.01706,-4.09060
24.20000,-4.03359,-4.09552
24.30000,-4.05052,-4.10241
24.40000,-4.06706,-4.10725
24.50000,-4.08359,-4.11189
24.60000,-4.10026,-4.11824
24.70000,-4.11692,-4.12397
24.80000,-4.13346,-4.13029
24.90000,-4.15026,-4.13637
25.00000,-4.16692,-4.14056
25.10000,-4.18332,-4.14631
25.20000,-4.20039,-4.15352
25.30000,-4.21679,-4.15744
25.40000,-4.23346,-4.16275
25.50000,-4.24999,-4.16698
25.60000,-4.26666,-4.17364
25.70000,-4.28346,-4.17921
25.80000,-4.30039,-4.18357
25.90000,-4.31706,-4.18779
26.00000,-4.33359,-4.19073
26.10000,-4.35039,-4.19421
26.20000,-4.36679,-4.19761
26.30000,-4.38332,-4.20455
26.40000,-4.40012,-4.20854
26.50000,-4.41679,-4.21356
26.60000,-4.43359,-4.21812
26.70000,-4.45026,-4.22213
26.80000,-4.46719,-4.22476
26.90000,-4.48332,-4.22761
27.00000,-4.50026,-4.23331
27.10000,-4.51679,-4.23553
27.20000,-4.53346,-4.24058
27.30000,-4.55039,-4.24385
27.40000,-4.56666,-4.24750
27.50000,-4.58372,-4.25174
27.60000,-4.60026,-4.25484
27.70000,-4.61692,-4.25723
27.80000,-4.63346,-4.25886
27.90000,-4.65012,-4.26304
28.00000,-4.66679,-4.26433
28.10000,-4.68346,-4.26800
28.20000,-4.70026,-4.27089
28.30000,-4.71679,-4.27441
28.40000,-4.73386,-4.27632
28.50000,-4.75026,-4.27881
28.60000,-4.76666,-4.28078
28.70000,-4.78346,-4.28383
28.80000,-4.79999,-4.28648
28.90000,-4.81692,-4.29021
29.00000,-4.83359,-4.29374
29.10000,-4.85039,-4.29521
29.20000,-4.86679,-4.29733
29.30000,-4.88372,-4.30123
29.40000,-4.90012,-4.30368
29.50000,-4.91652,-4.30578
29.60000,-4.93345,-4.30942
29.70000,-4.95025,-4.31335
29.80000,-4.96705,-4.31540
29.90000,-4.98372,-4.31962
30.00000,-5.00039,-4.32289
30.10000,-5.01679,-4.32605
30.20000,-5.03372,-4.32941
30.30000,-5.05012,-4.33089
30.40000,-5.06665,-4.33405
30.50000,-5.08372,-4.33719
30.60000,-5.10012,-4.33977
30.70000,-5.11705,-4.34268
30.80000,-5.13359,-4.34533
30.90000,-5.15025,-4.34694
31.00000,-5.16665,-4.34870
31.10000,-5.18345,-4.35072
31.20000,-5.19999,-4.35080
31.30000,-5.21692,-4.35364
31.40000,-5.23372,-4.35402
31.50000,-5.25012,-4.35424
31.60000,-5.26705,-4.35675
31.70000,-5.28332,-4.35726
31.80000,-5.30012,-4.36005
31.90000,-5.31692,-4.36238
32.00000,-5.33332,-4.36404
32.10000,-5.35012,-4.36608
32.20000,-5.36692,-4.36931
32.30000,-5.38372,-4.37142
32.40000,-5.40025,-4.37409
32.50000,-5.41705,-4.37578
32.60000,-5.43345,-4.37605
32.70000,-5.45012,-4.37865
32.80000,-5.46692,-4.38005
32.90000,-5.48345,-4.38128
33.00000,-5.50039,-4.38324
33.10000,-5.51705,-4.38380
33.20000,-5.53372,-4.38511
33.30000,-5.55025,-4.38467
33.40000,-5.56705,-4.38489
33.50000,-5.58332,-4.38304
33.60000,-5.60012,-4.38607
33.70000,-5.61705,-4.38812
33.80000,-5.63359,-4.38958
33.90000,-5.65039,-4.39080
34.00000,-5.66705,-4.39065
34.10000,-5.68359,-4.39143
34.20000,-5.70025,-4.39235
34.30000,-5.71665,-4.39384
34.40000,-5.73332,-4.39387
34.50000,-5.75012,-4.39734
34.60000,-5.76705,-4.39869
34.70000,-5.78345,-4.39953
34.80000,-5.80039,-4.40320
34.90000,-5.81679,-4.40195
35.00000,-5.83332,-4.40254
35.10000,-5.85012,-4.40232
35.20000,-5.86665,-4.40300
35.30000,-5.88372,-4.40231
35.40000,-5.90039,-4.40515
35.50000,-5.91705,-4.40435
35.60000,-5.93345,-4.40573
35.70000,-5.95039,-4.40653
35.80000,-5.96679,-4.40400
35.90000,-5.98345,-4.40571
36.00000,-6.00025,-4.40862
36.10000,-6.01665,-4.41123
36.20000,-6.03372,-4.41091
36.30000,-6.05052,-4.41189
36.40000,-6.06692,-4.41181
36.50000,-6.08345,-4.41012
36.60000,-6.10025,-4.40821
36.70000,-6.11679,-4.40307
36.80000,-6.13332,-4.40151
36.90000,-6.15038,-4.39992
37.00000,-6.16665,-4.39615
37.10000,-6.18372,-4.39638
37.20000,-6.20025,-4.39490
37.30000,-6.21692,-4.39064
37.40000,-6.23345,-4.38837
37.50000,-6.25012,-4.38691
37.60000,-6.26678,-4.38701
37.70000,-6.28358,-4.38808
37.80000,-6.30038,-4.38621
37.90000,-6.31692,-4.38498
38.00000,-6.33385,-4.38429
38.10000,-6.35012,-4.37976
38.20000,-6.36665,-4.37631
38.30000,-6.38345,-4.37357
38.40000,-6.39998,-4.37188
38.50000,-6.41692,-4.37160
38.60000,-6.43358,-4.37188
38.70000,-6.45038,-4.37100
38.80000,-6.46678,-4.36760
38.90000,-6.48372,-4.36345
39.00000,-6.49998,-4.35976
39.10000,-6.51665,-4.35883
39.20000,-6.53358,-4.35745
39.30000,-6.55012,-4.35745
39.40000,-6.56692,-4.35706
39.50000,-6.58358,-4.35640
39.60000,-6.60025,-4.35766
39.70000,-6.61665,-4.35939
39.80000,-6.63358,-4.35925
39.90000,-6.64998,-4.35750
40.00000,-6.66678,-4.36083
40.10000,-6.68372,-4.36226
40.20000,-6.70025,-4.36174
40.30000,-6.71718,-4.36290
40.40000,-6.73372,-4.36467
40.50000,-6.75025,-4.36436
40.60000,-6.76692,-4.36409
40.70000,-6.78345,-4.36416
40.80000,-6.80012,-4.36653
40.90000,-6.81692,-4.36763
41.00000,-6.83372,-4.36748
41.10000,-6.85012,-4.37113
41.20000,-6.86705,-4.37501
41.30000,-6.88345,-4.37407
41.40000,-6.89998,-4.37611
41.50000,-6.91678,-4.37456
41.60000,-6.93332,-4.37902
41.70000,-6.95025,-4.38173
41.80000,-6.96705,-4.38535
41.90000,-6.98385,-4.38522
42.00000,-7.00012,-4.38918
42.10000,-7.01705,-4.39538
42.20000,-7.03345,-4.39519
42.30000,-7.05012,-4.39665
42.40000,-7.06692,-4.39813
42.50000,-7.08345,-4.40234
42.60000,-7.10038,-4.40423
42.70000,-7.11705,-4.40615
42.80000,-7.13372,-4.40942
42.90000,-7.15012,-4.41020
43.00000,-7.16678,-4.41335
43.10000,-7.18332,-4.41573
43.20000,-7.19998,-4.42026
43.30000,-7.21705,-4.42242
43.40000,-7.23332,-4.42435
43.50000,-7.25038,-4.43127
43.60000,-7.26705,-4.43421
43.70000,-7.28345,-4.43760
43.80000,-7.30025,-4.43947
43.90000,-7.31678,-4.44361
44.00000,-7.33345,-4.44626
44.10000,-7.35012,-4.45025
44.20000,-7.36692,-4.45448
44.30000,-7.38345,-4.45890
44.40000,-7.40038,-4.46309
44.50000,-7.41665,-4.46570
44.60000,-7.43345,-4.46859
44.70000,-7.45025,-4.47187
44.80000,-7.46665,-4.47466
44.90000,-7.48358,-4.47876
45.00000,-7.50025,-4.48442
45.10000,-7.51705,-4.48951
45.20000,-7.53358,-4.49529
45.30000,-7.55038,-4.50025
45.40000,-7.56665,-4.50271
45.50000,-7.58332,-4.50803
45.60000,-7.60025,-4.51366
45.70000,-7.61691,-4.51921
45.80000,-7.63385,-4.52467
45.90000,-7.65038,-4.52926
46.00000,-7.66705,-4.53322
46.10000,-7.68345,-4.53727
46.20000,-7.70025,-4.54229
46.30000,-7.71678,-4.54567
46.40000,-7.73331,-4.55016
46.50000,-7.75038,-4.55490
46.60000,-7.76678,-4.55965
46.70000,-7.78371,-4.56517
46.80000,-7.80038,-4.56962
46.90000,-7.81691,-4.57435
47.00000,-7.83358,-4.57785
47.10000,-7.85025,-4.58252
47.20000,-7.86691,-4.58642
47.30000,-7.88358,-4.59215
47.40000,-7.90051,-4.59926
47.50000,-7.91678,-4.60290
47.60000,-7.93385,-4.60891
47.70000,-7.95011,-4.61317
47.80000,-7.96691,-4.61807
47.90000,-7.98345,-4.62388
48.00000,-8.00011,-4.62999
48.10000,-8.01691,-4.63634
48.20000,-8.03345,-4.64248
48.30000,-8.05038,-4.64815
48.40000,-8.06678,-4.65512
48.50000,-8.08371,-4.66286
48.60000,-8.10011,-4.66830
48.70000,-8.11678,-4.67588
48.80000,-8.13358,-4.68197
48.90000,-8.15011,-4.68867
49.00000,-8.16678,-4.69661
49.10000,-8.18331,-4.70393
49.20000,-8.20025,-4.71137
49.30000,-8.21651,-4.71704
49.40000,-8.23345,-4.72421
49.50000,-8.25011,-4.72925
49.60000,-8.26665,-4.73726
49.70000,-8.28371,-4.74328
49.80000,-8.30025,-4.75081
49.90000,-8.31718,-4.75803
50.00000,-8.33371,-4.76406
50.10000,-8.35025,-4.77070
50.20000,-8.36691,-4.77667
50.30000,-8.38345,-4.78293
50.40000,-8.40025,-4.78916
50.50000,-8.41691,-4.79703
50.60000,-8.43371,-4.80198
50.70000,-8.45011,-4.81010
50.80000,-8.46705,-4.81668
50.90000,-8.48331,-4.82113
51.00000,-8.50011,-4.82944
51.10000,-8.51678,-4.83509
51.20000,-8.53331,-4.84024
51.30000,-8.55025,-4.84723
51.40000,-8.56691,-4.85310
51.50000,-8.58358,-4.85796
51.60000,-8.60011,-4.86452
51.70000,-8.61705,-4.87098
51.80000,-8.63345,-4.87447
51.90000,-8.65011,-4.87929
52.00000,-8.66691,-4.88481
52.10000,-8.68345,-4.89231
52.20000,-8.70025,-4.89900
52.30000,-8.71705,-4.90690
52.40000,-8.73371,-4.91317
52.50000,-8.75011,-4.91856
52.60000,-8.76691,-4.92548
52.70000,-8.78345,-4.93130
52.80000,-8.80011,-4.93800
52.90000,-8.81705,-4.94553
53.00000,-8.83345,-4.95169
53.10000,-8.85038,-4.95854
53.20000,-8.86691,-4.96433
53.30000,-8.88345,-4.97011
53.40000,-8.89998,-4.97727
53.50000,-8.91678,-4.98354
53.60000,-8.93358,-4.98980
53.70000,-8.95011,-4.99604
53.80000,-8.96718,-4.99968
53.90000,-8.98345,-5.00552
54.00000,-9.00051,-5.01273
54.10000,-9.01678,-5.01462
54.20000,-9.03344,-5.01995
54.30000,-9.05011,-5.02495
54.40000,-9.06678,-5.02981
54.50000,-9.08358,-5.03492
54.60000,-9.10024,-5.04063
54.70000,-9.11704,-5.04467
54.80000,-9.13358,-5.05102
54.90000,-9.15038,-5.05522
55.00000,-9.16678,-5.05747
55.10000,-9.18331,-5.06222
55.20000,-9.20011,-5.06578
55.30000,-9.21664,-5.07277
55.40000,-9.23371,-5.07912
55.50000,-9.25038,-5.08455
55.60000,-9.26704,-5.09005
55.70000,-9.28344,-5.09483
55.80000,-9.30024,-5.10072
55.90000,-9.31678,-5.10363
56.00000,-9.33331,-5.10834
56.10000,-9.35038,-5.11428
56.20000,-9.36678,-5.12084
56.30000,-9.38358,-5.12776
56.40000,-9.40024,-5.13120
56.50000,-9.41691,-5.13623
56.60000,-9.43344,-5.14091
56.70000,-9.45024,-5.14466
56.80000,-9.46678,-5.14850
56.90000,-9.48344,-5.15481
57.00000,-9.50038,-5.15890
57.10000,-9.51678,-5.16398
57.20000,-9.53371,-5.16924
57.30000,-9.54998,-5.17017
57.40000,-9.56678,-5.17638
57.50000,-9.58344,-5.18110
57.60000,-9.60011,-5.18518
57.70000,-9.61691,-5.18884
57.80000,-9.63358,-5.19564
57.90000,-9.65038,-5.19829
58.00000,-9.66691,-5.20281
58.10000,-9.68384,-5.20702
58.20000,-9.69998,-5.20887
58.30000,-9.71691,-5.21416
58.40000,-9.73358,-5.21666
58.50000,-9.75024,-5.22226
58.60000,-9.76718,-5.22700
58.70000,-9.78371,-5.23084
58.80000,-9.80038,-5.23523
58.90000,-9.81678,-5.23804
59.00000,-9.83371,-5.24304
59.10000,-9.85011,-5.24529
59.20000,-9.86664,-5.25183
59.30000,-9.88371,-5.25871
59.40000,-9.90011,-5.26412
59.50000,-9.91704,-5.26989
59.60000,-9.93358,-5.27242
59.70000,-9.95024,-5.27695
59.80000,-9.96678,-5.28091
59.90000,-9.98344,-5.28728
60.00000,-10.00011,-5.29054
60.10000,-10.01691,-5.29591
60.20000,-10.03358,-5.29818
60.30000,-10.05024,-5.30228
60.40000,-10.06718,-5.30712
60.50000,-10.08331,-5.31067
60.60000,-10.10011,-5.31567
60.70000,-10.11678,-5.32023
60.80000,-10.13344,-5.32417
60.90000,-10.15024,-5.32849
61.00000,-10.16691,-5.33279
61.10000,-10.18371,-5.33481
61.20000,-10.20011,-5.33861
61.30000,-10.21704,-5.34315
61.40000,-10.23344,-5.34479
61.50000,-10.25024,-5.35075
61.60000,-10.26704,-5.35267
61.70000,-10.28344,-5.35551
61.80000,-10.30037,-5.35943
61.90000,-10.31691,-5.36223
62.00000,-10.33371,-5.36569
62.10000,-10.34997,-5.36780
62.20000,-10.36691,-5.37258
62.30000,-10.38344,-5.37417
62.40000,-10.39997,-5.37939
62.50000,-10.41704,-5.38339
62.60000,-10.43344,-5.38704
62.70000,-10.45037,-5.39179
62.80000,-10.46691,-5.39493
62.90000,-10.48357,-5.39848
63.00000,-10.50011,-5.40078
63.10000,-10.51677,-5.40501
63.20000,-10.53344,-5.40775
63.30000,-10.55011,-5.41327
63.40000,-10.56704,-5.41705
63.50000,-10.58357,-5.42339
63.60000,-10.60037,-5.42849
63.70000,-10.61677,-5.43200
63.80000,-10.63331,-5.43716
63.90000,-10.64997,-5.44314
64.00000,-10.66664,-5.44908
64.10001,-10.68357,-5.45511
64.20000,-10.70024,-5.46092
64.30000,-10.71717,-5.46647
64.40000,-10.73344,-5.47197
64.50000,-10.75024,-5.47623
64.60001,-10.76677,-5.48060
64.70000,-10.78331,-5.48588
64.80000,-10.80011,-5.49041
64.90000,-10.81664,-5.49637
65.00000,-10.83357,-5.50379
65.10001,-10.85011,-5.50973
65.20000,-10.86691,-5.51500
65.30000,-10.88331,-5.52209
65.40000,-10.90024,-5.52941
65.50000,-10.91691,-5.53466
65.60001,-10.93344,-5.54084
65.70001,-10.95024,-5.54629
65.80000,-10.96664,-5.55430
65.90000,-10.98384,-5.56301
66.00000,-11.00037,-5.57002
66.10001,-11.01704,-5.57647
66.20001,-11.03344,-5.58352
66.30000,-11.05024,-5.58832
66.40000,-11.06677,-5.59294
66.50000,-11.08357,-5.60091
66.60001,-11.10037,-5.60886
66.70001,-11.11691,-5.61639
66.80000,-11.13384,-5.62364
66.90000,-11.15011,-5.62839
67.00000,-11.16677,-5.63414
67.10001,-11.18344,-5.64343
67.20001,-11.19997,-5.65176
67.30000,-11.21691,-5.65896
67.40000,-11.23357,-5.66736
67.50000,-11.25051,-5.67429
67.60001,-11.26691,-5.67976
67.70001,-11.28384,-5.68544
67.80000,-11.30024,-5.68665
67.90000,-11.31664,-5.69368
68.00000,-11.33357,-5.70221
68.10001,-11.35011,-5.71098
68.20001,-11.36704,-5.71552
68.30000,-11.38357,-5.71886
68.40000,-11.40024,-5.72594
68.50000,-11.41664,-5.73427
68.60001,-11.43357,-5.74195
68.70001,-11.45011,-5.74360
68.80000,-11.46664,-5.74730
68.90000,-11.48371,-5.75343
69.00000,-11.50011,-5.76179
69.10001,-11.51704,-5.76779
69.20001,-11.53357,-5.77237
69.30000,-11.55011,-5.77394
69.40000,-11.56677,-5.78019
69.50000,-11.58357,-5.78884
69.60001,-11.60024,-5.79419
69.70001,-11.61677,-5.80449
69.80000,-11.63371,-5.81196
69.90000,-11.65024,-5.81698
70.00000,-11.66717,-5.81839
70.10001,-11.68357,-5.81703
70.20001,-11.69997,-5.82107
70.30000,-11.71677,-5.82507
70.40000,-11.73344,-5.83252
70.50000,-11.75024,-5.83444
70.60001,-11.76690,-5.83850
70.70001,-11.78371,-5.84360
70.80000,-11.79997,-5.84721
70.90000,-11.81704,-5.85586
71.00000,-11.83357,-5.86393
71.10001,-11.84997,-5.87076
71.20001,-11.86690,-5.87195
71.30000,-11.88344,-5.87799
71.40000,-11.90037,-5.88540
71.50000,-11.91704,-5.89343
71.60001,-11.93370,-5.89579
71.70001,-11.95010,-5.89780
71.80000,-11.96690,-5.90475
71.90000,-11.98344,-5.90905
72.00000,-12.00010,-5.91505
72.10001,-12.01704,-5.91851
72.20001,-12.03344,-5.92444
72.30000,-12.05037,-5.92979
72.40000,-12.06704,-5.93402
72.50000,-12.08357,-5.93940
72.60001,-12.10024,-5.94308
72.70001,-12.11690,-5.94784
72.80000,-12.13344,-5.95200
72.90000,-12.15010,-5.95866
73.00000,-12.16704,-5.96497
73.10001,-12.18344,-5.97095
73.20001,-12.20037,-5.97751
73.30000,-12.21677,-5.98131
73.40000,-12.23344,-5.98923
73.50000,-12.25010,-5.99564
73.60001,-12.26677,-6.00334
73.70001,-12.28357,-6.01123
73.80000,-12.30024,-6.01969
73.90000,-12.31704,-6.02638
74.00000,-12.33357,-6.03433
74.10001,-12.35037,-6.04265
74.20001,-12.36677,-6.04837
74.30000,-12.38330,-6.05632
74.40000,-12.40024,-6.06447
74.50000,-12.41677,-6.07305
74.60001,-12.43370,-6.08254
74.70001,-12.45037,-6.09043
74.80000,-12.46704,-6.09866
74.90000,-12.48344,-6.10679
75.00000,-12.50037,-6.11462
75.10001,-12.51677,-6.11963
75.20001,-12.53330,-6.12769
75.30000,-12.55037,-6.13866
75.40000,-12.56677,-6.14809
75.50000,-12.58370,-6.15718
75.60001,-12.60024,-6.16551
75.70001,-12.61690,-6.17372
75.80000,-12.63357,-6.18171
75.90000,-12.65010,-6.18916
76.00000,-12.66677,-6.19679
76.10001,-12.68344,-6.20741
76.20001,-12.70037,-6.21540
76.30000,-12.71677,-6.22266
76.40000,-12.73370,-6.23074
76.50000,-12.75024,-6.23526
76.60001,-12.76677,-6.24274
76.70001,-12.78344,-6.25032
76.80000,-12.79997,-6.25984
76.90000,-12.81677,-6.26844
77.00000,-12.83357,-6.28037
77.10001,-12.85024,-6.28645
77.20001,-12.86663,-6.29352
77.30000,-12.88357,-6.30185
77.40000,-12.90010,-6.30762
77.50000,-12.91677,-6.31670
77.60001,-12.93357,-6.32098
77.70001,-12.95010,-6.32840
77.80000,-12.96690,-6.33483
77.90000,-12.98370,-6.34249
78.00000,-13.00037,-6.34913
78.10001,-13.01677,-6.35691
78.20001,-13.03357,-6.36227
78.30000,-13.05010,-6.36346
78.40000,-13.06677,-6.37161
78.50000,-13.08370,-6.37735
78.60001,-13.10023,-6.38435
78.70001,-13.11703,-6.39219
78.80000,-13.13370,-6.39696
78.90000,-13.15023,-6.40044
79.00000,-13.16690,-6.40409
79.10001,-13.18357,-6.41078
79.20001,-13.20023,-6.41556
79.30000,-13.21677,-6.42437
79.40000,-13.23370,-6.43173
79.50000,-13.25010,-6.43656
79.60001,-13.26703,-6.44273
79.70001,-13.28343,-6.44689
79.80000,-13.30010,-6.45378
79.90000,-13.31677,-6.45940
80.00000,-13.33330,-6.46435
80.10001,-13.35023,-6.47040
80.20001,-13.36677,-6.47749
80.30000,-13.38370,-6.48296
80.40000,-13.40023,-6.48908
80.50001,-13.41703,-6.49499
80.60001,-13.43357,-6.49762
80.70001,-13.45010,-6.50382
80.80000,-13.46690,-6.50664
80.90000,-13.48330,-6.51399
81.00001,-13.50037,-6.51894
81.10001,-13.51703,-6.52184
81.20001,-13.53357,-6.52405
81.30000,-13.55010,-6.52802
81.40000,-13.56703,-6.53448
81.50001,-13.58343,-6.53552
81.60001,-13.60010,-6.53909
81.70001,-13.61717,-6.54338
81.80000,-13.63357,-6.54608
81.90000,-13.65050,-6.55273
82.00001,-13.66703,-6.55723
82.10001,-13.68370,-6.56103
82.20001,-13.70023,-6.56427
82.30000,-13.71677,-6.56897
82.40000,-13.73357,-6.57365
82.50001,-13.75023,-6.58244
82.60001,-13.76717,-6.58758
82.70001,-13.78357,-6.59370
82.80000,-13.80023,-6.60060
82.90000,-13.81663,-6.60596
83.00001,-13.83330,-6.61413
83.10001,-13.84997,-6.62140
83.20001,-13.86650,-6.63059
83.30000,-13.88343,-6.64053
83.40000,-13.90010,-6.65117
83.50001,-13.91703,-6.65922
83.60001,-13.93343,-6.66779
83.70001,-13.95023,-6.67610
83.80000,-13.96663,-6.68189
83.90000,-13.98330,-6.69101
84.00001,-14.00023,-6.69768
84.10001,-14.01690,-6.70652
84.20001,-14.03370,-6.71480
84.30000,-14.05037,-6.72567
84.40000,-14.06703,-6.73361
84.50001,-14.08357,-6.74125
84.60001,-14.10037,-6.75024
84.70001,-14.11690,-6.75675
84.80000,-14.13343,-6.76489
84.90000,-14.15023,-6.77095
85.00001,-14.16690,-6.78092
85.10001,-14.18370,-6.79179
85.20001,-14.20023,-6.79723
85.30000,-14.21676,-6.80471
85.40000,-14.23356,-6.81208
85.50001,-14.25010,-6.81711
85.60001,-14.26676,-6.82320
85.70001,-14.28343,-6.83399
85.80000,-14.30037,-6.84214
85.90000,-14.31676,-6.84764
86.00001,-14.33370,-6.85554
86.10001,-14.35010,-6.86132
86.20001,-14.36676,-6.86693
86.30000,-14.38343,-6.87218
86.40000,-14.40010,-6.87860
86.50001,-14.41690,-6.88422
86.60001,-14.43356,-6.88883
86.70001,-14.45036,-6.89699
86.80000,-14.46676,-6.90511
86.90000,-14.48370,-6.91313
87.00001,-14.50010,-6.91878
87.10001,-14.51676,-6.92659
87.20001,-14.53356,-6.93209
87.30000,-14.55010,-6.93875
87.40000,-14.56703,-6.94908
87.50001,-14.58356,-6.95481
87.60001,-14.60036,-6.96086
87.70001,-14.61676,-6.96993
87.80000,-14.63343,-6.98044
87.90000,-14.64996,-6.98123
88.00001,-14.66663,-6.98850
88.10001,-14.68370,-6.99921
88.20001,-14.70010,-7.01288
88.30000,-14.71703,-7.01824
88.40000,-14.73370,-7.02178
88.50001,-14.75023,-7.02748
88.60001,-14.76690,-7.03320
88.70001,-14.78356,-7.03992
88.80000,-14.80010,-7.04363
88.90000,-14.81676,-7.05011
89.00001,-14.83370,-7.05682
89.10001,-14.85010,-7.06286
89.20001,-14.86690,-7.06924
89.30000,-14.88330,-7.07397
89.40000,-14.90010,-7.07606
89.50001,-14.91676,-7.07688
89.60001,-14.93343,-7.08156
89.70001,-14.95010,-7.08697
89.80000,-14.96690,-7.09304
89.90000,-14.98370,-7.09773
90.00001,-15.00010,-7.10343
90.10001,-15.01703,-7.10958
90.18201,-15.03036,-7.11102