File: GFBaking/data/2_13PercentGluten/2_13gluten_Compression.is_comp_RawData/Specimen_RawData_3.csv
Time,Extension,Load
(sec),(mm),(N)
0.00000,-0.00013,-0.12943
0.10000,-0.00467,-0.13030
0.20000,-0.02427,-0.15866
0.30000,-0.04480,-0.18948
0.40000,-0.06373,-0.21675
0.50000,-0.08200,-0.23502
0.60000,-0.09933,-0.25278
0.70000,-0.11640,-0.27215
0.80000,-0.13347,-0.29193
0.90000,-0.15000,-0.30780
1.00000,-0.16680,-0.32139
1.10000,-0.18333,-0.33849
1.20000,-0.20027,-0.35210
1.30000,-0.21680,-0.37023
1.40000,-0.23373,-0.39006
1.50000,-0.25027,-0.40591
1.60000,-0.26693,-0.42203
1.70000,-0.28373,-0.43639
1.80000,-0.30013,-0.45470
1.90000,-0.31680,-0.47169
2.00000,-0.33333,-0.48832
2.10000,-0.35027,-0.50419
2.20000,-0.36680,-0.51984
2.30000,-0.38373,-0.54027
2.40000,-0.40040,-0.56074
2.50000,-0.41667,-0.58053
2.60000,-0.43360,-0.60029
2.70000,-0.45000,-0.61896
2.80000,-0.46680,-0.63998
2.90000,-0.48360,-0.66189
3.00000,-0.50027,-0.68275
3.10000,-0.51693,-0.70489
3.20000,-0.53373,-0.72692
3.30000,-0.55040,-0.74685
3.40000,-0.56667,-0.76881
3.50000,-0.58347,-0.79042
3.60000,-0.60013,-0.81188
3.70000,-0.61707,-0.83297
3.80000,-0.63373,-0.85585
3.90000,-0.65027,-0.87726
4.00000,-0.66707,-0.89902
4.10000,-0.68360,-0.91981
4.20000,-0.70026,-0.93951
4.30000,-0.71680,-0.96004
4.40000,-0.73360,-0.98104
4.50000,-0.75013,-1.00291
4.60000,-0.76693,-1.02425
4.70000,-0.78360,-1.04421
4.80000,-0.80026,-1.06484
4.90000,-0.81706,-1.08734
5.00000,-0.83333,-1.10832
5.10000,-0.85013,-1.12828
5.20000,-0.86680,-1.15214
5.30000,-0.88360,-1.17649
5.40000,-0.90013,-1.20049
5.50000,-0.91693,-1.22587
5.60000,-0.93360,-1.24641
5.70000,-0.95000,-1.26965
5.80000,-0.96693,-1.29360
5.90000,-0.98320,-1.31484
6.00000,-1.00013,-1.33730
6.10000,-1.01693,-1.35935
6.20000,-1.03360,-1.38413
6.30000,-1.05026,-1.40736
6.40000,-1.06706,-1.42773
6.50000,-1.08360,-1.44973
6.60000,-1.10000,-1.47332
6.70000,-1.11693,-1.49354
6.80000,-1.13333,-1.51541
6.90000,-1.15026,-1.53712
7.00000,-1.16706,-1.56146
7.10000,-1.18360,-1.58091
7.20000,-1.20040,-1.60281
7.30000,-1.21693,-1.62374
7.40000,-1.23360,-1.64528
7.50000,-1.25013,-1.66638
7.60000,-1.26693,-1.68789
7.70000,-1.28360,-1.70900
7.80000,-1.30040,-1.72992
7.90000,-1.31693,-1.74884
8.00000,-1.33360,-1.77079
8.10000,-1.35040,-1.79362
8.20000,-1.36680,-1.81450
8.30000,-1.38333,-1.83296
8.40000,-1.40000,-1.85414
8.50000,-1.41680,-1.87497
8.60000,-1.43346,-1.89454
8.70000,-1.45040,-1.91380
8.80000,-1.46706,-1.93127
8.90000,-1.48346,-1.94869
9.00000,-1.50026,-1.96569
9.10000,-1.51653,-1.98275
9.20000,-1.53360,-1.99988
9.30000,-1.55026,-2.01743
9.40000,-1.56706,-2.03494
9.50000,-1.58373,-2.05441
9.60000,-1.60040,-2.07410
9.70000,-1.61706,-2.09370
9.80000,-1.63333,-2.10998
9.90000,-1.65013,-2.12731
10.00000,-1.66653,-2.14310
10.10000,-1.68360,-2.16329
10.20000,-1.70040,-2.17890
10.30000,-1.71680,-2.19657
10.40000,-1.73373,-2.21492
10.50000,-1.75026,-2.23328
10.60000,-1.76693,-2.24972
10.70000,-1.78346,-2.26378
10.80000,-1.80026,-2.28262
10.90000,-1.81680,-2.30137
11.00000,-1.83373,-2.31710
11.10000,-1.85040,-2.32904
11.20000,-1.86693,-2.32760
11.30000,-1.88373,-2.34947
11.40000,-1.90000,-2.36635
11.50000,-1.91666,-2.38857
11.60000,-1.93333,-2.40636
11.70000,-1.95026,-2.42404
11.80000,-1.96693,-2.44094
11.90000,-1.98360,-2.45991
12.00000,-2.00040,-2.45093
12.10000,-2.01680,-2.40130
12.20000,-2.03346,-2.41220
12.30000,-2.04986,-2.42193
12.40000,-2.06680,-2.44325
12.50000,-2.08359,-2.46139
12.60000,-2.10013,-2.47899
12.70000,-2.11693,-2.46826
12.80000,-2.13373,-2.49620
12.90000,-2.15026,-2.51408
13.00000,-2.16666,-2.53041
13.10000,-2.18359,-2.55342
13.20000,-2.20013,-2.56541
13.30000,-2.21693,-2.58879
13.40000,-2.23373,-2.60998
13.50000,-2.25026,-2.62984
13.60000,-2.26706,-2.65011
13.70000,-2.28346,-2.67003
13.80000,-2.30026,-2.69141
13.90000,-2.31666,-2.70993
14.00000,-2.33346,-2.73075
14.10000,-2.35013,-2.75068
14.20000,-2.36706,-2.77305
14.30000,-2.38373,-2.79204
14.40000,-2.40013,-2.81318
14.50000,-2.41693,-2.83173
14.60000,-2.43333,-2.85089
14.70000,-2.45013,-2.86809
14.80000,-2.46679,-2.88885
14.90000,-2.48373,-2.90740
15.00000,-2.50013,-2.92428
15.10000,-2.51693,-2.94359
15.20000,-2.53359,-2.95865
15.30000,-2.54999,-2.97553
15.40000,-2.56693,-2.99213
15.50000,-2.58333,-3.00944
15.60000,-2.60013,-3.02707
15.70000,-2.61693,-3.04469
15.80000,-2.63359,-3.06090
15.90000,-2.65026,-3.07695
16.00000,-2.66706,-3.09355
16.10000,-2.68373,-3.10913
16.20000,-2.70013,-3.12601
16.30000,-2.71693,-3.14198
16.40000,-2.73333,-3.15694
16.50000,-2.75026,-3.17309
16.60000,-2.76693,-3.18685
16.70000,-2.78359,-3.20174
16.80000,-2.80039,-3.21651
16.90000,-2.81693,-3.23151
17.00000,-2.83346,-3.24658
17.10000,-2.84999,-3.26205
17.20000,-2.86693,-3.27739
17.30000,-2.88346,-3.29252
17.40000,-2.90039,-3.30821
17.50000,-2.91706,-3.32202
17.60000,-2.93333,-3.33647
17.70000,-2.95039,-3.35123
17.80000,-2.96666,-3.36581
17.90000,-2.98319,-3.38052
18.00000,-3.00013,-3.39545
18.10000,-3.01706,-3.40926
18.20000,-3.03359,-3.42425
18.30000,-3.05039,-3.43764
18.40000,-3.06706,-3.45040
18.50000,-3.08333,-3.46493
18.60000,-3.10026,-3.47935
18.70000,-3.11666,-3.49268
18.80000,-3.13346,-3.50595
18.90000,-3.15026,-3.51968
19.00000,-3.16693,-3.53273
19.10000,-3.18359,-3.54631
19.20000,-3.20039,-3.55999
19.30000,-3.21706,-3.57378
19.40000,-3.23346,-3.58629
19.50000,-3.25026,-3.59693
19.60000,-3.26666,-3.60860
19.70000,-3.28359,-3.62057
19.80000,-3.30039,-3.63126
19.90000,-3.31693,-3.64227
20.00000,-3.33386,-3.65591
20.10000,-3.35026,-3.66662
20.20000,-3.36693,-3.67769
20.30000,-3.38333,-3.68840
20.40000,-3.40026,-3.69975
20.50000,-3.41679,-3.71031
20.60000,-3.43359,-3.72216
20.70000,-3.45039,-3.73279
20.80000,-3.46679,-3.74367
20.90000,-3.48372,-3.75277
21.00000,-3.50012,-3.76204
21.10000,-3.51679,-3.77210
21.20000,-3.53346,-3.77993
21.30000,-3.55026,-3.78966
21.40000,-3.56679,-3.79823
21.50000,-3.58372,-3.80663
21.60000,-3.60026,-3.81355
21.70000,-3.61679,-3.82070
21.80000,-3.63359,-3.82964
21.90000,-3.64986,-3.83729
22.00000,-3.66692,-3.84775
22.10000,-3.68372,-3.85779
22.20000,-3.70039,-3.86799
22.30000,-3.71692,-3.87558
22.40000,-3.73359,-3.88424
22.50000,-3.75039,-3.89723
22.60000,-3.76666,-3.90566
22.70000,-3.78359,-3.91622
22.80000,-3.79999,-3.92652
22.90000,-3.81692,-3.93637
23.00000,-3.83372,-3.94481
23.10000,-3.85026,-3.95240
23.20000,-3.86692,-3.96324
23.30000,-3.88332,-3.97138
23.40000,-3.90012,-3.98122
23.50000,-3.91652,-3.99087
23.60000,-3.93359,-4.00017
23.70000,-3.95012,-4.00759
23.80000,-3.96706,-4.01773
23.90000,-3.98372,-4.02618
24.00000,-4.00012,-4.03467
24.10000,-4.01719,-4.04485
24.20000,-4.03332,-4.05209
24.30000,-4.05012,-4.05741
24.40000,-4.06679,-4.06558
24.50000,-4.08372,-4.07221
24.60000,-4.10026,-4.08070
24.70000,-4.11706,-4.08929
24.80000,-4.13372,-4.09671
24.90000,-4.15012,-4.10368
25.00000,-4.16692,-4.11139
25.10000,-4.18319,-4.11732
25.20000,-4.20012,-4.12420
25.30000,-4.21679,-4.12973
25.40000,-4.23359,-4.13532
25.50000,-4.25039,-4.14472
25.60000,-4.26706,-4.15016
25.70000,-4.28372,-4.15690
25.80000,-4.29999,-4.16461
25.90000,-4.31679,-4.17029
26.00000,-4.33332,-4.17675
26.10000,-4.35039,-4.18160
26.20000,-4.36719,-4.18696
26.30000,-4.38359,-4.19378
26.40000,-4.40039,-4.20092
26.50000,-4.41679,-4.20689
26.60000,-4.43359,-4.21263
26.70000,-4.45012,-4.21703
26.80000,-4.46692,-4.22162
26.90000,-4.48346,-4.22779
27.00000,-4.50039,-4.23550
27.10000,-4.51706,-4.24097
27.20000,-4.53346,-4.24589
27.30000,-4.55026,-4.25143
27.40000,-4.56666,-4.25671
27.50000,-4.58346,-4.26384
27.60000,-4.60012,-4.27008
27.70000,-4.61706,-4.27672
27.80000,-4.63346,-4.28247
27.90000,-4.65039,-4.28977
28.00000,-4.66706,-4.29481
28.10000,-4.68332,-4.30088
28.20000,-4.70039,-4.30699
28.30000,-4.71666,-4.31172
28.40000,-4.73359,-4.31826
28.50000,-4.75026,-4.32356
28.60000,-4.76692,-4.32945
28.70000,-4.78359,-4.33534
28.80000,-4.80039,-4.33971
28.90000,-4.81692,-4.34313
29.00000,-4.83332,-4.34890
29.10000,-4.85025,-4.35347
29.20000,-4.86679,-4.35827
29.30000,-4.88359,-4.36487
29.40000,-4.90039,-4.36965
29.50000,-4.91679,-4.37513
29.60000,-4.93359,-4.38021
29.70000,-4.95012,-4.38423
29.80000,-4.96679,-4.39022
29.90000,-4.98319,-4.39532
30.00000,-5.00025,-4.40131
30.10000,-5.01692,-4.40638
30.20000,-5.03385,-4.41240
30.30000,-5.05039,-4.41583
30.40000,-5.06692,-4.42044
30.50000,-5.08372,-4.42482
30.60000,-5.10012,-4.43137
30.70000,-5.11679,-4.43344
30.80000,-5.13345,-4.44036
30.90000,-5.15025,-4.44590
31.00000,-5.16679,-4.45131
31.10000,-5.18372,-4.45512
31.20000,-5.20025,-4.45898
31.30000,-5.21665,-4.46752
31.40000,-5.23359,-4.47253
31.50000,-5.24985,-4.47740
31.60000,-5.26679,-4.48020
31.70000,-5.28359,-4.48462
31.80000,-5.30025,-4.49200
31.90000,-5.31692,-4.49533
32.00000,-5.33372,-4.49872
32.10000,-5.35025,-4.50327
32.20000,-5.36665,-4.50589
32.30000,-5.38359,-4.50687
32.40000,-5.39999,-4.51102
32.50000,-5.41705,-4.51797
32.60000,-5.43385,-4.51632
32.70000,-5.45025,-4.51725
32.80000,-5.46705,-4.52047
32.90000,-5.48359,-4.52517
33.00000,-5.50025,-4.52561
33.10000,-5.51679,-4.52789
33.20000,-5.53372,-4.52993
33.30000,-5.55012,-4.53223
33.40000,-5.56705,-4.53223
33.50000,-5.58359,-4.53418
33.60000,-5.60012,-4.54046
33.70000,-5.61692,-4.54060
33.80000,-5.63332,-4.54055
33.90000,-5.64985,-4.54557
34.00000,-5.66692,-4.55099
34.10000,-5.68359,-4.55069
34.20000,-5.70012,-4.54984
34.30000,-5.71705,-4.55253
34.40000,-5.73359,-4.55195
34.50000,-5.75012,-4.56006
34.60000,-5.76692,-4.56251
34.70000,-5.78319,-4.56993
34.80000,-5.80012,-4.57313
34.90000,-5.81692,-4.57746
35.00000,-5.83359,-4.58045
35.10000,-5.85039,-4.57801
35.20000,-5.86705,-4.57774
35.30000,-5.88359,-4.58205
35.40000,-5.89999,-4.58898
35.50000,-5.91692,-4.59288
35.60000,-5.93345,-4.59756
35.70000,-5.95025,-4.60325
35.80000,-5.96705,-4.60385
35.90000,-5.98345,-4.60652
36.00000,-6.00039,-4.61026
36.10000,-6.01692,-4.61312
36.20000,-6.03359,-4.60787
36.30000,-6.05012,-4.61022
36.40000,-6.06692,-4.61166
36.50000,-6.08345,-4.61170
36.60000,-6.10038,-4.61410
36.70000,-6.11692,-4.61550
36.80000,-6.13345,-4.61752
36.90000,-6.15025,-4.62081
37.00000,-6.16665,-4.62561
37.10000,-6.18345,-4.63103
37.20000,-6.20012,-4.62885
37.30000,-6.21692,-4.62578
37.40000,-6.23358,-4.62851
37.50000,-6.25025,-4.63285
37.60000,-6.26692,-4.63613
37.70000,-6.28345,-4.64302
37.80000,-6.30025,-4.64797
37.90000,-6.31652,-4.65108
38.00000,-6.33358,-4.65622
38.10000,-6.35038,-4.65780
38.20000,-6.36692,-4.66208
38.30000,-6.38372,-4.66689
38.40000,-6.40025,-4.67284
38.50000,-6.41705,-4.68074
38.60000,-6.43332,-4.68740
38.70000,-6.45025,-4.69149
38.80000,-6.46665,-4.69573
38.90000,-6.48358,-4.69989
39.00000,-6.50038,-4.70139
39.10000,-6.51692,-4.70711
39.20000,-6.53372,-4.71163
39.30000,-6.55012,-4.71711
39.40000,-6.56678,-4.72089
39.50000,-6.58332,-4.72676
39.60000,-6.60025,-4.72915
39.70000,-6.61678,-4.73221
39.80000,-6.63358,-4.73958
39.90000,-6.65025,-4.74474
40.00000,-6.66692,-4.75100
40.10000,-6.68372,-4.75369
40.20000,-6.70012,-4.75774
40.30000,-6.71665,-4.75967
40.40000,-6.73345,-4.76453
40.50000,-6.75025,-4.76908
40.60000,-6.76678,-4.77282
40.70000,-6.78372,-4.77819
40.80000,-6.80025,-4.78198
40.90000,-6.81678,-4.78895
41.00000,-6.83358,-4.79248
41.10000,-6.84998,-4.79637
41.20000,-6.86692,-4.80165
41.30000,-6.88372,-4.80861
41.40000,-6.90025,-4.81349
41.50000,-6.91692,-4.81775
41.60000,-6.93372,-4.82278
41.70000,-6.95025,-4.82646
41.80000,-6.96665,-4.83254
41.90000,-6.98345,-4.83721
42.00000,-7.00012,-4.84247
42.10000,-7.01692,-4.84835
42.20000,-7.03385,-4.85219
42.30000,-7.05025,-4.85373
42.40000,-7.06705,-4.85332
42.50000,-7.08358,-4.85471
42.60000,-7.10025,-4.85460
42.70000,-7.11665,-4.85515
42.80000,-7.13345,-4.85838
42.90000,-7.15012,-4.86218
43.00000,-7.16705,-4.86722
43.10000,-7.18372,-4.87023
43.20000,-7.20012,-4.87291
43.30000,-7.21692,-4.87639
43.40000,-7.23332,-4.87747
43.50000,-7.25012,-4.88111
43.60000,-7.26692,-4.88494
43.70000,-7.28372,-4.88757
43.80000,-7.30025,-4.88839
43.90000,-7.31705,-4.89101
44.00000,-7.33372,-4.89099
44.10000,-7.34998,-4.89211
44.20000,-7.36692,-4.89683
44.30000,-7.38332,-4.89770
44.40000,-7.40012,-4.90101
44.50000,-7.41692,-4.90144
44.60000,-7.43372,-4.90290
44.70000,-7.45025,-4.90311
44.80000,-7.46692,-4.90560
44.90000,-7.48372,-4.90433
45.00000,-7.49998,-4.90526
45.10000,-7.51691,-4.90740
45.20000,-7.53345,-4.90894
45.30000,-7.55025,-4.91272
45.40000,-7.56691,-4.91390
45.50000,-7.58358,-4.91631
45.60000,-7.60038,-4.91837
45.70000,-7.61678,-4.91877
45.80000,-7.63345,-4.92051
45.90000,-7.64998,-4.92350
46.00000,-7.66691,-4.92587
46.10000,-7.68345,-4.92724
46.20000,-7.70038,-4.93005
46.30000,-7.71691,-4.93122
46.40000,-7.73345,-4.93353
46.50000,-7.75038,-4.93586
46.60000,-7.76665,-4.93870
46.70000,-7.78331,-4.94142
46.80000,-7.80011,-4.94398
46.90000,-7.81691,-4.94708
47.00000,-7.83358,-4.94864
47.10000,-7.85038,-4.95263
47.20000,-7.86705,-4.95430
47.30000,-7.88331,-4.95678
47.40000,-7.90025,-4.95772
47.50000,-7.91651,-4.96073
47.60000,-7.93345,-4.96363
47.70000,-7.95011,-4.96576
47.80000,-7.96691,-4.96942
47.90000,-7.98358,-4.97282
48.00000,-8.00038,-4.97619
48.10000,-8.01691,-4.97547
48.20000,-8.03331,-4.97762
48.30000,-8.05038,-4.98063
48.40000,-8.06678,-4.98201
48.50000,-8.08358,-4.98565
48.60000,-8.10038,-4.98665
48.70000,-8.11691,-4.98818
48.80000,-8.13371,-4.99010
48.90000,-8.15025,-4.98853
49.00000,-8.16691,-4.98933
49.10000,-8.18331,-4.98870
49.20000,-8.20038,-4.99193
49.30000,-8.21678,-4.99278
49.40000,-8.23358,-4.99637
49.50000,-8.25025,-4.99534
49.60000,-8.26678,-4.99665
49.70000,-8.28345,-4.99596
49.80000,-8.29985,-4.99273
49.90000,-8.31678,-4.99516
50.00000,-8.33358,-4.99670
50.10000,-8.35038,-4.99982
50.20000,-8.36691,-4.99961
50.30000,-8.38358,-5.00215
50.40000,-8.40025,-5.00172
50.50000,-8.41678,-5.00351
50.60000,-8.43358,-5.00560
50.70000,-8.44998,-5.00776
50.80000,-8.46691,-5.01120
50.90000,-8.48358,-5.01300
51.00000,-8.50038,-5.01586
51.10000,-8.51705,-5.01654
51.20000,-8.53371,-5.01901
51.30000,-8.55025,-5.01850
51.40000,-8.56665,-5.02021
51.50000,-8.58358,-5.02233
51.60000,-8.60011,-5.02253
51.70000,-8.61691,-5.02626
51.80000,-8.63371,-5.02680
51.90000,-8.65011,-5.02743
52.00000,-8.66705,-5.02975
52.10000,-8.68358,-5.02970
52.20000,-8.70025,-5.03105
52.30000,-8.71678,-5.03136
52.40000,-8.73358,-5.03210
52.50000,-8.75011,-5.03307
52.60000,-8.76705,-5.03384
52.70000,-8.78371,-5.03327
52.80000,-8.80024,-5.03487
52.90000,-8.81705,-5.03606
53.00000,-8.83345,-5.03614
53.10000,-8.84998,-5.03636
53.20000,-8.86678,-5.03715
53.30000,-8.88358,-5.03790
53.40000,-8.90011,-5.03720
53.50000,-8.91704,-5.03753
53.60000,-8.93371,-5.03784
53.70000,-8.94998,-5.03725
53.80000,-8.96678,-5.03828
53.90000,-8.98331,-5.03833
54.00000,-9.00011,-5.04242
54.10000,-9.01704,-5.04224
54.20000,-9.03358,-5.04291
54.30000,-9.05024,-5.04198
54.40000,-9.06691,-5.04062
54.50000,-9.08358,-5.03902
54.60000,-9.10011,-5.03857
54.70000,-9.11691,-5.03836
54.80000,-9.13344,-5.03681
54.90000,-9.15024,-5.03769
55.00000,-9.16704,-5.03753
55.10000,-9.18358,-5.03647
55.20000,-9.20038,-5.03624
55.30000,-9.21691,-5.03515
55.40000,-9.23358,-5.03586
55.50000,-9.25011,-5.03433
55.60000,-9.26691,-5.03388
55.70000,-9.28358,-5.03269
55.80000,-9.30038,-5.03478
55.90000,-9.31704,-5.03220
56.00000,-9.33344,-5.03064
56.10000,-9.35038,-5.03116
56.20000,-9.36678,-5.03081
56.30000,-9.38344,-5.02978
56.40000,-9.40011,-5.02872
56.50000,-9.41704,-5.03070
56.60000,-9.43358,-5.02946
56.70000,-9.45038,-5.02960
56.80000,-9.46691,-5.02825
56.90000,-9.48344,-5.02977
57.00000,-9.50024,-5.03033
57.10000,-9.51664,-5.02934
57.20000,-9.53344,-5.03082
57.30000,-9.55011,-5.03064
57.40000,-9.56664,-5.03048
57.50000,-9.58331,-5.03127
57.60000,-9.60024,-5.03229
57.70000,-9.61678,-5.03107
57.80000,-9.63318,-5.03348
57.90000,-9.65024,-5.03360
58.00000,-9.66664,-5.03225
58.10000,-9.68371,-5.03438
58.20000,-9.70038,-5.03331
58.30000,-9.71691,-5.03278
58.40000,-9.73371,-5.03234
58.50000,-9.75024,-5.03105
58.60000,-9.76691,-5.03004
58.70000,-9.78344,-5.02996
58.80000,-9.80024,-5.02824
58.90000,-9.81678,-5.02682
59.00000,-9.83371,-5.02773
59.10000,-9.85024,-5.02436
59.20000,-9.86678,-5.02449
59.30000,-9.88371,-5.02307
59.40000,-9.89998,-5.02194
59.50000,-9.91678,-5.02111
59.60000,-9.93344,-5.02021
59.70000,-9.95024,-5.01882
59.80000,-9.96678,-5.01739
59.90000,-9.98358,-5.01835
60.00000,-10.00024,-5.01687
60.10000,-10.01664,-5.01927
60.20000,-10.03358,-5.01957
60.30000,-10.04998,-5.02065
60.40000,-10.06691,-5.02293
60.50000,-10.08358,-5.02396
60.60000,-10.10038,-5.02654
60.70000,-10.11691,-5.02845
60.80000,-10.13371,-5.03058
60.90000,-10.15024,-5.03274
61.00000,-10.16678,-5.03521
61.10000,-10.18358,-5.03799
61.20000,-10.20011,-5.03943
61.30000,-10.21691,-5.04591
61.40000,-10.23371,-5.05000
61.50000,-10.25024,-5.05531
61.60000,-10.26704,-5.05815
61.70000,-10.28344,-5.05843
61.80000,-10.30011,-5.05931
61.90000,-10.31678,-5.06099
62.00000,-10.33371,-5.06293
62.10000,-10.35011,-5.06499
62.20000,-10.36704,-5.06991
62.30000,-10.38358,-5.07253
62.40000,-10.40011,-5.07517
62.50000,-10.41691,-5.07473
62.60000,-10.43331,-5.07627
62.70000,-10.45011,-5.07862
62.80000,-10.46677,-5.07984
62.90000,-10.48357,-5.08286
63.00000,-10.50011,-5.08646
63.10000,-10.51691,-5.08749
63.20000,-10.53357,-5.08562
63.30000,-10.54997,-5.08967
63.40000,-10.56691,-5.09072
63.50000,-10.58317,-5.09197
63.60000,-10.60024,-5.09413
63.70000,-10.61691,-5.09448
63.80000,-10.63357,-5.09621
63.90000,-10.65024,-5.09343
64.00000,-10.66704,-5.09465
64.10001,-10.68371,-5.09392
64.20000,-10.69997,-5.09604
64.30000,-10.71691,-5.09598
64.40000,-10.73344,-5.09389
64.50000,-10.75037,-5.09554
64.60001,-10.76704,-5.09425
64.70000,-10.78357,-5.09393
64.80000,-10.80037,-5.09132
64.90000,-10.81691,-5.09094
65.00000,-10.83357,-5.08957
65.10001,-10.84997,-5.08758
65.20000,-10.86691,-5.08623
65.30000,-10.88344,-5.08569
65.40000,-10.90024,-5.08519
65.50000,-10.91691,-5.08267
65.60001,-10.93357,-5.08182
65.70001,-10.95024,-5.08122
65.80000,-10.96664,-5.07751
65.90000,-10.98357,-5.07635
66.00000,-10.99997,-5.07542
66.10001,-11.01691,-5.07512
66.20001,-11.03357,-5.07357
66.30000,-11.05037,-5.07446
66.40000,-11.06704,-5.07402
66.50000,-11.08331,-5.07244
66.60001,-11.10024,-5.07167
66.70001,-11.11664,-5.07102
66.80000,-11.13357,-5.07273
66.90000,-11.15024,-5.07209
67.00000,-11.16691,-5.07135
67.10001,-11.18357,-5.07094
67.20001,-11.20037,-5.07294
67.30000,-11.21704,-5.06894
67.40000,-11.23344,-5.06908
67.50000,-11.25011,-5.06553
67.60001,-11.26664,-5.06564
67.70001,-11.28357,-5.06751
67.80000,-11.30024,-5.06465
67.90000,-11.31691,-5.06277
68.00000,-11.33371,-5.05927
68.10001,-11.35024,-5.05826
68.20001,-11.36691,-5.05588
68.30000,-11.38344,-5.05014
68.40000,-11.40024,-5.04445
68.50000,-11.41691,-5.04032
68.60001,-11.43371,-5.04126
68.70001,-11.45024,-5.03399
68.80000,-11.46677,-5.02932
68.90000,-11.48357,-5.02432
69.00000,-11.49997,-5.01932
69.10001,-11.51677,-5.01600
69.20001,-11.53344,-5.00823
69.30000,-11.55037,-5.00313
69.40000,-11.56677,-4.99881
69.50000,-11.58371,-4.99836
69.60001,-11.60024,-4.99453
69.70001,-11.61664,-4.98839
69.80000,-11.63371,-4.98394
69.90000,-11.65011,-4.97923
70.00000,-11.66691,-4.97700
70.10001,-11.68357,-4.97475
70.20001,-11.70037,-4.96849
70.30000,-11.71691,-4.96073
70.40000,-11.73371,-4.96090
70.50000,-11.75024,-4.95375
70.60001,-11.76664,-4.95169
70.70001,-11.78344,-4.94738
70.80000,-11.79997,-4.94145
70.90000,-11.81690,-4.93829
71.00000,-11.83370,-4.93427
71.10001,-11.85010,-4.93078
71.20001,-11.86704,-4.92962
71.30000,-11.88357,-4.92137
71.40000,-11.90024,-4.91601
71.50000,-11.91677,-4.90972
71.60001,-11.93357,-4.91131
71.70001,-11.95024,-4.90361
71.80000,-11.96704,-4.89855
71.90000,-11.98370,-4.88737
72.00000,-12.00024,-4.88336
72.10001,-12.01690,-4.88125
72.20001,-12.03330,-4.87399
72.30000,-12.04997,-4.86566
72.40000,-12.06677,-4.85834
72.50000,-12.08370,-4.85346
72.60001,-12.10010,-4.85229
72.70001,-12.11704,-4.84359
72.80000,-12.13357,-4.83373
72.90000,-12.14997,-4.82492
73.00000,-12.16690,-4.82132
73.10001,-12.18317,-4.82342
73.20001,-12.20010,-4.81730
73.30000,-12.21690,-4.80775
73.40000,-12.23357,-4.79844
73.50000,-12.25010,-4.79125
73.60001,-12.26690,-4.79564
73.70001,-12.28357,-4.78934
73.80000,-12.29997,-4.78181
73.90000,-12.31690,-4.77270
74.00000,-12.33344,-4.76533
74.10001,-12.35024,-4.76700
74.20001,-12.36690,-4.75797
74.30000,-12.38370,-4.75198
74.40000,-12.40037,-4.74653
74.50000,-12.41677,-4.74378
74.60001,-12.43344,-4.74489
74.70001,-12.45010,-4.74187
74.80000,-12.46704,-4.74298
74.90000,-12.48357,-4.73991
75.00000,-12.50037,-4.74357
75.10001,-12.51690,-4.74733
75.20001,-12.53357,-4.75009
75.30000,-12.55037,-4.75005
75.40000,-12.56677,-4.74865
75.50000,-12.58330,-4.74557
75.60001,-12.60010,-4.74721
75.70001,-12.61690,-4.74401
75.80000,-12.63357,-4.74016
75.90000,-12.65037,-4.73601
76.00000,-12.66704,-4.73081
76.10001,-12.68344,-4.72910
76.20001,-12.70024,-4.72859
76.30000,-12.71664,-4.72453
76.40000,-12.73357,-4.72516
76.50000,-12.75037,-4.72384
76.60001,-12.76704,-4.72369
76.70001,-12.78357,-4.72293
76.80000,-12.80024,-4.72353
76.90000,-12.81690,-4.71993
77.00000,-12.83330,-4.71972
77.10001,-12.85024,-4.71953
77.20001,-12.86663,-4.71890
77.30000,-12.88357,-4.72251
77.40000,-12.90037,-4.72161
77.50000,-12.91677,-4.72116
77.60001,-12.93357,-4.72325
77.70001,-12.95010,-4.72410
77.80000,-12.96704,-4.72670
77.90000,-12.98357,-4.72838
78.00000,-13.00037,-4.73123
78.10001,-13.01677,-4.72928
78.20001,-13.03370,-4.73402
78.30000,-13.05037,-4.73501
78.40000,-13.06690,-4.73565
78.50000,-13.08357,-4.73630
78.60001,-13.09997,-4.74146
78.70001,-13.11677,-4.74377
78.80000,-13.13343,-4.74626
78.90000,-13.15037,-4.74845
79.00000,-13.16690,-4.74955
79.10001,-13.18357,-4.75262
79.20001,-13.20023,-4.75436
79.30000,-13.21677,-4.75681
79.40000,-13.23357,-4.75819
79.50000,-13.24997,-4.75943
79.60001,-13.26677,-4.76202
79.70001,-13.28357,-4.76449
79.80000,-13.30023,-4.76934
79.90000,-13.31690,-4.77311
80.00000,-13.33370,-4.77803
80.10001,-13.35037,-4.77815
80.20001,-13.36663,-4.77813
80.30000,-13.38357,-4.78062
80.40000,-13.40010,-4.78090
80.50001,-13.41703,-4.78819
80.60001,-13.43370,-4.78785
80.70001,-13.45023,-4.79132
80.80000,-13.46703,-4.79416
80.90000,-13.48357,-4.79560
81.00001,-13.50037,-4.79964
81.10001,-13.51677,-4.80451
81.20001,-13.53357,-4.80938
81.30000,-13.55010,-4.81330
81.40000,-13.56703,-4.81757
81.50001,-13.58357,-4.81995
81.60001,-13.60010,-4.82476
81.70001,-13.61690,-4.82998
81.80000,-13.63343,-4.83472
81.90000,-13.65010,-4.84049
82.00001,-13.66677,-4.84833
82.10001,-13.68370,-4.85583
82.20001,-13.70010,-4.86169
82.30000,-13.71703,-4.87013
82.40000,-13.73370,-4.87674
82.50001,-13.74997,-4.88408
82.60001,-13.76690,-4.89009
82.70001,-13.78330,-4.89671
82.80000,-13.80010,-4.90312
82.90000,-13.81690,-4.91074
83.00001,-13.83357,-4.91703
83.10001,-13.85023,-4.92336
83.20001,-13.86690,-4.92983
83.30000,-13.88370,-4.93417
83.40000,-13.90010,-4.94100
83.50001,-13.91677,-4.94785
83.60001,-13.93343,-4.95612
83.70001,-13.95037,-4.96708
83.80000,-13.96703,-4.97486
83.90000,-13.98343,-4.98244
84.00001,-14.00037,-4.99316
84.10001,-14.01690,-5.00138
84.20001,-14.03357,-5.00925
84.30000,-14.05010,-5.01774
84.40000,-14.06690,-5.02657
84.50001,-14.08343,-5.03427
84.60001,-14.10037,-5.04419
84.70001,-14.11690,-5.05036
84.80000,-14.13357,-5.05978
84.90000,-14.15037,-5.06871
85.00001,-14.16677,-5.07738
85.10001,-14.18330,-5.08617
85.20001,-14.20010,-5.09671
85.30000,-14.21690,-5.10702
85.40000,-14.23343,-5.11711
85.50001,-14.25023,-5.12661
85.60001,-14.26676,-5.13593
85.70001,-14.28330,-5.14678
85.80000,-14.30037,-5.15589
85.90000,-14.31650,-5.16328
86.00001,-14.33356,-5.17499
86.10001,-14.35023,-5.18313
86.20001,-14.36690,-5.19036
86.30000,-14.38370,-5.19917
86.40000,-14.40036,-5.20574
86.50001,-14.41690,-5.21210
86.60001,-14.43330,-5.22068
86.70001,-14.45023,-5.22977
86.80000,-14.46676,-5.23728
86.90000,-14.48356,-5.23952
87.00001,-14.50023,-5.25091
87.10001,-14.51690,-5.26249
87.20001,-14.53370,-5.27792
87.30000,-14.55023,-5.28323
87.40000,-14.56703,-5.28640
87.50001,-14.58343,-5.29185
87.60001,-14.60023,-5.30180
87.70001,-14.61676,-5.31944
87.80000,-14.63356,-5.32995
87.90000,-14.65023,-5.33387
88.00001,-14.66676,-5.33777
88.10001,-14.68370,-5.34255
88.20001,-14.69996,-5.34027
88.30000,-14.71676,-5.34687
88.40000,-14.73343,-5.35671
88.50001,-14.75023,-5.36499
88.60001,-14.76663,-5.36553
88.70001,-14.78370,-5.36933
88.80000,-14.80036,-5.36769
88.90000,-14.81676,-5.38060
89.00001,-14.83370,-5.39241
89.10001,-14.84996,-5.39849
89.20001,-14.86676,-5.40531
89.30000,-14.88356,-5.41177
89.40000,-14.90023,-5.42203
89.50001,-14.91690,-5.43143
89.60001,-14.93343,-5.44682
89.70001,-14.95036,-5.46397
89.80000,-14.96676,-5.47310
89.90000,-14.98370,-5.48113
90.00001,-15.00010,-5.49119
90.04201,-15.00730,-5.48786