File: GFBaking/data/2_13PercentGluten/2_13gluten_Compression.is_comp_RawData/Specimen_RawData_2.csv
Time,Extension,Load
(sec),(mm),(N)
0.00000,-0.00027,-0.07318
0.10000,-0.00653,-0.07743
0.20000,-0.02587,-0.09779
0.30000,-0.04613,-0.12067
0.40000,-0.06453,-0.13643
0.50000,-0.08240,-0.15237
0.60000,-0.09960,-0.16574
0.70000,-0.11640,-0.18380
0.80000,-0.13333,-0.19470
0.90000,-0.14987,-0.20829
1.00000,-0.16680,-0.22046
1.10000,-0.18360,-0.23572
1.20000,-0.20013,-0.24531
1.30000,-0.21707,-0.25841
1.40000,-0.23373,-0.27496
1.50000,-0.25040,-0.28735
1.60000,-0.26680,-0.30110
1.70000,-0.28360,-0.31504
1.80000,-0.30013,-0.32941
1.90000,-0.31693,-0.34280
2.00000,-0.33387,-0.35364
2.10000,-0.35040,-0.36665
2.20000,-0.36693,-0.38104
2.30000,-0.38360,-0.39442
2.40000,-0.40027,-0.40836
2.50000,-0.41667,-0.42216
2.60000,-0.43360,-0.43540
2.70000,-0.45027,-0.44978
2.80000,-0.46693,-0.46249
2.90000,-0.48387,-0.47641
3.00000,-0.50013,-0.49002
3.10000,-0.51693,-0.50248
3.20000,-0.53347,-0.51485
3.30000,-0.55000,-0.52839
3.40000,-0.56680,-0.54184
3.50000,-0.58360,-0.55372
3.60000,-0.60013,-0.56639
3.70000,-0.61693,-0.58048
3.80000,-0.63373,-0.59403
3.90000,-0.65000,-0.60638
4.00000,-0.66693,-0.61926
4.10000,-0.68346,-0.63252
4.20000,-0.70026,-0.64657
4.30000,-0.71706,-0.65877
4.40000,-0.73360,-0.67306
4.50000,-0.75040,-0.68689
4.60000,-0.76706,-0.70078
4.70000,-0.78373,-0.71390
4.80000,-0.80013,-0.72824
4.90000,-0.81693,-0.74126
5.00000,-0.83360,-0.75370
5.10000,-0.85026,-0.76664
5.20000,-0.86706,-0.78095
5.30000,-0.88360,-0.79405
5.40000,-0.90053,-0.80727
5.50000,-0.91693,-0.81985
5.60000,-0.93346,-0.83314
5.70000,-0.95000,-0.84587
5.80000,-0.96680,-0.85885
5.90000,-0.98360,-0.87218
6.00000,-1.00026,-0.88599
6.10000,-1.01706,-0.89895
6.20000,-1.03333,-0.91152
6.30000,-1.05026,-0.92549
6.40000,-1.06666,-0.93802
6.50000,-1.08320,-0.95073
6.60000,-1.10013,-0.96196
6.70000,-1.11706,-0.97645
6.80000,-1.13360,-0.98967
6.90000,-1.15026,-1.00141
7.00000,-1.16706,-1.01435
7.10000,-1.18346,-1.02774
7.20000,-1.20026,-1.04292
7.30000,-1.21666,-1.05583
7.40000,-1.23346,-1.06742
7.50000,-1.25040,-1.08312
7.60000,-1.26693,-1.09606
7.70000,-1.28373,-1.10702
7.80000,-1.30053,-1.12050
7.90000,-1.31706,-1.13032
8.00000,-1.33360,-1.14267
8.10000,-1.35026,-1.15397
8.20000,-1.36693,-1.16589
8.30000,-1.38360,-1.17925
8.40000,-1.40053,-1.18876
8.50000,-1.41693,-1.20197
8.60000,-1.43373,-1.21637
8.70000,-1.45026,-1.22734
8.80000,-1.46680,-1.24135
8.90000,-1.48333,-1.25266
9.00000,-1.50026,-1.26506
9.10000,-1.51693,-1.27817
9.20000,-1.53346,-1.29177
9.30000,-1.55053,-1.30112
9.40000,-1.56680,-1.31143
9.50000,-1.58360,-1.32463
9.60000,-1.60000,-1.33693
9.70000,-1.61666,-1.35043
9.80000,-1.63346,-1.35992
9.90000,-1.65026,-1.37116
10.00000,-1.66693,-1.38126
10.10000,-1.68373,-1.39258
10.20000,-1.70040,-1.40463
10.30000,-1.71680,-1.41531
10.40000,-1.73360,-1.42656
10.50000,-1.74986,-1.43544
10.60000,-1.76680,-1.44677
10.70000,-1.78386,-1.45878
10.80000,-1.80040,-1.46844
10.90000,-1.81706,-1.48061
11.00000,-1.83386,-1.49072
11.10000,-1.85040,-1.50047
11.20000,-1.86693,-1.51167
11.30000,-1.88360,-1.52103
11.40000,-1.90026,-1.53345
11.50000,-1.91693,-1.54303
11.60000,-1.93386,-1.55017
11.70000,-1.95026,-1.56019
11.80000,-1.96680,-1.56939
11.90000,-1.98333,-1.58254
12.00000,-2.00013,-1.59244
12.10000,-2.01653,-1.60001
12.20000,-2.03359,-1.60879
12.30000,-2.05013,-1.61750
12.40000,-2.06680,-1.63092
12.50000,-2.08373,-1.64002
12.60000,-2.10026,-1.64913
12.70000,-2.11693,-1.65753
12.80000,-2.13346,-1.66595
12.90000,-2.15013,-1.67585
13.00000,-2.16679,-1.68549
13.10000,-2.18359,-1.69344
13.20000,-2.20026,-1.70216
13.30000,-2.21706,-1.70968
13.40000,-2.23386,-1.71929
13.50000,-2.25013,-1.72580
13.60000,-2.26693,-1.73597
13.70000,-2.28333,-1.74189
13.80000,-2.30026,-1.75107
13.90000,-2.31706,-1.75840
14.00000,-2.33373,-1.76531
14.10000,-2.35053,-1.77245
14.20000,-2.36706,-1.78013
14.30000,-2.38359,-1.78881
14.40000,-2.39999,-1.79749
14.50000,-2.41679,-1.80356
14.60000,-2.43359,-1.80980
14.70000,-2.45026,-1.81649
14.80000,-2.46719,-1.82203
14.90000,-2.48359,-1.82916
15.00000,-2.50039,-1.83562
15.10000,-2.51693,-1.84056
15.20000,-2.53373,-1.84543
15.30000,-2.55013,-1.84913
15.40000,-2.56693,-1.85552
15.50000,-2.58359,-1.86256
15.60000,-2.60026,-1.86981
15.70000,-2.61706,-1.87683
15.80000,-2.63346,-1.88267
15.90000,-2.65026,-1.88821
16.00000,-2.66666,-1.89370
16.10000,-2.68333,-1.89870
16.20000,-2.70013,-1.90679
16.30000,-2.71693,-1.91442
16.40000,-2.73359,-1.92117
16.50000,-2.75039,-1.92704
16.60000,-2.76706,-1.93189
16.70000,-2.78346,-1.93822
16.80000,-2.80026,-1.94502
16.90000,-2.81666,-1.95131
17.00000,-2.83359,-1.95724
17.10000,-2.85053,-1.96345
17.20000,-2.86706,-1.96820
17.30000,-2.88386,-1.97512
17.40000,-2.90026,-1.98045
17.50000,-2.91693,-1.98307
17.60000,-2.93333,-1.98659
17.70000,-2.95026,-1.98949
17.80000,-2.96693,-1.99430
17.90000,-2.98359,-2.00110
18.00000,-3.00053,-2.00685
18.10000,-3.01693,-2.01065
18.20000,-3.03373,-2.01511
18.30000,-3.05013,-2.02053
18.40000,-3.06679,-2.02726
18.50000,-3.08319,-2.03092
18.60000,-3.10026,-2.03664
18.70000,-3.11693,-2.04106
18.80000,-3.13359,-2.04410
18.90000,-3.15039,-2.04578
19.00000,-3.16679,-2.04818
19.10000,-3.18359,-2.05183
19.20000,-3.20013,-2.05402
19.30000,-3.21666,-2.05676
19.40000,-3.23333,-2.05952
19.50000,-3.25026,-2.06064
19.60000,-3.26693,-2.05908
19.70000,-3.28359,-2.06052
19.80000,-3.30039,-2.06320
19.90000,-3.31679,-2.06707
20.00000,-3.33359,-2.06608
20.10000,-3.35013,-2.06832
20.20000,-3.36693,-2.06871
20.30000,-3.38373,-2.06985
20.40000,-3.40026,-2.07137
20.50000,-3.41706,-2.07229
20.60000,-3.43386,-2.07539
20.70000,-3.45039,-2.07652
20.80000,-3.46666,-2.07733
20.90000,-3.48359,-2.08063
21.00000,-3.50026,-2.08386
21.10000,-3.51692,-2.08483
21.20000,-3.53386,-2.08496
21.30000,-3.55039,-2.08514
21.40000,-3.56706,-2.08710
21.50000,-3.58359,-2.09014
21.60000,-3.60039,-2.09361
21.70000,-3.61679,-2.09588
21.80000,-3.63372,-2.09722
21.90000,-3.65026,-2.09958
22.00000,-3.66692,-2.10105
22.10000,-3.68372,-2.10563
22.20000,-3.70012,-2.10678
22.30000,-3.71692,-2.10900
22.40000,-3.73332,-2.11062
22.50000,-3.75012,-2.11108
22.60000,-3.76679,-2.11332
22.70000,-3.78372,-2.11301
22.80000,-3.80026,-2.11504
22.90000,-3.81706,-2.11718
23.00000,-3.83372,-2.12024
23.10000,-3.85012,-2.12136
23.20000,-3.86706,-2.12046
23.30000,-3.88332,-2.12096
23.40000,-3.90026,-2.12508
23.50000,-3.91706,-2.12865
23.60000,-3.93359,-2.12696
23.70000,-3.95039,-2.12711
23.80000,-3.96706,-2.13310
23.90000,-3.98372,-2.13311
24.00000,-4.00012,-2.12566
24.10000,-4.01706,-2.11731
24.20000,-4.03359,-2.11500
24.30000,-4.05026,-2.11392
24.40000,-4.06719,-2.11703
24.50000,-4.08372,-2.11541
24.60000,-4.10052,-2.11410
24.70000,-4.11692,-2.10793
24.80000,-4.13359,-2.10906
24.90000,-4.14999,-2.11012
25.00000,-4.16692,-2.10929
25.10000,-4.18359,-2.11229
25.20000,-4.20026,-2.11628
25.30000,-4.21706,-2.11319
25.40000,-4.23346,-2.10879
25.50000,-4.25026,-2.10597
25.60000,-4.26666,-2.10333
25.70000,-4.28346,-2.10307
25.80000,-4.30012,-2.09471
25.90000,-4.31706,-2.09325
26.00000,-4.33359,-2.08793
26.10000,-4.35039,-2.08829
26.20000,-4.36706,-2.08394
26.30000,-4.38346,-2.07821
26.40000,-4.40039,-2.08367
26.50000,-4.41666,-2.08191
26.60000,-4.43359,-2.08348
26.70000,-4.45052,-2.08746
26.80000,-4.46706,-2.08119
26.90000,-4.48372,-2.08140
27.00000,-4.50039,-2.08492
27.10000,-4.51706,-2.08193
27.20000,-4.53346,-2.08328
27.30000,-4.55026,-2.08369
27.40000,-4.56692,-2.08594
27.50000,-4.58359,-2.08645
27.60000,-4.60052,-2.08698
27.70000,-4.61692,-2.08773
27.80000,-4.63372,-2.08866
27.90000,-4.65026,-2.08837
28.00000,-4.66692,-2.08889
28.10000,-4.68332,-2.08729
28.20000,-4.70039,-2.08852
28.30000,-4.71692,-2.08604
28.40000,-4.73359,-2.08894
28.50000,-4.75039,-2.08731
28.60000,-4.76692,-2.08639
28.70000,-4.78359,-2.08849
28.80000,-4.80012,-2.08930
28.90000,-4.81679,-2.09028
29.00000,-4.83345,-2.09183
29.10000,-4.85039,-2.09435
29.20000,-4.86692,-2.09617
29.30000,-4.88372,-2.09958
29.40000,-4.90039,-2.10188
29.50000,-4.91679,-2.10360
29.60000,-4.93372,-2.10590
29.70000,-4.95012,-2.10985
29.80000,-4.96692,-2.11191
29.90000,-4.98372,-2.11520
30.00000,-5.00039,-2.11732
30.10000,-5.01719,-2.12089
30.20000,-5.03385,-2.12390
30.30000,-5.05039,-2.12498
30.40000,-5.06665,-2.12733
30.50000,-5.08372,-2.13100
30.60000,-5.10039,-2.13278
30.70000,-5.11705,-2.13704
30.80000,-5.13399,-2.13847
30.90000,-5.15039,-2.14217
31.00000,-5.16692,-2.14293
31.10000,-5.18359,-2.14453
31.20000,-5.20012,-2.14815
31.30000,-5.21652,-2.14973
31.40000,-5.23345,-2.15386
31.50000,-5.25025,-2.15607
31.60000,-5.26692,-2.16104
31.70000,-5.28385,-2.16184
31.80000,-5.30012,-2.16713
31.90000,-5.31692,-2.16794
32.00000,-5.33345,-2.17072
32.10000,-5.35012,-2.17190
32.20000,-5.36692,-2.17364
32.30000,-5.38372,-2.17674
32.40000,-5.40039,-2.17665
32.50000,-5.41705,-2.17841
32.60000,-5.43385,-2.18200
32.70000,-5.45012,-2.18268
32.80000,-5.46705,-2.18554
32.90000,-5.48332,-2.18862
33.00000,-5.50012,-2.18888
33.10000,-5.51692,-2.19317
33.20000,-5.53385,-2.19730
33.30000,-5.55039,-2.19751
33.40000,-5.56705,-2.20314
33.50000,-5.58372,-2.20555
33.60000,-5.59999,-2.21044
33.70000,-5.61692,-2.21225
33.80000,-5.63359,-2.21432
33.90000,-5.65025,-2.21934
34.00000,-5.66719,-2.22196
34.10000,-5.68359,-2.22456
34.20000,-5.70039,-2.22821
34.30000,-5.71692,-2.22863
34.40000,-5.73359,-2.22866
34.50000,-5.74999,-2.23729
34.60000,-5.76705,-2.23668
34.70000,-5.78372,-2.23890
34.80000,-5.80025,-2.24123
34.90000,-5.81719,-2.24103
35.00000,-5.83345,-2.24497
35.10000,-5.85025,-2.24734
35.20000,-5.86679,-2.24851
35.30000,-5.88332,-2.25412
35.40000,-5.90012,-2.25577
35.50000,-5.91705,-2.25760
35.60000,-5.93359,-2.26019
35.70000,-5.95025,-2.26077
35.80000,-5.96719,-2.26127
35.90000,-5.98332,-2.26706
36.00000,-6.00025,-2.26803
36.10000,-6.01679,-2.27167
36.20000,-6.03359,-2.27681
36.30000,-6.05052,-2.27876
36.40000,-6.06705,-2.27806
36.50000,-6.08372,-2.28200
36.60000,-6.10038,-2.28143
36.70000,-6.11705,-2.27990
36.80000,-6.13345,-2.28223
36.90000,-6.15038,-2.28184
37.00000,-6.16705,-2.28576
37.10000,-6.18372,-2.28747
37.20000,-6.20052,-2.29014
37.30000,-6.21692,-2.29286
37.40000,-6.23372,-2.29704
37.50000,-6.25025,-2.29915
37.60000,-6.26692,-2.30475
37.70000,-6.28332,-2.30178
37.80000,-6.30038,-2.30831
37.90000,-6.31692,-2.31064
38.00000,-6.33358,-2.31408
38.10000,-6.35065,-2.31416
38.20000,-6.36692,-2.31722
38.30000,-6.38345,-2.32004
38.40000,-6.39998,-2.31824
38.50000,-6.41678,-2.31628
38.60000,-6.43358,-2.32035
38.70000,-6.45038,-2.32040
38.80000,-6.46705,-2.32160
38.90000,-6.48372,-2.32500
39.00000,-6.50052,-2.32685
39.10000,-6.51678,-2.33288
39.20000,-6.53372,-2.33308
39.30000,-6.55012,-2.33363
39.40000,-6.56692,-2.33714
39.50000,-6.58372,-2.33814
39.60000,-6.60038,-2.33899
39.70000,-6.61718,-2.33993
39.80000,-6.63372,-2.34151
39.90000,-6.65038,-2.34046
40.00000,-6.66678,-2.34044
40.10000,-6.68358,-2.34146
40.20000,-6.70025,-2.34204
40.30000,-6.71692,-2.34224
40.40000,-6.73372,-2.34360
40.50000,-6.75038,-2.34503
40.60000,-6.76718,-2.34625
40.70000,-6.78358,-2.34574
40.80000,-6.80038,-2.34717
40.90000,-6.81665,-2.34779
41.00000,-6.83372,-2.34811
41.10000,-6.85025,-2.34860
41.20000,-6.86692,-2.34965
41.30000,-6.88372,-2.35016
41.40000,-6.90012,-2.35121
41.50000,-6.91692,-2.35225
41.60000,-6.93345,-2.35179
41.70000,-6.94998,-2.35196
41.80000,-6.96678,-2.35233
41.90000,-6.98358,-2.35181
42.00000,-7.00025,-2.35306
42.10000,-7.01705,-2.35464
42.20000,-7.03385,-2.35602
42.30000,-7.04998,-2.35585
42.40000,-7.06692,-2.35676
42.50000,-7.08332,-2.35756
42.60000,-7.10038,-2.35911
42.70000,-7.11718,-2.36062
42.80000,-7.13372,-2.36105
42.90000,-7.15038,-2.36234
43.00000,-7.16705,-2.36313
43.10000,-7.18372,-2.36420
43.20000,-7.20012,-2.36538
43.30000,-7.21692,-2.36707
43.40000,-7.23358,-2.36754
43.50000,-7.25025,-2.36951
43.60000,-7.26718,-2.37213
43.70000,-7.28372,-2.37259
43.80000,-7.30038,-2.37590
43.90000,-7.31692,-2.37639
44.00000,-7.33358,-2.37860
44.10000,-7.34998,-2.38015
44.20000,-7.36705,-2.38341
44.30000,-7.38372,-2.38559
44.40000,-7.40025,-2.38891
44.50000,-7.41718,-2.39069
44.60000,-7.43358,-2.39136
44.70000,-7.45038,-2.39319
44.80000,-7.46692,-2.39469
44.90000,-7.48358,-2.39796
45.00000,-7.50025,-2.39865
45.10000,-7.51705,-2.40058
45.20000,-7.53372,-2.40117
45.30000,-7.55038,-2.40366
45.40000,-7.56718,-2.40475
45.50000,-7.58345,-2.40633
45.60000,-7.60038,-2.40910
45.70000,-7.61678,-2.41099
45.80000,-7.63358,-2.41348
45.90000,-7.65025,-2.41637
46.00000,-7.66665,-2.41815
46.10000,-7.68358,-2.42097
46.20000,-7.70025,-2.42406
46.30000,-7.71691,-2.42529
46.40000,-7.73331,-2.42720
46.50000,-7.75025,-2.43019
46.60000,-7.76691,-2.43111
46.70000,-7.78358,-2.43475
46.80000,-7.80051,-2.43575
46.90000,-7.81705,-2.43845
47.00000,-7.83371,-2.44022
47.10000,-7.85025,-2.44183
47.20000,-7.86705,-2.44237
47.30000,-7.88345,-2.44791
47.40000,-7.90038,-2.45034
47.50000,-7.91705,-2.45172
47.60000,-7.93358,-2.45429
47.70000,-7.95038,-2.45569
47.80000,-7.96678,-2.45761
47.90000,-7.98358,-2.45869
48.00000,-8.00011,-2.45977
48.10000,-8.01678,-2.46241
48.20000,-8.03345,-2.46619
48.30000,-8.05038,-2.46833
48.40000,-8.06691,-2.46883
48.50000,-8.08358,-2.47511
48.60000,-8.10038,-2.47709
48.70000,-8.11678,-2.48112
48.80000,-8.13371,-2.48318
48.90000,-8.15011,-2.48600
49.00000,-8.16691,-2.48829
49.10000,-8.18371,-2.49319
49.20000,-8.20038,-2.49632
49.30000,-8.21718,-2.49671
49.40000,-8.23371,-2.50000
49.50000,-8.25038,-2.50195
49.60000,-8.26678,-2.50642
49.70000,-8.28371,-2.50847
49.80000,-8.30025,-2.51307
49.90000,-8.31691,-2.51545
50.00000,-8.33385,-2.51936
50.10000,-8.35038,-2.51948
50.20000,-8.36705,-2.52210
50.30000,-8.38345,-2.52576
50.40000,-8.40025,-2.52851
50.50000,-8.41665,-2.53115
50.60000,-8.43371,-2.53338
50.70000,-8.45025,-2.53805
50.80000,-8.46691,-2.53877
50.90000,-8.48371,-2.54044
51.00000,-8.50011,-2.54222
51.10000,-8.51691,-2.54462
51.20000,-8.53345,-2.54765
51.30000,-8.55011,-2.54911
51.40000,-8.56678,-2.54795
51.50000,-8.58358,-2.55062
51.60000,-8.60025,-2.55552
51.70000,-8.61705,-2.56092
51.80000,-8.63371,-2.56489
51.90000,-8.65011,-2.57320
52.00000,-8.66691,-2.57366
52.10000,-8.68331,-2.57479
52.20000,-8.70025,-2.57841
52.30000,-8.71705,-2.58409
52.40000,-8.73371,-2.58774
52.50000,-8.75038,-2.59110
52.60000,-8.76705,-2.59182
52.70000,-8.78385,-2.59165
52.80000,-8.80011,-2.59769
52.90000,-8.81691,-2.60191
53.00000,-8.83358,-2.60609
53.10000,-8.85038,-2.60993
53.20000,-8.86731,-2.61560
53.30000,-8.88358,-2.62076
53.40000,-8.90038,-2.62723
53.50000,-8.91691,-2.62878
53.60000,-8.93371,-2.63544
53.70000,-8.94998,-2.63730
53.80000,-8.96704,-2.64044
53.90000,-8.98358,-2.64440
54.00000,-9.00024,-2.65002
54.10000,-9.01718,-2.65251
54.20000,-9.03344,-2.65646
54.30000,-9.05011,-2.65981
54.40000,-9.06678,-2.66405
54.50000,-9.08344,-2.66916
54.60000,-9.09998,-2.67441
54.70000,-9.11704,-2.67742
54.80000,-9.13358,-2.68079
54.90000,-9.15038,-2.68317
55.00000,-9.16718,-2.68378
55.10000,-9.18344,-2.68986
55.20000,-9.20038,-2.69428
55.30000,-9.21678,-2.69916
55.40000,-9.23358,-2.70133
55.50000,-9.25038,-2.70362
55.60000,-9.26704,-2.70898
55.70000,-9.28384,-2.71593
55.80000,-9.30051,-2.71989
55.90000,-9.31704,-2.72383
56.00000,-9.33344,-2.72536
56.10000,-9.35038,-2.73087
56.20000,-9.36691,-2.73361
56.30000,-9.38371,-2.73792
56.40000,-9.40038,-2.74129
56.50000,-9.41704,-2.74578
56.60000,-9.43371,-2.74956
56.70000,-9.45038,-2.75316
56.80000,-9.46704,-2.75583
56.90000,-9.48331,-2.75996
57.00000,-9.50038,-2.76323
57.10000,-9.51691,-2.76715
57.20000,-9.53358,-2.76742
57.30000,-9.55038,-2.77125
57.40000,-9.56678,-2.77752
57.50000,-9.58358,-2.78022
57.60000,-9.59998,-2.78483
57.70000,-9.61678,-2.78667
57.80000,-9.63344,-2.79016
57.90000,-9.65038,-2.79271
58.00000,-9.66691,-2.79203
58.10000,-9.68371,-2.79492
58.20000,-9.70038,-2.79360
58.30000,-9.71678,-2.79087
58.40000,-9.73358,-2.79598
58.50000,-9.75024,-2.79712
58.60000,-9.76691,-2.79775
58.70000,-9.78384,-2.79504
58.80000,-9.80038,-2.79667
58.90000,-9.81718,-2.80281
59.00000,-9.83371,-2.80828
59.10000,-9.85024,-2.81224
59.20000,-9.86664,-2.81581
59.30000,-9.88358,-2.81755
59.40000,-9.90011,-2.82138
59.50000,-9.91691,-2.82805
59.60000,-9.93384,-2.83141
59.70000,-9.95038,-2.83066
59.80000,-9.96718,-2.83419
59.90000,-9.98358,-2.84014
60.00000,-10.00038,-2.84567
60.10000,-10.01664,-2.85267
60.20000,-10.03358,-2.85276
60.30000,-10.05024,-2.85290
60.40000,-10.06691,-2.85629
60.50000,-10.08384,-2.85658
60.60000,-10.10024,-2.86374
60.70000,-10.11691,-2.86286
60.80000,-10.13344,-2.86329
60.90000,-10.14998,-2.86643
61.00000,-10.16678,-2.86982
61.10000,-10.18371,-2.87190
61.20000,-10.20024,-2.86950
61.30000,-10.21691,-2.87553
61.40000,-10.23358,-2.87824
61.50000,-10.24998,-2.88166
61.60000,-10.26704,-2.88208
61.70000,-10.28344,-2.88728
61.80000,-10.30037,-2.89391
61.90000,-10.31717,-2.89764
62.00000,-10.33358,-2.90047
62.10000,-10.35024,-2.90642
62.20000,-10.36691,-2.90876
62.30000,-10.38358,-2.91174
62.40000,-10.40011,-2.91262
62.50000,-10.41704,-2.91678
62.60000,-10.43357,-2.91404
62.70000,-10.45024,-2.91620
62.80000,-10.46704,-2.91489
62.90000,-10.48371,-2.91903
63.00000,-10.50037,-2.91969
63.10000,-10.51691,-2.92373
63.20000,-10.53357,-2.92266
63.30000,-10.55011,-2.93197
63.40000,-10.56691,-2.94024
63.50000,-10.58344,-2.94310
63.60000,-10.60024,-2.95033
63.70000,-10.61704,-2.95012
63.80000,-10.63344,-2.95225
63.90000,-10.65024,-2.96090
64.00000,-10.66677,-2.96947
64.10001,-10.68344,-2.96774
64.20000,-10.70011,-2.97260
64.30000,-10.71717,-2.97747
64.40000,-10.73384,-2.98078
64.50000,-10.75037,-2.98405
64.60001,-10.76717,-2.98934
64.70000,-10.78344,-2.99560
64.80000,-10.80024,-2.99770
64.90000,-10.81677,-3.00042
65.00000,-10.83371,-3.00786
65.10001,-10.85037,-3.01188
65.20000,-10.86704,-3.01566
65.30000,-10.88357,-3.01730
65.40000,-10.90024,-3.02239
65.50000,-10.91704,-3.02670
65.60001,-10.93344,-3.02993
65.70001,-10.95024,-3.03312
65.80000,-10.96691,-3.03202
65.90000,-10.98371,-3.03885
66.00000,-11.00051,-3.04404
66.10001,-11.01704,-3.04738
66.20001,-11.03371,-3.05176
66.30000,-11.05024,-3.05286
66.40000,-11.06704,-3.05573
66.50000,-11.08357,-3.06000
66.60001,-11.10037,-3.06457
66.70001,-11.11691,-3.06693
66.80000,-11.13357,-3.07142
66.90000,-11.15051,-3.07153
67.00000,-11.16691,-3.07651
67.10001,-11.18357,-3.08048
67.20001,-11.19997,-3.08332
67.30000,-11.21677,-3.08798
67.40000,-11.23357,-3.09152
67.50000,-11.25037,-3.09064
67.60001,-11.26691,-3.09444
67.70001,-11.28357,-3.09938
67.80000,-11.30037,-3.10080
67.90000,-11.31677,-3.10530
68.00000,-11.33371,-3.10908
68.10001,-11.34997,-3.11303
68.20001,-11.36691,-3.11796
68.30000,-11.38384,-3.12360
68.40000,-11.40051,-3.12807
68.50000,-11.41704,-3.13054
68.60001,-11.43371,-3.13339
68.70001,-11.45037,-3.13826
68.80000,-11.46677,-3.14078
68.90000,-11.48357,-3.14421
69.00000,-11.50024,-3.14690
69.10001,-11.51691,-3.14856
69.20001,-11.53384,-3.14824
69.30000,-11.55037,-3.15480
69.40000,-11.56704,-3.16056
69.50000,-11.58357,-3.16457
69.60001,-11.60050,-3.16728
69.70001,-11.61677,-3.16994
69.80000,-11.63357,-3.17639
69.90000,-11.65024,-3.18021
70.00000,-11.66691,-3.18805
70.10001,-11.68371,-3.19245
70.20001,-11.70010,-3.19493
70.30000,-11.71691,-3.19454
70.40000,-11.73344,-3.19637
70.50000,-11.75010,-3.20132
70.60001,-11.76677,-3.20666
70.70001,-11.78357,-3.21062
70.80000,-11.80024,-3.20933
70.90000,-11.81704,-3.21587
71.00000,-11.83370,-3.21542
71.10001,-11.85010,-3.21847
71.20001,-11.86690,-3.22258
71.30000,-11.88330,-3.22409
71.40000,-11.90037,-3.23031
71.50000,-11.91717,-3.23451
71.60001,-11.93370,-3.23799
71.70001,-11.95037,-3.24151
71.80000,-11.96704,-3.24540
71.90000,-11.98384,-3.24849
72.00000,-12.00010,-3.25193
72.10001,-12.01690,-3.25591
72.20001,-12.03370,-3.25990
72.30000,-12.05024,-3.26402
72.40000,-12.06717,-3.26811
72.50000,-12.08357,-3.27123
72.60001,-12.10037,-3.27519
72.70001,-12.11690,-3.28213
72.80000,-12.13357,-3.28276
72.90000,-12.14997,-3.28422
73.00000,-12.16690,-3.28983
73.10001,-12.18357,-3.29186
73.20001,-12.20024,-3.29766
73.30000,-12.21704,-3.30245
73.40000,-12.23357,-3.30359
73.50000,-12.25024,-3.30439
73.60001,-12.26677,-3.30635
73.70001,-12.28330,-3.30861
73.80000,-12.30010,-3.31283
73.90000,-12.31690,-3.31670
74.00000,-12.33357,-3.32035
74.10001,-12.35024,-3.32176
74.20001,-12.36690,-3.32263
74.30000,-12.38357,-3.32334
74.40000,-12.40037,-3.32803
74.50000,-12.41677,-3.32719
74.60001,-12.43370,-3.33188
74.70001,-12.45037,-3.33489
74.80000,-12.46704,-3.33785
74.90000,-12.48384,-3.34073
75.00000,-12.50037,-3.34207
75.10001,-12.51704,-3.34485
75.20001,-12.53330,-3.34351
75.30000,-12.55037,-3.34479
75.40000,-12.56690,-3.34469
75.50000,-12.58357,-3.34728
75.60001,-12.60050,-3.34582
75.70001,-12.61704,-3.34832
75.80000,-12.63370,-3.35242
75.90000,-12.65024,-3.35612
76.00000,-12.66690,-3.35684
76.10001,-12.68344,-3.35854
76.20001,-12.70024,-3.36102
76.30000,-12.71690,-3.36215
76.40000,-12.73357,-3.36657
76.50000,-12.75050,-3.36956
76.60001,-12.76677,-3.37452
76.70001,-12.78357,-3.37913
76.80000,-12.80010,-3.37988
76.90000,-12.81677,-3.38525
77.00000,-12.83344,-3.39289
77.10001,-12.85024,-3.39835
77.20001,-12.86690,-3.40290
77.30000,-12.88370,-3.40930
77.40000,-12.90037,-3.41318
77.50000,-12.91677,-3.41824
77.60001,-12.93357,-3.42397
77.70001,-12.95010,-3.42860
77.80000,-12.96677,-3.43382
77.90000,-12.98370,-3.43861
78.00000,-13.00037,-3.44486
78.10001,-13.01704,-3.45072
78.20001,-13.03384,-3.45461
78.30000,-13.05063,-3.46160
78.40000,-13.06690,-3.46159
78.50000,-13.08370,-3.46374
78.60001,-13.10037,-3.46897
78.70001,-13.11703,-3.47688
78.80000,-13.13397,-3.48382
78.90000,-13.15037,-3.49224
79.00000,-13.16717,-3.49904
79.10001,-13.18370,-3.50568
79.20001,-13.20023,-3.51254
79.30000,-13.21677,-3.51993
79.40000,-13.23370,-3.52717
79.50000,-13.25037,-3.53333
79.60001,-13.26690,-3.53941
79.70001,-13.28370,-3.54457
79.80000,-13.30010,-3.55166
79.90000,-13.31677,-3.55891
80.00000,-13.33330,-3.56496
80.10001,-13.34997,-3.57117
80.20001,-13.36677,-3.57744
80.30000,-13.38357,-3.58252
80.40000,-13.40023,-3.58959
80.50001,-13.41690,-3.59627
80.60001,-13.43383,-3.60230
80.70001,-13.45010,-3.60652
80.80000,-13.46690,-3.61365
80.90000,-13.48343,-3.61923
81.00001,-13.50037,-3.62718
81.10001,-13.51717,-3.63420
81.20001,-13.53370,-3.64091
81.30000,-13.55050,-3.64912
81.40000,-13.56717,-3.65644
81.50001,-13.58383,-3.66334
81.60001,-13.60010,-3.67058
81.70001,-13.61690,-3.67681
81.80000,-13.63357,-3.68303
81.90000,-13.65023,-3.68979
82.00001,-13.66717,-3.69524
82.10001,-13.68357,-3.70066
82.20001,-13.70037,-3.70675
82.30000,-13.71690,-3.71236
82.40000,-13.73357,-3.71731
82.50001,-13.75010,-3.72078
82.60001,-13.76690,-3.72611
82.70001,-13.78357,-3.73070
82.80000,-13.80023,-3.73749
82.90000,-13.81717,-3.74124
83.00001,-13.83343,-3.74441
83.10001,-13.85023,-3.74962
83.20001,-13.86663,-3.75318
83.30000,-13.88343,-3.75746
83.40000,-13.90023,-3.49753
83.50001,-13.91690,-3.44569
83.60001,-13.93357,-3.50371
83.70001,-13.95023,-3.54773
83.80000,-13.96703,-3.58126
83.90000,-13.98357,-3.60975
84.00001,-14.00023,-3.63376
84.10001,-14.01663,-3.65035
84.20001,-14.03370,-3.66409
84.30000,-14.05050,-3.67371
84.40000,-14.06703,-3.68682
84.50001,-14.08383,-3.70095
84.60001,-14.10037,-3.71327
84.70001,-14.11703,-3.72041
84.80000,-14.13343,-3.69133
84.90000,-14.15010,-3.70725
85.00001,-14.16690,-3.72034
85.10001,-14.18370,-3.73313
85.20001,-14.20050,-3.74408
85.30000,-14.21703,-3.75359
85.40000,-14.23370,-3.76304
85.50001,-14.25023,-3.76990
85.60001,-14.26690,-3.77797
85.70001,-14.28330,-3.78546
85.80000,-14.30023,-3.79577
85.90000,-14.31676,-3.80347
86.00001,-14.33356,-3.81361
86.10001,-14.35036,-3.82038
86.20001,-14.36676,-3.82858
86.30000,-14.38370,-3.83640
86.40000,-14.40010,-3.84369
86.50001,-14.41676,-3.85078
86.60001,-14.43343,-3.85905
86.70001,-14.45036,-3.86724
86.80000,-14.46690,-3.87348
86.90000,-14.48356,-3.88270
87.00001,-14.50036,-3.88893
87.10001,-14.51676,-3.89682
87.20001,-14.53370,-3.90429
87.30000,-14.55010,-3.91068
87.40000,-14.56690,-3.91921
87.50001,-14.58383,-3.92736
87.60001,-14.60036,-3.93539
87.70001,-14.61703,-3.94297
87.80000,-14.63370,-3.95181
87.90000,-14.65050,-3.95853
88.00001,-14.66676,-3.96489
88.10001,-14.68356,-3.97262
88.20001,-14.70023,-3.97925
88.30000,-14.71690,-3.98729
88.40000,-14.73383,-3.99301
88.50001,-14.75036,-4.00027
88.60001,-14.76716,-4.00825
88.70001,-14.78356,-4.01571
88.80000,-14.80036,-4.02282
88.90000,-14.81676,-4.02953
89.00001,-14.83370,-4.03888
89.10001,-14.85023,-4.04566
89.20001,-14.86690,-4.05557
89.30000,-14.88383,-4.06303
89.40000,-14.90023,-4.07253
89.50001,-14.91690,-4.08076
89.60001,-14.93343,-4.08895
89.70001,-14.94996,-4.09750
89.80000,-14.96676,-4.10741
89.90000,-14.98383,-4.11786
90.00001,-15.00023,-4.12512
90.10001,-15.01690,-4.13635
90.20001,-15.03370,-4.14411
90.30000,-15.05010,-4.15641
90.34400,-15.05756,-4.16141