File: GFBaking/data/2_13PercentGluten/2_13gluten_Compression.is_comp_RawData/Specimen_RawData_7.csv
Time,Extension,Load
(sec),(mm),(N)
0.00000,0.00000,-0.07267
0.10000,-0.00600,-0.07567
0.20000,-0.02587,-0.09322
0.30000,-0.04573,-0.11351
0.40000,-0.06440,-0.13148
0.50000,-0.08213,-0.14384
0.60000,-0.09907,-0.15405
0.70000,-0.11627,-0.16698
0.80000,-0.13307,-0.17947
0.90000,-0.14987,-0.19224
1.00000,-0.16693,-0.20391
1.10000,-0.18320,-0.21595
1.20000,-0.20013,-0.22453
1.30000,-0.21667,-0.23450
1.40000,-0.23320,-0.24647
1.50000,-0.24973,-0.26051
1.60000,-0.26667,-0.27270
1.70000,-0.28347,-0.28475
1.80000,-0.30000,-0.29554
1.90000,-0.31693,-0.30718
2.00000,-0.33320,-0.32173
2.10000,-0.35013,-0.33410
2.20000,-0.36653,-0.34787
2.30000,-0.38320,-0.35795
2.40000,-0.39987,-0.37243
2.50000,-0.41680,-0.38517
2.60000,-0.43347,-0.39714
2.70000,-0.45000,-0.41200
2.80000,-0.46693,-0.42335
2.90000,-0.48320,-0.43569
3.00000,-0.49987,-0.44762
3.10000,-0.51653,-0.46028
3.20000,-0.53333,-0.47360
3.30000,-0.55027,-0.48416
3.40000,-0.56680,-0.49918
3.50000,-0.58360,-0.51034
3.60000,-0.60027,-0.52324
3.70000,-0.61680,-0.53807
3.80000,-0.63320,-0.55117
3.90000,-0.65000,-0.56521
4.00000,-0.66667,-0.57527
4.10000,-0.68333,-0.59217
4.20000,-0.70026,-0.60478
4.30000,-0.71680,-0.61883
4.40000,-0.73346,-0.63429
4.50000,-0.75000,-0.64666
4.60000,-0.76680,-0.66110
4.70000,-0.78320,-0.67425
4.80000,-0.80013,-0.68876
4.90000,-0.81666,-0.70308
5.00000,-0.83333,-0.71492
5.10000,-0.85026,-0.72973
5.20000,-0.86666,-0.74124
5.30000,-0.88333,-0.75248
5.40000,-0.89973,-0.76790
5.50000,-0.91640,-0.78299
5.60000,-0.93333,-0.79596
5.70000,-0.95026,-0.81217
5.80000,-0.96680,-0.82329
5.90000,-0.98346,-0.83541
6.00000,-1.00026,-0.85087
6.10000,-1.01653,-0.86439
6.20000,-1.03333,-0.88119
6.30000,-1.04986,-0.89462
6.40000,-1.06666,-0.90837
6.50000,-1.08360,-0.92278
6.60000,-1.10013,-0.93848
6.70000,-1.11693,-0.95336
6.80000,-1.13360,-0.96799
6.90000,-1.15026,-0.98227
7.00000,-1.16653,-0.99669
7.10000,-1.18333,-1.01095
7.20000,-1.20000,-1.02550
7.30000,-1.21680,-1.04053
7.40000,-1.23360,-1.05306
7.50000,-1.25026,-1.06825
7.60000,-1.26693,-1.08229
7.70000,-1.28333,-1.09675
7.80000,-1.30000,-1.11110
7.90000,-1.31640,-1.12489
8.00000,-1.33333,-1.13938
8.10000,-1.35000,-1.15400
8.20000,-1.36666,-1.16761
8.30000,-1.38360,-1.18027
8.40000,-1.39986,-1.19622
8.50000,-1.41666,-1.20980
8.60000,-1.43320,-1.22291
8.70000,-1.44986,-1.23705
8.80000,-1.46653,-1.25009
8.90000,-1.48333,-1.26393
9.00000,-1.50013,-1.27851
9.10000,-1.51666,-1.29276
9.20000,-1.53360,-1.30671
9.30000,-1.54986,-1.32010
9.40000,-1.56666,-1.33378
9.50000,-1.58320,-1.34683
9.60000,-1.60013,-1.36169
9.70000,-1.61706,-1.37564
9.80000,-1.63360,-1.38933
9.90000,-1.65013,-1.40200
10.00000,-1.66680,-1.41706
10.10000,-1.68360,-1.42937
10.20000,-1.69986,-1.44374
10.30000,-1.71666,-1.45854
10.40000,-1.73333,-1.47151
10.50000,-1.75000,-1.48389
10.60000,-1.76693,-1.49825
10.70000,-1.78346,-1.51750
10.80000,-1.80000,-1.52679
10.90000,-1.81653,-1.54158
11.00000,-1.83333,-1.55675
11.10000,-1.84960,-1.56627
11.20000,-1.86666,-1.57884
11.30000,-1.88333,-1.59328
11.40000,-1.90000,-1.60374
11.50000,-1.91693,-1.61501
11.60000,-1.93333,-1.62782
11.70000,-1.95000,-1.63902
11.80000,-1.96666,-1.65123
11.90000,-1.98320,-1.66066
12.00000,-1.99986,-1.67405
12.10000,-2.01680,-1.68662
12.20000,-2.03346,-1.69759
12.30000,-2.05013,-1.71024
12.40000,-2.06693,-1.72313
12.50000,-2.08319,-1.73625
12.60000,-2.09999,-1.74672
12.70000,-2.11666,-1.75857
12.80000,-2.13333,-1.77064
12.90000,-2.15026,-1.78263
13.00000,-2.16693,-1.79697
13.10000,-2.18359,-1.80845
13.20000,-2.20026,-1.82038
13.30000,-2.21679,-1.83225
13.40000,-2.23306,-1.84561
13.50000,-2.24999,-1.85639
13.60000,-2.26679,-1.86786
13.70000,-2.28346,-1.87860
13.80000,-2.30039,-1.88860
13.90000,-2.31679,-1.89842
14.00000,-2.33359,-1.91013
14.10000,-2.35013,-1.92133
14.20000,-2.36679,-1.93071
14.30000,-2.38319,-1.93866
14.40000,-2.40013,-1.95077
14.50000,-2.41679,-1.96087
14.60000,-2.43346,-1.97144
14.70000,-2.45039,-1.98198
14.80000,-2.46666,-1.99089
14.90000,-2.48333,-2.00126
15.00000,-2.49986,-2.00982
15.10000,-2.51653,-2.02007
15.20000,-2.53319,-2.03090
15.30000,-2.55013,-2.03992
15.40000,-2.56679,-2.04858
15.50000,-2.58346,-2.05844
15.60000,-2.60026,-2.06467
15.70000,-2.61653,-2.07480
15.80000,-2.63346,-2.08315
15.90000,-2.64999,-2.09218
16.00000,-2.66679,-2.09975
16.10000,-2.68359,-2.10034
16.20000,-2.70013,-2.10091
16.30000,-2.71693,-2.10481
16.40000,-2.73346,-2.10659
16.50000,-2.75026,-2.10675
16.60000,-2.76653,-2.10530
16.70000,-2.78346,-2.10358
16.80000,-2.80013,-2.10556
16.90000,-2.81666,-2.10813
17.00000,-2.83359,-2.10490
17.10000,-2.85013,-2.10185
17.20000,-2.86693,-2.10057
17.30000,-2.88346,-2.10482
17.40000,-2.89999,-2.10249
17.50000,-2.91653,-2.10097
17.60000,-2.93359,-2.10395
17.70000,-2.95026,-2.10754
17.80000,-2.96666,-2.11781
17.90000,-2.98359,-2.13133
18.00000,-2.99999,-2.13514
18.10000,-3.01679,-2.14516
18.20000,-3.03319,-2.15573
18.30000,-3.04986,-2.16494
18.40000,-3.06653,-2.17683
18.50000,-3.08346,-2.18572
18.60000,-3.10013,-2.19558
18.70000,-3.11679,-2.20728
18.80000,-3.13373,-2.21830
18.90000,-3.14986,-2.22597
19.00000,-3.16693,-2.23629
19.10000,-3.18319,-2.24475
19.20000,-3.19999,-2.25541
19.30000,-3.21679,-2.26481
19.40000,-3.23346,-2.27464
19.50000,-3.25026,-2.28262
19.60000,-3.26693,-2.29032
19.70000,-3.28346,-2.29717
19.80000,-3.29986,-2.30581
19.90000,-3.31679,-2.31320
20.00000,-3.33346,-2.31955
20.10000,-3.35013,-2.32924
20.20000,-3.36706,-2.33668
20.30000,-3.38346,-2.34175
20.40000,-3.40013,-2.34769
20.50000,-3.41679,-2.35478
20.60000,-3.43346,-2.36163
20.70000,-3.44986,-2.36879
20.80000,-3.46692,-2.37352
20.90000,-3.48346,-2.37925
21.00000,-3.49999,-2.38514
21.10000,-3.51692,-2.39209
21.20000,-3.53332,-2.39509
21.30000,-3.54999,-2.39899
21.40000,-3.56652,-2.40466
21.50000,-3.58319,-2.41042
21.60000,-3.59999,-2.41729
21.70000,-3.61679,-2.42318
21.80000,-3.63332,-2.42817
21.90000,-3.65012,-2.43122
22.00000,-3.66692,-2.43769
22.10000,-3.68319,-2.44103
22.20000,-3.70012,-2.44498
22.30000,-3.71652,-2.44729
22.40000,-3.73332,-2.45366
22.50000,-3.75012,-2.45605
22.60000,-3.76679,-2.46139
22.70000,-3.78359,-2.46353
22.80000,-3.80026,-2.46617
22.90000,-3.81692,-2.46749
23.00000,-3.83319,-2.47126
23.10000,-3.85012,-2.47414
23.20000,-3.86679,-2.47684
23.30000,-3.88346,-2.48060
23.40000,-3.90026,-2.48282
23.50000,-3.91679,-2.48313
23.60000,-3.93359,-2.48787
23.70000,-3.95012,-2.48801
23.80000,-3.96679,-2.49078
23.90000,-3.98306,-2.49257
24.00000,-4.00012,-2.49590
24.10000,-4.01666,-2.49513
24.20000,-4.03332,-2.49384
24.30000,-4.05039,-2.49681
24.40000,-4.06666,-2.50032
24.50000,-4.08332,-2.50367
24.60000,-4.09986,-2.50959
24.70000,-4.11652,-2.51935
24.80000,-4.13319,-2.51830
24.90000,-4.15012,-2.51887
25.00000,-4.16666,-2.52006
25.10000,-4.18346,-2.52622
25.20000,-4.20026,-2.53015
25.30000,-4.21652,-2.53825
25.40000,-4.23332,-2.54239
25.50000,-4.24986,-2.53937
25.60000,-4.26679,-2.53977
25.70000,-4.28372,-2.54859
25.80000,-4.30012,-2.55408
25.90000,-4.31692,-2.55391
26.00000,-4.33346,-2.55251
26.10000,-4.35026,-2.54989
26.20000,-4.36652,-2.55103
26.30000,-4.38346,-2.55383
26.40000,-4.39999,-2.56029
26.50000,-4.41666,-2.55681
26.60000,-4.43372,-2.55600
26.70000,-4.45026,-2.55517
26.80000,-4.46692,-2.55729
26.90000,-4.48332,-2.55764
27.00000,-4.49999,-2.56170
27.10000,-4.51639,-2.55719
27.20000,-4.53346,-2.55988
27.30000,-4.55012,-2.55599
27.40000,-4.56666,-2.56190
27.50000,-4.58359,-2.56581
27.60000,-4.59999,-2.56604
27.70000,-4.61679,-2.55937
27.80000,-4.63332,-2.56562
27.90000,-4.64986,-2.56327
28.00000,-4.66652,-2.56678
28.10000,-4.68346,-2.57174
28.20000,-4.70012,-2.56912
28.30000,-4.71679,-2.56575
28.40000,-4.73359,-2.57059
28.50000,-4.74986,-2.56856
28.60000,-4.76679,-2.56956
28.70000,-4.78332,-2.57211
28.80000,-4.79999,-2.57387
28.90000,-4.81679,-2.57318
29.00000,-4.83345,-2.57089
29.10000,-4.85025,-2.57750
29.20000,-4.86692,-2.58039
29.30000,-4.88359,-2.57747
29.40000,-4.89985,-2.57645
29.50000,-4.91679,-2.58122
29.60000,-4.93345,-2.58181
29.70000,-4.95025,-2.58051
29.80000,-4.96705,-2.58110
29.90000,-4.98345,-2.58324
30.00000,-5.00012,-2.58218
30.10000,-5.01679,-2.58377
30.20000,-5.03332,-2.58660
30.30000,-5.04985,-2.58886
30.40000,-5.06679,-2.58919
30.50000,-5.08345,-2.58774
30.60000,-5.10012,-2.58917
30.70000,-5.11692,-2.59183
30.80000,-5.13319,-2.58835
30.90000,-5.14999,-2.58950
31.00000,-5.16652,-2.59185
31.10000,-5.18332,-2.59079
31.20000,-5.19999,-2.58923
31.30000,-5.21692,-2.59274
31.40000,-5.23345,-2.59137
31.50000,-5.25012,-2.59504
31.60000,-5.26692,-2.59476
31.70000,-5.28319,-2.59673
31.80000,-5.30012,-2.59841
31.90000,-5.31652,-2.59762
32.00000,-5.33319,-2.59970
32.10000,-5.35012,-2.59925
32.20000,-5.36692,-2.60056
32.30000,-5.38359,-2.59995
32.40000,-5.40012,-2.60069
32.50000,-5.41679,-2.59945
32.60000,-5.43319,-2.60179
32.70000,-5.45012,-2.60025
32.80000,-5.46679,-2.60078
32.90000,-5.48345,-2.60130
33.00000,-5.50039,-2.60305
33.10000,-5.51679,-2.60369
33.20000,-5.53345,-2.60412
33.30000,-5.54985,-2.60548
33.40000,-5.56665,-2.60613
33.50000,-5.58319,-2.60638
33.60000,-5.60025,-2.60736
33.70000,-5.61679,-2.60841
33.80000,-5.63345,-2.60814
33.90000,-5.65039,-2.60998
34.00000,-5.66665,-2.61238
34.10000,-5.68332,-2.61484
34.20000,-5.69985,-2.61489
34.30000,-5.71652,-2.61670
34.40000,-5.73319,-2.61793
34.50000,-5.75012,-2.62017
34.60000,-5.76679,-2.62132
34.70000,-5.78345,-2.62464
34.80000,-5.80025,-2.62615
34.90000,-5.81652,-2.62340
35.00000,-5.83345,-2.62449
35.10000,-5.84985,-2.62932
35.20000,-5.86665,-2.62978
35.30000,-5.88345,-2.62952
35.40000,-5.90025,-2.63317
35.50000,-5.91692,-2.63516
35.60000,-5.93359,-2.63457
35.70000,-5.95025,-2.63673
35.80000,-5.96665,-2.63786
35.90000,-5.98345,-2.64302
36.00000,-6.00012,-2.64014
36.10000,-6.01665,-2.64664
36.20000,-6.03372,-2.64801
36.30000,-6.05025,-2.65010
36.40000,-6.06692,-2.65239
36.50000,-6.08345,-2.65409
36.60000,-6.10012,-2.65921
36.70000,-6.11652,-2.66119
36.80000,-6.13345,-2.66454
36.90000,-6.15012,-2.66617
37.00000,-6.16665,-2.66702
37.10000,-6.18372,-2.67022
37.20000,-6.19998,-2.67281
37.30000,-6.21652,-2.67789
37.40000,-6.23318,-2.67893
37.50000,-6.24985,-2.68423
37.60000,-6.26665,-2.68679
37.70000,-6.28345,-2.69206
37.80000,-6.30012,-2.69352
37.90000,-6.31665,-2.69843
38.00000,-6.33358,-2.69871
38.10000,-6.34985,-2.70221
38.20000,-6.36678,-2.69968
38.30000,-6.38332,-2.70354
38.40000,-6.40012,-2.70456
38.50000,-6.41692,-2.70923
38.60000,-6.43358,-2.71084
38.70000,-6.45025,-2.71324
38.80000,-6.46692,-2.71358
38.90000,-6.48358,-2.71605
39.00000,-6.49998,-2.71620
39.10000,-6.51678,-2.71333
39.20000,-6.53332,-2.71492
39.30000,-6.54998,-2.71402
39.40000,-6.56705,-2.71686
39.50000,-6.58358,-2.72083
39.60000,-6.60025,-2.72629
39.70000,-6.61678,-2.72541
39.80000,-6.63345,-2.72527
39.90000,-6.64985,-2.72342
40.00000,-6.66665,-2.72290
40.10000,-6.68345,-2.72403
40.20000,-6.69998,-2.73027
40.30000,-6.71692,-2.73237
40.40000,-6.73332,-2.73477
40.50000,-6.74998,-2.73788
40.60000,-6.76652,-2.73630
40.70000,-6.78318,-2.73159
40.80000,-6.79998,-2.73179
40.90000,-6.81678,-2.73427
41.00000,-6.83345,-2.73556
41.10000,-6.85012,-2.73871
41.20000,-6.86692,-2.74035
41.30000,-6.88318,-2.73933
41.40000,-6.89998,-2.73858
41.50000,-6.91665,-2.73713
41.60000,-6.93345,-2.74333
41.70000,-6.95038,-2.74726
41.80000,-6.96678,-2.74688
41.90000,-6.98358,-2.74798
42.00000,-7.00025,-2.74457
42.10000,-7.01678,-2.74123
42.20000,-7.03318,-2.74430
42.30000,-7.05012,-2.74822
42.40000,-7.06678,-2.75135
42.50000,-7.08332,-2.75505
42.60000,-7.10038,-2.75781
42.70000,-7.11692,-2.75785
42.80000,-7.13358,-2.75795
42.90000,-7.15025,-2.76266
43.00000,-7.16678,-2.76520
43.10000,-7.18332,-2.76787
43.20000,-7.20012,-2.76750
43.30000,-7.21678,-2.76816
43.40000,-7.23345,-2.77235
43.50000,-7.25038,-2.77097
43.60000,-7.26665,-2.77413
43.70000,-7.28332,-2.77353
43.80000,-7.29998,-2.77303
43.90000,-7.31665,-2.77432
44.00000,-7.33332,-2.77755
44.10000,-7.35025,-2.77839
44.20000,-7.36678,-2.77887
44.30000,-7.38345,-2.77897
44.40000,-7.40038,-2.77851
44.50000,-7.41652,-2.77618
44.60000,-7.43332,-2.77818
44.70000,-7.44985,-2.77914
44.80000,-7.46665,-2.78142
44.90000,-7.48345,-2.78067
45.00000,-7.49998,-2.77999
45.10000,-7.51678,-2.77845
45.20000,-7.53332,-2.77784
45.30000,-7.55011,-2.77757
45.40000,-7.56651,-2.77735
45.50000,-7.58345,-2.77845
45.60000,-7.60011,-2.77684
45.70000,-7.61665,-2.77756
45.80000,-7.63371,-2.77986
45.90000,-7.65025,-2.78134
46.00000,-7.66691,-2.78214
46.10000,-7.68345,-2.78372
46.20000,-7.70011,-2.78491
46.30000,-7.71651,-2.78516
46.40000,-7.73358,-2.78723
46.50000,-7.75011,-2.78830
46.60000,-7.76665,-2.79003
46.70000,-7.78358,-2.78940
46.80000,-7.79985,-2.79121
46.90000,-7.81665,-2.79287
47.00000,-7.83318,-2.79501
47.10000,-7.84998,-2.79748
47.20000,-7.86665,-2.79981
47.30000,-7.88345,-2.80306
47.40000,-7.90011,-2.80431
47.50000,-7.91678,-2.80832
47.60000,-7.93358,-2.81198
47.70000,-7.94985,-2.81526
47.80000,-7.96678,-2.81883
47.90000,-7.98318,-2.82265
48.00000,-8.00011,-2.82715
48.10000,-8.01691,-2.83146
48.20000,-8.03358,-2.83212
48.30000,-8.05011,-2.83590
48.40000,-8.06691,-2.83690
48.50000,-8.08345,-2.84000
48.60000,-8.09985,-2.84249
48.70000,-8.11678,-2.84601
48.80000,-8.13345,-2.84966
48.90000,-8.15011,-2.85184
49.00000,-8.16705,-2.85523
49.10000,-8.18345,-2.85653
49.20000,-8.19998,-2.86216
49.30000,-8.21665,-2.86387
49.40000,-8.23345,-2.86992
49.50000,-8.24985,-2.87263
49.60000,-8.26691,-2.87527
49.70000,-8.28345,-2.87959
49.80000,-8.29998,-2.88055
49.90000,-8.31691,-2.88458
50.00000,-8.33331,-2.88800
50.10000,-8.34998,-2.89128
50.20000,-8.36651,-2.89395
50.30000,-8.38318,-2.89506
50.40000,-8.39985,-2.90216
50.50000,-8.41678,-2.90158
50.60000,-8.43331,-2.90309
50.70000,-8.45011,-2.90781
50.80000,-8.46691,-2.90903
50.90000,-8.48331,-2.90949
51.00000,-8.50011,-2.91080
51.10000,-8.51651,-2.91009
51.20000,-8.53345,-2.90855
51.30000,-8.55025,-2.90910
51.40000,-8.56678,-2.91026
51.50000,-8.58358,-2.91093
51.60000,-8.60025,-2.91060
51.70000,-8.61691,-2.91048
51.80000,-8.63331,-2.91235
51.90000,-8.65011,-2.91069
52.00000,-8.66678,-2.91099
52.10000,-8.68345,-2.91215
52.20000,-8.70038,-2.91302
52.30000,-8.71678,-2.91222
52.40000,-8.73345,-2.91261
52.50000,-8.75011,-2.91260
52.60000,-8.76678,-2.91110
52.70000,-8.78318,-2.91013
52.80000,-8.80024,-2.91098
52.90000,-8.81678,-2.91064
53.00000,-8.83331,-2.91140
53.10000,-8.85024,-2.90947
53.20000,-8.86651,-2.90871
53.30000,-8.88331,-2.90889
53.40000,-8.89998,-2.90693
53.50000,-8.91651,-2.90640
53.60000,-8.93318,-2.90470
53.70000,-8.94998,-2.90405
53.80000,-8.96678,-2.90683
53.90000,-8.98345,-2.90677
54.00000,-9.00024,-2.89526
54.10000,-9.01651,-2.90050
54.20000,-9.03344,-2.89743
54.30000,-9.04984,-2.89976
54.40000,-9.06691,-2.90544
54.50000,-9.08371,-2.90382
54.60000,-9.10024,-2.90507
54.70000,-9.11691,-2.90487
54.80000,-9.13358,-2.90802
54.90000,-9.15024,-2.91022
55.00000,-9.16651,-2.90939
55.10000,-9.18344,-2.91174
55.20000,-9.20011,-2.91354
55.30000,-9.21678,-2.91583
55.40000,-9.23358,-2.91560
55.50000,-9.25011,-2.92180
55.60000,-9.26691,-2.92807
55.70000,-9.28344,-2.92285
55.80000,-9.30011,-2.92352
55.90000,-9.31651,-2.92271
56.00000,-9.33344,-2.92257
56.10000,-9.34998,-2.92031
56.20000,-9.36664,-2.92515
56.30000,-9.38358,-2.92643
56.40000,-9.39998,-2.92369
56.50000,-9.41678,-2.92552
56.60000,-9.43331,-2.92609
56.70000,-9.44984,-2.92835
56.80000,-9.46664,-2.93043
56.90000,-9.48358,-2.93460
57.00000,-9.50011,-2.93606
57.10000,-9.51678,-2.93850
57.20000,-9.53344,-2.93833
57.30000,-9.54984,-2.94111
57.40000,-9.56691,-2.94486
57.50000,-9.58331,-2.94705
57.60000,-9.60011,-2.94987
57.70000,-9.61691,-2.95236
57.80000,-9.63358,-2.95572
57.90000,-9.65024,-2.95887
58.00000,-9.66678,-2.95997
58.10000,-9.68358,-2.96317
58.20000,-9.69984,-2.96638
58.30000,-9.71678,-2.96968
58.40000,-9.73331,-2.97217
58.50000,-9.75011,-2.97659
58.60000,-9.76691,-2.97833
58.70000,-9.78344,-2.97964
58.80000,-9.80011,-2.98439
58.90000,-9.81678,-2.98643
59.00000,-9.83358,-2.98941
59.10000,-9.84984,-2.99166
59.20000,-9.86691,-2.99510
59.30000,-9.88344,-2.99989
59.40000,-9.89998,-3.00194
59.50000,-9.91704,-3.00344
59.60000,-9.93331,-3.00650
59.70000,-9.94998,-3.00789
59.80000,-9.96651,-3.00963
59.90000,-9.98318,-3.01183
60.00000,-9.99984,-3.01626
60.10000,-10.01678,-3.01836
60.20000,-10.03344,-3.01837
60.30000,-10.05011,-3.02277
60.40000,-10.06691,-3.02402
60.50000,-10.08331,-3.02545
60.60000,-10.10011,-3.03006
60.70000,-10.11651,-3.03424
60.80000,-10.13344,-3.03664
60.90000,-10.15024,-3.03895
61.00000,-10.16664,-3.04209
61.10000,-10.18331,-3.04415
61.20000,-10.19998,-3.04840
61.30000,-10.21678,-3.05035
61.40000,-10.23331,-3.05476
61.50000,-10.25011,-3.05963
61.60000,-10.26664,-3.06067
61.70000,-10.28331,-3.06570
61.80000,-10.30011,-3.06749
61.90000,-10.31691,-3.07094
62.00000,-10.33358,-3.07348
62.10000,-10.34997,-3.07665
62.20000,-10.36678,-3.07884
62.30000,-10.38317,-3.08410
62.40000,-10.40024,-3.08727
62.50000,-10.41678,-3.08830
62.60000,-10.43344,-3.09142
62.70000,-10.45024,-3.09279
62.80000,-10.46664,-3.09471
62.90000,-10.48344,-3.09864
63.00000,-10.49997,-3.10179
63.10000,-10.51651,-3.10419
63.20000,-10.53317,-3.10800
63.30000,-10.55024,-3.11109
63.40000,-10.56677,-3.11262
63.50000,-10.58344,-3.11620
63.60000,-10.60024,-3.11786
63.70000,-10.61664,-3.12012
63.80000,-10.63331,-3.12385
63.90000,-10.64984,-3.12473
64.00000,-10.66677,-3.12797
64.10001,-10.68357,-3.13003
64.20000,-10.70024,-3.13251
64.30000,-10.71677,-3.13400
64.40000,-10.73344,-3.13668
64.50000,-10.75024,-3.13721
64.60001,-10.76664,-3.13919
64.70000,-10.78344,-3.14052
64.80000,-10.80011,-3.14104
64.90000,-10.81664,-3.14181
65.00000,-10.83371,-3.14110
65.10001,-10.85011,-3.14154
65.20000,-10.86691,-3.14317
65.30000,-10.88344,-3.14344
65.40000,-10.90024,-3.14519
65.50000,-10.91664,-3.14633
65.60001,-10.93344,-3.14747
65.70001,-10.94997,-3.14529
65.80000,-10.96664,-3.14866
65.90000,-10.98371,-3.15005
66.00000,-10.99997,-3.15218
66.10001,-11.01664,-3.15325
66.20001,-11.03317,-3.15581
66.30000,-11.04997,-3.15789
66.40000,-11.06664,-3.15941
66.50000,-11.08344,-3.16167
66.60001,-11.09997,-3.16425
66.70001,-11.11677,-3.16716
66.80000,-11.13357,-3.16825
66.90000,-11.14984,-3.17173
67.00000,-11.16677,-3.17197
67.10001,-11.18331,-3.17154
67.20001,-11.19997,-3.17205
67.30000,-11.21691,-3.17429
67.40000,-11.23344,-3.17408
67.50000,-11.25024,-3.17487
67.60001,-11.26691,-3.17557
67.70001,-11.28371,-3.17316
67.80000,-11.29984,-3.17107
67.90000,-11.31677,-3.17207
68.00000,-11.33344,-3.17375
68.10001,-11.35011,-3.17261
68.20001,-11.36704,-3.17354
68.30000,-11.38344,-3.17629
68.40000,-11.40024,-3.17823
68.50000,-11.41677,-3.17742
68.60001,-11.43357,-3.17744
68.70001,-11.44984,-3.17508
68.80000,-11.46677,-3.17328
68.90000,-11.48331,-3.17612
69.00000,-11.49997,-3.17905
69.10001,-11.51691,-3.17995
69.20001,-11.53331,-3.18266
69.30000,-11.54997,-3.18435
69.40000,-11.56664,-3.18576
69.50000,-11.58330,-3.18478
69.60001,-11.59984,-3.18554
69.70001,-11.61691,-3.18000
69.80000,-11.63344,-3.18165
69.90000,-11.65011,-3.18444
70.00000,-11.66691,-3.18781
70.10001,-11.68330,-3.19215
70.20001,-11.70010,-3.19644
70.30000,-11.71650,-3.19487
70.40000,-11.73344,-3.19728
70.50000,-11.75024,-3.19843
70.60001,-11.76677,-3.20148
70.70001,-11.78357,-3.20501
70.80000,-11.80024,-3.20721
70.90000,-11.81690,-3.20889
71.00000,-11.83317,-3.20513
71.10001,-11.84997,-3.20829
71.20001,-11.86677,-3.20804
71.30000,-11.88344,-3.21219
71.40000,-11.90037,-3.21789
71.50000,-11.91677,-3.21875
71.60001,-11.93357,-3.21959
71.70001,-11.95010,-3.21711
71.80000,-11.96677,-3.21643
71.90000,-11.98317,-3.21432
72.00000,-12.00010,-3.21979
72.10001,-12.01677,-3.22148
72.20001,-12.03344,-3.22653
72.30000,-12.05024,-3.22945
72.40000,-12.06664,-3.23174
72.50000,-12.08330,-3.23415
72.60001,-12.09984,-3.23683
72.70001,-12.11650,-3.23871
72.80000,-12.13317,-3.24036
72.90000,-12.15010,-3.24424
73.00000,-12.16677,-3.24647
73.10001,-12.18330,-3.25064
73.20001,-12.20024,-3.25272
73.30000,-12.21664,-3.25451
73.40000,-12.23344,-3.25842
73.50000,-12.24997,-3.25924
73.60001,-12.26664,-3.26358
73.70001,-12.28357,-3.26789
73.80000,-12.30024,-3.26924
73.90000,-12.31690,-3.27278
74.00000,-12.33357,-3.27658
74.10001,-12.35024,-3.27893
74.20001,-12.36664,-3.28118
74.30000,-12.38344,-3.28513
74.40000,-12.40010,-3.28720
74.50000,-12.41677,-3.29015
74.60001,-12.43357,-3.29414
74.70001,-12.45010,-3.29781
74.80000,-12.46677,-3.30070
74.90000,-12.48344,-3.30412
75.00000,-12.50010,-3.30669
75.10001,-12.51650,-3.30855
75.20001,-12.53344,-3.31346
75.30000,-12.55010,-3.31549
75.40000,-12.56664,-3.31954
75.50000,-12.58357,-3.32215
75.60001,-12.59984,-3.32629
75.70001,-12.61664,-3.33022
75.80000,-12.63330,-3.33333
75.90000,-12.64997,-3.33641
76.00000,-12.66664,-3.34088
76.10001,-12.68344,-3.34581
76.20001,-12.69997,-3.34798
76.30000,-12.71677,-3.35144
76.40000,-12.73357,-3.35457
76.50000,-12.74984,-3.35625
76.60001,-12.76677,-3.36004
76.70001,-12.78317,-3.36242
76.80000,-12.80010,-3.36614
76.90000,-12.81690,-3.36875
77.00000,-12.83357,-3.37281
77.10001,-12.85010,-3.37555
77.20001,-12.86690,-3.37837
77.30000,-12.88370,-3.38183
77.40000,-12.89997,-3.38268
77.50000,-12.91677,-3.38840
77.60001,-12.93343,-3.39087
77.70001,-12.95010,-3.39315
77.80000,-12.96704,-3.39758
77.90000,-12.98357,-3.39779
78.00000,-13.00023,-3.39936
78.10001,-13.01677,-3.40425
78.20001,-13.03343,-3.40526
78.30000,-13.04983,-3.41024
78.40000,-13.06677,-3.41876
78.50000,-13.08330,-3.41957
78.60001,-13.09997,-3.42354
78.70001,-13.11690,-3.42917
78.80000,-13.13330,-3.43240
78.90000,-13.14997,-3.43933
79.00000,-13.16650,-3.44172
79.10001,-13.18303,-3.44078
79.20001,-13.19983,-3.44710
79.30000,-13.21677,-3.45209
79.40000,-13.23330,-3.45402
79.50000,-13.24997,-3.45941
79.60001,-13.26690,-3.46130
79.70001,-13.28317,-3.46082
79.80000,-13.30010,-3.46852
79.90000,-13.31650,-3.47501
80.00000,-13.33343,-3.48172
80.10001,-13.35023,-3.48743
80.20001,-13.36690,-3.49019
80.30000,-13.38357,-3.49797
80.40000,-13.40023,-3.50603
80.50001,-13.41703,-3.50749
80.60001,-13.43330,-3.51265
80.70001,-13.45010,-3.51621
80.80000,-13.46677,-3.51922
80.90000,-13.48343,-3.53033
81.00001,-13.50023,-3.53287
81.10001,-13.51663,-3.53306
81.20001,-13.53357,-3.53641
81.30000,-13.55010,-3.53590
81.40000,-13.56677,-3.53963
81.50001,-13.58317,-3.54917
81.60001,-13.59997,-3.55614
81.70001,-13.61663,-3.56308
81.80000,-13.63330,-3.57416
81.90000,-13.65023,-3.57767
82.00001,-13.66663,-3.58363
82.10001,-13.68330,-3.59400
82.20001,-13.69997,-3.60201
82.30000,-13.71650,-3.60807
82.40000,-13.73317,-3.60961
82.50001,-13.75023,-3.61457
82.60001,-13.76663,-3.62275
82.70001,-13.78343,-3.63348
82.80000,-13.80023,-3.64350
82.90000,-13.81650,-3.65214
83.00001,-13.83343,-3.66037
83.10001,-13.84997,-3.66607
83.20001,-13.86677,-3.67586
83.30000,-13.88357,-3.68360
83.40000,-13.90010,-3.69171
83.50001,-13.91690,-3.69923
83.60001,-13.93357,-3.70751
83.70001,-13.95010,-3.71318
83.80000,-13.96650,-3.72023
83.90000,-13.98330,-3.72768
84.00001,-14.00010,-3.73303
84.10001,-14.01677,-3.74252
84.20001,-14.03370,-3.74976
84.30000,-14.05010,-3.75700
84.40000,-14.06690,-3.76422
84.50001,-14.08330,-3.77049
84.60001,-14.10010,-3.77923
84.70001,-14.11650,-3.78687
84.80000,-14.13343,-3.79653
84.90000,-14.15010,-3.80254
85.00001,-14.16663,-3.81134
85.10001,-14.18343,-3.81778
85.20001,-14.19997,-3.82475
85.30000,-14.21676,-3.83456
85.40000,-14.23317,-3.84276
85.50001,-14.24983,-3.84886
85.60001,-14.26650,-3.85692
85.70001,-14.28343,-3.86817
85.80000,-14.30010,-3.87647
85.90000,-14.31676,-3.88752
86.00001,-14.33370,-3.89594
86.10001,-14.34983,-3.90349
86.20001,-14.36676,-3.91475
86.30000,-14.38317,-3.92245
86.40000,-14.39996,-3.93314
86.50001,-14.41676,-3.94463
86.60001,-14.43343,-3.95004
86.70001,-14.45023,-3.95867
86.80000,-14.46690,-3.96470
86.90000,-14.48356,-3.97281
87.00001,-14.49983,-3.97903
87.10001,-14.51676,-3.98332
87.20001,-14.53343,-3.99281
87.30000,-14.55010,-4.00479
87.40000,-14.56690,-4.01360
87.50001,-14.58330,-4.02622
87.60001,-14.60023,-4.03399
87.70001,-14.61676,-4.03579
87.80000,-14.63343,-4.04901
87.90000,-14.64983,-4.06439
88.00001,-14.66676,-4.07675
88.10001,-14.68330,-4.08831
88.20001,-14.70010,-4.09823
88.30000,-14.71690,-4.10047
88.40000,-14.73343,-4.11114
88.50001,-14.75010,-4.12445
88.60001,-14.76663,-4.13514
88.70001,-14.78316,-4.14624
88.80000,-14.79996,-4.15450
88.90000,-14.81690,-4.16149
89.00001,-14.83330,-4.17091
89.10001,-14.84996,-4.18602
89.20001,-14.86690,-4.19617
89.30000,-14.88330,-4.20942
89.40000,-14.90023,-4.22113
89.50001,-14.91650,-4.22836
89.60001,-14.93330,-4.23640
89.70001,-14.95010,-4.24984
89.80000,-14.96690,-4.26030
89.90000,-14.98343,-4.26907
90.00001,-15.00010,-4.28323
90.10001,-15.01690,-4.29499
90.15801,-15.02650,-4.29708