File: GFBaking/data/3TspPectin/3TspPectin.is_comp_RawData/Specimen_RawData_1.csv
Time,Extension,Load
(sec),(mm),(N)
0.00000,-0.00027,0.00289
0.10000,-0.00653,0.00221
0.20000,-0.02627,0.00154
0.30000,-0.04627,0.00032
0.40000,-0.06453,-0.00012
0.50000,-0.08213,-0.00197
0.60000,-0.09933,-0.00138
0.70000,-0.11627,-0.00198
0.80000,-0.13320,-0.00255
0.90000,-0.15000,-0.00697
1.00000,-0.16680,-0.00475
1.10000,-0.18333,-0.00591
1.20000,-0.20013,-0.00635
1.30000,-0.21667,-0.00824
1.40000,-0.23320,-0.00960
1.50000,-0.25027,-0.01121
1.60000,-0.26667,-0.01375
1.70000,-0.28360,-0.01540
1.80000,-0.30027,-0.01660
1.90000,-0.31693,-0.02046
2.00000,-0.33333,-0.02337
2.10000,-0.35027,-0.02569
2.20000,-0.36693,-0.02913
2.30000,-0.38333,-0.03035
2.40000,-0.40040,-0.03423
2.50000,-0.41680,-0.03502
2.60000,-0.43347,-0.03940
2.70000,-0.45013,-0.04144
2.80000,-0.46693,-0.04937
2.90000,-0.48347,-0.04900
3.00000,-0.50013,-0.05432
3.10000,-0.51680,-0.05956
3.20000,-0.53333,-0.06173
3.30000,-0.55040,-0.06522
3.40000,-0.56667,-0.07046
3.50000,-0.58360,-0.07621
3.60000,-0.60027,-0.07986
3.70000,-0.61667,-0.08503
3.80000,-0.63347,-0.09320
3.90000,-0.65000,-0.09985
4.00000,-0.66680,-0.10407
4.10000,-0.68346,-0.11186
4.20000,-0.70026,-0.11781
4.30000,-0.71680,-0.12494
4.40000,-0.73346,-0.13458
4.50000,-0.75013,-0.13877
4.60000,-0.76666,-0.15460
4.70000,-0.78360,-0.15909
4.80000,-0.80013,-0.17157
4.90000,-0.81693,-0.17900
5.00000,-0.83360,-0.18801
5.10000,-0.85040,-0.20007
5.20000,-0.86666,-0.21079
5.30000,-0.88360,-0.22008
5.40000,-0.90013,-0.23039
5.50000,-0.91653,-0.24063
5.60000,-0.93373,-0.25332
5.70000,-0.95013,-0.26572
5.80000,-0.96693,-0.27608
5.90000,-0.98373,-0.28643
6.00000,-1.00000,-0.29846
6.10000,-1.01680,-0.31001
6.20000,-1.03346,-0.32301
6.30000,-1.05013,-0.33574
6.40000,-1.06666,-0.34925
6.50000,-1.08373,-0.36109
6.60000,-1.10013,-0.37128
6.70000,-1.11693,-0.38577
6.80000,-1.13346,-0.39839
6.90000,-1.15000,-0.41078
7.00000,-1.16666,-0.42478
7.10000,-1.18333,-0.43790
7.20000,-1.20026,-0.45133
7.30000,-1.21680,-0.46677
7.40000,-1.23373,-0.48170
7.50000,-1.25013,-0.49659
7.60000,-1.26693,-0.51445
7.70000,-1.28346,-0.53023
7.80000,-1.30000,-0.54955
7.90000,-1.31693,-0.56814
8.00000,-1.33346,-0.58483
8.10000,-1.35026,-0.60422
8.20000,-1.36706,-0.62242
8.30000,-1.38373,-0.64100
8.40000,-1.40000,-0.66059
8.50000,-1.41680,-0.68198
8.60000,-1.43346,-0.69909
8.70000,-1.45000,-0.72042
8.80000,-1.46706,-0.73833
8.90000,-1.48360,-0.75858
9.00000,-1.50013,-0.77776
9.10000,-1.51680,-0.79823
9.20000,-1.53346,-0.81833
9.30000,-1.55013,-0.84006
9.40000,-1.56680,-0.86251
9.50000,-1.58346,-0.88160
9.60000,-1.60000,-0.90326
9.70000,-1.61706,-0.92502
9.80000,-1.63346,-0.94546
9.90000,-1.65013,-0.96791
10.00000,-1.66666,-0.98872
10.10000,-1.68333,-1.01032
10.20000,-1.70013,-1.03381
10.30000,-1.71666,-1.05480
10.40000,-1.73360,-1.07919
10.50000,-1.75013,-1.10224
10.60000,-1.76693,-1.12485
10.70000,-1.78346,-1.14722
10.80000,-1.80026,-1.17061
10.90000,-1.81680,-1.19277
11.00000,-1.83333,-1.21595
11.10000,-1.85026,-1.23959
11.20000,-1.86680,-1.26290
11.30000,-1.88360,-1.28503
11.40000,-1.90026,-1.30964
11.50000,-1.91693,-1.33284
11.60000,-1.93346,-1.35869
11.70000,-1.95026,-1.38322
11.80000,-1.96693,-1.40752
11.90000,-1.98333,-1.43187
12.00000,-2.00040,-1.45652
12.10000,-2.01680,-1.48081
12.20000,-2.03359,-1.50465
12.30000,-2.05040,-1.53019
12.40000,-2.06693,-1.55390
12.50000,-2.08346,-1.57738
12.60000,-2.10013,-1.60092
12.70000,-2.11679,-1.62635
12.80000,-2.13346,-1.65249
12.90000,-2.15039,-1.67601
13.00000,-2.16666,-1.69822
13.10000,-2.18346,-1.72452
13.20000,-2.20013,-1.74817
13.30000,-2.21679,-1.77164
13.40000,-2.23333,-1.79167
13.50000,-2.24999,-1.80955
13.60000,-2.26679,-1.82085
13.70000,-2.28346,-1.83069
13.80000,-2.30039,-1.83430
13.90000,-2.31666,-1.84213
14.00000,-2.33346,-1.85988
14.10000,-2.35013,-1.86879
14.20000,-2.36666,-1.89208
14.30000,-2.38359,-1.91063
14.40000,-2.40013,-1.92761
14.50000,-2.41706,-1.95560
14.60000,-2.43359,-1.98570
14.70000,-2.45039,-2.01286
14.80000,-2.46666,-2.03899
14.90000,-2.48359,-2.06884
15.00000,-2.50013,-2.09661
15.10000,-2.51666,-2.12417
15.20000,-2.53373,-2.14560
15.30000,-2.54999,-2.14182
15.40000,-2.56693,-2.16038
15.50000,-2.58359,-2.17878
15.60000,-2.60013,-2.19163
15.70000,-2.61679,-2.21051
15.80000,-2.63346,-2.23736
15.90000,-2.65013,-2.26012
16.00000,-2.66666,-2.28597
16.10000,-2.68373,-2.30982
16.20000,-2.69999,-2.33177
16.30000,-2.71679,-2.35692
16.40000,-2.73346,-2.37897
16.50000,-2.74999,-2.40227
16.60000,-2.76679,-2.42732
16.70000,-2.78333,-2.45380
16.80000,-2.80026,-2.47915
16.90000,-2.81679,-2.50444
17.00000,-2.83359,-2.52860
17.10000,-2.85013,-2.55037
17.20000,-2.86693,-2.57415
17.30000,-2.88346,-2.59694
17.40000,-2.89986,-2.62031
17.50000,-2.91693,-2.64410
17.60000,-2.93346,-2.66950
17.70000,-2.95039,-2.69552
17.80000,-2.96693,-2.72174
17.90000,-2.98359,-2.74590
18.00000,-2.99999,-2.76947
18.10000,-3.01679,-2.79435
18.20000,-3.03359,-2.81743
18.30000,-3.04999,-2.84169
18.40000,-3.06706,-2.86673
18.50000,-3.08333,-2.89073
18.60000,-3.10026,-2.91437
18.70000,-3.11706,-2.93852
18.80000,-3.13359,-2.96096
18.90000,-3.15013,-2.98533
19.00000,-3.16679,-3.00843
19.10000,-3.18359,-3.02982
19.20000,-3.20013,-3.05442
19.30000,-3.21706,-3.07612
19.40000,-3.23346,-3.09927
19.50000,-3.25026,-3.12254
19.60000,-3.26679,-3.14299
19.70000,-3.28346,-3.16592
19.80000,-3.30013,-3.18760
19.90000,-3.31666,-3.20931
20.00000,-3.33346,-3.23140
20.10000,-3.35013,-3.25484
20.20000,-3.36706,-3.27556
20.30000,-3.38333,-3.29651
20.40000,-3.40013,-3.31849
20.50000,-3.41679,-3.33892
20.60000,-3.43332,-3.35916
20.70000,-3.45026,-3.37948
20.80000,-3.46692,-3.40141
20.90000,-3.48359,-3.41927
21.00000,-3.50026,-3.44049
21.10000,-3.51692,-3.45921
21.20000,-3.53346,-3.47904
21.30000,-3.55026,-3.49865
21.40000,-3.56679,-3.51782
21.50000,-3.58332,-3.53677
21.60000,-3.60039,-3.55753
21.70000,-3.61679,-3.57690
21.80000,-3.63359,-3.59743
21.90000,-3.65026,-3.61635
22.00000,-3.66666,-3.63400
22.10000,-3.68332,-3.65208
22.20000,-3.70012,-3.67122
22.30000,-3.71692,-3.68906
22.40000,-3.73332,-3.70811
22.50000,-3.75039,-3.72615
22.60000,-3.76679,-3.74363
22.70000,-3.78359,-3.76315
22.80000,-3.80012,-3.77952
22.90000,-3.81679,-3.79693
23.00000,-3.83332,-3.81228
23.10000,-3.84999,-3.83146
23.20000,-3.86692,-3.84838
23.30000,-3.88346,-3.86760
23.40000,-3.90026,-3.88368
23.50000,-3.91666,-3.90165
23.60000,-3.93359,-3.91931
23.70000,-3.95012,-3.93303
23.80000,-3.96666,-3.94892
23.90000,-3.98346,-3.96509
24.00000,-4.00012,-3.98098
24.10000,-4.01692,-3.99806
24.20000,-4.03359,-4.01346
24.30000,-4.05039,-4.02797
24.40000,-4.06679,-4.04234
24.50000,-4.08359,-4.05656
24.60000,-4.10026,-4.06978
24.70000,-4.11666,-4.08598
24.80000,-4.13372,-4.10101
24.90000,-4.15012,-4.11412
25.00000,-4.16692,-4.12864
25.10000,-4.18359,-4.14089
25.20000,-4.20026,-4.15460
25.30000,-4.21679,-4.16678
25.40000,-4.23332,-4.17902
25.50000,-4.25012,-4.19005
25.60000,-4.26679,-4.20319
25.70000,-4.28372,-4.21260
25.80000,-4.30012,-4.22245
25.90000,-4.31679,-4.23328
26.00000,-4.33319,-4.24210
26.10000,-4.34999,-4.25486
26.20000,-4.36679,-4.26621
26.30000,-4.38346,-4.27878
26.40000,-4.40026,-4.28878
26.50000,-4.41692,-4.30199
26.60000,-4.43372,-4.31310
26.70000,-4.45012,-4.32566
26.80000,-4.46692,-4.33505
26.90000,-4.48346,-4.34609
27.00000,-4.49999,-4.35736
27.10000,-4.51679,-4.37058
27.20000,-4.53332,-4.38092
27.30000,-4.55012,-4.39042
27.40000,-4.56692,-4.40088
27.50000,-4.58359,-4.41052
27.60000,-4.60012,-4.42052
27.70000,-4.61692,-4.43153
27.80000,-4.63359,-4.43890
27.90000,-4.64999,-4.44525
28.00000,-4.66719,-4.45494
28.10000,-4.68346,-4.46229
28.20000,-4.70026,-4.47114
28.30000,-4.71692,-4.47851
28.40000,-4.73359,-4.48662
28.50000,-4.75012,-4.48767
28.60000,-4.76679,-4.49812
28.70000,-4.78346,-4.50582
28.80000,-4.79999,-4.51014
28.90000,-4.81706,-4.51382
29.00000,-4.83345,-4.52194
29.10000,-4.85025,-4.52850
29.20000,-4.86679,-4.53146
29.30000,-4.88332,-4.53889
29.40000,-4.89999,-4.54757
29.50000,-4.91652,-4.54613
29.60000,-4.93345,-4.55022
29.70000,-4.95012,-4.56619
29.80000,-4.96705,-4.57171
29.90000,-4.98332,-4.57388
30.00000,-5.00025,-4.58095
30.10000,-5.01679,-4.58314
30.20000,-5.03345,-4.59391
30.30000,-5.05025,-4.59891
30.40000,-5.06665,-4.60158
30.50000,-5.08359,-4.60680
30.60000,-5.10025,-4.61005
30.70000,-5.11705,-4.61407
30.80000,-5.13345,-4.62069
30.90000,-5.15025,-4.62704
31.00000,-5.16692,-4.63013
31.10000,-5.18319,-4.62773
31.20000,-5.20039,-4.63442
31.30000,-5.21679,-4.63656
31.40000,-5.23359,-4.64380
31.50000,-5.25025,-4.64457
31.60000,-5.26692,-4.64804
31.70000,-5.28332,-4.65192
31.80000,-5.30012,-4.65760
31.90000,-5.31679,-4.65608
32.00000,-5.33332,-4.66488
32.10000,-5.35025,-4.66837
32.20000,-5.36679,-4.66743
32.30000,-5.38345,-4.66873
32.40000,-5.40012,-4.67229
32.50000,-5.41679,-4.67528
32.60000,-5.43345,-4.67889
32.70000,-5.44999,-4.68197
32.80000,-5.46679,-4.68690
32.90000,-5.48345,-4.69167
33.00000,-5.50025,-4.69434
33.10000,-5.51679,-4.69808
33.20000,-5.53359,-4.70493
33.30000,-5.55012,-4.70666
33.40000,-5.56665,-4.70811
33.50000,-5.58345,-4.71422
33.60000,-5.60012,-4.71677
33.70000,-5.61692,-4.72254
33.80000,-5.63359,-4.72630
33.90000,-5.65025,-4.72881
34.00000,-5.66692,-4.73219
34.10000,-5.68372,-4.73766
34.20000,-5.70025,-4.74018
34.30000,-5.71665,-4.74408
34.40000,-5.73359,-4.75114
34.50000,-5.75012,-4.75454
34.60000,-5.76692,-4.75955
34.70000,-5.78372,-4.76479
34.80000,-5.80012,-4.77014
34.90000,-5.81679,-4.77298
35.00000,-5.83332,-4.77839
35.10000,-5.85012,-4.78244
35.20000,-5.86679,-4.78798
35.30000,-5.88372,-4.79357
35.40000,-5.90012,-4.79574
35.50000,-5.91692,-4.80230
35.60000,-5.93345,-4.80312
35.70000,-5.95012,-4.80854
35.80000,-5.96679,-4.81269
35.90000,-5.98332,-4.81511
36.00000,-6.00025,-4.82179
36.10000,-6.01679,-4.82767
36.20000,-6.03372,-4.83231
36.30000,-6.05012,-4.83623
36.40000,-6.06679,-4.84295
36.50000,-6.08345,-4.85021
36.60000,-6.09998,-4.85438
36.70000,-6.11679,-4.85863
36.80000,-6.13332,-4.86474
36.90000,-6.15038,-4.86918
37.00000,-6.16705,-4.87297
37.10000,-6.18359,-4.87612
37.20000,-6.20012,-4.87794
37.30000,-6.21692,-4.88134
37.40000,-6.23345,-4.88341
37.50000,-6.24985,-4.88758
37.60000,-6.26705,-4.89227
37.70000,-6.28345,-4.89534
37.80000,-6.30025,-4.89842
37.90000,-6.31692,-4.90284
38.00000,-6.33358,-4.90628
38.10000,-6.35012,-4.90992
38.20000,-6.36692,-4.91499
38.30000,-6.38345,-4.91721
38.40000,-6.39998,-4.92348
38.50000,-6.41705,-4.92753
38.60000,-6.43345,-4.93263
38.70000,-6.45025,-4.94112
38.80000,-6.46678,-4.94460
38.90000,-6.48332,-4.94970
39.00000,-6.49998,-4.95856
39.10000,-6.51665,-4.96286
39.20000,-6.53345,-4.96747
39.30000,-6.55012,-4.97301
39.40000,-6.56692,-4.98259
39.50000,-6.58332,-4.98925
39.60000,-6.60025,-4.99707
39.70000,-6.61678,-5.00062
39.80000,-6.63332,-5.00719
39.90000,-6.65025,-5.01346
40.00000,-6.66678,-5.02275
40.10000,-6.68358,-5.03068
40.20000,-6.70025,-5.03654
40.30000,-6.71692,-5.04273
40.40000,-6.73345,-5.04931
40.50000,-6.75012,-5.05600
40.60000,-6.76692,-5.06190
40.70000,-6.78345,-5.07160
40.80000,-6.80038,-5.08062
40.90000,-6.81665,-5.08891
41.00000,-6.83358,-5.09672
41.10000,-6.85038,-5.10077
41.20000,-6.86692,-5.10990
41.30000,-6.88345,-5.11763
41.40000,-6.89998,-5.12535
41.50000,-6.91678,-5.13255
41.60000,-6.93332,-5.14123
41.70000,-6.95038,-5.14897
41.80000,-6.96665,-5.15767
41.90000,-6.98345,-5.16756
42.00000,-7.00025,-5.17687
42.10000,-7.01678,-5.18237
42.20000,-7.03345,-5.18999
42.30000,-7.05012,-5.19821
42.40000,-7.06692,-5.20747
42.50000,-7.08345,-5.22023
42.60000,-7.10025,-5.22645
42.70000,-7.11665,-5.23445
42.80000,-7.13358,-5.24780
42.90000,-7.15012,-5.25340
43.00000,-7.16665,-5.26167
43.10000,-7.18358,-5.27077
43.20000,-7.19998,-5.27784
43.30000,-7.21692,-5.28403
43.40000,-7.23358,-5.29648
43.50000,-7.25025,-5.30519
43.60000,-7.26665,-5.31195
43.70000,-7.28358,-5.32058
43.80000,-7.30025,-5.32783
43.90000,-7.31665,-5.33562
44.00000,-7.33372,-5.34579
44.10000,-7.35012,-5.35406
44.20000,-7.36678,-5.36163
44.30000,-7.38372,-5.36812
44.40000,-7.40025,-5.37454
44.50000,-7.41692,-5.38149
44.60000,-7.43358,-5.38748
44.70000,-7.45025,-5.39474
44.80000,-7.46678,-5.40254
44.90000,-7.48372,-5.41044
45.00000,-7.50011,-5.41527
45.10000,-7.51678,-5.42337
45.20000,-7.53332,-5.43029
45.30000,-7.54998,-5.43771
45.40000,-7.56678,-5.44478
45.50000,-7.58332,-5.45384
45.60000,-7.60011,-5.46188
45.70000,-7.61678,-5.46733
45.80000,-7.63358,-5.47715
45.90000,-7.65011,-5.48436
46.00000,-7.66691,-5.49248
46.10000,-7.68345,-5.49645
46.20000,-7.69985,-5.50226
46.30000,-7.71691,-5.51014
46.40000,-7.73345,-5.51801
46.50000,-7.75025,-5.52772
46.60000,-7.76691,-5.53497
46.70000,-7.78371,-5.54349
46.80000,-7.80011,-5.55052
46.90000,-7.81705,-5.55843
47.00000,-7.83358,-5.56507
47.10000,-7.84998,-5.57360
47.20000,-7.86705,-5.58292
47.30000,-7.88345,-5.59117
47.40000,-7.90025,-5.59874
47.50000,-7.91705,-5.60672
47.60000,-7.93358,-5.61506
47.70000,-7.95011,-5.62471
47.80000,-7.96691,-5.63266
47.90000,-7.98358,-5.63851
48.00000,-8.00011,-5.64723
48.10000,-8.01705,-5.65581
48.20000,-8.03345,-5.66222
48.30000,-8.05025,-5.67115
48.40000,-8.06678,-5.67540
48.50000,-8.08331,-5.68328
48.60000,-8.10011,-5.69189
48.70000,-8.11665,-5.69841
48.80000,-8.13345,-5.70606
48.90000,-8.15011,-5.71572
49.00000,-8.16691,-5.72342
49.10000,-8.18345,-5.72946
49.20000,-8.20025,-5.74134
49.30000,-8.21678,-5.74461
49.40000,-8.23318,-5.75311
49.50000,-8.25025,-5.76127
49.60000,-8.26678,-5.76932
49.70000,-8.28358,-5.77907
49.80000,-8.30025,-5.78651
49.90000,-8.31691,-5.79573
50.00000,-8.33345,-5.80220
50.10000,-8.35011,-5.81063
50.20000,-8.36678,-5.81759
50.30000,-8.38331,-5.82691
50.40000,-8.40038,-5.83692
50.50000,-8.41691,-5.84667
50.60000,-8.43358,-5.85498
50.70000,-8.45038,-5.86163
50.80000,-8.46678,-5.86948
50.90000,-8.48331,-5.87903
51.00000,-8.50011,-5.89101
51.10000,-8.51678,-5.89830
51.20000,-8.53345,-5.90866
51.30000,-8.55038,-5.92157
51.40000,-8.56678,-5.93048
51.50000,-8.58358,-5.94177
51.60000,-8.60011,-5.95048
51.70000,-8.61665,-5.96207
51.80000,-8.63345,-5.97197
51.90000,-8.64998,-5.97967
52.00000,-8.66678,-5.99288
52.10000,-8.68345,-6.00424
52.20000,-8.70025,-6.01504
52.30000,-8.71665,-6.02237
52.40000,-8.73358,-6.03043
52.50000,-8.75011,-6.03877
52.60000,-8.76665,-6.05029
52.70000,-8.78358,-6.05763
52.80000,-8.79998,-6.06703
52.90000,-8.81691,-6.07735
53.00000,-8.83371,-6.08663
53.10000,-8.85038,-6.08577
53.20000,-8.86678,-6.06909
53.30000,-8.88345,-6.08256
53.40000,-8.90024,-6.09100
53.50000,-8.91665,-6.10260
53.60000,-8.93371,-6.11708
53.70000,-8.95011,-6.12522
53.80000,-8.96678,-6.13771
53.90000,-8.98371,-6.14889
54.00000,-9.00011,-6.15761
54.10000,-9.01678,-6.16607
54.20000,-9.03344,-6.17720
54.30000,-9.05011,-6.18620
54.40000,-9.06665,-6.19745
54.50000,-9.08371,-6.20738
54.60000,-9.10011,-6.21602
54.70000,-9.11691,-6.22786
54.80000,-9.13344,-6.23527
54.90000,-9.14998,-6.24364
55.00000,-9.16678,-6.25279
55.10000,-9.18331,-6.26236
55.20000,-9.20011,-6.27187
55.30000,-9.21678,-6.28257
55.40000,-9.23358,-6.29207
55.50000,-9.25011,-6.29960
55.60000,-9.26691,-6.31012
55.70000,-9.28344,-6.31712
55.80000,-9.29998,-6.32665
55.90000,-9.31691,-6.33646
56.00000,-9.33331,-6.34525
56.10000,-9.35024,-6.35605
56.20000,-9.36678,-6.36481
56.30000,-9.38358,-6.37391
56.40000,-9.39998,-6.38193
56.50000,-9.41678,-6.39179
56.60000,-9.43331,-6.39891
56.70000,-9.44984,-6.41042
56.80000,-9.46704,-6.42179
56.90000,-9.48344,-6.42947
57.00000,-9.50038,-6.44197
57.10000,-9.51718,-6.44862
57.20000,-9.53344,-6.45733
57.30000,-9.55011,-6.46451
57.40000,-9.56691,-6.47658
57.50000,-9.58344,-6.48386
57.60000,-9.59998,-6.49627
57.70000,-9.61691,-6.50486
57.80000,-9.63331,-6.51375
57.90000,-9.65038,-6.52602
58.00000,-9.66691,-6.53079
58.10000,-9.68318,-6.53952
58.20000,-9.69998,-6.54595
58.30000,-9.71678,-6.55623
58.40000,-9.73358,-6.56412
58.50000,-9.75024,-6.57506
58.60000,-9.76704,-6.58455
58.70000,-9.78344,-6.59088
58.80000,-9.80011,-6.60273
58.90000,-9.81664,-6.60699
59.00000,-9.83331,-6.61691
59.10000,-9.85024,-6.62581
59.20000,-9.86691,-6.63552
59.30000,-9.88358,-6.64431
59.40000,-9.90024,-6.65308
59.50000,-9.91718,-6.66335
59.60000,-9.93344,-6.66829
59.70000,-9.95024,-6.67786
59.80000,-9.96678,-6.68547
59.90000,-9.98331,-6.69180
60.00000,-10.00038,-6.70204
60.10000,-10.01678,-6.70766
60.20000,-10.03344,-6.71398
60.30000,-10.05011,-6.72216
60.40000,-10.06691,-6.72721
60.50000,-10.08344,-6.73529
60.60000,-10.10011,-6.74272
60.70000,-10.11678,-6.74593
60.80000,-10.13331,-6.75621
60.90000,-10.15038,-6.75996
61.00000,-10.16691,-6.76711
61.10000,-10.18358,-6.77551
61.20000,-10.20011,-6.77767
61.30000,-10.21664,-6.78591
61.40000,-10.23344,-6.79098
61.50000,-10.24998,-6.79976
61.60000,-10.26678,-6.80702
61.70000,-10.28331,-6.81229
61.80000,-10.30024,-6.81666
61.90000,-10.31678,-6.82276
62.00000,-10.33371,-6.83025
62.10000,-10.35024,-6.83389
62.20000,-10.36664,-6.83739
62.30000,-10.38358,-6.83220
62.40000,-10.39997,-6.84798
62.50000,-10.41691,-6.85629
62.60000,-10.43357,-6.85819
62.70000,-10.45024,-6.86668
62.80000,-10.46677,-6.87722
62.90000,-10.48357,-6.88400
63.00000,-10.50011,-6.88045
63.10000,-10.51664,-6.88938
63.20000,-10.53371,-6.89413
63.30000,-10.55011,-6.89915
63.40000,-10.56691,-6.90264
63.50000,-10.58357,-6.90939
63.60000,-10.60011,-6.91171
63.70000,-10.61664,-6.91137
63.80000,-10.63344,-6.91544
63.90000,-10.65024,-6.91844
64.00000,-10.66664,-6.92474
64.10001,-10.68371,-6.92733
64.20000,-10.69997,-6.93239
64.30000,-10.71677,-6.93666
64.40000,-10.73344,-6.94011
64.50000,-10.75011,-6.94523
64.60001,-10.76691,-6.94742
64.70000,-10.78331,-6.94945
64.80000,-10.80011,-6.95194
64.90000,-10.81677,-6.95774
65.00000,-10.83384,-6.96146
65.10001,-10.85011,-6.96452
65.20000,-10.86677,-6.97283
65.30000,-10.88344,-6.96945
65.40000,-10.89984,-6.97137
65.50000,-10.91664,-6.97688
65.60001,-10.93331,-6.98299
65.70001,-10.95011,-6.98202
65.80000,-10.96704,-6.98673
65.90000,-10.98384,-6.99108
66.00000,-11.00011,-6.99237
66.10001,-11.01677,-6.99464
66.20001,-11.03331,-6.99633
66.30000,-11.04997,-7.00324
66.40000,-11.06704,-7.00874
66.50000,-11.08344,-7.01538
66.60001,-11.10037,-7.02042
66.70001,-11.11691,-7.02519
66.80000,-11.13357,-7.02468
66.90000,-11.15011,-7.02491
67.00000,-11.16691,-7.02579
67.10001,-11.18344,-7.02856
67.20001,-11.19997,-7.03289
67.30000,-11.21704,-7.03851
67.40000,-11.23344,-7.04154
67.50000,-11.25011,-7.04443
67.60001,-11.26664,-7.04626
67.70001,-11.28331,-7.05419
67.80000,-11.30011,-7.06086
67.90000,-11.31664,-7.06685
68.00000,-11.33357,-7.07351
68.10001,-11.35024,-7.07845
68.20001,-11.36717,-7.08528
68.30000,-11.38357,-7.09219
68.40000,-11.40024,-7.09931
68.50000,-11.41677,-7.10305
68.60001,-11.43331,-7.10849
68.70001,-11.45024,-7.11684
68.80000,-11.46691,-7.12547
68.90000,-11.48371,-7.13695
69.00000,-11.50024,-7.15050
69.10001,-11.51704,-7.15597
69.20001,-11.53331,-7.15813
69.30000,-11.55011,-7.16815
69.40000,-11.56677,-7.17066
69.50000,-11.58330,-7.17934
69.60001,-11.60037,-7.19250
69.70001,-11.61664,-7.18610
69.80000,-11.63357,-7.19680
69.90000,-11.65037,-7.20168
70.00000,-11.66691,-7.20685
70.10001,-11.68357,-7.21140
70.20001,-11.70024,-7.21847
70.30000,-11.71691,-7.22316
70.40000,-11.73344,-7.23332
70.50000,-11.75037,-7.24116
70.60001,-11.76677,-7.24619
70.70001,-11.78357,-7.25464
70.80000,-11.80010,-7.25940
70.90000,-11.81650,-7.26499
71.00000,-11.83344,-7.27298
71.10001,-11.85010,-7.27799
71.20001,-11.86677,-7.28261
71.30000,-11.88344,-7.28949
71.40000,-11.90024,-7.29426
71.50000,-11.91677,-7.30025
71.60001,-11.93344,-7.30668
71.70001,-11.95010,-7.30937
71.80000,-11.96664,-7.31574
71.90000,-11.98357,-7.32141
72.00000,-12.00010,-7.33066
72.10001,-12.01690,-7.33854
72.20001,-12.03357,-7.34204
72.30000,-12.05037,-7.34388
72.40000,-12.06677,-7.34742
72.50000,-12.08357,-7.34988
72.60001,-12.10024,-7.35348
72.70001,-12.11664,-7.35653
72.80000,-12.13370,-7.36672
72.90000,-12.15010,-7.36684
73.00000,-12.16704,-7.36894
73.10001,-12.18370,-7.37050
73.20001,-12.20010,-7.37029
73.30000,-12.21664,-7.37820
73.40000,-12.23357,-7.38262
73.50000,-12.25010,-7.38402
73.60001,-12.26664,-7.39062
73.70001,-12.28357,-7.39356
73.80000,-12.30010,-7.39829
73.90000,-12.31690,-7.40705
74.00000,-12.33357,-7.40883
74.10001,-12.35010,-7.41393
74.20001,-12.36677,-7.41706
74.30000,-12.38330,-7.42464
74.40000,-12.40024,-7.43015
74.50000,-12.41677,-7.43929
74.60001,-12.43357,-7.44645
74.70001,-12.45010,-7.45437
74.80000,-12.46690,-7.46140
74.90000,-12.48357,-7.46299
75.00000,-12.49997,-7.46848
75.10001,-12.51690,-7.47596
75.20001,-12.53344,-7.48375
75.30000,-12.55024,-7.48925
75.40000,-12.56690,-7.49615
75.50000,-12.58357,-7.50207
75.60001,-12.60024,-7.50887
75.70001,-12.61690,-7.52150
75.80000,-12.63357,-7.52742
75.90000,-12.64997,-7.53441
76.00000,-12.66717,-7.54063
76.10001,-12.68357,-7.54694
76.20001,-12.70037,-7.55093
76.30000,-12.71704,-7.55185
76.40000,-12.73357,-7.55521
76.50000,-12.75024,-7.56013
76.60001,-12.76690,-7.56411
76.70001,-12.78357,-7.56688
76.80000,-12.79997,-7.57586
76.90000,-12.81704,-7.58163
77.00000,-12.83357,-7.58672
77.10001,-12.85024,-7.59161
77.20001,-12.86677,-7.59103
77.30000,-12.88317,-7.59435
77.40000,-12.89997,-7.59990
77.50000,-12.91663,-7.60485
77.60001,-12.93343,-7.61116
77.70001,-12.95010,-7.61383
77.80000,-12.96690,-7.62182
77.90000,-12.98343,-7.62888
78.00000,-13.00023,-7.63547
78.10001,-13.01690,-7.63430
78.20001,-13.03330,-7.64244
78.30000,-13.05023,-7.64906
78.40000,-13.06690,-7.65539
78.50000,-13.08357,-7.65716
78.60001,-13.10037,-7.66455
78.70001,-13.11703,-7.66784
78.80000,-13.13343,-7.66970
78.90000,-13.15023,-7.67358
79.00000,-13.16690,-7.68044
79.10001,-13.18330,-7.68876
79.20001,-13.20050,-7.69592
79.30000,-13.21677,-7.69895
79.40000,-13.23357,-7.70554
79.50000,-13.25037,-7.71030
79.60001,-13.26690,-7.71351
79.70001,-13.28343,-7.71875
79.80000,-13.30010,-7.72390
79.90000,-13.31690,-7.72668
80.00000,-13.33343,-7.73111
80.10001,-13.35037,-7.73599
80.20001,-13.36690,-7.73834
80.30000,-13.38357,-7.74389
80.40000,-13.40010,-7.74405
80.50001,-13.41663,-7.74617
80.60001,-13.43343,-7.75061
80.70001,-13.45010,-7.75186
80.80000,-13.46677,-7.75548
80.90000,-13.48343,-7.76254
81.00001,-13.50037,-7.76619
81.10001,-13.51677,-7.76724
81.20001,-13.53357,-7.77086
81.30000,-13.55010,-7.77000
81.40000,-13.56663,-7.77449
81.50001,-13.58357,-7.77853
81.60001,-13.59997,-7.78188
81.70001,-13.61690,-7.78665
81.80000,-13.63370,-7.79104
81.90000,-13.65037,-7.79552
82.00001,-13.66677,-7.79796
82.10001,-13.68357,-7.80370
82.20001,-13.70023,-7.80492
82.30000,-13.71677,-7.80808
82.40000,-13.73383,-7.81417
82.50001,-13.75023,-7.81465
82.60001,-13.76690,-7.81880
82.70001,-13.78370,-7.82120
82.80000,-13.80023,-7.82449
82.90000,-13.81677,-7.82710
83.00001,-13.83357,-7.83263
83.10001,-13.85023,-7.83602
83.20001,-13.86677,-7.84282
83.30000,-13.88370,-7.84781
83.40000,-13.90010,-7.84965
83.50001,-13.91690,-7.85607
83.60001,-13.93357,-7.85972
83.70001,-13.95010,-7.86463
83.80000,-13.96677,-7.86851
83.90000,-13.98330,-7.87246
84.00001,-14.00023,-7.87862
84.10001,-14.01677,-7.88581
84.20001,-14.03357,-7.89370
84.30000,-14.05010,-7.90027
84.40000,-14.06690,-7.90904
84.50001,-14.08343,-7.91555
84.60001,-14.09983,-7.92527
84.70001,-14.11690,-7.93679
84.80000,-14.13343,-7.94860
84.90000,-14.15037,-7.96346
85.00001,-14.16703,-7.97552
85.10001,-14.18370,-7.98688
85.20001,-14.20010,-7.99802
85.30000,-14.21690,-8.01007
85.40000,-14.23356,-8.02069
85.50001,-14.24997,-8.03373
85.60001,-14.26690,-8.04671
85.70001,-14.28343,-8.05872
85.80000,-14.30037,-8.07447
85.90000,-14.31703,-8.08643
86.00001,-14.33356,-8.09860
86.10001,-14.35023,-8.10987
86.20001,-14.36690,-8.12200
86.30000,-14.38343,-8.13061
86.40000,-14.39996,-8.14496
86.50001,-14.41703,-8.15666
86.60001,-14.43343,-8.16604
86.70001,-14.45023,-8.18264
86.80000,-14.46690,-8.19124
86.90000,-14.48330,-8.20345
87.00001,-14.50010,-8.21458
87.10001,-14.51663,-8.22617
87.20001,-14.53356,-8.23999
87.30000,-14.55010,-8.25490
87.40000,-14.56690,-8.26725
87.50001,-14.58343,-8.27919
87.60001,-14.60023,-8.29400
87.70001,-14.61690,-8.30342
87.80000,-14.63330,-8.31626
87.90000,-14.65023,-8.32988
88.00001,-14.66663,-8.34109
88.10001,-14.68356,-8.35462
88.20001,-14.70023,-8.36991
88.30000,-14.71703,-8.38354
88.40000,-14.73343,-8.39470
88.50001,-14.75023,-8.41026
88.60001,-14.76690,-8.42046
88.70001,-14.78330,-8.43361
88.80000,-14.80050,-8.44973
88.90000,-14.81690,-8.46188
89.00001,-14.83370,-8.47597
89.10001,-14.85036,-8.48607
89.20001,-14.86690,-8.50007
89.30000,-14.88343,-8.51144
89.40000,-14.90010,-8.52537
89.50001,-14.91676,-8.53382
89.60001,-14.93330,-8.54977
89.70001,-14.95036,-8.56394
89.80000,-14.96690,-8.57844
89.90000,-14.98370,-8.59670
90.00001,-15.00023,-8.60819
90.10001,-15.01663,-8.62195
90.20001,-15.03343,-8.63683
90.29201,-15.04863,-8.64859