File: GFBaking/data/3TspPectin/3TspPectin.is_comp_RawData/Specimen_RawData_2.csv
Time,Extension,Load
(sec),(mm),(N)
0.00000,0.00000,-0.00050
0.10000,-0.00533,-0.00291
0.20000,-0.02520,-0.00809
0.30000,-0.04547,-0.01753
0.40000,-0.06413,-0.02440
0.50000,-0.08160,-0.03113
0.60000,-0.09920,-0.03950
0.70000,-0.11613,-0.04492
0.80000,-0.13307,-0.05139
0.90000,-0.15013,-0.05677
1.00000,-0.16667,-0.06337
1.10000,-0.18347,-0.06830
1.20000,-0.20000,-0.07648
1.30000,-0.21667,-0.08473
1.40000,-0.23307,-0.09130
1.50000,-0.25000,-0.09982
1.60000,-0.26667,-0.10781
1.70000,-0.28320,-0.11360
1.80000,-0.30013,-0.12188
1.90000,-0.31653,-0.13079
2.00000,-0.33333,-0.14067
2.10000,-0.34973,-0.14938
2.20000,-0.36653,-0.15953
2.30000,-0.38320,-0.17189
2.40000,-0.40000,-0.18061
2.50000,-0.41667,-0.19214
2.60000,-0.43333,-0.20560
2.70000,-0.45013,-0.21672
2.80000,-0.46627,-0.22903
2.90000,-0.48333,-0.24059
3.00000,-0.49973,-0.25235
3.10000,-0.51667,-0.26776
3.20000,-0.53347,-0.27880
3.30000,-0.55000,-0.29334
3.40000,-0.56680,-0.30743
3.50000,-0.58347,-0.32259
3.60000,-0.60013,-0.33760
3.70000,-0.61653,-0.35286
3.80000,-0.63347,-0.37004
3.90000,-0.65000,-0.38593
4.00000,-0.66653,-0.40335
4.10000,-0.68346,-0.42042
4.20000,-0.70000,-0.43759
4.30000,-0.71680,-0.45609
4.40000,-0.73333,-0.47474
4.50000,-0.75000,-0.49335
4.60000,-0.76653,-0.51239
4.70000,-0.78346,-0.52986
4.80000,-0.80000,-0.54864
4.90000,-0.81653,-0.56959
5.00000,-0.83346,-0.58925
5.10000,-0.84986,-0.60934
5.20000,-0.86653,-0.62955
5.30000,-0.88320,-0.64984
5.40000,-0.89973,-0.67033
5.50000,-0.91640,-0.69179
5.60000,-0.93333,-0.71551
5.70000,-0.94973,-0.73664
5.80000,-0.96653,-0.75934
5.90000,-0.98346,-0.78230
6.00000,-0.99986,-0.80461
6.10000,-1.01666,-0.82841
6.20000,-1.03320,-0.85116
6.30000,-1.05000,-0.87543
6.40000,-1.06680,-0.89938
6.50000,-1.08346,-0.92271
6.60000,-1.10013,-0.94793
6.70000,-1.11666,-0.97159
6.80000,-1.13333,-0.99546
6.90000,-1.14973,-1.01843
7.00000,-1.16666,-1.04351
7.10000,-1.18333,-1.06933
7.20000,-1.20000,-1.09285
7.30000,-1.21693,-1.11805
7.40000,-1.23320,-1.14227
7.50000,-1.25000,-1.16751
7.60000,-1.26666,-1.19227
7.70000,-1.28333,-1.21646
7.80000,-1.29973,-1.24139
7.90000,-1.31666,-1.26630
8.00000,-1.33333,-1.29040
8.10000,-1.34986,-1.31721
8.20000,-1.36680,-1.34051
8.30000,-1.38320,-1.36458
8.40000,-1.39986,-1.39018
8.50000,-1.41653,-1.41519
8.60000,-1.43306,-1.44015
8.70000,-1.44986,-1.46460
8.80000,-1.46666,-1.49043
8.90000,-1.48333,-1.51385
9.00000,-1.49986,-1.54049
9.10000,-1.51680,-1.56578
9.20000,-1.53320,-1.58829
9.30000,-1.55000,-1.60304
9.40000,-1.56640,-1.58873
9.50000,-1.58333,-1.61551
9.60000,-1.60013,-1.64377
9.70000,-1.61666,-1.66720
9.80000,-1.63346,-1.68869
9.90000,-1.65000,-1.71001
10.00000,-1.66680,-1.73442
10.10000,-1.68306,-1.75962
10.20000,-1.70000,-1.78205
10.30000,-1.71666,-1.80122
10.40000,-1.73320,-1.82181
10.50000,-1.75026,-1.84260
10.60000,-1.76666,-1.86232
10.70000,-1.78333,-1.88585
10.80000,-1.79986,-1.90889
10.90000,-1.81666,-1.92879
11.00000,-1.83306,-1.94479
11.10000,-1.85013,-1.95991
11.20000,-1.86680,-1.97712
11.30000,-1.88333,-1.99389
11.40000,-1.90026,-2.00614
11.50000,-1.91653,-2.01357
11.60000,-1.93333,-2.03266
11.70000,-1.94973,-2.05779
11.80000,-1.96640,-2.07684
11.90000,-1.98320,-2.10311
12.00000,-2.00000,-2.13536
12.10000,-2.01666,-2.16180
12.20000,-2.03333,-2.18502
12.30000,-2.05013,-2.20389
12.40000,-2.06653,-2.20651
12.50000,-2.08333,-2.22675
12.60000,-2.09973,-2.24662
12.70000,-2.11666,-2.25982
12.80000,-2.13359,-2.27282
12.90000,-2.14999,-2.27994
13.00000,-2.16666,-2.29525
13.10000,-2.18333,-2.32100
13.20000,-2.20013,-2.34778
13.30000,-2.21653,-2.37159
13.40000,-2.23333,-2.39330
13.50000,-2.25013,-2.41373
13.60000,-2.26666,-2.43559
13.70000,-2.28346,-2.45492
13.80000,-2.29986,-2.47435
13.90000,-2.31666,-2.49419
14.00000,-2.33319,-2.51779
14.10000,-2.34986,-2.54206
14.20000,-2.36639,-2.56674
14.30000,-2.38333,-2.59219
14.40000,-2.39986,-2.61544
14.50000,-2.41653,-2.63970
14.60000,-2.43359,-2.66206
14.70000,-2.44986,-2.68374
14.80000,-2.46666,-2.70516
14.90000,-2.48333,-2.72753
15.00000,-2.49986,-2.74894
15.10000,-2.51639,-2.77061
15.20000,-2.53333,-2.79078
15.30000,-2.54999,-2.81128
15.40000,-2.56666,-2.83577
15.50000,-2.58359,-2.84940
15.60000,-2.59986,-2.86647
15.70000,-2.61666,-2.89095
15.80000,-2.63319,-2.91315
15.90000,-2.64999,-2.93116
16.00000,-2.66679,-2.95303
16.10000,-2.68333,-2.97147
16.20000,-2.70013,-2.99018
16.30000,-2.71679,-3.00820
16.40000,-2.73346,-3.02509
16.50000,-2.74973,-3.04256
16.60000,-2.76653,-3.06019
16.70000,-2.78333,-3.07674
16.80000,-2.79986,-3.09321
16.90000,-2.81693,-3.10759
17.00000,-2.83346,-3.12402
17.10000,-2.85026,-3.13980
17.20000,-2.86666,-3.15632
17.30000,-2.88333,-3.17324
17.40000,-2.89973,-3.18741
17.50000,-2.91666,-3.20405
17.60000,-2.93333,-3.21935
17.70000,-2.94986,-3.23485
17.80000,-2.96679,-3.24978
17.90000,-2.98319,-3.26527
18.00000,-2.99999,-3.28178
18.10000,-3.01639,-3.29343
18.20000,-3.03306,-3.30731
18.30000,-3.04986,-3.32219
18.40000,-3.06666,-3.33716
18.50000,-3.08346,-3.34819
18.60000,-3.09986,-3.36165
18.70000,-3.11666,-3.37137
18.80000,-3.13306,-3.38440
18.90000,-3.14999,-3.39828
19.00000,-3.16639,-3.41063
19.10000,-3.18333,-3.42425
19.20000,-3.20013,-3.43715
19.30000,-3.21666,-3.44711
19.40000,-3.23359,-3.45851
19.50000,-3.25013,-3.47090
19.60000,-3.26666,-3.48435
19.70000,-3.28306,-3.49505
19.80000,-3.29999,-3.51049
19.90000,-3.31666,-3.52275
20.00000,-3.33319,-3.53355
20.10000,-3.35013,-3.54658
20.20000,-3.36666,-3.55840
20.30000,-3.38346,-3.57364
20.40000,-3.39986,-3.58812
20.50000,-3.41666,-3.60086
20.60000,-3.43306,-3.61398
20.70000,-3.45012,-3.62666
20.80000,-3.46666,-3.63729
20.90000,-3.48332,-3.64980
21.00000,-3.50012,-3.65993
21.10000,-3.51652,-3.66937
21.20000,-3.53319,-3.67904
21.30000,-3.54972,-3.68909
21.40000,-3.56639,-3.69787
21.50000,-3.58319,-3.70783
21.60000,-3.60012,-3.71885
21.70000,-3.61666,-3.72813
21.80000,-3.63332,-3.73890
21.90000,-3.65026,-3.74675
22.00000,-3.66652,-3.75437
22.10000,-3.68332,-3.76406
22.20000,-3.69972,-3.77225
22.30000,-3.71652,-3.78171
22.40000,-3.73346,-3.79080
22.50000,-3.75012,-3.79901
22.60000,-3.76679,-3.80740
22.70000,-3.78332,-3.81584
22.80000,-3.79999,-3.82421
22.90000,-3.81652,-3.83185
23.00000,-3.83332,-3.84035
23.10000,-3.84999,-3.84742
23.20000,-3.86652,-3.85389
23.30000,-3.88359,-3.85962
23.40000,-3.90012,-3.86748
23.50000,-3.91679,-3.87469
23.60000,-3.93332,-3.87775
23.70000,-3.94999,-3.88443
23.80000,-3.96639,-3.89053
23.90000,-3.98332,-3.89647
24.00000,-4.00012,-3.90162
24.10000,-4.01666,-3.90502
24.20000,-4.03359,-3.90914
24.30000,-4.04999,-3.91368
24.40000,-4.06666,-3.91681
24.50000,-4.08319,-3.91865
24.60000,-4.09972,-3.92430
24.70000,-4.11652,-3.92877
24.80000,-4.13332,-3.93331
24.90000,-4.14999,-3.93748
25.00000,-4.16652,-3.94166
25.10000,-4.18346,-3.94307
25.20000,-4.19972,-3.94509
25.30000,-4.21666,-3.94679
25.40000,-4.23319,-3.94938
25.50000,-4.24999,-3.95262
25.60000,-4.26679,-3.95275
25.70000,-4.28332,-3.95502
25.80000,-4.30012,-3.95817
25.90000,-4.31679,-3.96016
26.00000,-4.33346,-3.96290
26.10000,-4.34986,-3.96712
26.20000,-4.36652,-3.97158
26.30000,-4.38332,-3.97472
26.40000,-4.39999,-3.97994
26.50000,-4.41692,-3.98625
26.60000,-4.43319,-3.98662
26.70000,-4.44999,-3.99005
26.80000,-4.46652,-3.99536
26.90000,-4.48332,-3.99837
27.00000,-4.49959,-4.00345
27.10000,-4.51666,-4.01049
27.20000,-4.53332,-4.01622
27.30000,-4.54999,-4.02329
27.40000,-4.56692,-4.02763
27.50000,-4.58319,-4.03368
27.60000,-4.59999,-4.04025
27.70000,-4.61652,-4.04472
27.80000,-4.63306,-4.05158
27.90000,-4.64986,-4.05790
28.00000,-4.66666,-4.06731
28.10000,-4.68332,-4.07333
28.20000,-4.69986,-4.07818
28.30000,-4.71679,-4.08211
28.40000,-4.73319,-4.08791
28.50000,-4.74999,-4.09391
28.60000,-4.76639,-4.10025
28.70000,-4.78332,-4.10884
28.80000,-4.80012,-4.11323
28.90000,-4.81666,-4.11875
29.00000,-4.83332,-4.12415
29.10000,-4.84999,-4.13332
29.20000,-4.86679,-4.13851
29.30000,-4.88305,-4.14757
29.40000,-4.89999,-4.15580
29.50000,-4.91665,-4.16095
29.60000,-4.93332,-4.16765
29.70000,-4.95025,-4.17890
29.80000,-4.96665,-4.18330
29.90000,-4.98345,-4.19149
30.00000,-4.99999,-4.19931
30.10000,-5.01679,-4.20625
30.20000,-5.03305,-4.20423
30.30000,-5.04999,-4.21112
30.40000,-5.06665,-4.21367
30.50000,-5.08332,-4.22264
30.60000,-5.10012,-4.22605
30.70000,-5.11639,-4.23017
30.80000,-5.13319,-4.23723
30.90000,-5.14985,-4.24161
31.00000,-5.16639,-4.24777
31.10000,-5.18319,-4.25642
31.20000,-5.19999,-4.25983
31.30000,-5.21665,-4.26535
31.40000,-5.23319,-4.27321
31.50000,-5.25012,-4.27474
31.60000,-5.26639,-4.27899
31.70000,-5.28332,-4.28279
31.80000,-5.29972,-4.28488
31.90000,-5.31652,-4.29092
32.00000,-5.33332,-4.29548
32.10000,-5.34999,-4.29501
32.20000,-5.36665,-4.29912
32.30000,-5.38345,-4.30182
32.40000,-5.40012,-4.30524
32.50000,-5.41652,-4.30986
32.60000,-5.43332,-4.31443
32.70000,-5.44999,-4.31609
32.80000,-5.46665,-4.31988
32.90000,-5.48359,-4.32116
33.00000,-5.49999,-4.32814
33.10000,-5.51679,-4.32873
33.20000,-5.53332,-4.33469
33.30000,-5.54999,-4.33955
33.40000,-5.56652,-4.34115
33.50000,-5.58345,-4.34793
33.60000,-5.59999,-4.34910
33.70000,-5.61665,-4.35303
33.80000,-5.63345,-4.35623
33.90000,-5.64985,-4.35905
34.00000,-5.66652,-4.35841
34.10000,-5.68305,-4.36225
34.20000,-5.69972,-4.36509
34.30000,-5.71652,-4.36986
34.40000,-5.73332,-4.37424
34.50000,-5.74999,-4.37454
34.60000,-5.76652,-4.37981
34.70000,-5.78345,-4.38459
34.80000,-5.79985,-4.38795
34.90000,-5.81665,-4.39498
35.00000,-5.83319,-4.39752
35.10000,-5.84999,-4.40172
35.20000,-5.86679,-4.40883
35.30000,-5.88332,-4.41282
35.40000,-5.90012,-4.41671
35.50000,-5.91665,-4.42110
35.60000,-5.93345,-4.42488
35.70000,-5.94972,-4.42952
35.80000,-5.96665,-4.43522
35.90000,-5.98332,-4.43793
36.00000,-5.99999,-4.44133
36.10000,-6.01679,-4.44473
36.20000,-6.03332,-4.44752
36.30000,-6.05012,-4.45181
36.40000,-6.06665,-4.45374
36.50000,-6.08345,-4.45564
36.60000,-6.09972,-4.46031
36.70000,-6.11665,-4.46378
36.80000,-6.13332,-4.46602
36.90000,-6.14985,-4.47037
37.00000,-6.16679,-4.47199
37.10000,-6.18319,-4.47344
37.20000,-6.19985,-4.47774
37.30000,-6.21652,-4.48068
37.40000,-6.23318,-4.48561
37.50000,-6.24985,-4.48775
37.60000,-6.26665,-4.49294
37.70000,-6.28332,-4.49624
37.80000,-6.29985,-4.50077
37.90000,-6.31678,-4.50376
38.00000,-6.33318,-4.50506
38.10000,-6.34998,-4.50972
38.20000,-6.36638,-4.51180
38.30000,-6.38332,-4.51735
38.40000,-6.40012,-4.52096
38.50000,-6.41665,-4.52805
38.60000,-6.43345,-4.53176
38.70000,-6.44998,-4.53613
38.80000,-6.46692,-4.54096
38.90000,-6.48318,-4.54539
39.00000,-6.50012,-4.54961
39.10000,-6.51665,-4.55363
39.20000,-6.53332,-4.55970
39.30000,-6.55025,-4.56298
39.40000,-6.56665,-4.56696
39.50000,-6.58332,-4.56891
39.60000,-6.59998,-4.57204
39.70000,-6.61665,-4.57765
39.80000,-6.63305,-4.58280
39.90000,-6.64998,-4.58812
40.00000,-6.66678,-4.59356
40.10000,-6.68318,-4.59653
40.20000,-6.70012,-4.60028
40.30000,-6.71652,-4.60271
40.40000,-6.73318,-4.60748
40.50000,-6.74985,-4.61174
40.60000,-6.76652,-4.61471
40.70000,-6.78318,-4.62056
40.80000,-6.80012,-4.61993
40.90000,-6.81665,-4.62196
41.00000,-6.83318,-4.62482
41.10000,-6.85012,-4.62764
41.20000,-6.86638,-4.63060
41.30000,-6.88332,-4.63686
41.40000,-6.89972,-4.63849
41.50000,-6.91665,-4.64450
41.60000,-6.93345,-4.64957
41.70000,-6.95012,-4.65414
41.80000,-6.96678,-4.65833
41.90000,-6.98345,-4.66364
42.00000,-7.00012,-4.66584
42.10000,-7.01638,-4.67046
42.20000,-7.03332,-4.67435
42.30000,-7.04998,-4.67866
42.40000,-7.06652,-4.68393
42.50000,-7.08358,-4.68780
42.60000,-7.09998,-4.69193
42.70000,-7.11665,-4.69638
42.80000,-7.13318,-4.70023
42.90000,-7.14998,-4.70356
43.00000,-7.16638,-4.70719
43.10000,-7.18318,-4.71234
43.20000,-7.19998,-4.71738
43.30000,-7.21652,-4.71593
43.40000,-7.23345,-4.72135
43.50000,-7.24985,-4.72572
43.60000,-7.26665,-4.72990
43.70000,-7.28318,-4.73407
43.80000,-7.29972,-4.73619
43.90000,-7.31652,-4.74249
44.00000,-7.33345,-4.74795
44.10000,-7.34998,-4.75284
44.20000,-7.36665,-4.75863
44.30000,-7.38345,-4.76358
44.40000,-7.39972,-4.76633
44.50000,-7.41665,-4.77209
44.60000,-7.43318,-4.77354
44.70000,-7.44998,-4.78103
44.80000,-7.46678,-4.78665
44.90000,-7.48332,-4.78869
45.00000,-7.50011,-4.79298
45.10000,-7.51665,-4.79656
45.20000,-7.53332,-4.80168
45.30000,-7.54971,-4.80033
45.40000,-7.56678,-4.80688
45.50000,-7.58345,-4.80558
45.60000,-7.59985,-4.80850
45.70000,-7.61678,-4.81097
45.80000,-7.63345,-4.81252
45.90000,-7.65011,-4.81538
46.00000,-7.66665,-4.81586
46.10000,-7.68318,-4.81633
46.20000,-7.69971,-4.81569
46.30000,-7.71665,-4.81768
46.40000,-7.73345,-4.82035
46.50000,-7.74985,-4.81320
46.60000,-7.76678,-4.81447
46.70000,-7.78331,-4.81602
46.80000,-7.79998,-4.82741
46.90000,-7.81651,-4.82928
47.00000,-7.83318,-4.83174
47.10000,-7.84985,-4.83431
47.20000,-7.86651,-4.83979
47.30000,-7.88331,-4.84247
47.40000,-7.89985,-4.84853
47.50000,-7.91678,-4.84965
47.60000,-7.93318,-4.85229
47.70000,-7.94998,-4.84899
47.80000,-7.96638,-4.85489
47.90000,-7.98305,-4.86122
48.00000,-7.99998,-4.85648
48.10000,-8.01665,-4.85184
48.20000,-8.03331,-4.86372
48.30000,-8.05011,-4.86909
48.40000,-8.06678,-4.87649
48.50000,-8.08305,-4.88710
48.60000,-8.09998,-4.89713
48.70000,-8.11665,-4.90143
48.80000,-8.13318,-4.90868
48.90000,-8.15025,-4.91857
49.00000,-8.16665,-4.92415
49.10000,-8.18331,-4.92962
49.20000,-8.19998,-4.93106
49.30000,-8.21665,-4.93209
49.40000,-8.23305,-4.93645
49.50000,-8.24998,-4.94329
49.60000,-8.26665,-4.94457
49.70000,-8.28331,-4.95448
49.80000,-8.30025,-4.96086
49.90000,-8.31651,-4.96041
50.00000,-8.33318,-4.96612
50.10000,-8.34971,-4.97294
50.20000,-8.36638,-4.97478
50.30000,-8.38305,-4.97796
50.40000,-8.39998,-4.98445
50.50000,-8.41665,-4.98791
50.60000,-8.43318,-4.99352
50.70000,-8.45011,-4.99951
50.80000,-8.46651,-5.00380
50.90000,-8.48331,-5.00881
51.00000,-8.49971,-5.01154
51.10000,-8.51665,-5.01651
51.20000,-8.53345,-5.02469
51.30000,-8.54998,-5.03016
51.40000,-8.56678,-5.03325
51.50000,-8.58345,-5.03822
51.60000,-8.60011,-5.04506
51.70000,-8.61651,-5.04889
51.80000,-8.63331,-5.05343
51.90000,-8.64998,-5.05745
52.00000,-8.66665,-5.06164
52.10000,-8.68358,-5.06608
52.20000,-8.69998,-5.07127
52.30000,-8.71678,-5.07578
52.40000,-8.73331,-5.08025
52.50000,-8.74998,-5.08431
52.60000,-8.76638,-5.08713
52.70000,-8.78331,-5.09148
52.80000,-8.79998,-5.09694
52.90000,-8.81651,-5.10255
53.00000,-8.83358,-5.10704
53.10000,-8.84998,-5.11151
53.20000,-8.86651,-5.11708
53.30000,-8.88318,-5.12163
53.40000,-8.89985,-5.12722
53.50000,-8.91638,-5.13465
53.60000,-8.93345,-5.14062
53.70000,-8.95011,-5.14306
53.80000,-8.96665,-5.15359
53.90000,-8.98358,-5.16128
54.00000,-8.99985,-5.16713
54.10000,-9.01651,-5.17907
54.20000,-9.03318,-5.18528
54.30000,-9.04984,-5.19613
54.40000,-9.06678,-5.20201
54.50000,-9.08331,-5.21001
54.60000,-9.09998,-5.21894
54.70000,-9.11664,-5.22768
54.80000,-9.13344,-5.23298
54.90000,-9.14971,-5.23801
55.00000,-9.16664,-5.24684
55.10000,-9.18331,-5.25367
55.20000,-9.19998,-5.26209
55.30000,-9.21691,-5.27019
55.40000,-9.23331,-5.27345
55.50000,-9.25011,-5.28193
55.60000,-9.26664,-5.28964
55.70000,-9.28344,-5.29858
55.80000,-9.29984,-5.30597
55.90000,-9.31678,-5.31353
56.00000,-9.33331,-5.31767
56.10000,-9.34998,-5.32453
56.20000,-9.36691,-5.33293
56.30000,-9.38318,-5.33733
56.40000,-9.39984,-5.34202
56.50000,-9.41638,-5.34632
56.60000,-9.43304,-5.35102
56.70000,-9.44984,-5.35707
56.80000,-9.46664,-5.36459
56.90000,-9.48331,-5.36991
57.00000,-9.49984,-5.37737
57.10000,-9.51678,-5.38264
57.20000,-9.53304,-5.38759
57.30000,-9.54998,-5.39456
57.40000,-9.56651,-5.39917
57.50000,-9.58331,-5.40544
57.60000,-9.60011,-5.41290
57.70000,-9.61678,-5.41786
57.80000,-9.63344,-5.42511
57.90000,-9.65011,-5.43293
58.00000,-9.66664,-5.43753
58.10000,-9.68304,-5.44314
58.20000,-9.69998,-5.44939
58.30000,-9.71664,-5.45507
58.40000,-9.73331,-5.46257
58.50000,-9.75011,-5.46781
58.60000,-9.76664,-5.47009
58.70000,-9.78344,-5.47851
58.80000,-9.79998,-5.48618
58.90000,-9.81664,-5.49511
59.00000,-9.83304,-5.50021
59.10000,-9.84998,-5.50694
59.20000,-9.86664,-5.51286
59.30000,-9.88318,-5.51969
59.40000,-9.90011,-5.52798
59.50000,-9.91651,-5.53543
59.60000,-9.93331,-5.54167
59.70000,-9.94984,-5.54998
59.80000,-9.96651,-5.55597
59.90000,-9.98304,-5.56183
60.00000,-9.99984,-5.57012
60.10000,-10.01664,-5.57468
60.20000,-10.03331,-5.58367
60.30000,-10.05011,-5.58608
60.40000,-10.06651,-5.59046
60.50000,-10.08331,-5.59610
60.60000,-10.09984,-5.59893
60.70000,-10.11664,-5.60793
60.80000,-10.13344,-5.61241
60.90000,-10.14998,-5.61666
61.00000,-10.16664,-5.62270
61.10000,-10.18344,-5.63087
61.20000,-10.20011,-5.63666
61.30000,-10.21637,-5.63935
61.40000,-10.23318,-5.64330
61.50000,-10.24984,-5.64775
61.60000,-10.26664,-5.65675
61.70000,-10.28371,-5.66205
61.80000,-10.30011,-5.66793
61.90000,-10.31678,-5.67248
62.00000,-10.33331,-5.67757
62.10000,-10.35011,-5.68059
62.20000,-10.36637,-5.68601
62.30000,-10.38331,-5.68824
62.40000,-10.39997,-5.69529
62.50000,-10.41651,-5.70037
62.60000,-10.43344,-5.70515
62.70000,-10.44997,-5.70721
62.80000,-10.46664,-5.71328
62.90000,-10.48304,-5.71129
63.00000,-10.49984,-5.71835
63.10000,-10.51637,-5.72547
63.20000,-10.53344,-5.72738
63.30000,-10.54997,-5.73236
63.40000,-10.56664,-5.74024
63.50000,-10.58331,-5.74590
63.60000,-10.59971,-5.74822
63.70000,-10.61664,-5.75752
63.80000,-10.63317,-5.76268
63.90000,-10.64997,-5.76839
64.00000,-10.66677,-5.77341
64.10001,-10.68344,-5.78149
64.20000,-10.70024,-5.78714
64.30000,-10.71677,-5.79087
64.40000,-10.73344,-5.79431
64.50000,-10.74971,-5.79997
64.60001,-10.76664,-5.80122
64.70000,-10.78331,-5.80389
64.80000,-10.79997,-5.81231
64.90000,-10.81677,-5.81153
65.00000,-10.83331,-5.81230
65.10001,-10.84997,-5.81849
65.20000,-10.86664,-5.82330
65.30000,-10.88331,-5.82542
65.40000,-10.89971,-5.83924
65.50000,-10.91677,-5.84147
65.60001,-10.93331,-5.84647
65.70001,-10.94997,-5.85267
65.80000,-10.96691,-5.85894
65.90000,-10.98317,-5.86257
66.00000,-10.99984,-5.86458
66.10001,-11.01637,-5.86797
66.20001,-11.03304,-5.87016
66.30000,-11.04984,-5.87299
66.40000,-11.06664,-5.87545
66.50000,-11.08317,-5.87774
66.60001,-11.09997,-5.88245
66.70001,-11.11691,-5.87979
66.80000,-11.13317,-5.88656
66.90000,-11.14997,-5.89511
67.00000,-11.16637,-5.89329
67.10001,-11.18317,-5.89962
67.20001,-11.19997,-5.90879
67.30000,-11.21664,-5.91026
67.40000,-11.23331,-5.91133
67.50000,-11.25011,-5.91366
67.60001,-11.26677,-5.91466
67.70001,-11.28317,-5.91746
67.80000,-11.29997,-5.91711
67.90000,-11.31664,-5.91722
68.00000,-11.33317,-5.92146
68.10001,-11.35011,-5.91843
68.20001,-11.36664,-5.91894
68.30000,-11.38344,-5.92537
68.40000,-11.39984,-5.92505
68.50000,-11.41664,-5.92688
68.60001,-11.43304,-5.92848
68.70001,-11.44997,-5.92960
68.80000,-11.46664,-5.92854
68.90000,-11.48317,-5.93373
69.00000,-11.50011,-5.93404
69.10001,-11.51650,-5.93696
69.20001,-11.53331,-5.94293
69.30000,-11.54984,-5.94195
69.40000,-11.56650,-5.94155
69.50000,-11.58304,-5.94365
69.60001,-11.59997,-5.94660
69.70001,-11.61677,-5.94946
69.80000,-11.63330,-5.95043
69.90000,-11.65024,-5.95371
70.00000,-11.66637,-5.95457
70.10001,-11.68330,-5.95726
70.20001,-11.69970,-5.95938
70.30000,-11.71650,-5.95960
70.40000,-11.73330,-5.96081
70.50000,-11.74997,-5.96359
70.60001,-11.76677,-5.96597
70.70001,-11.78344,-5.96892
70.80000,-11.80010,-5.96596
70.90000,-11.81624,-5.96747
71.00000,-11.83317,-5.96966
71.10001,-11.84984,-5.97240
71.20001,-11.86664,-5.97657
71.30000,-11.88357,-5.97561
71.40000,-11.89997,-5.97868
71.50000,-11.91677,-5.98293
71.60001,-11.93330,-5.98516
71.70001,-11.95010,-5.98853
71.80000,-11.96650,-5.98975
71.90000,-11.98330,-5.99313
72.00000,-11.99997,-5.99155
72.10001,-12.01664,-5.99854
72.20001,-12.03357,-6.00143
72.30000,-12.04984,-6.00271
72.40000,-12.06650,-6.00522
72.50000,-12.08317,-6.00607
72.60001,-12.09984,-6.00863
72.70001,-12.11650,-6.01521
72.80000,-12.13344,-6.01829
72.90000,-12.15010,-6.01997
73.00000,-12.16664,-6.02638
73.10001,-12.18344,-6.02836
73.20001,-12.19984,-6.03412
73.30000,-12.21650,-6.03834
73.40000,-12.23317,-6.03920
73.50000,-12.24997,-6.04761
73.60001,-12.26677,-6.05413
73.70001,-12.28344,-6.05952
73.80000,-12.30010,-6.06309
73.90000,-12.31664,-6.06721
74.00000,-12.33344,-6.07241
74.10001,-12.34970,-6.07577
74.20001,-12.36664,-6.08010
74.30000,-12.38330,-6.08378
74.40000,-12.39984,-6.08881
74.50000,-12.41677,-6.09481
74.60001,-12.43344,-6.10067
74.70001,-12.45010,-6.10563
74.80000,-12.46664,-6.11085
74.90000,-12.48344,-6.11638
75.00000,-12.49984,-6.12223
75.10001,-12.51677,-6.12903
75.20001,-12.53330,-6.13233
75.30000,-12.54984,-6.14088
75.40000,-12.56690,-6.14571
75.50000,-12.58317,-6.15183
75.60001,-12.59970,-6.15668
75.70001,-12.61637,-6.16499
75.80000,-12.63317,-6.17060
75.90000,-12.64984,-6.17783
76.00000,-12.66664,-6.18447
76.10001,-12.68330,-6.18847
76.20001,-12.69984,-6.19701
76.30000,-12.71690,-6.20326
76.40000,-12.73317,-6.21009
76.50000,-12.74997,-6.21804
76.60001,-12.76650,-6.22297
76.70001,-12.78330,-6.23086
76.80000,-12.80010,-6.23816
76.90000,-12.81663,-6.23904
77.00000,-12.83330,-6.24089
77.10001,-12.85010,-6.24785
77.20001,-12.86677,-6.25236
77.30000,-12.88304,-6.25999
77.40000,-12.89997,-6.26514
77.50000,-12.91677,-6.26828
77.60001,-12.93330,-6.27296
77.70001,-12.95037,-6.27770
77.80000,-12.96677,-6.28294
77.90000,-12.98343,-6.28840
78.00000,-12.99983,-6.29186
78.10001,-13.01663,-6.29787
78.20001,-13.03304,-6.30454
78.30000,-13.04997,-6.31317
78.40000,-13.06650,-6.31871
78.50000,-13.08317,-6.32833
78.60001,-13.10023,-6.33565
78.70001,-13.11663,-6.34291
78.80000,-13.13330,-6.34930
78.90000,-13.14983,-6.35677
79.00000,-13.16637,-6.36301
79.10001,-13.18317,-6.37214
79.20001,-13.19997,-6.38342
79.30000,-13.21663,-6.39030
79.40000,-13.23330,-6.40144
79.50000,-13.25023,-6.41027
79.60001,-13.26650,-6.41718
79.70001,-13.28330,-6.42837
79.80000,-13.29983,-6.43687
79.90000,-13.31663,-6.44554
80.00000,-13.33343,-6.45632
80.10001,-13.34997,-6.46499
80.20001,-13.36677,-6.47230
80.30000,-13.38330,-6.48178
80.40000,-13.40010,-6.48879
80.50001,-13.41650,-6.49483
80.60001,-13.43330,-6.50241
80.70001,-13.44997,-6.50565
80.80000,-13.46663,-6.51395
80.90000,-13.48357,-6.52266
81.00001,-13.49997,-6.52908
81.10001,-13.51663,-6.53829
81.20001,-13.53343,-6.54600
81.30000,-13.54997,-6.55364
81.40000,-13.56637,-6.56122
81.50001,-13.58330,-6.57114
81.60001,-13.59997,-6.57844
81.70001,-13.61663,-6.58807
81.80000,-13.63357,-6.59523
81.90000,-13.64983,-6.60407
82.00001,-13.66637,-6.61357
82.10001,-13.68303,-6.62078
82.20001,-13.69970,-6.62863
82.30000,-13.71637,-6.63755
82.40000,-13.73317,-6.64682
82.50001,-13.74997,-6.65705
82.60001,-13.76663,-6.66850
82.70001,-13.78343,-6.67284
82.80000,-13.79983,-6.67980
82.90000,-13.81663,-6.68910
83.00001,-13.83303,-6.69393
83.10001,-13.84997,-6.70439
83.20001,-13.86677,-6.71246
83.30000,-13.88330,-6.72013
83.40000,-13.90010,-6.72641
83.50001,-13.91677,-6.73684
83.60001,-13.93343,-6.74248
83.70001,-13.94983,-6.75045
83.80000,-13.96663,-6.76110
83.90000,-13.98330,-6.76746
84.00001,-13.99983,-6.77643
84.10001,-14.01677,-6.78461
84.20001,-14.03330,-6.79322
84.30000,-14.04997,-6.80229
84.40000,-14.06663,-6.81063
84.50001,-14.08330,-6.81724
84.60001,-14.09983,-6.82386
84.70001,-14.11677,-6.83010
84.80000,-14.13330,-6.83502
84.90000,-14.14997,-6.84678
85.00001,-14.16677,-6.85391
85.10001,-14.18317,-6.85905
85.20001,-14.19983,-6.86483
85.30000,-14.21637,-6.87115
85.40000,-14.23303,-6.87849
85.50001,-14.24983,-6.88838
85.60001,-14.26676,-6.89840
85.70001,-14.28330,-6.90238
85.80000,-14.29997,-6.91290
85.90000,-14.31676,-6.92224
86.00001,-14.33317,-6.93216
86.10001,-14.34997,-6.94138
86.20001,-14.36637,-6.94806
86.30000,-14.38317,-6.95928
86.40000,-14.40010,-6.97244
86.50001,-14.41690,-6.98664
86.60001,-14.43356,-6.99356
86.70001,-14.45010,-7.00366
86.80000,-14.46676,-7.01154
86.90000,-14.48316,-7.01856
87.00001,-14.49996,-7.03195
87.10001,-14.51676,-7.04079
87.20001,-14.53330,-7.05096
87.30000,-14.55023,-7.05789
87.40000,-14.56676,-7.06569
87.50001,-14.58343,-7.07611
87.60001,-14.59996,-7.08662
87.70001,-14.61663,-7.09279
87.80000,-14.63316,-7.10066
87.90000,-14.65010,-7.11294
88.00001,-14.66663,-7.12142
88.10001,-14.68330,-7.13401
88.20001,-14.70023,-7.14221
88.30000,-14.71663,-7.15126
88.40000,-14.73330,-7.16217
88.50001,-14.74983,-7.16984
88.60001,-14.76636,-7.17641
88.70001,-14.78316,-7.18310
88.80000,-14.79996,-7.19297
88.90000,-14.81663,-7.20375
89.00001,-14.83330,-7.21457
89.10001,-14.85010,-7.22154
89.20001,-14.86650,-7.22776
89.30000,-14.88330,-7.23313
89.40000,-14.89983,-7.23994
89.50001,-14.91663,-7.24844
89.60001,-14.93356,-7.25712
89.70001,-14.95023,-7.26496
89.80000,-14.96676,-7.27308
89.90000,-14.98343,-7.28029
90.00001,-15.00010,-7.28843
90.10001,-15.01650,-7.29641
90.11601,-15.01930,-7.29571