File: GFBaking/data/3TspPectin/3TspPectin.is_comp_RawData/Specimen_RawData_3.csv
Time,Extension,Load
(sec),(mm),(N)
0.00000,0.00000,0.00506
0.10000,-0.00613,0.00443
0.20000,-0.02533,0.00321
0.30000,-0.04560,-0.00031
0.40000,-0.06440,-0.00054
0.50000,-0.08200,-0.00105
0.60000,-0.09920,-0.00421
0.70000,-0.11600,-0.00460
0.80000,-0.13307,-0.00821
0.90000,-0.14973,-0.01097
1.00000,-0.16640,-0.01496
1.10000,-0.18347,-0.01805
1.20000,-0.19987,-0.02223
1.30000,-0.21667,-0.02652
1.40000,-0.23320,-0.02858
1.50000,-0.25000,-0.03405
1.60000,-0.26667,-0.03482
1.70000,-0.28333,-0.04159
1.80000,-0.30000,-0.04575
1.90000,-0.31653,-0.05075
2.00000,-0.33347,-0.05493
2.10000,-0.34987,-0.05907
2.20000,-0.36680,-0.06503
2.30000,-0.38333,-0.06836
2.40000,-0.39987,-0.07469
2.50000,-0.41653,-0.07773
2.60000,-0.43307,-0.08421
2.70000,-0.44987,-0.08987
2.80000,-0.46667,-0.09459
2.90000,-0.48347,-0.10159
3.00000,-0.49987,-0.10841
3.10000,-0.51667,-0.11761
3.20000,-0.53307,-0.12661
3.30000,-0.54973,-0.13477
3.40000,-0.56653,-0.14245
3.50000,-0.58307,-0.15110
3.60000,-0.60000,-0.16097
3.70000,-0.61653,-0.17085
3.80000,-0.63347,-0.18066
3.90000,-0.64987,-0.18895
4.00000,-0.66653,-0.20008
4.10000,-0.68306,-0.21005
4.20000,-0.69973,-0.21862
4.30000,-0.71680,-0.23092
4.40000,-0.73320,-0.24137
4.50000,-0.75013,-0.25352
4.60000,-0.76653,-0.26660
4.70000,-0.78320,-0.27903
4.80000,-0.79986,-0.29045
4.90000,-0.81666,-0.30197
5.00000,-0.83320,-0.31601
5.10000,-0.85000,-0.32910
5.20000,-0.86680,-0.34457
5.30000,-0.88320,-0.35716
5.40000,-0.90013,-0.37037
5.50000,-0.91653,-0.38427
5.60000,-0.93306,-0.39642
5.70000,-0.94986,-0.41126
5.80000,-0.96640,-0.42426
5.90000,-0.98320,-0.44029
6.00000,-0.99986,-0.45587
6.10000,-1.01680,-0.47268
6.20000,-1.03320,-0.48772
6.30000,-1.05000,-0.50215
6.40000,-1.06640,-0.51681
6.50000,-1.08306,-0.53305
6.60000,-1.09986,-0.54876
6.70000,-1.11653,-0.56474
6.80000,-1.13333,-0.58015
6.90000,-1.15000,-0.59464
7.00000,-1.16666,-0.60982
7.10000,-1.18320,-0.62593
7.20000,-1.20000,-0.64201
7.30000,-1.21653,-0.65712
7.40000,-1.23320,-0.67320
7.50000,-1.25013,-0.68900
7.60000,-1.26640,-0.70282
7.70000,-1.28333,-0.71818
7.80000,-1.29986,-0.73456
7.90000,-1.31666,-0.75125
8.00000,-1.33320,-0.76379
8.10000,-1.34986,-0.77861
8.20000,-1.36640,-0.79323
8.30000,-1.38320,-0.80850
8.40000,-1.40013,-0.82352
8.50000,-1.41653,-0.83932
8.60000,-1.43346,-0.85514
8.70000,-1.44973,-0.86897
8.80000,-1.46653,-0.88564
8.90000,-1.48320,-0.90078
9.00000,-1.49973,-0.91820
9.10000,-1.51653,-0.93602
9.20000,-1.53333,-0.95350
9.30000,-1.55013,-0.97102
9.40000,-1.56653,-0.98800
9.50000,-1.58346,-1.00611
9.60000,-1.59986,-1.02370
9.70000,-1.61640,-1.04069
9.80000,-1.63320,-1.05890
9.90000,-1.64986,-1.07734
10.00000,-1.66666,-1.09640
10.10000,-1.68333,-1.11448
10.20000,-1.70013,-1.13169
10.30000,-1.71653,-1.15127
10.40000,-1.73333,-1.16962
10.50000,-1.74986,-1.18631
10.60000,-1.76640,-1.20375
10.70000,-1.78333,-1.21997
10.80000,-1.79986,-1.23805
10.90000,-1.81680,-1.25628
11.00000,-1.83333,-1.27240
11.10000,-1.85000,-1.28893
11.20000,-1.86653,-1.30650
11.30000,-1.88320,-1.32402
11.40000,-1.89986,-1.34265
11.50000,-1.91653,-1.36055
11.60000,-1.93346,-1.37563
11.70000,-1.94973,-1.39241
11.80000,-1.96680,-1.41101
11.90000,-1.98320,-1.42752
12.00000,-1.99986,-1.44558
12.10000,-2.01653,-1.46207
12.20000,-2.03306,-1.47957
12.30000,-2.04986,-1.49816
12.40000,-2.06653,-1.51704
12.50000,-2.08333,-1.53449
12.60000,-2.09973,-1.55190
12.70000,-2.11653,-1.56882
12.80000,-2.13306,-1.58708
12.90000,-2.14973,-1.60664
13.00000,-2.16666,-1.62521
13.10000,-2.18319,-1.64524
13.20000,-2.20013,-1.66034
13.30000,-2.21666,-1.67709
13.40000,-2.23346,-1.69647
13.50000,-2.24986,-1.71270
13.60000,-2.26653,-1.73148
13.70000,-2.28306,-1.75198
13.80000,-2.29973,-1.76880
13.90000,-2.31679,-1.78335
14.00000,-2.33319,-1.79998
14.10000,-2.35013,-1.81766
14.20000,-2.36666,-1.83318
14.30000,-2.38333,-1.85161
14.40000,-2.39986,-1.86828
14.50000,-2.41653,-1.88365
14.60000,-2.43319,-1.89883
14.70000,-2.44999,-1.91851
14.80000,-2.46666,-1.93335
14.90000,-2.48319,-1.95050
15.00000,-2.50013,-1.96822
15.10000,-2.51639,-1.98557
15.20000,-2.53306,-2.00119
15.30000,-2.54986,-2.01531
15.40000,-2.56639,-2.03064
15.50000,-2.58319,-2.04575
15.60000,-2.59999,-2.06176
15.70000,-2.61666,-2.07959
15.80000,-2.63306,-2.09479
15.90000,-2.65013,-2.10952
16.00000,-2.66639,-2.12591
16.10000,-2.68293,-2.14271
16.20000,-2.69986,-2.15955
16.30000,-2.71639,-2.17521
16.40000,-2.73333,-2.19176
16.50000,-2.74999,-2.20701
16.60000,-2.76666,-2.22223
16.70000,-2.78306,-2.23821
16.80000,-2.79999,-2.25417
16.90000,-2.81653,-2.26757
17.00000,-2.83306,-2.28721
17.10000,-2.85013,-2.30211
17.20000,-2.86653,-2.31693
17.30000,-2.88333,-2.33224
17.40000,-2.89999,-2.33883
17.50000,-2.91666,-2.33492
17.60000,-2.93333,-2.35422
17.70000,-2.94999,-2.37485
17.80000,-2.96653,-2.39391
17.90000,-2.98333,-2.40690
18.00000,-3.00013,-2.42213
18.10000,-3.01666,-2.43636
18.20000,-3.03359,-2.45299
18.30000,-3.04986,-2.46962
18.40000,-3.06653,-2.48598
18.50000,-3.08306,-2.50021
18.60000,-3.09959,-2.50871
18.70000,-3.11653,-2.52291
18.80000,-3.13319,-2.53848
18.90000,-3.14999,-2.54701
19.00000,-3.16639,-2.55852
19.10000,-3.18346,-2.57515
19.20000,-3.19973,-2.58728
19.30000,-3.21639,-2.59993
19.40000,-3.23333,-2.61151
19.50000,-3.24986,-2.62343
19.60000,-3.26666,-2.62952
19.70000,-3.28333,-2.65275
19.80000,-3.29999,-2.66946
19.90000,-3.31653,-2.68415
20.00000,-3.33346,-2.70301
20.10000,-3.34986,-2.72272
20.20000,-3.36639,-2.73230
20.30000,-3.38346,-2.74618
20.40000,-3.39986,-2.76437
20.50000,-3.41679,-2.78028
20.60000,-3.43319,-2.79155
20.70000,-3.44986,-2.80811
20.80000,-3.46652,-2.81792
20.90000,-3.48332,-2.82384
21.00000,-3.49986,-2.83408
21.10000,-3.51652,-2.84495
21.20000,-3.53346,-2.86039
21.30000,-3.54986,-2.87153
21.40000,-3.56692,-2.88445
21.50000,-3.58306,-2.89748
21.60000,-3.59986,-2.90559
21.70000,-3.61652,-2.91553
21.80000,-3.63292,-2.93024
21.90000,-3.64986,-2.94410
22.00000,-3.66652,-2.96263
22.10000,-3.68332,-2.96679
22.20000,-3.69986,-2.97821
22.30000,-3.71666,-2.99411
22.40000,-3.73306,-3.00329
22.50000,-3.74972,-3.01701
22.60000,-3.76652,-3.02520
22.70000,-3.78319,-3.04035
22.80000,-3.79999,-3.05005
22.90000,-3.81652,-3.05820
23.00000,-3.83332,-3.07269
23.10000,-3.84986,-3.08418
23.20000,-3.86666,-3.09638
23.30000,-3.88306,-3.10790
23.40000,-3.89972,-3.11915
23.50000,-3.91679,-3.13025
23.60000,-3.93319,-3.14313
23.70000,-3.95012,-3.16054
23.80000,-3.96666,-3.16751
23.90000,-3.98346,-3.17764
24.00000,-3.99999,-3.18854
24.10000,-4.01666,-3.19931
24.20000,-4.03319,-3.20965
24.30000,-4.04999,-3.22295
24.40000,-4.06679,-3.23012
24.50000,-4.08319,-3.24004
24.60000,-4.09999,-3.25433
24.70000,-4.11626,-3.25929
24.80000,-4.13306,-3.27115
24.90000,-4.14986,-3.28002
25.00000,-4.16639,-3.29013
25.10000,-4.18319,-3.30226
25.20000,-4.19999,-3.30826
25.30000,-4.21666,-3.32272
25.40000,-4.23306,-3.33365
25.50000,-4.24999,-3.34358
25.60000,-4.26639,-3.35522
25.70000,-4.28306,-3.36530
25.80000,-4.29986,-3.37562
25.90000,-4.31652,-3.38596
26.00000,-4.33332,-3.39524
26.10000,-4.34999,-3.40961
26.20000,-4.36679,-3.41691
26.30000,-4.38319,-3.42879
26.40000,-4.40012,-3.43747
26.50000,-4.41639,-3.44682
26.60000,-4.43306,-3.45379
26.70000,-4.45012,-3.45716
26.80000,-4.46652,-3.46660
26.90000,-4.48346,-3.48313
27.00000,-4.49999,-3.48915
27.10000,-4.51666,-3.49634
27.20000,-4.53319,-3.50579
27.30000,-4.54986,-3.50907
27.40000,-4.56652,-3.52336
27.50000,-4.58319,-3.53778
27.60000,-4.59999,-3.54594
27.70000,-4.61639,-3.55229
27.80000,-4.63346,-3.56055
27.90000,-4.64986,-3.57059
28.00000,-4.66652,-3.57917
28.10000,-4.68319,-3.58672
28.20000,-4.69972,-3.59623
28.30000,-4.71639,-3.60564
28.40000,-4.73332,-3.61636
28.50000,-4.74999,-3.62531
28.60000,-4.76639,-3.63612
28.70000,-4.78332,-3.64520
28.80000,-4.79985,-3.65376
28.90000,-4.81639,-3.66123
29.00000,-4.83319,-3.66817
29.10000,-4.84972,-3.67483
29.20000,-4.86679,-3.68545
29.30000,-4.88332,-3.69371
29.40000,-4.89999,-3.70148
29.50000,-4.91639,-3.70918
29.60000,-4.93332,-3.71569
29.70000,-4.94985,-3.72119
29.80000,-4.96652,-3.73038
29.90000,-4.98332,-3.73753
30.00000,-4.99985,-3.74585
30.10000,-5.01679,-3.75151
30.20000,-5.03319,-3.75652
30.30000,-5.04999,-3.76178
30.40000,-5.06652,-3.76924
30.50000,-5.08319,-3.77743
30.60000,-5.09985,-3.78333
30.70000,-5.11665,-3.79077
30.80000,-5.13332,-3.79693
30.90000,-5.14985,-3.80318
31.00000,-5.16679,-3.81149
31.10000,-5.18319,-3.81707
31.20000,-5.19985,-3.82094
31.30000,-5.21652,-3.82801
31.40000,-5.23305,-3.83281
31.50000,-5.24972,-3.83915
31.60000,-5.26665,-3.84696
31.70000,-5.28332,-3.85132
31.80000,-5.29972,-3.85848
31.90000,-5.31679,-3.86569
32.00000,-5.33319,-3.87077
32.10000,-5.34972,-3.87749
32.20000,-5.36652,-3.88314
32.30000,-5.38305,-3.89152
32.40000,-5.39999,-3.89849
32.50000,-5.41665,-3.90324
32.60000,-5.43332,-3.90876
32.70000,-5.44985,-3.91521
32.80000,-5.46679,-3.92136
32.90000,-5.48319,-3.92428
33.00000,-5.49985,-3.93170
33.10000,-5.51665,-3.93519
33.20000,-5.53319,-3.94089
33.30000,-5.55012,-3.94659
33.40000,-5.56665,-3.95034
33.50000,-5.58332,-3.95502
33.60000,-5.59999,-3.96048
33.70000,-5.61652,-3.96622
33.80000,-5.63305,-3.96950
33.90000,-5.64999,-3.97512
34.00000,-5.66679,-3.97803
34.10000,-5.68319,-3.98340
34.20000,-5.70012,-3.98768
34.30000,-5.71652,-3.99155
34.40000,-5.73319,-3.99544
34.50000,-5.74985,-3.99961
34.60000,-5.76639,-4.00265
34.70000,-5.78319,-4.00743
34.80000,-5.79999,-4.01294
34.90000,-5.81665,-4.01586
35.00000,-5.83305,-4.02030
35.10000,-5.84999,-4.02468
35.20000,-5.86639,-4.02726
35.30000,-5.88305,-4.03228
35.40000,-5.89985,-4.03656
35.50000,-5.91639,-4.04255
35.60000,-5.93332,-4.04716
35.70000,-5.95012,-4.05163
35.80000,-5.96665,-4.05588
35.90000,-5.98305,-4.06101
36.00000,-5.99999,-4.06711
36.10000,-6.01639,-4.07000
36.20000,-6.03305,-4.07597
36.30000,-6.04999,-4.08056
36.40000,-6.06652,-4.08504
36.50000,-6.08345,-4.09130
36.60000,-6.09998,-4.09575
36.70000,-6.11665,-4.10102
36.80000,-6.13319,-4.10605
36.90000,-6.14998,-4.11070
37.00000,-6.16652,-4.11373
37.10000,-6.18319,-4.11935
37.20000,-6.20012,-4.12444
37.30000,-6.21652,-4.12858
37.40000,-6.23345,-4.13276
37.50000,-6.24972,-4.13602
37.60000,-6.26652,-4.13967
37.70000,-6.28318,-4.14440
37.80000,-6.29958,-4.14761
37.90000,-6.31652,-4.15300
38.00000,-6.33332,-4.15723
38.10000,-6.34998,-4.16035
38.20000,-6.36638,-4.16823
38.30000,-6.38345,-4.17082
38.40000,-6.39972,-4.16920
38.50000,-6.41625,-4.17727
38.60000,-6.43332,-4.18291
38.70000,-6.44985,-4.18538
38.80000,-6.46665,-4.18452
38.90000,-6.48332,-4.19261
39.00000,-6.50012,-4.19159
39.10000,-6.51652,-4.19534
39.20000,-6.53332,-4.19747
39.30000,-6.54985,-4.20027
39.40000,-6.56638,-4.20693
39.50000,-6.58345,-4.20684
39.60000,-6.59985,-4.20567
39.70000,-6.61678,-4.21308
39.80000,-6.63345,-4.21428
39.90000,-6.64998,-4.21584
40.00000,-6.66652,-4.22303
40.10000,-6.68318,-4.22469
40.20000,-6.69972,-4.22241
40.30000,-6.71665,-4.22791
40.40000,-6.73345,-4.22505
40.50000,-6.74985,-4.23035
40.60000,-6.76678,-4.23309
40.70000,-6.78332,-4.23176
40.80000,-6.79985,-4.23719
40.90000,-6.81665,-4.23346
41.00000,-6.83305,-4.22728
41.10000,-6.84972,-4.22502
41.20000,-6.86652,-4.23219
41.30000,-6.88332,-4.23489
41.40000,-6.89972,-4.23344
41.50000,-6.91665,-4.23826
41.60000,-6.93318,-4.23613
41.70000,-6.94972,-4.23648
41.80000,-6.96652,-4.23859
41.90000,-6.98305,-4.23802
42.00000,-6.99985,-4.24246
42.10000,-7.01652,-4.24900
42.20000,-7.03332,-4.24431
42.30000,-7.04985,-4.23751
42.40000,-7.06665,-4.23144
42.50000,-7.08318,-4.23390
42.60000,-7.09985,-4.23784
42.70000,-7.11678,-4.23709
42.80000,-7.13318,-4.23773
42.90000,-7.15012,-4.24287
43.00000,-7.16678,-4.24574
43.10000,-7.18332,-4.24703
43.20000,-7.19985,-4.24982
43.30000,-7.21652,-4.25044
43.40000,-7.23318,-4.25592
43.50000,-7.24985,-4.25852
43.60000,-7.26678,-4.25862
43.70000,-7.28318,-4.25808
43.80000,-7.30012,-4.25739
43.90000,-7.31652,-4.25625
44.00000,-7.33305,-4.25938
44.10000,-7.34972,-4.25686
44.20000,-7.36638,-4.25719
44.30000,-7.38318,-4.25833
44.40000,-7.39985,-4.25745
44.50000,-7.41665,-4.26042
44.60000,-7.43305,-4.25993
44.70000,-7.45011,-4.26383
44.80000,-7.46638,-4.26162
44.90000,-7.48305,-4.26193
45.00000,-7.49985,-4.26339
45.10000,-7.51638,-4.26482
45.20000,-7.53332,-4.26593
45.30000,-7.54998,-4.26489
45.40000,-7.56665,-4.26555
45.50000,-7.58318,-4.26905
45.60000,-7.59998,-4.26939
45.70000,-7.61638,-4.27097
45.80000,-7.63305,-4.27420
45.90000,-7.65011,-4.27780
46.00000,-7.66651,-4.28111
46.10000,-7.68345,-4.28469
46.20000,-7.70011,-4.28679
46.30000,-7.71651,-4.28752
46.40000,-7.73318,-4.28969
46.50000,-7.74985,-4.29409
46.60000,-7.76651,-4.29408
46.70000,-7.78331,-4.29746
46.80000,-7.80011,-4.29803
46.90000,-7.81651,-4.29881
47.00000,-7.83345,-4.30254
47.10000,-7.84985,-4.30298
47.20000,-7.86651,-4.30565
47.30000,-7.88318,-4.30627
47.40000,-7.89971,-4.30848
47.50000,-7.91651,-4.31112
47.60000,-7.93331,-4.31511
47.70000,-7.95011,-4.32217
47.80000,-7.96651,-4.32052
47.90000,-7.98345,-4.32476
48.00000,-7.99971,-4.32659
48.10000,-8.01638,-4.33119
48.20000,-8.03331,-4.33555
48.30000,-8.04985,-4.34046
48.40000,-8.06665,-4.34383
48.50000,-8.08318,-4.34514
48.60000,-8.09998,-4.34936
48.70000,-8.11665,-4.35541
48.80000,-8.13345,-4.35911
48.90000,-8.14985,-4.36056
49.00000,-8.16638,-4.36560
49.10000,-8.18345,-4.36897
49.20000,-8.19985,-4.37419
49.30000,-8.21678,-4.38085
49.40000,-8.23331,-4.38458
49.50000,-8.24998,-4.38829
49.60000,-8.26651,-4.39315
49.70000,-8.28331,-4.39691
49.80000,-8.29998,-4.40359
49.90000,-8.31665,-4.41047
50.00000,-8.33345,-4.41455
50.10000,-8.34985,-4.41810
50.20000,-8.36678,-4.42499
50.30000,-8.38331,-4.42714
50.40000,-8.39985,-4.43247
50.50000,-8.41651,-4.43869
50.60000,-8.43305,-4.44173
50.70000,-8.44985,-4.44696
50.80000,-8.46665,-4.45322
50.90000,-8.48331,-4.45701
51.00000,-8.49971,-4.46339
51.10000,-8.51678,-4.46772
51.20000,-8.53318,-4.47144
51.30000,-8.54985,-4.47703
51.40000,-8.56651,-4.48100
51.50000,-8.58318,-4.48756
51.60000,-8.59998,-4.49067
51.70000,-8.61678,-4.49575
51.80000,-8.63345,-4.49840
51.90000,-8.64985,-4.50211
52.00000,-8.66665,-4.50679
52.10000,-8.68318,-4.51014
52.20000,-8.69985,-4.51678
52.30000,-8.71678,-4.51994
52.40000,-8.73318,-4.52748
52.50000,-8.74998,-4.52839
52.60000,-8.76665,-4.53246
52.70000,-8.78331,-4.53727
52.80000,-8.79998,-4.53980
52.90000,-8.81665,-4.54565
53.00000,-8.83318,-4.54778
53.10000,-8.84998,-4.55252
53.20000,-8.86678,-4.55460
53.30000,-8.88318,-4.55754
53.40000,-8.90024,-4.56249
53.50000,-8.91665,-4.56628
53.60000,-8.93318,-4.56918
53.70000,-8.94998,-4.57301
53.80000,-8.96651,-4.57907
53.90000,-8.98318,-4.58332
54.00000,-8.99985,-4.58909
54.10000,-9.01665,-4.59339
54.20000,-9.03304,-4.59880
54.30000,-9.04998,-4.60279
54.40000,-9.06638,-4.60646
54.50000,-9.08304,-4.61186
54.60000,-9.09998,-4.61602
54.70000,-9.11651,-4.62147
54.80000,-9.13331,-4.62693
54.90000,-9.14998,-4.63334
55.00000,-9.16664,-4.63614
55.10000,-9.18304,-4.64290
55.20000,-9.20011,-4.64705
55.30000,-9.21651,-4.65114
55.40000,-9.23318,-4.65534
55.50000,-9.25011,-4.65961
55.60000,-9.26651,-4.66241
55.70000,-9.28358,-4.67038
55.80000,-9.30011,-4.67329
55.90000,-9.31651,-4.67663
56.00000,-9.33304,-4.67991
56.10000,-9.34984,-4.68510
56.20000,-9.36638,-4.68822
56.30000,-9.38318,-4.69308
56.40000,-9.40011,-4.69750
56.50000,-9.41664,-4.70165
56.60000,-9.43371,-4.70497
56.70000,-9.44998,-4.70910
56.80000,-9.46664,-4.71082
56.90000,-9.48318,-4.71502
57.00000,-9.49984,-4.71859
57.10000,-9.51638,-4.72247
57.20000,-9.53331,-4.72813
57.30000,-9.55011,-4.73275
57.40000,-9.56651,-4.73664
57.50000,-9.58331,-4.74185
57.60000,-9.59971,-4.74518
57.70000,-9.61651,-4.75099
57.80000,-9.63318,-4.75483
57.90000,-9.64998,-4.75959
58.00000,-9.66678,-4.76447
58.10000,-9.68331,-4.76974
58.20000,-9.70011,-4.77385
58.30000,-9.71651,-4.77903
58.40000,-9.73344,-4.78410
58.50000,-9.74984,-4.78658
58.60000,-9.76651,-4.79242
58.70000,-9.78344,-4.79650
58.80000,-9.79998,-4.80207
58.90000,-9.81678,-4.80651
59.00000,-9.83344,-4.81069
59.10000,-9.85011,-4.81636
59.20000,-9.86664,-4.82158
59.30000,-9.88331,-4.82686
59.40000,-9.89984,-4.83132
59.50000,-9.91651,-4.83722
59.60000,-9.93331,-4.84134
59.70000,-9.94984,-4.84676
59.80000,-9.96678,-4.85302
59.90000,-9.98304,-4.85589
60.00000,-9.99984,-4.86101
60.10000,-10.01651,-4.86608
60.20000,-10.03304,-4.86932
60.30000,-10.04984,-4.87428
60.40000,-10.06664,-4.87980
60.50000,-10.08331,-4.88315
60.60000,-10.09984,-4.88805
60.70000,-10.11691,-4.89444
60.80000,-10.13318,-4.89742
60.90000,-10.14971,-4.90169
61.00000,-10.16651,-4.90625
61.10000,-10.18318,-4.91134
61.20000,-10.19998,-4.91610
61.30000,-10.21664,-4.92039
61.40000,-10.23344,-4.92429
61.50000,-10.24984,-4.92785
61.60000,-10.26664,-4.93281
61.70000,-10.28317,-4.93501
61.80000,-10.29984,-4.93881
61.90000,-10.31664,-4.94193
62.00000,-10.33317,-4.94455
62.10000,-10.35011,-4.95102
62.20000,-10.36678,-4.95542
62.30000,-10.38344,-4.95826
62.40000,-10.39984,-4.96131
62.50000,-10.41664,-4.96629
62.60000,-10.43317,-4.96911
62.70000,-10.44984,-4.97449
62.80000,-10.46677,-4.97948
62.90000,-10.48317,-4.98431
63.00000,-10.50011,-4.98962
63.10000,-10.51651,-4.99296
63.20000,-10.53317,-4.99917
63.30000,-10.54984,-5.00358
63.40000,-10.56637,-5.00812
63.50000,-10.58317,-5.01213
63.60000,-10.59984,-5.01879
63.70000,-10.61691,-5.02456
63.80000,-10.63317,-5.02979
63.90000,-10.64997,-5.03558
64.00000,-10.66637,-5.03967
64.10001,-10.68317,-5.04545
64.20000,-10.69997,-5.04997
64.30000,-10.71651,-5.05610
64.40000,-10.73317,-5.06142
64.50000,-10.74997,-5.06731
64.60001,-10.76677,-5.07314
64.70000,-10.78317,-5.07901
64.80000,-10.80011,-5.08430
64.90000,-10.81624,-5.08728
65.00000,-10.83304,-5.09360
65.10001,-10.84997,-5.10075
65.20000,-10.86651,-5.10720
65.30000,-10.88344,-5.11239
65.40000,-10.89997,-5.11648
65.50000,-10.91677,-5.12218
65.60001,-10.93317,-5.12689
65.70001,-10.94997,-5.13269
65.80000,-10.96664,-5.13570
65.90000,-10.98331,-5.13945
66.00000,-11.00011,-5.14325
66.10001,-11.01664,-5.14894
66.20001,-11.03357,-5.15533
66.30000,-11.04984,-5.15917
66.40000,-11.06651,-5.16320
66.50000,-11.08317,-5.16853
66.60001,-11.09971,-5.17312
66.70001,-11.11651,-5.17959
66.80000,-11.13331,-5.18600
66.90000,-11.15011,-5.19091
67.00000,-11.16651,-5.19670
67.10001,-11.18357,-5.20423
67.20001,-11.19997,-5.20875
67.30000,-11.21651,-5.21536
67.40000,-11.23331,-5.22187
67.50000,-11.24984,-5.22807
67.60001,-11.26664,-5.23471
67.70001,-11.28344,-5.24214
67.80000,-11.30011,-5.24804
67.90000,-11.31637,-5.25399
68.00000,-11.33331,-5.26008
68.10001,-11.34971,-5.26489
68.20001,-11.36637,-5.27187
68.30000,-11.38331,-5.27811
68.40000,-11.39984,-5.28324
68.50000,-11.41691,-5.29070
68.60001,-11.43344,-5.29383
68.70001,-11.45011,-5.29689
68.80000,-11.46664,-5.30147
68.90000,-11.48331,-5.30501
69.00000,-11.49997,-5.30580
69.10001,-11.51664,-5.31395
69.20001,-11.53344,-5.31842
69.30000,-11.54984,-5.32120
69.40000,-11.56677,-5.32708
69.50000,-11.58304,-5.32885
69.60001,-11.59970,-5.33132
69.70001,-11.61650,-5.33567
69.80000,-11.63317,-5.34110
69.90000,-11.64984,-5.34420
70.00000,-11.66664,-5.35233
70.10001,-11.68344,-5.35712
70.20001,-11.69970,-5.36148
70.30000,-11.71677,-5.36782
70.40000,-11.73317,-5.37053
70.50000,-11.74970,-5.37562
70.60001,-11.76650,-5.37943
70.70001,-11.78317,-5.38757
70.80000,-11.79997,-5.39229
70.90000,-11.81664,-5.39825
71.00000,-11.83330,-5.40104
71.10001,-11.84984,-5.40616
71.20001,-11.86677,-5.41195
71.30000,-11.88317,-5.41393
71.40000,-11.89984,-5.42060
71.50000,-11.91677,-5.42476
71.60001,-11.93330,-5.42978
71.70001,-11.95024,-5.43584
71.80000,-11.96677,-5.43976
71.90000,-11.98330,-5.44218
72.00000,-11.99984,-5.44567
72.10001,-12.01664,-5.45041
72.20001,-12.03317,-5.45283
72.30000,-12.04970,-5.45916
72.40000,-12.06650,-5.46289
72.50000,-12.08317,-5.46919
72.60001,-12.10010,-5.47314
72.70001,-12.11664,-5.47995
72.80000,-12.13330,-5.48298
72.90000,-12.14997,-5.48823
73.00000,-12.16650,-5.49155
73.10001,-12.18317,-5.49555
73.20001,-12.19984,-5.49999
73.30000,-12.21664,-5.50461
73.40000,-12.23317,-5.51098
73.50000,-12.25024,-5.51679
73.60001,-12.26650,-5.51932
73.70001,-12.28304,-5.52529
73.80000,-12.29984,-5.53034
73.90000,-12.31650,-5.53811
74.00000,-12.33330,-5.54589
74.10001,-12.34997,-5.54913
74.20001,-12.36664,-5.55705
74.30000,-12.38317,-5.56168
74.40000,-12.40010,-5.56774
74.50000,-12.41650,-5.57070
74.60001,-12.43304,-5.57748
74.70001,-12.45010,-5.58160
74.80000,-12.46650,-5.58757
74.90000,-12.48344,-5.59365
75.00000,-12.49997,-5.59714
75.10001,-12.51677,-5.60268
75.20001,-12.53330,-5.60751
75.30000,-12.54984,-5.61226
75.40000,-12.56650,-5.61606
75.50000,-12.58317,-5.62124
75.60001,-12.60010,-5.62826
75.70001,-12.61664,-5.63270
75.80000,-12.63357,-5.63724
75.90000,-12.64984,-5.64053
76.00000,-12.66637,-5.64096
76.10001,-12.68304,-5.64461
76.20001,-12.69970,-5.64730
76.30000,-12.71637,-5.65174
76.40000,-12.73317,-5.65594
76.50000,-12.74997,-5.65917
76.60001,-12.76650,-5.66251
76.70001,-12.78344,-5.66671
76.80000,-12.79984,-5.66463
76.90000,-12.81637,-5.66698
77.00000,-12.83317,-5.66596
77.10001,-12.84984,-5.66648
77.20001,-12.86663,-5.66724
77.30000,-12.88330,-5.66895
77.40000,-12.90010,-5.66949
77.50000,-12.91650,-5.67081
77.60001,-12.93343,-5.67179
77.70001,-12.94970,-5.67089
77.80000,-12.96650,-5.67438
77.90000,-12.98343,-5.67612
78.00000,-12.99983,-5.68008
78.10001,-13.01677,-5.68314
78.20001,-13.03330,-5.68642
78.30000,-13.04997,-5.68939
78.40000,-13.06650,-5.69243
78.50000,-13.08330,-5.69426
78.60001,-13.09997,-5.69594
78.70001,-13.11663,-5.70189
78.80000,-13.13343,-5.70498
78.90000,-13.14983,-5.71013
79.00000,-13.16677,-5.71288
79.10001,-13.18317,-5.71293
79.20001,-13.19970,-5.71054
79.30000,-13.21650,-5.71450
79.40000,-13.23303,-5.71463
79.50000,-13.24983,-5.71962
79.60001,-13.26663,-5.72339
79.70001,-13.28343,-5.72415
79.80000,-13.29983,-5.72782
79.90000,-13.31677,-5.73203
80.00000,-13.33303,-5.73539
80.10001,-13.34970,-5.74286
80.20001,-13.36650,-5.74567
80.30000,-13.38303,-5.74962
80.40000,-13.39997,-5.75569
80.50001,-13.41690,-5.76169
80.60001,-13.43343,-5.76761
80.70001,-13.44983,-5.77525
80.80000,-13.46677,-5.78177
80.90000,-13.48317,-5.78455
81.00001,-13.49983,-5.79162
81.10001,-13.51677,-5.79858
81.20001,-13.53330,-5.80694
81.30000,-13.55023,-5.81724
81.40000,-13.56663,-5.82251
81.50001,-13.58330,-5.82685
81.60001,-13.59997,-5.83493
81.70001,-13.61663,-5.84258
81.80000,-13.63317,-5.84805
81.90000,-13.64997,-5.85873
82.00001,-13.66677,-5.86537
82.10001,-13.68330,-5.87044
82.20001,-13.70010,-5.87825
82.30000,-13.71650,-5.88155
82.40000,-13.73317,-5.88502
82.50001,-13.74983,-5.88944
82.60001,-13.76637,-5.89882
82.70001,-13.78317,-5.90441
82.80000,-13.79983,-5.91083
82.90000,-13.81677,-5.91364
83.00001,-13.83317,-5.91808
83.10001,-13.85010,-5.92514
83.20001,-13.86650,-5.93113
83.30000,-13.88303,-5.94005
83.40000,-13.89983,-5.94548
83.50001,-13.91650,-5.95275
83.60001,-13.93343,-5.96058
83.70001,-13.95010,-5.96937
83.80000,-13.96677,-5.97658
83.90000,-13.98317,-5.98285
84.00001,-14.00010,-5.98795
84.10001,-14.01650,-5.99262
84.20001,-14.03317,-5.99945
84.30000,-14.04997,-6.00641
84.40000,-14.06650,-6.01323
84.50001,-14.08357,-6.02157
84.60001,-14.10010,-6.02543
84.70001,-14.11663,-6.03110
84.80000,-14.13330,-6.03501
84.90000,-14.14997,-6.04193
85.00001,-14.16650,-6.04614
85.10001,-14.18317,-6.05356
85.20001,-14.19997,-6.05936
85.30000,-14.21650,-6.06688
85.40000,-14.23356,-6.07277
85.50001,-14.24983,-6.07839
85.60001,-14.26650,-6.08566
85.70001,-14.28317,-6.09312
85.80000,-14.29983,-6.10128
85.90000,-14.31650,-6.10797
86.00001,-14.33330,-6.11730
86.10001,-14.35010,-6.12486
86.20001,-14.36637,-6.13411
86.30000,-14.38343,-6.14590
86.40000,-14.39983,-6.15146
86.50001,-14.41650,-6.16079
86.60001,-14.43317,-6.16586
86.70001,-14.44983,-6.17394
86.80000,-14.46663,-6.18277
86.90000,-14.48330,-6.19107
87.00001,-14.50010,-6.19804
87.10001,-14.51650,-6.20265
87.20001,-14.53343,-6.20930
87.30000,-14.54970,-6.21658
87.40000,-14.56636,-6.22891
87.50001,-14.58343,-6.23987
87.60001,-14.59996,-6.25253
87.70001,-14.61690,-6.26431
87.80000,-14.63343,-6.27577
87.90000,-14.65010,-6.28687
88.00001,-14.66663,-6.30088
88.10001,-14.68330,-6.31235
88.20001,-14.69983,-6.32200
88.30000,-14.71650,-6.33594
88.40000,-14.73343,-6.34840
88.50001,-14.74996,-6.36174
88.60001,-14.76690,-6.37351
88.70001,-14.78316,-6.38327
88.80000,-14.79983,-6.39446
88.90000,-14.81650,-6.40468
89.00001,-14.83303,-6.41602
89.10001,-14.84983,-6.42893
89.20001,-14.86663,-6.44404
89.30000,-14.88343,-6.45367
89.40000,-14.89983,-6.46635
89.50001,-14.91676,-6.48090
89.60001,-14.93316,-6.48858
89.70001,-14.94983,-6.50086
89.80000,-14.96663,-6.51110
89.90000,-14.98316,-6.52320
90.00001,-14.99996,-6.53631
90.09600,-15.01596,-6.54788