File: GFBaking/data/1TspPectin/1TspPectin.is_comp_RawData/Specimen_RawData_1.csv
Time,Extension,Load
(sec),(mm),(N)
0.00000,0.00000,-0.00209
0.10000,-0.00480,-0.00413
0.20000,-0.02467,-0.01797
0.30000,-0.04507,-0.03584
0.40000,-0.06387,-0.05121
0.50000,-0.08173,-0.06558
0.60000,-0.09920,-0.08096
0.70000,-0.11627,-0.09533
0.80000,-0.13280,-0.10891
0.90000,-0.14987,-0.12402
1.00000,-0.16627,-0.13947
1.10000,-0.18320,-0.15548
1.20000,-0.20000,-0.17113
1.30000,-0.21680,-0.18708
1.40000,-0.23347,-0.20240
1.50000,-0.25013,-0.21993
1.60000,-0.26680,-0.23743
1.70000,-0.28307,-0.25680
1.80000,-0.29987,-0.27779
1.90000,-0.31653,-0.29993
2.00000,-0.33333,-0.32362
2.10000,-0.35013,-0.34825
2.20000,-0.36640,-0.37325
2.30000,-0.38333,-0.39894
2.40000,-0.39987,-0.42629
2.50000,-0.41640,-0.45184
2.60000,-0.43293,-0.48071
2.70000,-0.44987,-0.50827
2.80000,-0.46653,-0.53875
2.90000,-0.48347,-0.57154
3.00000,-0.50013,-0.59713
3.10000,-0.51667,-0.62752
3.20000,-0.53333,-0.65676
3.30000,-0.54960,-0.68624
3.40000,-0.56653,-0.71595
3.50000,-0.58333,-0.74915
3.60000,-0.60013,-0.78420
3.70000,-0.61680,-0.81471
3.80000,-0.63347,-0.84856
3.90000,-0.65000,-0.88112
4.00000,-0.66653,-0.91466
4.10000,-0.68320,-0.94944
4.20000,-0.69973,-0.98059
4.30000,-0.71666,-1.01744
4.40000,-0.73346,-1.05172
4.50000,-0.75000,-1.08581
4.60000,-0.76680,-1.12133
4.70000,-0.78346,-1.15526
4.80000,-0.80000,-1.18569
4.90000,-0.81653,-1.21997
5.00000,-0.83333,-1.25468
5.10000,-0.84986,-1.28858
5.20000,-0.86666,-1.32336
5.30000,-0.88346,-1.35884
5.40000,-0.90000,-1.39481
5.50000,-0.91680,-1.42693
5.60000,-0.93333,-1.45723
5.70000,-0.95000,-1.49174
5.80000,-0.96640,-1.52435
5.90000,-0.98333,-1.55740
6.00000,-0.99986,-1.58569
6.10000,-1.01666,-1.60878
6.20000,-1.03346,-1.64206
6.30000,-1.04986,-1.66899
6.40000,-1.06666,-1.69063
6.50000,-1.08306,-1.70959
6.60000,-1.09973,-1.72654
6.70000,-1.11653,-1.76253
6.80000,-1.13333,-1.80088
6.90000,-1.15000,-1.83798
7.00000,-1.16680,-1.87499
7.10000,-1.18346,-1.90877
7.20000,-1.19973,-1.94520
7.30000,-1.21653,-1.97786
7.40000,-1.23306,-2.01197
7.50000,-1.25000,-2.04601
7.60000,-1.26680,-2.08163
7.70000,-1.28306,-2.11565
7.80000,-1.30000,-2.15016
7.90000,-1.31693,-2.18328
8.00000,-1.33346,-2.21763
8.10000,-1.34960,-2.25027
8.20000,-1.36653,-2.28163
8.30000,-1.38320,-2.30242
8.40000,-1.39986,-2.32346
8.50000,-1.41693,-2.29777
8.60000,-1.43333,-2.34472
8.70000,-1.45026,-2.38215
8.80000,-1.46666,-2.41420
8.90000,-1.48333,-2.44342
9.00000,-1.49973,-2.42394
9.10000,-1.51666,-2.46716
9.20000,-1.53320,-2.50105
9.30000,-1.55000,-2.53758
9.40000,-1.56680,-2.57252
9.50000,-1.58320,-2.60663
9.60000,-1.60000,-2.64236
9.70000,-1.61626,-2.67188
9.80000,-1.63293,-2.70329
9.90000,-1.64973,-2.73578
10.00000,-1.66653,-2.76900
10.10000,-1.68333,-2.80232
10.20000,-1.70013,-2.83469
10.30000,-1.71680,-2.86389
10.40000,-1.73320,-2.89492
10.50000,-1.75026,-2.92634
10.60000,-1.76653,-2.95627
10.70000,-1.78320,-2.98576
10.80000,-1.80000,-3.01596
10.90000,-1.81680,-3.04420
11.00000,-1.83346,-3.07060
11.10000,-1.85026,-3.10017
11.20000,-1.86666,-3.12720
11.30000,-1.88293,-3.15518
11.40000,-1.90000,-3.18357
11.50000,-1.91640,-3.21036
11.60000,-1.93320,-3.24039
11.70000,-1.95013,-3.26812
11.80000,-1.96680,-3.29765
11.90000,-1.98360,-3.32635
12.00000,-2.00013,-3.35298
12.10000,-2.01666,-3.37923
12.20000,-2.03306,-3.40589
12.30000,-2.04986,-3.43409
12.40000,-2.06653,-3.46019
12.50000,-2.08346,-3.49028
12.60000,-2.10013,-3.51609
12.70000,-2.11666,-3.54330
12.80000,-2.13333,-3.57012
12.90000,-2.14973,-3.59614
13.00000,-2.16653,-3.62276
13.10000,-2.18319,-3.64889
13.20000,-2.19986,-3.67518
13.30000,-2.21666,-3.70386
13.40000,-2.23333,-3.72837
13.50000,-2.24999,-3.75140
13.60000,-2.26626,-3.77860
13.70000,-2.28333,-3.80565
13.80000,-2.29959,-3.83251
13.90000,-2.31666,-3.86002
14.00000,-2.33346,-3.88584
14.10000,-2.35013,-3.90835
14.20000,-2.36666,-3.93417
14.30000,-2.38333,-3.95857
14.40000,-2.40013,-3.98242
14.50000,-2.41653,-4.00788
14.60000,-2.43346,-4.03665
14.70000,-2.44986,-4.05886
14.80000,-2.46666,-4.08140
14.90000,-2.48359,-4.10447
15.00000,-2.49999,-4.12883
15.10000,-2.51666,-4.15143
15.20000,-2.53319,-4.17563
15.30000,-2.54973,-4.19699
15.40000,-2.56626,-4.21871
15.50000,-2.58346,-4.24176
15.60000,-2.60013,-4.26146
15.70000,-2.61679,-4.28470
15.80000,-2.63346,-4.30032
15.90000,-2.64999,-4.32434
16.00000,-2.66666,-4.34407
16.10000,-2.68293,-4.36548
16.20000,-2.69986,-4.38801
16.30000,-2.71653,-4.40875
16.40000,-2.73333,-4.43071
16.50000,-2.75013,-4.45021
16.60000,-2.76666,-4.47156
16.70000,-2.78333,-4.49340
16.80000,-2.79986,-4.51626
16.90000,-2.81666,-4.54141
17.00000,-2.83306,-4.55800
17.10000,-2.84973,-4.57363
17.20000,-2.86653,-4.59712
17.30000,-2.88319,-4.62099
17.40000,-2.89986,-4.63756
17.50000,-2.91666,-4.65214
17.60000,-2.93333,-4.66572
17.70000,-2.94973,-4.68041
17.80000,-2.96666,-4.70019
17.90000,-2.98306,-4.71456
18.00000,-3.00013,-4.73391
18.10000,-3.01706,-4.75047
18.20000,-3.03346,-4.76850
18.30000,-3.05013,-4.77766
18.40000,-3.06666,-4.78937
18.50000,-3.08333,-4.81526
18.60000,-3.09986,-4.83527
18.70000,-3.11679,-4.85151
18.80000,-3.13319,-4.86697
18.90000,-3.14999,-4.88581
19.00000,-3.16653,-4.90318
19.10000,-3.18306,-4.92005
19.20000,-3.19986,-4.93448
19.30000,-3.21639,-4.94926
19.40000,-3.23333,-4.96040
19.50000,-3.24999,-4.97951
19.60000,-3.26666,-4.99932
19.70000,-3.28319,-5.01295
19.80000,-3.29999,-5.02841
19.90000,-3.31666,-5.04046
20.00000,-3.33306,-5.05381
20.10000,-3.34999,-5.06397
20.20000,-3.36639,-5.07786
20.30000,-3.38333,-5.09268
20.40000,-3.40013,-5.10537
20.50000,-3.41666,-5.11821
20.60000,-3.43332,-5.13305
20.70000,-3.45012,-5.15029
20.80000,-3.46679,-5.15898
20.90000,-3.48306,-5.17344
21.00000,-3.49999,-5.19273
21.10000,-3.51652,-5.20359
21.20000,-3.53346,-5.22002
21.30000,-3.55026,-5.23136
21.40000,-3.56666,-5.24388
21.50000,-3.58332,-5.25927
21.60000,-3.59986,-5.27008
21.70000,-3.61652,-5.28517
21.80000,-3.63306,-5.30295
21.90000,-3.64999,-5.31266
22.00000,-3.66652,-5.32577
22.10000,-3.68332,-5.33942
22.20000,-3.70012,-5.35366
22.30000,-3.71652,-5.36895
22.40000,-3.73332,-5.37965
22.50000,-3.74972,-5.38953
22.60000,-3.76652,-5.39725
22.70000,-3.78319,-5.41111
22.80000,-3.79999,-5.42342
22.90000,-3.81652,-5.42786
23.00000,-3.83346,-5.43648
23.10000,-3.84999,-5.44786
23.20000,-3.86639,-5.46505
23.30000,-3.88346,-5.47390
23.40000,-3.89972,-5.48610
23.50000,-3.91666,-5.50003
23.60000,-3.93346,-5.51382
23.70000,-3.94999,-5.53096
23.80000,-3.96666,-5.54228
23.90000,-3.98346,-5.55228
24.00000,-4.00012,-5.55987
24.10000,-4.01639,-5.57079
24.20000,-4.03332,-5.59152
24.30000,-4.04986,-5.60286
24.40000,-4.06666,-5.60959
24.50000,-4.08346,-5.62029
24.60000,-4.09999,-5.63192
24.70000,-4.11666,-5.64414
24.80000,-4.13332,-5.65503
24.90000,-4.14999,-5.66358
25.00000,-4.16639,-5.67281
25.10000,-4.18332,-5.68232
25.20000,-4.19986,-5.69413
25.30000,-4.21666,-5.70708
25.40000,-4.23332,-5.71862
25.50000,-4.24986,-5.72893
25.60000,-4.26666,-5.73841
25.70000,-4.28306,-5.74525
25.80000,-4.29986,-5.75558
25.90000,-4.31652,-5.76642
26.00000,-4.33332,-5.77629
26.10000,-4.34999,-5.78623
26.20000,-4.36679,-5.79371
26.30000,-4.38332,-5.80130
26.40000,-4.39972,-5.81756
26.50000,-4.41666,-5.82885
26.60000,-4.43292,-5.83812
26.70000,-4.44986,-5.85021
26.80000,-4.46666,-5.86075
26.90000,-4.48346,-5.87393
27.00000,-4.50012,-5.88461
27.10000,-4.51679,-5.89703
27.20000,-4.53346,-5.90644
27.30000,-4.54986,-5.91576
27.40000,-4.56679,-5.92459
27.50000,-4.58332,-5.93540
27.60000,-4.59999,-5.94764
27.70000,-4.61692,-5.95732
27.80000,-4.63332,-5.96757
27.90000,-4.65012,-5.97952
28.00000,-4.66666,-5.98853
28.10000,-4.68319,-5.99599
28.20000,-4.69972,-6.00843
28.30000,-4.71666,-6.01873
28.40000,-4.73332,-6.02891
28.50000,-4.74999,-6.03663
28.60000,-4.76679,-6.04546
28.70000,-4.78319,-6.05478
28.80000,-4.79999,-6.06499
28.90000,-4.81639,-6.07330
29.00000,-4.83319,-6.08359
29.10000,-4.84985,-6.09328
29.20000,-4.86679,-6.10484
29.30000,-4.88332,-6.11506
29.40000,-4.90012,-6.12666
29.50000,-4.91679,-6.13638
29.60000,-4.93319,-6.14480
29.70000,-4.94999,-6.15487
29.80000,-4.96639,-6.16474
29.90000,-4.98305,-6.17318
30.00000,-4.99999,-6.18399
30.10000,-5.01679,-6.19494
30.20000,-5.03332,-6.20307
30.30000,-5.05012,-6.21420
30.40000,-5.06665,-6.22224
30.50000,-5.08292,-6.23215
30.60000,-5.09999,-6.24276
30.70000,-5.11652,-6.25504
30.80000,-5.13319,-6.26291
30.90000,-5.15012,-6.27326
31.00000,-5.16665,-6.28180
31.10000,-5.18332,-6.28937
31.20000,-5.19985,-6.29735
31.30000,-5.21665,-6.30598
31.40000,-5.23305,-6.31621
31.50000,-5.25012,-6.32334
31.60000,-5.26665,-6.33058
31.70000,-5.28332,-6.33761
31.80000,-5.30012,-6.34546
31.90000,-5.31652,-6.35308
32.00000,-5.33332,-6.35712
32.10000,-5.34972,-6.36328
32.20000,-5.36639,-6.37028
32.30000,-5.38319,-6.37767
32.40000,-5.39999,-6.38548
32.50000,-5.41665,-6.39197
32.60000,-5.43332,-6.39865
32.70000,-5.44999,-6.40403
32.80000,-5.46652,-6.40961
32.90000,-5.48345,-6.41690
33.00000,-5.49972,-6.42104
33.10000,-5.51665,-6.42846
33.20000,-5.53345,-6.43192
33.30000,-5.55012,-6.43703
33.40000,-5.56665,-6.44030
33.50000,-5.58345,-6.44584
33.60000,-5.60012,-6.44787
33.70000,-5.61639,-6.45113
33.80000,-5.63332,-6.45536
33.90000,-5.64999,-6.45955
34.00000,-5.66665,-6.46282
34.10000,-5.68345,-6.46399
34.20000,-5.69985,-6.46568
34.30000,-5.71665,-6.46965
34.40000,-5.73332,-6.47186
34.50000,-5.74985,-6.47490
34.60000,-5.76639,-6.47790
34.70000,-5.78332,-6.48208
34.80000,-5.79985,-6.48373
34.90000,-5.81679,-6.48790
35.00000,-5.83345,-6.49038
35.10000,-5.84972,-6.49170
35.20000,-5.86665,-6.49557
35.30000,-5.88319,-6.49871
35.40000,-5.89985,-6.49920
35.50000,-5.91665,-6.50259
35.60000,-5.93332,-6.50724
35.70000,-5.94999,-6.50892
35.80000,-5.96679,-6.51397
35.90000,-5.98345,-6.51661
36.00000,-5.99972,-6.52087
36.10000,-6.01665,-6.52435
36.20000,-6.03305,-6.52416
36.30000,-6.04972,-6.52824
36.40000,-6.06665,-6.53696
36.50000,-6.08319,-6.54261
36.60000,-6.09998,-6.54768
36.70000,-6.11679,-6.55273
36.80000,-6.13332,-6.55533
36.90000,-6.14985,-6.56318
37.00000,-6.16665,-6.56870
37.10000,-6.18319,-6.57263
37.20000,-6.19998,-6.58188
37.30000,-6.21692,-6.58575
37.40000,-6.23318,-6.59094
37.50000,-6.25012,-6.59571
37.60000,-6.26665,-6.60053
37.70000,-6.28332,-6.60449
37.80000,-6.29985,-6.61091
37.90000,-6.31678,-6.61507
38.00000,-6.33332,-6.61997
38.10000,-6.34998,-6.62735
38.20000,-6.36678,-6.63210
38.30000,-6.38332,-6.63828
38.40000,-6.39998,-6.64232
38.50000,-6.41638,-6.64543
38.60000,-6.43292,-6.65251
38.70000,-6.44985,-6.66364
38.80000,-6.46665,-6.66925
38.90000,-6.48332,-6.67274
39.00000,-6.49998,-6.67858
39.10000,-6.51665,-6.68376
39.20000,-6.53318,-6.68883
39.30000,-6.54998,-6.69016
39.40000,-6.56638,-6.69337
39.50000,-6.58318,-6.70012
39.60000,-6.60012,-6.70418
39.70000,-6.61665,-6.70651
39.80000,-6.63345,-6.70835
39.90000,-6.65012,-6.71290
40.00000,-6.66665,-6.71718
40.10000,-6.68305,-6.72022
40.20000,-6.69998,-6.72165
40.30000,-6.71652,-6.72606
40.40000,-6.73332,-6.73107
40.50000,-6.75012,-6.73325
40.60000,-6.76652,-6.73572
40.70000,-6.78345,-6.74257
40.80000,-6.79998,-6.74688
40.90000,-6.81665,-6.74757
41.00000,-6.83305,-6.74887
41.10000,-6.85012,-6.75102
41.20000,-6.86665,-6.74969
41.30000,-6.88345,-6.75108
41.40000,-6.90012,-6.75061
41.50000,-6.91652,-6.74565
41.60000,-6.93345,-6.74327
41.70000,-6.94972,-6.74552
41.80000,-6.96652,-6.74979
41.90000,-6.98332,-6.75123
42.00000,-6.99998,-6.74957
42.10000,-7.01665,-6.74784
42.20000,-7.03332,-6.75597
42.30000,-7.05012,-6.75737
42.40000,-7.06638,-6.75854
42.50000,-7.08332,-6.76105
42.60000,-7.09958,-6.76444
42.70000,-7.11665,-6.76854
42.80000,-7.13345,-6.77252
42.90000,-7.14998,-6.77608
43.00000,-7.16678,-6.77711
43.10000,-7.18332,-6.77660
43.20000,-7.19998,-6.77604
43.30000,-7.21652,-6.78059
43.40000,-7.23332,-6.78180
43.50000,-7.24985,-6.78450
43.60000,-7.26665,-6.78499
43.70000,-7.28345,-6.78280
43.80000,-7.29998,-6.78535
43.90000,-7.31678,-6.79017
44.00000,-7.33318,-6.78934
44.10000,-7.34998,-6.79573
44.20000,-7.36638,-6.80067
44.30000,-7.38332,-6.80557
44.40000,-7.39998,-6.80768
44.50000,-7.41665,-6.81428
44.60000,-7.43332,-6.81544
44.70000,-7.44985,-6.82478
44.80000,-7.46665,-6.83124
44.90000,-7.48305,-6.83386
45.00000,-7.49985,-6.83995
45.10000,-7.51651,-6.84512
45.20000,-7.53332,-6.84731
45.30000,-7.54998,-6.84911
45.40000,-7.56678,-6.85677
45.50000,-7.58332,-6.85961
45.60000,-7.59985,-6.86673
45.70000,-7.61665,-6.87109
45.80000,-7.63305,-6.87397
45.90000,-7.64998,-6.88011
46.00000,-7.66665,-6.88697
46.10000,-7.68331,-6.89262
46.20000,-7.70011,-6.89883
46.30000,-7.71678,-6.90550
46.40000,-7.73345,-6.91035
46.50000,-7.74971,-6.91597
46.60000,-7.76665,-6.92043
46.70000,-7.78305,-6.92241
46.80000,-7.79985,-6.92767
46.90000,-7.81678,-6.93099
47.00000,-7.83318,-6.93460
47.10000,-7.84998,-6.93812
47.20000,-7.86665,-6.94042
47.30000,-7.88345,-6.94363
47.40000,-7.89985,-6.94727
47.50000,-7.91678,-6.94953
47.60000,-7.93331,-6.95236
47.70000,-7.94998,-6.95589
47.80000,-7.96678,-6.95662
47.90000,-7.98318,-6.95971
48.00000,-8.00011,-6.96187
48.10000,-8.01638,-6.96352
48.20000,-8.03291,-6.96506
48.30000,-8.04971,-6.96829
48.40000,-8.06651,-6.97217
48.50000,-8.08318,-6.97389
48.60000,-8.09998,-6.97959
48.70000,-8.11665,-6.98179
48.80000,-8.13318,-6.98612
48.90000,-8.14998,-6.98944
49.00000,-8.16625,-6.99109
49.10000,-8.18331,-6.99541
49.20000,-8.20011,-6.99939
49.30000,-8.21678,-7.00276
49.40000,-8.23345,-7.00536
49.50000,-8.25011,-7.00837
49.60000,-8.26665,-7.01041
49.70000,-8.28305,-7.01423
49.80000,-8.30011,-7.02002
49.90000,-8.31651,-7.02189
50.00000,-8.33345,-7.02874
50.10000,-8.35025,-7.03040
50.20000,-8.36665,-7.03423
50.30000,-8.38358,-7.03787
50.40000,-8.39998,-7.03915
50.50000,-8.41665,-7.04321
50.60000,-8.43305,-7.04728
50.70000,-8.44998,-7.05237
50.80000,-8.46651,-7.05403
50.90000,-8.48331,-7.05950
51.00000,-8.49985,-7.06021
51.10000,-8.51665,-7.06507
51.20000,-8.53345,-7.06951
51.30000,-8.54971,-7.06931
51.40000,-8.56638,-7.07136
51.50000,-8.58305,-7.07297
51.60000,-8.59998,-7.07841
51.70000,-8.61651,-7.07967
51.80000,-8.63318,-7.08463
51.90000,-8.64998,-7.08537
52.00000,-8.66651,-7.09170
52.10000,-8.68358,-7.09571
52.20000,-8.69985,-7.09851
52.30000,-8.71678,-7.10356
52.40000,-8.73345,-7.10624
52.50000,-8.75011,-7.11152
52.60000,-8.76678,-7.11459
52.70000,-8.78345,-7.11953
52.80000,-8.80011,-7.12118
52.90000,-8.81638,-7.12581
53.00000,-8.83345,-7.12907
53.10000,-8.84985,-7.13319
53.20000,-8.86678,-7.14076
53.30000,-8.88345,-7.14328
53.40000,-8.89998,-7.14778
53.50000,-8.91678,-7.15129
53.60000,-8.93331,-7.15582
53.70000,-8.94998,-7.15686
53.80000,-8.96638,-7.16171
53.90000,-8.98345,-7.16738
54.00000,-8.99985,-7.17032
54.10000,-9.01665,-7.17555
54.20000,-9.03331,-7.17805
54.30000,-9.04984,-7.18327
54.40000,-9.06665,-7.18825
54.50000,-9.08304,-7.19204
54.60000,-9.09984,-7.19988
54.70000,-9.11664,-7.20736
54.80000,-9.13331,-7.21160
54.90000,-9.14998,-7.21566
55.00000,-9.16664,-7.22111
55.10000,-9.18331,-7.22348
55.20000,-9.19984,-7.22848
55.30000,-9.21678,-7.23406
55.40000,-9.23304,-7.23673
55.50000,-9.24971,-7.24274
55.60000,-9.26651,-7.24723
55.70000,-9.28344,-7.25448
55.80000,-9.30011,-7.26014
55.90000,-9.31664,-7.26480
56.00000,-9.33331,-7.26822
56.10000,-9.34971,-7.27352
56.20000,-9.36651,-7.27836
56.30000,-9.38318,-7.28457
56.40000,-9.40011,-7.29364
56.50000,-9.41678,-7.29800
56.60000,-9.43331,-7.30338
56.70000,-9.45011,-7.30775
56.80000,-9.46664,-7.31114
56.90000,-9.48331,-7.31416
57.00000,-9.49984,-7.32051
57.10000,-9.51664,-7.32630
57.20000,-9.53331,-7.32934
57.30000,-9.54984,-7.33503
57.40000,-9.56651,-7.33416
57.50000,-9.58318,-7.33877
57.60000,-9.59998,-7.34091
57.70000,-9.61651,-7.34348
57.80000,-9.63318,-7.34494
57.90000,-9.64971,-7.34555
58.00000,-9.66651,-7.34984
58.10000,-9.68331,-7.35165
58.20000,-9.70011,-7.35650
58.30000,-9.71691,-7.35824
58.40000,-9.73318,-7.36036
58.50000,-9.74998,-7.36154
58.60000,-9.76638,-7.36272
58.70000,-9.78331,-7.36643
58.80000,-9.80011,-7.36959
58.90000,-9.81664,-7.37179
59.00000,-9.83318,-7.37426
59.10000,-9.85011,-7.37915
59.20000,-9.86678,-7.37955
59.30000,-9.88304,-7.38270
59.40000,-9.89984,-7.38374
59.50000,-9.91624,-7.38639
59.60000,-9.93318,-7.39319
59.70000,-9.95011,-7.39445
59.80000,-9.96664,-7.39685
59.90000,-9.98344,-7.39914
60.00000,-9.99998,-7.40042
60.10000,-10.01664,-7.40124
60.20000,-10.03318,-7.40325
60.30000,-10.05024,-7.40551
60.40000,-10.06664,-7.40503
60.50000,-10.08344,-7.40962
60.60000,-10.10011,-7.40881
60.70000,-10.11664,-7.40907
60.80000,-10.13331,-7.40946
60.90000,-10.14971,-7.40970
61.00000,-10.16651,-7.41075
61.10000,-10.18318,-7.41158
61.20000,-10.19998,-7.41171
61.30000,-10.21651,-7.41217
61.40000,-10.23344,-7.41389
61.50000,-10.24998,-7.41249
61.60000,-10.26651,-7.41360
61.70000,-10.28331,-7.41406
61.80000,-10.29984,-7.41542
61.90000,-10.31664,-7.41881
62.00000,-10.33331,-7.41931
62.10000,-10.34997,-7.42147
62.20000,-10.36678,-7.42435
62.30000,-10.38344,-7.42763
62.40000,-10.40011,-7.43000
62.50000,-10.41637,-7.43215
62.60000,-10.43331,-7.43663
62.70000,-10.44984,-7.43847
62.80000,-10.46664,-7.44472
62.90000,-10.48331,-7.44776
63.00000,-10.49984,-7.45132
63.10000,-10.51677,-7.45847
63.20000,-10.53331,-7.46202
63.30000,-10.55011,-7.46801
63.40000,-10.56651,-7.47329
63.50000,-10.58331,-7.47913
63.60000,-10.59984,-7.48506
63.70000,-10.61664,-7.49267
63.80000,-10.63344,-7.49664
63.90000,-10.64984,-7.50296
64.00000,-10.66664,-7.50788
64.10001,-10.68304,-7.51264
64.20000,-10.69997,-7.51824
64.30000,-10.71664,-7.52105
64.40000,-10.73331,-7.52505
64.50000,-10.74984,-7.52820
64.60001,-10.76664,-7.53552
64.70000,-10.78331,-7.53852
64.80000,-10.79984,-7.54265
64.90000,-10.81664,-7.54665
65.00000,-10.83291,-7.54851
65.10001,-10.84997,-7.55534
65.20000,-10.86677,-7.56023
65.30000,-10.88331,-7.56399
65.40000,-10.89997,-7.56773
65.50000,-10.91677,-7.57201
65.60001,-10.93331,-7.57296
65.70001,-10.94971,-7.57654
65.80000,-10.96677,-7.58036
65.90000,-10.98304,-7.58150
66.00000,-10.99997,-7.58754
66.10001,-11.01691,-7.58836
66.20001,-11.03344,-7.59163
66.30000,-11.05011,-7.59441
66.40000,-11.06664,-7.59543
66.50000,-11.08331,-7.59784
66.60001,-11.09971,-7.60148
66.70001,-11.11677,-7.60610
66.80000,-11.13317,-7.60845
66.90000,-11.14997,-7.61222
67.00000,-11.16664,-7.61328
67.10001,-11.18331,-7.61730
67.20001,-11.20024,-7.61994
67.30000,-11.21651,-7.61974
67.40000,-11.23317,-7.61890
67.50000,-11.24984,-7.62093
67.60001,-11.26664,-7.62358
67.70001,-11.28331,-7.62352
67.80000,-11.29997,-7.62428
67.90000,-11.31677,-7.62445
68.00000,-11.33317,-7.62541
68.10001,-11.34997,-7.62735
68.20001,-11.36637,-7.62537
68.30000,-11.38317,-7.62713
68.40000,-11.39997,-7.62654
68.50000,-11.41664,-7.62838
68.60001,-11.43331,-7.62886
68.70001,-11.45011,-7.62987
68.80000,-11.46677,-7.62793
68.90000,-11.48304,-7.62781
69.00000,-11.49997,-7.62886
69.10001,-11.51650,-7.62854
69.20001,-11.53331,-7.63091
69.30000,-11.55024,-7.62774
69.40000,-11.56664,-7.62743
69.50000,-11.58357,-7.62817
69.60001,-11.59997,-7.62644
69.70001,-11.61664,-7.62604
69.80000,-11.63304,-7.62708
69.90000,-11.64997,-7.62923
70.00000,-11.66664,-7.62924
70.10001,-11.68344,-7.63133
70.20001,-11.70010,-7.63185
70.30000,-11.71664,-7.63431
70.40000,-11.73317,-7.63432
70.50000,-11.74944,-7.63290
70.60001,-11.76650,-7.63670
70.70001,-11.78317,-7.64113
70.80000,-11.79984,-7.64478
70.90000,-11.81637,-7.64682
71.00000,-11.83330,-7.65257
71.10001,-11.85010,-7.65525
71.20001,-11.86650,-7.65801
71.30000,-11.88330,-7.66184
71.40000,-11.89970,-7.66266
71.50000,-11.91650,-7.67001
71.60001,-11.93344,-7.67418
71.70001,-11.95010,-7.67780
71.80000,-11.96677,-7.68340
71.90000,-11.98344,-7.69133
72.00000,-11.99997,-7.69737
72.10001,-12.01650,-7.70533
72.20001,-12.03330,-7.71334
72.30000,-12.04984,-7.71972
72.40000,-12.06664,-7.72998
72.50000,-12.08344,-7.73567
72.60001,-12.09997,-7.74362
72.70001,-12.11677,-7.75101
72.80000,-12.13317,-7.75596
72.90000,-12.14997,-7.76317
73.00000,-12.16650,-7.77017
73.10001,-12.18344,-7.77726
73.20001,-12.19997,-7.78229
73.30000,-12.21664,-7.78784
73.40000,-12.23344,-7.79114
73.50000,-12.24984,-7.79623
73.60001,-12.26664,-7.80181
73.70001,-12.28304,-7.80525
73.80000,-12.29984,-7.81201
73.90000,-12.31650,-7.81940
74.00000,-12.33317,-7.82797
74.10001,-12.34997,-7.83402
74.20001,-12.36677,-7.84660
74.30000,-12.38344,-7.85221
74.40000,-12.39970,-7.86294
74.50000,-12.41664,-7.87281
74.60001,-12.43290,-7.88279
74.70001,-12.44984,-7.89523
74.80000,-12.46664,-7.90448
74.90000,-12.48330,-7.91447
75.00000,-12.50010,-7.92424
75.10001,-12.51677,-7.93146
75.20001,-12.53344,-7.93788
75.30000,-12.54984,-7.94798
75.40000,-12.56677,-7.95859
75.50000,-12.58317,-7.96746
75.60001,-12.60010,-7.97888
75.70001,-12.61690,-7.98809
75.80000,-12.63330,-7.99645
75.90000,-12.65010,-8.00883
76.00000,-12.66650,-8.01865
76.10001,-12.68330,-8.02981
76.20001,-12.69984,-8.04057
76.30000,-12.71664,-8.05126
76.40000,-12.73330,-8.06222
76.50000,-12.75010,-8.07651
76.60001,-12.76677,-8.08596
76.70001,-12.78317,-8.09918
76.80000,-12.79997,-8.11201
76.90000,-12.81637,-8.12248
77.00000,-12.83317,-8.13595
77.10001,-12.84997,-8.15073
77.20001,-12.86663,-8.16410
77.30000,-12.88317,-8.17561
77.40000,-12.89997,-8.18910
77.50000,-12.91677,-8.19843
77.60001,-12.93304,-8.20840
77.70001,-12.95010,-8.22075
77.80000,-12.96637,-8.22938
77.90000,-12.98330,-8.24293
78.00000,-12.99997,-8.25316
78.10001,-13.01677,-8.26672
78.20001,-13.03343,-8.27832
78.30000,-13.05010,-8.29090
78.40000,-13.06663,-8.30088
78.50000,-13.08304,-8.31221
78.60001,-13.09997,-8.32484
78.70001,-13.11650,-8.33551
78.80000,-13.13317,-8.35031
78.90000,-13.14997,-8.35966
79.00000,-13.16663,-8.37393
79.10001,-13.18357,-8.38606
79.20001,-13.19997,-8.39398
79.30000,-13.21663,-8.40568
79.40000,-13.23303,-8.41729
79.50000,-13.24983,-8.42926
79.60001,-13.26637,-8.44013
79.70001,-13.28330,-8.45423
79.80000,-13.29997,-8.46295
79.90000,-13.31650,-8.47522
80.00000,-13.33343,-8.48718
80.10001,-13.34970,-8.49541
80.20001,-13.36650,-8.50422
80.30000,-13.38317,-8.51683
80.40000,-13.39983,-8.52715
80.50001,-13.41663,-8.53705
80.60001,-13.43330,-8.55001
80.70001,-13.45010,-8.55743
80.80000,-13.46650,-8.56816
80.90000,-13.48343,-8.57800
81.00001,-13.49970,-8.58665
81.10001,-13.51650,-8.59707
81.20001,-13.53343,-8.60569
81.30000,-13.54997,-8.61920
81.40000,-13.56663,-8.62944
81.50001,-13.58343,-8.64058
81.60001,-13.59997,-8.64748
81.70001,-13.61637,-8.65820
81.80000,-13.63330,-8.66859
81.90000,-13.64970,-8.67499
82.00001,-13.66663,-8.68976
82.10001,-13.68357,-8.69960
82.20001,-13.70010,-8.70901
82.30000,-13.71677,-8.71635
82.40000,-13.73330,-8.72437
82.50001,-13.74983,-8.73281
82.60001,-13.76623,-8.74266
82.70001,-13.78330,-8.75432
82.80000,-13.79983,-8.76138
82.90000,-13.81663,-8.77418
83.00001,-13.83357,-8.75021
83.10001,-13.85010,-8.76763
83.20001,-13.86677,-8.78133
83.30000,-13.88290,-8.79186
83.40000,-13.89970,-8.80410
83.50001,-13.91650,-8.82005
83.60001,-13.93330,-8.83203
83.70001,-13.94997,-8.84502
83.80000,-13.96677,-8.86315
83.90000,-13.98330,-8.87277
84.00001,-13.99983,-8.88457
84.10001,-14.01677,-8.89725
84.20001,-14.03303,-8.90693
84.30000,-14.04997,-8.92145
84.40000,-14.06663,-8.93204
84.50001,-14.08330,-8.94481
84.60001,-14.09997,-8.95532
84.70001,-14.11677,-8.97014
84.80000,-14.13343,-8.98187
84.90000,-14.14970,-8.99238
85.00001,-14.16663,-9.00392
85.10001,-14.18317,-9.01272
85.20001,-14.19997,-9.02835
85.30000,-14.21676,-9.03708
85.40000,-14.23317,-9.05356
85.50001,-14.25010,-9.06767
85.60001,-14.26663,-9.07829
85.70001,-14.28330,-9.09060
85.80000,-14.29970,-9.10550
85.90000,-14.31663,-9.12048
86.00001,-14.33317,-9.13413
86.10001,-14.34997,-9.15330
86.20001,-14.36676,-9.16658
86.30000,-14.38330,-9.18372
86.40000,-14.39996,-9.19635
86.50001,-14.41636,-9.21197
86.60001,-14.43317,-9.22669
86.70001,-14.44983,-9.24552
86.80000,-14.46650,-9.26028
86.90000,-14.48303,-9.27418
87.00001,-14.50010,-9.29446
87.10001,-14.51663,-9.30438
87.20001,-14.53303,-9.31587
87.30000,-14.54996,-9.33160
87.40000,-14.56636,-9.34665
87.50001,-14.58330,-9.36733
87.60001,-14.60010,-9.38545
87.70001,-14.61676,-9.40614
87.80000,-14.63343,-9.42109
87.90000,-14.65010,-9.43860
88.00001,-14.66676,-9.45675
88.10001,-14.68303,-9.47859
88.20001,-14.70010,-9.49088
88.30000,-14.71650,-9.50450
88.40000,-14.73330,-9.52412
88.50001,-14.75010,-9.53874
88.60001,-14.76663,-9.55509
88.70001,-14.78343,-9.57166
88.80000,-14.79983,-9.58673
88.90000,-14.81650,-9.59999
89.00001,-14.83316,-9.61749
89.10001,-14.84996,-9.63420
89.20001,-14.86650,-9.64875
89.30000,-14.88343,-9.66830
89.40000,-14.90010,-9.68199
89.50001,-14.91663,-9.69654
89.60001,-14.93343,-9.71070
89.70001,-14.94983,-9.72370
89.80000,-14.96650,-9.73791
89.90000,-14.98303,-9.75965
90.00001,-14.99996,-9.77670
90.10001,-15.01663,-9.79240
90.20001,-15.03343,-9.81305
90.30000,-15.05010,-9.82332
90.31400,-15.05250,-9.82188