File: GFBaking/data/1TspPectin/1TspPectin.is_comp_RawData/Specimen_RawData_3.csv
Time,Extension,Load
(sec),(mm),(N)
0.00000,0.63666,-0.04966
0.10000,0.63106,-0.05497
0.20000,0.61160,-0.08644
0.30000,0.59120,-0.11999
0.40000,0.57267,-0.14905
0.50000,0.55480,-0.17439
0.60000,0.53760,-0.19828
0.70000,0.52080,-0.22111
0.80000,0.50347,-0.24518
0.90000,0.48693,-0.26714
1.00000,0.47027,-0.29177
1.10000,0.45347,-0.31701
1.20000,0.43680,-0.34166
1.30000,0.42013,-0.36684
1.40000,0.40347,-0.39176
1.50000,0.38680,-0.41832
1.60000,0.37040,-0.44574
1.70000,0.35333,-0.47284
1.80000,0.33680,-0.49734
1.90000,0.32000,-0.52446
2.00000,0.30347,-0.55253
2.10000,0.28707,-0.58034
2.20000,0.27013,-0.61155
2.30000,0.25360,-0.63860
2.40000,0.23667,-0.66892
2.50000,0.22013,-0.69814
2.60000,0.20320,-0.72954
2.70000,0.18680,-0.75945
2.80000,0.17000,-0.79066
2.90000,0.15333,-0.82201
3.00000,0.13693,-0.85127
3.10000,0.12000,-0.88793
3.20000,0.10347,-0.91805
3.30000,0.08667,-0.94554
3.40000,0.07000,-0.97747
3.50000,0.05333,-1.00807
3.60000,0.03680,-1.03801
3.70000,0.02000,-1.06639
3.80000,0.00333,-1.09461
3.90000,-0.01307,-1.12807
4.00000,-0.03013,-1.15918
4.10000,-0.04653,-1.19039
4.20000,-0.06333,-1.22217
4.30000,-0.08013,-1.25347
4.40000,-0.09653,-1.28277
4.50000,-0.11320,-1.31278
4.60000,-0.12987,-1.34866
4.70000,-0.14653,-1.37765
4.80000,-0.16307,-1.40288
4.90000,-0.18013,-1.42585
5.00000,-0.19653,-1.45039
5.10000,-0.21320,-1.46370
5.20000,-0.22987,-1.47749
5.30000,-0.24640,-1.49801
5.40000,-0.26307,-1.52777
5.50000,-0.27973,-1.56217
5.60000,-0.29653,-1.59759
5.70000,-0.31307,-1.63118
5.80000,-0.33000,-1.66302
5.90000,-0.34653,-1.69340
6.00000,-0.36320,-1.72154
6.10000,-0.37987,-1.75407
6.20000,-0.39640,-1.78473
6.30000,-0.41333,-1.81563
6.40000,-0.42987,-1.84405
6.50000,-0.44667,-1.87575
6.60000,-0.46333,-1.90527
6.70000,-0.48000,-1.93402
6.80000,-0.49653,-1.95641
6.90000,-0.51333,-1.99094
7.00000,-0.53000,-2.01886
7.10000,-0.54640,-1.99048
7.20000,-0.56333,-2.03242
7.30000,-0.57987,-2.06636
7.40000,-0.59667,-2.09886
7.50000,-0.61347,-2.12841
7.60000,-0.62987,-2.14428
7.70000,-0.64640,-2.16126
7.80000,-0.66320,-2.18067
7.90000,-0.68000,-2.20486
8.00000,-0.69640,-2.22925
8.10000,-0.71333,-2.25348
8.20000,-0.72986,-2.28497
8.30000,-0.74653,-2.31532
8.40000,-0.76320,-2.34300
8.50000,-0.77973,-2.36683
8.60000,-0.79653,-2.39057
8.70000,-0.81293,-2.42271
8.80000,-0.83000,-2.45272
8.90000,-0.84653,-2.48354
9.00000,-0.86333,-2.50888
9.10000,-0.87973,-2.53482
9.20000,-0.89666,-2.56356
9.30000,-0.91333,-2.58949
9.40000,-0.92960,-2.62014
9.50000,-0.94653,-2.65135
9.60000,-0.96320,-2.67794
9.70000,-0.98000,-2.70849
9.80000,-0.99680,-2.73909
9.90000,-1.01333,-2.76707
10.00000,-1.02973,-2.79677
10.10000,-1.04640,-2.82465
10.20000,-1.06333,-2.85277
10.30000,-1.07973,-2.88174
10.40000,-1.09680,-2.91497
10.50000,-1.11320,-2.94043
10.60000,-1.13000,-2.96763
10.70000,-1.14666,-2.99232
10.80000,-1.16320,-3.01854
10.90000,-1.17986,-3.04760
11.00000,-1.19666,-3.07646
11.10000,-1.21333,-3.10255
11.20000,-1.22973,-3.12870
11.30000,-1.24680,-3.15512
11.40000,-1.26333,-3.17941
11.50000,-1.27986,-3.20625
11.60000,-1.29653,-3.22916
11.70000,-1.31306,-3.25219
11.80000,-1.32973,-3.27745
11.90000,-1.34640,-3.29950
12.00000,-1.36320,-3.32642
12.10000,-1.37986,-3.35243
12.20000,-1.39666,-3.37938
12.30000,-1.41320,-3.40219
12.40000,-1.42986,-3.42568
12.50000,-1.44653,-3.44830
12.60000,-1.46306,-3.47389
12.70000,-1.48000,-3.49984
12.80000,-1.49653,-3.52371
12.90000,-1.51346,-3.54609
13.00000,-1.53000,-3.56890
13.10000,-1.54666,-3.59222
13.20000,-1.56320,-3.61301
13.30000,-1.58000,-3.63833
13.40000,-1.59666,-3.66136
13.50000,-1.61293,-3.68396
13.60000,-1.63013,-3.70612
13.70000,-1.64653,-3.72888
13.80000,-1.66333,-3.75108
13.90000,-1.68000,-3.77291
14.00000,-1.69640,-3.79461
14.10000,-1.71306,-3.81588
14.20000,-1.72986,-3.83863
14.30000,-1.74666,-3.85958
14.40000,-1.76306,-3.88153
14.50000,-1.78013,-3.90251
14.60000,-1.79653,-3.91928
14.70000,-1.81333,-3.94221
14.80000,-1.83000,-3.96077
14.90000,-1.84640,-3.97962
15.00000,-1.86306,-4.00059
15.10000,-1.87973,-4.02141
15.20000,-1.89653,-4.04119
15.30000,-1.91320,-4.06384
15.40000,-1.93013,-4.08350
15.50000,-1.94653,-4.10340
15.60000,-1.96320,-4.12504
15.70000,-1.97986,-4.14168
15.80000,-1.99640,-4.16031
15.90000,-2.01333,-4.17925
16.00000,-2.02986,-4.19968
16.10000,-2.04666,-4.22009
16.20000,-2.06333,-4.24079
16.30000,-2.08013,-4.26001
16.40000,-2.09653,-4.27570
16.50000,-2.11319,-4.29317
16.60000,-2.12999,-4.30965
16.70000,-2.14626,-4.32845
16.80000,-2.16359,-4.34781
16.90000,-2.17999,-4.36491
17.00000,-2.19666,-4.38135
17.10000,-2.21346,-4.39897
17.20000,-2.22999,-4.41538
17.30000,-2.24653,-4.43284
17.40000,-2.26333,-4.45143
17.50000,-2.27999,-4.46594
17.60000,-2.29639,-4.48213
17.70000,-2.31346,-4.49665
17.80000,-2.32986,-4.51162
17.90000,-2.34653,-4.52693
18.00000,-2.36306,-4.54086
18.10000,-2.37959,-4.55380
18.20000,-2.39639,-4.56996
18.30000,-2.41319,-4.58323
18.40000,-2.42986,-4.59737
18.50000,-2.44653,-4.61171
18.60000,-2.46333,-4.62624
18.70000,-2.47986,-4.64146
18.80000,-2.49653,-4.65709
18.90000,-2.51319,-4.66756
19.00000,-2.52959,-4.68168
19.10000,-2.54666,-4.69576
19.20000,-2.56319,-4.70890
19.30000,-2.57999,-4.72255
19.40000,-2.59653,-4.73478
19.50000,-2.61346,-4.74730
19.60000,-2.62986,-4.75836
19.70000,-2.64666,-4.77101
19.80000,-2.66333,-4.78145
19.90000,-2.67973,-4.79216
20.00000,-2.69693,-4.80548
20.10000,-2.71319,-4.81463
20.20000,-2.72999,-4.82573
20.30000,-2.74666,-4.83580
20.40000,-2.76319,-4.84644
20.50000,-2.77986,-4.85666
20.60000,-2.79653,-4.86609
20.70000,-2.81319,-4.87393
20.80000,-2.82973,-4.88351
20.90000,-2.84679,-4.89163
21.00000,-2.86306,-4.90026
21.10000,-2.87986,-4.91067
21.20000,-2.89653,-4.91695
21.30000,-2.91306,-4.92581
21.40000,-2.92973,-4.93361
21.50000,-2.94639,-4.94231
21.60000,-2.96333,-4.95023
21.70000,-2.97986,-4.95944
21.80000,-2.99679,-4.96674
21.90000,-3.01306,-4.97179
22.00000,-3.02986,-4.98113
22.10000,-3.04666,-4.98647
22.20000,-3.06306,-4.99337
22.30000,-3.08013,-5.00087
22.40000,-3.09653,-5.00663
22.50000,-3.11333,-5.01380
22.60000,-3.12999,-5.02054
22.70000,-3.14679,-5.02784
22.80000,-3.16319,-5.03212
22.90000,-3.17986,-5.03956
23.00000,-3.19666,-5.04464
23.10000,-3.21293,-5.05072
23.20000,-3.23013,-5.05739
23.30000,-3.24653,-5.06338
23.40000,-3.26333,-5.07046
23.50000,-3.27999,-5.07545
23.60000,-3.29653,-5.08090
23.70000,-3.31319,-5.08567
23.80000,-3.32986,-5.09148
23.90000,-3.34653,-5.09622
24.00000,-3.36306,-5.10381
24.10000,-3.38013,-5.10723
24.20000,-3.39639,-5.11098
24.30000,-3.41319,-5.11899
24.40000,-3.42986,-5.12341
24.50000,-3.44639,-5.12985
24.60000,-3.46306,-5.13505
24.70000,-3.47972,-5.14043
24.80000,-3.49652,-5.14615
24.90000,-3.51319,-5.15367
25.00000,-3.52999,-5.15923
25.10000,-3.54652,-5.16433
25.20000,-3.56319,-5.17079
25.30000,-3.57986,-5.17521
25.40000,-3.59626,-5.17922
25.50000,-3.61332,-5.18614
25.60000,-3.62986,-5.19067
25.70000,-3.64666,-5.19758
25.80000,-3.66332,-5.20365
25.90000,-3.67999,-5.20939
26.00000,-3.69652,-5.21322
26.10000,-3.71346,-5.21880
26.20000,-3.72999,-5.22344
26.30000,-3.74639,-5.22890
26.40000,-3.76346,-5.23412
26.50000,-3.77986,-5.23728
26.60000,-3.79666,-5.24251
26.70000,-3.81346,-5.24662
26.80000,-3.82986,-5.25015
26.90000,-3.84652,-5.25394
27.00000,-3.86306,-5.25893
27.10000,-3.87986,-5.26183
27.20000,-3.89639,-5.26703
27.30000,-3.91346,-5.26987
27.40000,-3.92972,-5.27097
27.50000,-3.94652,-5.27348
27.60000,-3.96319,-5.27537
27.70000,-3.97972,-5.27883
27.80000,-3.99652,-5.28210
27.90000,-4.01306,-5.28271
28.00000,-4.02999,-5.28463
28.10000,-4.04666,-5.28963
28.20000,-4.06346,-5.29188
28.30000,-4.07986,-5.29380
28.40000,-4.09652,-5.29636
28.50000,-4.11319,-5.29727
28.60000,-4.12959,-5.29863
28.70000,-4.14666,-5.30379
28.80000,-4.16306,-5.30619
28.90000,-4.18012,-5.31042
29.00000,-4.19679,-5.31363
29.10000,-4.21332,-5.31389
29.20000,-4.22986,-5.31533
29.30000,-4.24652,-5.31680
29.40000,-4.26332,-5.31790
29.50000,-4.27959,-5.32040
29.60000,-4.29666,-5.32323
29.70000,-4.31332,-5.32546
29.80000,-4.32999,-5.32890
29.90000,-4.34652,-5.32935
30.00000,-4.36306,-5.33317
30.10000,-4.37986,-5.33491
30.20000,-4.39652,-5.33737
30.30000,-4.41332,-5.33846
30.40000,-4.42972,-5.34042
30.50000,-4.44679,-5.34258
30.60000,-4.46319,-5.34315
30.70000,-4.47986,-5.34514
30.80000,-4.49652,-5.34446
30.90000,-4.51292,-5.34469
31.00000,-4.52972,-5.34590
31.10000,-4.54639,-5.34626
31.20000,-4.56332,-5.34762
31.30000,-4.57986,-5.34788
31.40000,-4.59666,-5.34807
31.50000,-4.61306,-5.34642
31.60000,-4.62986,-5.34825
31.70000,-4.64652,-5.34540
31.80000,-4.66306,-5.34375
31.90000,-4.67999,-5.34496
32.00000,-4.69652,-5.34505
32.10000,-4.71332,-5.34697
32.20000,-4.72999,-5.34830
32.30000,-4.74666,-5.34862
32.40000,-4.76319,-5.35026
32.50000,-4.77986,-5.35297
32.60000,-4.79665,-5.35442
32.70000,-4.81306,-5.35557
32.80000,-4.83012,-5.35885
32.90000,-4.84652,-5.36014
33.00000,-4.86332,-5.36323
33.10000,-4.88012,-5.36580
33.20000,-4.89665,-5.36656
33.30000,-4.91319,-5.36873
33.40000,-4.92972,-5.37059
33.50000,-4.94652,-5.37282
33.60000,-4.96305,-5.37547
33.70000,-4.98012,-5.37717
33.80000,-4.99652,-5.38064
33.90000,-5.01319,-5.38665
34.00000,-5.02985,-5.38744
34.10000,-5.04652,-5.38940
34.20000,-5.06319,-5.39127
34.30000,-5.07972,-5.39457
34.40000,-5.09652,-5.39620
34.50000,-5.11305,-5.40052
34.60000,-5.12999,-5.40474
34.70000,-5.14639,-5.40672
34.80000,-5.16319,-5.41058
34.90000,-5.17985,-5.41187
35.00000,-5.19639,-5.41399
35.10000,-5.21319,-5.41677
35.20000,-5.22972,-5.42203
35.30000,-5.24652,-5.42644
35.40000,-5.26332,-5.42964
35.50000,-5.27999,-5.43112
35.60000,-5.29652,-5.43292
35.70000,-5.31332,-5.43728
35.80000,-5.32999,-5.44098
35.90000,-5.34639,-5.44397
36.00000,-5.36345,-5.44926
36.10000,-5.37985,-5.45017
36.20000,-5.39665,-5.45236
36.30000,-5.41345,-5.45699
36.40000,-5.42999,-5.45881
36.50000,-5.44652,-5.45937
36.60000,-5.46319,-5.46248
36.70000,-5.47999,-5.46439
36.80000,-5.49652,-5.46720
36.90000,-5.51345,-5.47069
37.00000,-5.52985,-5.47302
37.10000,-5.54652,-5.47521
37.20000,-5.56319,-5.47661
37.30000,-5.57972,-5.47909
37.40000,-5.59639,-5.48186
37.50000,-5.61292,-5.48404
37.60000,-5.62985,-5.48836
37.70000,-5.64652,-5.49479
37.80000,-5.66345,-5.49923
37.90000,-5.67972,-5.50074
38.00000,-5.69652,-5.50445
38.10000,-5.71332,-5.50810
38.20000,-5.72972,-5.50622
38.30000,-5.74665,-5.51135
38.40000,-5.76319,-5.51593
38.50000,-5.77999,-5.52114
38.60000,-5.79665,-5.52504
38.70000,-5.81332,-5.52708
38.80000,-5.82985,-5.53122
38.90000,-5.84665,-5.53482
39.00000,-5.86332,-5.53721
39.10000,-5.87972,-5.54034
39.20000,-5.89679,-5.54475
39.30000,-5.91319,-5.54555
39.40000,-5.92999,-5.55012
39.50000,-5.94679,-5.55275
39.60000,-5.96332,-5.55580
39.70000,-5.97999,-5.55858
39.80000,-5.99652,-5.56238
39.90000,-6.01332,-5.56248
40.00000,-6.02985,-5.56737
40.10000,-6.04679,-5.57226
40.20000,-6.06319,-5.57460
40.30000,-6.07999,-5.57883
40.40000,-6.09665,-5.57782
40.50000,-6.11305,-5.57931
40.60000,-6.12972,-5.58217
40.70000,-6.14638,-5.58586
40.80000,-6.16332,-5.58829
40.90000,-6.17985,-5.59199
41.00000,-6.19678,-5.59241
41.10000,-6.21318,-5.59469
41.20000,-6.22985,-5.60257
41.30000,-6.24652,-5.60307
41.40000,-6.26292,-5.60387
41.50000,-6.27998,-5.60673
41.60000,-6.29652,-5.61058
41.70000,-6.31345,-5.61119
41.80000,-6.32998,-5.61099
41.90000,-6.34665,-5.61425
42.00000,-6.36318,-5.61584
42.10000,-6.37998,-5.61931
42.20000,-6.39665,-5.62135
42.30000,-6.41292,-5.62408
42.40000,-6.43012,-5.62681
42.50000,-6.44652,-5.62696
42.60000,-6.46332,-5.63153
42.70000,-6.48012,-5.63283
42.80000,-6.49652,-5.63603
42.90000,-6.51318,-5.63770
43.00000,-6.52985,-5.64011
43.10000,-6.54665,-5.64256
43.20000,-6.56305,-5.64638
43.30000,-6.57998,-5.64693
43.40000,-6.59638,-5.64935
43.50000,-6.61318,-5.65427
43.60000,-6.62985,-5.65568
43.70000,-6.64625,-5.66106
43.80000,-6.66305,-5.66490
43.90000,-6.67972,-5.66848
44.00000,-6.69665,-5.67143
44.10000,-6.71318,-5.67517
44.20000,-6.72998,-5.67850
44.30000,-6.74638,-5.68340
44.40000,-6.76332,-5.68620
44.50000,-6.77985,-5.68819
44.60000,-6.79625,-5.69423
44.70000,-6.81332,-5.70001
44.80000,-6.82985,-5.70274
44.90000,-6.84678,-5.70606
45.00000,-6.86332,-5.71045
45.10000,-6.88012,-5.71531
45.20000,-6.89652,-5.71662
45.30000,-6.91318,-5.71945
45.40000,-6.92985,-5.72207
45.50000,-6.94625,-5.72562
45.60000,-6.96345,-5.73407
45.70000,-6.97985,-5.73876
45.80000,-6.99652,-5.74571
45.90000,-7.01332,-5.74729
46.00000,-7.02998,-5.75304
46.10000,-7.04665,-5.75787
46.20000,-7.06318,-5.76159
46.30000,-7.07998,-5.76588
46.40000,-7.09638,-5.77244
46.50000,-7.11345,-5.77558
46.60000,-7.12985,-5.77901
46.70000,-7.14652,-5.78452
46.80000,-7.16332,-5.78824
46.90000,-7.17972,-5.79132
47.00000,-7.19638,-5.79428
47.10000,-7.21305,-5.79693
47.20000,-7.22985,-5.80088
47.30000,-7.24652,-5.80566
47.40000,-7.26332,-5.80793
47.50000,-7.27972,-5.80946
47.60000,-7.29652,-5.81351
47.70000,-7.31318,-5.81487
47.80000,-7.32972,-5.81746
47.90000,-7.34665,-5.82376
48.00000,-7.36318,-5.82687
48.10000,-7.37985,-5.83132
48.20000,-7.39665,-5.83700
48.30000,-7.41332,-5.83900
48.40000,-7.42972,-5.84404
48.50000,-7.44651,-5.85161
48.60000,-7.46332,-5.85368
48.70000,-7.47972,-5.85245
48.80000,-7.49678,-5.85706
48.90000,-7.51331,-5.85686
49.00000,-7.52998,-5.85869
49.10000,-7.54678,-5.85640
49.20000,-7.56318,-5.85914
49.30000,-7.57985,-5.86288
49.40000,-7.59651,-5.86204
49.50000,-7.61331,-5.86174
49.60000,-7.62971,-5.86749
49.70000,-7.64665,-5.87130
49.80000,-7.66305,-5.87426
49.90000,-7.67985,-5.87974
50.00000,-7.69665,-5.87846
50.10000,-7.71318,-5.87661
50.20000,-7.72985,-5.87725
50.30000,-7.74638,-5.88146
50.40000,-7.76331,-5.88637
50.50000,-7.77985,-5.89185
50.60000,-7.79665,-5.89365
50.70000,-7.81318,-5.88981
50.80000,-7.82998,-5.89510
50.90000,-7.84651,-5.89654
51.00000,-7.86305,-5.89825
51.10000,-7.87998,-5.90067
51.20000,-7.89651,-5.90447
51.30000,-7.91331,-5.91006
51.40000,-7.92998,-5.91166
51.50000,-7.94678,-5.91570
51.60000,-7.96318,-5.91589
51.70000,-7.97998,-5.91743
51.80000,-7.99651,-5.91630
51.90000,-8.01305,-5.92062
52.00000,-8.03025,-5.92603
52.10000,-8.04651,-5.92693
52.20000,-8.06331,-5.92878
52.30000,-8.07998,-5.93044
52.40000,-8.09665,-5.93292
52.50000,-8.11318,-5.93703
52.60000,-8.12985,-5.94095
52.70000,-8.14651,-5.94346
52.80000,-8.16305,-5.94775
52.90000,-8.18011,-5.95204
53.00000,-8.19651,-5.95388
53.10000,-8.21331,-5.95700
53.20000,-8.22985,-5.95787
53.30000,-8.24625,-5.96136
53.40000,-8.26305,-5.96361
53.50000,-8.27971,-5.96508
53.60000,-8.29651,-5.96680
53.70000,-8.31305,-5.96908
53.80000,-8.32985,-5.97055
53.90000,-8.34651,-5.97181
54.00000,-8.36331,-5.97923
54.10000,-8.37998,-5.98361
54.20000,-8.39638,-5.98547
54.30000,-8.41331,-5.98639
54.40000,-8.42985,-5.98909
54.50000,-8.44665,-5.99354
54.60000,-8.46331,-5.99722
54.70000,-8.48011,-5.99911
54.80000,-8.49651,-6.00008
54.90000,-8.51331,-6.00271
55.00000,-8.52985,-6.00204
55.10000,-8.54625,-6.00621
55.20000,-8.56345,-6.00883
55.30000,-8.57985,-6.00728
55.40000,-8.59665,-6.01344
55.50000,-8.61331,-6.01611
55.60000,-8.62998,-6.01955
55.70000,-8.64638,-6.02139
55.80000,-8.66318,-6.02758
55.90000,-8.67985,-6.03092
56.00000,-8.69651,-6.03207
56.10000,-8.71345,-6.03519
56.20000,-8.72985,-6.03649
56.30000,-8.74651,-6.03776
56.40000,-8.76318,-6.03962
56.50000,-8.77971,-6.04597
56.60000,-8.79651,-6.04718
56.70000,-8.81304,-6.04892
56.80000,-8.82985,-6.05371
56.90000,-8.84651,-6.06178
57.00000,-8.86345,-6.06342
57.10000,-8.87985,-6.06684
57.20000,-8.89651,-6.07211
57.30000,-8.91304,-6.07197
57.40000,-8.92958,-6.07334
57.50000,-8.94651,-6.07699
57.60000,-8.96318,-6.08005
57.70000,-8.97998,-6.08284
57.80000,-8.99664,-6.08516
57.90000,-9.01345,-6.08618
58.00000,-9.02971,-6.08800
58.10000,-9.04651,-6.08985
58.20000,-9.06318,-6.08906
58.30000,-9.07971,-6.09133
58.40000,-9.09691,-6.09408
58.50000,-9.11318,-6.09190
58.60000,-9.13011,-6.09453
58.70000,-9.14664,-6.09415
58.80000,-9.16331,-6.09463
58.90000,-9.17984,-6.09423
59.00000,-9.19651,-6.09309
59.10000,-9.21318,-6.08984
59.20000,-9.22971,-6.09016
59.30000,-9.24664,-6.09024
59.40000,-9.26304,-6.08926
59.50000,-9.27984,-6.09095
59.60000,-9.29651,-6.08745
59.70000,-9.31291,-6.08709
59.80000,-9.32971,-6.08938
59.90000,-9.34651,-6.09111
60.00000,-9.36331,-6.09187
60.10000,-9.37984,-6.09664
60.20000,-9.39678,-6.09720
60.30000,-9.41318,-6.09782
60.40000,-9.42998,-6.10228
60.50000,-9.44651,-6.10391
60.60000,-9.46304,-6.10552
60.70000,-9.47998,-6.11010
60.80000,-9.49651,-6.11280
60.90000,-9.51331,-6.11505
61.00000,-9.53011,-6.11802
61.10000,-9.54664,-6.12028
61.20000,-9.56304,-6.12192
61.30000,-9.57984,-6.12442
61.40000,-9.59651,-6.12714
61.50000,-9.61304,-6.13045
61.60000,-9.63024,-6.13536
61.70000,-9.64638,-6.13481
61.80000,-9.66318,-6.13719
61.90000,-9.68011,-6.14096
62.00000,-9.69664,-6.14209
62.10000,-9.71331,-6.14498
62.20000,-9.72998,-6.15043
62.30000,-9.74664,-6.15255
62.40000,-9.76304,-6.15778
62.50000,-9.78011,-6.16048
62.60000,-9.79638,-6.16300
62.70000,-9.81318,-6.16732
62.80000,-9.82971,-6.16863
62.90000,-9.84624,-6.17177
63.00000,-9.86318,-6.17696
63.10000,-9.87971,-6.17953
63.20000,-9.89651,-6.18379
63.30000,-9.91318,-6.18892
63.40000,-9.92998,-6.19195
63.50000,-9.94651,-6.19538
63.60000,-9.96331,-6.20080
63.70000,-9.97984,-6.20053
63.80000,-9.99638,-6.20214
63.90000,-10.01344,-6.20743
64.00000,-10.02998,-6.21307
64.10001,-10.04664,-6.21846
64.20000,-10.06344,-6.22391
64.30000,-10.08011,-6.22915
64.40000,-10.09651,-6.23147
64.50000,-10.11331,-6.23851
64.60001,-10.12998,-6.24592
64.70000,-10.14638,-6.25133
64.80000,-10.16344,-6.26022
64.90000,-10.17984,-6.26428
65.00000,-10.19664,-6.27321
65.10001,-10.21344,-6.27881
65.20000,-10.22997,-6.28441
65.30000,-10.24637,-6.29121
65.40000,-10.26317,-6.29767
65.50000,-10.27984,-6.30170
65.60001,-10.29637,-6.30804
65.70001,-10.31331,-6.31248
65.80000,-10.32971,-6.31762
65.90000,-10.34664,-6.32607
66.00000,-10.36331,-6.32874
66.10001,-10.37971,-6.33561
66.20001,-10.39651,-6.34051
66.30000,-10.41291,-6.34534
66.40000,-10.42984,-6.35144
66.50000,-10.44651,-6.36094
66.60001,-10.46331,-6.36577
66.70001,-10.47984,-6.37002
66.80000,-10.49664,-6.37724
66.90000,-10.51317,-6.37983
67.00000,-10.52957,-6.38562
67.10001,-10.54651,-6.39284
67.20001,-10.56304,-6.39927
67.30000,-10.57984,-6.40417
67.40000,-10.59664,-6.41365
67.50000,-10.61344,-6.41998
67.60001,-10.62984,-6.42446
67.70001,-10.64664,-6.43248
67.80000,-10.66331,-6.43689
67.90000,-10.67971,-6.44237
68.00000,-10.69691,-6.44929
68.10001,-10.71331,-6.45433
68.20001,-10.72997,-6.46098
68.30000,-10.74677,-6.46673
68.40000,-10.76317,-6.47122
68.50000,-10.77984,-6.47730
68.60001,-10.79651,-6.48432
68.70001,-10.81317,-6.48677
68.80000,-10.82971,-6.49415
68.90000,-10.84677,-6.50312
69.00000,-10.86317,-6.50807
69.10001,-10.87997,-6.51390
69.20001,-10.89651,-6.51664
69.30000,-10.91291,-6.51979
69.40000,-10.92971,-6.52666
69.50000,-10.94637,-6.53477
69.60001,-10.96317,-6.54245
69.70001,-10.97957,-6.54707
69.80000,-10.99664,-6.55122
69.90000,-11.01317,-6.55724
70.00000,-11.02997,-6.56134
70.10001,-11.04664,-6.56609
70.20001,-11.06291,-6.57292
70.30000,-11.07997,-6.57900
70.40000,-11.09651,-6.58223
70.50000,-11.11331,-6.58868
70.60001,-11.12997,-6.59713
70.70001,-11.14677,-6.60703
70.80000,-11.16317,-6.61353
70.90000,-11.17997,-6.62159
71.00000,-11.19664,-6.62579
71.10001,-11.21304,-6.63506
71.20001,-11.23011,-6.64687
71.30000,-11.24651,-6.65454
71.40000,-11.26331,-6.66375
71.50000,-11.28011,-6.67292
71.60001,-11.29651,-6.68034
71.70001,-11.31317,-6.68896
71.80000,-11.32984,-6.69756
71.90000,-11.34651,-6.70404
72.00000,-11.36304,-6.71153
72.10001,-11.38011,-6.72031
72.20001,-11.39637,-6.72612
72.30000,-11.41317,-6.73567
72.40000,-11.42984,-6.74022
72.50000,-11.44637,-6.74606
72.60001,-11.46304,-6.75335
72.70001,-11.47971,-6.76065
72.80000,-11.49651,-6.76958
72.90000,-11.51317,-6.77730
73.00000,-11.53011,-6.78532
73.10001,-11.54651,-6.79185
73.20001,-11.56317,-6.80190
73.30000,-11.57984,-6.80675
73.40000,-11.59637,-6.81557
73.50000,-11.61330,-6.82453
73.60001,-11.62984,-6.83347
73.70001,-11.64650,-6.84223
73.80000,-11.66330,-6.85167
73.90000,-11.68010,-6.86124
74.00000,-11.69664,-6.86634
74.10001,-11.71330,-6.87820
74.20001,-11.72997,-6.88396
74.30000,-11.74637,-6.89342
74.40000,-11.76344,-6.90472
74.50000,-11.77997,-6.91288
74.60001,-11.79664,-6.92109
74.70001,-11.81344,-6.92966
74.80000,-11.82997,-6.93675
74.90000,-11.84650,-6.94439
75.00000,-11.86317,-6.95349
75.10001,-11.87984,-6.95912
75.20001,-11.89637,-6.97036
75.30000,-11.91330,-6.97771
75.40000,-11.92970,-6.98357
75.50000,-11.94650,-6.99449
75.60001,-11.96317,-6.99994
75.70001,-11.97970,-7.00912
75.80000,-11.99650,-7.01935
75.90000,-12.01304,-7.02812
76.00000,-12.02984,-7.03778
76.10001,-12.04637,-7.04843
76.20001,-12.06330,-7.05928
76.30000,-12.07984,-7.06663
76.40000,-12.09650,-7.07679
76.50000,-12.11317,-7.08346
76.60001,-12.12970,-7.09187
76.70001,-12.14664,-7.10078
76.80000,-12.16317,-7.10976
76.90000,-12.17997,-7.11932
77.00000,-12.19677,-7.13002
77.10001,-12.21344,-7.13997
77.20001,-12.22984,-7.14603
77.30000,-12.24664,-7.15778
77.40000,-12.26330,-7.16379
77.50000,-12.27970,-7.17205
77.60001,-12.29664,-7.18357
77.70001,-12.31304,-7.19028
77.80000,-12.32997,-7.20330
77.90000,-12.34677,-7.21350
78.00000,-12.36330,-7.22015
78.10001,-12.37984,-7.22914
78.20001,-12.39650,-7.23910
78.30000,-12.41317,-7.24577
78.40000,-12.42970,-7.25601
78.50000,-12.44677,-7.26627
78.60001,-12.46304,-7.27427
78.70001,-12.47984,-7.28697
78.80000,-12.49650,-7.29456
78.90000,-12.51304,-7.30385
79.00000,-12.52970,-7.31299
79.10001,-12.54637,-7.32187
79.20001,-12.56317,-7.32997
79.30000,-12.57970,-7.34258
79.40000,-12.59664,-7.35163
79.50000,-12.61317,-7.35849
79.60001,-12.62997,-7.36982
79.70001,-12.64650,-7.37512
79.80000,-12.66304,-7.38348
79.90000,-12.67997,-7.39495
80.00000,-12.69650,-7.40350
80.10001,-12.71330,-7.41267
80.20001,-12.72997,-7.42050
80.30000,-12.74677,-7.42730
80.40000,-12.76317,-7.43099
80.50001,-12.77997,-7.43820
80.60001,-12.79664,-7.44143
80.70001,-12.81290,-7.44677
80.80000,-12.83010,-7.45782
80.90000,-12.84650,-7.46298
81.00001,-12.86330,-7.47316
81.10001,-12.88010,-7.48199
81.20001,-12.89664,-7.48971
81.30000,-12.91330,-7.49907
81.40000,-12.92984,-7.50946
81.50001,-12.94650,-7.51743
81.60001,-12.96290,-7.52917
81.70001,-12.97997,-7.54019
81.80000,-12.99650,-7.55067
81.90000,-13.01343,-7.56616
82.00001,-13.02997,-7.57409
82.10001,-13.04637,-7.58474
82.20001,-13.06303,-7.59460
82.30000,-13.07970,-7.60581
82.40000,-13.09650,-7.61533
82.50001,-13.11317,-7.62774
82.60001,-13.13010,-7.63832
82.70001,-13.14650,-7.64652
82.80000,-13.16330,-7.65835
82.90000,-13.17983,-7.66200
83.00001,-13.19637,-7.67388
83.10001,-13.21330,-7.68180
83.20001,-13.22970,-7.68973
83.30000,-13.24663,-7.69984
83.40000,-13.26330,-7.71066
83.50001,-13.27997,-7.71646
83.60001,-13.29650,-7.72254
83.70001,-13.31330,-7.73098
83.80000,-13.32997,-7.73441
83.90000,-13.34637,-7.74146
84.00001,-13.36343,-7.75040
84.10001,-13.37983,-7.75353
84.20001,-13.39663,-7.76222
84.30000,-13.41330,-7.77059
84.40000,-13.42983,-7.77669
84.50001,-13.44650,-7.78349
84.60001,-13.46317,-7.79072
84.70001,-13.47983,-7.79489
84.80000,-13.49637,-7.80299
84.90000,-13.51343,-7.80970
85.00001,-13.52983,-7.81291
85.10001,-13.54663,-7.82067
85.20001,-13.56317,-7.82148
85.30000,-13.57970,-7.82575
85.40000,-13.59637,-7.83111
85.50001,-13.61290,-7.83767
85.60001,-13.62983,-7.84177
85.70001,-13.64650,-7.85056
85.80000,-13.66343,-7.85450
85.90000,-13.67983,-7.85712
86.00001,-13.69663,-7.86487
86.10001,-13.71317,-7.86957
86.20001,-13.72970,-7.87288
86.30000,-13.74663,-7.87766
86.40000,-13.76317,-7.88371
86.50001,-13.78010,-7.89143
86.60001,-13.79663,-7.89732
86.70001,-13.81343,-7.90000
86.80000,-13.82983,-7.89867
86.90000,-13.84663,-7.90687
87.00001,-13.86317,-7.91082
87.10001,-13.87957,-7.91915
87.20001,-13.89677,-7.92716
87.30000,-13.91317,-7.93221
87.40000,-13.93010,-7.93992
87.50001,-13.94663,-7.94671
87.60001,-13.96317,-7.95184
87.70001,-13.97983,-7.95917
87.80000,-13.99650,-7.97053
87.90000,-14.01317,-7.97437
88.00001,-14.02970,-7.98853
88.10001,-14.04677,-8.00077
88.20001,-14.06330,-8.01049
88.30000,-14.07997,-8.02477
88.40000,-14.09663,-8.03007
88.50001,-14.11317,-8.03987
88.60001,-14.12970,-8.05013
88.70001,-14.14637,-8.06213
88.80000,-14.16317,-8.07368
88.90000,-14.17983,-8.08819
89.00001,-14.19677,-8.10028
89.10001,-14.21317,-8.11147
89.20001,-14.22997,-8.12682
89.30000,-14.24650,-8.13533
89.40000,-14.26303,-8.14917
89.50001,-14.27997,-8.16322
89.60001,-14.29636,-8.17631
89.70001,-14.31330,-8.19143
89.80000,-14.33010,-8.20699
89.90000,-14.34677,-8.21779
90.00001,-14.36317,-8.22937
90.05801,-14.37303,-8.23683