File: GFBaking/data/1TspPectin/1TspPectin.is_comp_RawData/Specimen_RawData_2.csv
Time,Extension,Load
(sec),(mm),(N)
0.00000,0.00000,0.00008
0.10000,-0.00573,-0.00463
0.20000,-0.02560,-0.02740
0.30000,-0.04533,-0.04949
0.40000,-0.06413,-0.06559
0.50000,-0.08213,-0.08083
0.60000,-0.09907,-0.09799
0.70000,-0.11613,-0.11613
0.80000,-0.13293,-0.13116
0.90000,-0.14987,-0.14405
1.00000,-0.16640,-0.15806
1.10000,-0.18333,-0.17288
1.20000,-0.20000,-0.19201
1.30000,-0.21640,-0.21195
1.40000,-0.23333,-0.22461
1.50000,-0.24973,-0.23721
1.60000,-0.26640,-0.25305
1.70000,-0.28320,-0.26877
1.80000,-0.29987,-0.28667
1.90000,-0.31640,-0.29856
2.00000,-0.33333,-0.31141
2.10000,-0.34987,-0.32543
2.20000,-0.36640,-0.34337
2.30000,-0.38320,-0.36248
2.40000,-0.39960,-0.37896
2.50000,-0.41667,-0.39476
2.60000,-0.43320,-0.41028
2.70000,-0.44987,-0.42765
2.80000,-0.46653,-0.44767
2.90000,-0.48320,-0.46631
3.00000,-0.50000,-0.48307
3.10000,-0.51640,-0.49878
3.20000,-0.53320,-0.51870
3.30000,-0.54973,-0.53784
3.40000,-0.56680,-0.56274
3.50000,-0.58333,-0.58201
3.60000,-0.60000,-0.60467
3.70000,-0.61680,-0.62645
3.80000,-0.63320,-0.65016
3.90000,-0.65000,-0.67463
4.00000,-0.66653,-0.69603
4.10000,-0.68333,-0.71939
4.20000,-0.69973,-0.74076
4.30000,-0.71666,-0.76486
4.40000,-0.73320,-0.78884
4.50000,-0.74986,-0.81287
4.60000,-0.76680,-0.83572
4.70000,-0.78306,-0.85889
4.80000,-0.79973,-0.88484
4.90000,-0.81640,-0.91461
5.00000,-0.83333,-0.93922
5.10000,-0.84986,-0.96226
5.20000,-0.86666,-0.98921
5.30000,-0.88320,-1.01433
5.40000,-0.89973,-1.03532
5.50000,-0.91666,-1.06002
5.60000,-0.93293,-1.07947
5.70000,-0.94986,-1.10231
5.80000,-0.96653,-1.12419
5.90000,-0.98320,-1.14968
6.00000,-1.00000,-1.17573
6.10000,-1.01680,-1.20148
6.20000,-1.03320,-1.22190
6.30000,-1.04960,-1.24704
6.40000,-1.06666,-1.27450
6.50000,-1.08306,-1.30022
6.60000,-1.10000,-1.32502
6.70000,-1.11666,-1.34883
6.80000,-1.13333,-1.37403
6.90000,-1.15026,-1.39950
7.00000,-1.16653,-1.42363
7.10000,-1.18333,-1.44911
7.20000,-1.19986,-1.47353
7.30000,-1.21666,-1.49780
7.40000,-1.23320,-1.52338
7.50000,-1.25013,-1.54960
7.60000,-1.26666,-1.57318
7.70000,-1.28320,-1.59937
7.80000,-1.30000,-1.62259
7.90000,-1.31640,-1.64722
8.00000,-1.33306,-1.67489
8.10000,-1.34973,-1.68716
8.20000,-1.36653,-1.69506
8.30000,-1.38306,-1.70097
8.40000,-1.40013,-1.71999
8.50000,-1.41653,-1.74127
8.60000,-1.43306,-1.76763
8.70000,-1.45000,-1.79155
8.80000,-1.46626,-1.81405
8.90000,-1.48320,-1.84218
9.00000,-1.50000,-1.86588
9.10000,-1.51666,-1.88972
9.20000,-1.53333,-1.91084
9.30000,-1.55000,-1.93229
9.40000,-1.56666,-1.95782
9.50000,-1.58306,-1.98351
9.60000,-1.60000,-2.00781
9.70000,-1.61640,-2.02990
9.80000,-1.63333,-2.05477
9.90000,-1.65000,-2.07804
10.00000,-1.66653,-2.10026
10.10000,-1.68320,-2.12224
10.20000,-1.69973,-2.14328
10.30000,-1.71653,-2.16527
10.40000,-1.73320,-2.18824
10.50000,-1.75000,-2.20972
10.60000,-1.76653,-2.22740
10.70000,-1.78346,-2.22063
10.80000,-1.80000,-2.22032
10.90000,-1.81666,-2.23062
11.00000,-1.83333,-2.23586
11.10000,-1.84973,-2.25889
11.20000,-1.86653,-2.28297
11.30000,-1.88320,-2.30782
11.40000,-1.89986,-2.33068
11.50000,-1.91653,-2.35412
11.60000,-1.93333,-2.37574
11.70000,-1.94973,-2.39527
11.80000,-1.96640,-2.41466
11.90000,-1.98333,-2.43464
12.00000,-1.99960,-2.45436
12.10000,-2.01653,-2.47619
12.20000,-2.03319,-2.49617
12.30000,-2.05000,-2.51374
12.40000,-2.06666,-2.53238
12.50000,-2.08333,-2.54884
12.60000,-2.09986,-2.56411
12.70000,-2.11639,-2.58438
12.80000,-2.13333,-2.60393
12.90000,-2.14973,-2.62185
13.00000,-2.16679,-2.64295
13.10000,-2.18333,-2.66032
13.20000,-2.19999,-2.67905
13.30000,-2.21679,-2.69619
13.40000,-2.23319,-2.71171
13.50000,-2.24999,-2.72923
13.60000,-2.26653,-2.74587
13.70000,-2.28333,-2.76222
13.80000,-2.29986,-2.77870
13.90000,-2.31679,-2.79484
14.00000,-2.33319,-2.80912
14.10000,-2.34973,-2.82399
14.20000,-2.36653,-2.84092
14.30000,-2.38293,-2.85618
14.40000,-2.39973,-2.87338
14.50000,-2.41653,-2.88954
14.60000,-2.43319,-2.90676
14.70000,-2.44986,-2.92157
14.80000,-2.46679,-2.93937
14.90000,-2.48333,-2.95470
15.00000,-2.49973,-2.96883
15.10000,-2.51653,-2.98209
15.20000,-2.53293,-2.99570
15.30000,-2.54999,-3.01067
15.40000,-2.56653,-3.02550
15.50000,-2.58333,-3.04017
15.60000,-2.59986,-3.05335
15.70000,-2.61666,-3.06537
15.80000,-2.63333,-3.07880
15.90000,-2.64973,-3.09257
16.00000,-2.66666,-3.10763
16.10000,-2.68306,-3.12096
16.20000,-2.70013,-3.13409
16.30000,-2.71666,-3.14599
16.40000,-2.73333,-3.15998
16.50000,-2.74999,-3.17174
16.60000,-2.76653,-3.18359
16.70000,-2.78333,-3.19592
16.80000,-2.79973,-3.20651
16.90000,-2.81666,-3.21827
17.00000,-2.83319,-3.22942
17.10000,-2.85013,-3.24134
17.20000,-2.86666,-3.25115
17.30000,-2.88319,-3.26208
17.40000,-2.89999,-3.27390
17.50000,-2.91639,-3.28409
17.60000,-2.93306,-3.29510
17.70000,-2.94973,-3.30564
17.80000,-2.96653,-3.31501
17.90000,-2.98306,-3.32594
18.00000,-2.99999,-3.33671
18.10000,-3.01653,-3.34542
18.20000,-3.03306,-3.35485
18.30000,-3.04999,-3.36392
18.40000,-3.06626,-3.37407
18.50000,-3.08333,-3.38455
18.60000,-3.09986,-3.39214
18.70000,-3.11653,-3.40195
18.80000,-3.13333,-3.41086
18.90000,-3.14999,-3.41914
19.00000,-3.16653,-3.42696
19.10000,-3.18306,-3.43425
19.20000,-3.19999,-3.44237
19.30000,-3.21639,-3.44820
19.40000,-3.23346,-3.45598
19.50000,-3.24999,-3.46398
19.60000,-3.26666,-3.47185
19.70000,-3.28346,-3.47961
19.80000,-3.29986,-3.48743
19.90000,-3.31653,-3.49425
20.00000,-3.33306,-3.50183
20.10000,-3.34986,-3.50722
20.20000,-3.36639,-3.51488
20.30000,-3.38333,-3.52214
20.40000,-3.39986,-3.52807
20.50000,-3.41652,-3.53345
20.60000,-3.43332,-3.53855
20.70000,-3.44972,-3.54287
20.80000,-3.46639,-3.54721
20.90000,-3.48306,-3.55033
21.00000,-3.49986,-3.55341
21.10000,-3.51639,-3.55559
21.20000,-3.53332,-3.55971
21.30000,-3.54986,-3.56388
21.40000,-3.56652,-3.56864
21.50000,-3.58332,-3.57295
21.60000,-3.59959,-3.57631
21.70000,-3.61652,-3.58178
21.80000,-3.63319,-3.58580
21.90000,-3.64999,-3.59049
22.00000,-3.66652,-3.59467
22.10000,-3.68332,-3.59827
22.20000,-3.69999,-3.60052
22.30000,-3.71652,-3.60465
22.40000,-3.73332,-3.60545
22.50000,-3.74986,-3.60753
22.60000,-3.76666,-3.60956
22.70000,-3.78332,-3.61077
22.80000,-3.79999,-3.61213
22.90000,-3.81679,-3.61367
23.00000,-3.83319,-3.61375
23.10000,-3.84986,-3.61400
23.20000,-3.86639,-3.61458
23.30000,-3.88319,-3.61494
23.40000,-3.89972,-3.61440
23.50000,-3.91666,-3.61512
23.60000,-3.93319,-3.61436
23.70000,-3.94986,-3.61453
23.80000,-3.96666,-3.61383
23.90000,-3.98319,-3.61326
24.00000,-3.99972,-3.61155
24.10000,-4.01639,-3.61003
24.20000,-4.03346,-3.60889
24.30000,-4.04986,-3.60801
24.40000,-4.06666,-3.60805
24.50000,-4.08319,-3.60749
24.60000,-4.09972,-3.60762
24.70000,-4.11666,-3.60796
24.80000,-4.13292,-3.60870
24.90000,-4.14986,-3.61142
25.00000,-4.16639,-3.61274
25.10000,-4.18332,-3.61610
25.20000,-4.19999,-3.61712
25.30000,-4.21666,-3.61815
25.40000,-4.23332,-3.61978
25.50000,-4.24972,-3.62071
25.60000,-4.26652,-3.61969
25.70000,-4.28306,-3.61983
25.80000,-4.29999,-3.62464
25.90000,-4.31666,-3.62464
26.00000,-4.33332,-3.62693
26.10000,-4.34999,-3.62770
26.20000,-4.36652,-3.62728
26.30000,-4.38332,-3.62748
26.40000,-4.39986,-3.62999
26.50000,-4.41666,-3.63130
26.60000,-4.43319,-3.63228
26.70000,-4.45012,-3.63352
26.80000,-4.46652,-3.63155
26.90000,-4.48319,-3.63228
27.00000,-4.49999,-3.63119
27.10000,-4.51639,-3.63268
27.20000,-4.53306,-3.63437
27.30000,-4.54972,-3.63571
27.40000,-4.56666,-3.63557
27.50000,-4.58306,-3.63515
27.60000,-4.59999,-3.63676
27.70000,-4.61652,-3.63570
27.80000,-4.63306,-3.63816
27.90000,-4.65012,-3.63776
28.00000,-4.66639,-3.63864
28.10000,-4.68319,-3.63993
28.20000,-4.69999,-3.64109
28.30000,-4.71666,-3.64316
28.40000,-4.73319,-3.64542
28.50000,-4.74999,-3.64732
28.60000,-4.76666,-3.64867
28.70000,-4.78306,-3.65115
28.80000,-4.79985,-3.65514
28.90000,-4.81639,-3.65903
29.00000,-4.83332,-3.66455
29.10000,-4.84999,-3.66660
29.20000,-4.86652,-3.67094
29.30000,-4.88332,-3.67506
29.40000,-4.89985,-3.67902
29.50000,-4.91652,-3.68268
29.60000,-4.93305,-3.68486
29.70000,-4.94999,-3.68872
29.80000,-4.96652,-3.69144
29.90000,-4.98345,-3.69658
30.00000,-4.99999,-3.69812
30.10000,-5.01652,-3.70176
30.20000,-5.03332,-3.70465
30.30000,-5.04985,-3.70846
30.40000,-5.06652,-3.71169
30.50000,-5.08319,-3.71654
30.60000,-5.09985,-3.72078
30.70000,-5.11652,-3.72592
30.80000,-5.13332,-3.73070
30.90000,-5.14999,-3.73430
31.00000,-5.16639,-3.74083
31.10000,-5.18332,-3.74308
31.20000,-5.19959,-3.74799
31.30000,-5.21639,-3.75354
31.40000,-5.23305,-3.75833
31.50000,-5.24999,-3.76574
31.60000,-5.26652,-3.76904
31.70000,-5.28332,-3.77425
31.80000,-5.29999,-3.77524
31.90000,-5.31652,-3.78310
32.00000,-5.33332,-3.78151
32.10000,-5.34972,-3.78593
32.20000,-5.36665,-3.79436
32.30000,-5.38332,-3.79964
32.40000,-5.39985,-3.80844
32.50000,-5.41679,-3.81573
32.60000,-5.43319,-3.82202
32.70000,-5.44999,-3.82830
32.80000,-5.46652,-3.83220
32.90000,-5.48332,-3.84185
33.00000,-5.49985,-3.84377
33.10000,-5.51679,-3.85191
33.20000,-5.53332,-3.85321
33.30000,-5.54985,-3.86158
33.40000,-5.56665,-3.86822
33.50000,-5.58305,-3.87332
33.60000,-5.59972,-3.87691
33.70000,-5.61639,-3.88077
33.80000,-5.63332,-3.88661
33.90000,-5.64985,-3.89322
34.00000,-5.66665,-3.90255
34.10000,-5.68319,-3.90499
34.20000,-5.69972,-3.90996
34.30000,-5.71665,-3.91437
34.40000,-5.73292,-3.92045
34.50000,-5.74985,-3.92747
34.60000,-5.76665,-3.93262
34.70000,-5.78332,-3.93867
34.80000,-5.79999,-3.94725
34.90000,-5.81665,-3.95004
35.00000,-5.83332,-3.95547
35.10000,-5.84985,-3.96158
35.20000,-5.86652,-3.95765
35.30000,-5.88305,-3.96297
35.40000,-5.89999,-3.96599
35.50000,-5.91665,-3.97326
35.60000,-5.93332,-3.98033
35.70000,-5.95012,-3.97927
35.80000,-5.96665,-3.98595
35.90000,-5.98332,-3.98913
36.00000,-5.99985,-3.99815
36.10000,-6.01652,-4.00394
36.20000,-6.03319,-4.00519
36.30000,-6.05012,-4.00847
36.40000,-6.06665,-4.01279
36.50000,-6.08319,-4.01940
36.60000,-6.10012,-4.02258
36.70000,-6.11639,-4.02681
36.80000,-6.13305,-4.03041
36.90000,-6.14972,-4.02874
37.00000,-6.16665,-4.03681
37.10000,-6.18319,-4.04203
37.20000,-6.20012,-4.04933
37.30000,-6.21665,-4.04700
37.40000,-6.23305,-4.04912
37.50000,-6.24998,-4.05182
37.60000,-6.26625,-4.05323
37.70000,-6.28318,-4.05815
37.80000,-6.29985,-4.06221
37.90000,-6.31665,-4.06537
38.00000,-6.33332,-4.06790
38.10000,-6.34985,-4.07184
38.20000,-6.36665,-4.07758
38.30000,-6.38318,-4.07809
38.40000,-6.39985,-4.08334
38.50000,-6.41638,-4.08540
38.60000,-6.43345,-4.09334
38.70000,-6.44998,-4.09606
38.80000,-6.46665,-4.09793
38.90000,-6.48345,-4.10754
39.00000,-6.49985,-4.11202
39.10000,-6.51665,-4.11453
39.20000,-6.53318,-4.12077
39.30000,-6.55012,-4.12718
39.40000,-6.56652,-4.13239
39.50000,-6.58332,-4.14043
39.60000,-6.59985,-4.14780
39.70000,-6.61638,-4.15257
39.80000,-6.63332,-4.15603
39.90000,-6.64972,-4.15969
40.00000,-6.66638,-4.16487
40.10000,-6.68318,-4.17038
40.20000,-6.69985,-4.17428
40.30000,-6.71638,-4.17884
40.40000,-6.73332,-4.18179
40.50000,-6.74985,-4.18428
40.60000,-6.76638,-4.19065
40.70000,-6.78332,-4.19143
40.80000,-6.79958,-4.19673
40.90000,-6.81652,-4.19938
41.00000,-6.83332,-4.20429
41.10000,-6.84998,-4.20901
41.20000,-6.86665,-4.21229
41.30000,-6.88332,-4.21844
41.40000,-6.89998,-4.22022
41.50000,-6.91638,-4.22667
41.60000,-6.93318,-4.23146
41.70000,-6.94972,-4.23381
41.80000,-6.96678,-4.23953
41.90000,-6.98332,-4.24294
42.00000,-6.99985,-4.24293
42.10000,-7.01665,-4.24882
42.20000,-7.03318,-4.25523
42.30000,-7.04998,-4.25671
42.40000,-7.06652,-4.25900
42.50000,-7.08332,-4.26417
42.60000,-7.09985,-4.27166
42.70000,-7.11665,-4.27898
42.80000,-7.13318,-4.28268
42.90000,-7.14998,-4.28948
43.00000,-7.16665,-4.29435
43.10000,-7.18305,-4.30062
43.20000,-7.19972,-4.30714
43.30000,-7.21638,-4.31257
43.40000,-7.23318,-4.31694
43.50000,-7.24972,-4.32140
43.60000,-7.26665,-4.32322
43.70000,-7.28318,-4.32669
43.80000,-7.29985,-4.32912
43.90000,-7.31665,-4.33383
44.00000,-7.33292,-4.33526
44.10000,-7.34985,-4.34030
44.20000,-7.36652,-4.34241
44.30000,-7.38318,-4.34691
44.40000,-7.39985,-4.35263
44.50000,-7.41665,-4.35852
44.60000,-7.43332,-4.36150
44.70000,-7.44985,-4.36958
44.80000,-7.46665,-4.37800
44.90000,-7.48305,-4.38597
45.00000,-7.50011,-4.39678
45.10000,-7.51665,-4.40043
45.20000,-7.53318,-4.40273
45.30000,-7.55011,-4.40874
45.40000,-7.56651,-4.41824
45.50000,-7.58332,-4.42525
45.60000,-7.59985,-4.43433
45.70000,-7.61665,-4.43602
45.80000,-7.63305,-4.44051
45.90000,-7.65011,-4.44900
46.00000,-7.66638,-4.45561
46.10000,-7.68318,-4.46227
46.20000,-7.70011,-4.46910
46.30000,-7.71638,-4.47384
46.40000,-7.73305,-4.47966
46.50000,-7.74985,-4.48462
46.60000,-7.76651,-4.48874
46.70000,-7.78305,-4.49584
46.80000,-7.79998,-4.50125
46.90000,-7.81651,-4.50561
47.00000,-7.83318,-4.51296
47.10000,-7.84998,-4.51792
47.20000,-7.86625,-4.52353
47.30000,-7.88318,-4.53012
47.40000,-7.89985,-4.53468
47.50000,-7.91651,-4.54203
47.60000,-7.93318,-4.54680
47.70000,-7.94998,-4.55380
47.80000,-7.96665,-4.55954
47.90000,-7.98318,-4.56680
48.00000,-7.99998,-4.57148
48.10000,-8.01638,-4.57658
48.20000,-8.03345,-4.58343
48.30000,-8.04985,-4.58805
48.40000,-8.06665,-4.59400
48.50000,-8.08331,-4.59891
48.60000,-8.09998,-4.60399
48.70000,-8.11665,-4.60738
48.80000,-8.13305,-4.61355
48.90000,-8.14998,-4.61833
49.00000,-8.16651,-4.62275
49.10000,-8.18345,-4.62908
49.20000,-8.19985,-4.63079
49.30000,-8.21651,-4.63679
49.40000,-8.23318,-4.63923
49.50000,-8.24971,-4.64224
49.60000,-8.26625,-4.64629
49.70000,-8.28305,-4.65105
49.80000,-8.29985,-4.65713
49.90000,-8.31638,-4.66061
50.00000,-8.33331,-4.66732
50.10000,-8.34985,-4.67166
50.20000,-8.36651,-4.67948
50.30000,-8.38331,-4.68502
50.40000,-8.39958,-4.68898
50.50000,-8.41651,-4.69418
50.60000,-8.43318,-4.69692
50.70000,-8.44998,-4.70273
50.80000,-8.46651,-4.70751
50.90000,-8.48331,-4.71003
51.00000,-8.49985,-4.71084
51.10000,-8.51638,-4.71307
51.20000,-8.53318,-4.71687
51.30000,-8.54958,-4.71787
51.40000,-8.56678,-4.72335
51.50000,-8.58331,-4.72285
51.60000,-8.59985,-4.72463
51.70000,-8.61665,-4.72641
51.80000,-8.63318,-4.72581
51.90000,-8.64985,-4.72566
52.00000,-8.66651,-4.72754
52.10000,-8.68331,-4.72675
52.20000,-8.69985,-4.72803
52.30000,-8.71678,-4.73153
52.40000,-8.73331,-4.73210
52.50000,-8.74985,-4.73443
52.60000,-8.76665,-4.73438
52.70000,-8.78305,-4.73582
52.80000,-8.79971,-4.73869
52.90000,-8.81638,-4.74145
53.00000,-8.83331,-4.74431
53.10000,-8.84971,-4.74607
53.20000,-8.86678,-4.74935
53.30000,-8.88318,-4.75091
53.40000,-8.89971,-4.75472
53.50000,-8.91651,-4.75582
53.60000,-8.93291,-4.75703
53.70000,-8.94985,-4.76230
53.80000,-8.96651,-4.76388
53.90000,-8.98304,-4.76598
54.00000,-8.99971,-4.76908
54.10000,-9.01665,-4.77436
54.20000,-9.03331,-4.77812
54.30000,-9.04984,-4.78245
54.40000,-9.06665,-4.78455
54.50000,-9.08291,-4.78431
54.60000,-9.10011,-4.78859
54.70000,-9.11664,-4.78953
54.80000,-9.13331,-4.79172
54.90000,-9.15011,-4.79373
55.00000,-9.16651,-4.79347
55.10000,-9.18331,-4.79473
55.20000,-9.19984,-4.79678
55.30000,-9.21664,-4.79899
55.40000,-9.23318,-4.79880
55.50000,-9.25011,-4.79972
55.60000,-9.26664,-4.79999
55.70000,-9.28318,-4.80223
55.80000,-9.29998,-4.80292
55.90000,-9.31624,-4.80315
56.00000,-9.33318,-4.80408
56.10000,-9.34984,-4.80559
56.20000,-9.36664,-4.80674
56.30000,-9.38318,-4.80872
56.40000,-9.40011,-4.80957
56.50000,-9.41651,-4.80825
56.60000,-9.43318,-4.80812
56.70000,-9.44998,-4.80775
56.80000,-9.46638,-4.80884
56.90000,-9.48318,-4.80985
57.00000,-9.49984,-4.81075
57.10000,-9.51664,-4.81270
57.20000,-9.53331,-4.81376
57.30000,-9.54998,-4.81291
57.40000,-9.56651,-4.81293
57.50000,-9.58304,-4.81743
57.60000,-9.59998,-4.82028
57.70000,-9.61651,-4.82065
57.80000,-9.63331,-4.82338
57.90000,-9.64984,-4.82513
58.00000,-9.66651,-4.82843
58.10000,-9.68344,-4.83531
58.20000,-9.69998,-4.83762
58.30000,-9.71678,-4.84110
58.40000,-9.73318,-4.84592
58.50000,-9.74998,-4.85112
58.60000,-9.76651,-4.85806
58.70000,-9.78344,-4.86522
58.80000,-9.79984,-4.87004
58.90000,-9.81651,-4.87668
59.00000,-9.83331,-4.87599
59.10000,-9.84958,-4.88181
59.20000,-9.86651,-4.89047
59.30000,-9.88318,-4.89669
59.40000,-9.89984,-4.90218
59.50000,-9.91624,-4.90883
59.60000,-9.93331,-4.91777
59.70000,-9.94984,-4.92361
59.80000,-9.96638,-4.93187
59.90000,-9.98318,-4.93919
60.00000,-9.99958,-4.94703
60.10000,-10.01664,-4.95652
60.20000,-10.03331,-4.96290
60.30000,-10.05011,-4.97075
60.40000,-10.06664,-4.97733
60.50000,-10.08344,-4.98436
60.60000,-10.09998,-4.98888
60.70000,-10.11638,-4.99385
60.80000,-10.13331,-4.99842
60.90000,-10.14958,-5.00246
61.00000,-10.16664,-5.01153
61.10000,-10.18331,-5.01899
61.20000,-10.19998,-5.02777
61.30000,-10.21678,-5.03434
61.40000,-10.23318,-5.04040
61.50000,-10.24984,-5.04861
61.60000,-10.26637,-5.05869
61.70000,-10.28317,-5.06594
61.80000,-10.29971,-5.07563
61.90000,-10.31664,-5.08628
62.00000,-10.33317,-5.09593
62.10000,-10.34984,-5.10696
62.20000,-10.36678,-5.11634
62.30000,-10.38317,-5.12553
62.40000,-10.39971,-5.13474
62.50000,-10.41637,-5.14594
62.60000,-10.43317,-5.15689
62.70000,-10.44971,-5.16879
62.80000,-10.46664,-5.17952
62.90000,-10.48317,-5.18960
63.00000,-10.49984,-5.20021
63.10000,-10.51664,-5.20864
63.20000,-10.53291,-5.21800
63.30000,-10.54984,-5.22965
63.40000,-10.56651,-5.23981
63.50000,-10.58317,-5.24938
63.60000,-10.59984,-5.25964
63.70000,-10.61677,-5.26885
63.80000,-10.63331,-5.27618
63.90000,-10.64984,-5.28678
64.00000,-10.66651,-5.29586
64.10001,-10.68317,-5.30526
64.20000,-10.70011,-5.31431
64.30000,-10.71664,-5.32246
64.40000,-10.73331,-5.33203
64.50000,-10.75011,-5.34182
64.60001,-10.76664,-5.34942
64.70000,-10.78331,-5.35897
64.80000,-10.79984,-5.36897
64.90000,-10.81664,-5.37466
65.00000,-10.83304,-5.38505
65.10001,-10.85011,-5.39551
65.20000,-10.86664,-5.40711
65.30000,-10.88331,-5.41767
65.40000,-10.89997,-5.42643
65.50000,-10.91624,-5.43801
65.60001,-10.93304,-5.45049
65.70001,-10.94971,-5.46369
65.80000,-10.96651,-5.47354
65.90000,-10.98304,-5.48460
66.00000,-10.99997,-5.49720
66.10001,-11.01664,-5.50863
66.20001,-11.03304,-5.52082
66.30000,-11.04997,-5.52876
66.40000,-11.06624,-5.53869
66.50000,-11.08317,-5.55181
66.60001,-11.09984,-5.56226
66.70001,-11.11664,-5.57302
66.80000,-11.13331,-5.58631
66.90000,-11.15011,-5.59952
67.00000,-11.16664,-5.60509
67.10001,-11.18304,-5.61796
67.20001,-11.19997,-5.62761
67.30000,-11.21637,-5.63720
67.40000,-11.23331,-5.65219
67.50000,-11.24984,-5.66348
67.60001,-11.26651,-5.67414
67.70001,-11.28344,-5.68777
67.80000,-11.29984,-5.69702
67.90000,-11.31651,-5.70762
68.00000,-11.33317,-5.71741
68.10001,-11.34997,-5.73026
68.20001,-11.36651,-5.73784
68.30000,-11.38331,-5.75056
68.40000,-11.39984,-5.75929
68.50000,-11.41651,-5.77035
68.60001,-11.43331,-5.77876
68.70001,-11.44984,-5.78955
68.80000,-11.46651,-5.80086
68.90000,-11.48304,-5.81041
69.00000,-11.49984,-5.81955
69.10001,-11.51637,-5.83081
69.20001,-11.53344,-5.84070
69.30000,-11.54997,-5.84528
69.40000,-11.56637,-5.85373
69.50000,-11.58317,-5.85881
69.60001,-11.59957,-5.86689
69.70001,-11.61664,-5.87741
69.80000,-11.63317,-5.88485
69.90000,-11.64984,-5.89091
70.00000,-11.66664,-5.90032
70.10001,-11.68344,-5.90894
70.20001,-11.69997,-5.91412
70.30000,-11.71650,-5.92173
70.40000,-11.73330,-5.93033
70.50000,-11.74984,-5.93680
70.60001,-11.76677,-5.94929
70.70001,-11.78330,-5.95685
70.80000,-11.79997,-5.96328
70.90000,-11.81677,-5.97179
71.00000,-11.83330,-5.97917
71.10001,-11.84997,-5.98698
71.20001,-11.86650,-5.99723
71.30000,-11.88317,-6.00520
71.40000,-11.89984,-6.01510
71.50000,-11.91677,-6.02607
71.60001,-11.93330,-6.03264
71.70001,-11.94984,-6.04342
71.80000,-11.96650,-6.05247
71.90000,-11.98304,-6.06296
72.00000,-11.99984,-6.07378
72.10001,-12.01637,-6.08476
72.20001,-12.03330,-6.09541
72.30000,-12.04970,-6.10612
72.40000,-12.06664,-6.11825
72.50000,-12.08330,-6.12687
72.60001,-12.09970,-6.13630
72.70001,-12.11664,-6.14395
72.80000,-12.13304,-6.15097
72.90000,-12.14984,-6.16146
73.00000,-12.16650,-6.16821
73.10001,-12.18330,-6.17663
73.20001,-12.19997,-6.18562
73.30000,-12.21664,-6.19138
73.40000,-12.23330,-6.19594
73.50000,-12.24970,-6.20562
73.60001,-12.26650,-6.21436
73.70001,-12.28304,-6.22257
73.80000,-12.29997,-6.23596
73.90000,-12.31637,-6.24327
74.00000,-12.33330,-6.25598
74.10001,-12.35024,-6.26890
74.20001,-12.36664,-6.27892
74.30000,-12.38330,-6.28878
74.40000,-12.39970,-6.29920
74.50000,-12.41664,-6.30968
74.60001,-12.43304,-6.32133
74.70001,-12.45010,-6.33496
74.80000,-12.46650,-6.34349
74.90000,-12.48317,-6.35515
75.00000,-12.49997,-6.36448
75.10001,-12.51637,-6.37451
75.20001,-12.53317,-6.38468
75.30000,-12.54970,-6.39441
75.40000,-12.56650,-6.40498
75.50000,-12.58304,-6.41591
75.60001,-12.60010,-6.42714
75.70001,-12.61650,-6.43540
75.80000,-12.63304,-6.44709
75.90000,-12.64997,-6.45606
76.00000,-12.66624,-6.46751
76.10001,-12.68317,-6.48221
76.20001,-12.69984,-6.49216
76.30000,-12.71650,-6.50474
76.40000,-12.73317,-6.51694
76.50000,-12.74997,-6.52907
76.60001,-12.76664,-6.53843
76.70001,-12.78317,-6.55220
76.80000,-12.79997,-6.56006
76.90000,-12.81624,-6.56632
77.00000,-12.83344,-6.58428
77.10001,-12.84997,-6.59714
77.20001,-12.86663,-6.61008
77.30000,-12.88344,-6.62121
77.40000,-12.89984,-6.63286
77.50000,-12.91663,-6.64465
77.60001,-12.93304,-6.65886
77.70001,-12.94997,-6.67297
77.80000,-12.96637,-6.68575
77.90000,-12.98330,-6.70110
78.00000,-12.99997,-6.71380
78.10001,-13.01663,-6.73229
78.20001,-13.03330,-6.74370
78.30000,-13.04970,-6.75690
78.40000,-13.06637,-6.77135
78.50000,-13.08304,-6.78563
78.60001,-13.09997,-6.80043
78.70001,-13.11650,-6.81336
78.80000,-13.13343,-6.82859
78.90000,-13.14983,-6.84187
79.00000,-13.16637,-6.85740
79.10001,-13.18330,-6.87166
79.20001,-13.19957,-6.88598
79.30000,-13.21650,-6.90293
79.40000,-13.23317,-6.91643
79.50000,-13.24997,-6.93327
79.60001,-13.26650,-6.95023
79.70001,-13.28330,-6.96652
79.80000,-13.29997,-6.97930
79.90000,-13.31650,-6.99731
80.00000,-13.33330,-7.01526
80.10001,-13.34970,-7.03065
80.20001,-13.36677,-7.05208
80.30000,-13.38330,-7.06857
80.40000,-13.39997,-7.08495
80.50001,-13.41677,-7.09940
80.60001,-13.43317,-7.11163
80.70001,-13.44997,-7.12566
80.80000,-13.46650,-7.14187
80.90000,-13.48330,-7.15161
81.00001,-13.49983,-7.16178
81.10001,-13.51677,-7.18104
81.20001,-13.53330,-7.19357
81.30000,-13.54983,-7.21136
81.40000,-13.56650,-7.22229
81.50001,-13.58303,-7.23798
81.60001,-13.59970,-7.25373
81.70001,-13.61637,-7.27022
81.80000,-13.63330,-7.28767
81.90000,-13.64970,-7.30642
82.00001,-13.66663,-7.32378
82.10001,-13.68317,-7.33693
82.20001,-13.69970,-7.34930
82.30000,-13.71663,-7.36408
82.40000,-13.73290,-7.37843
82.50001,-13.74983,-7.39188
82.60001,-13.76650,-7.40655
82.70001,-13.78343,-7.41530
82.80000,-13.79983,-7.43047
82.90000,-13.81677,-7.44670
83.00001,-13.83317,-7.45615
83.10001,-13.84983,-7.47227
83.20001,-13.86677,-7.47863
83.30000,-13.88303,-7.48642
83.40000,-13.90010,-7.50619
83.50001,-13.91663,-7.52079
83.60001,-13.93317,-7.53683
83.70001,-13.94997,-7.55488
83.80000,-13.96663,-7.57190
83.90000,-13.98330,-7.58388
84.00001,-13.99983,-7.59699
84.10001,-14.01663,-7.61051
84.20001,-14.03317,-7.62494
84.30000,-14.05010,-7.63690
84.40000,-14.06663,-7.64277
84.50001,-14.08317,-7.65584
84.60001,-14.09997,-7.67057
84.70001,-14.11637,-7.68251
84.80000,-14.13317,-7.69747
84.90000,-14.14970,-7.70991
85.00001,-14.16663,-7.72190
85.10001,-14.18303,-7.73403
85.20001,-14.20010,-7.75210
85.30000,-14.21650,-7.76375
85.40000,-14.23303,-7.77455
85.50001,-14.24997,-7.78481
85.60001,-14.26623,-7.79912
85.70001,-14.28317,-7.81429
85.80000,-14.29983,-7.82740
85.90000,-14.31663,-7.84027
86.00001,-14.33330,-7.85602
86.10001,-14.35010,-7.87221
86.20001,-14.36663,-7.88248
86.30000,-14.38303,-7.89735
86.40000,-14.39983,-7.90688
86.50001,-14.41636,-7.92052
86.60001,-14.43330,-7.93997
86.70001,-14.44996,-7.95070
86.80000,-14.46663,-7.96591
86.90000,-14.48343,-7.98102
87.00001,-14.49996,-7.99486
87.10001,-14.51676,-8.00911
87.20001,-14.53316,-8.02508
87.30000,-14.54996,-8.03776
87.40000,-14.56636,-8.04218
87.50001,-14.58343,-8.06426
87.60001,-14.59983,-8.07443
87.70001,-14.61650,-8.09505
87.80000,-14.63330,-8.10671
87.90000,-14.64970,-8.12056
88.00001,-14.66636,-8.13814
88.10001,-14.68303,-8.15949
88.20001,-14.69983,-8.17663
88.30000,-14.71636,-8.19684
88.40000,-14.73330,-8.21729
88.50001,-14.74983,-8.23421
88.60001,-14.76636,-8.25881
88.70001,-14.78316,-8.27896
88.80000,-14.79956,-8.29682
88.90000,-14.81663,-8.32054
89.00001,-14.83330,-8.34077
89.10001,-14.84996,-8.36209
89.20001,-14.86650,-8.38292
89.30000,-14.88343,-8.40453
89.40000,-14.89983,-8.41960
89.50001,-14.91636,-8.44246
89.60001,-14.93330,-8.46241
89.70001,-14.94970,-8.48463
89.80000,-14.96676,-8.51139
89.90000,-14.98330,-8.53261
90.00001,-14.99996,-8.55512
90.10001,-15.01676,-8.57909
90.20001,-15.03330,-8.60147
90.20200,-15.03356,-8.60166