File: FirefighterJacket/data/instron/Specimen_RawData_6.csv
Time,Extension,Load
(sec),(mm),(N)
0.00000,0.00000,0.04581
0.20000,0.02853,0.13165
0.40000,0.06560,0.19331
0.60000,0.09973,0.25591
0.80000,0.13320,0.35049
1.00000,0.16653,0.37224
1.20000,0.20013,0.44513
1.40000,0.23373,0.46720
1.60000,0.26680,0.50697
1.80000,0.30027,0.60121
2.00000,0.33347,0.60863
2.20000,0.36667,0.69839
2.40000,0.40000,0.71544
2.60000,0.43307,0.81908
2.80000,0.46680,0.84107
3.00000,0.50027,0.88799
3.20000,0.53347,0.95488
3.40000,0.56680,0.97729
3.60000,0.60013,1.02598
3.80000,0.63347,1.06144
4.00000,0.66666,1.11266
4.20000,0.69986,1.17537
4.40000,0.73373,1.18375
4.60000,0.76693,1.21680
4.80000,0.80026,1.28215
5.00000,0.83346,1.27249
5.20000,0.86680,1.29400
5.40000,0.90013,1.33534
5.60000,0.93333,1.38448
5.80000,0.96653,1.47230
6.00000,1.00000,1.53329
6.20000,1.03360,1.48911
6.40000,1.06680,1.52862
6.60000,1.10000,1.54084
6.80000,1.13346,1.62784
7.00000,1.16680,1.61563
7.20000,1.19986,1.64151
7.40000,1.23333,1.71506
7.60000,1.26680,1.72747
7.80000,1.30040,1.83081
8.00000,1.33346,1.86909
8.20000,1.36680,1.78345
8.40000,1.40026,1.83925
8.60000,1.43346,1.90374
8.80000,1.46666,1.91657
9.00000,1.49986,1.99301
9.20000,1.53346,2.02472
9.40000,1.56706,2.02852
9.60000,1.60013,2.05431
9.80000,1.63333,2.11088
10.00000,1.66653,2.15563
10.20000,1.70000,2.19504
10.40000,1.73320,2.18740
10.60000,1.76653,2.24142
10.80000,1.80026,2.26034
11.00000,1.83360,2.31550
11.20000,1.86680,2.30450
11.40000,1.90026,2.31454
11.60000,1.93346,2.35146
11.80000,1.96679,2.42121
12.00000,1.99999,2.47658
12.20000,2.03333,2.48123
12.40000,2.06679,2.54722
12.60000,2.10013,2.60528
12.80000,2.13346,2.56403
13.00000,2.16666,2.64699
13.20000,2.20013,2.64318
13.40000,2.23346,2.66967
13.60000,2.26666,2.69848
13.80000,2.29999,2.77798
14.00000,2.33346,2.82210
14.20000,2.36706,2.81554
14.40000,2.40013,2.84880
14.60000,2.43346,2.88623
14.80000,2.46679,2.92466
15.00000,2.50013,2.98744
15.20000,2.53333,2.98753
15.40000,2.56653,3.13155
15.60000,2.60013,3.01380
15.80000,2.63373,3.09993
16.00000,2.66679,3.17463
16.20000,2.69999,3.19315
16.40000,2.73346,3.21524
16.60000,2.76693,3.24565
16.80000,2.80013,3.30634
17.00000,2.83333,3.38555
17.20000,2.86693,3.36686
17.40000,2.90026,3.37399
17.60000,2.93359,3.43598
17.80000,2.96679,3.50615
18.00000,3.00013,3.50987
18.20000,3.03346,3.52516
18.40000,3.06666,3.60956
18.60000,3.09986,3.65994
18.80000,3.13333,3.65737
19.00000,3.16693,3.72237
19.20000,3.20012,3.73998
19.40000,3.23346,3.69905
19.60000,3.26679,3.79541
19.80000,3.30012,3.86621
20.00000,3.33332,3.86759
20.20000,3.36666,3.95334
20.40000,3.40026,3.93147
20.60000,3.43359,4.01837
20.80000,3.46679,4.09407
21.00000,3.50012,4.08478
21.20000,3.53332,4.15537
21.40000,3.56666,4.17460
21.60000,3.59999,4.12171
21.80000,3.63332,4.22492
22.00000,3.66666,4.31505
22.20000,3.70026,4.33197
22.40000,3.73332,4.33139
22.60000,3.76666,4.38043
22.80000,3.80012,4.42769
23.00000,3.83346,4.53963
23.20000,3.86666,4.54148
23.40000,3.89999,4.57424
23.60000,3.93346,4.59041
23.80000,3.96706,4.66442
24.00000,4.00012,4.69309
24.20000,4.03359,4.67970
24.40000,4.06679,4.69766
24.60000,4.10012,4.80644
24.80000,4.13332,4.82337
25.00000,4.16652,4.93838
25.20000,4.20026,4.96038
25.40000,4.23359,4.92491
25.60000,4.26679,5.04320
25.80000,4.29999,5.10777
26.00000,4.33332,5.19151
26.20000,4.36679,5.14612
26.40000,4.39986,5.22795
26.60000,4.43332,5.22387
26.80000,4.46679,5.30299
27.00000,4.50025,5.36475
27.20000,4.53345,5.37466
27.40000,4.56692,5.48917
27.60000,4.60012,5.48413
27.80000,4.63332,5.52824
28.00000,4.66665,5.61119
28.20000,4.69999,5.63882
28.40000,4.73345,5.65907
28.60000,4.76692,5.71044
28.80000,4.80012,5.75950
29.00000,4.83332,5.83747
29.20000,4.86679,5.88364
29.40000,4.90025,5.89450
29.60000,4.93332,5.92120
29.80000,4.96665,5.98797
30.00000,5.00025,6.05862
30.20000,5.03372,6.08937
30.40000,5.06679,6.10173
30.60000,5.10012,6.24049
30.80000,5.13332,6.25537
31.00000,5.16665,6.33042
31.20000,5.19999,6.36328
31.40000,5.23319,6.39493
31.60000,5.26665,6.46549
31.80000,5.30025,6.55661
32.00000,5.33345,6.61143
32.20000,5.36665,6.61686
32.40000,5.40025,6.65522
32.60000,5.43345,6.71130
32.80000,5.46665,6.77047
33.00000,5.49985,6.90419
33.20000,5.53359,6.89871
33.40000,5.56692,6.96369
33.60000,5.60012,7.03198
33.80000,5.63359,7.05666
34.00000,5.66665,7.11454
34.20000,5.70012,7.13730
34.40000,5.73332,7.15982
34.60000,5.76652,7.22516
34.80000,5.80012,7.36307
35.00000,5.83372,7.45595
35.20000,5.86678,7.44709
35.40000,5.90012,7.52363
35.60000,5.93345,7.57382
35.80000,5.96678,7.58420
36.00000,5.99998,7.74716
36.20000,6.03332,7.77746
36.40000,6.06678,7.78267
36.60000,6.10025,7.81079
36.80000,6.13332,7.89730
37.00000,6.16678,7.98158
37.20000,6.20012,8.02168
37.40000,6.23345,8.15354
37.60000,6.26678,8.14642
37.80000,6.29998,8.24337
38.00000,6.33332,8.25623
38.20000,6.36692,8.31650
38.40000,6.40012,8.36075
38.60000,6.43332,8.43497
38.80000,6.46678,8.52514
39.00000,6.50012,8.58353
39.20000,6.53332,8.65068
39.40000,6.56652,8.75580
39.60000,6.60012,8.79592
39.80000,6.63358,8.84132
40.00000,6.66678,8.88148
40.20000,6.70025,8.92936
40.40000,6.73345,8.98331
40.60000,6.76678,9.02538
40.80000,6.79985,9.15067
41.00000,6.83332,9.23066
41.20000,6.86665,9.29316
41.40000,6.90025,9.36161
41.60000,6.93358,9.45822
41.80000,6.96665,9.48953
42.00000,7.00012,9.67705
42.20000,7.03358,9.60371
42.40000,7.06665,9.76966
42.60000,7.09998,9.74124
42.80000,7.13331,9.85753
43.00000,7.16692,9.94466
43.20000,7.20011,9.91940
43.40000,7.23345,9.96246
43.60000,7.26678,10.15495
43.80000,7.30011,10.10135
44.00000,7.33331,10.23778
44.20000,7.36665,10.31966
44.40000,7.39985,10.39295
44.60000,7.43345,10.53985
44.80000,7.46678,10.53252
45.00000,7.50011,10.56883
45.20000,7.53358,10.65521
45.40000,7.56691,10.72189
45.60000,7.59998,10.94252
45.80000,7.63331,10.93537
46.00000,7.66678,11.00339
46.20000,7.70025,11.03425
46.40000,7.73345,11.13996
46.60000,7.76691,11.28680
46.80000,7.79998,11.31833
47.00000,7.83345,11.42089
47.20000,7.86665,11.48339
47.40000,7.89985,11.61731
47.60000,7.93345,11.67013
47.80000,7.96691,11.71540
48.00000,8.00011,11.82302
48.20000,8.03345,11.90168
48.40000,8.06678,11.97514
48.60000,8.10011,12.15141
48.80000,8.13318,12.19632
49.00000,8.16664,12.28263
49.20000,8.20011,12.32105
49.40000,8.23371,12.41291
49.60000,8.26691,12.65220
49.80000,8.30011,12.60574
50.00000,8.33331,12.74458
50.20000,8.36678,12.81788
50.40000,8.39984,12.84668
50.60000,8.43331,12.97270
50.80000,8.46664,13.03550
51.00000,8.50024,13.16152
51.20000,8.53344,13.19830
51.40000,8.56651,13.30207
51.60000,8.60011,13.45410
51.80000,8.63344,13.48873
52.00000,8.66664,13.64280
52.20000,8.69998,13.76135
52.40000,8.73344,13.82666
52.60000,8.76704,13.94932
52.80000,8.80011,14.02024
53.00000,8.83358,14.10940
53.20000,8.86678,14.20849
53.40000,8.90011,14.30996
53.60000,8.93331,14.42818
53.80000,8.96664,14.47350
54.00000,8.99998,14.66176
54.20000,9.03371,14.72348
54.40000,9.06664,14.83976
54.60000,9.09998,14.94059
54.80000,9.13331,15.02775
55.00000,9.16678,15.12527
55.20000,9.19984,15.22108
55.40000,9.23331,15.31931
55.60000,9.26691,15.44093
55.80000,9.30038,15.49509
56.00000,9.33358,15.65535
56.20000,9.36691,15.78012
56.40000,9.39998,15.84223
56.60000,9.43344,16.02811
56.80000,9.46664,16.12327
57.00000,9.49998,16.21752
57.20000,9.53344,16.31576
57.40000,9.56691,16.43682
57.60000,9.60011,16.49812
57.80000,9.63331,16.60630
58.00000,9.66677,16.75230
58.20000,9.70011,16.83831
58.40000,9.73331,16.92829
58.60000,9.76664,17.10429
58.80000,9.80024,17.16106
59.00000,9.83371,17.36210
59.20000,9.86691,17.37389
59.40000,9.90011,17.49799
59.60000,9.93344,17.69212
59.80000,9.96677,17.71748
60.00000,9.99997,17.89225
60.20000,10.03331,17.98268
60.40000,10.06677,18.12425
60.60000,10.10024,18.27695
60.80000,10.13344,18.31009
61.00000,10.16664,18.46184
61.20000,10.20011,18.60491
61.40000,10.23357,18.73840
61.60000,10.26664,18.84724
61.80000,10.29997,18.95186
62.00000,10.33344,19.09020
62.20000,10.36691,19.22485
62.40000,10.40011,19.33921
62.60000,10.43344,19.51535
62.80000,10.46677,19.50567
63.00000,10.50011,19.75462
63.20000,10.53331,19.81257
63.40000,10.56664,19.92702
63.60000,10.59997,20.14058
63.80000,10.63357,20.14115
64.00000,10.66691,20.33599
64.20000,10.70011,20.45602
64.40000,10.73344,20.57723
64.60001,10.76677,20.71800
64.80000,10.79997,20.80267
65.00000,10.83331,21.06984
65.20000,10.86677,21.13030
65.40000,10.90037,21.32992
65.60001,10.93344,21.45807
65.80000,10.96690,21.56659
66.00000,11.00010,21.74190
66.20001,11.03344,21.83504
66.40000,11.06650,21.99033
66.60001,11.09997,22.10133
66.80000,11.13344,22.18633
67.00000,11.16690,22.39792
67.20001,11.20010,22.55275
67.40000,11.23330,22.70113
67.60001,11.26664,22.90398
67.80000,11.30010,22.88994
68.00000,11.33330,23.10537
68.20001,11.36664,23.24993
68.40000,11.40024,23.39076
68.60001,11.43357,23.58732
68.80000,11.46664,23.66860
69.00000,11.50010,23.84567
69.20001,11.53330,23.95801
69.40000,11.56677,24.11614
69.60001,11.59997,24.33681
69.80000,11.63317,24.45053
70.00000,11.66677,24.60082
70.20001,11.70024,24.73836
70.40000,11.73344,24.88481
70.60001,11.76664,25.11982
70.80000,11.79997,25.19424
71.00000,11.83344,25.36626
71.20001,11.86664,25.52075
71.40000,11.89997,25.69702
71.60001,11.93330,25.88616
71.80000,11.96704,25.94406
72.00000,12.00024,26.13805
72.20001,12.03344,26.28760
72.40000,12.06677,26.47236
72.60001,12.10010,26.67233
72.80000,12.13317,26.75814
73.00000,12.16650,26.87525
73.20001,12.19997,27.06354
73.40000,12.23357,27.25233
73.60001,12.26677,27.48996
73.80000,12.30010,27.62660
74.00000,12.33344,27.74000
74.20001,12.36690,27.87262
74.40000,12.39997,28.05006
74.60001,12.43317,28.25899
74.80000,12.46690,28.33928
75.00000,12.50037,28.56699
75.20001,12.53343,28.67815
75.40000,12.56690,28.89212
75.60001,12.59997,29.00248
75.80000,12.63343,29.21920
76.00000,12.66677,29.42435
76.20001,12.69983,29.53380
76.40000,12.73330,29.70547
76.60001,12.76690,29.90368
76.80000,12.80010,30.01995
77.00000,12.83330,30.21606
77.20001,12.86690,30.38156
77.40000,12.90023,30.52700
77.60001,12.93317,30.75760
77.80000,12.96650,30.87144
78.00000,13.00023,31.06798
78.20001,13.03343,31.20641
78.40000,13.06677,31.36695
78.60001,13.10010,31.60690
78.80000,13.13343,31.70614
79.00000,13.16677,31.86216
79.20001,13.19997,32.03692
79.40000,13.23330,32.23427
79.60001,13.26677,32.41241
79.80000,13.30037,32.52615
80.00000,13.33343,32.73037
80.20001,13.36663,32.92548
80.40000,13.40010,33.07052
80.60001,13.43343,33.26594
80.80000,13.46650,33.39361
81.00001,13.49996,33.54463
81.20001,13.53343,33.69285
81.40000,13.56703,33.85129
81.60001,13.60010,34.04506
81.80000,13.63357,34.13659
82.00001,13.66676,34.39151
82.20001,13.70010,34.42565
82.40000,13.73330,34.58689
82.60001,13.76650,34.69956
82.80000,13.80010,34.69679
83.00001,13.83356,34.57982
83.20001,13.86690,33.98980
83.40000,13.89996,33.45213
83.60001,13.93343,33.74710
83.80000,13.96676,34.01516
84.00001,13.99996,34.38530
84.20001,14.03330,34.56315
84.40000,14.06690,34.80837
84.60001,14.10023,35.03336
84.80000,14.13343,35.13410
85.00001,14.16690,35.34539
85.20001,14.20010,35.52653
85.40000,14.23343,35.68306
85.60001,14.26663,35.82250
85.80000,14.29983,35.95687
86.00001,14.33343,36.10305
86.20001,14.36690,36.20816
86.40000,14.40010,36.40642
86.60001,14.43330,36.68435
86.80000,14.46676,36.82830
87.00001,14.50010,37.08443
87.20001,14.53316,37.15734
87.40000,14.56663,37.35781
87.60001,14.60023,37.58739
87.80000,14.63370,37.75824
88.00001,14.66690,37.99920
88.20001,14.70023,38.17355
88.40000,14.73343,38.42343
88.60001,14.76663,38.64620
88.80000,14.79996,38.84733
89.00001,14.83316,39.07497
89.20001,14.86676,39.20870
89.40000,14.90023,39.38787
89.60001,14.93343,39.64071
89.80000,14.96663,39.78700
90.00001,15.00009,40.00561
90.20001,15.03343,40.22395
90.40000,15.06663,40.41248
90.60001,15.09983,40.66766
90.80000,15.13356,40.84500
91.00001,15.16689,41.07689
91.20001,15.20009,41.19357
91.40000,15.23356,41.41426
91.60001,15.26663,41.63240
91.80000,15.30009,41.77492
92.00001,15.33343,42.04142
92.20001,15.36649,42.11636
92.40000,15.39996,42.33598
92.60001,15.43356,42.60641
92.80000,15.46676,42.72473
93.00001,15.49996,42.96538
93.20001,15.53343,43.06855
93.40000,15.56689,43.28402
93.60001,15.59983,43.47714
93.80000,15.63329,43.63542
94.00001,15.66676,43.76212
94.20001,15.70009,43.87558
94.40000,15.73342,44.10020
94.60001,15.76676,44.28272
94.80000,15.80009,44.43752
95.00001,15.83342,44.58751
95.20001,15.86662,44.73425
95.40000,15.89996,44.86140
95.60001,15.93342,45.11330
95.80000,15.96702,45.23093
96.00001,16.00009,45.45419
96.20001,16.03329,45.60648
96.40000,16.06676,45.83347
96.60001,16.10009,46.04902
96.80000,16.13316,46.18843
97.00001,16.16649,46.42711
97.20001,16.20009,46.50815
97.40000,16.23356,46.72613
97.60001,16.26676,46.88164
97.80000,16.30009,47.08614
98.00001,16.33342,47.36281
98.20001,16.36676,47.51146
98.40000,16.39996,47.75372
98.60001,16.43316,48.01375
98.80000,16.46676,48.25130
99.00001,16.50022,48.53534
99.20001,16.53342,48.68598
99.40000,16.56676,48.98455
99.60001,16.60009,49.24647
99.80000,16.63356,49.43200
100.00001,16.66662,49.66245
100.20001,16.69996,49.80863
100.40000,16.73356,50.15592
100.60001,16.76689,50.41036
100.80000,16.80022,50.56417
101.00001,16.83342,50.84604
101.20001,16.86675,50.97307
101.40000,16.90009,51.18650
101.60001,16.93329,51.48618
101.80000,16.96649,51.64883
102.00001,17.00009,51.96983
102.20001,17.03355,52.15712
102.40000,17.06675,52.32821
102.60001,17.10009,52.64352
102.80000,17.13342,52.77157
103.00001,17.16689,53.06069
103.20001,17.19995,53.25274
103.40000,17.23315,53.55980
103.60001,17.26675,53.74006
103.80000,17.30035,53.95249
104.00001,17.33342,54.24493
104.20001,17.36675,54.43968
104.40000,17.40009,54.59735
104.60001,17.43329,54.94311
104.80000,17.46662,55.17348
105.00001,17.49982,55.33832
105.20001,17.53342,55.58725
105.40000,17.56689,55.92684
105.60001,17.60009,56.19104
105.80000,17.63329,56.38392
106.00001,17.66689,56.64384
106.20001,17.70009,56.98489
106.40000,17.73329,57.23767
106.60001,17.76662,57.46908
106.80000,17.80022,57.67717
107.00001,17.83355,57.90463
107.20001,17.86675,58.14637
107.40000,17.90009,58.43787
107.60001,17.93342,58.71987
107.80000,17.96689,59.00312
108.00001,17.99995,59.21683
108.20001,18.03329,59.54977
108.40000,18.06675,59.81369
108.60001,18.10022,59.99613
108.80000,18.13342,60.27299
109.00001,18.16675,60.55919
109.20001,18.20008,60.75506
109.40000,18.23342,61.02256
109.60001,18.26662,61.34143
109.80000,18.29982,61.55801
110.00001,18.33342,61.98046
110.20001,18.36702,62.14206
110.40000,18.40008,62.47615
110.60001,18.43355,62.76609
110.80000,18.46675,62.99471
111.00001,18.50008,63.35547
111.20001,18.53328,63.59008
111.40000,18.56662,63.90841
111.60001,18.60008,64.15148
111.80000,18.63355,64.32938
112.00001,18.66675,64.61901
112.20001,18.69995,64.83855
112.40000,18.73328,65.10220
112.60001,18.76675,65.39902
112.80000,18.79982,65.70250
113.00001,18.83328,65.98464
113.20001,18.86688,66.15969
113.40001,18.90022,66.53450
113.60001,18.93342,66.78845
113.80000,18.96688,67.06702
114.00001,19.00008,67.43264
114.20001,19.03342,67.67784
114.40001,19.06662,68.02812
114.60001,19.09995,68.30411
114.80000,19.13328,68.61931
115.00001,19.16688,68.84383
115.20001,19.20008,69.17550
115.40001,19.23328,69.41075
115.60001,19.26675,69.64865
115.80000,19.30022,69.93642
116.00001,19.33328,70.16949
116.20001,19.36662,70.44851
116.40001,19.40008,70.65537
116.60001,19.43368,70.99090
116.80000,19.46675,71.35382
117.00001,19.50022,71.65618
117.20001,19.53342,71.94960
117.40001,19.56675,72.22837
117.60001,19.59995,72.57733
117.80000,19.63328,72.85865
118.00001,19.66662,73.26729
118.20001,19.70035,73.57253
118.40001,19.73342,73.84331
118.60001,19.76662,74.14171
118.80000,19.79995,74.41294
119.00001,19.83355,74.73615
119.20001,19.86662,74.85507
119.40001,19.89995,75.10006
119.60001,19.93355,75.48078
119.80000,19.96701,75.73589
120.00001,19.99995,76.02688
120.20001,20.03341,76.29332
120.40001,20.06675,76.51319
120.60001,20.10008,76.86383
120.80000,20.13328,77.09402
121.00001,20.16661,77.51797
121.20001,20.19995,77.83844
121.40001,20.23355,78.07951
121.60001,20.26688,78.49968
121.80000,20.30008,78.78283
122.00001,20.33341,79.19027
122.20001,20.36688,79.55560
122.40001,20.39981,79.82730
122.60001,20.43328,80.17745
122.80000,20.46675,80.55337
123.00001,20.50008,80.88467
123.20001,20.53355,81.19833
123.40001,20.56675,81.44761
123.60001,20.60008,81.82862
123.80000,20.63355,82.08750
124.00001,20.66648,82.47531
124.20001,20.69981,82.73500
124.40001,20.73341,83.07278
124.60001,20.76688,83.43262
124.80000,20.80021,83.71305
125.00001,20.83328,84.13410
125.20001,20.86675,84.46663
125.40001,20.90008,84.76529
125.60001,20.93328,85.14816
125.80000,20.96661,85.49463
126.00001,21.00008,85.73522
126.20001,21.03368,86.12469
126.40001,21.06675,86.48180
126.60001,21.10008,86.78369
126.80000,21.13341,87.14909
127.00001,21.16675,87.44407
127.20001,21.19995,87.78087
127.40001,21.23315,88.06917
127.60001,21.26675,88.38846
127.80000,21.30021,88.73933
128.00000,21.33341,89.12969
128.20002,21.36661,89.51810
128.40001,21.40008,89.85383
128.60001,21.43354,90.14431
128.80000,21.46661,90.54650
129.00000,21.49994,90.85479
129.20002,21.53354,91.18247
129.40001,21.56688,91.48375
129.60001,21.60008,91.76441
129.80000,21.63341,92.03638
130.00000,21.66674,92.38238
130.20002,21.70008,92.60032
130.40001,21.73328,93.06375
130.60001,21.76661,93.28161
130.80000,21.80008,93.63310
131.00000,21.83354,93.97458
131.20002,21.86674,94.12587
131.40002,21.90008,94.55977
131.60000,21.93354,94.85063
131.80000,21.96674,95.17154
132.00000,21.99981,95.46821
132.20002,22.03328,95.81699
132.40002,22.06674,96.06420
132.60000,22.10021,96.41369
132.80000,22.13354,96.70808
133.00000,22.16688,96.99563
133.20002,22.20008,97.26430
133.40002,22.23341,97.63706
133.60000,22.26661,97.93422
133.80000,22.29981,98.30065
134.00000,22.33328,98.57762
134.20002,22.36701,98.86672
134.40002,22.40008,99.18325
134.60000,22.43314,99.57448
134.80000,22.46688,99.89492
135.00000,22.50021,100.31429
135.20002,22.53328,100.61574
135.40002,22.56661,100.93599
135.60000,22.60034,101.28194
135.80000,22.63367,101.60712
136.00000,22.66674,101.91791
136.20002,22.70008,102.09088
136.40002,22.73341,102.48572
136.60000,22.76688,102.70056
136.80000,22.80007,103.04777
137.00000,22.83314,103.42447
137.20002,22.86674,103.72943
137.40002,22.90034,103.98483
137.60000,22.93341,104.39487
137.80000,22.96661,104.74979
138.00000,22.99994,105.13207
138.20002,23.03354,105.54311
138.40002,23.06647,105.89621
138.60000,23.09994,106.22664
138.80000,23.13341,106.57314
139.00000,23.16674,106.97144
139.20002,23.20007,107.31784
139.40002,23.23354,107.70098
139.60000,23.26687,108.05672
139.80000,23.30007,108.38228
140.00000,23.33327,108.78039
140.20002,23.36661,109.18485
140.40002,23.39994,109.53232
140.60000,23.43354,109.89064
140.80000,23.46674,110.26856
141.00000,23.50007,110.54278
141.20002,23.53341,110.89255
141.40002,23.56674,111.33348
141.60000,23.59981,111.65958
141.80000,23.63327,112.02849
142.00000,23.66674,112.42787
142.20002,23.70021,112.74754
142.40002,23.73341,113.09787
142.60000,23.76687,113.45223
142.80000,23.80007,113.80499
143.00000,23.83341,114.15590
143.20002,23.86661,114.47505
143.40002,23.89994,114.90030
143.60000,23.93341,115.14266
143.80000,23.96687,115.42555
144.00000,24.00007,115.90148
144.20002,24.03327,116.23819
144.40002,24.06674,116.60432
144.60000,24.10020,116.94208
144.80000,24.13327,117.24682
145.00000,24.16660,117.56794
145.20002,24.20020,117.95323
145.40002,24.23354,118.37102
145.60000,24.26674,118.76960
145.80000,24.30020,119.10466
146.00000,24.33340,119.44913
146.20002,24.36674,119.77878
146.40002,24.39994,120.11082
146.60000,24.43314,120.53347
146.80000,24.46674,120.86594
147.00000,24.50020,121.33298
147.20002,24.53340,121.61136
147.40002,24.56674,122.04939
147.60000,24.60020,122.41191
147.80000,24.63340,122.72625
148.00000,24.66674,123.13106
148.20002,24.69994,123.44421
148.40002,24.73354,123.93360
148.60000,24.76700,124.24881
148.80000,24.80007,124.60596
149.00000,24.83354,125.03240
149.20002,24.86674,125.38296
149.40002,24.90007,125.71367
149.60000,24.93327,126.01535
149.80000,24.96660,126.36650
150.00000,25.00007,126.66829
150.20002,25.03367,127.11737
150.40002,25.06674,127.46584
150.60000,25.09994,127.84335
150.80000,25.13340,128.25396
151.00000,25.16687,128.67318
151.20002,25.19993,128.91142
151.40002,25.23327,129.34096
151.60000,25.26700,129.77297
151.80000,25.30020,130.14472
152.00000,25.33340,130.52948
152.20002,25.36687,130.80748
152.40002,25.40007,131.23729
152.60000,25.43340,131.61019
152.80000,25.46660,131.98069
153.00000,25.49993,132.26573
153.20002,25.53340,132.59912
153.40002,25.56700,132.89129
153.60000,25.60020,133.33984
153.80000,25.63340,133.65422
154.00000,25.66673,133.95475
154.20002,25.70007,134.22512
154.40002,25.73327,134.62546
154.60000,25.76673,134.99099
154.80000,25.80033,135.28633
155.00000,25.83367,135.64003
155.20002,25.86673,135.90742
155.40002,25.90020,136.22802
155.60000,25.93353,136.49674
155.80000,25.96673,136.83025
156.00000,25.99993,137.15494
156.20002,26.03327,137.50783
156.40002,26.06673,137.80500
156.60000,26.10033,138.25204
156.80000,26.13340,138.60987
157.00000,26.16673,138.96483
157.20002,26.20007,139.21283
157.40002,26.23353,139.66452
157.60000,26.26660,140.00386
157.80000,26.29993,140.27488
158.00000,26.33353,140.67623
158.20002,26.36700,140.98922
158.40002,26.40020,141.27290
158.60000,26.43353,141.62858
158.80000,26.46673,141.90177
159.00000,26.50006,142.28493
159.20002,26.53326,142.62038
159.40002,26.56673,142.88533
159.60000,26.60020,143.22204
159.80000,26.63353,143.29225
160.00000,26.66686,143.51471
160.20002,26.69993,143.59402
160.40002,26.73340,143.93555
160.60000,26.76686,144.21447
160.80000,26.80006,144.63278
161.00002,26.83326,144.91230
161.20002,26.86686,145.30031
161.40002,26.90033,145.75497
161.60000,26.93353,146.10761
161.80000,26.96673,146.48482
162.00002,26.99993,146.78636
162.20002,27.03340,147.16311
162.40002,27.06660,147.40719
162.60000,27.09993,147.74628
162.80000,27.13340,148.07842
163.00002,27.16700,148.25216
163.20002,27.20006,148.59808
163.40002,27.23340,148.84187
163.60000,27.26700,149.09500
163.80000,27.30020,149.41482
164.00002,27.33340,149.64723
164.20002,27.36660,149.93697
164.40002,27.40020,150.39784
164.60000,27.43366,150.67768
164.80000,27.46686,151.12747
165.00002,27.50020,151.46233
165.20002,27.53326,151.84770
165.40002,27.56673,152.19752
165.60000,27.60006,152.60222
165.80000,27.63326,152.98988
166.00002,27.66673,153.35481
166.20002,27.70020,153.76539
166.40002,27.73339,154.17174
166.60000,27.76673,154.56255
166.80000,27.80019,154.97245
167.00002,27.83353,155.35310
167.20002,27.86646,155.65190
167.40002,27.90006,156.08926
167.60000,27.93366,156.51312
167.80000,27.96699,156.83185
168.00002,28.00019,157.16512
168.20002,28.03353,157.50762
168.40002,28.06673,157.86897
168.60000,28.10006,158.20270
168.80000,28.13326,158.58999
169.00002,28.16673,158.85863
169.20002,28.20006,159.18525
169.40002,28.23366,159.51486
169.60000,28.26673,159.94955
169.80000,28.30006,160.21600
170.00002,28.33339,160.51078
170.20002,28.36686,160.75851
170.40002,28.39993,161.01411
170.60000,28.43326,161.37304
170.80000,28.46686,161.64571
171.00002,28.50019,161.93327
171.20002,28.53339,162.18854
171.40002,28.56699,162.57437
171.60000,28.60006,162.87049
171.80000,28.63339,163.15656
172.00002,28.66659,163.52378
172.20002,28.69993,163.91043
172.40002,28.73339,164.19398
172.60000,28.76699,164.53614
172.80000,28.80006,164.85974
173.00002,28.83339,165.16488
173.20002,28.86673,165.52249
173.40002,28.90019,165.68072
173.60000,28.93326,165.95915
173.80000,28.96672,166.11714
174.00002,29.00019,166.09745
174.20002,29.03352,166.21640
174.40002,29.06686,166.41799
174.60000,29.10019,166.73194
174.80000,29.13339,166.98677
175.00002,29.16672,167.15946
175.20002,29.19992,167.33108
175.40002,29.23339,167.58654
175.60000,29.26672,167.83228
175.80000,29.30032,167.93611
176.00002,29.33339,168.08782
176.20002,29.36672,168.20190
176.40002,29.40019,168.26181
176.60000,29.43352,168.24417
176.80000,29.46659,167.97535
177.00002,29.50006,167.73736
177.20002,29.53352,167.58420
177.40002,29.56699,167.45914
177.60000,29.60019,167.52267
177.80000,29.63352,167.64930
178.00002,29.66672,168.01579
178.20002,29.70006,168.36977
178.40002,29.73326,168.62784
178.60000,29.76659,169.05280
178.80000,29.80006,169.51859
179.00002,29.83366,169.86785
179.20002,29.86672,170.28330
179.40002,29.90006,170.62530
179.60000,29.93352,171.09834
179.80000,29.96686,171.50393
180.00002,29.99992,171.89434
180.20002,30.03326,172.13572
180.40002,30.06686,172.53608
180.60000,30.10019,172.93403
180.80000,30.13339,173.28132
181.00002,30.16672,173.64765
181.20002,30.20005,174.00837
181.40002,30.23339,174.20020
181.60000,30.26672,174.46440
181.80000,30.29992,174.69537
182.00002,30.33339,174.92805
182.20002,30.36699,175.14879
182.40002,30.40019,175.39430
182.60000,30.43339,175.66221
182.80000,30.46685,175.87170
183.00002,30.50005,176.17891
183.20002,30.53312,176.44342
183.40002,30.56672,176.68946
183.60000,30.60019,177.08341
183.80000,30.63365,177.36057
184.00002,30.66672,177.37819
184.20002,30.70019,177.70013
184.40002,30.73339,177.90819
184.60000,30.76672,178.14202
184.80000,30.80005,178.27695
185.00002,30.83325,178.51928
185.20002,30.86672,178.75152
185.40002,30.90032,178.86734
185.60000,30.93352,178.98671
185.80000,30.96659,179.11213
186.00002,31.00005,179.27293
186.20002,31.03352,179.25683
186.40002,31.06672,179.15240
186.60000,31.09992,179.22113
186.80000,31.13365,179.11095
187.00002,31.16699,179.15810
187.20002,31.20019,179.17773
187.40002,31.23352,178.97671
187.60000,31.26672,178.69705
187.80000,31.30005,178.27438
188.00002,31.33312,178.24948
188.20002,31.36658,178.39205
188.40002,31.39992,178.78294
188.60000,31.43352,179.16931
188.80000,31.46685,179.52656
189.00002,31.49991,179.76953
189.20002,31.53338,180.06211
189.40002,31.56685,180.25655
189.60000,31.59992,180.59313
189.80000,31.63338,180.89592
190.00002,31.66698,181.19510
190.20002,31.70032,181.39668
190.40002,31.73352,181.70286
190.60000,31.76685,181.96639
190.80000,31.80005,182.32975
191.00002,31.83338,182.63385
191.20002,31.86658,182.90462
191.40002,31.89991,183.08096
191.60000,31.93338,183.37810
191.80000,31.96685,183.65877
192.00002,32.00005,183.98380
192.20002,32.03338,184.27398
192.40002,32.06671,184.37220
192.60000,32.10018,184.64889
192.80000,32.13338,184.85779
193.00002,32.16658,184.98620
193.20002,32.20031,185.12916
193.40002,32.23365,185.24744
193.60000,32.26685,185.46809
193.80000,32.30018,185.71483
194.00002,32.33338,186.02334
194.20002,32.36672,186.19878
194.40002,32.39992,186.34349
194.60000,32.43325,186.72040
194.80000,32.46671,187.00639
195.00002,32.50032,187.22804
195.20002,32.53352,187.56382
195.40002,32.56672,187.68823
195.60000,32.60005,188.06040
195.80000,32.63365,188.29102
196.00002,32.66645,188.43105
196.20002,32.69991,188.66949
196.40002,32.73351,188.74798
196.60000,32.76698,188.99072
196.80000,32.80018,189.10645
197.00002,32.83351,189.25870
197.20002,32.86671,189.35459
197.40002,32.90005,189.40816
197.60000,32.93325,189.62832
197.80000,32.96658,189.76618
198.00002,33.00004,190.00735
198.20002,33.03365,190.33564
198.40002,33.06671,190.37560
198.60000,33.09991,190.81913
198.80000,33.13351,191.11166
199.00002,33.16684,191.45584
199.20002,33.19991,191.66956
199.40002,33.23324,191.78279
199.60000,33.26685,192.02087
199.80000,33.30031,192.23416
200.00002,33.33338,192.47765
200.20002,33.36684,192.75589
200.40002,33.40004,192.93290
200.60000,33.43338,193.21321
200.80000,33.46671,193.40627
201.00002,33.49991,193.70157
201.20002,33.53338,193.88475
201.40002,33.56698,193.93669
201.60000,33.60004,194.09122
201.80000,33.63338,193.52239
202.00002,33.66685,193.58810
202.20002,33.70018,193.79200
202.40002,33.73338,193.94608
202.60000,33.76658,194.26130
202.80000,33.80031,194.50663
203.00002,33.83365,194.76674
203.20002,33.86685,194.94276
203.40002,33.90018,195.13188
203.60000,33.93338,195.42448
203.80000,33.96671,195.66497
204.00002,34.00004,195.91089
204.20002,34.03324,196.10839
204.40002,34.06671,196.37812
204.60000,34.10017,196.71068
204.80000,34.13364,196.88584
205.00002,34.16671,197.12789
205.20002,34.20018,197.34763
205.40002,34.23351,197.51269
205.60000,34.26671,197.65042
205.80000,34.29991,197.65060
206.00002,34.33351,197.88660
206.20002,34.36698,197.89645
206.40002,34.40004,198.02099
206.60000,34.43351,198.27420
206.80000,34.46684,198.23171
207.00002,34.50004,198.36050
207.20002,34.53324,198.36361
207.40002,34.56657,198.38119
207.60000,34.59991,198.42105
207.80000,34.63364,198.57896
208.00002,34.66684,198.85238
208.20002,34.70004,198.99694
208.40002,34.73351,199.26015
208.60000,34.76684,199.51727
208.80000,34.79991,199.64153
209.00002,34.83324,199.81558
209.20002,34.86697,199.92374
209.40002,34.90031,200.11904
209.60000,34.93337,200.26440
209.80000,34.96684,200.40814
210.00002,35.00004,200.67168
210.20002,35.03351,200.82634
210.40002,35.06671,201.00955
210.60000,35.09991,201.25736
210.80000,35.13337,201.44839
211.00002,35.16698,201.78411
211.20002,35.20017,201.96559
211.40002,35.23324,202.19810
211.60000,35.26671,202.44448
211.80000,35.30017,202.51011
212.00002,35.33324,202.68157
212.20002,35.36657,202.75943
212.40002,35.40004,202.96775
212.60000,35.43364,203.05896
212.80000,35.46684,203.04175
213.00002,35.50031,203.08241
213.20002,35.53351,203.11935
213.40002,35.56684,202.33329
213.60000,35.60004,198.69685
213.80000,35.63324,195.53430
214.00002,35.66684,193.69839
214.20002,35.70017,192.71558
214.40002,35.73351,192.37569
214.60000,35.76671,192.53017
214.80000,35.79991,192.75380
215.00002,35.83337,193.30196
215.20002,35.86657,193.80581
215.40002,35.89991,194.36860
215.60000,35.93351,195.09802
215.80000,35.96697,195.50208
216.00002,36.00017,195.99959
216.20002,36.03350,196.43949
216.40002,36.06670,196.86587
216.60000,36.10017,197.38952
216.80000,36.13324,195.34642
217.00002,36.16657,194.32262
217.20002,36.19990,193.52078
217.40002,36.23364,192.71202
217.60000,36.26670,192.00930
217.80000,36.30004,189.05722
218.00002,36.33337,187.06895
218.20002,36.36684,182.71610
218.40002,36.40004,181.56728
218.60000,36.43324,181.24690
218.80000,36.46684,181.23193
219.00002,36.50030,181.18832
219.20002,36.53364,181.27751
219.40002,36.56670,181.56108
219.60000,36.60004,181.51965
219.80000,36.63337,176.80002
220.00002,36.66657,175.07778
220.20002,36.69990,173.42700
220.40002,36.73337,169.70092
220.60000,36.76697,169.04183
220.80000,36.80004,169.04732
221.00002,36.83324,169.30912
221.20002,36.86684,169.65449
221.40002,36.90017,170.18612
221.60000,36.93324,170.77725
221.80000,36.96657,171.11499
222.00002,37.00017,171.76948
222.20002,37.03364,172.25863
222.40002,37.06684,172.59603
222.60000,37.10017,172.96454
222.80000,37.13337,166.31328
223.00002,37.16684,163.97245
223.20002,37.20017,162.83527
223.40002,37.23324,162.22568
223.60000,37.26670,161.76514
223.80000,37.30030,161.25022
224.00002,37.33350,160.89104
224.20002,37.36670,160.77839
224.40002,37.40003,160.83719
224.60000,37.43350,161.21471
224.80000,37.46657,161.43916
225.00002,37.50004,161.90335
225.20002,37.53350,162.38399
225.40002,37.56683,162.91209
225.60000,37.60003,163.51691
225.80002,37.63337,163.91870
226.00002,37.66670,164.33531
226.20002,37.70017,164.60737
226.40002,37.73337,164.88019
226.60000,37.76657,165.22270
226.80002,37.80003,165.60804
227.00002,37.83363,166.08611
227.20002,37.86683,166.40911
227.40002,37.90003,166.68707
227.60000,37.93350,167.08551
227.80002,37.96683,167.40063
228.00002,38.00003,167.78423
228.20002,38.03323,168.21055
228.40002,38.06683,168.68718
228.60000,38.10030,169.24402
228.80002,38.13337,169.63989
229.00002,38.16683,170.06190
229.20002,38.20003,170.34117
229.40002,38.23337,170.63003
229.60000,38.26670,170.83023
229.80002,38.29990,170.78219
230.00002,38.33337,170.82838
230.20002,38.36697,170.69623
230.40002,38.40003,170.81711
230.60000,38.43337,170.90265
230.80002,38.46670,170.76658
231.00002,38.50017,171.15256
231.20002,38.53337,171.48828
231.40002,38.56657,171.95966
231.60000,38.60017,172.54297
231.80002,38.63363,172.85122
232.00002,38.66683,173.42161
232.20002,38.70017,173.87997
232.40002,38.73350,174.38322
232.60000,38.76670,174.88647
232.80002,38.80003,175.19243
233.00002,38.83323,175.62848
233.20002,38.86670,175.90558
233.40002,38.90030,176.17788
233.60000,38.93337,176.49936
233.80002,38.96657,176.58055
234.00002,39.00016,176.91327
234.20002,39.03350,177.07642
234.40002,39.06656,177.20398
234.60000,39.10003,177.42822
234.80002,39.13363,177.55892
235.00002,39.16696,177.74312
235.20002,39.20016,177.76269
235.40002,39.23350,177.96921
235.60000,39.26683,178.22692
235.80002,39.30003,177.99437
236.00002,39.33323,177.93093
236.20002,39.36656,177.80663
236.40002,39.40003,177.65965
236.60000,39.43350,177.68778
236.80002,39.46683,177.38113
237.00002,39.49976,177.50043
237.20002,39.53363,177.82833
237.40002,39.56683,178.31910
237.60000,39.59990,178.94482
237.80002,39.63323,179.34596
238.00002,39.66696,180.04872
238.20002,39.70030,180.54070
238.40002,39.73336,181.02102
238.60000,39.76683,181.63435
238.80002,39.80003,182.02445
239.00002,39.83350,182.53412
239.20002,39.86670,182.90637
239.40002,39.89990,183.18251
239.60000,39.93336,183.54427
239.80002,39.96683,183.70289
240.00002,40.00016,183.95212
240.20002,40.03323,184.13214
240.40002,40.06670,184.24563
240.60000,40.10016,184.46367
240.80002,40.13323,184.56655
241.00002,40.16669,184.83300
241.20002,40.20016,185.08831
241.40002,40.23350,185.35554
241.60000,40.26683,185.73446
241.80002,40.30016,186.00844
242.00002,40.33349,186.41040
242.20002,40.36669,186.63656
242.40002,40.39989,186.92827
242.60000,40.43336,187.33867
242.80002,40.46656,187.74694
243.00002,40.50029,188.20073
243.20002,40.53349,188.46836
243.40002,40.56669,188.83888
243.60000,40.60003,189.26851
243.80002,40.63349,189.44304
244.00002,40.66656,189.66693
244.20002,40.69990,189.94084
244.40002,40.73349,190.29191
244.60000,40.76696,190.68697
244.80002,40.80016,190.91913
245.00002,40.83349,191.20926
245.20002,40.86669,191.39951
245.40002,40.90016,191.68528
245.60000,40.93336,191.98250
245.80002,40.96656,192.10104
246.00002,41.00003,192.36827
246.20002,41.03363,192.68222
246.40002,41.06669,193.03598
246.60000,41.10003,193.44928
246.80002,41.13336,193.68988
247.00002,41.16696,194.00304
247.20002,41.19976,194.33886
247.40002,41.23323,194.69475
247.60000,41.26669,195.12223
247.80002,41.30016,195.44799
248.00002,41.33349,195.82812
248.20002,41.36683,196.19735
248.40002,41.40003,196.52192
248.60000,41.43336,196.95509
248.80002,41.46669,197.14810
249.00002,41.49976,197.41045
249.20002,41.53336,197.65615
249.40002,41.56696,197.81630
249.60000,41.60016,198.03841
249.80002,41.63336,198.03308
250.00002,41.66682,198.12761
250.20002,41.70029,198.08069
250.40002,41.73322,198.16428
250.60000,41.76669,198.24689
250.80002,41.80016,198.27237
251.00002,41.83376,198.42645
251.20002,41.86669,197.36791
251.40002,41.90016,195.77716
251.60000,41.93349,195.44313
251.80002,41.96669,195.21801
252.00002,41.99989,195.41413
252.20002,42.03323,195.54777
252.40002,42.06669,195.79383
252.60000,42.10029,196.22236
252.80002,42.13349,196.42385
253.00002,42.16669,196.71926
253.20002,42.20016,196.92516
253.40002,42.23349,197.12674
253.60000,42.26656,197.39965
253.80002,42.29989,197.47330
254.00002,42.33362,197.79034
254.20002,42.36696,197.88072
254.40002,42.40016,198.14860
254.60000,42.43349,198.39831
254.80002,42.46669,198.37074
255.00002,42.50016,197.01768
255.20002,42.53309,196.48008
255.40002,42.56656,196.25464
255.60000,42.60002,196.29464
255.80002,42.63362,196.12875
256.00000,42.66682,196.27666
256.20002,42.70002,196.30222
256.40003,42.73349,194.67684
256.60000,42.76682,193.88393
256.80002,42.79989,193.30826
257.00000,42.83322,193.13294
257.20002,42.86682,193.08163
257.40003,42.90029,193.04371
257.60000,42.93349,188.50015
257.80002,42.96682,187.43809
258.00000,43.00002,187.02703
258.20002,43.03349,186.87224
258.40003,43.06669,187.11168
258.60000,43.09989,187.43493
258.80002,43.13336,187.68456
259.00000,43.16695,188.00372
259.20002,43.20002,180.73998
259.40003,43.23335,178.62292
259.60000,43.26669,177.78523
259.80002,43.30016,177.55603
260.00000,43.33322,177.68800
260.20002,43.36656,177.92616
260.40003,43.40029,178.35384
260.60000,43.43362,178.78419
260.80002,43.46669,179.14614
261.00000,43.50016,179.65984
261.20002,43.53335,180.08361
261.40003,43.56669,180.51427
261.60000,43.59988,180.94370
261.80002,43.63322,181.35289
262.00000,43.66669,181.81773
262.20000,43.70029,182.24234
262.40003,43.73335,182.70627
262.60000,43.76668,183.19765
262.80003,43.80015,183.50575
263.00000,43.83349,183.90007
263.20000,43.86655,184.19843
263.40003,43.90002,184.53535
263.60000,43.93348,184.87338
263.80003,43.96695,185.03487
264.00000,44.00015,185.33804
264.20000,44.03349,185.62490
264.40003,44.06682,185.99628
264.60000,44.10002,186.42565
264.80003,44.13322,186.59206
265.00000,44.16655,186.93389
265.20000,44.20002,187.18708
265.40003,44.23362,187.55961
265.60000,44.26669,187.96129
265.80003,44.29989,186.41714
266.00000,44.33348,186.24535
266.20000,44.36682,186.07959
266.40003,44.39988,186.19401
266.60000,44.43322,186.30875
266.80003,44.46682,186.33451
267.00000,44.50028,186.59092
267.20000,44.53348,186.70721
267.40003,44.56682,186.93971
267.60000,44.60015,175.15061
267.80003,44.63335,169.52500
268.00000,44.66669,166.80861
268.20000,44.69988,164.87792
268.40003,44.73335,163.35316
268.60000,44.76682,162.38015
268.80003,44.80002,161.72720
269.00000,44.83335,159.10465
269.20000,44.86682,157.97008
269.40003,44.90028,140.36076
269.60000,44.93335,134.87817
269.80003,44.96668,131.47469
270.00000,45.00028,128.87660
270.20000,45.03362,126.42284
270.40003,45.06681,124.14520
270.60000,45.10015,122.38732
270.65200,45.10868,121.92886