File: FirefighterJacket/data/instron/Specimen_RawData_4.csv
Time,Extension,Load
(sec),(mm),(N)
0.00000,0.00000,0.05416
0.20000,0.02867,-0.12379
0.40000,0.06520,0.06169
0.60000,0.09947,0.03709
0.80000,0.13333,0.04404
1.00000,0.16680,0.07527
1.20000,0.20013,0.08066
1.40000,0.23347,0.08240
1.60000,0.26693,0.05375
1.80000,0.30027,0.10148
2.00000,0.33320,0.15928
2.20000,0.36653,0.10418
2.40000,0.40000,0.09975
2.60000,0.43360,0.11942
2.80000,0.46680,0.11096
3.00000,0.50013,0.08155
3.20000,0.53333,0.08205
3.40000,0.56693,0.11705
3.60000,0.60000,0.10713
3.80000,0.63320,0.14038
4.00000,0.66680,0.13497
4.20000,0.70026,0.17699
4.40000,0.73333,0.15050
4.60000,0.76680,0.17423
4.80000,0.80013,0.18607
5.00000,0.83360,0.20082
5.20000,0.86666,0.18164
5.40000,0.90000,0.19224
5.60000,0.93346,0.20974
5.80000,0.96680,0.17618
6.00000,1.00013,0.22741
6.20000,1.03333,0.20691
6.40000,1.06680,0.28769
6.60000,1.10026,0.23580
6.80000,1.13320,0.23223
7.00000,1.16653,0.28107
7.20000,1.20013,0.30788
7.40000,1.23360,0.28274
7.60000,1.26680,0.26188
7.80000,1.30026,0.30679
8.00000,1.33346,0.30032
8.20000,1.36693,0.29356
8.40000,1.40000,0.30877
8.60000,1.43320,0.27177
8.80000,1.46666,0.26468
9.00000,1.50013,0.30977
9.20000,1.53346,0.34980
9.40000,1.56680,0.29454
9.60000,1.60013,0.35965
9.80000,1.63360,0.37034
10.00000,1.66680,0.32570
10.20000,1.69986,0.45160
10.40000,1.73346,0.39273
10.60000,1.76680,0.40882
10.80000,1.80026,0.44783
11.00000,1.83360,0.48800
11.20000,1.86680,0.51301
11.40000,1.90026,0.50933
11.60000,1.93333,0.44377
11.80000,1.96666,0.50471
12.00000,1.99999,0.54306
12.20000,2.03346,0.50349
12.40000,2.06679,0.56103
12.60000,2.09999,0.56257
12.80000,2.13333,0.60479
13.00000,2.16706,0.57421
13.20000,2.19999,0.62128
13.40000,2.23319,0.70957
13.60000,2.26693,0.65176
13.80000,2.30026,0.63824
14.00000,2.33346,0.66806
14.20000,2.36679,0.72097
14.40000,2.40026,0.64545
14.60000,2.43359,0.75099
14.80000,2.46666,0.74200
15.00000,2.49986,0.75493
15.20000,2.53333,0.76124
15.40000,2.56679,0.80496
15.60000,2.60013,0.79639
15.80000,2.63346,0.81850
16.00000,2.66679,0.83612
16.20000,2.70026,0.87697
16.40000,2.73333,0.90687
16.60000,2.76653,0.92979
16.80000,2.79999,0.98245
17.00000,2.83346,0.97309
17.20000,2.86679,0.95797
17.40000,2.90013,1.01107
17.60000,2.93359,0.95020
17.80000,2.96679,1.04393
18.00000,3.00013,1.06888
18.20000,3.03319,1.10594
18.40000,3.06666,1.10496
18.60000,3.10013,1.15905
18.80000,3.13346,1.14124
19.00000,3.16666,1.13158
19.20000,3.20012,1.17324
19.40000,3.23359,1.20974
19.60000,3.26666,1.21198
19.80000,3.29999,1.22844
20.00000,3.33346,1.35305
20.20000,3.36679,1.28943
20.40000,3.40012,1.34792
20.60000,3.43359,1.30857
20.80000,3.46679,1.36353
21.00000,3.50026,1.40156
21.20000,3.53332,1.47120
21.40000,3.56652,1.46735
21.60000,3.60026,1.52157
21.80000,3.63332,1.54529
22.00000,3.66692,1.57368
22.20000,3.69999,1.61183
22.40000,3.73346,1.58179
22.60000,3.76706,1.66420
22.80000,3.80012,1.69656
23.00000,3.83319,1.69370
23.20000,3.86666,1.77485
23.40000,3.90026,1.75518
23.60000,3.93359,1.76935
23.80000,3.96692,1.86113
24.00000,4.00026,1.80539
24.20000,4.03346,1.88825
24.40000,4.06666,1.95229
24.60000,4.09999,1.95407
24.80000,4.13319,1.96859
25.00000,4.16679,2.06417
25.20000,4.20012,2.14913
25.40000,4.23346,2.15724
25.60000,4.26692,2.06743
25.80000,4.30012,2.21454
26.00000,4.33332,2.22835
26.20000,4.36652,2.30077
26.40000,4.40012,2.31301
26.60000,4.43359,2.32492
26.80000,4.46679,2.40003
27.00000,4.50025,2.45567
27.20000,4.53345,2.48175
27.40000,4.56692,2.52986
27.60000,4.59999,2.57331
27.80000,4.63319,2.64419
28.00000,4.66665,2.65661
28.20000,4.70012,2.71019
28.40000,4.73345,2.74670
28.60000,4.76679,2.77505
28.80000,4.80012,2.82339
29.00000,4.83372,2.87234
29.20000,4.86652,2.92833
29.40000,4.89985,3.01556
29.60000,4.93359,3.00579
29.80000,4.96679,3.10992
30.00000,5.00012,3.16523
30.20000,5.03345,3.23078
30.40000,5.06692,3.27965
30.60000,5.10012,3.30177
30.80000,5.13332,3.35197
31.00000,5.16665,3.41059
31.20000,5.19999,3.48752
31.40000,5.23345,3.51639
31.60000,5.26679,3.58582
31.80000,5.30012,3.65115
32.00000,5.33345,3.73843
32.20000,5.36692,3.79789
32.40000,5.39999,3.81954
32.60000,5.43319,3.84830
32.80000,5.46665,3.90432
33.00000,5.50025,4.02922
33.20000,5.53345,4.10983
33.40000,5.56692,4.17267
33.60000,5.60025,4.17140
33.80000,5.63359,4.25655
34.00000,5.66665,4.38855
34.20000,5.69985,4.39804
34.40000,5.73318,4.49106
34.60000,5.76679,4.56386
34.80000,5.80012,4.65144
35.00000,5.83345,4.68740
35.20000,5.86665,4.78388
35.40000,5.90025,4.85668
35.60000,5.93332,4.98710
35.80000,5.96665,5.04388
36.00000,6.00012,5.10590
36.20000,6.03345,5.18131
36.40000,6.06692,5.30714
36.60000,6.10025,5.34570
36.80000,6.13345,5.45596
37.00000,6.16692,5.52204
37.20000,6.19998,5.61276
37.40000,6.23318,5.77989
37.60000,6.26665,5.79244
37.80000,6.29998,5.86466
38.00000,6.33345,5.99206
38.20000,6.36678,6.07822
38.40000,6.39998,6.15190
38.60000,6.43372,6.28210
38.80000,6.46678,6.35841
39.00000,6.49972,6.46209
39.20000,6.53332,6.50804
39.40000,6.56678,6.66329
39.60000,6.60012,6.68871
39.80000,6.63358,6.85764
40.00000,6.66692,6.91360
40.20000,6.70025,7.02246
40.40000,6.73332,7.14567
40.60000,6.76652,7.24715
40.80000,6.79998,7.35719
41.00000,6.83345,7.48367
41.20000,6.86678,7.66617
41.40000,6.90012,7.72240
41.60000,6.93345,7.87226
41.80000,6.96692,7.93649
42.00000,6.99998,8.00738
42.20000,7.03318,8.19993
42.40000,7.06678,8.28730
42.60000,7.10025,8.44002
42.80000,7.13345,8.55160
43.00000,7.16678,8.64383
43.20000,7.20025,8.86347
43.40000,7.23358,8.93087
43.60000,7.26651,8.99642
43.80000,7.29998,9.16920
44.00000,7.33331,9.28346
44.20000,7.36665,9.55045
44.40000,7.40011,9.61495
44.60000,7.43358,9.64008
44.80000,7.46678,9.91275
45.00000,7.50025,9.94344
45.20000,7.53331,10.03200
45.40000,7.56665,10.13787
45.60000,7.59998,10.28712
45.80000,7.63358,10.46168
46.00000,7.66665,10.53059
46.20000,7.70011,10.65851
46.40000,7.73345,10.76045
46.60000,7.76691,11.03087
46.80000,7.79998,11.06305
47.00000,7.83331,11.18782
47.20000,7.86665,11.39851
47.40000,7.90011,11.51145
47.60000,7.93345,11.72827
47.80000,7.96665,11.91714
48.00000,7.99985,12.02768
48.20000,8.03345,12.22056
48.40000,8.06664,12.40631
48.60000,8.09985,12.58943
48.80000,8.13331,12.72672
49.00000,8.16691,12.89278
49.20000,8.20024,13.08569
49.40000,8.23371,13.24544
49.60000,8.26678,13.49790
49.80000,8.30024,13.61156
50.00000,8.33331,13.82300
50.20000,8.36651,13.99139
50.40000,8.39984,14.24711
50.60000,8.43344,14.44049
50.80000,8.46691,14.54328
51.00000,8.50011,14.77539
51.20000,8.53344,14.92511
51.40000,8.56691,15.19207
51.60000,8.59998,15.33450
51.80000,8.63318,15.56007
52.00000,8.66678,15.69410
52.20000,8.70024,15.96059
52.40000,8.73344,16.12673
52.60000,8.76678,16.44098
52.80000,8.80011,16.62248
53.00000,8.83344,16.78010
53.20000,8.86664,17.03003
53.40000,8.89998,17.24000
53.60000,8.93318,17.46785
53.80000,8.96678,17.70216
54.00000,9.00011,17.87491
54.20000,9.03344,18.15622
54.40000,9.06664,18.36491
54.60000,9.10024,18.67370
54.80000,9.13331,18.90676
55.00000,9.16651,19.14234
55.20000,9.19998,19.33628
55.40000,9.23358,19.64018
55.60000,9.26678,19.94594
55.80000,9.30024,20.13133
56.00000,9.33358,20.34243
56.20000,9.36691,20.66672
56.40000,9.40011,20.90713
56.60000,9.43331,21.22480
56.80000,9.46664,21.49985
57.00000,9.49998,21.80371
57.20000,9.53344,21.99367
57.40000,9.56677,22.30162
57.60000,9.60011,22.65560
57.80000,9.63371,22.91270
58.00000,9.66651,23.15766
58.20000,9.69984,23.46509
58.40000,9.73344,23.81802
58.60000,9.76677,24.14058
58.80000,9.80011,24.38803
59.00000,9.83344,24.68083
59.20000,9.86691,24.96681
59.40000,9.90024,25.32485
59.60000,9.93331,25.66587
59.80000,9.96651,25.96867
60.00000,9.99997,26.26297
60.20000,10.03344,26.57706
60.40000,10.06677,26.96120
60.60000,10.10011,27.28800
60.80000,10.13344,27.54357
61.00000,10.16691,27.90987
61.20000,10.19997,28.21698
61.40000,10.23317,28.58910
61.60000,10.26651,29.04257
61.80000,10.30024,29.31350
62.00000,10.33331,29.61196
62.20000,10.36691,29.96271
62.40000,10.40011,30.31124
62.60000,10.43357,30.76773
62.80000,10.46664,31.08416
63.00000,10.49984,31.42220
63.20000,10.53331,31.75867
63.40000,10.56677,32.16751
63.60000,10.60011,32.57013
63.80000,10.63344,32.90599
64.00000,10.66664,33.25790
64.20000,10.70024,33.63576
64.40000,10.73317,34.00187
64.60001,10.76651,34.45450
64.80000,10.80011,34.81291
65.00000,10.83357,35.17897
65.20000,10.86690,35.58239
65.40000,10.90024,36.00573
65.60001,10.93344,36.38254
65.80000,10.96690,36.82054
66.00000,10.99997,37.13886
66.20001,11.03330,37.59004
66.40000,11.06664,37.92165
66.60001,11.10010,38.40514
66.80000,11.13357,38.76042
67.00000,11.16664,39.19594
67.20001,11.19997,39.61163
67.40000,11.23357,39.98859
67.60001,11.26650,40.49308
67.80000,11.29984,40.81325
68.00000,11.33344,41.22012
68.20001,11.36690,41.65429
68.40000,11.40010,42.09928
68.60001,11.43357,42.60797
68.80000,11.46677,42.97767
69.00000,11.50010,43.41841
69.20001,11.53330,43.81098
69.40000,11.56664,44.26245
69.60001,11.59997,44.77267
69.80000,11.63330,45.12029
70.00000,11.66677,45.60734
70.20001,11.69997,46.00758
70.40000,11.73344,46.52328
70.60001,11.76690,47.00031
70.80000,11.79997,47.40860
71.00000,11.83317,47.82812
71.20001,11.86677,48.35355
71.40000,11.90010,48.75226
71.60001,11.93330,49.27113
71.80000,11.96677,49.65185
72.00000,12.00010,50.20236
72.20001,12.03357,50.66361
72.40000,12.06677,51.16444
72.60001,12.09997,51.62932
72.80000,12.13344,52.12207
73.00000,12.16677,52.64182
73.20001,12.20024,53.02361
73.40000,12.23344,53.53057
73.60001,12.26663,53.99015
73.80000,12.30024,54.49895
74.00000,12.33330,55.00047
74.20001,12.36650,55.48810
74.40000,12.39997,55.93034
74.60001,12.43343,56.50995
74.80000,12.46663,57.01005
75.00000,12.50023,57.52812
75.20001,12.53343,58.01720
75.40000,12.56690,58.52735
75.60001,12.60010,59.04487
75.80000,12.63317,59.57640
76.00000,12.66663,60.09495
76.20001,12.70010,60.06959
76.40000,12.73357,60.57687
76.60001,12.76677,61.18849
76.80000,12.80010,61.74817
77.00000,12.83357,62.26663
77.20001,12.86677,62.81972
77.40000,12.89983,63.38186
77.60001,12.93330,63.93540
77.80000,12.96663,64.57953
78.00000,13.00010,65.16166
78.20001,13.03343,65.70379
78.40000,13.06677,66.31130
78.60001,13.10037,66.87749
78.80000,13.13330,67.47508
79.00000,13.16650,68.10363
79.20001,13.19997,68.72765
79.40000,13.23343,69.25462
79.60001,13.26677,69.78292
79.80000,13.30010,70.44278
80.00000,13.33343,71.03955
80.20001,13.36703,71.70333
80.40000,13.39997,72.19955
80.60001,13.43316,72.92198
80.80000,13.46663,73.58271
81.00001,13.50023,74.19064
81.20001,13.53343,74.79204
81.40000,13.56690,75.46904
81.60001,13.60023,76.07516
81.80000,13.63357,76.73844
82.00001,13.66663,77.34852
82.20001,13.69983,78.02845
82.40000,13.73316,78.60433
82.60001,13.76676,79.31137
82.80000,13.80010,80.00428
83.00001,13.83343,80.60658
83.20001,13.86690,81.21209
83.40000,13.90036,81.85026
83.60001,13.93330,82.53164
83.80000,13.96650,83.12645
84.00001,13.99996,83.86314
84.20001,14.03343,84.52076
84.40000,14.06676,85.10830
84.60001,14.10010,85.84293
84.80000,14.13343,86.49130
85.00001,14.16690,87.19404
85.20001,14.20010,87.87722
85.40000,14.23316,88.54325
85.60001,14.26663,89.19820
85.80000,14.30010,89.73842
86.00001,14.33343,90.04148
86.20001,14.36663,90.55680
86.40000,14.40010,91.13582
86.60001,14.43356,91.79642
86.80000,14.46650,92.41753
87.00001,14.49983,93.07088
87.20001,14.53343,93.78365
87.40000,14.56676,94.32136
87.60001,14.60010,95.05377
87.80000,14.63356,95.72225
88.00001,14.66690,96.44068
88.20001,14.70023,97.08826
88.40000,14.73330,97.70597
88.60001,14.76663,98.46058
88.80000,14.79983,99.14177
89.00001,14.83343,99.82757
89.20001,14.86690,100.48309
89.40000,14.90009,101.19175
89.60001,14.93343,101.86725
89.80000,14.96676,102.58818
90.00001,14.99983,103.25030
90.20001,15.03329,103.83865
90.40000,15.06676,104.52311
90.60001,15.10023,105.04868
90.80000,15.13329,105.67320
91.00001,15.16676,106.40314
91.20001,15.20009,107.14084
91.40000,15.23356,107.83770
91.60001,15.26663,108.45518
91.80000,15.29996,109.17282
92.00001,15.33329,109.92502
92.20001,15.36676,110.63157
92.40000,15.40009,111.28031
92.60001,15.43343,111.33526
92.80000,15.46663,111.92335
93.00001,15.50023,112.66755
93.20001,15.53343,113.38277
93.40000,15.56649,114.07853
93.60001,15.60009,114.77009
93.80000,15.63342,115.49076
94.00001,15.66676,114.63197
94.20001,15.70022,115.20219
94.40000,15.73356,114.68639
94.60001,15.76702,115.58741
94.80000,15.79982,115.71018
95.00001,15.83316,116.63944
95.20001,15.86676,117.54109
95.40000,15.90022,118.38713
95.60001,15.93356,119.26575
95.80000,15.96662,120.17909
96.00001,16.00009,121.09268
96.20001,16.03369,121.90585
96.40000,16.06676,122.67728
96.60001,16.09996,123.51476
96.80000,16.13342,124.30812
97.00001,16.16689,125.06286
97.20001,16.20022,125.83754
97.40000,16.23342,126.49514
97.60001,16.26689,127.27896
97.80000,16.30009,128.04883
98.00001,16.33329,128.64219
98.20001,16.36649,128.83266
98.40000,16.39996,129.26714
98.60001,16.43342,129.99017
98.80000,16.46676,130.72687
99.00001,16.49996,131.43791
99.20001,16.53342,132.20521
99.40000,16.56689,132.95212
99.60001,16.60009,133.65472
99.80000,16.63329,134.31538
100.00001,16.66676,134.98811
100.20001,16.70022,134.85522
100.40000,16.73342,135.50254
100.60001,16.76689,136.26009
100.80000,16.80009,137.10726
101.00001,16.83355,137.80376
101.20001,16.86675,138.55022
101.40000,16.89995,139.20609
101.60001,16.93329,139.80550
101.80000,16.96675,140.32875
102.00001,17.00022,140.98252
102.20001,17.03342,141.52500
102.40000,17.06675,142.09736
102.60001,17.10022,142.73109
102.80000,17.13329,143.31209
103.00001,17.16649,143.93054
103.20001,17.20009,144.49307
103.40000,17.23369,145.09805
103.60001,17.26689,145.57399
103.80000,17.30022,146.02160
104.00001,17.33355,146.45350
104.20001,17.36689,146.84088
104.40000,17.39995,146.78741
104.60001,17.43342,147.21943
104.80000,17.46675,147.62740
105.00001,17.50022,148.20806
105.20001,17.53342,148.75185
105.40000,17.56662,149.40006
105.60001,17.60009,150.05466
105.80000,17.63355,150.74342
106.00001,17.66662,151.47410
106.20001,17.69982,152.24620
106.40000,17.73355,152.98672
106.60001,17.76689,153.66632
106.80000,17.79995,154.41660
107.00001,17.83342,155.28827
107.20001,17.86675,156.21205
107.40000,17.90022,157.04557
107.60001,17.93342,157.90775
107.80000,17.96649,158.70143
108.00001,17.99995,159.57994
108.20001,18.03355,160.39839
108.40000,18.06675,161.16910
108.60001,18.09995,161.95375
108.80000,18.13329,162.71614
109.00001,18.16702,163.58562
109.20001,18.19995,164.25323
109.40000,18.23329,165.04036
109.60001,18.26675,165.76583
109.80000,18.30035,166.48553
110.00001,18.33342,167.15473
110.20001,18.36675,167.87156
110.40000,18.40022,168.55881
110.60001,18.43355,169.21667
110.80000,18.46675,169.96326
111.00001,18.49995,170.66430
111.20001,18.53342,171.38243
111.40000,18.56688,171.99650
111.60001,18.60022,172.59499
111.80000,18.63328,173.27292
112.00001,18.66675,173.80990
112.20001,18.70035,174.40468
112.40000,18.73315,174.96377
112.60001,18.76662,175.44867
112.80000,18.80008,175.89865
113.00001,18.83368,176.52722
113.20001,18.86675,177.07283
113.40001,18.90022,177.77722
113.60001,18.93355,178.41153
113.80000,18.96702,179.15918
114.00001,18.99995,179.85389
114.20001,19.03315,180.56959
114.40001,19.06675,181.26953
114.60001,19.10008,181.81542
114.80000,19.13355,182.45364
115.00001,19.16675,183.01560
115.20001,19.20008,183.63481
115.40001,19.23368,184.29397
115.60001,19.26662,185.00391
115.80000,19.29982,185.60424
116.00001,19.33342,186.26228
116.20001,19.36688,186.93851
116.40001,19.39995,187.58504
116.60001,19.43355,188.23924
116.80000,19.46675,188.92882
117.00001,19.50035,189.69966
117.20001,19.53342,190.37843
117.40001,19.56662,190.99427
117.60001,19.59995,191.64179
117.80000,19.63342,192.24888
118.00001,19.66688,192.99600
118.20001,19.70008,193.62899
118.40001,19.73342,194.39775
118.60001,19.76688,195.06406
118.80000,19.80008,195.75577
119.00001,19.83315,196.41513
119.20001,19.86688,197.05975
119.40001,19.90021,197.73876
119.60001,19.93341,198.44614
119.80000,19.96688,198.98804
120.00001,20.00021,199.77866
120.20001,20.03355,200.47477
120.40001,20.06675,201.15919
120.60001,20.09995,201.86141
120.80000,20.13328,202.50773
121.00001,20.16701,203.31260
121.20001,20.20008,204.11624
121.40001,20.23341,204.88674
121.60001,20.26675,205.60743
121.80000,20.30021,206.25785
122.00001,20.33341,206.95839
122.20001,20.36648,207.64519
122.40001,20.40008,208.29985
122.60001,20.43355,209.01328
122.80000,20.46675,209.66498
123.00001,20.50021,210.30543
123.20001,20.53355,211.12597
123.40001,20.56688,211.79594
123.60001,20.59995,212.49466
123.80000,20.63315,213.16895
124.00001,20.66661,213.86875
124.20001,20.70008,214.57423
124.40001,20.73355,215.22043
124.60001,20.76675,215.84073
124.80000,20.80008,216.55153
125.00001,20.83368,217.21816
125.20001,20.86661,217.77615
125.40001,20.90008,218.39347
125.60001,20.93341,218.99736
125.80000,20.96688,219.41552
126.00001,21.00021,219.88958
126.20001,21.03355,220.37081
126.40001,21.06688,220.92270
126.60001,21.10021,220.21381
126.80000,21.13328,220.55259
127.00001,21.16648,221.09073
127.20001,21.19995,221.56976
127.40001,21.23354,222.00216
127.60001,21.26688,222.53923
127.80000,21.30021,223.05885
128.00000,21.33341,223.68012
128.20002,21.36688,224.29198
128.40001,21.39995,225.02044
128.60001,21.43328,225.76133
128.80000,21.46674,226.49067
129.00000,21.50034,227.39217
129.20002,21.53341,228.21754
129.40001,21.56701,229.00635
129.60001,21.60008,229.81830
129.80000,21.63354,230.62654
130.00000,21.66674,231.47460
130.20002,21.69981,232.26960
130.40001,21.73341,233.03473
130.60001,21.76688,233.85862
130.80000,21.80021,234.49609
131.00000,21.83341,235.29189
131.20002,21.86674,235.99578
131.40002,21.90034,236.75630
131.60000,21.93328,237.44950
131.80000,21.96648,238.12033
132.00000,22.00008,238.87360
132.20002,22.03341,239.53892
132.40002,22.06688,240.20014
132.60000,22.10021,240.82419
132.80000,22.13354,241.45825
133.00000,22.16701,242.10867
133.20002,22.19994,242.69374
133.40002,22.23341,243.33576
133.60000,22.26661,243.92122
133.80000,22.30021,244.55993
134.00000,22.33354,245.08983
134.20002,22.36674,245.74403
134.40002,22.40008,246.35952
134.60000,22.43354,246.88710
134.80000,22.46648,247.44233
135.00000,22.49981,247.94867
135.20002,22.53341,248.48036
135.40002,22.56688,249.02415
135.60000,22.60008,249.42297
135.80000,22.63354,249.92896
136.00000,22.66688,250.41386
136.20002,22.70021,250.77887
136.40002,22.73341,251.13281
136.60000,22.76661,251.53201
136.80000,22.80007,251.94446
137.00000,22.83367,252.36024
137.20002,22.86674,252.55261
137.40002,22.90007,252.63093
137.60000,22.93341,252.51137
137.80000,22.96701,252.06467
138.00000,23.00007,251.54406
138.20002,23.03327,251.25103
138.40002,23.06674,251.29605
138.60000,23.10021,251.86937
138.80000,23.13354,252.46769
139.00000,23.16687,253.36053
139.20002,23.20021,254.24099
139.40002,23.23354,255.16907
139.60000,23.26674,256.05092
139.80000,23.29994,256.90304
140.00000,23.33327,257.82377
140.20002,23.36674,258.64463
140.40002,23.40021,259.46742
140.60000,23.43354,260.30559
140.80000,23.46687,261.09569
141.00000,23.50047,261.86692
141.20002,23.53327,262.52961
141.40002,23.56634,263.24650
141.60000,23.60007,263.90336
141.80000,23.63354,264.59312
142.00000,23.66674,265.27608
142.20002,23.70021,265.93026
142.40002,23.73341,266.54463
142.60000,23.76674,267.20263
142.80000,23.79994,267.78307
143.00000,23.83314,268.31992
143.20002,23.86661,268.92964
143.40002,23.90007,269.53332
143.60000,23.93354,268.67120
143.80000,23.96687,264.85823
144.00000,24.00021,265.38668
144.20002,24.03367,266.02427
144.40002,24.06660,266.70294
144.60000,24.09980,267.38800
144.80000,24.13340,268.03138
145.00000,24.16687,268.73726
145.20002,24.20007,269.26722
145.40002,24.23340,269.85023
145.60000,24.26674,270.52414
145.80000,24.30034,271.21345
146.00000,24.33327,271.83369
146.20002,24.36660,272.29469
146.40002,24.39994,272.93507
146.60000,24.43354,273.55483
146.80000,24.46674,273.98206
147.00000,24.50007,274.55166
147.20002,24.53354,274.99009
147.40002,24.56700,275.63604
147.60000,24.59994,276.12790
147.80000,24.63314,276.59569
148.00000,24.66674,277.09372
148.20002,24.70020,277.53877
148.40002,24.73354,277.90850
148.60000,24.76687,278.39195
148.80000,24.80034,278.83563
149.00000,24.83354,279.23573
149.20002,24.86660,279.53647
149.40002,24.89994,279.81220
149.60000,24.93340,274.35012
149.80000,24.96687,272.84838
150.00000,25.00007,273.32349
150.20002,25.03340,273.78643
150.40002,25.06660,274.38940
150.60000,25.10007,274.98050
150.80000,25.13327,275.41203
151.00000,25.16647,275.91377
151.20002,25.20007,276.45154
151.40002,25.23354,276.96608
151.60000,25.26687,277.47702
151.80000,25.30020,277.91092
152.00000,25.33353,278.43302
152.20002,25.36673,278.89036
152.40002,25.40007,279.37328
152.60000,25.43313,279.89324
152.80000,25.46673,280.33018
153.00000,25.50007,280.94100
153.20002,25.53353,281.26733
153.40002,25.56660,281.81553
153.60000,25.60007,282.32934
153.80000,25.63367,282.83527
154.00000,25.66660,283.27050
154.20002,25.69980,283.62840
154.40002,25.73327,284.10247
154.60000,25.76687,284.57537
154.80000,25.80007,284.90361
155.00000,25.83353,285.35711
155.20002,25.86687,285.74679
155.40002,25.90020,286.10712
155.60000,25.93327,286.35977
155.80000,25.96660,286.56561
156.00000,25.99993,286.69063
156.20002,26.03340,286.16441
156.40002,26.06687,284.35050
156.60000,26.10007,280.41357
156.80000,26.13353,276.44433
157.00000,26.16700,274.07099
157.20002,26.20007,273.05836
157.40002,26.23313,272.79869
157.60000,26.26673,273.13868
157.80000,26.30020,273.68836
158.00000,26.33340,274.42511
158.20002,26.36687,275.06510
158.40002,26.40007,275.69775
158.60000,26.43353,276.26976
158.80000,26.46660,276.50513
159.00000,26.49993,276.60869
159.20002,26.53326,276.56799
159.40002,26.56673,276.19593
159.60000,26.60020,275.60584
159.80000,26.63340,274.41647
160.00000,26.66673,273.00462
160.20002,26.70020,272.19286
160.40002,26.73326,271.73834
160.60000,26.76660,271.21302
160.80000,26.80006,270.65743
161.00002,26.83340,269.82294
161.20002,26.86686,268.93254
161.40002,26.90020,268.16310
161.60000,26.93353,268.08940
161.80000,26.96686,268.13708
162.00002,26.99993,268.35529
162.20002,27.03340,268.66138
162.40002,27.06646,268.66326
162.60000,27.10006,268.46118
162.80000,27.13340,267.99418
163.00002,27.16673,267.34157
163.20002,27.20006,266.98520
163.40002,27.23366,267.16253
163.60000,27.26673,267.54564
163.80000,27.29980,267.95657
164.00002,27.33340,268.65030
164.20002,27.36686,269.36250
164.40002,27.40006,270.15861
164.60000,27.43353,271.18804
164.80000,27.46700,271.98408
165.00002,27.50020,272.53643
165.20002,27.53340,272.72796
165.40002,27.56660,272.47746
165.60000,27.60006,271.82456
165.80000,27.63340,270.77932
166.00002,27.66686,269.77126
166.20002,27.70006,268.74397
166.40002,27.73339,267.97330
166.60000,27.76686,267.15795
166.80000,27.79993,266.13479
167.00002,27.83313,264.89018
167.20002,27.86673,263.81865
167.40002,27.90019,262.87049
167.60000,27.93353,261.88497
167.80000,27.96686,260.61000
168.00002,28.00019,259.83222
168.20002,28.03353,259.51758
168.40002,28.06673,259.14311
168.60000,28.09993,259.01543
168.80000,28.13353,258.45792
169.00002,28.16673,256.96075
169.20002,28.20019,254.98657
169.40002,28.23339,253.49237
169.60000,28.26673,253.07342
169.80000,28.30033,253.15246
170.00002,28.33326,253.30370
170.20002,28.36659,253.43560
170.40002,28.40006,253.83951
170.60000,28.43353,254.41917
170.80000,28.46673,254.76595
171.00002,28.50019,255.34438
171.20002,28.53353,255.99906
171.40002,28.56686,256.38059
171.60000,28.60006,256.77744
171.80000,28.63326,257.19317
172.00002,28.66659,257.80652
172.20002,28.70019,258.20145
172.40002,28.73353,258.21222
172.60000,28.76673,257.64138
172.80000,28.80033,257.12825
173.00002,28.83353,256.79767
173.20002,28.86673,256.78918
173.40002,28.89979,257.31269
173.60000,28.93339,258.24158
173.80000,28.96686,259.19233
174.00002,29.00006,260.00021
174.20002,29.03352,260.57929
174.40002,29.06672,261.15367
174.60000,29.10032,261.56658
174.80000,29.13352,261.55582
175.00002,29.16659,261.51864
175.20002,29.20006,261.04640
175.40002,29.23352,260.05721
175.60000,29.26686,258.16936
175.80000,29.30019,256.33214
176.00002,29.33339,255.32382
176.20002,29.36686,254.99066
176.40002,29.40006,255.14798
176.60000,29.43326,255.45642
176.80000,29.46672,256.07238
177.00002,29.50019,256.73607
177.20002,29.53339,257.37651
177.40002,29.56686,257.90149
177.60000,29.60019,258.12063
177.80000,29.63366,258.08141
178.00002,29.66672,258.05039
178.20002,29.70006,258.16640
178.40002,29.73326,258.34445
178.60000,29.76686,258.86510
178.80000,29.80006,259.25122
179.00002,29.83339,259.65836
179.20002,29.86686,259.89139
179.40002,29.90019,260.10863
179.60000,29.93326,260.36998
179.80000,29.96659,260.47718
180.00002,30.00006,260.41474
180.20002,30.03352,260.44620
180.40002,30.06672,260.45859
180.60000,30.10032,260.62680
180.80000,30.13352,260.86969
181.00002,30.16686,261.05510
181.20002,30.20005,261.08088
181.40002,30.23326,261.20938
181.60000,30.26659,261.31814
181.80000,30.30005,261.26154
182.00002,30.33352,261.20942
182.20002,30.36672,261.09757
182.40002,30.40005,250.30727
182.60000,30.43365,249.61663
182.80000,30.46672,249.25308
183.00002,30.49992,249.15848
183.20002,30.53339,249.06294
183.40002,30.56672,249.23757
183.60000,30.60005,249.51007
183.80000,30.63352,249.92373
184.00002,30.66685,250.53877
184.20002,30.70019,251.00913
184.40002,30.73325,251.11798
184.60000,30.76659,251.10971
184.80000,30.79992,251.28013
185.00002,30.83352,251.56960
185.20002,30.86685,251.98607
185.40002,30.90005,252.33492
185.60000,30.93339,252.56539
185.80000,30.96685,252.86697
186.00002,31.00005,253.36619
186.20002,31.03325,254.09058
186.40002,31.06672,254.74055
186.60000,31.10005,255.09110
186.80000,31.13339,255.23270
187.00002,31.16685,255.31014
187.20002,31.20019,255.30163
187.40002,31.23352,255.44370
187.60000,31.26672,255.68213
187.80000,31.29992,255.82949
188.00002,31.33325,256.24348
188.20002,31.36672,256.63534
188.40002,31.40019,256.75151
188.60000,31.43352,256.88477
188.80000,31.46672,257.14971
189.00002,31.50032,257.45392
189.20002,31.53325,257.76608
189.40002,31.56645,258.09972
189.60000,31.60005,258.54945
189.80000,31.63365,258.93070
190.00002,31.66685,259.28976
190.20002,31.70018,259.22853
190.40002,31.73338,258.91813
190.60000,31.76685,258.85774
190.80000,31.80005,254.60200
191.00002,31.83338,238.33329
191.20002,31.86671,228.69576
191.40002,31.90018,221.75739
191.60000,31.93352,216.15362
191.80000,31.96672,212.41689
192.00002,32.00005,210.86797
192.20002,32.03365,210.33183
192.40002,32.06671,210.51183
192.60000,32.10005,209.53674
192.80000,32.13352,207.31283
193.00002,32.16685,205.14755
193.20002,32.20005,203.13391
193.40002,32.23351,201.58630
193.60000,32.26685,200.13738
193.80000,32.30018,198.58645
194.00002,32.33338,197.72999
194.20002,32.36658,197.33856
194.40002,32.39992,197.35476
194.60000,32.43338,197.50778
194.80000,32.46685,197.39805
195.00002,32.49991,197.10822
195.20002,32.53338,196.35774
195.40002,32.56698,195.40554
195.60000,32.59991,194.35527
195.80000,32.63311,192.93137
196.00002,32.66685,191.23068
196.20002,32.70018,189.54886
196.40002,32.73338,187.54173
196.60000,32.76698,185.94023
196.80000,32.80018,184.25137
197.00002,32.83351,182.72759
197.20002,32.86671,181.50931
197.40002,32.89991,180.54510
197.60000,32.93338,179.82172
197.80000,32.96684,178.91021
198.00002,33.00018,178.03244
198.20002,33.03338,176.88902
198.40002,33.06685,175.08658
198.60000,33.10031,172.00792