File: FirefighterJacket/data/instron/Specimen_RawData_3.csv
Time,Extension,Load
(sec),(mm),(N)
0.00000,-0.00013,0.00612
0.20000,0.02440,-0.11458
0.40000,0.06387,0.01726
0.60000,0.09893,-0.00864
0.80000,0.13307,-0.00649
1.00000,0.16667,-0.03173
1.20000,0.20000,-0.02066
1.40000,0.23320,0.00663
1.60000,0.26653,-0.04003
1.80000,0.29987,0.00206
2.00000,0.33307,0.04260
2.20000,0.36640,0.07194
2.40000,0.39987,0.06509
2.60000,0.43320,0.02146
2.80000,0.46667,0.10970
3.00000,0.49987,0.09350
3.20000,0.53320,0.14330
3.40000,0.56667,0.14844
3.60000,0.59973,0.09950
3.80000,0.63293,0.14805
4.00000,0.66653,0.07669
4.20000,0.70013,0.16011
4.40000,0.73333,0.18541
4.60000,0.76666,0.12156
4.80000,0.79986,0.16962
5.00000,0.83320,0.19430
5.20000,0.86640,0.21312
5.40000,0.89946,0.24624
5.60000,0.93320,0.22358
5.80000,0.96680,0.21982
6.00000,0.99986,0.22948
6.20000,1.03320,0.27824
6.40000,1.06653,0.23951
6.60000,1.09986,0.23198
6.80000,1.13306,0.25528
7.00000,1.16626,0.33775
7.20000,1.19986,0.30296
7.40000,1.23333,0.33910
7.60000,1.26653,0.33167
7.80000,1.29986,0.32798
8.00000,1.33320,0.34409
8.20000,1.36653,0.39829
8.40000,1.39960,0.37310
8.60000,1.43293,0.40014
8.80000,1.46653,0.42693
9.00000,1.50000,0.48939
9.20000,1.53320,0.44670
9.40000,1.56653,0.48757
9.60000,1.59973,0.42699
9.80000,1.63320,0.47290
10.00000,1.66626,0.48446
10.20000,1.69973,0.56698
10.40000,1.73333,0.53399
10.60000,1.76680,0.49273
10.80000,1.79986,0.60732
11.00000,1.83333,0.58263
11.20000,1.86653,0.59935
11.40000,1.89973,0.62359
11.60000,1.93306,0.67228
11.80000,1.96639,0.63487
12.00000,1.99986,0.65952
12.20000,2.03333,0.70204
12.40000,2.06653,0.75246
12.60000,2.09986,0.73054
12.80000,2.13306,0.76331
13.00000,2.16639,0.76481
13.20000,2.19959,0.80907
13.40000,2.23306,0.85114
13.60000,2.26666,0.85100
13.80000,2.30013,0.82528
14.00000,2.33333,0.86327
14.20000,2.36679,0.86842
14.40000,2.39986,0.91977
14.60000,2.43319,0.93419
14.80000,2.46639,0.92495
15.00000,2.49959,1.00083
15.20000,2.53319,1.01018
15.40000,2.56666,1.06467
15.60000,2.59986,1.04323
15.80000,2.63306,1.07369
16.00000,2.66653,1.12402
16.20000,2.69999,1.12176
16.40000,2.73306,1.10953
16.60000,2.76639,1.20772
16.80000,2.79999,1.17902
17.00000,2.83346,1.18798
17.20000,2.86653,1.22254
17.40000,2.89999,1.29653
17.60000,2.93306,1.31697
17.80000,2.96653,1.34020
18.00000,2.99973,1.33200
18.20000,3.03306,1.37926
18.40000,3.06653,1.41503
18.60000,3.09999,1.39994
18.80000,3.13319,1.44020
19.00000,3.16639,1.54031
19.20000,3.19973,1.50159
19.40000,3.23319,1.57844
19.60000,3.26639,1.57531
19.80000,3.29972,1.62056
20.00000,3.33319,1.65036
20.20000,3.36666,1.70068
20.40000,3.39986,1.73626
20.60000,3.43332,1.72727
20.80000,3.46652,1.76509
21.00000,3.49986,1.83831
21.20000,3.53306,1.83684
21.40000,3.56626,1.91615
21.60000,3.59986,1.93523
21.80000,3.63346,1.93266
22.00000,3.66652,1.96714
22.20000,3.69986,2.03242
22.40000,3.73319,2.06493
22.60000,3.76666,2.08363
22.80000,3.79959,2.12222
23.00000,3.83306,2.16927
23.20000,3.86652,2.15803
23.40000,3.90012,2.26760
23.60000,3.93332,2.28571
23.80000,3.96666,2.31528
24.00000,3.99972,2.35690
24.20000,4.03306,2.43494
24.40000,4.06639,2.52413
24.60000,4.09959,2.58342
24.80000,4.13319,2.49343
25.00000,4.16666,2.60341
25.20000,4.19986,2.64669
25.40000,4.23306,2.70232
25.60000,4.26639,2.76245
25.80000,4.29986,2.78973
26.00000,4.33292,2.85549
26.20000,4.36639,2.87780
26.40000,4.39999,2.88729
26.60000,4.43345,2.92538
26.80000,4.46652,2.88692
27.00000,4.49999,3.07115
27.20000,4.53319,3.13000
27.40000,4.56652,3.16053
27.60000,4.59972,3.22989
27.80000,4.63292,3.27439
28.00000,4.66652,3.31117
28.20000,4.69999,3.38148
28.40000,4.73305,3.45654
28.60000,4.76639,3.45612
28.80000,4.79985,3.49658
29.00000,4.83332,3.60723
29.20000,4.86639,3.66929
29.40000,4.89972,3.71865
29.60000,4.93332,3.78883
29.80000,4.96679,3.85987
30.00000,4.99985,3.91045
30.20000,5.03332,3.94398
30.40000,5.06639,4.04194
30.60000,5.09985,4.03001
30.80000,5.13305,4.07287
31.00000,5.16639,4.20042
31.20000,5.19985,4.25892
31.40000,5.23332,4.31929
31.60000,5.26652,4.34552
31.80000,5.29972,4.37524
32.00000,5.33305,4.47891
32.20000,5.36639,4.61133
32.40000,5.39972,4.69684
32.60000,5.43305,4.76233
32.80000,5.46652,4.76595
33.00000,5.50012,4.92088
33.20000,5.53319,4.95952
33.40000,5.56665,5.05374
33.60000,5.59972,5.09089
33.80000,5.63305,5.19004
34.00000,5.66639,5.26596
34.20000,5.69972,5.35277
34.40000,5.73318,5.41254
34.60000,5.76679,5.45310
34.80000,5.79972,5.63938
35.00000,5.83305,5.75548
35.20000,5.86665,5.76746
35.40000,5.89985,5.89694
35.60000,5.93305,5.99047
35.80000,5.96638,6.08110
36.00000,5.99998,6.17941
36.20000,6.03332,6.21434
36.40000,6.06652,6.30541
36.60000,6.09998,6.36849
36.80000,6.13318,6.49188
37.00000,6.16652,6.58261
37.20000,6.19985,6.72403
37.40000,6.23292,6.81050
37.60000,6.26652,6.84236
37.80000,6.29998,7.00765
38.00000,6.33318,7.07593
38.20000,6.36652,7.15562
38.40000,6.39985,7.31943
38.60000,6.43332,7.38867
38.80000,6.46638,7.51091
39.00000,6.49985,7.58574
39.20000,6.53318,7.73602
39.40000,6.56665,7.84252
39.60000,6.59998,7.92129
39.80000,6.63318,8.00922
40.00000,6.66652,8.14855
40.20000,6.69985,8.25736
40.40000,6.73318,8.39854
40.60000,6.76638,8.51397
40.80000,6.79985,8.63556
41.00000,6.83332,8.76811
41.20000,6.86665,8.90732
41.40000,6.89972,8.96866
41.60000,6.93318,9.10619
41.80000,6.96652,9.23001
42.00000,6.99972,9.33333
42.20000,7.03305,9.48102
42.40000,7.06652,9.60118
42.60000,7.09998,9.64472
42.80000,7.13318,9.89346
43.00000,7.16652,9.96192
43.20000,7.19985,10.11422
43.40000,7.23318,10.24846
43.60000,7.26638,10.38510
43.80000,7.29958,10.51331
44.00000,7.33318,10.65279
44.20000,7.36665,10.79418
44.40000,7.39985,10.96010
44.60000,7.43305,11.18530
44.80000,7.46651,11.23498
45.00000,7.49985,11.39308
45.20000,7.53305,11.46635
45.40000,7.56638,11.58412
45.60000,7.59985,11.72796
45.80000,7.63331,11.80442
46.00000,7.66678,12.00538
46.20000,7.69998,12.16494
46.40000,7.73318,12.30725
46.60000,7.76665,12.53929
46.80000,7.79971,12.54051
47.00000,7.83291,12.76388
47.20000,7.86651,12.81164
47.40000,7.90011,12.95550
47.60000,7.93318,13.13030
47.80000,7.96638,13.19701
48.00000,7.99985,13.43752
48.20000,8.03331,13.55949
48.40000,8.06638,13.74861
48.60000,8.09971,14.02472
48.80000,8.13331,14.15288
49.00000,8.16664,14.32301
49.20000,8.19984,14.47440
49.40000,8.23318,14.71383
49.60000,8.26651,14.91325
49.80000,8.29971,15.01455
50.00000,8.33305,15.23504
50.20000,8.36624,15.37349
50.40000,8.39971,15.59250
50.60000,8.43331,15.86749
50.80000,8.46651,15.99740
51.00000,8.49971,16.21392
51.20000,8.53318,16.37023
51.40000,8.56651,16.57624
51.60000,8.59958,16.81005
51.80000,8.63304,16.96469
52.00000,8.66678,17.25723
52.20000,8.69998,17.41339
52.40000,8.73331,17.64697
52.60000,8.76664,17.83282
52.80000,8.79984,17.99909
53.00000,8.83304,18.26996
53.20000,8.86638,18.45156
53.40000,8.89958,18.72724
53.60000,8.93318,19.00282
53.80000,8.96664,19.10668
54.00000,8.99998,19.40708
54.20000,9.03304,19.56911
54.40000,9.06651,19.76815
54.60000,9.09984,20.13759
54.80000,9.13291,20.26805
55.00000,9.16638,20.51341
55.20000,9.19998,20.71514
55.40000,9.23344,21.00478
55.60000,9.26638,21.27255
55.80000,9.29998,21.54555
56.00000,9.33318,21.77320
56.20000,9.36651,21.95277
56.40000,9.39971,22.19665
56.60000,9.43304,22.55702
56.80000,9.46651,22.75646
57.00000,9.50011,23.01663
57.20000,9.53318,23.23430
57.40000,9.56638,23.54398
57.60000,9.59984,23.85825
57.80000,9.63318,24.14409
58.00000,9.66637,24.40018
58.20000,9.69971,24.58140
58.40000,9.73331,24.85074
58.60000,9.76664,25.23106
58.80000,9.79984,25.46357
59.00000,9.83331,25.76372
59.20000,9.86651,26.00288
59.40000,9.89984,26.36689
59.60000,9.93304,26.70544
59.80000,9.96637,26.95246
60.00000,9.99984,27.19725
60.20000,10.03344,27.48118
60.40000,10.06651,27.88210
60.60000,10.09971,28.18098
60.80000,10.13317,28.44790
61.00000,10.16664,28.79780
61.20000,10.19984,29.01006
61.40000,10.23304,29.36077
61.60000,10.26664,29.77904
61.80000,10.30011,30.05656
62.00000,10.33331,30.37764
62.20000,10.36651,30.65417
62.40000,10.39984,30.99446
62.60000,10.43317,31.40155
62.80000,10.46637,31.61415
63.00000,10.49971,31.96062
63.20000,10.53317,32.31212
63.40000,10.56664,32.70261
63.60000,10.59971,33.10357
63.80000,10.63317,33.43808
64.00000,10.66651,33.80559
64.20000,10.69997,34.16372
64.40000,10.73304,34.52494
64.60001,10.76637,34.99474
64.80000,10.79997,35.26226
65.00000,10.83344,35.65647
65.20000,10.86664,35.99709
65.40000,10.89997,36.41817
65.60001,10.93304,36.85649
65.80000,10.96650,37.18435
66.00000,10.99997,37.55565
66.20001,11.03290,37.95939
66.40000,11.06650,38.37546
66.60001,11.09997,38.79401
66.80000,11.13330,39.12815
67.00000,11.16650,39.52641
67.20001,11.19997,39.92719
67.40000,11.23330,40.36838
67.60001,11.26624,40.85431
67.80000,11.29970,41.21235
68.00000,11.33330,41.63853
68.20001,11.36664,42.09472
68.40000,11.39997,42.41592
68.60001,11.43330,42.96621
68.80000,11.46650,43.29036
69.00000,11.49984,43.81638
69.20001,11.53304,44.22117
69.40000,11.56650,44.65217
69.60001,11.59997,45.12072
69.80000,11.63344,45.50229
70.00000,11.66664,45.93586
70.20001,11.69984,46.39505
70.40000,11.73317,46.86147
70.60001,11.76650,47.38665
70.80000,11.79970,47.81631
71.00000,11.83317,48.23254
71.20001,11.86677,48.68856
71.40000,11.90010,49.21123
71.60001,11.93317,49.70377
71.80000,11.96664,50.06767
72.00000,11.99984,50.64056
72.20001,12.03317,51.11249
72.40000,12.06650,51.49862
72.60001,12.09957,52.01462
72.80000,12.13317,52.52665
73.00000,12.16677,52.99319
73.20001,12.19983,53.50919
73.40000,12.23317,53.99110
73.60001,12.26650,54.44720
73.80000,12.29997,54.99200
74.00000,12.33317,55.52780
74.20001,12.36637,56.03582
74.40000,12.39997,56.55335
74.60001,12.43330,57.03608
74.80000,12.46663,57.53752
75.00000,12.49997,58.02942
75.20001,12.53317,58.56257
75.40000,12.56650,59.10682
75.60001,12.59970,59.60579
75.80000,12.63303,60.18082
76.00000,12.66650,60.75126
76.20001,12.70010,61.21289
76.40000,12.73317,61.81933
76.60001,12.76637,62.34022
76.80000,12.79997,62.90100
77.00000,12.83330,63.48751
77.20001,12.86637,63.99000
77.40000,12.89983,64.61282
77.60001,12.93330,65.12396
77.80000,12.96677,65.66227
78.00000,12.99997,66.27408
78.20001,13.03330,66.82990
78.40000,13.06650,67.38617
78.60001,13.09983,67.95997
78.80000,13.13317,68.55408
79.00000,13.16637,69.03658
79.20001,13.19983,69.74262
79.40000,13.23343,70.31386
79.60001,13.26650,70.88078
79.80000,13.29970,71.56474
80.00000,13.33330,72.14162
80.20001,13.36663,72.76727
80.40000,13.39957,73.33708
80.60001,13.43303,73.99036
80.80000,13.46663,74.64166
81.00001,13.49996,75.22213
81.20001,13.53316,75.87251
81.40000,13.56663,76.39706
81.60001,13.59983,77.04793
81.80000,13.63330,77.67194
82.00001,13.66650,78.04434
82.20001,13.69970,78.71971
82.40000,13.73316,79.36519
82.60001,13.76676,79.92751
82.80000,13.79983,80.62957
83.00001,13.83316,81.22444
83.20001,13.86650,81.85185
83.40000,13.89983,82.28733
83.60001,13.93303,82.82309
83.80000,13.96623,83.61936
84.00001,13.99996,84.22876
84.20001,14.03356,84.89553
84.40000,14.06663,85.57280
84.60001,14.09983,86.17909
84.80000,14.13316,86.78161
85.00001,14.16663,87.43545
85.20001,14.19983,88.17387
85.40000,14.23303,88.79514
85.60001,14.26650,89.43383
85.80000,14.30010,90.15125
86.00001,14.33316,90.69704
86.20001,14.36650,91.43853
86.40000,14.39983,92.14451
86.60001,14.43316,92.77743
86.80000,14.46636,93.50213
87.00001,14.49970,94.18063
87.20001,14.53330,94.86345
87.40000,14.56663,95.04934
87.60001,14.59996,95.70365
87.80000,14.63330,96.45180
88.00001,14.66650,97.18002
88.20001,14.69983,97.89476
88.40000,14.73303,98.64673
88.60001,14.76636,99.27365
88.80000,14.79983,100.06647
89.00001,14.83343,100.79203
89.20001,14.86663,101.53925
89.40000,14.89983,102.29218
89.60001,14.93316,102.94507
89.80000,14.96663,103.67253
90.00001,14.99970,104.37583
90.20001,15.03303,105.07359
90.40000,15.06676,105.83788
90.60001,15.10009,106.49787
90.80000,15.13329,107.25569
91.00001,15.16649,107.91282
91.20001,15.19983,108.71759
91.40000,15.23316,109.40813
91.60001,15.26636,110.05925
91.80000,15.29969,110.84779
92.00001,15.33316,111.61498
92.20001,15.36663,112.33712
92.40000,15.39996,113.06447
92.60001,15.43316,113.82381
92.80000,15.46663,114.56789
93.00001,15.49996,115.35052
93.20001,15.53303,115.93535
93.40000,15.56636,115.96136
93.60001,15.59996,116.51138
93.80000,15.63356,117.29828
94.00001,15.66662,116.97942
94.20001,15.69996,117.75713
94.40000,15.73302,118.61013
94.60001,15.76649,119.34292
94.80000,15.79982,120.13403
95.00001,15.83302,120.78587
95.20001,15.86662,121.62033
95.40000,15.90009,122.35210
95.60001,15.93342,123.02670
95.80000,15.96636,122.61751
96.00001,15.99996,123.39756
96.20001,16.03342,124.06101
96.40000,16.06636,124.75678
96.60001,16.09969,125.39766
96.80000,16.13316,126.31870
97.00001,16.16662,127.06188
97.20001,16.19996,127.90381
97.40000,16.23329,128.67221
97.60001,16.26649,129.31673
97.80000,16.29996,130.24894
98.00001,16.33302,130.97612
98.20001,16.36636,131.70344
98.40000,16.39982,132.47193
98.60001,16.43342,133.14300
98.80000,16.46649,133.95404
99.00001,16.49969,134.68062
99.20001,16.53316,135.48451
99.40000,16.56649,136.25247
99.60001,16.59969,136.89112
99.80000,16.63302,137.63086
100.00001,16.66662,138.34473
100.20001,16.70009,139.01026
100.40000,16.73316,139.46902
100.60001,16.76649,140.08048
100.80000,16.79982,140.84516
101.00001,16.83329,141.61880
101.20001,16.86649,142.33776
101.40000,16.89969,142.97669
101.60001,16.93329,143.67583
101.80000,16.96675,144.46420
102.00001,16.99982,145.20509
102.20001,17.03315,146.01781
102.40000,17.06649,146.80105
102.60001,17.09995,147.57989
102.80000,17.13302,148.35474
103.00001,17.16649,149.13065
103.20001,17.20009,149.88617
103.40000,17.23329,150.64524
103.60001,17.26675,151.39760
103.80000,17.29995,152.10479
104.00001,17.33315,152.77950
104.20001,17.36649,153.47920
104.40000,17.39969,154.07751
104.60001,17.43302,154.55827
104.80000,17.46649,155.13137
105.00001,17.49995,155.66323
105.20001,17.53329,154.33974
105.40000,17.56649,154.84002
105.60001,17.59995,155.54188
105.80000,17.63342,156.06998
106.00001,17.66635,156.86531
106.20001,17.69955,157.59951
106.40000,17.73329,158.33547
106.60001,17.76675,159.06040
106.80000,17.79995,159.78135
107.00001,17.83329,160.49253
107.20001,17.86649,161.18636
107.40000,17.89969,161.92133
107.60001,17.93302,162.60223
107.80000,17.96635,163.41856
108.00001,17.99982,164.09775
108.20001,18.03342,164.78049
108.40000,18.06662,165.44050
108.60001,18.09982,166.05055
108.80000,18.13329,166.52904
109.00001,18.16662,167.16929
109.20001,18.19969,167.82947
109.40000,18.23302,168.42909
109.60001,18.26675,169.06999
109.80000,18.30008,168.98621
110.00001,18.33315,169.58216
110.20001,18.36662,170.33231
110.40000,18.39982,170.94707
110.60001,18.43328,171.52525
110.80000,18.46635,172.20886
111.00001,18.49969,172.79772
111.20001,18.53315,173.44678
111.40000,18.56675,174.01665
111.60001,18.59982,174.46971
111.80000,18.63315,174.89113
112.00001,18.66648,175.37273
112.20001,18.69995,175.77194
112.40000,18.73288,176.17494
112.60001,18.76635,176.62395
112.80000,18.80008,177.09091
113.00001,18.83342,177.54046
113.20001,18.86662,178.03079
113.40001,18.89995,178.51066
113.60001,18.93328,178.98068
113.80000,18.96648,179.49864
114.00001,18.99968,179.88944
114.20001,19.03315,180.30735
114.40001,19.06648,180.82744
114.60001,19.10008,181.29351
114.80000,19.13315,181.55647
115.00001,19.16648,181.96348
115.20001,19.19982,182.55198
115.40001,19.23315,183.11759
115.60001,19.26622,183.76356
115.80000,19.29982,184.50513
116.00001,19.33328,185.18198
116.20001,19.36675,185.96521
116.40001,19.39995,186.74094
116.60001,19.43342,187.45573
116.80000,19.46662,188.26857
117.00001,19.49982,189.00771
117.20001,19.53302,189.90582
117.40001,19.56648,190.77862
117.60001,19.59995,191.52107
117.80000,19.63342,192.39696
118.00001,19.66648,193.20074
118.20001,19.69968,194.03916
118.40001,19.73315,194.91628
118.60001,19.76648,195.71446
118.80000,19.79968,196.52138
119.00001,19.83315,197.29700
119.20001,19.86662,198.13897
119.40001,19.90021,198.94289
119.60001,19.93328,199.62206
119.80000,19.96662,200.38867
120.00001,19.99982,201.11075
120.20001,20.03315,201.86266
120.40001,20.06635,202.59699
120.60001,20.09968,203.27481
120.80000,20.13315,204.06170
121.00001,20.16675,204.72275
121.20001,20.19995,205.49959
121.40001,20.23315,206.22702
121.60001,20.26661,206.97104
121.80000,20.29995,207.72222
122.00001,20.33315,208.34474
122.20001,20.36635,208.99933
122.40001,20.39995,209.70680
122.60001,20.43341,210.25179
122.80000,20.46661,205.16133
123.00001,20.49995,205.65184
123.20001,20.53315,205.25048
123.40001,20.56661,205.97942
123.60001,20.59981,206.86727
123.80000,20.63288,207.61933
124.00001,20.66648,208.45506
124.20001,20.70008,209.27357
124.40001,20.73315,210.14281
124.60001,20.76635,210.96578
124.80000,20.79995,211.71115
125.00001,20.83328,212.39417
125.20001,20.86635,213.20684
125.40001,20.89968,213.85049
125.60001,20.93328,214.53150
125.80000,20.96675,215.11432
126.00001,20.99995,215.66309
126.20001,21.03315,216.17511
126.40001,21.06648,216.68149
126.60001,21.09981,216.98911
126.80000,21.13301,217.35968
127.00001,21.16635,217.60993
127.20001,21.19981,217.91352
127.40001,21.23341,218.12744
127.60001,21.26648,218.25427
127.80000,21.29981,218.20540
128.00000,21.33314,218.33327
128.20002,21.36661,218.40639
128.40001,21.39981,218.65770
128.60001,21.43301,218.95209
128.80000,21.46661,219.44959
129.00000,21.50008,219.88092
129.20002,21.53314,220.34870
129.40001,21.56661,220.95559
129.60001,21.59994,221.61635
129.80000,21.63314,222.37768
130.00000,21.66648,223.05837
130.20002,21.69968,223.92109
130.40001,21.73314,224.69431
130.60001,21.76661,225.43402
130.80000,21.79994,226.20097
131.00000,21.83301,226.97318
131.20002,21.86661,227.79999
131.40002,21.89994,228.61993
131.60000,21.93288,229.34079
131.80000,21.96634,230.16322
132.00000,22.00008,230.89793
132.20002,22.03341,231.68545
132.40002,22.06661,232.41581
132.60000,22.09994,233.17069
132.80000,22.13314,233.94719
133.00000,22.16648,234.63877
133.20002,22.19968,235.33309
133.40002,22.23301,236.05255
133.60000,22.26661,236.75181
133.80000,22.29994,237.36123
134.00000,22.33314,238.03670
134.20002,22.36634,238.64293
134.40002,22.39994,239.35923
134.60000,22.43328,239.99333
134.80000,22.46634,240.63725
135.00000,22.49967,241.26982
135.20002,22.53328,241.84184
135.40002,22.56674,242.43038
135.60000,22.59994,242.93579
135.80000,22.63328,243.51263
136.00000,22.66647,244.06649
136.20002,22.69967,244.61815
136.40002,22.73314,245.20220
136.60000,22.76634,245.64531
136.80000,22.79981,246.27943
137.00000,22.83327,246.84137
137.20002,22.86661,247.34510
137.40002,22.89967,247.93191
137.60000,22.93341,248.36067
137.80000,22.96647,248.89024
138.00000,22.99967,249.42853
138.20002,23.03301,249.93099
138.40002,23.06674,250.46149
138.60000,23.10007,250.90011
138.80000,23.13314,251.30101
139.00000,23.16661,251.83577
139.20002,23.19967,252.32410
139.40002,23.23314,252.67413
139.60000,23.26647,253.07126
139.80000,23.29967,253.56652
140.00000,23.33314,253.93039
140.20002,23.36661,254.46199
140.40002,23.39994,254.72483
140.60000,23.43314,255.16540
140.80000,23.46647,255.54638
141.00000,23.49981,255.90474
141.20002,23.53301,256.20282
141.40002,23.56647,256.50876
141.60000,23.59994,256.85478
141.80000,23.63327,257.14699
142.00000,23.66661,257.35496
142.20002,23.69994,257.69997
142.40002,23.73314,257.91727
142.60000,23.76661,258.14645
142.80000,23.79980,258.39277
143.00000,23.83314,258.75844
143.20002,23.86647,259.14853
143.40002,23.89994,259.41936
143.60000,23.93327,259.79886
143.80000,23.96647,260.18197
144.00000,23.99980,260.50650
144.20002,24.03314,260.91440
144.40002,24.06634,261.21369
144.60000,24.09980,261.59490
144.80000,24.13327,261.97691
145.00000,24.16674,262.29922
145.20002,24.19980,262.66322
145.40002,24.23327,263.09513
145.60000,24.26660,263.46415
145.80000,24.29980,263.87742
146.00000,24.33314,264.33105
146.20002,24.36634,264.78864
146.40002,24.39980,265.21292
146.60000,24.43327,265.67869
146.80000,24.46647,266.14446
147.00000,24.49994,266.60485
147.20002,24.53314,266.98072
147.40002,24.56674,267.31823
147.60000,24.59967,267.64393
147.80000,24.63300,268.04334
148.00000,24.66660,268.23932
148.20002,24.69994,268.60159
148.40002,24.73327,268.56592
148.60000,24.76660,268.80775
148.80000,24.79980,268.73477
149.00000,24.83314,268.74270
149.20002,24.86634,268.73764
149.40002,24.89967,268.76142
149.60000,24.93314,268.93830
149.80000,24.96660,268.98092
150.00000,24.99994,269.12332
150.20002,25.03313,269.39632
150.40002,25.06647,269.46176
150.60000,25.09994,269.74574
150.80000,25.13313,270.00241
151.00000,25.16647,270.29594
151.20002,25.19993,270.69442
151.40002,25.23340,270.97825
151.60000,25.26660,271.37820
151.80000,25.29993,271.77285
152.00000,25.33313,272.16051
152.20002,25.36647,272.45861
152.40002,25.39967,272.77399
152.60000,25.43300,273.08010
152.80000,25.46647,273.37888
153.00000,25.50007,273.56815
153.20002,25.53313,273.77408
153.40002,25.56647,273.72358
153.60000,25.59993,273.88001
153.80000,25.63327,273.91724
154.00000,25.66633,273.97349
154.20002,25.69980,274.36515
154.40002,25.73340,274.61858
154.60000,25.76673,274.98621
154.80000,25.79993,275.39320
155.00000,25.83327,275.90847
155.20002,25.86647,276.35684
155.40002,25.89980,276.78460
155.60000,25.93300,277.36042
155.80000,25.96633,277.84776
156.00000,25.99993,278.39847
156.20002,26.03340,278.96393
156.40002,26.06647,279.50559
156.60000,26.09980,280.09098
156.80000,26.13313,280.68675
157.00000,26.16660,281.26152
157.20002,26.19966,281.77351
157.40002,26.23327,282.21371
157.60000,26.26673,282.61114
157.80000,26.30007,283.09554
158.00000,26.33327,283.43871
158.20002,26.36646,283.72949
158.40002,26.39980,284.00520
158.60000,26.43313,284.24390
158.80000,26.46633,284.30831
159.00000,26.49980,284.28907
159.20002,26.53313,284.35772
159.40002,26.56673,284.19534
159.60000,26.59980,284.03826
159.80000,26.63300,283.70451
160.00000,26.66646,283.42402
160.20002,26.69980,283.21205
160.40002,26.73286,282.86915
160.60000,26.76646,282.70205
160.80000,26.79993,282.51179
161.00002,26.83340,282.35640
161.20002,26.86660,282.34800
161.40002,26.89993,282.41100
161.60000,26.93313,282.74976
161.80000,26.96646,282.91272
162.00002,26.99966,283.26733
162.20002,27.03300,283.55110
162.40002,27.06646,283.97422
162.60000,27.10006,284.34670
162.80000,27.13326,284.69931
163.00002,27.16646,285.10461
163.20002,27.19980,285.55084
163.40002,27.23326,285.96006
163.60000,27.26646,286.47741
163.80000,27.29980,286.95004
164.00002,27.33340,287.37366
164.20002,27.36673,287.87404
164.40002,27.40006,288.32214
164.60000,27.43326,288.78909
164.80000,27.46646,289.19348
165.00002,27.49979,289.52049
165.20002,27.53300,289.90507
165.40002,27.56646,290.03084
165.60000,27.59979,290.21000
165.80000,27.63340,289.92599
166.00002,27.66646,289.59358
166.20002,27.69979,289.00942
166.40002,27.73326,288.44966
166.60000,27.76659,287.81945
166.80000,27.79979,287.18887
167.00002,27.83313,286.77968
167.20002,27.86659,286.60249
167.40002,27.90006,286.64006
167.60000,27.93326,286.85134
167.80000,27.96659,287.07905
168.00002,27.99979,287.45376
168.20002,28.03313,287.83446
168.40002,28.06633,288.28721
168.60000,28.09979,288.85081
168.80000,28.13313,289.26337
169.00002,28.16673,289.76399
169.20002,28.19979,290.29960
169.40002,28.23313,290.86011
169.60000,28.26659,291.29060
169.80000,28.29993,291.71268
170.00002,28.33299,292.06438
170.20002,28.36633,292.32521
170.40002,28.39993,292.63670
170.60000,28.43339,292.82063
170.80000,28.46659,292.80799
171.00002,28.49993,292.73354
171.20002,28.53313,292.61526
171.40002,28.56646,292.58549
171.60000,28.59966,292.65270
171.80000,28.63313,292.80171
172.00002,28.66659,293.19253
172.20002,28.70006,293.52169
172.40002,28.73326,293.92119
172.60000,28.76646,294.38326
172.80000,28.79979,294.91464
173.00002,28.83313,295.43089
173.20002,28.86633,296.00851
173.40002,28.89979,296.51826
173.60000,28.93339,297.02799
173.80000,28.96672,297.47577
174.00002,28.99979,297.92560
174.20002,29.03326,298.29631
174.40002,29.06646,298.73013
174.60000,29.09979,299.15852
174.80000,29.13312,299.50462
175.00002,29.16646,299.97608
175.20002,29.19992,300.32648
175.40002,29.23326,300.75345
175.60000,29.26646,301.15528
175.80000,29.29979,301.56411
176.00002,29.33312,301.96168
176.20002,29.36646,302.36797
176.40002,29.39966,302.77910
176.60000,29.43312,303.08595
176.80000,29.46659,303.47621
177.00002,29.50006,303.74071
177.20002,29.53326,303.96635
177.40002,29.56672,304.44911
177.60000,29.59979,304.74473
177.80000,29.63312,305.12020
178.00002,29.66632,305.41250
178.20002,29.69966,305.80088
178.40002,29.73312,306.16650
178.60000,29.76672,306.52551
178.80000,29.79979,306.82163
179.00002,29.83299,307.22899
179.20002,29.86659,307.58563
179.40002,29.89979,307.91583
179.60000,29.93299,308.19356
179.80000,29.96646,308.49539
180.00002,29.99992,308.90150
180.20002,30.03339,309.20012
180.40002,30.06659,309.47393
180.60000,30.09992,309.95961
180.80000,30.13312,310.17845
181.00002,30.16646,310.60113
181.20002,30.19979,310.88782
181.40002,30.23326,311.18056
181.60000,30.26646,311.40652
181.80000,30.30005,311.66494
182.00002,30.33312,311.96112
182.20002,30.36632,312.16757
182.40002,30.39992,312.42037
182.60000,30.43325,312.70444
182.80000,30.46632,312.88289
183.00002,30.49966,313.12104
183.20002,30.53325,313.48001
183.40002,30.56659,313.70223
183.60000,30.59979,313.93018
183.80000,30.63325,314.12348
184.00002,30.66645,314.48644
184.20002,30.69979,314.71968
184.40002,30.73312,315.00101
184.60000,30.76632,315.26309
184.80000,30.79979,315.45337
185.00002,30.83339,315.85079
185.20002,30.86645,316.18811
185.40002,30.89979,316.41584
185.60000,30.93312,316.72426
185.80000,30.96659,317.06635
186.00002,30.99965,317.26401
186.20002,31.03312,317.55205
186.40002,31.06659,317.83167
186.60000,31.10005,318.07240
186.80000,31.13325,318.29886
187.00002,31.16659,318.57483
187.20002,31.19979,318.70805
187.40002,31.23299,318.93626
187.60000,31.26632,319.16950
187.80000,31.29965,319.26807
188.00002,31.33325,319.56099
188.20002,31.36672,319.82884
188.40002,31.39992,320.04941
188.60000,31.43298,320.23318
188.80000,31.46658,320.37228
189.00002,31.49991,320.67072
189.20002,31.53311,320.78877
189.40002,31.56658,321.08948
189.60000,31.59992,321.30830
189.80000,31.63325,321.47210
190.00002,31.66658,321.73563
190.20002,31.70005,321.95274
190.40002,31.73311,322.15483
190.60000,31.76658,322.36777
190.80000,31.79978,322.46552
191.00002,31.83298,322.78165
191.20002,31.86645,322.91122
191.40002,31.90005,323.12445
191.60000,31.93325,323.42006
191.80000,31.96645,323.55156
192.00002,31.99978,323.82675
192.20002,32.03325,324.10342
192.40002,32.06632,324.42123
192.60000,32.09965,324.57076
192.80000,32.13338,324.72752
193.00002,32.16672,324.94605
193.20002,32.20005,325.16837
193.40002,32.23325,325.34637
193.60000,32.26645,325.52924
193.80000,32.29978,325.67192
194.00002,32.33285,325.80055
194.20002,32.36631,326.10264
194.40002,32.39978,326.35812
194.60000,32.43325,326.61140
194.80000,32.46645,326.72845
195.00002,32.49965,326.97953
195.20002,32.53325,327.30088
195.40002,32.56658,327.44952
195.60000,32.59978,327.69043
195.80000,32.63311,327.90184
196.00002,32.66671,328.12152
196.20002,32.70005,328.24203
196.40002,32.73325,328.44268
196.60000,32.76658,328.59441
196.80000,32.79978,328.72155
197.00002,32.83311,328.86259
197.20002,32.86645,329.01492
197.40002,32.89965,329.20115
197.60000,32.93325,329.36156
197.80000,32.96671,329.45227
198.00002,32.99991,329.66252
198.20002,33.03311,329.84771
198.40002,33.06658,330.04053
198.60000,33.09991,330.29702
198.80000,33.13311,320.14877
199.00002,33.16645,320.37590
199.20002,33.20004,320.64844
199.40002,33.23324,320.99612
199.60000,33.26658,321.32138
199.80000,33.29978,321.44427
200.00002,33.33325,321.68780
200.20002,33.36658,310.81827
200.40002,33.39978,309.51463
200.60000,33.43311,308.76424
200.80000,33.46671,300.21384
201.00002,33.50005,299.68338
201.20002,33.53311,299.35572
201.40002,33.56631,299.31081
201.60000,33.59991,299.46620
201.80000,33.63311,299.35390
202.00002,33.66631,298.60603
202.20002,33.69978,296.26869
202.40002,33.73324,294.41269
202.60000,33.76671,279.89693
202.80000,33.80004,231.33757
203.00002,33.83338,226.17899
203.20002,33.86658,223.12684
203.40002,33.89991,211.33278
203.60000,33.93311,209.63119
203.80000,33.96631,206.23771
204.00002,33.99991,204.28501
204.20002,34.03338,202.44846
204.40002,34.06644,202.00441
204.60000,34.09978,201.69878
204.80000,34.13311,201.79998
205.00002,34.16658,202.18888
205.20002,34.19978,202.58637
205.40002,34.23311,203.11315
205.60000,34.26658,200.69316
205.80000,34.30004,200.12757
206.00002,34.33337,199.56628
206.20002,34.36658,198.37465
206.21000,34.36818,198.17403