File: FirefighterJacket/data/instron/Specimen_RawData_5.csv
Time,Extension,Load
(sec),(mm),(N)
0.00000,0.00000,0.10564
0.20000,0.02800,-0.00217
0.40000,0.06520,0.06522
0.60000,0.09973,0.04456
0.80000,0.13333,0.07988
1.00000,0.16653,0.12086
1.20000,0.19987,0.16062
1.40000,0.23347,0.12719
1.60000,0.26707,0.14466
1.80000,0.30000,0.17785
2.00000,0.33347,0.19888
2.20000,0.36667,0.25989
2.40000,0.40013,0.19965
2.60000,0.43320,0.22228
2.80000,0.46667,0.25829
3.00000,0.50027,0.28849
3.20000,0.53360,0.24442
3.40000,0.56680,0.34959
3.60000,0.60000,0.23397
3.80000,0.63333,0.32282
4.00000,0.66680,0.35840
4.20000,0.70000,0.34390
4.40000,0.73333,0.38332
4.60000,0.76680,0.29053
4.80000,0.80040,0.36184
5.00000,0.83346,0.41879
5.20000,0.86666,0.41137
5.40000,0.90000,0.45817
5.60000,0.93346,0.38420
5.80000,0.96653,0.40987
6.00000,1.00013,0.42281
6.20000,1.03360,0.39911
6.40000,1.06706,0.50865
6.60000,1.10013,0.41913
6.80000,1.13346,0.46249
7.00000,1.16666,0.53074
7.20000,1.20013,0.48477
7.40000,1.23333,0.52953
7.60000,1.26666,0.46249
7.80000,1.30013,0.56413
8.00000,1.33373,0.55063
8.20000,1.36666,0.53394
8.40000,1.40000,0.55132
8.60000,1.43333,0.55057
8.80000,1.46680,0.55139
9.00000,1.49986,0.57398
9.20000,1.53333,0.55121
9.40000,1.56706,0.59078
9.60000,1.60026,0.57720
9.80000,1.63360,0.66422
10.00000,1.66693,0.65241
10.20000,1.70013,0.61700
10.40000,1.73346,0.68651
10.60000,1.76653,0.72417
10.80000,1.80000,0.67783
11.00000,1.83346,0.69402
11.20000,1.86693,0.69869
11.40000,1.90000,0.71600
11.60000,1.93320,0.63761
11.80000,1.96693,0.73868
12.00000,2.00013,0.78765
12.20000,2.03319,0.76693
12.40000,2.06679,0.76949
12.60000,2.10026,0.75063
12.80000,2.13373,0.78648
13.00000,2.16679,0.83893
13.20000,2.20013,0.74917
13.40000,2.23333,0.80946
13.60000,2.26679,0.81784
13.80000,2.30013,0.87074
14.00000,2.33333,0.87135
14.20000,2.36679,0.82386
14.40000,2.40039,0.90158
14.60000,2.43333,0.86789
14.80000,2.46666,0.90828
15.00000,2.49999,0.95977
15.20000,2.53346,0.88947
15.40000,2.56653,0.96622
15.60000,2.60013,0.98028
15.80000,2.63359,0.94319
16.00000,2.66693,0.97893
16.20000,2.70013,1.02014
16.40000,2.73346,1.02681
16.60000,2.76666,0.99944
16.80000,2.80013,0.99206
17.00000,2.83333,1.06685
17.20000,2.86666,1.08191
17.40000,2.90013,1.05150
17.60000,2.93359,1.11310
17.80000,2.96679,1.13787
18.00000,3.00013,1.13636
18.20000,3.03346,1.14449
18.40000,3.06693,1.15142
18.60000,3.09973,1.13133
18.80000,3.13333,1.21069
19.00000,3.16693,1.21903
19.20000,3.20026,1.16490
19.40000,3.23332,1.18084
19.60000,3.26679,1.22631
19.80000,3.30012,1.20733
20.00000,3.33346,1.28791
20.20000,3.36666,1.32246
20.40000,3.39999,1.30955
20.60000,3.43359,1.28043
20.80000,3.46706,1.29390
21.00000,3.50012,1.31127
21.20000,3.53319,1.43893
21.40000,3.56679,1.35882
21.60000,3.60026,1.35177
21.80000,3.63332,1.42801
22.00000,3.66666,1.48032
22.20000,3.70039,1.45257
22.40000,3.73359,1.45211
22.60000,3.76666,1.42971
22.80000,3.80012,1.51075
23.00000,3.83332,1.48988
23.20000,3.86692,1.52010
23.40000,3.89999,1.56974
23.60000,3.93332,1.46695
23.80000,3.96679,1.59185
24.00000,4.00026,1.62047
24.20000,4.03346,1.59391
24.40000,4.06666,1.62937
24.60000,4.10012,1.63034
24.80000,4.13359,1.67312
25.00000,4.16652,1.67999
25.20000,4.19999,1.71402
25.40000,4.23359,1.64895
25.60000,4.26692,1.70467
25.80000,4.30026,1.74876
26.00000,4.33346,1.75140
26.20000,4.36679,1.80107
26.40000,4.39999,1.83490
26.60000,4.43332,1.79339
26.80000,4.46665,1.82508
27.00000,4.50012,1.79456
27.20000,4.53372,1.92630
27.40000,4.56679,1.86400
27.60000,4.59999,1.85386
27.80000,4.63332,1.95771
28.00000,4.66665,1.91396
28.20000,4.69985,1.95888
28.40000,4.73332,1.97778
28.60000,4.76692,1.97426
28.80000,4.80039,2.04014
29.00000,4.83345,2.03917
29.20000,4.86679,2.07672
29.40000,4.89999,2.11536
29.60000,4.93345,2.08302
29.80000,4.96679,2.13122
30.00000,4.99985,2.16958
30.20000,5.03345,2.15660
30.40000,5.06692,2.14865
30.60000,5.09999,2.19386
30.80000,5.13319,2.24329
31.00000,5.16692,2.24592
31.20000,5.20012,2.26232
31.40000,5.23319,2.25749
31.60000,5.26665,2.28067
31.80000,5.30025,2.33923
32.00000,5.33359,2.31258
32.20000,5.36665,2.27574
32.40000,5.39999,2.40103
32.60000,5.43345,2.36540
32.80000,5.46692,2.41546
33.00000,5.50012,2.47102
33.20000,5.53332,2.45418
33.40000,5.56679,2.51662
33.60000,5.60025,2.53551
33.80000,5.63359,2.59044
34.00000,5.66665,2.59282
34.20000,5.69999,2.65442
34.40000,5.73332,2.58767
34.60000,5.76652,2.64072
34.80000,5.80012,2.64255
35.00000,5.83345,2.66431
35.20000,5.86692,2.68938
35.40000,5.90012,2.74218
35.60000,5.93345,2.78805
35.80000,5.96678,2.79810
36.00000,6.00025,2.75496
36.20000,6.03332,2.80746
36.40000,6.06665,2.92727
36.60000,6.10025,2.87286
36.80000,6.13372,2.92697
37.00000,6.16678,2.95677
37.20000,6.19998,2.95676
37.40000,6.23332,2.95646
37.60000,6.26665,3.01363
37.80000,6.29998,3.04225
38.00000,6.33332,3.12114
38.20000,6.36692,3.09590
38.40000,6.40025,3.13900
38.60000,6.43345,3.14184
38.80000,6.46678,3.18430
39.00000,6.49998,3.18668
39.20000,6.53345,3.22656
39.40000,6.56665,3.24533
39.60000,6.59998,3.34983
39.80000,6.63345,3.37655
40.00000,6.66692,3.35334
40.20000,6.70012,3.39829
40.40000,6.73332,3.42198
40.60000,6.76692,3.42470
40.80000,6.80012,3.48836
41.00000,6.83318,3.45735
41.20000,6.86665,3.54285
41.40000,6.90025,3.50927
41.60000,6.93358,3.53209
41.80000,6.96692,3.62009
42.00000,6.99998,3.60416
42.20000,7.03345,3.60339
42.40000,7.06692,3.70708
42.60000,7.09998,3.75114
42.80000,7.13331,3.79279
43.00000,7.16665,3.79009
43.20000,7.20038,3.80699
43.40000,7.23345,3.88111
43.60000,7.26665,3.86903
43.80000,7.30025,3.93732
44.00000,7.33345,3.94032
44.20000,7.36665,4.00354
44.40000,7.39998,4.03439
44.60000,7.43358,4.00536
44.80000,7.46705,4.10008
45.00000,7.50011,4.11972
45.20000,7.53345,4.14910
45.40000,7.56665,4.17404
45.60000,7.60025,4.24041
45.80000,7.63345,4.23065
46.00000,7.66665,4.29644
46.20000,7.70011,4.30909
46.40000,7.73358,4.31282
46.60000,7.76678,4.37377
46.80000,7.79998,4.46254
47.00000,7.83331,4.47284
47.20000,7.86678,4.49479
47.40000,7.89985,4.55310
47.60000,7.93331,4.56418
47.80000,7.96705,4.59300
48.00000,8.00025,4.64021
48.20000,8.03345,4.69704
48.40000,8.06678,4.75154
48.60000,8.10011,4.76850
48.80000,8.13344,4.82478
49.00000,8.16664,4.85126
49.20000,8.19998,4.95156
49.40000,8.23344,4.94091
49.60000,8.26691,4.92549
49.80000,8.30011,4.97924
50.00000,8.33331,5.03584
50.20000,8.36678,5.11389
50.40000,8.40011,5.12251
50.60000,8.43318,5.08481
50.80000,8.46664,5.20995
51.00000,8.50038,5.27812
51.20000,8.53358,5.25106
51.40000,8.56664,5.35022
51.60000,8.60011,5.36117
51.80000,8.63344,5.41933
52.00000,8.66678,5.46301
52.20000,8.69998,5.51885
52.40000,8.73331,5.54572
52.60000,8.76678,5.52821
52.80000,8.80024,5.63927
53.00000,8.83331,5.66120
53.20000,8.86651,5.77198
53.40000,8.89998,5.80065
53.60000,8.93344,5.78745
53.80000,8.96651,5.86708
54.00000,9.00011,5.94878
54.20000,9.03371,5.98093
54.40000,9.06691,5.99773
54.60000,9.09998,6.03438
54.80000,9.13344,6.06086
55.00000,9.16678,6.15793
55.20000,9.20024,6.20345
55.40000,9.23331,6.18499
55.60000,9.26664,6.27264
55.80000,9.30024,6.38324
56.00000,9.33371,6.37032
56.20000,9.36678,6.39810
56.40000,9.39998,6.48393
56.60000,9.43344,6.49887
56.80000,9.46691,6.62361
57.00000,9.49984,6.61173
57.20000,9.53344,6.63529
57.40000,9.56691,6.72925
57.60000,9.60024,6.78441
57.80000,9.63344,6.82486
58.00000,9.66677,6.89813
58.20000,9.70011,6.95681
58.40000,9.73344,6.94035
58.60000,9.76664,6.97951
58.80000,9.79997,7.15833
59.00000,9.83357,7.14822
59.20000,9.86704,7.16079
59.40000,9.90011,7.27534
59.60000,9.93331,7.31222
59.80000,9.96677,7.40963
60.00000,10.00011,7.45537
60.20000,10.03331,7.53524
60.40000,10.06664,7.50908
60.60000,10.10011,7.54636
60.80000,10.13357,7.65047
61.00000,10.16677,7.72473
61.20000,10.20011,7.69067
61.40000,10.23331,7.84881
61.60000,10.26691,7.87454
61.80000,10.29997,7.89241
62.00000,10.33331,8.04365
62.20000,10.36677,7.96532
62.40000,10.40024,8.00954
62.60000,10.43344,8.12498
62.80000,10.46664,8.19138
63.00000,10.50024,8.28805
63.20000,10.53344,8.32666
63.40000,10.56651,8.35129
63.60000,10.60011,8.43782
63.80000,10.63357,8.52669
64.00000,10.66691,8.60419
64.20000,10.70011,8.66737
64.40000,10.73344,8.70669
64.60001,10.76677,8.78531
64.80000,10.80011,8.84000
65.00000,10.83344,8.96731
65.20000,10.86677,9.00202
65.40000,10.90024,8.95111
65.60001,10.93384,9.04159
65.80000,10.96677,9.12962
66.00000,10.99997,9.23457
66.20001,11.03330,9.24950
66.40000,11.06677,9.33042
66.60001,11.09984,9.43069
66.80000,11.13344,9.56027
67.00000,11.16704,9.65420
67.20001,11.20024,9.68032
67.40000,11.23344,9.82775
67.60001,11.26677,9.77048
67.80000,11.30010,9.91893
68.00000,11.33357,9.98109
68.20001,11.36664,10.02827
68.40000,11.39984,10.10913
68.60001,11.43344,10.23330
68.80000,11.46704,10.23233
69.00000,11.49997,10.33378
69.20001,11.53330,10.39613
69.40000,11.56664,10.47265
69.60001,11.60024,10.59032
69.80000,11.63317,10.63979
70.00000,11.66677,10.78961
70.20001,11.70024,10.81548
70.40000,11.73370,10.81816
70.60001,11.76677,11.04073
70.80000,11.80010,11.06210
71.00000,11.83344,11.16973
71.20001,11.86677,11.20839
71.40000,11.89997,11.26562
71.60001,11.93330,11.43081
71.80000,11.96677,11.44597
72.00000,12.00024,11.62806
72.20001,12.03330,11.68369
72.40000,12.06650,11.74408
72.60001,12.10024,11.96755
72.80000,12.13344,11.89634
73.00000,12.16650,12.01263
73.20001,12.19997,12.18450
73.40000,12.23357,12.14070
73.60001,12.26703,12.39164
73.80000,12.30010,12.38172
74.00000,12.33344,12.44888
74.20001,12.36677,12.56980
74.40000,12.40010,12.61473
74.60001,12.43330,12.81604
74.80000,12.46663,12.85953
75.00000,12.50010,13.00431
75.20001,12.53357,13.02535
75.40000,12.56677,13.08919
75.60001,12.59997,13.31268
75.80000,12.63343,13.37922
76.00000,12.66677,13.49646
76.20001,12.69983,13.60158
76.40000,12.73330,13.64178
76.60001,12.76690,13.79174
76.80000,12.80023,13.88955
77.00000,12.83330,13.99326
77.20001,12.86677,14.10112
77.40000,12.89997,14.20113
77.60001,12.93357,14.36443
77.80000,12.96663,14.38412
78.00000,12.99997,14.54811
78.20001,13.03343,14.60353
78.40000,13.06703,14.70651
78.60001,13.10010,14.90619
78.80000,13.13330,14.93542
79.00000,13.16690,15.05441
79.20001,13.19997,15.17603
79.40000,13.23317,15.25398
79.60001,13.26663,15.45453
79.80000,13.30023,15.50820
80.00000,13.33357,15.74995
80.20001,13.36677,15.72189
80.40000,13.40010,15.93390
80.60001,13.43343,16.04651
80.80000,13.46677,16.10262
81.00001,13.49996,16.30244
81.20001,13.53330,16.32648
81.40000,13.56677,16.51170
81.60001,13.60037,16.67250
81.80000,13.63343,16.77503
82.00001,13.66663,16.86294
82.20001,13.69996,17.00426
82.40000,13.73343,17.12862
82.60001,13.76650,17.27868
82.80000,13.80010,17.33645
83.00001,13.83370,17.48190
83.20001,13.86690,17.50991
83.40000,13.90010,17.69253
83.60001,13.93343,17.91429
83.80000,13.96676,17.97231
84.00001,14.00010,18.18493
84.20001,14.03330,18.22789
84.40000,14.06663,18.35957
84.60001,14.10023,18.51313
84.80000,14.13356,18.67648
85.00001,14.16676,18.83937
85.20001,14.20010,18.95739
85.40000,14.23343,19.11757
85.60001,14.26690,19.27748
85.80000,14.29983,19.35937
86.00001,14.33343,19.57075
86.20001,14.36703,19.70641
86.40000,14.40036,19.86521
86.60001,14.43356,20.02328
86.80000,14.46676,20.12565
87.00001,14.50010,20.27501
87.20001,14.53330,20.38159
87.40000,14.56663,20.57995
87.60001,14.59996,20.82966
87.80000,14.63343,20.84801
88.00001,14.66703,21.02232
88.20001,14.70010,21.17330
88.40000,14.73330,21.34877
88.60001,14.76676,21.55750
88.80000,14.80023,21.65360
89.00001,14.83329,21.80634
89.20001,14.86676,21.98748
89.40000,14.90036,22.13243
89.60001,14.93356,22.38045
89.80000,14.96676,22.49278
90.00001,14.99996,22.67103
90.20001,15.03343,22.76509
90.40000,15.06689,22.96217
90.60001,15.10009,23.19897
90.80000,15.13329,23.27999
91.00001,15.16689,23.47369
91.20001,15.20036,23.64621
91.40000,15.23343,23.80845
91.60001,15.26663,24.01357
91.80000,15.30023,24.15445
92.00001,15.33356,24.36653
92.20001,15.36649,24.48294
92.40000,15.40009,24.70045
92.60001,15.43356,24.91545
92.80000,15.46689,25.03312
93.00001,15.50023,25.20784
93.20001,15.53343,25.33797
93.40000,15.56676,25.61836
93.60001,15.60023,25.78307
93.80000,15.63329,25.88180
94.00001,15.66662,26.13639
94.20001,15.70022,26.30146
94.40000,15.73369,26.48018
94.60001,15.76676,26.73535
94.80000,15.79996,26.88413
95.00001,15.83356,27.04999
95.20001,15.86676,27.20051
95.40000,15.89982,27.42481
95.60001,15.93329,27.70422
95.80000,15.96702,27.81965
96.00001,16.00036,28.04439
96.20001,16.03342,28.18872
96.40000,16.06676,28.39606
96.60001,16.10009,28.64957
96.80000,16.13342,28.70422
97.00001,16.16662,28.95159
97.20001,16.19996,29.10838
97.40000,16.23356,29.30922
97.60001,16.26702,29.60395
97.80000,16.30009,29.73443
98.00001,16.33329,29.90251
98.20001,16.36676,30.05052
98.40000,16.40022,30.27742
98.60001,16.43316,30.55633
98.80000,16.46676,30.59293
99.00001,16.50022,30.91807
99.20001,16.53369,31.05512
99.40000,16.56689,31.22621
99.60001,16.60009,31.54144
99.80000,16.63342,31.63471
100.00001,16.66689,31.90533
100.20001,16.69996,32.10171
100.40000,16.73329,32.25432
100.60001,16.76675,32.60915
100.80000,16.80036,32.69085
101.00001,16.83355,32.89933
101.20001,16.86675,33.12574
101.40000,16.90022,33.35439
101.60001,16.93355,33.57716
101.80000,16.96649,33.68855
102.00001,16.99995,33.99092
102.20001,17.03355,34.23680
102.40000,17.06702,34.44346
102.60001,17.10009,34.67375
102.80000,17.13342,34.85684
103.00001,17.16675,35.09426
103.20001,17.20009,35.30648
103.40000,17.23329,35.53134
103.60001,17.26662,35.81719
103.80000,17.30022,35.89703
104.00001,17.33369,36.21778
104.20001,17.36675,36.46204
104.40000,17.40009,36.67520
104.60001,17.43355,37.03141
104.80000,17.46675,37.19776
105.00001,17.49995,37.40299
105.20001,17.53342,37.62047
105.40000,17.56702,37.94212
105.60001,17.60022,38.18969
105.80000,17.63342,38.34662
106.00001,17.66662,38.60402
106.20001,17.70009,38.87297
106.40000,17.73355,39.09857
106.60001,17.76662,39.38720
106.80000,17.79995,39.54425
107.00001,17.83342,39.84366
107.20001,17.86702,40.12377
107.40000,17.90009,40.29964
107.60001,17.93329,40.66924
107.80000,17.96675,40.84865
108.00001,18.00009,41.13358
108.20001,18.03315,41.38556
108.40000,18.06675,41.66688
108.60001,18.10022,41.90033
108.80000,18.13368,42.13294
109.00001,18.16675,42.42711
109.20001,18.20008,42.67845
109.40000,18.23355,42.94405
109.60001,18.26675,43.27032
109.80000,18.29995,43.45268
110.00001,18.33329,43.78982
110.20001,18.36675,43.99516
110.40000,18.40035,44.22281
110.60001,18.43342,44.55506
110.80000,18.46662,44.77690
111.00001,18.49995,45.11628
111.20001,18.53328,45.37661
111.40000,18.56649,45.60735
111.60001,18.60008,45.93226
111.80000,18.63368,46.14639
112.00001,18.66688,46.46569
112.20001,18.70022,46.64662
112.40000,18.73355,46.97700
112.60001,18.76688,47.29613
112.80000,18.80022,47.47167
113.00001,18.83342,47.76915
113.20001,18.86662,48.03016
113.40001,18.90035,48.34105
113.60001,18.93355,48.64176
113.80000,18.96688,48.83697
114.00001,18.99995,49.14463
114.20001,19.03355,49.41119
114.40001,19.06688,49.73121
114.60001,19.09982,49.97104
114.80000,19.13342,50.21297
115.00001,19.16702,50.54097
115.20001,19.20035,50.87354
115.40001,19.23342,51.07549
115.60001,19.26675,51.41990
115.80000,19.30022,51.71632
116.00001,19.33355,51.97654
116.20001,19.36662,52.21958
116.40001,19.40008,52.45133
116.60001,19.43355,52.82695
116.80000,19.46701,53.08105
117.00001,19.49995,53.36838
117.20001,19.53328,53.64313
117.40001,19.56688,53.96727
117.60001,19.60021,54.25400
117.80000,19.63328,54.51781
118.00001,19.66662,54.83779
118.20001,19.70035,55.08292
118.40001,19.73355,55.32993
118.60001,19.76688,55.70530
118.80000,19.80008,55.99171
119.00001,19.83341,56.23355
119.20001,19.86688,56.48972
119.40001,19.90008,56.73072
119.60001,19.93328,56.98737
119.80000,19.96688,57.25144
120.00001,20.00021,57.44343
120.20001,20.03341,57.69115
120.40001,20.06661,58.00817
120.60001,20.10021,58.17339
120.80000,20.13355,58.36608
121.00001,20.16648,58.59039
121.20001,20.20008,58.80768
121.40001,20.23368,59.00337
121.60001,20.26688,59.29684
121.80000,20.30008,59.47816
122.00001,20.33341,59.68958
122.20001,20.36675,59.84175
122.40001,20.40021,60.02108
122.60001,20.43341,60.33304
122.80000,20.46661,60.50922
123.00001,20.50008,60.81714
123.20001,20.53368,61.04311
123.40001,20.56675,61.22902
123.60001,20.59995,61.56520
123.80000,20.63341,61.80834
124.00001,20.66688,62.02559
124.20001,20.69995,62.20546
124.40001,20.73341,62.55142
124.60001,20.76688,62.79189
124.80000,20.80021,63.06580
125.00001,20.83341,63.31228
125.20001,20.86675,63.50667
125.40001,20.90021,63.68502
125.60001,20.93341,63.97148
125.80000,20.96661,64.21012
126.00001,21.00008,64.48699
126.20001,21.03368,64.81203
126.40001,21.06701,65.10654
126.60001,21.10008,65.47434
126.80000,21.13328,65.73652
127.00001,21.16675,66.12386
127.20001,21.20008,66.41003
127.40001,21.23315,66.71094
127.60001,21.26675,67.02680
127.80000,21.30021,67.33357
128.00000,21.33354,67.64916
128.20002,21.36688,67.89102
128.40001,21.40008,68.22617
128.60001,21.43341,68.51311
128.80000,21.46674,68.74536
129.00000,21.49994,69.01423
129.20002,21.53341,69.31787
129.40001,21.56688,69.65408
129.60001,21.60034,70.01172
129.80000,21.63341,70.29328
130.00000,21.66661,70.62627
130.20002,21.70008,70.94298
130.40001,21.73341,71.29416
130.60001,21.76648,71.60240
130.80000,21.80008,71.82566
131.00000,21.83354,72.22471
131.20002,21.86701,72.43280
131.40002,21.90008,72.82097
131.60000,21.93341,73.06917
131.80000,21.96674,73.39034
132.00000,22.00008,73.78784
132.20002,22.03341,73.98532
132.40002,22.06661,74.30526
132.60000,22.10008,74.69464
132.80000,22.13368,75.09948
133.00000,22.16674,75.44606
133.20002,22.19994,75.62433
133.40002,22.23354,76.09361
133.60000,22.26674,76.38945
133.80000,22.29981,76.64539
134.00000,22.33328,76.98762
134.20002,22.36701,77.30922
134.40002,22.40021,77.69044
134.60000,22.43354,78.01583
134.80000,22.46674,78.31577
135.00000,22.49994,78.63050
135.20002,22.53368,78.94302
135.40002,22.56674,79.22273
135.60000,22.60008,79.62164
135.80000,22.63354,79.90938
136.00000,22.66701,80.33675
136.20002,22.70008,80.59763
136.40002,22.73327,81.00833
136.60000,22.76674,81.36478
136.80000,22.80007,81.68523
137.00000,22.83327,81.99763
137.20002,22.86687,82.32154
137.40002,22.90021,82.75088
137.60000,22.93354,83.06167
137.80000,22.96674,83.29825
138.00000,23.00007,83.74780
138.20002,23.03341,84.00598
138.40002,23.06687,84.40438
138.60000,23.10007,84.75858
138.80000,23.13327,85.07809
139.00000,23.16674,85.45265
139.20002,23.20034,85.78466
139.40002,23.23341,86.20563
139.60000,23.26674,86.58388
139.80000,23.30021,86.93415
140.00000,23.33341,87.26040
140.20002,23.36647,87.55811
140.40002,23.40007,87.94075
140.60000,23.43367,88.22921
140.80000,23.46701,88.60399
141.00000,23.50021,88.95534
141.20002,23.53354,89.29491
141.40002,23.56674,89.60682
141.60000,23.60021,89.96390
141.80000,23.63327,90.33288
142.00000,23.66661,90.65819
142.20002,23.70021,90.95797
142.40002,23.73367,91.31365
142.60000,23.76674,91.64942
142.80000,23.80007,91.96914
143.00000,23.83341,92.29243
143.20002,23.86687,92.57514
143.40002,23.89980,92.92028
143.60000,23.93341,93.27107
143.80000,23.96687,93.58844
144.00000,24.00021,94.02397
144.20002,24.03354,94.34511
144.40002,24.06674,94.68914
144.60000,24.10007,95.03009
144.80000,24.13354,95.44679
145.00000,24.16660,95.72914
145.20002,24.19994,96.15295
145.40002,24.23340,96.49161
145.60000,24.26700,96.77896
145.80000,24.29994,97.07730
146.00000,24.33340,97.50156
146.20002,24.36687,97.82517
146.40002,24.40020,98.19663
146.60000,24.43327,98.48501
146.80000,24.46674,98.65422
147.00000,24.50020,99.01831
147.20002,24.53354,99.31537
147.40002,24.56674,99.64699
147.60000,24.60007,99.96345
147.80000,24.63327,100.21350
148.00000,24.66674,100.62238
148.20002,24.69994,100.96078
148.40002,24.73340,101.31888
148.60000,24.76687,101.60036
148.80000,24.80034,101.96662
149.00000,24.83340,102.22128
149.20002,24.86674,102.57011
149.40002,24.90007,102.85717
149.60000,24.93354,103.25796
149.80000,24.96647,103.56981
150.00000,25.00007,103.89180
150.20002,25.03367,104.21645
150.40002,25.06700,104.59203
150.60000,25.10020,104.92411
150.80000,25.13340,105.23321
151.00000,25.16674,105.63049
151.20002,25.20007,105.90289
151.40002,25.23327,106.33541
151.60000,25.26673,106.70286
151.80000,25.30020,107.04386
152.00000,25.33367,107.44034
152.20002,25.36673,107.79363
152.40002,25.39993,108.18680
152.60000,25.43340,108.53968
152.80000,25.46687,108.90456
153.00000,25.49993,109.27273
153.20002,25.53353,109.61708
153.40002,25.56700,109.98150
153.60000,25.60020,110.31295
153.80000,25.63340,110.62705
154.00000,25.66673,111.04843
154.20002,25.70007,111.31396
154.40002,25.73353,111.67598
154.60000,25.76660,111.96932
154.80000,25.79993,112.30194
155.00000,25.83353,112.59953
155.20002,25.86700,113.04629
155.40002,25.90007,113.28566
155.60000,25.93327,113.64826
155.80000,25.96673,113.94904
156.00000,26.00007,114.40273
156.20002,26.03313,114.74816
156.40002,26.06660,115.06466
156.60000,26.10033,115.39333
156.80000,26.13353,115.71161
157.00000,26.16687,116.08133
157.20002,26.20020,116.45076
157.40002,26.23327,116.71554
157.60000,26.26687,117.12996
157.80000,26.29993,117.47523
158.00000,26.33340,117.81416
158.20002,26.36687,118.15128
158.40002,26.40033,118.44497
158.60000,26.43340,118.83305
158.80000,26.46660,119.11469
159.00000,26.50020,119.49635
159.20002,26.53353,119.86122
159.40002,26.56660,120.18863
159.60000,26.60020,120.44244
159.80000,26.63353,120.79228
160.00000,26.66700,121.21829
160.20002,26.70020,121.40967
160.40002,26.73326,121.67237
160.60000,26.76673,122.06245
160.80000,26.80020,122.30280
161.00002,26.83326,122.64449
161.20002,26.86673,122.92914
161.40002,26.90020,123.25824
161.60000,26.93366,123.57777
161.80000,26.96673,123.93624
162.00002,27.00006,124.19980
162.20002,27.03353,124.53454
162.40002,27.06686,124.98123
162.60000,27.09993,125.27249
162.80000,27.13340,125.58258
163.00002,27.16700,125.91626
163.20002,27.20033,126.16937
163.40002,27.23353,126.44281
163.60000,27.26686,126.69554
163.80000,27.30006,126.94712
164.00002,27.33353,127.22205
164.20002,27.36673,127.52212
164.40002,27.39993,127.66892
164.60000,27.43340,127.91052
164.80000,27.46700,128.11908
165.00002,27.50020,128.43001
165.20002,27.53340,128.67066
165.40002,27.56673,128.92921
165.60000,27.60006,129.22660
165.80000,27.63326,129.51271
166.00002,27.66673,129.78272
166.20002,27.70020,130.08190
166.40002,27.73366,130.48086
166.60000,27.76673,130.71752
166.80000,27.80006,131.12786
167.00002,27.83339,131.46694
167.20002,27.86686,131.73642
167.40002,27.89993,132.08023
167.60000,27.93339,132.41911
167.80000,27.96686,132.63711
168.00002,28.00033,133.08360
168.20002,28.03339,133.37180
168.40002,28.06659,133.62559
168.60000,28.10006,134.03959
168.80000,28.13339,134.32268
169.00002,28.16659,134.74368
169.20002,28.19993,134.94430
169.40002,28.23366,135.35606
169.60000,28.26699,135.58116
169.80000,28.30006,135.90943
170.00002,28.33353,136.27642
170.20002,28.36659,136.64746
170.40002,28.40019,136.94016
170.60000,28.43339,137.23234
170.80000,28.46673,137.62218
171.00002,28.50019,137.83631
171.20002,28.53366,138.16235
171.40002,28.56673,138.41773
171.60000,28.59993,138.74274
171.80000,28.63326,139.12715
172.00002,28.66673,139.43587
172.20002,28.69993,139.73757
172.40002,28.73326,139.96700
172.60000,28.76686,140.26190
172.80000,28.80019,140.65023
173.00002,28.83353,140.93000
173.20002,28.86673,141.26523
173.40002,28.90006,141.58408
173.60000,28.93339,141.91650
173.80000,28.96659,142.27109
174.00002,28.99992,142.64235
174.20002,29.03352,143.00745
174.40002,29.06699,143.28957
174.60000,29.10006,143.68500
174.80000,29.13326,144.03820
175.00002,29.16686,144.43501
175.20002,29.20019,144.74696
175.40002,29.23312,145.12142
175.60000,29.26672,145.39340
175.80000,29.30019,145.76841
176.00002,29.33366,146.12076
176.20002,29.36686,146.42728
176.40002,29.40006,146.78821
176.60000,29.43339,147.08990
176.80000,29.46686,147.38500
177.00002,29.50006,147.67486
177.20002,29.53326,147.97028
177.40002,29.56672,148.22855
177.60000,29.60032,148.49504
177.80000,29.63339,148.78931
178.00002,29.66659,149.08889
178.20002,29.70019,149.34195
178.40002,29.73352,149.62479
178.60000,29.76646,149.78207
178.80000,29.80006,149.99175
179.00002,29.83366,150.31437
179.20002,29.86686,150.55766
179.40002,29.90006,150.70662
179.60000,29.93339,150.93816
179.80000,29.96672,151.08763
180.00002,30.00019,151.38615
180.20002,30.03339,151.46577
180.40002,30.06659,151.67679
180.60000,30.10019,151.83103
180.80000,30.13379,152.05578
181.00002,30.16686,152.32268
181.20002,30.19992,152.55691
181.40002,30.23339,152.80300
181.60000,30.26672,153.10245
181.80000,30.29979,153.38772
182.00002,30.33339,153.61023
182.20002,30.36685,153.95328
182.40002,30.40032,154.33975
182.60000,30.43352,154.62534
182.80000,30.46672,155.01482
183.00002,30.50019,155.31387
183.20002,30.53352,155.66334
183.40002,30.56659,156.01101
183.60000,30.59992,156.33255
183.80000,30.63352,156.56065
184.00002,30.66699,156.82325
184.20002,30.70005,157.08933
184.40002,30.73325,157.35781
184.60000,30.76672,157.66269
184.80000,30.80019,157.95793
185.00002,30.83339,158.19294
185.20002,30.86672,158.40784
185.40002,30.90032,158.84086
185.60000,30.93339,159.08213
185.80000,30.96685,159.36377
186.00002,31.00019,159.71594
186.20002,31.03339,159.95814
186.40002,31.06685,160.07429
186.60000,31.09992,160.33513
186.80000,31.13325,160.61483
187.00002,31.16685,160.95567
187.20002,31.20032,161.30237
187.40002,31.23325,161.61526
187.60000,31.26658,161.96633
187.80000,31.30018,162.20884
188.00002,31.33352,162.60127
188.20002,31.36658,162.87874
188.40002,31.40019,163.15894
188.60000,31.43365,163.52370
188.80000,31.46698,163.84814
189.00002,31.50032,164.12625
189.20002,31.53338,164.47453
189.40002,31.56672,164.78822
189.60000,31.59992,165.10660
189.80000,31.63325,165.43020
190.00002,31.66671,165.53111
190.20002,31.70018,165.68512
190.40002,31.73365,166.01510
190.60000,31.76672,166.35574
190.80000,31.79992,166.72326
191.00002,31.83338,167.04984
191.20002,31.86671,167.39383
191.40002,31.89991,167.62219
191.60000,31.93338,168.00279
191.80000,31.96711,168.38234
192.00002,32.00018,168.70836
192.20002,32.03338,168.91560
192.40002,32.06685,169.24659
192.60000,32.09991,169.52235
192.80000,32.13352,169.84683
193.00002,32.16672,170.16154
193.20002,32.20005,170.44298
193.40002,32.23338,170.77019
193.60000,32.26698,170.98334
193.80000,32.30005,171.31807
194.00002,32.33325,171.56070
194.20002,32.36672,171.76695
194.40002,32.40031,172.07049
194.60000,32.43311,172.26147
194.80000,32.46671,172.44002
195.00002,32.50032,172.73402
195.20002,32.53352,172.98033
195.40002,32.56685,173.26174
195.60000,32.59991,173.51661
195.80000,32.63338,173.76553
196.00002,32.66685,174.08965
196.20002,32.69991,174.31881
196.40002,32.73338,174.53687
196.60000,32.76685,174.86410
196.80000,32.80045,175.21048
197.00002,32.83338,175.47093
197.20002,32.86658,175.71373
197.40002,32.90005,175.93520
197.60000,32.93338,176.22016
197.80000,32.96658,176.25924
198.00002,32.99991,176.48766
198.20002,33.03351,176.79214
198.40002,33.06698,177.08872
198.60000,33.10005,177.40691
198.80000,33.13338,177.70514
199.00002,33.16671,177.89656
199.20002,33.20018,178.20301
199.40002,33.23338,178.52493
199.60000,33.26658,178.80591
199.80000,33.30018,179.08599
200.00002,33.33364,179.38495
200.20002,33.36671,179.68645
200.40002,33.39991,179.97893
200.60000,33.43338,180.21036
200.80000,33.46685,180.44868
201.00002,33.49991,180.74131
201.20002,33.53338,180.98563
201.40002,33.56684,181.27512
201.60000,33.60031,181.47165
201.80000,33.63351,181.71318
202.00002,33.66671,181.92634
202.20002,33.70005,182.24489
202.40002,33.73351,182.29233
202.60000,33.76658,182.53030
202.80000,33.80004,182.78619
203.00002,33.83351,182.98388
203.20002,33.86698,183.27078
203.40002,33.90018,183.64731
203.60000,33.93338,183.86541
203.80000,33.96671,184.18804
204.00002,34.00018,184.38689
204.20002,34.03324,184.64217
204.40002,34.06658,184.90797
204.60000,34.10017,185.21823
204.80000,34.13364,185.46503
205.00002,34.16684,185.30896
205.20002,34.20004,185.48835
205.40002,34.23324,185.75750
205.60000,34.26684,186.01825
205.80000,34.29991,186.34107
206.00002,34.33324,186.49550
206.20002,34.36684,186.89973
206.40002,34.40044,187.12617
206.60000,34.43338,187.41369
206.80000,34.46658,187.69946
207.00002,34.50017,187.76679
207.20002,34.53337,188.10019
207.40002,34.56657,188.38333
207.60000,34.59991,188.65390
207.80000,34.63364,188.90122
208.00002,34.66697,189.08763
208.20002,34.70017,189.26783
208.40002,34.73351,189.55229
208.60000,34.76671,189.68528
208.80000,34.80018,189.76843
209.00002,34.83324,189.86898
209.20002,34.86658,189.97323
209.40002,34.90017,190.11423
209.60000,34.93378,190.11779
209.80000,34.96684,190.18030
210.00002,34.99991,190.36744
210.20002,35.03351,190.50566
210.40002,35.06684,190.80557
210.60000,35.09977,190.84614
210.80000,35.13337,191.02147
211.00002,35.16698,191.23718
211.20002,35.20031,191.36613
211.40002,35.23351,191.50820
211.60000,35.26684,191.66436
211.80000,35.30017,191.61908
212.00002,35.33351,191.70543
212.20002,35.36671,191.67719
212.40002,35.39991,191.69306
212.60000,35.43337,191.79935
212.80000,35.46697,191.73896
213.00002,35.50004,191.73332
213.20002,35.53324,192.00142
213.40002,35.56657,192.06546
213.60000,35.60004,192.19421
213.80000,35.63311,192.17093
214.00002,35.66657,192.33221
214.20002,35.70031,192.60224
214.40002,35.73364,192.87579
214.60000,35.76684,193.13835
214.80000,35.80017,193.37822
215.00002,35.83337,193.66600
215.20002,35.86684,193.98633
215.40002,35.90004,194.15407
215.60000,35.93337,194.36043
215.80000,35.96684,194.55222
216.00002,36.00030,194.72050
216.20002,36.03337,194.85123
216.40002,36.06657,194.82451
216.60000,36.10004,194.76868
216.80000,36.13351,194.31060
217.00002,36.16657,193.56301
217.20002,36.20004,190.07131
217.40002,36.23350,189.21727
217.60000,36.26697,189.03773
217.80000,36.30017,188.80734
218.00002,36.33337,188.83318
218.20002,36.36670,188.86905
218.40002,36.40017,188.93739
218.60000,36.43337,188.86466
218.80000,36.46670,189.08478
219.00002,36.50004,189.46243
219.20002,36.53364,189.87386
219.40002,36.56670,190.28813
219.60000,36.59990,190.79616
219.80000,36.63337,191.16566
220.00002,36.66684,191.66797
220.20002,36.69990,192.06785
220.40002,36.73337,192.50942
220.60000,36.76697,193.10160
220.80000,36.80030,193.48983
221.00002,36.83337,193.89208
221.20002,36.86670,194.38786
221.40002,36.89990,194.74868
221.60000,36.93350,195.19577
221.80000,36.96670,195.55582
222.00002,36.99990,195.92786
222.20002,37.03350,196.39840
222.40002,37.06697,196.73768
222.60000,37.10017,196.83169
222.80000,37.13324,197.05018
223.00002,37.16670,197.42008
223.20002,37.20004,197.71539
223.40002,37.23310,197.83339
223.60000,37.26670,198.29368
223.80000,37.30017,198.49148
224.00002,37.33350,198.71129
224.20002,37.36670,198.93538
224.40002,37.40003,199.23110
224.60000,37.43337,199.52016
224.80000,37.46684,199.86641
225.00002,37.49990,200.06914
225.20002,37.53323,200.35984
225.40002,37.56683,200.66183
225.60000,37.60030,200.94210
225.80002,37.63337,201.14455
226.00002,37.66657,201.36308
226.20002,37.70017,201.51056
226.40002,37.73350,201.74116
226.60000,37.76657,201.98697
226.80002,37.80003,202.18009
227.00002,37.83363,202.42509
227.20002,37.86697,202.70726
227.40002,37.90003,202.79126
227.60000,37.93337,203.13799
227.80002,37.96670,203.30401
228.00002,38.00017,203.49486
228.20002,38.03323,203.68760
228.40002,38.06670,203.84882
228.60000,38.10017,204.03342
228.80002,38.13363,204.13993
229.00002,38.16670,204.18009
229.20002,38.19990,204.41130
229.40002,38.23337,204.48841
229.60000,38.26683,204.75466
229.80002,38.29990,204.73644
230.00002,38.33337,204.77559
230.20002,38.36697,204.79480
230.40002,38.40017,204.98890
230.60000,38.43350,205.16401
230.80002,38.46670,205.34743
231.00002,38.50003,205.47267
231.20002,38.53337,205.56312
231.40002,38.56670,205.71774
231.60000,38.60003,205.84745
231.80002,38.63350,206.01552
232.00002,38.66696,206.21497
232.20002,38.70003,206.34532
232.40002,38.73323,206.45497
232.60000,38.76683,206.70583
232.80002,38.80017,206.82322
233.00002,38.83323,206.95781
233.20002,38.86670,207.03746
233.40002,38.90016,207.13957
233.60000,38.93363,207.22987
233.80002,38.96670,207.19726
234.00002,39.00003,207.32503
234.20002,39.03336,207.42115
234.40002,39.06683,207.47967
234.60000,39.10003,207.54291
234.80002,39.13323,207.44259
235.00002,39.16696,206.66212
235.20002,39.20043,206.44814
235.40002,39.23336,206.26619
235.60000,39.26656,205.99093
235.80002,39.30030,204.19406
236.00002,39.33336,202.61083
236.20002,39.36656,201.45554
236.40002,39.39990,201.00657
236.60000,39.43376,200.89364
236.80002,39.46683,199.54462
237.00002,39.50016,198.21038
237.20002,39.53336,195.09802
237.40002,39.56670,193.45008
237.60000,39.60016,192.64149
237.80002,39.63336,192.10793
238.00002,39.66656,191.90701
238.20002,39.70016,191.92923
238.40002,39.73363,192.08616
238.60000,39.76683,192.37410
238.80002,39.79990,192.13462
239.00002,39.83350,185.06341
239.20002,39.86683,182.81942
239.40002,39.89976,179.08415
239.60000,39.93336,176.05186
239.80002,39.96696,175.23909
240.00002,40.00016,175.56997
240.20002,40.03350,176.11768
240.40002,40.06683,176.93719
240.60000,40.10016,177.85212
240.80002,40.13349,178.75887
241.00002,40.16669,179.67867
241.20002,40.19989,180.61316
241.40002,40.23336,181.43507
241.60000,40.26696,182.50167
241.80002,40.30003,183.16610
242.00002,40.33336,183.93643
242.20002,40.36669,184.65512
242.40002,40.40016,185.21640
242.60000,40.43309,185.78554
242.80002,40.46670,186.29940
243.00002,40.50016,186.78507
243.20002,40.53376,187.26194
243.40002,40.56683,187.70115
243.60000,40.60016,188.24141
243.80002,40.63336,188.51761
244.00002,40.66683,188.86175
244.20002,40.70003,188.54167
244.40002,40.73336,185.29622
244.60000,40.76696,182.09534
244.80002,40.80029,179.74226
245.00002,40.83349,179.43574
245.20002,40.86656,179.98202
245.40002,40.90016,180.59460
245.60000,40.93349,181.46388
245.80002,40.96656,182.20944
246.00002,41.00003,183.12817
246.20002,41.03363,183.99557
246.40002,41.06696,184.81512
246.60000,41.10016,185.69654
246.80002,41.13349,186.35217
247.00002,41.16669,187.06867
247.20002,41.20016,187.77691
247.40002,41.23323,188.35217
247.60000,41.26656,188.96209
247.80002,41.30002,189.50203
248.00002,41.33363,190.07914
248.20002,41.36683,190.61953
248.40002,41.40003,191.00288
248.60000,41.43362,189.64371
248.80002,41.46682,188.04321
249.00002,41.49989,186.70302
249.20002,41.53336,183.75339
249.40002,41.56696,181.92315
249.60000,41.60029,181.26864
249.80002,41.63349,180.93016
250.00002,41.66669,180.92856
250.20002,41.70002,180.95460
250.40002,41.73349,181.14543
250.60000,41.76669,181.31465
250.80002,41.80003,181.54586
251.00002,41.83349,181.84612
251.20002,41.86709,182.20803
251.40002,41.90002,182.61192
251.60000,41.93336,183.16554
251.80002,41.96683,183.50536
252.00002,42.00016,184.12355
252.20002,42.03323,184.58229
252.40002,42.06682,185.25854
252.60000,42.10042,186.03610
252.80002,42.13362,186.66418
253.00002,42.16682,187.29469
253.20002,42.20016,187.93190
253.40002,42.23336,188.57164
253.60000,42.26682,189.22267
253.80002,42.30002,189.66004
254.00002,42.33336,190.22768
254.20002,42.36696,190.68997
254.40002,42.40042,191.23983
254.60000,42.43349,191.80372
254.80002,42.46669,191.07467
255.00002,42.50016,189.21370
255.20002,42.53349,188.52428
255.40002,42.56656,188.30653
255.60000,42.60015,188.66030
255.80002,42.63362,188.93071
256.00000,42.66696,189.37014
256.20002,42.70016,189.79630
256.40003,42.73336,190.17855
256.60000,42.76695,188.42012
256.80002,42.80015,187.04060
257.00000,42.83335,186.41071
257.20002,42.86669,186.34023
257.40003,42.90016,186.64636
257.60000,42.93362,187.08607
257.80002,42.96669,187.52782
258.00000,43.00002,188.08022
258.20002,43.03349,188.59588
258.40003,43.06669,189.13969
258.60000,43.09989,189.67882
258.80002,43.13336,190.15318
259.00000,43.16695,190.68887
259.20002,43.20029,191.14850
259.40003,43.23349,191.59019
259.60000,43.26669,192.23124
259.80002,43.30016,192.58952
260.00000,43.33362,193.20961
260.20002,43.36669,193.74719
260.40003,43.40002,194.35443
260.60000,43.43375,194.97117
260.80002,43.46695,195.39131
261.00000,43.50002,195.89709
261.20002,43.53322,196.49338
261.40003,43.56682,196.83234
261.60000,43.60029,197.45359
261.80002,43.63322,197.70814
262.00000,43.66682,198.16726
262.20000,43.70029,198.56129
262.40003,43.73362,198.99195
262.60000,43.76682,199.33026
262.80003,43.80015,199.64846
263.00000,43.83349,200.06070
263.20000,43.86682,200.45137
263.40003,43.90002,200.86497
263.60000,43.93335,201.17162
263.80003,43.96682,201.48221
264.00000,44.00029,201.85094
264.20000,44.03322,202.12414
264.40003,44.06669,202.48985
264.60000,44.10028,202.86027
264.80003,44.13348,203.12678
265.00000,44.16655,203.50279
265.20000,44.20002,203.80119
265.40003,44.23362,204.25912
265.60000,44.26695,204.58629
265.80003,44.30015,204.91930
266.00000,44.33335,205.34251
266.20000,44.36655,205.69261
266.40003,44.40015,205.97050
266.60000,44.43335,206.37384
266.80003,44.46669,206.50402
267.00000,44.50028,206.89711
267.20000,44.53362,207.25196
267.40003,44.56668,207.48213
267.60000,44.60002,207.89621
267.80003,44.63362,208.14698
268.00000,44.66682,208.40494
268.20000,44.69975,208.63730
268.40003,44.73348,208.86458
268.60000,44.76709,209.12733
268.80003,44.80029,209.27090
269.00000,44.83349,209.54506
269.20000,44.86668,209.70516
269.40003,44.90015,209.89655
269.60000,44.93348,210.06918
269.80003,44.96668,210.18766
270.00000,45.00015,210.29053
270.20000,45.03348,210.45260
270.40003,45.06708,210.65440
270.60000,45.10001,210.86667
270.80003,45.13321,208.90040
271.00000,45.16682,206.62501
271.20000,45.20015,204.33385
271.40003,45.23322,202.08977
271.60000,45.26681,200.90874
271.80003,45.30042,178.47933
272.00000,45.33362,173.00410
272.20000,45.36668,171.23709
272.40003,45.40015,168.53837
272.60000,45.43335,168.31966
272.80003,45.46681,168.39249
273.00000,45.50001,168.89004
273.20000,45.53321,169.50378
273.40003,45.56682,170.28855
273.60000,45.60041,171.13652
273.80003,45.63335,171.89510
274.00000,45.66668,172.70610
274.20000,45.70001,173.54101
274.40003,45.73348,174.31753
274.60000,45.76655,175.05789
274.80003,45.80015,175.66362
275.00000,45.83361,176.30806
275.20000,45.86695,176.87598
275.40003,45.90015,177.40294
275.60000,45.93348,177.48656
275.80003,45.96682,177.45852
276.00000,46.00015,178.00957
276.20000,46.03335,178.42479
276.40003,46.06668,179.02268
276.60000,46.10015,179.61456
276.80003,46.13375,180.01428
277.00000,46.16681,180.62958
277.20000,46.19988,181.13149
277.40003,46.23348,181.45898
277.60000,46.26681,181.87292
277.80003,46.30001,173.52397
278.00000,46.33348,171.65193
278.20000,46.36694,171.16539
278.40003,46.40028,171.14110
278.60000,46.43348,171.57614
278.80003,46.46681,172.00377
279.00000,46.50015,172.60643
279.20000,46.53348,173.10243
279.40003,46.56668,173.77930
279.60000,46.60001,174.59178
279.80003,46.63348,175.13141
280.00000,46.66695,175.73528
280.20000,46.70015,167.74949
280.40003,46.73335,166.44718
280.60000,46.76681,166.27632
280.80003,46.80014,166.33870
281.00000,46.83321,166.69078
281.20000,46.86668,167.20617
281.40003,46.90028,167.86186
281.60000,46.93361,168.59358
281.80003,46.96681,169.22809
282.00000,47.00001,169.89389
282.20000,47.03334,170.50173
282.40003,47.06681,167.58861
282.60000,47.10001,161.72269
282.80003,47.13335,158.94016
283.00000,47.16694,157.71601
283.20000,47.20041,154.44887
283.40003,47.23348,152.82571
283.60000,47.26668,151.62953
283.80003,47.30015,150.21486
283.98800,47.33174,125.48480