File: FirefighterJacket/data/instron/Specimen_RawData_7.csv
Time,Extension,Load
(sec),(mm),(N)
0.00000,0.00000,0.07578
0.30000,0.04520,-0.01739
0.60000,0.09920,0.00299
0.90000,0.14973,0.06641
1.20000,0.20013,0.03038
1.50000,0.25000,0.08972
1.80000,0.29987,0.10977
2.10000,0.35013,0.10984
2.40000,0.40000,0.11063
2.70000,0.44987,0.16030
3.00000,0.50000,0.10643
3.30000,0.55000,0.13251
3.60000,0.59987,0.09687
3.90000,0.64986,0.05079
4.20000,0.70000,0.14290
4.50000,0.75013,0.15924
4.80000,0.80000,0.17136
5.10000,0.85013,0.22269
5.40000,0.90000,0.19207
5.70000,0.94973,0.26534
6.00000,1.00013,0.25783
6.30000,1.05000,0.23527
6.60000,1.09986,0.24113
6.90000,1.15026,0.34345
7.20000,1.20000,0.29047
7.50000,1.25000,0.29039
7.80000,1.30013,0.27437
8.10000,1.35013,0.29902
8.40000,1.40000,0.38162
8.70000,1.45000,0.35024
9.00000,1.50000,0.34256
9.30000,1.55000,0.34082
9.60000,1.59986,0.33272
9.90000,1.65000,0.37401
10.20000,1.69986,0.33494
10.50000,1.74973,0.46220
10.80000,1.80013,0.33856
11.10000,1.85000,0.41031
11.40000,1.89986,0.45500
11.70000,1.95013,0.43041
12.00000,1.99999,0.52028
12.30000,2.04986,0.47669
12.60000,2.09999,0.50012
12.90000,2.14999,0.50901
13.20000,2.19999,0.51688
13.50000,2.24999,0.47068
13.80000,2.29999,0.48844
14.10000,2.35013,0.53148
14.40000,2.39986,0.54092
14.70000,2.44999,0.55371
15.00000,2.49999,0.53826
15.30000,2.54986,0.60901
15.60000,2.60026,0.58529
15.90000,2.64999,0.60869
16.20000,2.69986,0.62193
16.50000,2.75013,0.62149
16.80000,2.80013,0.56988
17.10000,2.84986,0.58111
17.40000,2.89999,0.65619
17.70000,2.95013,0.67430
18.00000,3.00013,0.68502
18.30000,3.04986,0.72161
18.60000,3.09999,0.67891
18.90000,3.14999,0.74207
19.20000,3.19973,0.78050
19.50000,3.24986,0.74506
19.80000,3.29986,0.74534
20.10000,3.34972,0.77993
20.40000,3.40012,0.72608
20.70000,3.45012,0.81216
21.00000,3.49986,0.76829
21.30000,3.55012,0.79706
21.60000,3.59999,0.78935
21.90000,3.64972,0.89998
22.20000,3.69986,0.85077
22.50000,3.74999,0.85761
22.80000,3.79999,0.90610
23.10000,3.84999,0.91137
23.40000,3.89999,0.92222
23.70000,3.95012,0.90814
24.00000,3.99972,0.96277
24.30000,4.04999,0.93962
24.60000,4.10012,0.92787
24.90000,4.14986,1.03110
25.20000,4.20012,1.01227
25.50000,4.24999,1.04056
25.80000,4.29986,1.04550
26.10000,4.35012,1.08857
26.40000,4.39999,1.11491
26.70000,4.44986,1.12951
27.00000,4.49999,1.10316
27.30000,4.54999,1.11713
27.60000,4.59999,1.17744
27.90000,4.64985,1.18866
28.20000,4.69985,1.23629
28.50000,4.74999,1.22083
28.80000,4.79985,1.20085
29.10000,4.84999,1.30972
29.40000,4.89985,1.32739
29.70000,4.94972,1.31094
30.00000,5.00012,1.33629
30.30000,5.04999,1.32422
30.60000,5.09985,1.37443
30.90000,5.15012,1.39282
31.20000,5.19999,1.40862
31.50000,5.24985,1.44103
31.80000,5.29999,1.46189
32.10000,5.34999,1.45960
32.40000,5.39985,1.51322
32.70000,5.44999,1.50560
33.00000,5.49999,1.54701
33.30000,5.54999,1.52249
33.60000,5.59972,1.53295
33.90000,5.65012,1.58126
34.20000,5.69999,1.62245
34.50000,5.74972,1.70851
34.80000,5.80012,1.65490
35.10000,5.84998,1.64305
35.40000,5.89985,1.70009
35.70000,5.95025,1.70395
36.00000,5.99998,1.73207
36.30000,6.04985,1.75152
36.60000,6.10012,1.80551
36.90000,6.15012,1.83471
37.20000,6.20012,1.86775
37.50000,6.24985,1.87583
37.80000,6.29985,1.87982
38.10000,6.34998,1.93064
38.40000,6.39972,1.95323
38.70000,6.44998,1.93726
39.00000,6.49998,2.00995
39.30000,6.54972,1.94098
39.60000,6.60012,2.02904
39.90000,6.64998,2.07288
40.20000,6.69985,2.06363
40.50000,6.75012,2.14580
40.80000,6.79998,2.18756
41.10000,6.84985,2.15456
41.40000,6.89985,2.18797
41.70000,6.94985,2.23531
42.00000,7.00012,2.31613
42.30000,7.04985,2.23266
42.60000,7.09985,2.28686
42.90000,7.15011,2.29883
43.20000,7.19971,2.41922
43.50000,7.24998,2.45858
43.80000,7.29998,2.47422
44.10000,7.34985,2.45389
44.40000,7.40011,2.45836
44.70000,7.44998,2.53579
45.00000,7.49985,2.60096
45.30000,7.55011,2.56372
45.60000,7.59998,2.63032
45.90000,7.64985,2.67990
46.20000,7.69998,2.65506
46.50000,7.74998,2.70266
46.80000,7.80025,2.75997
47.10000,7.84998,2.76193
47.40000,7.89998,2.82789
47.70000,7.94998,2.87596
48.00000,7.99971,2.94337
48.30000,8.04998,2.94374
48.60000,8.09998,2.94641
48.90000,8.14971,2.99095
49.20000,8.20011,3.07334
49.50000,8.24998,3.11170
49.80000,8.29984,3.14402
50.10000,8.35024,3.16548
50.40000,8.39984,3.20013
50.70000,8.44984,3.16696
51.00000,8.49998,3.24729
51.30000,8.55011,3.31953
51.60000,8.60011,3.33332
51.90000,8.64998,3.44100
52.20000,8.69998,3.35572
52.50000,8.75011,3.48704
52.80000,8.79998,3.52529
53.10000,8.85011,3.54240
53.40000,8.90011,3.59501
53.70000,8.94984,3.68141
54.00000,9.00024,3.68385
54.30000,9.04998,3.74402
54.60000,9.09984,3.79800
54.90000,9.15024,3.80889
55.20000,9.20011,3.85364
55.50000,9.24984,3.89652
55.80000,9.30011,3.92574
56.10000,9.35011,4.01147
56.40000,9.39998,3.99472
56.70000,9.44998,4.09066
57.00000,9.49998,4.11916
57.30000,9.54998,4.18899
57.60000,9.59984,4.29267
57.90000,9.65011,4.32056
58.20000,9.69997,4.34091
58.50000,9.74971,4.43038
58.80000,9.80011,4.44050
59.10000,9.84997,4.52844
59.40000,9.89997,4.53264
59.70000,9.95011,4.61969
60.00000,9.99997,4.61739
60.30000,10.04984,4.75012
60.60000,10.09997,4.74560
60.90000,10.14997,4.78760
61.20000,10.20011,4.87155
61.50000,10.24984,4.96182
61.80000,10.30011,5.00016
62.10000,10.35011,5.04755
62.40000,10.39984,5.08320
62.70000,10.45011,5.11523
63.00000,10.49997,5.21603
63.30000,10.54984,5.29895
63.60000,10.60024,5.31878
63.90000,10.65011,5.38317
64.20000,10.69984,5.44830
64.50000,10.75011,5.55362
64.80000,10.79997,5.56603
65.10001,10.84997,5.68400
65.40000,10.90011,5.71872
65.70001,10.95011,5.75577
66.00000,11.00010,5.83127
66.30000,11.04984,5.96156
66.60001,11.09997,5.98881
66.90000,11.14997,6.08143
67.20001,11.19984,6.08727
67.50000,11.24997,6.25840
67.80000,11.29997,6.27519
68.10001,11.34984,6.37864
68.40000,11.40010,6.41821
68.70001,11.44997,6.42803
69.00000,11.49984,6.53677
69.30000,11.55010,6.65373
69.60001,11.59984,6.75996
69.90000,11.64997,6.79880
70.20001,11.69997,6.85552
70.50000,11.74997,6.93304
70.80000,11.80010,7.04159
71.10001,11.84997,7.11360
71.40000,11.89997,7.19814
71.70001,11.95010,7.19996
72.00000,11.99984,7.37725
72.30000,12.05010,7.43082
72.60001,12.09984,7.50100
72.90000,12.14984,7.61760
73.20001,12.20024,7.70769
73.50000,12.24997,7.83568
73.80000,12.29997,7.89332
74.10001,12.35010,7.93636
74.40000,12.40010,8.05446
74.70001,12.44997,8.08199
75.00000,12.50010,8.21799
75.30000,12.55010,8.31169
75.60001,12.60010,8.44211
75.90000,12.64997,8.49747
76.20001,12.70010,8.59628
76.50000,12.75010,8.73762
76.80000,12.79970,8.83938
77.10001,12.84997,8.97085
77.40000,12.89997,8.90911
77.70001,12.94983,9.07923
78.00000,13.00023,9.22919
78.30000,13.04997,9.31072
78.60001,13.09997,9.38950
78.90000,13.15010,9.52118
79.20001,13.19997,9.60037
79.50000,13.24983,9.75538
79.80000,13.29997,9.84506
80.10001,13.34997,9.91177
80.40000,13.39997,9.95821
80.70001,13.44983,10.13450
81.00001,13.49996,10.26060
81.30000,13.55010,10.34787
81.60001,13.59983,10.50163
81.90000,13.65010,10.61745
82.20001,13.69996,10.73258
82.50001,13.74983,10.84369
82.80000,13.80023,10.97755
83.10001,13.84996,11.12285
83.40000,13.89983,11.19006
83.70001,13.95023,11.28782
84.00001,13.99996,11.47208
84.30000,14.05010,11.60662
84.60001,14.10010,11.70487
84.90000,14.15010,11.85082
85.20001,14.19996,11.93651
85.50001,14.24996,12.10811
85.80000,14.30010,12.27973
86.10001,14.34996,12.37063
86.40000,14.39983,12.45231
86.70001,14.45010,12.67191
87.00001,14.49983,12.73147
87.30000,14.54983,12.93434
87.60001,14.60010,13.05800
87.90000,14.64983,13.18550
88.20001,14.69983,13.39502
88.50001,14.75010,13.46591
88.80000,14.79996,13.64804
89.10001,14.84983,13.86528
89.40000,14.89996,13.98098
89.70001,14.94996,14.10180
90.00001,14.99996,14.28585
90.30000,15.04996,14.42370
90.60001,15.10009,14.64864
90.90000,15.15009,14.75811
91.20001,15.19983,14.93627
91.50001,15.25023,15.10534
91.80000,15.30009,15.25504
92.10001,15.34983,15.44541
92.40000,15.40023,15.57636
92.70001,15.45009,15.74265
93.00001,15.49983,15.95463
93.30000,15.55009,16.14155
93.60001,15.60009,16.28174
93.90000,15.64996,16.39629
94.20001,15.69996,16.61046
94.50001,15.75009,16.85652
94.80000,15.80009,16.99163
95.10001,15.84982,17.16205
95.40000,15.89996,17.35261
95.70001,15.94996,17.54446
96.00001,15.99982,17.73445
96.30000,16.05009,17.99246
96.60001,16.09996,18.19130
96.90000,16.14982,18.40115
97.20001,16.20009,18.55126
97.50001,16.25009,18.78986
97.80000,16.29982,18.92474
98.10001,16.35009,19.23615
98.40000,16.39996,19.39137
98.70001,16.44996,19.56852
99.00001,16.49982,19.81258
99.30000,16.54996,20.01578
99.60001,16.59996,20.33276
99.90000,16.64996,20.47044
100.20001,16.70009,20.70511
100.50001,16.75009,20.92161
100.80000,16.79982,21.13845
101.10001,16.85009,21.34750
101.40000,16.90009,21.56649
101.70001,16.94982,21.79340
102.00001,17.00022,22.11192
102.30000,17.05009,22.26151
102.60001,17.09982,22.55535
102.90000,17.15009,22.79063
103.20001,17.19995,22.99310
103.50001,17.24995,23.25345
103.80000,17.30009,23.49259
104.10001,17.35009,23.82998
104.40000,17.40009,24.01621
104.70001,17.44995,24.30490
105.00001,17.49995,24.54259
105.30000,17.55009,24.76965
105.60001,17.59982,25.05793
105.90000,17.64995,25.28551
106.20001,17.69995,25.61171
106.50001,17.74982,25.86784
106.80000,17.80009,26.19958
107.10001,17.84995,26.46792
107.40000,17.89982,26.70784
107.70001,17.95009,26.97669
108.00001,17.99995,27.17974
108.30000,18.04995,27.52268
108.60001,18.09995,27.89914
108.90000,18.14995,28.11400
109.20001,18.19995,28.38823
109.50001,18.24995,28.70750
109.80000,18.29995,28.97040
110.10001,18.34995,29.38988
110.40000,18.39982,29.58748
110.70001,18.45009,29.88942
111.00001,18.49995,30.23242
111.30000,18.54982,30.44547
111.60001,18.60008,30.85585
111.90000,18.64995,31.10657
112.20001,18.70008,31.44409
112.50001,18.75022,31.74554
112.80000,18.79995,32.05295
113.10001,18.84995,32.38400
113.40001,18.90008,32.66372
113.70001,18.95008,33.00495
114.00001,19.00008,33.27747
114.30000,19.04995,33.58132
114.60001,19.09995,34.02726
114.90001,19.14995,34.30122
115.20001,19.19982,34.53303
115.50001,19.25008,34.88767
115.80000,19.29995,35.28957
116.10001,19.34968,35.58445
116.40001,19.40008,35.92473
116.70001,19.44995,36.27441
117.00001,19.49982,36.56478
117.30000,19.55008,36.93847
117.60001,19.59995,37.35389
117.90001,19.64981,37.62873
118.20001,19.69995,37.98706
118.50001,19.74995,38.35141
118.80000,19.79995,38.72994
119.10001,19.84995,39.14214
119.40001,19.89995,39.44214
119.70001,19.95008,39.84082
120.00001,19.99982,40.17465
120.30000,20.05021,40.57555
120.60001,20.09995,40.99568
120.90001,20.14995,41.23722
121.20001,20.20008,41.66645
121.50001,20.25008,42.02220
121.80000,20.29981,42.33272
122.10001,20.34995,42.80079
122.40001,20.39995,43.15535
122.70001,20.44995,43.56046
123.00001,20.50008,43.93904
123.30000,20.55021,44.33024
123.60001,20.60008,44.79767
123.90001,20.64995,45.11697
124.20001,20.70008,45.52407
124.50001,20.74995,45.91101
124.80000,20.79968,46.31764
125.10001,20.85008,46.80398
125.40001,20.90008,47.12327
125.70001,20.94981,47.53207
126.00001,21.00008,47.97465
126.30000,21.04994,48.37619
126.60001,21.09981,48.86573
126.90001,21.15008,49.26353
127.20001,21.19995,49.65862
127.50001,21.24981,50.13789
127.80000,21.29995,50.53266
128.10001,21.35008,50.93860
128.40001,21.39995,51.38532
128.70002,21.44994,51.79392
129.00000,21.50008,52.26781
129.30000,21.55008,52.68863
129.60001,21.59994,53.14296
129.90001,21.65008,53.52615
130.20002,21.70008,54.06663
130.50000,21.74981,54.34523
130.80000,21.80021,54.90385
131.10000,21.84994,55.31255
131.40002,21.89994,55.77450
131.70002,21.95008,56.17774
132.00000,22.00008,56.63910
132.30000,22.04981,57.09494
132.60000,22.09994,57.61284
132.90002,22.15008,58.02261
133.20002,22.19994,58.40093
133.50000,22.24994,58.88087
133.80000,22.29994,59.36507
134.10000,22.34994,59.84137
134.40002,22.39981,60.21350
134.70002,22.44994,60.72868
135.00000,22.49994,61.21529
135.30000,22.54981,61.68705
135.60000,22.60008,62.12130
135.90002,22.65007,62.62814
136.20002,22.69994,63.04841
136.50000,22.75007,63.48153
136.80000,22.79994,64.04610
137.10000,22.84994,64.51400
137.40002,22.89994,64.98747
137.70002,22.95007,65.50900
138.00000,23.00007,65.98175
138.30000,23.04981,66.38444
138.60000,23.10007,66.92879
138.90002,23.15007,67.34086
139.20002,23.19981,67.83303
139.50000,23.25007,68.31804
139.80000,23.29994,68.84145
140.10000,23.34994,69.35180
140.40002,23.40007,69.86788
140.70002,23.44994,70.33932
141.00000,23.49994,70.80613
141.30000,23.55007,71.35748
141.60000,23.60007,71.81467
141.90002,23.64994,72.29724
142.20002,23.70007,72.75095
142.50000,23.75007,73.22714
142.80000,23.80007,73.64471
143.10000,23.84994,74.15854
143.40002,23.89994,74.71656
143.70002,23.94994,75.24314
144.00000,23.99980,75.62533
144.30000,24.04994,76.06450
144.60000,24.09994,76.60202
144.90002,24.14980,76.96753
145.20002,24.20007,77.37995
145.50000,24.24994,77.83832
145.80000,24.29994,78.21206
146.10000,24.35020,78.68543
146.40002,24.39994,79.08791
146.70002,24.44980,79.52360
147.00000,24.49994,79.92689
147.30000,24.54994,80.32097
147.60000,24.59994,80.71781
147.90002,24.64994,81.06277
148.20002,24.69994,81.45538
148.50000,24.75007,81.87733
148.80000,24.79980,82.25141
149.10000,24.85007,82.61805
149.40002,24.90007,82.55385
149.70002,24.94980,81.39132
150.00000,25.00020,80.16255
150.30000,25.04994,80.64998
150.60000,25.09994,81.04315
150.90002,25.15020,81.19685
151.20002,25.20007,80.82260
151.50000,25.24993,76.20362
151.80000,25.30007,77.27794
152.10000,25.35020,78.61618
152.40002,25.40007,79.70102
152.70002,25.44980,80.62793
153.00000,25.50007,81.42618
153.30000,25.54993,81.95490
153.60000,25.59980,82.22214
153.90002,25.64993,79.77564
154.20002,25.69993,79.93548
154.50000,25.74980,81.04838
154.80000,25.80007,81.90989
155.10000,25.85007,82.75555
155.40002,25.89993,83.55383
155.70002,25.95007,84.38318
156.00000,25.99993,85.13948
156.30000,26.04980,85.82172
156.60000,26.09980,86.22945
156.90002,26.15007,86.65072
157.20002,26.20007,87.11553
157.50000,26.24993,87.67749
157.80000,26.30007,88.11884
158.10000,26.35007,88.67588
158.40002,26.39980,89.17997
158.70002,26.45007,89.62103
159.00000,26.49993,89.94451
159.30000,26.54980,90.34176
159.60000,26.60020,90.72419
159.90002,26.65006,91.09777
160.20002,26.69993,91.55317
160.50000,26.75006,91.92022
160.80000,26.79993,92.22503
161.10000,26.84993,92.70572
161.40002,26.90006,93.25684
161.70002,26.95006,93.70147
162.00002,27.00006,94.28734
162.30000,27.04980,94.79294
162.60000,27.09993,95.34890
162.90002,27.14993,95.73499
163.20002,27.19980,96.21946
163.50002,27.25006,96.59963
163.80000,27.29993,97.11678
164.10000,27.34980,97.68548
164.40002,27.40006,98.23047
164.70002,27.44993,98.77264
165.00002,27.49979,99.24015
165.30000,27.55020,99.86081
165.60000,27.59993,100.32641
165.90002,27.64980,100.85220
166.20002,27.69993,101.45552
166.50002,27.74980,101.82684
166.80000,27.79993,102.42496
167.10000,27.84980,102.95272
167.40002,27.90006,103.41050
167.70002,27.95006,104.02152
168.00002,27.99993,104.52041
168.30000,28.04993,105.03173
168.60000,28.09993,105.55843
168.90002,28.14979,105.96006
169.20002,28.20006,106.59311
169.50002,28.24993,107.04419
169.80000,28.29993,107.60020
170.10000,28.35019,108.02887
170.40002,28.39993,108.52816
170.70002,28.44993,109.10789
171.00002,28.49993,109.62628
171.30000,28.55006,110.14691
171.60000,28.60006,110.62595
171.90002,28.65006,111.13666
172.20002,28.69993,111.66395
172.50002,28.74993,112.20156
172.80000,28.79979,112.66307
173.10000,28.85006,113.17371
173.40002,28.89992,113.65319
173.70002,28.94979,114.21093
174.00002,29.00006,114.72942
174.30000,29.05006,115.28595
174.60000,29.09992,115.84368
174.90002,29.15006,116.37241
175.20002,29.19992,116.87974
175.50002,29.24979,117.44529
175.80000,29.29992,118.05585
176.10000,29.34992,118.64549
176.40002,29.40006,119.06317
176.70002,29.44992,119.60930
177.00002,29.49992,120.04036
177.30000,29.55019,120.55690
177.60000,29.59979,120.89997
177.90002,29.65006,121.36919
178.20002,29.69992,121.67268
178.50002,29.74992,122.11548
178.80000,29.80019,122.55690
179.10000,29.84992,123.01329
179.40002,29.89979,123.46636
179.70002,29.95019,124.00590
180.00002,29.99992,124.34865
180.30000,30.05006,124.67656
180.60000,30.10006,124.88952
180.90002,30.15006,124.90859
181.20002,30.20005,125.03863
181.50002,30.24979,125.06081
181.80000,30.29992,125.21631
182.10000,30.34992,125.55433
182.40002,30.39979,125.91433
182.70002,30.45006,126.35121
183.00002,30.49992,126.83774
183.30000,30.54992,127.30571
183.60000,30.60019,127.88889
183.90002,30.65006,128.39181
184.20002,30.69992,129.01142
184.50002,30.75005,129.59315
184.80000,30.79992,130.11904
185.10000,30.84992,130.70996
185.40002,30.89992,131.31835
185.70002,30.94992,131.82274
186.00002,30.99992,132.36245
186.30000,31.04992,132.88938
186.60000,31.10005,133.35757
186.90002,31.15005,133.96712
187.20002,31.19992,134.38657
187.50002,31.25005,134.93409
187.80000,31.30005,135.41634
188.10000,31.34992,135.95239
188.40002,31.40019,136.37421
188.70002,31.44992,136.91104
189.00002,31.49978,137.29156
189.30000,31.55018,137.82242
189.60000,31.59992,138.31072
189.90002,31.65005,138.76166
190.20002,31.69978,139.19272
190.50002,31.75005,139.63799
190.80000,31.79992,140.02009
191.10000,31.84992,140.52162
191.40002,31.89991,140.91301
191.70002,31.95005,141.28624
192.00002,31.99965,141.81604
192.30000,32.04992,142.25595
192.60000,32.09991,142.76258
192.90002,32.14965,143.23818
193.20002,32.20005,143.64059
193.50002,32.24992,144.14487
193.80000,32.29978,144.60387
194.10000,32.35005,145.06500
194.40002,32.40005,145.53171
194.70002,32.44978,145.92187
195.00002,32.49991,146.42737
195.30000,32.54991,146.84377
195.60000,32.60005,147.28530
195.90002,32.64991,147.82795
196.20002,32.70005,148.26631
196.50002,32.75005,148.63743
196.80000,32.79978,148.96551
197.10000,32.85005,149.36067
197.40002,32.89991,149.64829
197.70002,32.94978,149.98132
198.00002,33.00018,150.32685
198.30000,33.04991,150.18096
198.60000,33.09991,150.55152
198.90002,33.15018,150.91400
199.20002,33.20004,151.17913
199.50002,33.25005,151.45564
199.80000,33.30005,151.62295
200.10000,33.35005,151.73366
200.40002,33.39991,151.78008
200.70002,33.44978,151.78881
201.00002,33.49991,151.87859
201.30000,33.54991,152.06626
201.60000,33.59978,152.40349
201.90002,33.65004,152.70019
202.20002,33.69991,152.96738
202.50002,33.74964,153.36798
202.80000,33.80004,153.79457
203.10000,33.85004,154.13884
203.40002,33.89978,154.45573
203.70002,33.95018,154.83825
204.00002,33.99991,155.12085
204.30000,34.04991,155.32693
204.60000,34.09991,155.50468
204.90002,34.14991,155.64892
205.20002,34.20004,155.61270
205.50002,34.24991,155.57591
205.80000,34.29991,155.46853
206.10000,34.35004,155.54018
206.40002,34.39978,155.75055
206.70002,34.45004,156.17573
207.00002,34.49991,156.73479
207.30000,34.54978,157.39303
207.60000,34.60018,158.14180
207.90002,34.64991,158.87659
208.20002,34.69991,159.60522
208.50002,34.75004,160.22239
208.80000,34.79991,160.93006
209.10000,34.85004,161.52048
209.40002,34.90004,162.03165
209.70002,34.95017,162.56696
210.00002,35.00018,163.10679
210.30000,35.04991,163.60685
210.60000,35.09991,164.13668
210.90002,35.14991,164.66109
211.20002,35.19977,165.25978
211.50002,35.24991,165.77257
211.80000,35.29991,166.38644
212.10000,35.34978,166.79464
212.40002,35.39991,167.31841
212.70002,35.45004,167.69392
213.00002,35.49991,168.18766
213.30000,35.55004,168.60399
213.60000,35.59991,168.99312
213.90002,35.64991,169.41437
214.20002,35.69991,169.74205
214.50002,35.75004,170.09949
214.80000,35.79991,170.54692
215.10000,35.84991,170.98418
215.40002,35.90004,171.42463
215.70002,35.95017,171.87925
216.00002,35.99977,172.29320
216.30000,36.05004,172.80148
216.60000,36.09990,173.24241
216.90002,36.14977,173.61768
217.20002,36.20017,173.92470
217.50002,36.25004,174.34502
217.80000,36.29990,174.73085
218.10000,36.35017,175.12443
218.40002,36.40004,175.48220
218.70002,36.45004,175.80045
219.00002,36.50004,175.97796
219.30000,36.55004,176.21342
219.60000,36.60017,176.38097
219.90002,36.64991,176.38348
220.20002,36.69990,176.32468
220.50002,36.75004,176.03582
220.80000,36.79977,175.17949
221.10000,36.85004,173.71394
221.40002,36.89990,171.24623
221.70002,36.94977,169.91772
222.00002,37.00017,169.90090
222.30000,37.04990,170.34978
222.60000,37.09990,170.96469
222.90002,37.15017,171.60628
223.20002,37.19990,172.43581
223.50002,37.24990,173.15168
223.80000,37.29990,173.96480
224.10000,37.35004,174.74156
224.40002,37.39990,175.31272
224.70002,37.44977,175.85173
225.00002,37.50004,175.99000
225.30002,37.55017,176.47121
225.60000,37.59990,177.04189
225.90002,37.65003,177.56086
226.20002,37.70003,178.07821
226.50002,37.74977,178.54938
226.80002,37.80017,179.03747
227.10000,37.85003,179.43768
227.40002,37.89990,179.91152
227.70002,37.95017,180.25434
228.00002,38.00003,180.52328
228.30002,38.04990,180.79633
228.60000,38.10003,180.96343
228.90002,38.15003,181.09513
229.20002,38.20003,181.02692
229.50002,38.24990,181.07651
229.80002,38.29990,181.04941
230.10000,38.34990,180.85742
230.40002,38.39977,180.47838
230.70002,38.44990,180.14871
231.00002,38.50003,179.92664
231.30002,38.54977,180.10408
231.60000,38.60030,180.56685
231.90002,38.64990,181.01683
232.20002,38.69976,181.54297
232.50002,38.75016,182.13576
232.80002,38.80003,182.58153
233.10000,38.84976,183.02387
233.40002,38.89990,182.92896
233.70002,38.95003,183.31278
234.00002,39.00016,183.72690
234.30002,39.04990,184.06285
234.60000,39.09990,184.66836
234.90002,39.15003,184.99251
235.20002,39.19990,185.43385
235.50002,39.25017,185.93339
235.80002,39.30003,186.37199
236.10000,39.34976,186.84596
236.40002,39.40016,187.15767
236.70002,39.45003,187.50135
237.00002,39.49990,187.79041
237.30002,39.55016,188.12101
237.60000,39.60003,188.47041
237.90002,39.64990,188.63935
238.20002,39.69990,188.94590
238.50002,39.75016,189.09503
238.80002,39.80003,189.29977
239.10000,39.84990,189.38163
239.40002,39.90003,189.36999
239.70002,39.94989,189.14150
240.00002,39.99976,188.96880
240.30002,40.05003,188.51789
240.60000,40.09990,188.08652
240.90002,40.14976,187.70557
241.20002,40.20003,187.55006
241.50002,40.25003,187.49841
241.80002,40.29990,187.46775
242.10000,40.35003,187.44064
242.40002,40.40003,187.17580
242.70002,40.45003,187.06135
243.00002,40.50003,187.13282
243.30002,40.55003,187.29182
243.60000,40.60003,187.65230
243.90002,40.64976,187.91918
244.20002,40.70003,188.34168
244.50002,40.75003,188.89723
244.80002,40.79989,189.44649
245.10000,40.85003,190.08651
245.40002,40.90003,190.63313
245.70002,40.94976,191.17791
246.00002,41.00016,191.74278
246.30002,41.05002,192.33508
246.60000,41.09989,192.77615
246.90002,41.15016,193.21803
247.20002,41.20003,193.70452
247.50002,41.25016,194.10728
247.80002,41.30002,194.20961
248.10000,41.34989,194.46718
248.40002,41.40016,194.79234
248.70002,41.45002,195.17630
249.00002,41.49989,195.47706
249.30002,41.55003,195.85283
249.60000,41.59976,196.20476
249.90002,41.65002,196.48425
250.20002,41.69989,196.77946
250.50002,41.74976,197.12701
250.80002,41.80003,197.38665
251.10000,41.84989,197.60832
251.40002,41.89989,197.86512
251.70002,41.95002,198.07380
252.00002,42.00003,198.41595
252.30002,42.04989,198.67823
252.60000,42.09989,198.94816
252.90002,42.15002,199.24982
253.20002,42.20002,199.48272
253.50002,42.24989,199.84063
253.80002,42.30002,200.03475
254.10000,42.35016,200.34306
254.40002,42.39989,200.62698
254.70002,42.45002,200.94885
255.00002,42.50002,201.22889
255.30002,42.54989,201.39461
255.60000,42.60015,201.61182
255.90002,42.65002,201.76871
256.20002,42.69989,202.02508
256.50000,42.75029,202.31578
256.80002,42.80015,202.51771
257.10000,42.84989,202.66704
257.40003,42.90002,202.88143
257.70002,42.95002,203.06122
258.00000,43.00002,203.45349
258.30002,43.04989,203.39353
258.60000,43.09989,203.68120
258.90003,43.14989,203.99153
259.20002,43.19976,204.24489
259.50000,43.25002,204.43033
259.80002,43.30002,204.74944
260.10000,43.34975,204.92652
260.40003,43.40015,205.14390
260.70002,43.45002,205.31606
261.00000,43.49975,205.36589
261.30002,43.55002,205.50668
261.60000,43.60002,205.72795
261.90003,43.64989,206.01239
262.20000,43.69989,206.24503
262.50000,43.75002,206.46444
262.80003,43.80002,206.62349
263.10000,43.84989,206.92285
263.40003,43.90015,207.14445
263.70000,43.95015,207.36631
264.00000,43.99975,207.72632
264.30003,44.05015,207.91784
264.60000,44.10002,208.19219
264.90003,44.14989,208.45987
265.20000,44.20015,208.71971
265.50000,44.25002,208.91290
265.80003,44.29989,209.25134
266.10000,44.35015,209.52683
266.40003,44.40002,209.75376
266.70000,44.45002,209.97236
267.00000,44.50002,210.27436
267.30003,44.55015,210.50690
267.60000,44.60015,210.78462
267.90003,44.64988,210.95177
268.20000,44.69988,210.99610
268.50000,44.75002,211.12204
268.80003,44.79975,211.15951
269.10000,44.85002,211.37439
269.40003,44.89988,211.56019
269.70000,44.94975,211.63443
270.00000,45.00015,211.87792
270.30003,45.05002,212.02730
270.60000,45.09988,212.29059
270.90003,45.15015,212.52580
271.20000,45.20002,212.75457
271.50000,45.25002,212.99824
271.80003,45.29988,213.12250
272.10000,45.35002,213.28297
272.40003,45.40002,213.51054
272.70000,45.44988,213.73678
273.00000,45.50015,213.83716
273.30003,45.55001,214.02838
273.60000,45.59988,214.22911
273.90003,45.65002,214.39480
274.20000,45.70001,214.63774
274.50000,45.74988,214.76287
274.80003,45.80015,214.98159
275.10000,45.85001,215.16653
275.40003,45.90001,215.39014
275.70000,45.95015,215.60967
276.00000,46.00001,215.77735
276.30003,46.04988,215.99270
276.60000,46.10001,216.20674
276.90003,46.15015,216.33944
277.20000,46.20001,216.38522
277.50000,46.24988,216.70360
277.80003,46.29988,216.61431
278.10000,46.34988,216.74143
278.40003,46.39975,216.84093
278.70000,46.45001,216.84561
279.00000,46.50001,216.86595
279.30003,46.54974,216.79280
279.60000,46.60001,216.82533
279.90003,46.65001,216.95755
280.20000,46.69988,217.06400
280.50000,46.75015,217.40979
280.80003,46.80001,217.57817
281.10000,46.84988,217.83605
281.40003,46.89988,217.96603
281.70000,46.95001,218.20828
282.00000,46.99988,218.41301
282.30003,47.04975,218.58748
282.60000,47.10001,218.84061
282.90003,47.15015,218.96642
283.20000,47.19988,219.01071
283.50000,47.25001,219.13558
283.80003,47.30001,219.31456
284.10000,47.34974,219.46926
284.40003,47.40014,219.67988
284.70000,47.45001,219.75029
285.00000,47.49988,219.93672
285.30003,47.55014,220.12241
285.60000,47.60014,220.23488
285.90003,47.64988,220.36493
286.20000,47.70014,220.41706
286.50000,47.75001,220.46033
286.80003,47.80001,220.58560
287.10000,47.84987,220.73798
287.40003,47.90001,220.91705
287.70000,47.95001,220.98219
288.00000,47.99974,221.14994
288.30003,48.05001,221.36070
288.60000,48.09988,221.36539
288.90003,48.14974,221.44929
289.20000,48.20001,221.56712
289.50000,48.25001,221.73895
289.80003,48.29988,221.85020
290.10000,48.35014,222.16264
290.40003,48.40001,222.31447
290.70000,48.44987,222.58980
291.00000,48.50001,222.79793
291.30003,48.55001,222.97328
291.60000,48.60001,223.28231
291.90003,48.64974,223.49348
292.20000,48.70001,223.66341
292.50000,48.75014,223.92450
292.80003,48.79974,224.07221
293.10000,48.85001,224.36898
293.40003,48.90001,224.60943
293.70000,48.94987,224.69042
294.00000,49.00014,224.93409
294.30003,49.05014,225.07701
294.60000,49.09987,225.25316
294.90003,49.15014,225.41044
295.20000,49.20014,225.60982
295.50000,49.24987,225.61893
295.80003,49.30001,225.41104
296.10000,49.35014,225.36894
296.40003,49.40001,225.29151
296.70000,49.44987,225.50646
297.00000,49.49987,225.71458
297.30003,49.55000,225.97106
297.60000,49.59974,226.12251
297.90003,49.64987,226.11946
298.20000,49.69987,226.25366
298.50000,49.74974,226.39154
298.80003,49.80014,226.47839
299.10000,49.85001,226.67473
299.40003,49.89987,226.77623
299.70000,49.95014,226.83680
300.00000,49.99987,227.07038
300.30003,50.04974,227.21155
300.60000,50.09987,227.42357
300.90003,50.15000,227.57927
301.20000,50.20000,227.80914
301.50000,50.24987,228.01619
301.80003,50.30014,228.22179
302.10000,50.35000,228.46395
302.40003,50.39987,228.60998
302.70000,50.45000,228.76095
303.00000,50.49987,228.99264
303.30003,50.54973,229.17047
303.60000,50.60014,229.34275
303.90003,50.65000,229.49863
304.20000,50.69987,229.56055
304.50000,50.75014,229.71246
304.80003,50.80000,229.83205
305.10000,50.85013,229.99495
305.40003,50.90000,230.05694
305.70000,50.95014,230.19128
306.00000,51.00013,230.41649
306.30003,51.04987,230.50169
306.60000,51.09987,230.74916
306.90003,51.15000,230.79829
307.20000,51.19987,230.96094
307.50000,51.25000,231.06486
307.80003,51.29987,231.25907
308.10000,51.34973,231.31400
308.40003,51.40000,231.25395
308.70000,51.45000,231.28264
309.00000,51.49987,231.45238
309.30003,51.55014,231.44422
309.60000,51.60000,231.61957
309.90003,51.64986,231.71486
310.20000,51.70000,231.74983
310.50000,51.74987,231.94769
310.80003,51.80000,231.94246
311.10000,51.84986,231.99895
311.40003,51.90000,232.14318
311.70000,51.95000,232.31663
312.00000,51.99987,232.53934
312.30003,52.05000,232.63756
312.60000,52.10000,232.81891
312.90003,52.14987,232.90070
313.20000,52.20013,233.07059
313.50000,52.25013,233.37403
313.80003,52.29986,233.51142
314.10000,52.35026,233.75265
314.40003,52.40000,233.94721
314.70000,52.45000,234.15213
315.00000,52.50013,234.32702
315.30003,52.55013,234.39445
315.60000,52.60013,234.62325
315.90003,52.64986,234.75356
316.20000,52.70000,234.85640
316.50000,52.75000,235.15778
316.80003,52.79986,235.24275
317.10000,52.85000,235.40253
317.40003,52.90000,235.53533
317.70000,52.94973,235.67183
318.00000,53.00013,235.78105
318.30003,53.05000,235.89958
318.60000,53.09986,236.13907
318.90003,53.14999,236.17195
319.20000,53.19986,236.24580
319.50000,53.24986,236.44762
319.80003,53.29986,236.59220
320.10000,53.34999,236.89901
320.40003,53.40013,237.00956
320.70000,53.44986,237.18290
321.00000,53.50000,237.30716
321.30003,53.55013,237.42907
321.60000,53.59973,237.58840
321.90003,53.65013,237.69232
322.20000,53.70000,237.77895
322.50003,53.74986,237.89052
322.80003,53.80013,238.03035
323.10000,53.85013,238.24211
323.40003,53.89986,238.33906
323.70000,53.95013,238.40919
324.00003,53.99999,238.55481
324.30003,54.04986,238.70131
324.60000,54.10013,238.72823
324.90003,54.15013,238.72336
325.20000,54.19999,238.73717
325.50003,54.24999,238.88174
325.80003,54.29999,238.99697
326.10000,54.34986,239.21587
326.40003,54.39973,239.39790
326.70000,54.44973,239.54449
327.00003,54.49986,239.76609
327.30003,54.54973,239.94077
327.60000,54.60013,240.21469
327.90003,54.64999,240.26550
328.20000,54.69986,240.47853
328.50003,54.75013,240.80625
328.80003,54.79986,240.88722
329.10000,54.84986,241.19919
329.40003,54.89986,241.40025
329.70000,54.94999,241.62194
330.00003,55.00013,241.75493
330.30003,55.04986,241.74552
330.60000,55.09999,241.87574
330.90003,55.15013,242.02527
331.20000,55.19972,242.15816
331.50003,55.24999,242.42980
331.80003,55.29999,242.53869
332.10000,55.34972,242.63445
332.40003,55.40026,242.70682
332.70000,55.45012,242.87758
333.00003,55.49999,243.08527
333.30003,55.55026,243.28597
333.60000,55.59999,243.44187
333.90003,55.64986,243.62519
334.20000,55.70012,243.71225
334.50003,55.75012,243.86520
334.80003,55.80012,244.02576
335.10000,55.84999,244.17471
335.40003,55.89985,244.22785
335.70000,55.94986,244.37191
336.00003,55.99972,244.51684
336.30003,56.04999,244.69940
336.60000,56.09999,244.90396
336.90003,56.14972,244.84415
337.20000,56.19999,244.86298
337.50003,56.24986,244.93260
337.80003,56.29972,245.03330
338.10000,56.35012,245.18251
338.40003,56.39999,245.18084
338.70000,56.44985,245.27846
339.00003,56.49999,245.37003
339.30003,56.54999,245.50291
339.60000,56.59999,245.67634
339.90003,56.64999,245.75362
340.20000,56.69999,245.92742
340.50003,56.75012,246.05205
340.80003,56.79986,246.15783
341.10000,56.85012,246.41914
341.40003,56.90012,246.52224
341.70000,56.94972,246.71193
342.00003,57.00012,246.87240
342.30003,57.04999,246.93763
342.60000,57.09985,247.16737
342.90003,57.15012,247.28762
343.20000,57.19998,247.30643
343.50003,57.24985,247.57899
343.80003,57.29999,247.65324
344.10000,57.35012,247.83354
344.40003,57.40012,247.90525
344.70000,57.44985,247.94556
345.00003,57.49999,248.10055
345.30003,57.54999,248.23589
345.60000,57.59972,248.35769
345.90003,57.64985,248.27480
346.20000,57.69999,248.27465
346.50003,57.74972,248.31342
346.80003,57.80012,248.50428
347.10000,57.84998,248.64530
347.40003,57.89985,248.63387
347.70000,57.95012,248.72025
348.00003,57.99998,248.74965
348.30003,58.04985,248.87454
348.60000,58.09985,248.90356
348.90003,58.14985,249.07235
349.20000,58.20012,249.10629
349.50003,58.24985,249.26584
349.80003,58.29998,249.30935
350.10000,58.35012,249.43169
350.40003,58.39972,249.48008
350.70000,58.44998,249.45075
351.00003,58.49998,249.59192
351.30003,58.54985,249.47774
351.60000,58.60012,249.62362
351.90003,58.64998,249.61127
352.20000,58.69985,249.56614
352.50003,58.75012,249.68494
352.80003,58.79998,249.66262
353.10000,58.84971,249.82188
353.40003,58.89998,249.87713
353.70000,58.94998,249.87791
354.00003,59.00012,250.02189
354.30003,59.04985,250.13767
354.60000,59.09998,250.00978
354.90003,59.15011,250.05182
355.20000,59.19971,249.91805
355.50003,59.24985,249.92678
355.80003,59.29985,249.97693
356.10000,59.34972,250.09040
356.40003,59.39998,250.12888
356.70000,59.44998,250.16518
357.00003,59.49985,250.29073
357.30003,59.55011,250.34981
357.60000,59.59985,250.45944
357.90003,59.64985,250.64370
358.20000,59.69985,250.82825
358.50003,59.74985,250.97972
358.80003,59.80011,251.14682
359.10000,59.84971,251.32706
359.40003,59.89998,251.40103
359.70000,59.94998,251.53909
360.00003,59.99985,251.68374
360.30003,60.04998,251.77954
360.60000,60.10011,252.05757
360.90003,60.14971,252.17302
361.20000,60.20024,252.16745
361.50003,60.24998,252.28534
361.80003,60.29998,252.47328
362.10000,60.35011,252.59469
362.40003,60.39998,252.57442
362.70000,60.44998,252.43102
363.00003,60.49998,252.30974
363.30003,60.55011,252.25315
363.60000,60.59998,252.38134
363.90003,60.64985,252.42276
364.20000,60.69984,252.47978
364.50003,60.74984,252.75344
364.80003,60.79971,252.89904
365.10000,60.84985,253.17144
365.40003,60.89984,253.15525
365.70000,60.94971,253.32011
366.00003,61.00011,253.46514
366.30003,61.04998,253.54719
366.60000,61.09984,253.77085
366.90003,61.15011,253.88332
367.20000,61.19998,253.89777
367.50003,61.24984,254.03937
367.80003,61.29998,254.24642
368.10000,61.34998,254.45430
368.40003,61.40011,254.62417
368.70000,61.44984,254.65094
369.00003,61.50011,254.76789
369.30003,61.55011,254.94186
369.60000,61.59984,255.14495
369.90003,61.65011,255.17119
370.20000,61.69998,255.27233
370.50003,61.74971,255.32953
370.80003,61.80011,255.44515
371.10000,61.85011,255.68459
371.40003,61.89984,255.73699
371.70000,61.95011,255.77631
372.00003,61.99997,255.89757
372.30003,62.04997,255.97243
372.60000,62.09997,256.12030
372.90003,62.15011,256.14114
373.20000,62.20011,256.16892
373.50003,62.24997,256.21843
373.80003,62.29997,256.23444
374.10000,62.34998,256.33195
374.40003,62.39971,256.30180
374.70000,62.44997,256.23916
375.00003,62.49997,256.20162
375.30003,62.54984,256.13625
375.60000,62.60010,256.08409
375.90003,62.64997,255.89928
376.20000,62.69983,255.73486
376.50003,62.74997,255.46605
376.80003,62.79997,255.20500
377.10000,62.84983,254.98893
377.40003,62.89997,254.01594
377.70000,62.94996,253.58291
378.00003,63.00010,250.13490
378.30003,63.04996,248.45669
378.60000,63.09997,248.17208
378.90003,63.14997,248.13913
379.20000,63.19983,248.22531
379.50003,63.24997,248.38323
379.80003,63.29997,248.48167
380.10000,63.34996,248.70206
380.40003,63.40010,248.70990
380.70000,63.45010,233.32672
381.00003,63.49996,227.73013
381.25200,63.54303,145.19263