File: FirefighterJacket/data/instron/Specimen_RawData_1.csv
Time,Extension,Load
(sec),(mm),(N)
0.00000,0.00000,0.00990
0.20000,0.02533,-0.03306
0.40000,0.06413,0.01533
0.60000,0.09893,0.05974
0.80000,0.13307,0.08279
1.00000,0.16680,0.04702
1.20000,0.19987,-0.03325
1.40000,0.23320,0.02254
1.60000,0.26653,0.00314
1.80000,0.30000,0.09178
2.00000,0.33333,0.04617
2.20000,0.36653,0.07658
2.40000,0.40000,0.09897
2.60000,0.43360,0.05130
2.80000,0.46680,0.09299
3.00000,0.49973,0.12575
3.20000,0.53320,0.03964
3.40000,0.56667,0.11071
3.60000,0.59987,0.05488
3.80000,0.63320,0.16122
4.00000,0.66680,0.16088
4.20000,0.70026,0.13061
4.40000,0.73346,0.11224
4.60000,0.76666,0.17989
4.80000,0.79986,0.15688
5.00000,0.83333,0.16683
5.20000,0.86666,0.15577
5.40000,0.89986,0.19865
5.60000,0.93333,0.18344
5.80000,0.96666,0.20175
6.00000,1.00000,0.19389
6.20000,1.03320,0.21067
6.40000,1.06640,0.22034
6.60000,1.10000,0.23590
6.80000,1.13320,0.27124
7.00000,1.16653,0.29226
7.20000,1.20013,0.24258
7.40000,1.23346,0.24410
7.60000,1.26680,0.23648
7.80000,1.29986,0.31552
8.00000,1.33333,0.30875
8.20000,1.36653,0.33098
8.40000,1.40000,0.30187
8.60000,1.43320,0.29046
8.80000,1.46666,0.40237
9.00000,1.50026,0.36306
9.20000,1.53333,0.35561
9.40000,1.56653,0.34045
9.60000,1.59986,0.40846
9.80000,1.63333,0.46941
10.00000,1.66666,0.44026
10.20000,1.70000,0.42284
10.40000,1.73346,0.49487
10.60000,1.76693,0.45513
10.80000,1.80013,0.50920
11.00000,1.83333,0.52345
11.20000,1.86666,0.47268
11.40000,1.90000,0.54548
11.60000,1.93333,0.57414
11.80000,1.96639,0.64157
12.00000,1.99999,0.60351
12.20000,2.03346,0.60114
12.40000,2.06679,0.63410
12.60000,2.09999,0.61405
12.80000,2.13333,0.66366
13.00000,2.16679,0.66023
13.20000,2.19999,0.65759
13.40000,2.23319,0.69206
13.60000,2.26679,0.73441
13.80000,2.30026,0.75845
14.00000,2.33346,0.72201
14.20000,2.36666,0.78285
14.40000,2.39999,0.80434
14.60000,2.43319,0.85937
14.80000,2.46666,0.86130
15.00000,2.49999,0.82256
15.20000,2.53333,0.90257
15.40000,2.56679,0.91217
15.60000,2.59999,0.87210
15.80000,2.63333,0.94922
16.00000,2.66666,0.97196
16.20000,2.69999,0.99069
16.40000,2.73333,1.01796
16.60000,2.76653,0.96322
16.80000,2.80013,1.08086
17.00000,2.83359,1.03510
17.20000,2.86679,1.08282
17.40000,2.89999,1.10643
17.60000,2.93306,1.13720
17.80000,2.96666,1.18489
18.00000,2.99999,1.21151
18.20000,3.03333,1.23645
18.40000,3.06666,1.26503
18.60000,3.10013,1.24552
18.80000,3.13346,1.33353
19.00000,3.16653,1.32969
19.20000,3.19999,1.33727
19.40000,3.23332,1.37948
19.60000,3.26652,1.33662
19.80000,3.29986,1.50584
20.00000,3.33346,1.44281
20.20000,3.36679,1.48220
20.40000,3.40012,1.55641
20.60000,3.43332,1.49797
20.80000,3.46666,1.64346
21.00000,3.49999,1.66480
21.20000,3.53332,1.65093
21.40000,3.56652,1.65167
21.60000,3.59999,1.75479
21.80000,3.63359,1.75637
22.00000,3.66679,1.81441
22.20000,3.69999,1.87081
22.40000,3.73319,1.89364
22.60000,3.76666,1.88769
22.80000,3.79999,1.95049
23.00000,3.83319,2.00813
23.20000,3.86679,2.03481
23.40000,3.90012,2.06881
23.60000,3.93346,2.02127
23.80000,3.96679,2.17922
24.00000,3.99999,2.17121
24.20000,4.03332,2.19730
24.40000,4.06666,2.21529
24.60000,4.09986,2.33022
24.80000,4.13332,2.32849
25.00000,4.16692,2.36067
25.20000,4.19999,2.31706
25.40000,4.23332,2.44804
25.60000,4.26666,2.47441
25.80000,4.29999,2.55030
26.00000,4.33332,2.52462
26.20000,4.36652,2.61293
26.40000,4.39999,2.61288
26.60000,4.43345,2.72265
26.80000,4.46679,2.79644
27.00000,4.49999,2.85113
27.20000,4.53319,2.89447
27.40000,4.56665,2.91213
27.60000,4.59985,2.97666
27.80000,4.63319,3.05330
28.00000,4.66679,3.10528
28.20000,4.70025,3.12449
28.40000,4.73345,3.11639
28.60000,4.76652,3.12911
28.80000,4.79999,3.26505
29.00000,4.83332,3.29602
29.20000,4.86665,3.35006
29.40000,4.89999,3.39586
29.60000,4.93332,3.43293
29.80000,4.96692,3.57746
30.00000,4.99999,3.58287
30.20000,5.03332,3.58453
30.40000,5.06665,3.69761
30.60000,5.09999,3.68467
30.80000,5.13332,3.83415
31.00000,5.16639,3.91610
31.20000,5.19999,3.92940
31.40000,5.23359,4.01559
31.60000,5.26679,3.98922
31.80000,5.29999,4.14991
32.00000,5.33332,4.16846
32.20000,5.36665,4.25273
32.40000,5.39985,4.34228
32.60000,5.43319,4.35493
32.80000,5.46679,4.42495
33.00000,5.50025,4.48466
33.20000,5.53359,4.55655
33.40000,5.56679,4.64718
33.60000,5.59999,4.66333
33.80000,5.63345,4.78737
34.00000,5.66665,4.79192
34.20000,5.69985,4.89949
34.40000,5.73332,4.96335
34.60000,5.76679,4.97904
34.80000,5.80012,5.13985
35.00000,5.83332,5.19080
35.20000,5.86652,5.32916
35.40000,5.89985,5.35106
35.60000,5.93318,5.44468
35.80000,5.96652,5.63486
36.00000,5.99998,5.62568
36.20000,6.03358,5.67904
36.40000,6.06678,5.73418
36.60000,6.10012,5.79896
36.80000,6.13332,5.91070
37.00000,6.16665,6.03874
37.20000,6.19998,6.09397
37.40000,6.23318,6.19256
37.60000,6.26665,6.24147
37.80000,6.30025,6.37094
38.00000,6.33345,6.44006
38.20000,6.36652,6.61586
38.40000,6.39998,6.63964
38.60000,6.43332,6.67330
38.80000,6.46665,6.86323
39.00000,6.49985,6.92745
39.20000,6.53345,6.98521
39.40000,6.56692,7.09655
39.60000,6.60012,7.15967
39.80000,6.63332,7.30146
40.00000,6.66652,7.38256
40.20000,6.69985,7.49541
40.40000,6.73332,7.61289
40.60000,6.76652,7.70317
40.80000,6.80012,7.83017
41.00000,6.83358,7.91876
41.20000,6.86678,8.00021
41.40000,6.89985,8.12898
41.60000,6.93332,8.21311
41.80000,6.96665,8.39100
42.00000,6.99985,8.47759
42.20000,7.03318,8.57041
42.40000,7.06678,8.67054
42.60000,7.10012,8.70410
42.80000,7.13345,8.94614
43.00000,7.16665,9.06737
43.20000,7.19985,9.15488
43.40000,7.23331,9.22100
43.60000,7.26665,9.21931
43.80000,7.29998,9.41539
44.00000,7.33331,9.49696
44.20000,7.36678,9.66460
44.40000,7.40011,9.74189
44.60000,7.43331,9.73170
44.80000,7.46665,10.00878
45.00000,7.50011,10.09821
45.20000,7.53331,10.19340
45.40000,7.56638,10.34698
45.60000,7.60011,10.52354
45.80000,7.63345,10.64283
46.00000,7.66678,10.71633
46.20000,7.70011,10.88632
46.40000,7.73331,11.01737
46.60000,7.76651,11.24539
46.80000,7.79998,11.32744
47.00000,7.83331,11.44230
47.20000,7.86665,11.63356
47.40000,7.90025,11.74376
47.60000,7.93345,11.92312
47.80000,7.96665,12.08575
48.00000,7.99998,12.19147
48.20000,8.03345,12.32840
48.40000,8.06664,12.49938
48.60000,8.09985,12.73663
48.80000,8.13344,12.85736
49.00000,8.16678,12.98519
49.20000,8.20011,13.13431
49.40000,8.23331,13.29902
49.60000,8.26664,13.53980
49.80000,8.29998,13.65626
50.00000,8.33331,13.79050
50.20000,8.36651,13.94594
50.40000,8.39998,14.14030
50.60000,8.43344,14.37014
50.80000,8.46678,14.52590
51.00000,8.49984,14.68229
51.20000,8.53318,14.83466
51.40000,8.56678,15.05289
51.60000,8.59998,15.30680
51.80000,8.63318,15.45370
52.00000,8.66678,15.57185
52.20000,8.70011,15.81483
52.40000,8.73331,15.99780
52.60000,8.76664,16.19809
52.80000,8.79998,16.43850
53.00000,8.83331,16.53774
53.20000,8.86664,16.75569
53.40000,8.89998,16.91321
53.60000,8.93344,17.18212
53.80000,8.96678,17.31904
54.00000,9.00011,17.56142
54.20000,9.03318,17.73746
54.40000,9.06651,17.93838
54.60000,9.09998,18.24179
54.80000,9.13331,18.38540
55.00000,9.16651,18.59340
55.20000,9.20011,18.78864
55.40000,9.23358,19.06715
55.60000,9.26678,19.32250
55.80000,9.29998,19.49392
56.00000,9.33331,19.68536
56.20000,9.36664,19.87420
56.40000,9.39998,20.13681
56.60000,9.43318,20.36281
56.80000,9.46664,20.55961
57.00000,9.50011,20.72419
57.20000,9.53344,20.93748
57.40000,9.56651,21.22320
57.60000,9.59984,21.48530
57.80000,9.63344,21.71977
58.00000,9.66664,21.93940
58.20000,9.69984,22.16044
58.40000,9.73344,22.41445
58.60000,9.76691,22.66554
58.80000,9.80011,22.96381
59.00000,9.83331,23.19997
59.20000,9.86651,23.41460
59.40000,9.89997,23.75199
59.60000,9.93344,24.01060
59.80000,9.96664,24.24884
60.00000,9.99997,24.52332
60.20000,10.03357,24.76264
60.40000,10.06677,25.03061
60.60000,10.09997,25.36859
60.80000,10.13344,25.65527
61.00000,10.16664,25.93135
61.20000,10.19997,26.16156
61.40000,10.23317,26.45334
61.60000,10.26664,26.79341
61.80000,10.30011,27.04086
62.00000,10.33344,27.28059
62.20000,10.36664,27.55604
62.40000,10.39997,27.84734
62.60000,10.43331,28.17742
62.80000,10.46664,28.53258
63.00000,10.49984,28.73907
63.20000,10.53331,29.03134
63.40000,10.56677,29.36929
63.60000,10.60011,29.78630
63.80000,10.63331,29.98853
64.00000,10.66651,30.28180
64.20000,10.70011,30.51396
64.40000,10.73331,30.87402
64.60001,10.76651,31.33395
64.80000,10.80011,31.54754
65.00000,10.83331,31.78168
65.20000,10.86677,32.18612
65.40000,10.89984,32.58996
65.60001,10.93331,32.95184
65.80000,10.96664,33.29132
66.00000,11.00010,33.49929
66.20001,11.03317,33.92880
66.40000,11.06664,34.24146
66.60001,11.10010,34.70309
66.80000,11.13344,35.04088
67.00000,11.16664,35.26473
67.20001,11.19997,35.65326
67.40000,11.23330,35.97326
67.60001,11.26664,36.42079
67.80000,11.29984,36.82091
68.00000,11.33330,37.13066
68.20001,11.36690,37.55239
68.40000,11.40010,37.92096
68.60001,11.43344,38.32416
68.80000,11.46664,38.70780
69.00000,11.49997,38.96919
69.20001,11.53330,39.43953
69.40000,11.56650,39.82958
69.60001,11.59997,40.30063
69.80000,11.63344,40.33377
70.00000,11.66677,40.65326
70.20001,11.69997,41.12607
70.40000,11.73344,41.54798
70.60001,11.76677,42.01209
70.80000,11.79997,42.44576
71.00000,11.83317,42.72671
71.20001,11.86677,43.20234
71.40000,11.90010,43.64687
71.60001,11.93344,44.16928
71.80000,11.96677,44.58764
72.00000,11.99997,44.93007
72.20001,12.03330,45.46406
72.40000,12.06664,45.86407
72.60001,12.09997,46.31800
72.80000,12.13330,46.72197
73.00000,12.16690,47.10047
73.20001,12.20010,47.64277
73.40000,12.23317,48.02623
73.60001,12.26663,48.55656
73.80000,12.29997,48.90815
74.00000,12.33330,49.37243
74.20001,12.36650,49.87837
74.40000,12.40010,50.28031
74.60001,12.43357,50.76631
74.80000,12.46677,51.29731
75.00000,12.49997,51.64823
75.20001,12.53330,52.16592
75.40000,12.56650,52.53968
75.60001,12.59997,53.03967
75.80000,12.63317,53.50236
76.00000,12.66663,54.03288
76.20001,12.70010,54.50741
76.40000,12.73343,55.00105
76.60001,12.76663,55.47298
76.80000,12.79997,55.98838
77.00000,12.83330,56.47352
77.20001,12.86663,56.92106
77.40000,12.89983,57.52055
77.60001,12.93343,58.06894
77.80000,12.96690,58.58117
78.00000,13.00010,59.06967
78.20001,13.03330,59.53579
78.40000,13.06663,60.03162
78.60001,13.09997,60.54689
78.80000,13.13330,61.04924
79.00000,13.16650,61.46377
79.20001,13.19997,62.12926
79.40000,13.23343,62.59785
79.60001,13.26677,63.12042
79.80000,13.29983,63.62623
80.00000,13.33317,64.19830
80.20001,13.36663,64.74606
80.40000,13.39997,65.28842
80.60001,13.43330,65.78173
80.80000,13.46677,66.36452
81.00001,13.50023,66.83009
81.20001,13.53330,67.46456
81.40000,13.56663,67.92109
81.60001,13.59996,68.50813
81.80000,13.63330,69.08274
82.00001,13.66663,69.63900
82.20001,13.69983,70.19406
82.40000,13.73330,70.79430
82.60001,13.76690,71.27046
82.80000,13.80010,71.89745
83.00001,13.83316,72.38518
83.20001,13.86663,72.92687
83.40000,13.89996,73.56393
83.60001,13.93330,74.06444
83.80000,13.96663,74.65305
84.00001,14.00023,75.18150
84.20001,14.03356,75.75430
84.40000,14.06676,76.24109
84.60001,14.10010,76.79103
84.80000,14.13316,77.45713
85.00001,14.16663,77.87431
85.20001,14.19996,78.45263
85.40000,14.23316,78.80206
85.60001,14.26663,79.50907
85.80000,14.30010,80.16493
86.00001,14.33343,80.73604
86.20001,14.36650,81.30535
86.40000,14.39996,81.83301
86.60001,14.43343,82.44784
86.80000,14.46663,83.00386
87.00001,14.49983,83.55990
87.20001,14.53330,84.14981
87.40000,14.56690,84.59200
87.60001,14.60010,84.76481
87.80000,14.63343,85.35929
88.00001,14.66663,85.95171
88.20001,14.69996,86.62472
88.40000,14.73330,87.23793
88.60001,14.76663,87.86880
88.80000,14.79996,88.54783
89.00001,14.83343,89.08202
89.20001,14.86676,89.26167
89.40000,14.89996,89.74825
89.60001,14.93329,90.33627
89.80000,14.96663,90.84510
90.00001,14.99996,91.27369
90.20001,15.03316,91.65137
90.40000,15.06676,92.06448
90.60001,15.10023,92.59750
90.80000,15.13343,93.19459
91.00001,15.16663,93.65757
91.20001,15.19996,94.29378
91.40000,15.23329,94.97062
91.60001,15.26676,95.54458
91.80000,15.29983,96.21066
92.00001,15.33343,96.77764
92.20001,15.36689,96.93544
92.40000,15.40009,97.51351
92.60001,15.43329,98.05692
92.80000,15.46649,98.67422
93.00001,15.49996,98.75377
93.20001,15.53316,99.24268
93.40000,15.56649,99.74905
93.60001,15.60009,100.25609
93.80000,15.63356,100.80618
94.00001,15.66676,101.24527
94.20001,15.69996,101.72068
94.40000,15.73316,102.29263
94.60001,15.76662,102.89246
94.80000,15.79996,103.61640
95.00001,15.83316,104.25568
95.20001,15.86649,104.88908
95.40000,15.90022,105.62008
95.60001,15.93342,106.39261
95.80000,15.96649,107.01180
96.00001,15.99996,107.59286
96.20001,16.03329,108.13398
96.40000,16.06662,108.70799
96.60001,16.09996,109.56224
96.80000,16.13329,110.32643
97.00001,16.16689,111.06331
97.20001,16.20009,111.85428
97.40000,16.23342,112.62679
97.60001,16.26649,113.38464
97.80000,16.29996,114.15008
98.00001,16.33329,114.92597
98.20001,16.36649,115.59596
98.40000,16.39996,116.43444
98.60001,16.43356,117.19320
98.80000,16.46676,118.04291
99.00001,16.49982,118.28804
99.20001,16.53302,119.15952
99.40000,16.56676,119.74416
99.60001,16.59996,120.56006
99.80000,16.63316,120.95728
100.00001,16.66676,121.40357
100.20001,16.70022,122.09882
100.40000,16.73356,122.77606
100.60001,16.76675,123.45468
100.80000,16.79982,124.30287
101.00001,16.83316,125.04827
101.20001,16.86662,125.69835
101.40000,16.89982,126.30461
101.60001,16.93329,127.04683
101.80000,16.96689,127.83316
102.00001,17.00009,128.54771
102.20001,17.03329,129.19420
102.40000,17.06649,129.85371
102.60001,17.10009,130.71789
102.80000,17.13329,131.43661
103.00001,17.16649,132.20148
103.20001,17.19995,132.95938
103.40000,17.23355,133.62448
103.60001,17.26662,134.40167
103.80000,17.29982,135.20613
104.00001,17.33329,135.96459
104.20001,17.36662,136.72300
104.40000,17.40009,137.33132
104.60001,17.43329,138.10969
104.80000,17.46662,138.87599
105.00001,17.50022,138.68044
105.20001,17.53342,139.38811
105.40000,17.56662,140.02595
105.60001,17.59982,140.73387
105.80000,17.63342,141.30603
106.00001,17.66662,140.84056
106.20001,17.69982,141.16168
106.40000,17.73342,141.84424
106.60001,17.76689,142.57285
106.80000,17.80022,143.45631
107.00001,17.83329,144.17028
107.20001,17.86662,144.89904
107.40000,17.89995,145.58754
107.60001,17.93329,146.37860
107.80000,17.96662,146.99550
108.00001,17.99995,147.15252
108.20001,18.03355,147.75258
108.40000,18.06675,148.29676
108.60001,18.09995,146.12677
108.80000,18.13315,146.31237
109.00001,18.16662,146.15356
109.20001,18.19995,146.16445
109.40000,18.23329,146.60143
109.60001,18.26675,147.28029
109.80000,18.30022,147.83063
110.00001,18.33342,148.50945
110.20001,18.36675,149.22121
110.40000,18.39995,149.73262
110.60001,18.43328,150.44888
110.80000,18.46662,151.16218
111.00001,18.49982,151.71006
111.20001,18.53328,152.44772
111.40000,18.56688,153.15228
111.60001,18.60008,153.72672
111.80000,18.63315,154.29175
112.00001,18.66662,154.79400
112.20001,18.69995,153.82458
112.40000,18.73342,154.32925
112.60001,18.76648,154.59351
112.80000,18.80008,155.10849
113.00001,18.83342,155.68195
113.20001,18.86662,156.29224
113.40001,18.89995,156.79033
113.60001,18.93315,157.36708
113.80000,18.96675,157.83338
114.00001,18.99995,157.85951
114.20001,19.03315,158.43861
114.40001,19.06662,158.98915
114.60001,19.10022,159.51106
114.80000,19.13342,160.08332
115.00001,19.16662,160.42152
115.20001,19.19995,160.85034
115.40001,19.23328,161.09986
115.60001,19.26662,161.52695
115.80000,19.29995,161.85656
116.00001,19.33342,162.34184
116.20001,19.36688,162.79487
116.40001,19.40008,163.30952
116.60001,19.43328,163.91341
116.80000,19.46648,164.62045
117.00001,19.49982,164.96403
117.20001,19.53328,165.67275
117.40001,19.56662,166.43846
117.60001,19.59995,167.17153
117.80000,19.63355,167.95417
118.00001,19.66675,168.64719
118.20001,19.69995,169.37518
118.40001,19.73328,170.00925
118.60001,19.76675,170.71508
118.80000,19.79995,171.39394
119.00001,19.83328,172.03435
119.20001,19.86675,172.56379
119.40001,19.90008,173.15751
119.60001,19.93341,173.54071
119.80000,19.96662,173.95170
120.00001,19.99995,174.38242
120.20001,20.03328,174.70574
120.40001,20.06661,175.12918
120.60001,20.09995,175.43511
120.80000,20.13328,175.77818
121.00001,20.16688,176.23333
121.20001,20.20008,176.80291
121.40001,20.23315,177.32648
121.60001,20.26661,178.02393
121.80000,20.30008,178.61426
122.00001,20.33328,179.10417
122.20001,20.36648,179.36911
122.40001,20.40008,179.91014
122.60001,20.43341,180.47089
122.80000,20.46675,181.07353
123.00001,20.49995,181.72424
123.20001,20.53315,182.36827
123.40001,20.56661,182.47949
123.60001,20.60008,177.23091
123.80000,20.63315,177.71583
124.00001,20.66661,178.31311
124.20001,20.70021,178.96751
124.40001,20.73355,179.70195
124.60001,20.76648,180.39828
124.80000,20.79995,180.98453
125.00001,20.83341,181.64448
125.20001,20.86661,182.22092
125.40001,20.89981,182.84403
125.60001,20.93341,183.53947
125.80000,20.96675,184.16466
126.00001,21.00021,184.88122
126.20001,21.03328,185.49826
126.40001,21.06648,186.05432
126.60001,21.09995,186.74809
126.80000,21.13328,187.30162
127.00001,21.16648,187.88483
127.20001,21.19995,188.56421
127.40001,21.23341,189.12109
127.60001,21.26661,189.69307
127.80000,21.29995,190.38144
128.00000,21.33328,190.94743
128.20002,21.36675,191.52803
128.40001,21.40008,192.14373
128.60001,21.43314,192.62055
128.80000,21.46674,193.19208
129.00000,21.50008,193.77554
129.20002,21.53341,194.32155
129.40001,21.56661,194.77794
129.60001,21.59981,195.39887
129.80000,21.63328,195.92667
130.00000,21.66661,196.48137
130.20002,21.69981,197.04724
130.40001,21.73328,197.58707
130.60001,21.76674,198.15668
130.80000,21.80008,198.68039
131.00000,21.83328,199.15514
131.20002,21.86661,199.70311
131.40002,21.89994,200.15867
131.60000,21.93314,200.60185
131.80000,21.96661,200.97055
132.00000,22.00008,201.42725
132.20002,22.03354,201.94396
132.40002,22.06688,202.36598
132.60000,22.09981,202.79072
132.80000,22.13314,203.25037
133.00000,22.16661,203.67818
133.20002,22.19994,204.27937
133.40002,22.23314,204.75885
133.60000,22.26661,205.12611
133.80000,22.30008,205.59592
134.00000,22.33341,206.14859
134.20002,22.36661,206.62664
134.40002,22.39994,207.08630
134.60000,22.43328,207.61659
134.80000,22.46648,208.08291
135.00000,22.49981,208.50750
135.20002,22.53341,209.03215
135.40002,22.56688,209.51370
135.60000,22.60008,209.98321
135.80000,22.63341,210.36986
136.00000,22.66661,210.81546
136.20002,22.69994,211.38342
136.40002,22.73341,211.81127
136.60000,22.76647,212.27421
136.80000,22.79994,212.73971
137.00000,22.83341,213.21783
137.20002,22.86674,213.68697
137.40002,22.89981,214.11268
137.60000,22.93327,214.57164
137.80000,22.96647,214.97719
138.00000,22.99981,215.42547
138.20002,23.03314,215.96128
138.40002,23.06674,216.30876
138.60000,23.10021,216.82775
138.80000,23.13341,217.21868
139.00000,23.16661,217.70036
139.20002,23.19994,218.06488
139.40002,23.23327,218.45566
139.60000,23.26661,218.86911
139.80000,23.29994,219.29223
140.00000,23.33341,219.66470
140.20002,23.36687,220.12282
140.40002,23.40007,220.60869
140.60000,23.43314,220.99836
140.80000,23.46661,221.48330
141.00000,23.49994,221.85670
141.20002,23.53327,222.23003
141.40002,23.56647,222.63413
141.60000,23.60021,222.97699
141.80000,23.63354,223.32497
142.00000,23.66674,223.66317
142.20002,23.69994,223.90286
142.40002,23.73314,224.19373
142.60000,23.76661,224.39037
142.80000,23.79994,224.14826
143.00000,23.83314,220.22486
143.20002,23.86674,220.01464
143.40002,23.90021,220.31436
143.60000,23.93341,220.78536
143.80000,23.96647,221.11237
144.00000,23.99980,221.50196
144.20002,24.03340,221.76342
144.40002,24.06660,222.07478
144.60000,24.09994,222.49138
144.80000,24.13340,222.95102
145.00000,24.16687,223.36965
145.20002,24.20020,223.84893
145.40002,24.23327,224.25769
145.60000,24.26660,224.66063
145.80000,24.29980,225.06317
146.00000,24.33327,225.43857
146.20002,24.36660,225.79692
146.40002,24.39994,226.20786
146.60000,24.43340,226.66173
146.80000,24.46674,227.12404
147.00000,24.49980,227.37412
147.20002,24.53327,227.90784
147.40002,24.56674,228.23164
147.60000,24.59994,228.69352
147.80000,24.63314,228.95876
148.00000,24.66674,229.35225
148.20002,24.70020,229.69995
148.40002,24.73340,230.09133
148.60000,24.76660,230.48246
148.80000,24.79980,230.73789
149.00000,24.83327,231.05221
149.20002,24.86674,231.44571
149.40002,24.89980,231.76257
149.60000,24.93340,232.05103
149.80000,24.96674,232.34244
150.00000,25.00007,232.66761
150.20002,25.03313,232.87943
150.40002,25.06660,233.12302
150.60000,25.10007,233.37888
150.80000,25.13327,233.31203
151.00000,25.16647,233.60757
151.20002,25.20007,233.84050
151.40002,25.23340,234.23940
151.60000,25.26673,234.54608
151.80000,25.30007,234.91716
152.00000,25.33313,235.22617
152.20002,25.36673,235.56488
152.40002,25.39993,235.85342
152.60000,25.43327,236.20008
152.80000,25.46660,236.59293
153.00000,25.50020,236.90870
153.20002,25.53340,237.23574
153.40002,25.56647,237.51758
153.60000,25.59993,237.84086
153.80000,25.63327,238.14183
154.00000,25.66660,238.47876
154.20002,25.69967,238.60546
154.40002,25.73340,238.96025
154.60000,25.76687,239.18441
154.80000,25.80007,239.50461
155.00000,25.83340,239.73685
155.20002,25.86660,239.93835
155.40002,25.89993,240.16920
155.60000,25.93327,240.08781
155.80000,25.96647,240.26928
156.00000,25.99993,240.48362
156.20002,26.03353,240.55813
156.40002,26.06660,240.69583
156.60000,26.09980,235.02098
156.80000,26.13313,235.09594
157.00000,26.16673,235.33707
157.20002,26.19993,235.52611
157.40002,26.23313,235.72214
157.60000,26.26687,236.01903
157.80000,26.30020,236.13438
158.00000,26.33340,236.26316
158.20002,26.36660,236.29934
158.40002,26.39993,236.65976
158.60000,26.43326,237.07390
158.80000,26.46660,237.26758
159.00000,26.49993,237.48433
159.20002,26.53326,237.76755
159.40002,26.56673,238.08079
159.60000,26.60006,238.57094
159.80000,26.63326,238.78967
160.00000,26.66633,239.14076
160.20002,26.70020,239.52642
160.40002,26.73326,239.76898
160.60000,26.76646,240.16036
160.80000,26.80006,240.42394
161.00002,26.83353,240.75462
161.20002,26.86673,241.06165
161.40002,26.89993,241.29409
161.60000,26.93313,241.63561
161.80000,26.96646,241.85704
162.00002,26.99993,242.25408
162.20002,27.03326,242.41362
162.40002,27.06660,242.67320
162.60000,27.10020,242.96541
162.80000,27.13340,243.25335
163.00002,27.16660,243.49257
163.20002,27.19993,243.72512
163.40002,27.23326,243.90258
163.60000,27.26660,244.20435
163.80000,27.29993,244.39313
164.00002,27.33340,244.61901
164.20002,27.36686,244.84629
164.40002,27.39993,245.01458
164.60000,27.43340,245.29895
164.80000,27.46646,245.53645
165.00002,27.49993,245.79458
165.20002,27.53340,246.06761
165.40002,27.56660,246.23951
165.60000,27.59993,246.53615
165.80000,27.63340,246.81007
166.00002,27.66673,247.07837
166.20002,27.69993,247.29466
166.40002,27.73326,247.46357
166.60000,27.76673,247.79119
166.80000,27.79979,248.03810
167.00002,27.83313,248.19244
167.20002,27.86673,248.37049
167.40002,27.90019,248.78709
167.60000,27.93339,248.97570
167.80000,27.96673,249.06842
168.00002,27.99993,249.43743
168.20002,28.03326,249.52691
168.40002,28.06659,249.67639
168.60000,28.09993,249.99106
168.80000,28.13326,250.26621
169.00002,28.16686,250.48774
169.20002,28.20006,250.63353
169.40002,28.23313,250.89195
169.60000,28.26659,251.14629
169.80000,28.30006,251.38795
170.00002,28.33326,251.55406
170.20002,28.36646,251.72118
170.40002,28.40006,251.94252
170.60000,28.43339,252.14221
170.80000,28.46673,252.41137
171.00002,28.50006,252.55000
171.20002,28.53326,252.63270
171.40002,28.56659,252.90661
171.60000,28.60006,253.07391
171.80000,28.63313,253.25339
172.00002,28.66659,253.43455
172.20002,28.70019,253.60806
172.40002,28.73339,253.77201
172.60000,28.76659,254.07562
172.80000,28.79992,254.18572
173.00002,28.83326,254.42246
173.20002,28.86673,254.55117
173.40002,28.90006,254.76534
173.60000,28.93353,255.02833
173.80000,28.96672,255.22510
174.00002,29.00006,255.23428
174.20002,29.03326,255.30444
174.40002,29.06672,244.74643
174.60000,29.09992,245.22329
174.80000,29.13326,245.33959
175.00002,29.16659,245.57175
175.20002,29.20006,245.72941
175.40002,29.23352,245.99094
175.60000,29.26672,245.67580
175.80000,29.29992,245.82861
176.00002,29.33326,246.00316
176.20002,29.36672,246.28863
176.40002,29.40006,246.49244
176.60000,29.43326,246.79597
176.80000,29.46672,247.01232
177.00002,29.50019,247.20345
177.20002,29.53339,247.37490
177.40002,29.56659,247.57119
177.60000,29.59992,247.88702
177.80000,29.63326,248.09999
178.00002,29.66672,248.26495
178.20002,29.69979,248.52699
178.40002,29.73339,248.68654
178.60000,29.76686,248.95217
178.80000,29.80006,249.12449
179.00002,29.83326,249.22434
179.20002,29.86659,249.41193
179.40002,29.90006,249.61635
179.60000,29.93326,249.81430
179.80000,29.96646,249.90896
180.00002,30.00019,250.05141
180.20002,30.03339,250.13473
180.40002,30.06672,250.31803
180.60000,30.10006,250.45177
180.80000,30.13326,250.50348
181.00002,30.16672,241.22987
181.20002,30.20005,241.22398
181.40002,30.23326,241.39738
181.60000,30.26672,241.54481
181.80000,30.30019,241.66826
182.00002,30.33339,241.76668
182.20002,30.36646,241.88984
182.40002,30.39992,242.13327
182.60000,30.43325,242.36647
182.80000,30.46659,242.41162
183.00002,30.49992,242.45799
183.20002,30.53352,242.52037
183.40002,30.56685,239.66035
183.60000,30.60005,238.89482
183.80000,30.63339,238.67011
184.00002,30.66672,238.61839
184.20002,30.69992,238.60130
184.40002,30.73339,238.72519
184.60000,30.76659,238.74996
184.80000,30.80005,238.79226
185.00002,30.83352,238.84574
185.20002,30.86672,238.88513
185.40002,30.89979,239.01125
185.60000,30.93325,239.12854
185.80000,30.96659,239.29132
186.00002,30.99992,239.41595
186.20002,31.03325,239.61632
186.40002,31.06685,239.67734
186.60000,31.10019,239.95329
186.80000,31.13339,239.97977
187.00002,31.16672,240.08453
187.20002,31.19992,240.18815
187.40002,31.23325,240.34644
187.60000,31.26658,240.47613
187.80000,31.29992,240.57236
188.00002,31.33338,240.64980
188.20002,31.36685,240.82899
188.40002,31.40019,241.00803
188.60000,31.43325,241.15304
188.80000,31.46658,241.24853
189.00002,31.50005,241.39589
189.20002,31.53338,241.53272
189.40002,31.56658,241.70363
189.60000,31.60018,241.87829
189.80000,31.63351,242.00030
190.00002,31.66671,242.03232
190.20002,31.70005,242.19841
190.40002,31.73325,242.27018
190.60000,31.76658,242.43731
190.80000,31.80005,242.39464
191.00002,31.83325,242.27230
191.20002,31.86671,230.37331
191.40002,31.90018,230.48224
191.60000,31.93352,230.76894
191.80000,31.96645,230.99249
192.00002,32.00005,231.19757
192.20002,32.03338,229.64204
192.40002,32.06671,229.49375
192.60000,32.09991,229.48466
192.80000,32.13352,229.52387
193.00002,32.16685,229.68791
193.20002,32.20005,229.81033
193.40002,32.23325,229.89426
193.60000,32.26658,230.16552
193.80000,32.30005,230.16727
194.00002,32.33338,230.29277
194.20002,32.36658,226.30220
194.40002,32.40005,221.20280
194.60000,32.43365,217.49588
194.80000,32.46671,213.48396
194.94402,32.49138,147.32912