File: GFBaking/data/2_8PercentGluten/2_8gluten_Compression.is_comp_RawData/Specimen_RawData_1.csv
Time,Extension,Load
(sec),(mm),(N)
0.00000,0.00000,-0.26525
0.10000,-0.00600,-0.26957
0.20000,-0.02560,-0.29408
0.30000,-0.04533,-0.31946
0.40000,-0.06427,-0.34220
0.50000,-0.08213,-0.36041
0.60000,-0.09920,-0.37922
0.70000,-0.11653,-0.39594
0.80000,-0.13320,-0.41308
0.90000,-0.15000,-0.42975
1.00000,-0.16667,-0.44626
1.10000,-0.18333,-0.46249
1.20000,-0.19987,-0.47917
1.30000,-0.21680,-0.49536
1.40000,-0.23347,-0.51077
1.50000,-0.24987,-0.52701
1.60000,-0.26707,-0.54279
1.70000,-0.28333,-0.55831
1.80000,-0.30000,-0.57568
1.90000,-0.31653,-0.59208
2.00000,-0.33320,-0.60779
2.10000,-0.34987,-0.62380
2.20000,-0.36680,-0.63955
2.30000,-0.38333,-0.65424
2.40000,-0.39987,-0.67016
2.50000,-0.41680,-0.68552
2.60000,-0.43307,-0.70039
2.70000,-0.45000,-0.71563
2.80000,-0.46653,-0.73246
2.90000,-0.48333,-0.74726
3.00000,-0.50027,-0.76332
3.10000,-0.51680,-0.77846
3.20000,-0.53360,-0.79282
3.30000,-0.55000,-0.80789
3.40000,-0.56667,-0.82278
3.50000,-0.58320,-0.83716
3.60000,-0.60000,-0.85194
3.70000,-0.61680,-0.86780
3.80000,-0.63333,-0.88231
3.90000,-0.65027,-0.89701
4.00000,-0.66667,-0.91097
4.10000,-0.68360,-0.92818
4.20000,-0.70013,-0.94219
4.30000,-0.71680,-0.95809
4.40000,-0.73333,-0.97237
4.50000,-0.75013,-0.98935
4.60000,-0.76680,-1.00333
4.70000,-0.78333,-1.01944
4.80000,-0.80013,-1.03360
4.90000,-0.81653,-1.04925
5.00000,-0.83320,-1.06256
5.10000,-0.85000,-1.07732
5.20000,-0.86653,-1.09236
5.30000,-0.88320,-1.10757
5.40000,-0.90000,-1.12241
5.50000,-0.91666,-1.13673
5.60000,-0.93333,-1.15424
5.70000,-0.95040,-1.16952
5.80000,-0.96653,-1.18464
5.90000,-0.98320,-1.19978
6.00000,-0.99986,-1.21533
6.10000,-1.01666,-1.23029
6.20000,-1.03360,-1.24313
6.30000,-1.05000,-1.25751
6.40000,-1.06693,-1.27254
6.50000,-1.08346,-1.28750
6.60000,-1.10026,-1.30323
6.70000,-1.11653,-1.31785
6.80000,-1.13320,-1.33108
6.90000,-1.15013,-1.34470
7.00000,-1.16666,-1.36055
7.10000,-1.18360,-1.37616
7.20000,-1.20000,-1.39249
7.30000,-1.21680,-1.40590
7.40000,-1.23346,-1.42058
7.50000,-1.25000,-1.43543
7.60000,-1.26653,-1.44912
7.70000,-1.28320,-1.46687
7.80000,-1.30013,-1.48057
7.90000,-1.31666,-1.49548
8.00000,-1.33373,-1.50862
8.10000,-1.35000,-1.52392
8.20000,-1.36666,-1.53804
8.30000,-1.38320,-1.55598
8.40000,-1.39986,-1.57008
8.50000,-1.41666,-1.58636
8.60000,-1.43346,-1.60016
8.70000,-1.45013,-1.61439
8.80000,-1.46653,-1.62978
8.90000,-1.48360,-1.64482
9.00000,-1.49986,-1.65562
9.10000,-1.51653,-1.67135
9.20000,-1.53333,-1.68731
9.30000,-1.54986,-1.69761
9.40000,-1.56680,-1.71198
9.50000,-1.58333,-1.72751
9.60000,-1.60026,-1.74288
9.70000,-1.61666,-1.75760
9.80000,-1.63346,-1.77035
9.90000,-1.64986,-1.78288
10.00000,-1.66666,-1.79356
10.10000,-1.68360,-1.80676
10.20000,-1.70013,-1.82078
10.30000,-1.71693,-1.83641
10.40000,-1.73346,-1.85310
10.50000,-1.75013,-1.86690
10.60000,-1.76666,-1.87614
10.70000,-1.78333,-1.88716
10.80000,-1.79973,-1.90601
10.90000,-1.81666,-1.91970
11.00000,-1.83360,-1.93698
11.10000,-1.85000,-1.95315
11.20000,-1.86693,-1.97302
11.30000,-1.88333,-1.98329
11.40000,-1.90000,-1.99996
11.50000,-1.91666,-2.01204
11.60000,-1.93306,-2.02640
11.70000,-1.94986,-2.03381
11.80000,-1.96680,-2.04621
11.90000,-1.98346,-2.05816
12.00000,-2.00000,-2.07151
12.10000,-2.01680,-2.08365
12.20000,-2.03319,-2.09574
12.30000,-2.04986,-2.11068
12.40000,-2.06653,-2.12179
12.50000,-2.08319,-2.13652
12.60000,-2.10026,-2.15079
12.70000,-2.11693,-2.16366
12.80000,-2.13346,-2.17691
12.90000,-2.14999,-2.19175
13.00000,-2.16666,-2.20235
13.10000,-2.18333,-2.21221
13.20000,-2.19999,-2.22558
13.30000,-2.21679,-2.23727
13.40000,-2.23333,-2.24961
13.50000,-2.25039,-2.26196
13.60000,-2.26679,-2.27328
13.70000,-2.28346,-2.28401
13.80000,-2.30013,-2.29551
13.90000,-2.31666,-2.30669
14.00000,-2.33319,-2.31745
14.10000,-2.35013,-2.32918
14.20000,-2.36693,-2.34069
14.30000,-2.38333,-2.35244
14.40000,-2.40026,-2.36461
14.50000,-2.41666,-2.37583
14.60000,-2.43333,-2.38678
14.70000,-2.44986,-2.39831
14.80000,-2.46653,-2.40978
14.90000,-2.48333,-2.42095
15.00000,-2.50013,-2.43237
15.10000,-2.51679,-2.44299
15.20000,-2.53319,-2.45519
15.30000,-2.55026,-2.46664
15.40000,-2.56653,-2.47770
15.50000,-2.58319,-2.48752
15.60000,-2.59999,-2.49838
15.70000,-2.61653,-2.50917
15.80000,-2.63346,-2.52075
15.90000,-2.65013,-2.53081
16.00000,-2.66679,-2.54243
16.10000,-2.68333,-2.55308
16.20000,-2.70013,-2.56299
16.30000,-2.71653,-2.57278
16.40000,-2.73319,-2.58330
16.50000,-2.75026,-2.59235
16.60000,-2.76666,-2.60309
16.70000,-2.78359,-2.61346
16.80000,-2.80026,-2.62309
16.90000,-2.81693,-2.63211
17.00000,-2.83333,-2.64111
17.10000,-2.84999,-2.65165
17.20000,-2.86653,-2.66100
17.30000,-2.88333,-2.67098
17.40000,-2.90013,-2.68053
17.50000,-2.91666,-2.69049
17.60000,-2.93359,-2.69973
17.70000,-2.94999,-2.70865
17.80000,-2.96653,-2.71815
17.90000,-2.98333,-2.72695
18.00000,-2.99986,-2.73676
18.10000,-3.01653,-2.74656
18.20000,-3.03346,-2.75445
18.30000,-3.05013,-2.76466
18.40000,-3.06653,-2.77232
18.50000,-3.08373,-2.78148
18.60000,-3.09986,-2.78858
18.70000,-3.11639,-2.79794
18.80000,-3.13333,-2.80941
18.90000,-3.15013,-2.81041
19.00000,-3.16693,-2.82280
19.10000,-3.18359,-2.83018
19.20000,-3.20013,-2.83239
19.30000,-3.21666,-2.53687
19.40000,-3.23346,-2.59759
19.50000,-3.24986,-2.61942
19.60000,-3.26653,-2.64833
19.70000,-3.28346,-2.67802
19.80000,-3.29999,-2.69473
19.90000,-3.31693,-2.71362
20.00000,-3.33346,-2.73301
20.10000,-3.34999,-2.75131
20.20000,-3.36653,-2.76869
20.30000,-3.38319,-2.78607
20.40000,-3.39973,-2.79768
20.50000,-3.41679,-2.81164
20.60000,-3.43346,-2.82320
20.70000,-3.44986,-2.83286
20.80000,-3.46692,-2.84280
20.90000,-3.48332,-2.85263
21.00000,-3.49999,-2.86754
21.10000,-3.51666,-2.87566
21.20000,-3.53306,-2.88719
21.30000,-3.54986,-2.89739
21.40000,-3.56666,-2.90544
21.50000,-3.58346,-2.91393
21.60000,-3.59999,-2.92469
21.70000,-3.61692,-2.93374
21.80000,-3.63319,-2.94267
21.90000,-3.64986,-2.95109
22.00000,-3.66666,-2.95842
22.10000,-3.68319,-2.96278
22.20000,-3.70012,-2.97104
22.30000,-3.71679,-2.97980
22.40000,-3.73346,-2.98709
22.50000,-3.75012,-2.99721
22.60000,-3.76666,-3.00332
22.70000,-3.78306,-3.00767
22.80000,-3.79999,-3.01496
22.90000,-3.81692,-3.02256
23.00000,-3.83346,-3.02934
23.10000,-3.85026,-3.03095
23.20000,-3.86679,-3.03999
23.30000,-3.88346,-3.04697
23.40000,-3.90012,-3.05258
23.50000,-3.91679,-3.05633
23.60000,-3.93319,-3.06117
23.70000,-3.95012,-3.06895
23.80000,-3.96692,-3.07367
23.90000,-3.98332,-3.08091
24.00000,-4.00039,-3.08932
24.10000,-4.01666,-3.09328
24.20000,-4.03332,-3.10085
24.30000,-4.04986,-3.10893
24.40000,-4.06652,-3.11607
24.50000,-4.08319,-3.12438
24.60000,-4.10012,-3.13239
24.70000,-4.11679,-3.13286
24.80000,-4.13332,-3.13895
24.90000,-4.15026,-3.15145
25.00000,-4.16652,-3.15435
25.10000,-4.18332,-3.15691
25.20000,-4.19999,-3.16620
25.30000,-4.21652,-3.17207
25.40000,-4.23359,-3.17483
25.50000,-4.25012,-3.17809
25.60000,-4.26679,-3.18512
25.70000,-4.28332,-3.19087
25.80000,-4.30026,-3.19289
25.90000,-4.31652,-3.19772
26.00000,-4.33332,-3.20804
26.10000,-4.35012,-3.21082
26.20000,-4.36666,-3.21242
26.30000,-4.38359,-3.21787
26.40000,-4.40012,-3.22296
26.50000,-4.41679,-3.22856
26.60000,-4.43332,-3.23552
26.70000,-4.44986,-3.24135
26.80000,-4.46652,-3.24963
26.90000,-4.48346,-3.25383
27.00000,-4.50026,-3.25966
27.10000,-4.51666,-3.26407
27.20000,-4.53359,-3.26997
27.30000,-4.54999,-3.27430
27.40000,-4.56666,-3.27852
27.50000,-4.58319,-3.28632
27.60000,-4.59972,-3.29072
27.70000,-4.61652,-3.29662
27.80000,-4.63332,-3.30134
27.90000,-4.65012,-3.30814
28.00000,-4.66652,-3.31260
28.10000,-4.68346,-3.31700
28.20000,-4.69972,-3.32193
28.30000,-4.71666,-3.32838
28.40000,-4.73332,-3.33393
28.50000,-4.74986,-3.33860
28.60000,-4.76679,-3.34515
28.70000,-4.78346,-3.35075
28.80000,-4.80012,-3.35592
28.90000,-4.81666,-3.36190
29.00000,-4.83345,-3.36799
29.10000,-4.84985,-3.37306
29.20000,-4.86665,-3.37885
29.30000,-4.88345,-3.38517
29.40000,-4.89999,-3.39080
29.50000,-4.91705,-3.39671
29.60000,-4.93345,-3.40085
29.70000,-4.95025,-3.40707
29.80000,-4.96665,-3.41200
29.90000,-4.98345,-3.41835
30.00000,-4.99985,-3.42234
30.10000,-5.01679,-3.42868
30.20000,-5.03345,-3.43368
30.30000,-5.04985,-3.43897
30.40000,-5.06692,-3.44383
30.50000,-5.08332,-3.44902
30.60000,-5.09985,-3.45441
30.70000,-5.11652,-3.46002
30.80000,-5.13332,-3.46546
30.90000,-5.14999,-3.47069
31.00000,-5.16679,-3.47636
31.10000,-5.18345,-3.48082
31.20000,-5.19985,-3.48580
31.30000,-5.21692,-3.49068
31.40000,-5.23319,-3.49509
31.50000,-5.24985,-3.50001
31.60000,-5.26652,-3.50427
31.70000,-5.28319,-3.50976
31.80000,-5.29999,-3.51547
31.90000,-5.31679,-3.51987
32.00000,-5.33359,-3.52567
32.10000,-5.34999,-3.52976
32.20000,-5.36679,-3.53487
32.30000,-5.38332,-3.53828
32.40000,-5.39999,-3.54383
32.50000,-5.41692,-3.54891
32.60000,-5.43332,-3.55280
32.70000,-5.45039,-3.55816
32.80000,-5.46679,-3.56201
32.90000,-5.48359,-3.56690
33.00000,-5.50012,-3.57062
33.10000,-5.51679,-3.57464
33.20000,-5.53319,-3.57784
33.30000,-5.54999,-3.58286
33.40000,-5.56679,-3.58647
33.50000,-5.58332,-3.59152
33.60000,-5.60025,-3.59484
33.70000,-5.61665,-3.59920
33.80000,-5.63319,-3.60227
33.90000,-5.64999,-3.60618
34.00000,-5.66652,-3.60860
34.10000,-5.68319,-3.61266
34.20000,-5.69999,-3.61726
34.30000,-5.71679,-3.62026
34.40000,-5.73332,-3.62498
34.50000,-5.75025,-3.62798
34.60000,-5.76639,-3.63009
34.70000,-5.78305,-3.63365
34.80000,-5.79999,-3.63691
34.90000,-5.81665,-3.64070
35.00000,-5.83359,-3.64477
35.10000,-5.85012,-3.64747
35.20000,-5.86692,-3.65091
35.30000,-5.88332,-3.65420
35.40000,-5.90012,-3.65743
35.50000,-5.91652,-3.65908
35.60000,-5.93332,-3.66225
35.70000,-5.95012,-3.66444
35.80000,-5.96665,-3.66683
35.90000,-5.98372,-3.67036
36.00000,-6.00012,-3.67231
36.10000,-6.01679,-3.67529
36.20000,-6.03332,-3.67813
36.30000,-6.04999,-3.68025
36.40000,-6.06652,-3.68240
36.50000,-6.08332,-3.68517
36.60000,-6.09998,-3.68728
36.70000,-6.11652,-3.69073
36.80000,-6.13359,-3.69282
36.90000,-6.14998,-3.69555
37.00000,-6.16665,-3.69773
37.10000,-6.18332,-3.70054
37.20000,-6.19972,-3.70279
37.30000,-6.21652,-3.70648
37.40000,-6.23345,-3.71015
37.50000,-6.25012,-3.71190
37.60000,-6.26652,-3.71508
37.70000,-6.28358,-3.71704
37.80000,-6.29972,-3.71917
37.90000,-6.31665,-3.72211
38.00000,-6.33332,-3.72467
38.10000,-6.34985,-3.72748
38.20000,-6.36678,-3.73004
38.30000,-6.38345,-3.73302
38.40000,-6.40012,-3.73498
38.50000,-6.41665,-3.73812
38.60000,-6.43345,-3.74071
38.70000,-6.44985,-3.74267
38.80000,-6.46678,-3.74658
38.90000,-6.48358,-3.74932
39.00000,-6.50012,-3.75153
39.10000,-6.51705,-3.75488
39.20000,-6.53345,-3.75686
39.30000,-6.55025,-3.75963
39.40000,-6.56678,-3.76191
39.50000,-6.58332,-3.76423
39.60000,-6.59985,-3.76748
39.70000,-6.61665,-3.77129
39.80000,-6.63345,-3.77324
39.90000,-6.64998,-3.77515
40.00000,-6.66705,-3.77776
40.10000,-6.68332,-3.78205
40.20000,-6.69985,-3.78338
40.30000,-6.71652,-3.78579
40.40000,-6.73318,-3.78969
40.50000,-6.74985,-3.79124
40.60000,-6.76678,-3.79498
40.70000,-6.78345,-3.79778
40.80000,-6.79985,-3.80174
40.90000,-6.81692,-3.80327
41.00000,-6.83318,-3.80682
41.10000,-6.84985,-3.81064
41.20000,-6.86665,-3.81363
41.30000,-6.88318,-3.81703
41.40000,-6.89998,-3.81966
41.50000,-6.91678,-3.82228
41.60000,-6.93345,-3.82441
41.70000,-6.94998,-3.82732
41.80000,-6.96665,-3.82874
41.90000,-6.98318,-3.83095
42.00000,-6.99998,-3.83416
42.10000,-7.01678,-3.83644
42.20000,-7.03332,-3.83834
42.30000,-7.05038,-3.84004
42.40000,-7.06678,-3.84229
42.50000,-7.08345,-3.84312
42.60000,-7.09998,-3.84499
42.70000,-7.11678,-3.84719
42.80000,-7.13332,-3.84850
42.90000,-7.15012,-3.85021
43.00000,-7.16692,-3.85195
43.10000,-7.18318,-3.85240
43.20000,-7.20025,-3.85471
43.30000,-7.21665,-3.85570
43.40000,-7.23332,-3.85789
43.50000,-7.24985,-3.85919
43.60000,-7.26652,-3.85954
43.70000,-7.28318,-3.86188
43.80000,-7.29998,-3.86245
43.90000,-7.31678,-3.86403
44.00000,-7.33318,-3.86545
44.10000,-7.35025,-3.86709
44.20000,-7.36638,-3.86648
44.30000,-7.38318,-3.87010
44.40000,-7.39998,-3.87105
44.50000,-7.41665,-3.87393
44.60000,-7.43345,-3.87483
44.70000,-7.45011,-3.87724
44.80000,-7.46678,-3.87905
44.90000,-7.48332,-3.88140
45.00000,-7.50025,-3.88342
45.10000,-7.51665,-3.88414
45.20000,-7.53318,-3.88628
45.30000,-7.55025,-3.88740
45.40000,-7.56665,-3.88921
45.50000,-7.58372,-3.89004
45.60000,-7.60025,-3.89165
45.70000,-7.61678,-3.89354
45.80000,-7.63331,-3.89450
45.90000,-7.65011,-3.89528
46.00000,-7.66651,-3.89609
46.10000,-7.68318,-3.89775
46.20000,-7.69998,-3.89864
46.30000,-7.71651,-3.90081
46.40000,-7.73358,-3.90275
46.50000,-7.74985,-3.90308
46.60000,-7.76651,-3.90500
46.70000,-7.78331,-3.90572
46.80000,-7.79998,-3.90861
46.90000,-7.81665,-3.91046
47.00000,-7.83331,-3.91052
47.10000,-7.85011,-3.91088
47.20000,-7.86651,-3.91213
47.30000,-7.88358,-3.91211
47.40000,-7.89985,-3.91222
47.50000,-7.91651,-3.91192
47.60000,-7.93331,-3.91254
47.70000,-7.94985,-3.91275
47.80000,-7.96678,-3.91398
47.90000,-7.98345,-3.91472
48.00000,-8.00011,-3.91497
48.10000,-8.01678,-3.91693
48.20000,-8.03358,-3.91788
48.30000,-8.04985,-3.91740
48.40000,-8.06665,-3.91958
48.50000,-8.08345,-3.92056
48.60000,-8.09998,-3.92251
48.70000,-8.11705,-3.92445
48.80000,-8.13345,-3.92540
48.90000,-8.15011,-3.92614
49.00000,-8.16678,-3.92770
49.10000,-8.18345,-3.92970
49.20000,-8.19998,-3.93078
49.30000,-8.21665,-3.93385
49.40000,-8.23358,-3.93596
49.50000,-8.24998,-3.93954
49.60000,-8.26691,-3.94190
49.70000,-8.28331,-3.94448
49.80000,-8.29985,-3.94715
49.90000,-8.31651,-3.94932
50.00000,-8.33305,-3.95045
50.10000,-8.34985,-3.95367
50.20000,-8.36678,-3.95648
50.30000,-8.38358,-3.95815
50.40000,-8.39985,-3.96063
50.50000,-8.41678,-3.96240
50.60000,-8.43305,-3.96393
50.70000,-8.44985,-3.96676
50.80000,-8.46665,-3.96819
50.90000,-8.48331,-3.97137
51.00000,-8.50011,-3.97432
51.10000,-8.51678,-3.97670
51.20000,-8.53345,-3.97836
51.30000,-8.54998,-3.98013
51.40000,-8.56678,-3.98147
51.50000,-8.58318,-3.98332
51.60000,-8.59998,-3.98684
51.70000,-8.61691,-3.98949
51.80000,-8.63331,-3.99090
51.90000,-8.65038,-3.99359
52.00000,-8.66678,-3.99348
52.10000,-8.68345,-3.99352
52.20000,-8.70011,-3.99510
52.30000,-8.71678,-3.99658
52.40000,-8.73318,-3.99789
52.50000,-8.74998,-3.99990
52.60000,-8.76691,-4.00245
52.70000,-8.78331,-4.00457
52.80000,-8.80038,-4.00697
52.90000,-8.81665,-4.00818
53.00000,-8.83331,-4.01111
53.10000,-8.84998,-4.01288
53.20000,-8.86651,-4.01428
53.30000,-8.88318,-4.01703
53.40000,-8.90011,-4.02084
53.50000,-8.91678,-4.02233
53.60000,-8.93318,-4.02408
53.70000,-8.95038,-4.02685
53.80000,-8.96651,-4.02894
53.90000,-8.98318,-4.03212
54.00000,-8.99985,-4.03411
54.10000,-9.01651,-4.03682
54.20000,-9.03331,-4.03972
54.30000,-9.04998,-4.04228
54.40000,-9.06665,-4.04425
54.50000,-9.08304,-4.04715
54.60000,-9.09998,-4.05030
54.70000,-9.11651,-4.05357
54.80000,-9.13331,-4.05763
54.90000,-9.15024,-4.06079
55.00000,-9.16664,-4.06375
55.10000,-9.18371,-4.06687
55.20000,-9.20011,-4.06881
55.30000,-9.21678,-4.07187
55.40000,-9.23331,-4.07464
55.50000,-9.25011,-4.07818
55.60000,-9.26664,-4.08160
55.70000,-9.28344,-4.08617
55.80000,-9.30024,-4.08880
55.90000,-9.31664,-4.09194
56.00000,-9.33358,-4.09577
56.10000,-9.34998,-4.09880
56.20000,-9.36664,-4.10270
56.30000,-9.38331,-4.10471
56.40000,-9.39984,-4.10762
56.50000,-9.41664,-4.11137
56.60000,-9.43344,-4.11547
56.70000,-9.45011,-4.11737
56.80000,-9.46651,-4.12173
56.90000,-9.48358,-4.12495
57.00000,-9.49971,-4.12636
57.10000,-9.51651,-4.12973
57.20000,-9.53331,-4.13050
57.30000,-9.54984,-4.13309
57.40000,-9.56678,-4.13584
57.50000,-9.58344,-4.13852
57.60000,-9.60011,-4.14044
57.70000,-9.61664,-4.14357
57.80000,-9.63344,-4.14489
57.90000,-9.64984,-4.14667
58.00000,-9.66664,-4.14932
58.10000,-9.68344,-4.15111
58.20000,-9.69984,-4.15350
58.30000,-9.71691,-4.15668
58.40000,-9.73344,-4.15825
58.50000,-9.75011,-4.15960
58.60000,-9.76664,-4.16121
58.70000,-9.78344,-4.16379
58.80000,-9.79984,-4.16491
58.90000,-9.81678,-4.16679
59.00000,-9.83344,-4.16769
59.10000,-9.84984,-4.17038
59.20000,-9.86704,-4.17273
59.30000,-9.88318,-4.17410
59.40000,-9.89971,-4.17607
59.50000,-9.91651,-4.17908
59.60000,-9.93318,-4.18107
59.70000,-9.94984,-4.18398
59.80000,-9.96678,-4.18717
59.90000,-9.98344,-4.18956
60.00000,-9.99984,-4.19244
60.10000,-10.01691,-4.19583
60.20000,-10.03318,-4.19778
60.30000,-10.04984,-4.20144
60.40000,-10.06664,-4.20373
60.50000,-10.08318,-4.20775
60.60000,-10.10011,-4.21088
60.70000,-10.11678,-4.21344
60.80000,-10.13358,-4.21575
60.90000,-10.15011,-4.21906
61.00000,-10.16678,-4.22209
61.10000,-10.18318,-4.22380
61.20000,-10.19998,-4.22783
61.30000,-10.21678,-4.23106
61.40000,-10.23331,-4.23466
61.50000,-10.25037,-4.23861
61.60000,-10.26678,-4.24078
61.70000,-10.28358,-4.24447
61.80000,-10.30011,-4.24773
61.90000,-10.31678,-4.25066
62.00000,-10.33317,-4.25324
62.10000,-10.35011,-4.25817
62.20000,-10.36678,-4.26059
62.30000,-10.38331,-4.26552
62.40000,-10.40024,-4.26769
62.50000,-10.41651,-4.27173
62.60000,-10.43331,-4.27615
62.70000,-10.44997,-4.27998
62.80000,-10.46651,-4.28303
62.90000,-10.48317,-4.28624
63.00000,-10.50011,-4.29127
63.10000,-10.51677,-4.29308
63.20000,-10.53331,-4.29683
63.30000,-10.55011,-4.29986
63.40000,-10.56651,-4.30220
63.50000,-10.58331,-4.30536
63.60000,-10.59997,-4.30793
63.70000,-10.61664,-4.31183
63.80000,-10.63344,-4.31574
63.90000,-10.65011,-4.31808
64.00000,-10.66691,-4.32072
64.10001,-10.68331,-4.32454
64.20000,-10.70024,-4.32726
64.30000,-10.71637,-4.32842
64.40000,-10.73331,-4.33394
64.50000,-10.75011,-4.33745
64.60001,-10.76677,-4.34151
64.70000,-10.78371,-4.34565
64.80000,-10.80011,-4.34900
64.90000,-10.81691,-4.35277
65.00000,-10.83331,-4.35522
65.10001,-10.84997,-4.35819
65.20000,-10.86651,-4.36205
65.30000,-10.88344,-4.36617
65.40000,-10.90011,-4.36928
65.50000,-10.91651,-4.37290
65.60001,-10.93357,-4.37577
65.70001,-10.94997,-4.37815
65.80000,-10.96664,-4.38045
65.90000,-10.98317,-4.38257
66.00000,-10.99984,-4.38569
66.10001,-11.01651,-4.38877
66.20001,-11.03331,-4.39158
66.30000,-11.05011,-4.39514
66.40000,-11.06651,-4.39858
66.50000,-11.08344,-4.40196
66.60001,-11.09984,-4.40591
66.70001,-11.11664,-4.41214
66.80000,-11.13331,-4.41501
66.90000,-11.14997,-4.41869
67.00000,-11.16677,-4.42341
67.10001,-11.18344,-4.42755
67.20001,-11.20024,-4.43122
67.30000,-11.21651,-4.43582
67.40000,-11.23344,-4.44113
67.50000,-11.24984,-4.44491
67.60001,-11.26664,-4.45123
67.70001,-11.28344,-4.45442
67.80000,-11.29997,-4.45926
67.90000,-11.31704,-4.46536
68.00000,-11.33331,-4.46797
68.10001,-11.35011,-4.47246
68.20001,-11.36664,-4.47795
68.30000,-11.38331,-4.48164
68.40000,-11.39984,-4.48581
68.50000,-11.41677,-4.49089
68.60001,-11.43344,-4.49387
68.70001,-11.44997,-4.49905
68.80000,-11.46691,-4.50152
68.90000,-11.48331,-4.50536
69.00000,-11.49984,-4.50697
69.10001,-11.51650,-4.51476
69.20001,-11.53317,-4.51942
69.30000,-11.54984,-4.52083
69.40000,-11.56664,-4.52537
69.50000,-11.58344,-4.53165
69.60001,-11.59984,-4.53273
69.70001,-11.61691,-4.53410
69.80000,-11.63317,-4.54005
69.90000,-11.64984,-4.54575
70.00000,-11.66650,-4.54818
70.10001,-11.68317,-4.55074
70.20001,-11.69997,-4.55624
70.30000,-11.71677,-4.56040
70.40000,-11.73344,-4.56069
70.50000,-11.74984,-4.56467
70.60001,-11.76677,-4.56864
70.70001,-11.78330,-4.57218
70.80000,-11.79997,-4.57403
70.90000,-11.81677,-4.57685
71.00000,-11.83330,-4.58385
71.10001,-11.85037,-4.58568
71.20001,-11.86677,-4.58467
71.30000,-11.88344,-4.58886
71.40000,-11.89997,-4.59412
71.50000,-11.91677,-4.59345
71.60001,-11.93317,-4.59484
71.70001,-11.95010,-4.60216
71.80000,-11.96690,-4.60622
71.90000,-11.98330,-4.60663
72.00000,-12.00024,-4.60931
72.10001,-12.01664,-4.61342
72.20001,-12.03330,-4.61707
72.30000,-12.04997,-4.61824
72.40000,-12.06650,-4.62256
72.50000,-12.08317,-4.62756
72.60001,-12.10010,-4.63125
72.70001,-12.11677,-4.63272
72.80000,-12.13330,-4.63752
72.90000,-12.15024,-4.64092
73.00000,-12.16650,-4.64301
73.10001,-12.18317,-4.64499
73.20001,-12.19997,-4.64842
73.30000,-12.21664,-4.64898
73.40000,-12.23344,-4.65104
73.50000,-12.25010,-4.65349
73.60001,-12.26677,-4.65768
73.70001,-12.28317,-4.66292
73.80000,-12.30024,-4.66509
73.90000,-12.31650,-4.66907
74.00000,-12.33317,-4.67365
74.10001,-12.35024,-4.67845
74.20001,-12.36664,-4.68110
74.30000,-12.38370,-4.68548
74.40000,-12.40010,-4.68865
74.50000,-12.41690,-4.69160
74.60001,-12.43344,-4.69501
74.70001,-12.45024,-4.69694
74.80000,-12.46664,-4.69986
74.90000,-12.48330,-4.70426
75.00000,-12.50024,-4.70842
75.10001,-12.51650,-4.71233
75.20001,-12.53357,-4.71768
75.30000,-12.54984,-4.72074
75.40000,-12.56650,-4.72712
75.50000,-12.58317,-4.73202
75.60001,-12.59997,-4.73841
75.70001,-12.61650,-4.74297
75.80000,-12.63330,-4.74959
75.90000,-12.64997,-4.75495
76.00000,-12.66650,-4.76117
76.10001,-12.68357,-4.76665
76.20001,-12.69984,-4.76941
76.30000,-12.71650,-4.77471
76.40000,-12.73330,-4.77837
76.50000,-12.74997,-4.78541
76.60001,-12.76677,-4.79124
76.70001,-12.78357,-4.79769
76.80000,-12.80024,-4.80236
76.90000,-12.81677,-4.81008
77.00000,-12.83344,-4.81517
77.10001,-12.84984,-4.82033
77.20001,-12.86663,-4.82667
77.30000,-12.88357,-4.83250
77.40000,-12.89997,-4.83675
77.50000,-12.91704,-4.84318
77.60001,-12.93343,-4.84741
77.70001,-12.95024,-4.85251
77.80000,-12.96663,-4.85836
77.90000,-12.98330,-4.86344
78.00000,-12.99970,-4.86817
78.10001,-13.01663,-4.87501
78.20001,-13.03343,-4.87936
78.30000,-13.04997,-4.88491
78.40000,-13.06690,-4.89077
78.50000,-13.08330,-4.89542
78.60001,-13.09997,-4.90056
78.70001,-13.11663,-4.90478
78.80000,-13.13317,-4.91076
78.90000,-13.14983,-4.91608
79.00000,-13.16677,-4.92309
79.10001,-13.18357,-4.92844
79.20001,-13.19997,-4.93381
79.30000,-13.21677,-4.93853
79.40000,-13.23317,-4.94150
79.50000,-13.24983,-4.94810
79.60001,-13.26663,-4.95152
79.70001,-13.28330,-4.95767
79.80000,-13.30023,-4.96275
79.90000,-13.31677,-4.96770
80.00000,-13.33357,-4.97233
80.10001,-13.34997,-4.97803
80.20001,-13.36690,-4.98353
80.30000,-13.38317,-4.98691
80.40000,-13.39997,-4.99325
80.50001,-13.41690,-4.99861
80.60001,-13.43330,-5.00472
80.70001,-13.45023,-5.01014
80.80000,-13.46677,-5.01542
80.90000,-13.48357,-5.02082
81.00001,-13.50010,-5.02607
81.10001,-13.51663,-5.03040
81.20001,-13.53317,-5.03401
81.30000,-13.54997,-5.04083
81.40000,-13.56677,-5.04657
81.50001,-13.58330,-5.05350
81.60001,-13.60023,-5.05991
81.70001,-13.61663,-5.06558
81.80000,-13.63330,-5.07229
81.90000,-13.64997,-5.07924
82.00001,-13.66637,-5.08523
82.10001,-13.68317,-5.09262
82.20001,-13.69997,-5.10180
82.30000,-13.71663,-5.10879
82.40000,-13.73317,-5.11633
82.50001,-13.75023,-5.12470
82.60001,-13.76650,-5.12994
82.70001,-13.78317,-5.13733
82.80000,-13.79997,-5.14459
82.90000,-13.81650,-5.15288
83.00001,-13.83343,-5.16175
83.10001,-13.85010,-5.16990
83.20001,-13.86677,-5.17630
83.30000,-13.88330,-5.18394
83.40000,-13.90010,-5.19202
83.50001,-13.91650,-5.20033
83.60001,-13.93330,-5.21028
83.70001,-13.95023,-5.21912
83.80000,-13.96663,-5.22743
83.90000,-13.98357,-5.23654
84.00001,-14.00010,-5.24475
84.10001,-14.01677,-5.25397
84.20001,-14.03330,-5.26279
84.30000,-14.04997,-5.27198
84.40000,-14.06650,-5.27976
84.50001,-14.08343,-5.29082
84.60001,-14.10010,-5.29897
84.70001,-14.11663,-5.30833
84.80000,-14.13357,-5.31713
84.90000,-14.14997,-5.32541
85.00001,-14.16663,-5.33487
85.10001,-14.18330,-5.34327
85.20001,-14.19983,-5.35200
85.30000,-14.21650,-5.36163
85.40000,-14.23330,-5.37273
85.50001,-14.24997,-5.38079
85.60001,-14.26650,-5.39144
85.70001,-14.28356,-5.40107
85.80000,-14.29983,-5.40789
85.90000,-14.31650,-5.41897
86.00001,-14.33317,-5.42677
86.10001,-14.34997,-5.43944
86.20001,-14.36676,-5.44901
86.30000,-14.38343,-5.45919
86.40000,-14.40010,-5.46863
86.50001,-14.41663,-5.47976
86.60001,-14.43343,-5.48799
86.70001,-14.44996,-5.49635
86.80000,-14.46663,-5.50748
86.90000,-14.48343,-5.51684
87.00001,-14.50010,-5.52668
87.10001,-14.51703,-5.53830
87.20001,-14.53356,-5.54738
87.30000,-14.55023,-5.55616
87.40000,-14.56676,-5.56589
87.50001,-14.58343,-5.57467
87.60001,-14.59996,-5.58251
87.70001,-14.61676,-5.59076
87.80000,-14.63343,-5.59850
87.90000,-14.64996,-5.60617
88.00001,-14.66690,-5.61538
88.10001,-14.68330,-5.62310
88.20001,-14.69983,-5.63323
88.30000,-14.71650,-5.64219
88.40000,-14.73303,-5.65116
88.50001,-14.74983,-5.66252
88.60001,-14.76663,-5.67405
88.70001,-14.78343,-5.68357
88.80000,-14.79983,-5.69418
88.90000,-14.81690,-5.70490
89.00001,-14.83303,-5.71177
89.10001,-14.84996,-5.72466
89.20001,-14.86663,-5.73277
89.30000,-14.88330,-5.74407
89.40000,-14.90023,-5.75485
89.50001,-14.91690,-5.76604
89.60001,-14.93356,-5.77508
89.70001,-14.94996,-5.78550
89.80000,-14.96690,-5.79498
89.90000,-14.98330,-5.80320
90.00001,-14.99983,-5.81409
90.09801,-15.01650,-5.82415