File: GFBaking/data/2_8PercentGluten/2_8gluten_Compression.is_comp_RawData/Specimen_RawData_3.csv
Time,Extension,Load
(sec),(mm),(N)
0.00000,0.00000,-0.11406
0.10000,-0.00600,-0.11959
0.20000,-0.02547,-0.14111
0.30000,-0.04560,-0.16499
0.40000,-0.06413,-0.18301
0.50000,-0.08213,-0.20078
0.60000,-0.09920,-0.21708
0.70000,-0.11627,-0.23449
0.80000,-0.13320,-0.25091
0.90000,-0.14987,-0.26888
1.00000,-0.16653,-0.28430
1.10000,-0.18307,-0.29933
1.20000,-0.19973,-0.31547
1.30000,-0.21653,-0.33061
1.40000,-0.23333,-0.34572
1.50000,-0.25000,-0.36170
1.60000,-0.26667,-0.38029
1.70000,-0.28347,-0.39484
1.80000,-0.29973,-0.41041
1.90000,-0.31667,-0.42678
2.00000,-0.33307,-0.44395
2.10000,-0.35000,-0.46091
2.20000,-0.36680,-0.47754
2.30000,-0.38333,-0.49522
2.40000,-0.40013,-0.51401
2.50000,-0.41680,-0.53315
2.60000,-0.43347,-0.54593
2.70000,-0.44973,-0.56196
2.80000,-0.46653,-0.57770
2.90000,-0.48320,-0.59597
3.00000,-0.49987,-0.61473
3.10000,-0.51693,-0.63301
3.20000,-0.53333,-0.65031
3.30000,-0.55000,-0.66951
3.40000,-0.56667,-0.68796
3.50000,-0.58333,-0.70435
3.60000,-0.59973,-0.72443
3.70000,-0.61667,-0.74231
3.80000,-0.63333,-0.75950
3.90000,-0.65000,-0.77927
4.00000,-0.66680,-0.79717
4.10000,-0.68320,-0.81446
4.20000,-0.70000,-0.83108
4.30000,-0.71640,-0.84982
4.40000,-0.73320,-0.87103
4.50000,-0.74986,-0.88891
4.60000,-0.76666,-0.90625
4.70000,-0.78333,-0.92584
4.80000,-0.80000,-0.94388
4.90000,-0.81693,-0.96211
5.00000,-0.83320,-0.98136
5.10000,-0.85000,-1.00077
5.20000,-0.86640,-1.01759
5.30000,-0.88333,-1.03567
5.40000,-0.90000,-1.05448
5.50000,-0.91666,-1.07567
5.60000,-0.93346,-1.09560
5.70000,-0.95000,-1.11358
5.80000,-0.96680,-1.13226
5.90000,-0.98306,-1.15076
6.00000,-1.00000,-1.17011
6.10000,-1.01666,-1.18866
6.20000,-1.03333,-1.20812
6.30000,-1.05013,-1.22730
6.40000,-1.06666,-1.24556
6.50000,-1.08346,-1.26338
6.60000,-1.10000,-1.28230
6.70000,-1.11653,-1.30089
6.80000,-1.13293,-1.31942
6.90000,-1.15013,-1.33781
7.00000,-1.16666,-1.35599
7.10000,-1.18333,-1.37611
7.20000,-1.20013,-1.39442
7.30000,-1.21640,-1.41322
7.40000,-1.23333,-1.43191
7.50000,-1.24986,-1.45090
7.60000,-1.26640,-1.46896
7.70000,-1.28320,-1.48869
7.80000,-1.30013,-1.50743
7.90000,-1.31666,-1.52654
8.00000,-1.33346,-1.54551
8.10000,-1.35013,-1.56422
8.20000,-1.36653,-1.58320
8.30000,-1.38320,-1.60176
8.40000,-1.39973,-1.62012
8.50000,-1.41666,-1.63949
8.60000,-1.43333,-1.65874
8.70000,-1.45000,-1.67742
8.80000,-1.46680,-1.69677
8.90000,-1.48346,-1.71585
9.00000,-1.50013,-1.73392
9.10000,-1.51640,-1.75163
9.20000,-1.53333,-1.76956
9.30000,-1.55000,-1.78768
9.40000,-1.56666,-1.80630
9.50000,-1.58360,-1.82482
9.60000,-1.60000,-1.84295
9.70000,-1.61680,-1.86115
9.80000,-1.63333,-1.87893
9.90000,-1.65000,-1.89654
10.00000,-1.66640,-1.91439
10.10000,-1.68333,-1.93246
10.20000,-1.70000,-1.94991
10.30000,-1.71666,-1.96720
10.40000,-1.73346,-1.98601
10.50000,-1.74986,-2.00404
10.60000,-1.76653,-2.02117
10.70000,-1.78293,-2.03753
10.80000,-1.79973,-2.05479
10.90000,-1.81653,-2.07082
11.00000,-1.83346,-2.08192
11.10000,-1.85000,-2.10081
11.20000,-1.86666,-2.11065
11.30000,-1.88346,-2.11231
11.40000,-1.89986,-2.11127
11.50000,-1.91666,-2.10790
11.60000,-1.93306,-2.10601
11.70000,-1.95000,-2.10856
11.80000,-1.96680,-2.10724
11.90000,-1.98333,-2.10984
12.00000,-2.00013,-2.11290
12.10000,-2.01680,-2.11449
12.20000,-2.03346,-2.12225
12.30000,-2.04986,-2.12838
12.40000,-2.06653,-2.12046
12.50000,-2.08333,-2.13084
12.60000,-2.09999,-2.13933
12.70000,-2.11693,-2.16177
12.80000,-2.13346,-2.18425
12.90000,-2.15026,-2.20445
13.00000,-2.16666,-2.22339
13.10000,-2.18333,-2.24248
13.20000,-2.19973,-2.26331
13.30000,-2.21666,-2.28132
13.40000,-2.23319,-2.30284
13.50000,-2.24999,-2.32274
13.60000,-2.26679,-2.34228
13.70000,-2.28319,-2.35945
13.80000,-2.29986,-2.38050
13.90000,-2.31639,-2.39777
14.00000,-2.33319,-2.41460
14.10000,-2.34986,-2.43466
14.20000,-2.36666,-2.45161
14.30000,-2.38333,-2.46737
14.40000,-2.39999,-2.48706
14.50000,-2.41693,-2.50718
14.60000,-2.43319,-2.52174
14.70000,-2.44999,-2.54110
14.80000,-2.46653,-2.55641
14.90000,-2.48346,-2.57555
15.00000,-2.50026,-2.58940
15.10000,-2.51679,-2.60593
15.20000,-2.53346,-2.62168
15.30000,-2.55013,-2.63977
15.40000,-2.56693,-2.65863
15.50000,-2.58306,-2.67485
15.60000,-2.59986,-2.68639
15.70000,-2.61653,-2.70192
15.80000,-2.63319,-2.72330
15.90000,-2.65013,-2.73705
16.00000,-2.66666,-2.75547
16.10000,-2.68333,-2.76960
16.20000,-2.69986,-2.78526
16.30000,-2.71653,-2.80195
16.40000,-2.73293,-2.81864
16.50000,-2.74999,-2.83648
16.60000,-2.76666,-2.85051
16.70000,-2.78319,-2.86523
16.80000,-2.80013,-2.88085
16.90000,-2.81653,-2.89700
17.00000,-2.83319,-2.91056
17.10000,-2.84986,-2.92659
17.20000,-2.86653,-2.94162
17.30000,-2.88319,-2.95617
17.40000,-2.90013,-2.97251
17.50000,-2.91666,-2.98628
17.60000,-2.93333,-3.00362
17.70000,-2.95026,-3.01753
17.80000,-2.96653,-3.03211
17.90000,-2.98333,-3.04791
18.00000,-2.99986,-3.06242
18.10000,-3.01653,-3.07893
18.20000,-3.03346,-3.09319
18.30000,-3.05013,-3.10816
18.40000,-3.06679,-3.12367
18.50000,-3.08346,-3.13959
18.60000,-3.09999,-3.15298
18.70000,-3.11626,-3.16804
18.80000,-3.13319,-3.18203
18.90000,-3.14986,-3.19629
19.00000,-3.16653,-3.21166
19.10000,-3.18346,-3.22669
19.20000,-3.19999,-3.24093
19.30000,-3.21666,-3.25627
19.40000,-3.23333,-3.26975
19.50000,-3.24999,-3.28422
19.60000,-3.26653,-3.29872
19.70000,-3.28346,-3.31572
19.80000,-3.30013,-3.32812
19.90000,-3.31679,-3.34236
20.00000,-3.33359,-3.35605
20.10000,-3.34999,-3.36963
20.20000,-3.36666,-3.38366
20.30000,-3.38306,-3.39801
20.40000,-3.39973,-3.40959
20.50000,-3.41652,-3.42377
20.60000,-3.43332,-3.43620
20.70000,-3.44999,-3.45110
20.80000,-3.46666,-3.46696
20.90000,-3.48359,-3.47958
21.00000,-3.49986,-3.49414
21.10000,-3.51666,-3.50791
21.20000,-3.53319,-3.52792
21.30000,-3.54999,-3.53997
21.40000,-3.56679,-3.55091
21.50000,-3.58346,-3.56611
21.60000,-3.60012,-3.57963
21.70000,-3.61679,-3.59587
21.80000,-3.63346,-3.61256
21.90000,-3.64972,-3.62384
22.00000,-3.66666,-3.63848
22.10000,-3.68319,-3.64615
22.20000,-3.69999,-3.66004
22.30000,-3.71692,-3.67083
22.40000,-3.73319,-3.67859
22.50000,-3.75012,-3.69666
22.60000,-3.76652,-3.70653
22.70000,-3.78319,-3.71246
22.80000,-3.79959,-3.72233
22.90000,-3.81666,-3.73508
23.00000,-3.83319,-3.74964
23.10000,-3.84986,-3.76452
23.20000,-3.86679,-3.76765
23.30000,-3.88319,-3.77812
23.40000,-3.89999,-3.79318
23.50000,-3.91652,-3.80468
23.60000,-3.93306,-3.81738
23.70000,-3.94986,-3.82944
23.80000,-3.96666,-3.84599
23.90000,-3.98332,-3.86305
24.00000,-3.99999,-3.87297
24.10000,-4.01679,-3.88304
24.20000,-4.03306,-3.89425
24.30000,-4.04986,-3.90482
24.40000,-4.06639,-3.91122
24.50000,-4.08319,-3.92159
24.60000,-4.09999,-3.93436
24.70000,-4.11679,-3.94343
24.80000,-4.13346,-3.95261
24.90000,-4.15012,-3.96354
25.00000,-4.16679,-3.97646
25.10000,-4.18306,-3.98697
25.20000,-4.19999,-3.99704
25.30000,-4.21652,-4.00928
25.40000,-4.23332,-4.02444
25.50000,-4.25026,-4.03247
25.60000,-4.26666,-4.04558
25.70000,-4.28346,-4.05773
25.80000,-4.29999,-4.06366
25.90000,-4.31679,-4.07410
26.00000,-4.33306,-4.08407
26.10000,-4.35012,-4.09576
26.20000,-4.36652,-4.10497
26.30000,-4.38319,-4.11542
26.40000,-4.39999,-4.12393
26.50000,-4.41652,-4.13378
26.60000,-4.43319,-4.14280
26.70000,-4.44972,-4.15209
26.80000,-4.46652,-4.16147
26.90000,-4.48319,-4.17022
27.00000,-4.50012,-4.18012
27.10000,-4.51666,-4.18845
27.20000,-4.53332,-4.19759
27.30000,-4.55026,-4.20655
27.40000,-4.56652,-4.21407
27.50000,-4.58332,-4.22427
27.60000,-4.59972,-4.23330
27.70000,-4.61666,-4.24365
27.80000,-4.63332,-4.25214
27.90000,-4.64999,-4.26069
28.00000,-4.66679,-4.26952
28.10000,-4.68346,-4.27878
28.20000,-4.69999,-4.28649
28.30000,-4.71639,-4.29392
28.40000,-4.73346,-4.30332
28.50000,-4.74986,-4.31027
28.60000,-4.76666,-4.31933
28.70000,-4.78346,-4.32670
28.80000,-4.79999,-4.33557
28.90000,-4.81679,-4.34164
29.00000,-4.83332,-4.34907
29.10000,-4.85012,-4.35651
29.20000,-4.86652,-4.36263
29.30000,-4.88332,-4.36960
29.40000,-4.89985,-4.37602
29.50000,-4.91665,-4.38495
29.60000,-4.93345,-4.39045
29.70000,-4.94985,-4.39785
29.80000,-4.96652,-4.40491
29.90000,-4.98305,-4.41170
30.00000,-4.99985,-4.41826
30.10000,-5.01652,-4.42505
30.20000,-5.03332,-4.43225
30.30000,-5.04999,-4.43732
30.40000,-5.06665,-4.44625
30.50000,-5.08345,-4.45193
30.60000,-5.09972,-4.45896
30.70000,-5.11665,-4.46600
30.80000,-5.13305,-4.47277
30.90000,-5.14999,-4.48079
31.00000,-5.16679,-4.48780
31.10000,-5.18345,-4.49479
31.20000,-5.20012,-4.50148
31.30000,-5.21679,-4.50852
31.40000,-5.23345,-4.51501
31.50000,-5.24972,-4.52160
31.60000,-5.26665,-4.52976
31.70000,-5.28319,-4.53381
31.80000,-5.29999,-4.54207
31.90000,-5.31692,-4.54706
32.00000,-5.33332,-4.55273
32.10000,-5.34999,-4.55945
32.20000,-5.36665,-4.56691
32.30000,-5.38332,-4.57387
32.40000,-5.39959,-4.57937
32.50000,-5.41665,-4.58563
32.60000,-5.43319,-4.59149
32.70000,-5.44985,-4.59918
32.80000,-5.46679,-4.60534
32.90000,-5.48319,-4.61098
33.00000,-5.50012,-4.61751
33.10000,-5.51652,-4.62321
33.20000,-5.53319,-4.62890
33.30000,-5.54985,-4.63537
33.40000,-5.56665,-4.64331
33.50000,-5.58332,-4.64884
33.60000,-5.60012,-4.65629
33.70000,-5.61679,-4.66354
33.80000,-5.63319,-4.66958
33.90000,-5.64999,-4.67655
34.00000,-5.66639,-4.68295
34.10000,-5.68332,-4.68993
34.20000,-5.69999,-4.69623
34.30000,-5.71665,-4.70249
34.40000,-5.73345,-4.71078
34.50000,-5.74999,-4.71790
34.60000,-5.76679,-4.72348
34.70000,-5.78305,-4.73048
34.80000,-5.80012,-4.73634
34.90000,-5.81665,-4.74301
35.00000,-5.83332,-4.74882
35.10000,-5.85025,-4.75450
35.20000,-5.86665,-4.76156
35.30000,-5.88332,-4.76778
35.40000,-5.89999,-4.77318
35.50000,-5.91665,-4.77935
35.60000,-5.93305,-4.78661
35.70000,-5.94999,-4.79390
35.80000,-5.96652,-4.79847
35.90000,-5.98332,-4.80488
36.00000,-6.00012,-4.80864
36.10000,-6.01652,-4.81412
36.20000,-6.03332,-4.81912
36.30000,-6.04985,-4.82252
36.40000,-6.06639,-4.82781
36.50000,-6.08319,-4.83633
36.60000,-6.09998,-4.84418
36.70000,-6.11665,-4.84898
36.80000,-6.13332,-4.85673
36.90000,-6.15012,-4.86590
37.00000,-6.16652,-4.87165
37.10000,-6.18332,-4.88924
37.20000,-6.19972,-4.88760
37.30000,-6.21652,-4.89401
37.40000,-6.23332,-4.90066
37.50000,-6.25012,-4.90180
37.60000,-6.26678,-4.90780
37.70000,-6.28345,-4.91374
37.80000,-6.29998,-4.91930
37.90000,-6.31638,-4.92559
38.00000,-6.33332,-4.93203
38.10000,-6.34998,-4.93920
38.20000,-6.36665,-4.94371
38.30000,-6.38358,-4.94536
38.40000,-6.39998,-4.95069
38.50000,-6.41678,-4.95731
38.60000,-6.43318,-4.96237
38.70000,-6.44998,-4.96801
38.80000,-6.46652,-4.97263
38.90000,-6.48345,-4.97632
39.00000,-6.49998,-4.97776
39.10000,-6.51665,-4.98167
39.20000,-6.53345,-4.98738
39.30000,-6.54985,-4.99233
39.40000,-6.56665,-4.99638
39.50000,-6.58305,-4.99890
39.60000,-6.59972,-5.00297
39.70000,-6.61652,-5.00732
39.80000,-6.63332,-5.01225
39.90000,-6.64998,-5.01441
40.00000,-6.66665,-5.02012
40.10000,-6.68345,-5.02297
40.20000,-6.69985,-5.02639
40.30000,-6.71665,-5.03072
40.40000,-6.73305,-5.03518
40.50000,-6.74998,-5.04120
40.60000,-6.76665,-5.04606
40.70000,-6.78332,-5.04965
40.80000,-6.79998,-5.05427
40.90000,-6.81665,-5.06008
41.00000,-6.83332,-5.06388
41.10000,-6.84985,-5.06919
41.20000,-6.86678,-5.07452
41.30000,-6.88345,-5.07744
41.40000,-6.89998,-5.08212
41.50000,-6.91692,-5.08585
41.60000,-6.93345,-5.08987
41.70000,-6.95012,-5.09241
41.80000,-6.96665,-5.09560
41.90000,-6.98332,-5.09937
42.00000,-6.99985,-5.10176
42.10000,-7.01665,-5.10440
42.20000,-7.03318,-5.10844
42.30000,-7.04985,-5.11304
42.40000,-7.06678,-5.11546
42.50000,-7.08305,-5.11874
42.60000,-7.09985,-5.12141
42.70000,-7.11652,-5.12750
42.80000,-7.13318,-5.13006
42.90000,-7.14985,-5.13475
43.00000,-7.16665,-5.13950
43.10000,-7.18345,-5.14376
43.20000,-7.20012,-5.14997
43.30000,-7.21678,-5.15366
43.40000,-7.23318,-5.15723
43.50000,-7.24998,-5.15875
43.60000,-7.26638,-5.16261
43.70000,-7.28332,-5.16604
43.80000,-7.30025,-5.16907
43.90000,-7.31665,-5.17128
44.00000,-7.33345,-5.17582
44.10000,-7.35012,-5.18118
44.20000,-7.36665,-5.18369
44.30000,-7.38305,-5.18792
44.40000,-7.39985,-5.18948
44.50000,-7.41652,-5.19289
44.60000,-7.43318,-5.19938
44.70000,-7.45025,-5.20414
44.80000,-7.46665,-5.20749
44.90000,-7.48345,-5.21175
45.00000,-7.50011,-5.21416
45.10000,-7.51665,-5.21588
45.20000,-7.53305,-5.22020
45.30000,-7.54998,-5.22300
45.40000,-7.56651,-5.22665
45.50000,-7.58332,-5.23102
45.60000,-7.60011,-5.23450
45.70000,-7.61651,-5.23697
45.80000,-7.63331,-5.24181
45.90000,-7.64971,-5.24495
46.00000,-7.66638,-5.24740
46.10000,-7.68318,-5.25298
46.20000,-7.69998,-5.25587
46.30000,-7.71678,-5.26003
46.40000,-7.73331,-5.26311
46.50000,-7.74998,-5.26637
46.60000,-7.76638,-5.26835
46.70000,-7.78331,-5.27316
46.80000,-7.79971,-5.27615
46.90000,-7.81665,-5.28028
47.00000,-7.83345,-5.28383
47.10000,-7.85011,-5.28616
47.20000,-7.86678,-5.29017
47.30000,-7.88331,-5.29259
47.40000,-7.89998,-5.29517
47.50000,-7.91651,-5.29809
47.60000,-7.93331,-5.30327
47.70000,-7.94985,-5.30580
47.80000,-7.96665,-5.31081
47.90000,-7.98358,-5.31467
48.00000,-7.99998,-5.31522
48.10000,-8.01678,-5.32086
48.20000,-8.03331,-5.32433
48.30000,-8.04998,-5.32661
48.40000,-8.06638,-5.32905
48.50000,-8.08331,-5.33039
48.60000,-8.09998,-5.33282
48.70000,-8.11665,-5.33777
48.80000,-8.13345,-5.33852
48.90000,-8.14985,-5.34039
49.00000,-8.16665,-5.34286
49.10000,-8.18318,-5.34635
49.20000,-8.19985,-5.35004
49.30000,-8.21651,-5.35388
49.40000,-8.23345,-5.35844
49.50000,-8.24998,-5.35837
49.60000,-8.26678,-5.36444
49.70000,-8.28345,-5.36819
49.80000,-8.29985,-5.37010
49.90000,-8.31665,-5.37209
50.00000,-8.33305,-5.37465
50.10000,-8.34998,-5.37633
50.20000,-8.36665,-5.37680
50.30000,-8.38318,-5.37535
50.40000,-8.39985,-5.37830
50.50000,-8.41651,-5.38349
50.60000,-8.43331,-5.38867
50.70000,-8.44971,-5.39386
50.80000,-8.46665,-5.39956
50.90000,-8.48331,-5.40207
51.00000,-8.49998,-5.41040
51.10000,-8.51691,-5.41148
51.20000,-8.53345,-5.41267
51.30000,-8.55011,-5.41657
51.40000,-8.56665,-5.41863
51.50000,-8.58345,-5.42278
51.60000,-8.59985,-5.42738
51.70000,-8.61678,-5.43353
51.80000,-8.63331,-5.43529
51.90000,-8.64998,-5.43474
52.00000,-8.66678,-5.43675
52.10000,-8.68318,-5.44024
52.20000,-8.69998,-5.44529
52.30000,-8.71638,-5.45059
52.40000,-8.73318,-5.45901
52.50000,-8.74985,-5.46438
52.60000,-8.76665,-5.46480
52.70000,-8.78331,-5.46772
52.80000,-8.79998,-5.47110
52.90000,-8.81678,-5.47377
53.00000,-8.83318,-5.47519
53.10000,-8.84998,-5.47685
53.20000,-8.86651,-5.47832
53.30000,-8.88331,-5.48256
53.40000,-8.90011,-5.48727
53.50000,-8.91678,-5.48989
53.60000,-8.93345,-5.49342
53.70000,-8.95011,-5.49979
53.80000,-8.96678,-5.50300
53.90000,-8.98318,-5.50613
54.00000,-8.99998,-5.50676
54.10000,-9.01651,-5.50902
54.20000,-9.03331,-5.51357
54.30000,-9.05011,-5.51559
54.40000,-9.06651,-5.51691
54.50000,-9.08331,-5.51991
54.60000,-9.09998,-5.52066
54.70000,-9.11678,-5.52163
54.80000,-9.13304,-5.52128
54.90000,-9.15011,-5.52559
55.00000,-9.16664,-5.52825
55.10000,-9.18318,-5.53236
55.20000,-9.20011,-5.53533
55.30000,-9.21664,-5.53877
55.40000,-9.23331,-5.53984
55.50000,-9.24971,-5.54155
55.60000,-9.26651,-5.54548
55.70000,-9.28318,-5.54905
55.80000,-9.29998,-5.55132
55.90000,-9.31664,-5.55027
56.00000,-9.33331,-5.55373
56.10000,-9.35011,-5.55316
56.20000,-9.36651,-5.55393
56.30000,-9.38331,-5.55499
56.40000,-9.39971,-5.55533
56.50000,-9.41664,-5.55869
56.60000,-9.43344,-5.56033
56.70000,-9.45011,-5.56310
56.80000,-9.46678,-5.56680
56.90000,-9.48344,-5.56878
57.00000,-9.50011,-5.56945
57.10000,-9.51638,-5.57124
57.20000,-9.53331,-5.57470
57.30000,-9.54984,-5.57788
57.40000,-9.56664,-5.58026
57.50000,-9.58344,-5.58156
57.60000,-9.59998,-5.58270
57.70000,-9.61678,-5.58407
57.80000,-9.63331,-5.58651
57.90000,-9.65011,-5.58954
58.00000,-9.66638,-5.59099
58.10000,-9.68331,-5.59257
58.20000,-9.69984,-5.59478
58.30000,-9.71664,-5.59815
58.40000,-9.73344,-5.59852
58.50000,-9.74971,-5.59973
58.60000,-9.76664,-5.60119
58.70000,-9.78318,-5.60278
58.80000,-9.79984,-5.60425
58.90000,-9.81651,-5.60512
59.00000,-9.83331,-5.60552
59.10000,-9.84998,-5.60631
59.20000,-9.86664,-5.60803
59.30000,-9.88344,-5.60840
59.40000,-9.89984,-5.61041
59.50000,-9.91678,-5.61229
59.60000,-9.93304,-5.61225
59.70000,-9.94998,-5.61491
59.80000,-9.96678,-5.61642
59.90000,-9.98344,-5.61832
60.00000,-10.00011,-5.61931
60.10000,-10.01678,-5.62157
60.20000,-10.03358,-5.62261
60.30000,-10.04971,-5.62442
60.40000,-10.06664,-5.62948
60.50000,-10.08331,-5.63039
60.60000,-10.09998,-5.63277
60.70000,-10.11678,-5.63506
60.80000,-10.13344,-5.63430
60.90000,-10.15011,-5.63645
61.00000,-10.16678,-5.63938
61.10000,-10.18331,-5.64005
61.20000,-10.19971,-5.64144
61.30000,-10.21678,-5.64552
61.40000,-10.23318,-5.64673
61.50000,-10.24998,-5.65065
61.60000,-10.26678,-5.65213
61.70000,-10.28331,-5.65386
61.80000,-10.30011,-5.65653
61.90000,-10.31651,-5.65865
62.00000,-10.33317,-5.65896
62.10000,-10.34984,-5.66196
62.20000,-10.36664,-5.66417
62.30000,-10.38331,-5.66459
62.40000,-10.39997,-5.66712
62.50000,-10.41678,-5.66736
62.60000,-10.43317,-5.66817
62.70000,-10.45011,-5.67080
62.80000,-10.46651,-5.67036
62.90000,-10.48331,-5.67231
63.00000,-10.49997,-5.67346
63.10000,-10.51677,-5.67465
63.20000,-10.53344,-5.67616
63.30000,-10.55011,-5.67788
63.40000,-10.56677,-5.67804
63.50000,-10.58317,-5.67950
63.60000,-10.60011,-5.68174
63.70000,-10.61664,-5.68282
63.80000,-10.63331,-5.68607
63.90000,-10.65024,-5.68689
64.00000,-10.66664,-5.68772
64.10001,-10.68344,-5.68956
64.20000,-10.69997,-5.69120
64.30000,-10.71677,-5.69218
64.40000,-10.73304,-5.69362
64.50000,-10.75011,-5.69576
64.60001,-10.76651,-5.69627
64.70000,-10.78317,-5.69797
64.80000,-10.80011,-5.69885
64.90000,-10.81651,-5.70040
65.00000,-10.83331,-5.70235
65.10001,-10.84971,-5.70320
65.20000,-10.86651,-5.70453
65.30000,-10.88317,-5.70692
65.40000,-10.89997,-5.70928
65.50000,-10.91664,-5.71058
65.60001,-10.93344,-5.71324
65.70001,-10.95024,-5.71454
65.80000,-10.96651,-5.71520
65.90000,-10.98344,-5.71720
66.00000,-10.99984,-5.71800
66.10001,-11.01664,-5.72028
66.20001,-11.03344,-5.72243
66.30000,-11.04997,-5.72368
66.40000,-11.06651,-5.72416
66.50000,-11.08331,-5.72705
66.60001,-11.10011,-5.72727
66.70001,-11.11651,-5.72874
66.80000,-11.13331,-5.72910
66.90000,-11.14997,-5.72908
67.00000,-11.16677,-5.73210
67.10001,-11.18357,-5.73314
67.20001,-11.20011,-5.73412
67.30000,-11.21677,-5.73431
67.40000,-11.23331,-5.73512
67.50000,-11.25011,-5.73574
67.60001,-11.26651,-5.73658
67.70001,-11.28357,-5.73795
67.80000,-11.30011,-5.73737
67.90000,-11.31677,-5.73998
68.00000,-11.33344,-5.73974
68.10001,-11.34997,-5.74128
68.20001,-11.36677,-5.74295
68.30000,-11.38317,-5.74377
68.40000,-11.39971,-5.74406
68.50000,-11.41664,-5.74597
68.60001,-11.43344,-5.74791
68.70001,-11.44997,-5.74872
68.80000,-11.46677,-5.75286
68.90000,-11.48344,-5.75346
69.00000,-11.49984,-5.75588
69.10001,-11.51677,-5.75902
69.20001,-11.53317,-5.76178
69.30000,-11.55011,-5.76660
69.40000,-11.56677,-5.77048
69.50000,-11.58344,-5.77468
69.60001,-11.60011,-5.77885
69.70001,-11.61664,-5.78424
69.80000,-11.63344,-5.78798
69.90000,-11.64984,-5.79246
70.00000,-11.66664,-5.79648
70.10001,-11.68330,-5.80140
70.20001,-11.69984,-5.80611
70.30000,-11.71677,-5.80950
70.40000,-11.73330,-5.81406
70.50000,-11.75010,-5.81890
70.60001,-11.76677,-5.82247
70.70001,-11.78371,-5.82802
70.80000,-11.79984,-5.83162
70.90000,-11.81677,-5.83677
71.00000,-11.83330,-5.84180
71.10001,-11.84997,-5.84876
71.20001,-11.86690,-5.85409
71.30000,-11.88317,-5.85933
71.40000,-11.89997,-5.86480
71.50000,-11.91637,-5.86960
71.60001,-11.93317,-5.87584
71.70001,-11.94984,-5.88256
71.80000,-11.96664,-5.88799
71.90000,-11.98330,-5.89252
72.00000,-11.99997,-5.90109
72.10001,-12.01690,-5.90602
72.20001,-12.03317,-5.91092
72.30000,-12.04997,-5.91732
72.40000,-12.06637,-5.92215
72.50000,-12.08344,-5.93138
72.60001,-12.10024,-5.93784
72.70001,-12.11677,-5.94405
72.80000,-12.13344,-5.94993
72.90000,-12.15024,-5.95767
73.00000,-12.16677,-5.96292
73.10001,-12.18317,-5.96933
73.20001,-12.19997,-5.97625
73.30000,-12.21664,-5.98101
73.40000,-12.23330,-5.98761
73.50000,-12.25024,-5.99178
73.60001,-12.26677,-5.99806
73.70001,-12.28344,-6.00437
73.80000,-12.30010,-6.01062
73.90000,-12.31677,-6.01633
74.00000,-12.33304,-6.02210
74.10001,-12.34997,-6.02907
74.20001,-12.36664,-6.03350
74.30000,-12.38330,-6.03953
74.40000,-12.40010,-6.04320
74.50000,-12.41650,-6.05092
74.60001,-12.43330,-6.05619
74.70001,-12.44984,-6.06195
74.80000,-12.46650,-6.06648
74.90000,-12.48317,-6.07275
75.00000,-12.50010,-6.07933
75.10001,-12.51677,-6.08433
75.20001,-12.53344,-6.09031
75.30000,-12.55010,-6.09327
75.40000,-12.56650,-6.09881
75.50000,-12.58330,-6.10510
75.60001,-12.59970,-6.11003
75.70001,-12.61664,-6.11614
75.80000,-12.63357,-6.12296
75.90000,-12.65010,-6.12803
76.00000,-12.66677,-6.13448
76.10001,-12.68344,-6.14118
76.20001,-12.70024,-6.14815
76.30000,-12.71650,-6.15389
76.40000,-12.73330,-6.16158
76.50000,-12.74997,-6.16738
76.60001,-12.76664,-6.17458
76.70001,-12.78357,-6.17997
76.80000,-12.79997,-6.18426
76.90000,-12.81677,-6.19222
77.00000,-12.83344,-6.19746
77.10001,-12.84997,-6.20358
77.20001,-12.86650,-6.20915
77.30000,-12.88330,-6.21643
77.40000,-12.89997,-6.22248
77.50000,-12.91663,-6.23244
77.60001,-12.93357,-6.23817
77.70001,-12.94997,-6.24538
77.80000,-12.96677,-6.25371
77.90000,-12.98317,-6.26035
78.00000,-12.99970,-6.26851
78.10001,-13.01650,-6.27555
78.20001,-13.03330,-6.28647
78.30000,-13.04997,-6.29370
78.40000,-13.06663,-6.30481
78.50000,-13.08343,-6.31314
78.60001,-13.09983,-6.32209
78.70001,-13.11663,-6.33096
78.80000,-13.13317,-6.33744
78.90000,-13.14997,-6.34571
79.00000,-13.16677,-6.35496
79.10001,-13.18343,-6.36376
79.20001,-13.20010,-6.37099
79.30000,-13.21677,-6.37841
79.40000,-13.23343,-6.38541
79.50000,-13.24970,-6.39404
79.60001,-13.26663,-6.40210
79.70001,-13.28330,-6.40858
79.80000,-13.29997,-6.41617
79.90000,-13.31690,-6.42358
80.00000,-13.33330,-6.43044
80.10001,-13.35010,-6.43907
80.20001,-13.36663,-6.44536
80.30000,-13.38330,-6.45158
80.40000,-13.39970,-6.45852
80.50001,-13.41677,-6.46601
80.60001,-13.43330,-6.47237
80.70001,-13.44997,-6.48102
80.80000,-13.46690,-6.48661
80.90000,-13.48317,-6.49370
81.00001,-13.49983,-6.49999
81.10001,-13.51650,-6.50756
81.20001,-13.53317,-6.51460
81.30000,-13.54970,-6.52221
81.40000,-13.56663,-6.52929
81.50001,-13.58330,-6.53564
81.60001,-13.60010,-6.54444
81.70001,-13.61690,-6.55056
81.80000,-13.63330,-6.55779
81.90000,-13.64997,-6.56659
82.00001,-13.66650,-6.57223
82.10001,-13.68330,-6.58323
82.20001,-13.70010,-6.59131
82.30000,-13.71663,-6.59892
82.40000,-13.73343,-6.60714
82.50001,-13.75010,-6.61643
82.60001,-13.76690,-6.62457
82.70001,-13.78317,-6.63204
82.80000,-13.80010,-6.64096
82.90000,-13.81663,-6.64780
83.00001,-13.83343,-6.65828
83.10001,-13.85023,-6.66603
83.20001,-13.86677,-6.67361
83.30000,-13.88357,-6.68317
83.40000,-13.90010,-6.69204
83.50001,-13.91677,-6.69972
83.60001,-13.93317,-6.70956
83.70001,-13.95010,-6.71913
83.80000,-13.96663,-6.72796
83.90000,-13.98330,-6.73741
84.00001,-14.00023,-6.74595
84.10001,-14.01650,-6.75486
84.20001,-14.03317,-6.76381
84.30000,-14.04970,-6.77202
84.40000,-14.06637,-6.77959
84.50001,-14.08317,-6.79045
84.60001,-14.09983,-6.79959
84.70001,-14.11650,-6.80806
84.80000,-14.13330,-6.81952
84.90000,-14.15010,-6.82779
85.00001,-14.16650,-6.83692
85.10001,-14.18343,-6.84805
85.20001,-14.19983,-6.85545
85.30000,-14.21663,-6.86622
85.40000,-14.23356,-6.87559
85.50001,-14.25010,-6.88504
85.60001,-14.26690,-6.89355
85.70001,-14.28356,-6.90396
85.80000,-14.30010,-6.91233
85.90000,-14.31650,-6.92105
86.00001,-14.33330,-6.93022
86.10001,-14.34997,-6.93896
86.20001,-14.36663,-6.94946
86.30000,-14.38343,-6.95895
86.40000,-14.39996,-6.96811
86.50001,-14.41690,-6.97974
86.60001,-14.43343,-6.98822
86.70001,-14.44996,-6.99600
86.80000,-14.46636,-7.00518
86.90000,-14.48330,-7.01462
87.00001,-14.49983,-7.02315
87.10001,-14.51663,-7.03553
87.20001,-14.53343,-7.04161
87.30000,-14.54996,-7.05163
87.40000,-14.56663,-7.06099
87.50001,-14.58316,-7.07050
87.60001,-14.59983,-7.08077
87.70001,-14.61650,-7.09059
87.80000,-14.63343,-7.10093
87.90000,-14.64996,-7.10906
88.00001,-14.66663,-7.11991
88.10001,-14.68356,-7.12853
88.20001,-14.69983,-7.13736
88.30000,-14.71676,-7.14808
88.40000,-14.73316,-7.15572
88.50001,-14.74996,-7.16642
88.60001,-14.76676,-7.17571
88.70001,-14.78343,-7.18584
88.80000,-14.80010,-7.19600
88.90000,-14.81676,-7.20706
89.00001,-14.83343,-7.21523
89.10001,-14.84983,-7.22436
89.20001,-14.86676,-7.23677
89.30000,-14.88330,-7.24490
89.40000,-14.89996,-7.25861
89.50001,-14.91690,-7.26810
89.60001,-14.93343,-7.27619
89.70001,-14.95010,-7.28624
89.80000,-14.96663,-7.29677
89.90000,-14.98330,-7.30496
90.00001,-14.99970,-7.31542
90.10001,-15.01663,-7.32583
90.20001,-15.03330,-7.33353
90.30000,-15.04983,-7.34436
90.36601,-15.06090,-7.35296