File: GFBaking/data/2_8PercentGluten/2_8gluten_Compression.is_comp_RawData/Specimen_RawData_2.csv
Time,Extension,Load
(sec),(mm),(N)
0.00000,0.00000,-0.20209
0.10000,-0.00533,-0.20502
0.20000,-0.02493,-0.22803
0.30000,-0.04533,-0.25278
0.40000,-0.06387,-0.27425
0.50000,-0.08160,-0.29297
0.60000,-0.09907,-0.31134
0.70000,-0.11573,-0.32799
0.80000,-0.13293,-0.34592
0.90000,-0.15000,-0.36282
1.00000,-0.16653,-0.37986
1.10000,-0.18333,-0.39630
1.20000,-0.20013,-0.41377
1.30000,-0.21680,-0.43091
1.40000,-0.23307,-0.44793
1.50000,-0.25000,-0.46632
1.60000,-0.26640,-0.48282
1.70000,-0.28333,-0.50191
1.80000,-0.30000,-0.51876
1.90000,-0.31653,-0.53833
2.00000,-0.33347,-0.55588
2.10000,-0.34987,-0.57556
2.20000,-0.36667,-0.59352
2.30000,-0.38307,-0.61244
2.40000,-0.40000,-0.63111
2.50000,-0.41653,-0.64991
2.60000,-0.43333,-0.66899
2.70000,-0.45013,-0.68757
2.80000,-0.46653,-0.70691
2.90000,-0.48320,-0.72596
3.00000,-0.49987,-0.74489
3.10000,-0.51640,-0.76372
3.20000,-0.53307,-0.78340
3.30000,-0.55000,-0.80268
3.40000,-0.56653,-0.82296
3.50000,-0.58333,-0.84305
3.60000,-0.60000,-0.86266
3.70000,-0.61640,-0.88238
3.80000,-0.63320,-0.90287
3.90000,-0.64960,-0.92263
4.00000,-0.66653,-0.94303
4.10000,-0.68346,-0.96361
4.20000,-0.69986,-0.98393
4.30000,-0.71666,-1.00529
4.40000,-0.73333,-1.02581
4.50000,-0.75013,-1.04629
4.60000,-0.76653,-1.06734
4.70000,-0.78320,-1.08694
4.80000,-0.79986,-1.10824
4.90000,-0.81653,-1.12835
5.00000,-0.83346,-1.14855
5.10000,-0.84986,-1.16905
5.20000,-0.86666,-1.18994
5.30000,-0.88333,-1.20998
5.40000,-0.90000,-1.22972
5.50000,-0.91626,-1.24963
5.60000,-0.93320,-1.26974
5.70000,-0.94986,-1.29009
5.80000,-0.96666,-1.31056
5.90000,-0.98333,-1.33055
6.00000,-0.99986,-1.35009
6.10000,-1.01666,-1.37199
6.20000,-1.03306,-1.39037
6.30000,-1.04973,-1.41040
6.40000,-1.06640,-1.43134
6.50000,-1.08333,-1.45166
6.60000,-1.09986,-1.47225
6.70000,-1.11666,-1.49267
6.80000,-1.13346,-1.51324
6.90000,-1.14973,-1.53318
7.00000,-1.16666,-1.55414
7.10000,-1.18293,-1.57316
7.20000,-1.19986,-1.59425
7.30000,-1.21666,-1.61460
7.40000,-1.23333,-1.63388
7.50000,-1.25000,-1.65445
7.60000,-1.26666,-1.67477
7.70000,-1.28320,-1.69406
7.80000,-1.29973,-1.71433
7.90000,-1.31653,-1.73436
8.00000,-1.33306,-1.75367
8.10000,-1.34986,-1.77535
8.20000,-1.36680,-1.79483
8.30000,-1.38320,-1.81452
8.40000,-1.40000,-1.83497
8.50000,-1.41653,-1.85469
8.60000,-1.43320,-1.87314
8.70000,-1.44973,-1.89371
8.80000,-1.46666,-1.91493
8.90000,-1.48320,-1.93532
9.00000,-1.50000,-1.95506
9.10000,-1.51680,-1.97433
9.20000,-1.53306,-1.99416
9.30000,-1.55000,-2.01334
9.40000,-1.56653,-2.03291
9.50000,-1.58306,-2.05246
9.60000,-1.59973,-2.07230
9.70000,-1.61666,-2.09174
9.80000,-1.63333,-2.11083
9.90000,-1.65013,-2.13068
10.00000,-1.66680,-2.14887
10.10000,-1.68306,-2.16808
10.20000,-1.70000,-2.18801
10.30000,-1.71626,-2.20662
10.40000,-1.73320,-2.22631
10.50000,-1.74986,-2.24463
10.60000,-1.76666,-2.26404
10.70000,-1.78333,-2.28355
10.80000,-1.80013,-2.30263
10.90000,-1.81666,-2.32056
11.00000,-1.83306,-2.33970
11.10000,-1.85000,-2.35904
11.20000,-1.86653,-2.37717
11.30000,-1.88320,-2.39625
11.40000,-1.90026,-2.41430
11.50000,-1.91666,-2.43246
11.60000,-1.93333,-2.45108
11.70000,-1.94986,-2.43175
11.80000,-1.96666,-2.41580
11.90000,-1.98293,-2.41838
12.00000,-2.00000,-2.43798
12.10000,-2.01653,-2.41068
12.20000,-2.03319,-2.32187
12.30000,-2.05000,-2.33690
12.40000,-2.06653,-2.36525
12.50000,-2.08333,-2.39221
12.60000,-2.09960,-2.41684
12.70000,-2.11639,-2.43897
12.80000,-2.13319,-2.45966
12.90000,-2.14999,-2.47989
13.00000,-2.16653,-2.50188
13.10000,-2.18333,-2.52499
13.20000,-2.20013,-2.54653
13.30000,-2.21639,-2.56839
13.40000,-2.23333,-2.58857
13.50000,-2.24973,-2.60930
13.60000,-2.26653,-2.62986
13.70000,-2.28333,-2.64988
13.80000,-2.29986,-2.66871
13.90000,-2.31666,-2.68694
14.00000,-2.33346,-2.70454
14.10000,-2.35013,-2.72262
14.20000,-2.36653,-2.74055
14.30000,-2.38333,-2.75764
14.40000,-2.39986,-2.77461
14.50000,-2.41653,-2.79180
14.60000,-2.43346,-2.80871
14.70000,-2.44999,-2.82491
14.80000,-2.46679,-2.84158
14.90000,-2.48319,-2.85599
15.00000,-2.49999,-2.87130
15.10000,-2.51626,-2.88324
15.20000,-2.53333,-2.89545
15.30000,-2.54986,-2.90904
15.40000,-2.56653,-2.92521
15.50000,-2.58333,-2.93986
15.60000,-2.59986,-2.95396
15.70000,-2.61653,-2.97020
15.80000,-2.63306,-2.98567
15.90000,-2.64973,-3.00097
16.00000,-2.66639,-3.01739
16.10000,-2.68333,-3.03494
16.20000,-2.69986,-3.05255
16.30000,-2.71653,-3.07040
16.40000,-2.73346,-3.08766
16.50000,-2.74973,-3.10454
16.60000,-2.76653,-3.12119
16.70000,-2.78293,-3.13735
16.80000,-2.79999,-3.15553
16.90000,-2.81679,-3.17228
17.00000,-2.83346,-3.18846
17.10000,-2.85013,-3.20465
17.20000,-2.86679,-3.22163
17.30000,-2.88333,-3.23668
17.40000,-2.89973,-3.25177
17.50000,-2.91653,-3.26854
17.60000,-2.93306,-3.28323
17.70000,-2.94986,-3.30100
17.80000,-2.96679,-3.31614
17.90000,-2.98319,-3.33201
18.00000,-2.99986,-3.34757
18.10000,-3.01639,-3.36211
18.20000,-3.03319,-3.37692
18.30000,-3.04959,-3.39338
18.40000,-3.06666,-3.40961
18.50000,-3.08319,-3.42388
18.60000,-3.09986,-3.43831
18.70000,-3.11679,-3.45176
18.80000,-3.13319,-3.46591
18.90000,-3.14999,-3.48021
19.00000,-3.16639,-3.49320
19.10000,-3.18306,-3.50667
19.20000,-3.19973,-3.52151
19.30000,-3.21666,-3.53623
19.40000,-3.23333,-3.54883
19.50000,-3.24999,-3.56417
19.60000,-3.26679,-3.57631
19.70000,-3.28319,-3.58924
19.80000,-3.29986,-3.60267
19.90000,-3.31626,-3.61543
20.00000,-3.33319,-3.62969
20.10000,-3.34999,-3.64267
20.20000,-3.36666,-3.65478
20.30000,-3.38333,-3.66802
20.40000,-3.40013,-3.68051
20.50000,-3.41666,-3.69168
20.60000,-3.43279,-3.70214
20.70000,-3.44986,-3.71561
20.80000,-3.46652,-3.72789
20.90000,-3.48332,-3.74020
21.00000,-3.50012,-3.75186
21.10000,-3.51666,-3.76362
21.20000,-3.53346,-3.77487
21.30000,-3.54999,-3.78630
21.40000,-3.56666,-3.79784
21.50000,-3.58306,-3.80946
21.60000,-3.59986,-3.82046
21.70000,-3.61666,-3.83190
21.80000,-3.63332,-3.84212
21.90000,-3.65012,-3.85240
22.00000,-3.66666,-3.86446
22.10000,-3.68332,-3.87549
22.20000,-3.69959,-3.88658
22.30000,-3.71639,-3.89691
22.40000,-3.73319,-3.90921
22.50000,-3.74999,-3.92030
22.60000,-3.76652,-3.93089
22.70000,-3.78332,-3.94275
22.80000,-3.80012,-3.95499
22.90000,-3.81639,-3.96875
23.00000,-3.83332,-3.98222
23.10000,-3.84972,-3.99519
23.20000,-3.86666,-4.00843
23.30000,-3.88319,-4.02178
23.40000,-3.89999,-4.03563
23.50000,-3.91666,-4.04758
23.60000,-3.93332,-4.05963
23.70000,-3.95012,-4.07278
23.80000,-3.96639,-4.08528
23.90000,-3.98332,-4.09715
24.00000,-3.99972,-4.10905
24.10000,-4.01666,-4.12159
24.20000,-4.03346,-4.13306
24.30000,-4.04986,-4.14397
24.40000,-4.06666,-4.15631
24.50000,-4.08319,-4.16684
24.60000,-4.09972,-4.17791
24.70000,-4.11626,-4.18876
24.80000,-4.13332,-4.20083
24.90000,-4.14986,-4.21096
25.00000,-4.16666,-4.22232
25.10000,-4.18346,-4.23281
25.20000,-4.19986,-4.24313
25.30000,-4.21652,-4.25385
25.40000,-4.23306,-4.26325
25.50000,-4.24972,-4.27350
25.60000,-4.26652,-4.28405
25.70000,-4.28332,-4.29474
25.80000,-4.29999,-4.30412
25.90000,-4.31666,-4.31522
26.00000,-4.33332,-4.32517
26.10000,-4.34972,-4.33462
26.20000,-4.36666,-4.34415
26.30000,-4.38306,-4.35384
26.40000,-4.39986,-4.36440
26.50000,-4.41666,-4.37340
26.60000,-4.43319,-4.38367
26.70000,-4.44999,-4.39313
26.80000,-4.46679,-4.40353
26.90000,-4.48332,-4.41162
27.00000,-4.49972,-4.42017
27.10000,-4.51652,-4.43027
27.20000,-4.53306,-4.43859
27.30000,-4.54986,-4.44902
27.40000,-4.56692,-4.45776
27.50000,-4.58332,-4.46744
27.60000,-4.59999,-4.47564
27.70000,-4.61652,-4.48431
27.80000,-4.63332,-4.49271
27.90000,-4.64972,-4.50200
28.00000,-4.66679,-4.51032
28.10000,-4.68319,-4.51846
28.20000,-4.69986,-4.52712
28.30000,-4.71652,-4.53509
28.40000,-4.73319,-4.54435
28.50000,-4.74986,-4.55162
28.60000,-4.76639,-4.55975
28.70000,-4.78306,-4.56727
28.80000,-4.79985,-4.57654
28.90000,-4.81666,-4.58438
29.00000,-4.83319,-4.59220
29.10000,-4.84985,-4.60093
29.20000,-4.86665,-4.60782
29.30000,-4.88305,-4.61566
29.40000,-4.89999,-4.62353
29.50000,-4.91625,-4.63137
29.60000,-4.93319,-4.63990
29.70000,-4.94999,-4.64858
29.80000,-4.96665,-4.65668
29.90000,-4.98345,-4.66474
30.00000,-5.00012,-4.67232
30.10000,-5.01679,-4.67942
30.20000,-5.03305,-4.68728
30.30000,-5.04999,-4.69574
30.40000,-5.06652,-4.70420
30.50000,-5.08332,-4.71329
30.60000,-5.10012,-4.72092
30.70000,-5.11652,-4.72935
30.80000,-5.13345,-4.73754
30.90000,-5.14999,-4.74565
31.00000,-5.16665,-4.75327
31.10000,-5.18305,-4.76133
31.20000,-5.19985,-4.76892
31.30000,-5.21639,-4.77614
31.40000,-5.23319,-4.78492
31.50000,-5.24999,-4.79109
31.60000,-5.26652,-4.79859
31.70000,-5.28319,-4.80634
31.80000,-5.29972,-4.81319
31.90000,-5.31639,-4.82057
32.00000,-5.33305,-4.82803
32.10000,-5.34999,-4.83591
32.20000,-5.36652,-4.84261
32.30000,-5.38332,-4.85003
32.40000,-5.39999,-4.85664
32.50000,-5.41625,-4.86335
32.60000,-5.43319,-4.87045
32.70000,-5.44972,-4.87703
32.80000,-5.46665,-4.88445
32.90000,-5.48332,-4.89108
33.00000,-5.49999,-4.89784
33.10000,-5.51665,-4.90392
33.20000,-5.53332,-4.90997
33.30000,-5.54999,-4.91607
33.40000,-5.56639,-4.92171
33.50000,-5.58319,-4.92768
33.60000,-5.59972,-4.93273
33.70000,-5.61665,-4.94016
33.80000,-5.63345,-4.94511
33.90000,-5.65012,-4.95057
34.00000,-5.66665,-4.95625
34.10000,-5.68319,-4.96123
34.20000,-5.69999,-4.96683
34.30000,-5.71639,-4.97196
34.40000,-5.73332,-4.97844
34.50000,-5.74985,-4.98355
34.60000,-5.76652,-4.99086
34.70000,-5.78332,-4.99566
34.80000,-5.79985,-5.00082
34.90000,-5.81665,-5.00617
35.00000,-5.83305,-5.01119
35.10000,-5.84972,-5.01644
35.20000,-5.86652,-5.02209
35.30000,-5.88332,-5.02795
35.40000,-5.89985,-5.03241
35.50000,-5.91665,-5.03864
35.60000,-5.93345,-5.04276
35.70000,-5.94959,-5.04624
35.80000,-5.96665,-5.05167
35.90000,-5.98305,-5.05617
36.00000,-5.99999,-5.06254
36.10000,-6.01652,-5.06823
36.20000,-6.03332,-5.07395
36.30000,-6.05012,-5.07939
36.40000,-6.06679,-5.08466
36.50000,-6.08332,-5.08818
36.60000,-6.09972,-5.09321
36.70000,-6.11665,-5.09820
36.80000,-6.13319,-5.10289
36.90000,-6.14998,-5.10924
37.00000,-6.16679,-5.11385
37.10000,-6.18332,-5.11895
37.20000,-6.19998,-5.12522
37.30000,-6.21652,-5.13088
37.40000,-6.23318,-5.13611
37.50000,-6.24958,-5.14217
37.60000,-6.26652,-5.14818
37.70000,-6.28318,-5.15382
37.80000,-6.29998,-5.16091
37.90000,-6.31678,-5.16680
38.00000,-6.33318,-5.17355
38.10000,-6.34998,-5.18070
38.20000,-6.36638,-5.18653
38.30000,-6.38318,-5.19179
38.40000,-6.39985,-5.19884
38.50000,-6.41665,-5.20513
38.60000,-6.43332,-5.20993
38.70000,-6.45012,-5.21581
38.80000,-6.46678,-5.22121
38.90000,-6.48305,-5.22606
39.00000,-6.49998,-5.23316
39.10000,-6.51638,-5.23758
39.20000,-6.53318,-5.24495
39.30000,-6.54998,-5.25129
39.40000,-6.56665,-5.25751
39.50000,-6.58345,-5.26347
39.60000,-6.59998,-5.27006
39.70000,-6.61652,-5.27577
39.80000,-6.63305,-5.28175
39.90000,-6.64985,-5.28751
40.00000,-6.66652,-5.29321
40.10000,-6.68332,-5.30003
40.20000,-6.70025,-5.30512
40.30000,-6.71665,-5.31036
40.40000,-6.73332,-5.31652
40.50000,-6.74985,-5.32195
40.60000,-6.76665,-5.32877
40.70000,-6.78318,-5.33518
40.80000,-6.80012,-5.34112
40.90000,-6.81665,-5.34645
41.00000,-6.83332,-5.35179
41.10000,-6.85012,-5.35645
41.20000,-6.86665,-5.36247
41.30000,-6.88332,-5.36764
41.40000,-6.89972,-5.37223
41.50000,-6.91638,-5.37695
41.60000,-6.93305,-5.38187
41.70000,-6.94985,-5.38838
41.80000,-6.96652,-5.39400
41.90000,-6.98332,-5.40022
42.00000,-7.00012,-5.40579
42.10000,-7.01652,-5.41204
42.20000,-7.03345,-5.41726
42.30000,-7.04972,-5.42069
42.40000,-7.06652,-5.42686
42.50000,-7.08332,-5.43295
42.60000,-7.09998,-5.43955
42.70000,-7.11665,-5.44523
42.80000,-7.13332,-5.45117
42.90000,-7.15012,-5.45687
43.00000,-7.16638,-5.46232
43.10000,-7.18318,-5.46831
43.20000,-7.19985,-5.47286
43.30000,-7.21652,-5.47952
43.40000,-7.23345,-5.48460
43.50000,-7.24998,-5.49010
43.60000,-7.26678,-5.49678
43.70000,-7.28332,-5.50205
43.80000,-7.29998,-5.50564
43.90000,-7.31652,-5.51051
44.00000,-7.33332,-5.51633
44.10000,-7.34998,-5.52242
44.20000,-7.36665,-5.52946
44.30000,-7.38345,-5.53352
44.40000,-7.39972,-5.53993
44.50000,-7.41652,-5.54483
44.60000,-7.43305,-5.55152
44.70000,-7.44985,-5.55613
44.80000,-7.46652,-5.56221
44.90000,-7.48332,-5.56785
45.00000,-7.49998,-5.57425
45.10000,-7.51651,-5.58230
45.20000,-7.53345,-5.58577
45.30000,-7.54985,-5.59335
45.40000,-7.56665,-5.59865
45.50000,-7.58305,-5.60358
45.60000,-7.59985,-5.61003
45.70000,-7.61678,-5.61634
45.80000,-7.63331,-5.62370
45.90000,-7.65011,-5.63058
46.00000,-7.66678,-5.63643
46.10000,-7.68331,-5.64312
46.20000,-7.69971,-5.64919
46.30000,-7.71651,-5.65587
46.40000,-7.73305,-5.66117
46.50000,-7.74985,-5.66819
46.60000,-7.76691,-5.67576
46.70000,-7.78331,-5.68196
46.80000,-7.80011,-5.68873
46.90000,-7.81665,-5.69473
47.00000,-7.83331,-5.70042
47.10000,-7.84971,-5.70667
47.20000,-7.86665,-5.71345
47.30000,-7.88331,-5.71877
47.40000,-7.89998,-5.72569
47.50000,-7.91665,-5.73119
47.60000,-7.93318,-5.73677
47.70000,-7.94998,-5.74373
47.80000,-7.96638,-5.74965
47.90000,-7.98305,-5.75592
48.00000,-7.99971,-5.76221
48.10000,-8.01665,-5.76923
48.20000,-8.03331,-5.77519
48.30000,-8.04998,-5.78287
48.40000,-8.06665,-5.78765
48.50000,-8.08305,-5.79392
48.60000,-8.09998,-5.80085
48.70000,-8.11651,-5.80680
48.80000,-8.13318,-5.81426
48.90000,-8.14998,-5.82086
49.00000,-8.16665,-5.82699
49.10000,-8.18345,-5.83348
49.20000,-8.19998,-5.84034
49.30000,-8.21678,-5.84523
49.40000,-8.23318,-5.85158
49.50000,-8.24998,-5.85764
49.60000,-8.26651,-5.86276
49.70000,-8.28318,-5.86899
49.80000,-8.30011,-5.87553
49.90000,-8.31665,-5.88076
50.00000,-8.33331,-5.88675
50.10000,-8.35011,-5.89244
50.20000,-8.36665,-5.89748
50.30000,-8.38305,-5.90232
50.40000,-8.39998,-5.90838
50.50000,-8.41665,-5.91345
50.60000,-8.43331,-5.91975
50.70000,-8.45011,-5.92444
50.80000,-8.46665,-5.93101
50.90000,-8.48345,-5.93588
51.00000,-8.49985,-5.93982
51.10000,-8.51651,-5.94457
51.20000,-8.53318,-5.95054
51.30000,-8.54998,-5.95601
51.40000,-8.56665,-5.95989
51.50000,-8.58331,-5.96606
51.60000,-8.60011,-5.97013
51.70000,-8.61651,-5.97609
51.80000,-8.63331,-5.98196
51.90000,-8.64971,-5.98807
52.00000,-8.66651,-5.99367
52.10000,-8.68318,-5.99961
52.20000,-8.69985,-6.00611
52.30000,-8.71651,-6.01220
52.40000,-8.73318,-6.01880
52.50000,-8.74998,-6.02442
52.60000,-8.76625,-6.03070
52.70000,-8.78331,-6.03732
52.80000,-8.79998,-6.04285
52.90000,-8.81665,-6.04941
53.00000,-8.83345,-6.05512
53.10000,-8.84998,-6.06043
53.20000,-8.86678,-6.06648
53.30000,-8.88331,-6.07127
53.40000,-8.89998,-6.07571
53.50000,-8.91638,-6.08167
53.60000,-8.93345,-6.08728
53.70000,-8.94998,-6.09220
53.80000,-8.96665,-6.09825
53.90000,-8.98345,-6.10290
54.00000,-8.99985,-6.10716
54.10000,-9.01665,-6.11239
54.20000,-9.03318,-6.11687
54.30000,-9.04971,-6.12100
54.40000,-9.06651,-6.12696
54.50000,-9.08331,-6.13306
54.60000,-9.09998,-6.13801
54.70000,-9.11664,-6.14369
54.80000,-9.13344,-6.14874
54.90000,-9.14971,-6.15502
55.00000,-9.16664,-6.16121
55.10000,-9.18304,-6.16566
55.20000,-9.19998,-6.17203
55.30000,-9.21664,-6.17810
55.40000,-9.23331,-6.18320
55.50000,-9.24998,-6.18875
55.60000,-9.26678,-6.19474
55.70000,-9.28344,-6.19910
55.80000,-9.29971,-6.20471
55.90000,-9.31664,-6.21047
56.00000,-9.33318,-6.21472
56.10000,-9.34984,-6.22155
56.20000,-9.36678,-6.22689
56.30000,-9.38331,-6.23197
56.40000,-9.39998,-6.23765
56.50000,-9.41651,-6.24292
56.60000,-9.43331,-6.24893
56.70000,-9.44971,-6.25351
56.80000,-9.46678,-6.25844
56.90000,-9.48318,-6.26383
57.00000,-9.49998,-6.26931
57.10000,-9.51678,-6.27371
57.20000,-9.53318,-6.27925
57.30000,-9.54998,-6.28315
57.40000,-9.56638,-6.28832
57.50000,-9.58318,-6.29330
57.60000,-9.59984,-6.29810
57.70000,-9.61664,-6.30277
57.80000,-9.63331,-6.30766
57.90000,-9.64998,-6.31333
58.00000,-9.66664,-6.31747
58.10000,-9.68318,-6.32255
58.20000,-9.69998,-6.32786
58.30000,-9.71624,-6.33097
58.40000,-9.73318,-6.33835
58.50000,-9.74998,-6.34338
58.60000,-9.76664,-6.34964
58.70000,-9.78344,-6.35514
58.80000,-9.80011,-6.36176
58.90000,-9.81678,-6.36593
59.00000,-9.83304,-6.37204
59.10000,-9.84998,-6.37805
59.20000,-9.86651,-6.38261
59.30000,-9.88331,-6.38940
59.40000,-9.90024,-6.39465
59.50000,-9.91664,-6.40071
59.60000,-9.93344,-6.40592
59.70000,-9.94998,-6.41167
59.80000,-9.96664,-6.41735
59.90000,-9.98304,-6.42374
60.00000,-9.99998,-6.43116
60.10000,-10.01651,-6.43588
60.20000,-10.03331,-6.44291
60.30000,-10.04998,-6.44735
60.40000,-10.06638,-6.45196
60.50000,-10.08318,-6.45805
60.60000,-10.09984,-6.46438
60.70000,-10.11651,-6.46844
60.80000,-10.13318,-6.47463
60.90000,-10.14998,-6.48032
61.00000,-10.16664,-6.48580
61.10000,-10.18331,-6.49328
61.20000,-10.19998,-6.49691
61.30000,-10.21637,-6.50367
61.40000,-10.23344,-6.50975
61.50000,-10.24971,-6.51525
61.60000,-10.26664,-6.52271
61.70000,-10.28344,-6.52871
61.80000,-10.29998,-6.53446
61.90000,-10.31664,-6.53892
62.00000,-10.33331,-6.54504
62.10000,-10.34997,-6.54954
62.20000,-10.36637,-6.55534
62.30000,-10.38331,-6.56136
62.40000,-10.39984,-6.56682
62.50000,-10.41678,-6.57501
62.60000,-10.43357,-6.57957
62.70000,-10.44997,-6.58358
62.80000,-10.46664,-6.58925
62.90000,-10.48331,-6.59400
63.00000,-10.49997,-6.59932
63.10000,-10.51637,-6.60573
63.20000,-10.53344,-6.61012
63.30000,-10.54984,-6.61387
63.40000,-10.56664,-6.61946
63.50000,-10.58331,-6.62340
63.60000,-10.59984,-6.62887
63.70000,-10.61664,-6.63417
63.80000,-10.63317,-6.63901
63.90000,-10.64984,-6.64358
64.00000,-10.66651,-6.64943
64.10001,-10.68331,-6.65606
64.20000,-10.69984,-6.66091
64.30000,-10.71651,-6.66788
64.40000,-10.73331,-6.67180
64.50000,-10.74971,-6.67710
64.60001,-10.76677,-6.68361
64.70000,-10.78304,-6.68694
64.80000,-10.79997,-6.69350
64.90000,-10.81677,-6.70063
65.00000,-10.83344,-6.70630
65.10001,-10.85011,-6.70945
65.20000,-10.86677,-6.71474
65.30000,-10.88344,-6.71799
65.40000,-10.89971,-6.72172
65.50000,-10.91664,-6.72634
65.60001,-10.93317,-6.73051
65.70001,-10.94997,-6.73590
65.80000,-10.96677,-6.73929
65.90000,-10.98317,-6.74338
66.00000,-10.99997,-6.74814
66.10001,-11.01664,-6.75295
66.20001,-11.03331,-6.75706
66.30000,-11.04971,-6.76115
66.40000,-11.06677,-6.76605
66.50000,-11.08317,-6.77050
66.60001,-11.09997,-6.77765
66.70001,-11.11677,-6.78212
66.80000,-11.13317,-6.78663
66.90000,-11.14997,-6.79014
67.00000,-11.16637,-6.79395
67.10001,-11.18317,-6.79763
67.20001,-11.19984,-6.80275
67.30000,-11.21664,-6.80711
67.40000,-11.23331,-6.81163
67.50000,-11.24997,-6.81714
67.60001,-11.26677,-6.82114
67.70001,-11.28317,-6.82625
67.80000,-11.29997,-6.82989
67.90000,-11.31624,-6.83266
68.00000,-11.33331,-6.83850
68.10001,-11.34984,-6.84291
68.20001,-11.36664,-6.84832
68.30000,-11.38317,-6.85214
68.40000,-11.39997,-6.85765
68.50000,-11.41664,-6.86249
68.60001,-11.43304,-6.86824
68.70001,-11.44984,-6.87333
68.80000,-11.46651,-6.87724
68.90000,-11.48331,-6.88411
69.00000,-11.50011,-6.88877
69.10001,-11.51664,-6.89353
69.20001,-11.53331,-6.89755
69.30000,-11.54984,-6.90284
69.40000,-11.56664,-6.90638
69.50000,-11.58304,-6.91263
69.60001,-11.59997,-6.91840
69.70001,-11.61650,-6.92288
69.80000,-11.63344,-6.92986
69.90000,-11.65011,-6.93375
70.00000,-11.66650,-6.93926
70.10001,-11.68330,-6.94431
70.20001,-11.69984,-6.94935
70.30000,-11.71650,-6.95395
70.40000,-11.73330,-6.95992
70.50000,-11.75010,-6.96659
70.60001,-11.76664,-6.97327
70.70001,-11.78330,-6.97929
70.80000,-11.79997,-6.98172
70.90000,-11.81650,-6.98668
71.00000,-11.83330,-6.98984
71.10001,-11.84970,-6.99199
71.20001,-11.86650,-6.99906
71.30000,-11.88330,-7.00623
71.40000,-11.89997,-7.01100
71.50000,-11.91664,-7.01461
71.60001,-11.93330,-7.02251
71.70001,-11.95010,-7.02971
71.80000,-11.96650,-7.03593
71.90000,-11.98330,-7.04644
72.00000,-11.99984,-7.05505
72.10001,-12.01664,-7.06238
72.20001,-12.03344,-7.06542
72.30000,-12.04997,-7.07140
72.40000,-12.06677,-7.07846
72.50000,-12.08330,-7.08385
72.60001,-12.10010,-7.08845
72.70001,-12.11650,-7.09259
72.80000,-12.13330,-7.09758
72.90000,-12.14984,-7.09661
73.00000,-12.16664,-7.10444
73.10001,-12.18344,-7.11206
73.20001,-12.19984,-7.11780
73.30000,-12.21650,-7.12369
73.40000,-12.23304,-7.13229
73.50000,-12.24984,-7.14072
73.60001,-12.26650,-7.14857
73.70001,-12.28330,-7.15589
73.80000,-12.29984,-7.16297
73.90000,-12.31664,-7.17782
74.00000,-12.33330,-7.18209
74.10001,-12.34984,-7.18742
74.20001,-12.36664,-7.19208
74.30000,-12.38304,-7.19999
74.40000,-12.39997,-7.21112
74.50000,-12.41677,-7.21696
74.60001,-12.43344,-7.21950
74.70001,-12.45010,-7.22278
74.80000,-12.46677,-7.22840
74.90000,-12.48344,-7.23295
75.00000,-12.49984,-7.23919
75.10001,-12.51650,-7.24368
75.20001,-12.53317,-7.24821
75.30000,-12.54997,-7.25515
75.40000,-12.56690,-7.26013
75.50000,-12.58330,-7.26547
75.60001,-12.60010,-7.27076
75.70001,-12.61664,-7.27638
75.80000,-12.63344,-7.28175
75.90000,-12.64970,-7.28663
76.00000,-12.66664,-7.29381
76.10001,-12.68330,-7.29926
76.20001,-12.69997,-7.30768
76.30000,-12.71664,-7.31137
76.40000,-12.73317,-7.31799
76.50000,-12.74997,-7.32405
76.60001,-12.76637,-7.33007
76.70001,-12.78317,-7.33644
76.80000,-12.79984,-7.34313
76.90000,-12.81663,-7.34958
77.00000,-12.83330,-7.35515
77.10001,-12.84997,-7.36343
77.20001,-12.86663,-7.36668
77.30000,-12.88304,-7.37236
77.40000,-12.89997,-7.37431
77.50000,-12.91637,-7.37619
77.60001,-12.93330,-7.38566
77.70001,-12.95010,-7.39319
77.80000,-12.96663,-7.39772
77.90000,-12.98330,-7.40044
78.00000,-13.00010,-7.40502
78.10001,-13.01677,-7.40925
78.20001,-13.03304,-7.41492
78.30000,-13.04997,-7.42132
78.40000,-13.06650,-7.42551
78.50000,-13.08330,-7.43437
78.60001,-13.10010,-7.43974
78.70001,-13.11650,-7.44433
78.80000,-13.13343,-7.45008
78.90000,-13.14997,-7.45316
79.00000,-13.16663,-7.45589
79.10001,-13.18303,-7.46368
79.20001,-13.19997,-7.47110
79.30000,-13.21637,-7.47633
79.40000,-13.23330,-7.48357
79.50000,-13.25010,-7.48686
79.60001,-13.26663,-7.49283
79.70001,-13.28343,-7.49849
79.80000,-13.29970,-7.50278
79.90000,-13.31637,-7.50789
80.00000,-13.33317,-7.51484
80.10001,-13.34997,-7.52017
80.20001,-13.36663,-7.52420
80.30000,-13.38330,-7.53161
80.40000,-13.40010,-7.53541
80.50001,-13.41650,-7.53992
80.60001,-13.43330,-7.54409
80.70001,-13.44957,-7.54768
80.80000,-13.46663,-7.55349
80.90000,-13.48330,-7.55820
81.00001,-13.50010,-7.56289
81.10001,-13.51677,-7.56744
81.20001,-13.53330,-7.57136
81.30000,-13.54997,-7.57540
81.40000,-13.56637,-7.58025
81.50001,-13.58330,-7.58476
81.60001,-13.59983,-7.58828
81.70001,-13.61650,-7.59394
81.80000,-13.63343,-7.59851
81.90000,-13.64997,-7.60338
82.00001,-13.66677,-7.60942
82.10001,-13.68330,-7.61342
82.20001,-13.69997,-7.61866
82.30000,-13.71650,-7.62558
82.40000,-13.73330,-7.63039
82.50001,-13.74983,-7.63546
82.60001,-13.76663,-7.64196
82.70001,-13.78343,-7.64652
82.80000,-13.79983,-7.65206
82.90000,-13.81663,-7.65861
83.00001,-13.83317,-7.66464
83.10001,-13.84983,-7.66970
83.20001,-13.86637,-7.67653
83.30000,-13.88330,-7.68451
83.40000,-13.89983,-7.69051
83.50001,-13.91663,-7.69921
83.60001,-13.93343,-7.70405
83.70001,-13.94983,-7.71156
83.80000,-13.96650,-7.71992
83.90000,-13.98290,-7.72504
84.00001,-13.99997,-7.73664
84.10001,-14.01677,-7.74415
84.20001,-14.03330,-7.75259
84.30000,-14.05010,-7.76123
84.40000,-14.06690,-7.77099
84.50001,-14.08343,-7.77757
84.60001,-14.09983,-7.78434
84.70001,-14.11677,-7.79235
84.80000,-14.13317,-7.79651
84.90000,-14.14997,-7.80460
85.00001,-14.16690,-7.81085
85.10001,-14.18330,-7.81688
85.20001,-14.20010,-7.82401
85.30000,-14.21663,-7.82900
85.40000,-14.23330,-7.83551
85.50001,-14.24983,-7.84425
85.60001,-14.26663,-7.85039
85.70001,-14.28317,-7.85593
85.80000,-14.29997,-7.86378
85.90000,-14.31663,-7.86855
86.00001,-14.33317,-7.87410
86.10001,-14.34997,-7.88147
86.20001,-14.36637,-7.88751
86.30000,-14.38303,-7.89348
86.40000,-14.39970,-7.90272
86.50001,-14.41650,-7.90984
86.60001,-14.43317,-7.91588
86.70001,-14.44996,-7.92349
86.80000,-14.46676,-7.92862
86.90000,-14.48303,-7.93398
87.00001,-14.49996,-7.94128
87.10001,-14.51636,-7.94725
87.20001,-14.53330,-7.95482
87.30000,-14.55010,-7.96094
87.40000,-14.56663,-7.96744
87.50001,-14.58343,-7.97481
87.60001,-14.60010,-7.98161
87.70001,-14.61676,-7.98999
87.80000,-14.63316,-7.99550
87.90000,-14.64996,-8.00114
88.00001,-14.66650,-8.00289
88.10001,-14.68316,-8.01040
88.20001,-14.69996,-8.01608
88.30000,-14.71650,-8.02182
88.40000,-14.73343,-8.02933
88.50001,-14.75010,-8.03703
88.60001,-14.76663,-8.04110
88.70001,-14.78303,-8.04620
88.80000,-14.79996,-8.05376
88.90000,-14.81650,-8.05978
89.00001,-14.83330,-8.07074
89.10001,-14.84996,-8.07657
89.20001,-14.86650,-8.08387
89.30000,-14.88330,-8.09153
89.40000,-14.89970,-8.09793
89.50001,-14.91650,-8.10652
89.60001,-14.93316,-8.11580
89.70001,-14.94996,-8.12456
89.80000,-14.96663,-8.12950
89.90000,-14.98330,-8.13927
90.00001,-15.00010,-8.14806
90.10001,-15.01636,-8.15635
90.20001,-15.03330,-8.16750
90.28401,-15.04703,-8.17374