File: GFBaking/data/2_8PercentGluten/2_8gluten_4Point_1.is_flex_RawData/Specimen_RawData_4.csv
Time,Extension,Load
(sec),(mm),(N)
0.00000,-0.00027,0.00008
0.05000,-0.00147,-0.00001
0.10000,-0.00587,-0.00003
0.15000,-0.01520,0.00000
0.20000,-0.02587,0.00001
0.25000,-0.03587,-0.00002
0.30000,-0.04600,0.00000
0.35000,-0.05533,0.00000
0.40000,-0.06440,0.00001
0.45000,-0.07360,0.00002
0.50000,-0.08213,0.00000
0.55000,-0.09080,-0.00001
0.60000,-0.09947,0.00000
0.65000,-0.10800,0.00002
0.70000,-0.11640,-0.00001
0.75000,-0.12480,0.00000
0.80000,-0.13320,0.00001
0.85000,-0.14160,0.00000
0.90000,-0.14987,0.00000
0.95000,-0.15813,0.00000
1.00000,-0.16680,0.00001
1.05000,-0.17507,0.00000
1.10000,-0.18320,0.00001
1.15000,-0.19187,0.00001
1.20000,-0.20027,0.00001
1.25000,-0.20840,0.00001
1.30000,-0.21680,0.00000
1.35000,-0.22547,0.00001
1.40000,-0.23360,0.00001
1.45000,-0.24187,0.00000
1.50000,-0.25027,0.00001
1.55000,-0.25853,-0.00001
1.60000,-0.26667,0.00001
1.65000,-0.27507,0.00003
1.70000,-0.28347,0.00000
1.75000,-0.29160,0.00000
1.80000,-0.30000,0.00000
1.85000,-0.30827,0.00001
1.90000,-0.31667,-0.00001
1.95000,-0.32520,0.00003
2.00000,-0.33333,0.00002
2.05000,-0.34173,0.00000
2.10000,-0.35027,0.00000
2.15000,-0.35853,0.00000
2.20000,-0.36680,0.00001
2.25000,-0.37533,0.00002
2.30000,-0.38347,0.00002
2.35000,-0.39173,0.00000
2.40000,-0.40027,0.00002
2.45000,-0.40853,0.00000
2.50000,-0.41653,0.00000
2.55000,-0.42480,0.00000
2.60000,-0.43347,0.00001
2.65000,-0.44187,0.00003
2.70000,-0.45013,0.00002
2.75000,-0.45880,-0.00001
2.80000,-0.46707,-0.00002
2.85000,-0.47533,0.00001
2.90000,-0.48360,0.00001
2.95000,-0.49200,0.00001
3.00000,-0.50027,0.00002
3.05000,-0.50867,0.00000
3.10000,-0.51680,0.00002
3.15000,-0.52533,0.00000
3.20000,-0.53347,0.00002
3.25000,-0.54160,0.00000
3.30000,-0.55013,0.00003
3.35000,-0.55840,0.00002
3.40000,-0.56653,0.00001
3.45000,-0.57507,0.00001
3.50000,-0.58373,0.00001
3.55000,-0.59187,-0.00003
3.60000,-0.60013,0.00003
3.65000,-0.60880,0.00001
3.70000,-0.61693,0.00001
3.75000,-0.62520,0.00002
3.80000,-0.63360,0.00000
3.85000,-0.64200,0.00000
3.90000,-0.65013,0.00002
3.95000,-0.65853,0.00003
4.00000,-0.66680,0.00005
4.05000,-0.67520,0.00000
4.10000,-0.68346,0.00002
4.15000,-0.69160,0.00002
4.20000,-0.70013,0.00001
4.25000,-0.70853,0.00003
4.30000,-0.71666,0.00004
4.35000,-0.72520,0.00005
4.40000,-0.73373,0.00001
4.45000,-0.74173,0.00001
4.50000,-0.75013,0.00003
4.55000,-0.75866,0.00003
4.60000,-0.76680,0.00002
4.65000,-0.77506,0.00003
4.70000,-0.78346,0.00002
4.75000,-0.79186,0.00001
4.80000,-0.80000,0.00002
4.85000,-0.80826,0.00001
4.90000,-0.81666,0.00001
4.95000,-0.82506,0.00002
5.00000,-0.83333,0.00001
5.05000,-0.84173,0.00000
5.10000,-0.85026,0.00003
5.15000,-0.85853,0.00007
5.20000,-0.86680,0.00003
5.25000,-0.87520,0.00002
5.30000,-0.88360,0.00002
5.35000,-0.89186,0.00004
5.40000,-0.90013,0.00007
5.45000,-0.90880,0.00002
5.50000,-0.91680,0.00001
5.55000,-0.92506,0.00000
5.60000,-0.93346,0.00001
5.65000,-0.94186,0.00005
5.70000,-0.95000,0.00002
5.75000,-0.95826,0.00001
5.80000,-0.96693,0.00001
5.85000,-0.97520,0.00003
5.90000,-0.98346,0.00002
5.95000,-0.99200,0.00003
6.00000,-1.00026,0.00005
6.05000,-1.00853,0.00000
6.10000,-1.01680,0.00001
6.15000,-1.02533,0.00002
6.20000,-1.03360,0.00003
6.25000,-1.04186,0.00000
6.30000,-1.05013,0.00003
6.35000,-1.05866,0.00002
6.40000,-1.06680,0.00001
6.45000,-1.07493,0.00002
6.50000,-1.08360,0.00002
6.55000,-1.09186,0.00000
6.60000,-1.09986,0.00001
6.65000,-1.10840,0.00002
6.70000,-1.11706,0.00002
6.75000,-1.12520,0.00004
6.80000,-1.13360,0.00002
6.85000,-1.14213,0.00002
6.90000,-1.15026,0.00000
6.95000,-1.15853,0.00003
7.00000,-1.16693,0.00001
7.05000,-1.17533,0.00000
7.10000,-1.18346,0.00002
7.15000,-1.19186,0.00002
7.20000,-1.20013,0.00002
7.25000,-1.20853,0.00000
7.30000,-1.21680,0.00004
7.35000,-1.22480,0.00001
7.40000,-1.23346,0.00001
7.45000,-1.24200,0.00003
7.50000,-1.25000,0.00002
7.55000,-1.25853,0.00000
7.60000,-1.26706,0.00002
7.65000,-1.27520,0.00000
7.70000,-1.28360,0.00002
7.75000,-1.29213,0.00001
7.80000,-1.30013,0.00000
7.85000,-1.30840,0.00003
7.90000,-1.31680,0.00003
7.95000,-1.32506,0.00003
8.00000,-1.33333,0.00003
8.05000,-1.34160,0.00000
8.10000,-1.35000,0.00001
8.15000,-1.35826,0.00001
8.20000,-1.36666,0.00001
8.25000,-1.37493,0.00002
8.30000,-1.38346,0.00003
8.35000,-1.39186,0.00003
8.40000,-1.40013,0.00001
8.45000,-1.40853,0.00003
8.50000,-1.41693,0.00003
8.55000,-1.42520,0.00000
8.60000,-1.43360,0.00002
8.65000,-1.44200,0.00003
8.70000,-1.45026,0.00000
8.75000,-1.45840,0.00002
8.80000,-1.46680,0.00002
8.85000,-1.47520,0.00002
8.90000,-1.48333,-0.00001
8.95000,-1.49160,0.00001
9.00000,-1.50013,0.00003
9.05000,-1.50853,0.00001
9.10000,-1.51666,0.00002
9.15000,-1.52520,0.00002
9.20000,-1.53360,0.00003
9.25000,-1.54186,0.00002
9.30000,-1.55026,0.00001
9.35000,-1.55866,0.00004
9.40000,-1.56693,0.00001
9.45000,-1.57520,0.00003
9.50000,-1.58346,0.00001
9.55000,-1.59213,0.00000
9.60000,-1.60026,-0.00001
9.65000,-1.60840,0.00003
9.70000,-1.61693,0.00004
9.75000,-1.62520,0.00001
9.80000,-1.63333,0.00004
9.85000,-1.64186,0.00004
9.90000,-1.65040,0.00000
9.95000,-1.65840,0.00002
10.00000,-1.66680,0.00003
10.05000,-1.67546,0.00001
10.10000,-1.68360,0.00001
10.15000,-1.69186,0.00004
10.20000,-1.70040,0.00003
10.25000,-1.70866,0.00000
10.30000,-1.71693,0.00003
10.35000,-1.72520,0.00004
10.40000,-1.73346,0.00003
10.45000,-1.74186,0.00003
10.50000,-1.75000,0.00003
10.55000,-1.75813,0.00001
10.60000,-1.76666,0.00002
10.65000,-1.77506,0.00005
10.70000,-1.78320,0.00001
10.75000,-1.79173,0.00001
10.80000,-1.80026,0.00004
10.85000,-1.80840,0.00003
10.90000,-1.81666,0.00002
10.95000,-1.82533,0.00002
11.00000,-1.83346,0.00000
11.05000,-1.84173,0.00000
11.10000,-1.85000,-0.00001
11.15000,-1.85826,0.00003
11.20000,-1.86653,0.00000
11.25000,-1.87480,0.00000
11.30000,-1.88333,0.00000
11.35000,-1.89160,0.00000
11.40000,-1.90000,0.00001
11.45000,-1.90840,0.00003
11.50000,-1.91693,0.00001
11.55000,-1.92533,-0.00003
11.60000,-1.93346,0.00000
11.65000,-1.94200,0.00002
11.70000,-1.95040,0.00001
11.75000,-1.95853,0.00001
11.80000,-1.96680,0.00003
11.85000,-1.97546,0.00002
11.90000,-1.98360,0.00001
11.95000,-1.99173,0.00002
12.00000,-2.00026,0.00003
12.05000,-2.00866,-0.00002
12.10000,-2.01666,0.00002
12.15000,-2.02493,0.00000
12.20000,-2.03359,0.00003
12.25000,-2.04186,0.00001
12.30000,-2.05013,0.00002
12.35000,-2.05866,0.00002
12.40000,-2.06693,0.00001
12.45000,-2.07520,0.00002
12.50000,-2.08359,0.00002
12.55000,-2.09199,0.00000
12.60000,-2.10039,-0.00002
12.65000,-2.10866,0.00002
12.70000,-2.11679,0.00002
12.75000,-2.12533,0.00000
12.80000,-2.13346,0.00002
12.85000,-2.14159,0.00001
12.90000,-2.15026,0.00001
12.95000,-2.15839,0.00003
13.00000,-2.16653,0.00001
13.05000,-2.17506,0.00001
13.10000,-2.18373,0.00001
13.15000,-2.19186,0.00001
13.20000,-2.20013,0.00003
13.25000,-2.20879,0.00000
13.30000,-2.21693,0.00000
13.35000,-2.22519,0.00004
13.40000,-2.23359,0.00003
13.45000,-2.24199,0.00001
13.50000,-2.25026,0.00001
13.55000,-2.25853,0.00000
13.60000,-2.26679,0.00001
13.65000,-2.27519,0.00004
13.70000,-2.28359,0.00002
13.75000,-2.29159,0.00004
13.80000,-2.30013,0.00003
13.85000,-2.30853,0.00001
13.90000,-2.31666,0.00002
13.95000,-2.32519,0.00001
14.00000,-2.33359,0.00001
14.05000,-2.34173,-0.00002
14.10000,-2.35013,0.00000
14.15000,-2.35866,0.00002
14.20000,-2.36679,-0.00001
14.25000,-2.37506,0.00003
14.30000,-2.38346,0.00001
14.35000,-2.39173,0.00004
14.40000,-2.39999,0.00002
14.45000,-2.40839,0.00002
14.50000,-2.41666,0.00003
14.55000,-2.42493,0.00001
14.60000,-2.43319,0.00000
14.65000,-2.44159,0.00000
14.70000,-2.45013,0.00000
14.75000,-2.45853,0.00000
14.80000,-2.46679,0.00001
14.85000,-2.47519,0.00002
14.90000,-2.48359,0.00002
14.95000,-2.49173,0.00003
15.00000,-2.50013,0.00002
15.05000,-2.50853,0.00000
15.10000,-2.51666,0.00000
15.15000,-2.52493,0.00001
15.20000,-2.53346,0.00002
15.25000,-2.54173,0.00002
15.30000,-2.54986,0.00000
15.35000,-2.55826,0.00001
15.40000,-2.56679,0.00000
15.45000,-2.57493,0.00001
15.50000,-2.58333,0.00001
15.55000,-2.59186,-0.00001
15.60000,-2.60026,0.00000
15.65000,-2.60853,0.00001
15.70000,-2.61693,0.00002
15.75000,-2.62546,0.00001
15.80000,-2.63373,-0.00001
15.85000,-2.64213,0.00001
15.90000,-2.65026,0.00002
15.95000,-2.65879,0.00001
16.00000,-2.66693,0.00001
16.05000,-2.67506,0.00001
16.10000,-2.68359,0.00002
16.15000,-2.69186,0.00003
16.20000,-2.69999,0.00004
16.25000,-2.70853,0.00002
16.30000,-2.71706,0.00000
16.35000,-2.72519,0.00003
16.40000,-2.73346,0.00003
16.45000,-2.74213,0.00002
16.50000,-2.75026,0.00000
16.55000,-2.75853,-0.00002
16.60000,-2.76693,-0.00001
16.65000,-2.77533,-0.00001
16.70000,-2.78359,0.00001
16.75000,-2.79186,0.00000
16.80000,-2.80013,0.00002
16.85000,-2.80839,0.00001
16.90000,-2.81666,0.00000
16.95000,-2.82479,0.00000
17.00000,-2.83346,0.00001
17.05000,-2.84186,0.00000
17.10000,-2.84999,0.00001
17.15000,-2.85853,0.00000
17.20000,-2.86706,0.00001
17.25000,-2.87506,0.00001
17.30000,-2.88346,0.00000
17.35000,-2.89213,0.00001
17.40000,-2.90013,0.00000
17.45000,-2.90839,0.00003
17.50000,-2.91679,0.00004
17.55000,-2.92519,-0.00001
17.60000,-2.93333,0.00000
17.65000,-2.94159,0.00000
17.70000,-2.94999,0.00001
17.75000,-2.95839,0.00000
17.80000,-2.96666,0.00000
17.85000,-2.97506,0.00002
17.90000,-2.98359,0.00001
17.95000,-2.99186,0.00001
18.00000,-3.00013,0.00002
18.05000,-3.00853,-0.00002
18.10000,-3.01693,0.00001
18.15000,-3.02519,0.00000
18.20000,-3.03346,0.00000
18.25000,-3.04199,0.00002
18.30000,-3.05013,0.00000
18.35000,-3.05826,0.00001
18.40000,-3.06679,0.00000
18.45000,-3.07519,0.00001
18.50000,-3.08333,0.00000
18.55000,-3.09159,0.00000
18.60000,-3.10013,0.00000
18.65000,-3.10826,0.00000
18.70000,-3.11666,-0.00002
18.75000,-3.12519,0.00001
18.80000,-3.13359,0.00000
18.85000,-3.14199,0.00000
18.90000,-3.15026,-0.00001
18.95000,-3.15853,0.00002
19.00000,-3.16679,0.00003
19.05000,-3.17519,0.00000
19.10000,-3.18346,0.00001
19.15000,-3.19186,0.00003
19.20000,-3.20013,0.00003
19.25000,-3.20826,0.00001
19.30000,-3.21679,-0.00001
19.35000,-3.22506,0.00002
19.40000,-3.23319,0.00001
19.45000,-3.24186,0.00001
19.50000,-3.25039,0.00001
19.55000,-3.25853,-0.00002
19.60000,-3.26679,0.00003
19.65000,-3.27546,0.00000
19.70000,-3.28359,0.00000
19.75000,-3.29186,0.00001
19.80000,-3.30039,0.00001
19.85000,-3.30866,0.00000
19.90000,-3.31679,0.00002
19.95000,-3.32519,0.00002
20.00000,-3.33346,0.00003
20.05000,-3.34186,-0.00001
20.10000,-3.35026,0.00000
20.15000,-3.35826,0.00002
20.20000,-3.36693,-0.00002
20.25000,-3.37519,0.00002
20.30000,-3.38333,0.00001
20.35000,-3.39186,0.00003
20.40000,-3.40039,0.00000
20.45000,-3.40852,0.00001
20.50000,-3.41679,0.00001
20.55000,-3.42546,0.00000
20.60000,-3.43359,-0.00001
20.65000,-3.44172,0.00004
20.70000,-3.45012,0.00002
20.75000,-3.45852,0.00002
20.80000,-3.46666,0.00001
20.85000,-3.47492,0.00001
20.90000,-3.48332,0.00001
20.95000,-3.49159,0.00003
21.00000,-3.49999,0.00000
21.05000,-3.50839,0.00000
21.10000,-3.51679,0.00000
21.15000,-3.52519,0.00002
21.20000,-3.53346,0.00000
21.25000,-3.54186,0.00002
21.30000,-3.55026,-0.00001
21.35000,-3.55852,0.00001
21.40000,-3.56679,0.00003
21.45000,-3.57532,0.00002
21.50000,-3.58346,0.00000
21.55000,-3.59159,0.00001
21.60000,-3.60012,0.00000
21.65000,-3.60852,0.00003
21.70000,-3.61666,0.00000
21.75000,-3.62492,0.00001
21.80000,-3.63359,0.00002
21.85000,-3.64186,0.00003
21.90000,-3.65012,0.00002
21.95000,-3.65866,0.00000
22.00000,-3.66692,0.00001
22.05000,-3.67519,0.00000
22.10000,-3.68359,0.00001
22.15000,-3.69199,0.00001
22.20000,-3.70026,0.00000
22.25000,-3.70852,0.00003
22.30000,-3.71679,0.00002
22.35000,-3.72532,0.00000
22.40000,-3.73346,0.00001
22.45000,-3.74172,0.00001
22.50000,-3.75026,0.00001
22.55000,-3.75852,-0.00001
22.60000,-3.76666,0.00000
22.65000,-3.77519,0.00001
22.70000,-3.78359,0.00000
22.75000,-3.79172,0.00003
22.80000,-3.80012,0.00001
22.85000,-3.80879,0.00002
22.90000,-3.81679,0.00000
22.95000,-3.82506,0.00001
23.00000,-3.83359,0.00001
23.05000,-3.84186,-0.00005
23.10000,-3.85012,0.00002
23.15000,-3.85852,0.00001
23.20000,-3.86679,0.00001
23.25000,-3.87506,0.00002
23.30000,-3.88332,-0.00001
23.35000,-3.89146,0.00000
23.40000,-3.90012,-0.00001
23.45000,-3.90866,0.00001
23.50000,-3.91679,-0.00001
23.55000,-3.92532,-0.00001
23.60000,-3.93359,-0.00001
23.65000,-3.94172,0.00001
23.70000,-3.95012,0.00001
23.75000,-3.95866,0.00001
23.80000,-3.96679,0.00001
23.85000,-3.97506,0.00002
23.90000,-3.98359,0.00000
23.95000,-3.99186,-0.00002
24.00000,-3.99999,0.00002
24.05000,-4.00826,0.00000
24.10000,-4.01679,0.00001
24.15000,-4.02492,0.00002
24.20000,-4.03332,-0.00001
24.25000,-4.04172,0.00000
24.30000,-4.05012,0.00001
24.35000,-4.05852,0.00001
24.40000,-4.06679,0.00001
24.45000,-4.07532,0.00001
24.50000,-4.08359,-0.00001
24.55000,-4.09186,-0.00001
24.60000,-4.10012,-0.00001
24.65000,-4.10866,0.00001
24.70000,-4.11692,0.00000
24.75000,-4.12506,0.00000
24.80000,-4.13346,-0.00001
24.85000,-4.14186,0.00002
24.90000,-4.14999,0.00000
24.95000,-4.15826,-0.00002
25.00000,-4.16679,0.00001
25.05000,-4.17506,-0.00002
25.10000,-4.18332,-0.00002
25.15000,-4.19186,0.00002
25.20000,-4.20026,-0.00001
25.25000,-4.20866,0.00001
25.30000,-4.21692,-0.00002
25.35000,-4.22532,-0.00002
25.40000,-4.23359,0.00000
25.45000,-4.24199,0.00000
25.50000,-4.25012,0.00000
25.55000,-4.25852,-0.00001
25.60000,-4.26679,-0.00002
25.65000,-4.27492,0.00000
25.70000,-4.28359,-0.00001
25.75000,-4.29172,0.00000
25.80000,-4.29986,0.00000
25.85000,-4.30852,0.00000
25.90000,-4.31692,-0.00003
25.95000,-4.32506,-0.00001
26.00000,-4.33359,0.00002
26.05000,-4.34212,-0.00004
26.10000,-4.35026,-0.00002
26.15000,-4.35852,0.00001
26.20000,-4.36692,-0.00002
26.25000,-4.37532,-0.00001
26.30000,-4.38346,0.00000
26.35000,-4.39186,0.00001
26.40000,-4.40012,0.00001
26.45000,-4.40852,0.00000
26.50000,-4.41679,0.00002
26.55000,-4.42492,-0.00002
26.60000,-4.43346,-0.00001
26.65000,-4.44186,0.00001
26.70000,-4.44999,-0.00001
26.75000,-4.45852,-0.00001
26.80000,-4.46706,0.00000
26.85000,-4.47506,-0.00002
26.90000,-4.48346,0.00000
26.95000,-4.49199,-0.00002
27.00000,-4.50012,-0.00002
27.05000,-4.50839,-0.00004
27.10000,-4.51679,-0.00001
27.15000,-4.52506,0.00001
27.20000,-4.53319,0.00000
27.25000,-4.54146,-0.00002
27.30000,-4.54986,-0.00002
27.35000,-4.55826,-0.00002
27.40000,-4.56666,-0.00002
27.45000,-4.57519,-0.00001
27.50000,-4.58372,0.00000
27.55000,-4.59199,-0.00003
27.60000,-4.60012,-0.00002
27.65000,-4.60866,0.00000
27.70000,-4.61692,-0.00002
27.75000,-4.62519,-0.00002
27.80000,-4.63346,0.00000
27.85000,-4.64199,0.00001
27.90000,-4.65012,-0.00003
27.95000,-4.65839,-0.00001
28.00000,-4.66679,0.00001
28.05000,-4.67519,-0.00003
28.10000,-4.68319,-0.00002
28.15000,-4.69159,-0.00002
28.20000,-4.70012,-0.00001
28.25000,-4.70839,-0.00001
28.30000,-4.71679,-0.00002
28.35000,-4.72532,-0.00002
28.40000,-4.73359,-0.00002
28.45000,-4.74199,-0.00002
28.50000,-4.75039,-0.00002
28.55000,-4.75866,-0.00004
28.60000,-4.76692,-0.00002
28.65000,-4.77532,-0.00001
28.70000,-4.78346,-0.00001
28.75000,-4.79185,0.00000
28.80000,-4.80012,-0.00001
28.85000,-4.80826,-0.00001
28.90000,-4.81679,-0.00001
28.95000,-4.82492,-0.00001
29.00000,-4.83319,-0.00003
29.05000,-4.84185,-0.00003
29.10000,-4.85039,-0.00003
29.15000,-4.85852,-0.00002
29.20000,-4.86692,0.00000
29.25000,-4.87546,-0.00002
29.30000,-4.88359,-0.00004
29.35000,-4.89185,-0.00002
29.40000,-4.90039,-0.00003
29.45000,-4.90865,-0.00005
29.50000,-4.91692,-0.00001
29.55000,-4.92519,-0.00004
29.60000,-4.93345,-0.00004
29.65000,-4.94185,-0.00001
29.70000,-4.95012,0.00000
29.75000,-4.95825,-0.00002
29.80000,-4.96679,-0.00003
29.85000,-4.97519,-0.00001
29.90000,-4.98332,-0.00001
29.95000,-4.99185,-0.00004
30.00000,-5.00039,-0.00002
30.05000,-5.00852,-0.00004
30.10000,-5.01679,-0.00003
30.15000,-5.02545,-0.00002
30.20000,-5.03345,-0.00004
30.25000,-5.04159,-0.00002
30.30000,-5.04999,-0.00003
30.35000,-5.05852,-0.00001
30.40000,-5.06665,-0.00002
30.45000,-5.07505,-0.00004
30.50000,-5.08345,-0.00001
30.55000,-5.09172,-0.00005
30.60000,-5.09999,-0.00003
30.65000,-5.10839,-0.00001
30.70000,-5.11679,-0.00001
30.75000,-5.12519,-0.00001
30.80000,-5.13345,-0.00001
30.85000,-5.14185,-0.00002
30.90000,-5.15025,-0.00002
30.95000,-5.15839,-0.00003
31.00000,-5.16679,-0.00002
31.05000,-5.17532,-0.00005
31.10000,-5.18359,-0.00005
31.15000,-5.19172,-0.00002
31.20000,-5.19999,-0.00004
31.25000,-5.20825,-0.00002
31.30000,-5.21652,-0.00005
31.35000,-5.22492,-0.00004
31.40000,-5.23359,-0.00003
31.45000,-5.24185,-0.00002
31.50000,-5.25012,-0.00001
31.55000,-5.25865,-0.00005
31.60000,-5.26692,-0.00005
31.65000,-5.27519,-0.00004
31.70000,-5.28359,-0.00002
31.75000,-5.29199,-0.00003
31.80000,-5.30025,-0.00004
31.85000,-5.30852,-0.00002
31.90000,-5.31679,-0.00002
31.95000,-5.32532,-0.00003
32.00000,-5.33345,-0.00004
32.05000,-5.34159,-0.00005
32.10000,-5.35012,-0.00004
32.15000,-5.35839,-0.00002
32.20000,-5.36652,-0.00005
32.25000,-5.37505,-0.00003
32.30000,-5.38372,-0.00004
32.35000,-5.39185,-0.00004
32.40000,-5.40025,-0.00002
32.45000,-5.40879,-0.00003
32.50000,-5.41692,-0.00004
32.55000,-5.42519,-0.00005
32.60000,-5.43372,-0.00005
32.65000,-5.44185,-0.00006
32.70000,-5.45012,-0.00003
32.75000,-5.45852,-0.00004
32.80000,-5.46692,-0.00002
32.85000,-5.47519,-0.00003
32.90000,-5.48345,-0.00002
32.95000,-5.49159,-0.00004
33.00000,-5.50025,-0.00005
33.05000,-5.50852,-0.00007
33.05800,-5.50985,-0.00007