File: GFBaking/data/2_8PercentGluten/2_8gluten_4Point_1.is_flex_RawData/Specimen_RawData_1.csv
Time,Extension,Load
(sec),(mm),(N)
0.00000,1.21266,-0.00008
0.05000,1.21146,-0.00014
0.10000,1.20666,-0.00013
0.15000,1.19720,-0.00009
0.20000,1.18680,-0.00013
0.25000,1.17666,-0.00011
0.30000,1.16666,-0.00014
0.35000,1.15746,-0.00013
0.40000,1.14840,-0.00011
0.45000,1.13946,-0.00012
0.50000,1.13080,-0.00015
0.55000,1.12213,-0.00015
0.60000,1.11360,-0.00015
0.65000,1.10493,-0.00011
0.70000,1.09653,-0.00013
0.75000,1.08826,-0.00014
0.80000,1.07973,-0.00014
0.85000,1.07120,-0.00016
0.90000,1.06306,-0.00015
0.95000,1.05453,-0.00019
1.00000,1.04600,-0.00011
1.05000,1.03786,-0.00017
1.10000,1.02960,-0.00014
1.15000,1.02106,-0.00012
1.20000,1.01280,-0.00012
1.25000,1.00453,-0.00008
1.30000,0.99613,-0.00013
1.35000,0.98786,-0.00013
1.40000,0.97960,-0.00013
1.45000,0.97133,-0.00016
1.50000,0.96306,-0.00015
1.55000,0.95466,-0.00013
1.60000,0.94640,-0.00014
1.65000,0.93786,-0.00013
1.70000,0.92946,-0.00012
1.75000,0.92093,-0.00014
1.80000,0.91280,-0.00013
1.85000,0.90440,-0.00013
1.90000,0.89586,-0.00014
1.95000,0.88773,-0.00015
2.00000,0.87946,-0.00013
2.05000,0.87080,-0.00016
2.10000,0.86280,-0.00013
2.15000,0.85453,-0.00014
2.20000,0.84613,-0.00014
2.25000,0.83786,-0.00013
2.30000,0.82973,-0.00014
2.35000,0.82133,-0.00015
2.40000,0.81280,-0.00013
2.45000,0.80440,-0.00015
2.50000,0.79626,-0.00016
2.55000,0.78773,-0.00015
2.60000,0.77933,-0.00014
2.65000,0.77106,-0.00014
2.70000,0.76266,-0.00013
2.75000,0.75413,-0.00016
2.80000,0.74586,-0.00015
2.85000,0.73760,-0.00014
2.90000,0.72946,-0.00013
2.95000,0.72093,-0.00013
3.00000,0.71266,-0.00012
3.05000,0.70453,-0.00012
3.10000,0.69600,-0.00015
3.15000,0.68786,-0.00013
3.20000,0.67973,-0.00015
3.25000,0.67106,-0.00014
3.30000,0.66253,-0.00013
3.35000,0.65453,-0.00014
3.40000,0.64613,-0.00013
3.45000,0.63746,-0.00015
3.50000,0.62947,-0.00013
3.55000,0.62120,-0.00014
3.60000,0.61267,-0.00012
3.65000,0.60427,-0.00013
3.70000,0.59600,-0.00012
3.75000,0.58760,-0.00013
3.80000,0.57933,-0.00012
3.85000,0.57107,-0.00013
3.90000,0.56280,-0.00014
3.95000,0.55467,-0.00013
4.00000,0.54613,-0.00013
4.05000,0.53787,-0.00015
4.10000,0.52960,-0.00014
4.15000,0.52107,-0.00015
4.20000,0.51267,-0.00014
4.25000,0.50453,-0.00012
4.30000,0.49613,-0.00014
4.35000,0.48760,-0.00011
4.40000,0.47947,-0.00015
4.45000,0.47120,-0.00013
4.50000,0.46267,-0.00013
4.55000,0.45440,-0.00016
4.60000,0.44627,-0.00012
4.65000,0.43787,-0.00014
4.70000,0.42947,-0.00011
4.75000,0.42133,-0.00013
4.80000,0.41307,-0.00013
4.85000,0.40453,-0.00012
4.90000,0.39613,-0.00011
4.95000,0.38760,-0.00012
5.00000,0.37947,-0.00011
5.05000,0.37093,-0.00013
5.10000,0.36267,-0.00016
5.15000,0.35453,-0.00010
5.20000,0.34613,-0.00010
5.25000,0.33760,-0.00013
5.30000,0.32947,-0.00012
5.35000,0.32133,-0.00012
5.40000,0.31280,-0.00011
5.45000,0.30453,-0.00010
5.50000,0.29640,-0.00012
5.55000,0.28800,-0.00011
5.60000,0.27947,-0.00011
5.65000,0.27120,-0.00011
5.70000,0.26280,-0.00008
5.75000,0.25427,-0.00011
5.80000,0.24600,-0.00009
5.85000,0.23773,-0.00013
5.90000,0.22933,-0.00011
5.95000,0.22093,-0.00013
6.00000,0.21267,-0.00010
6.05000,0.20440,-0.00013
6.10000,0.19613,-0.00013
6.15000,0.18760,-0.00013
6.20000,0.17947,-0.00012
6.25000,0.17120,-0.00012
6.30000,0.16267,-0.00012
6.35000,0.15440,-0.00011
6.40000,0.14627,-0.00012
6.45000,0.13773,-0.00014
6.50000,0.12933,-0.00010
6.55000,0.12120,-0.00013
6.60000,0.11280,-0.00011
6.65000,0.10413,-0.00011
6.70000,0.09600,-0.00014
6.75000,0.08760,-0.00010
6.80000,0.07920,-0.00013
6.85000,0.07093,-0.00010
6.90000,0.06280,-0.00011
6.95000,0.05453,-0.00011
7.00000,0.04613,-0.00010
7.05000,0.03773,-0.00012
7.10000,0.02947,-0.00010
7.15000,0.02133,-0.00012
7.20000,0.01267,-0.00010
7.25000,0.00440,-0.00012
7.30000,-0.00373,-0.00011
7.35000,-0.01227,-0.00009
7.40000,-0.02067,-0.00012
7.45000,-0.02880,-0.00011
7.50000,-0.03720,-0.00013
7.55000,-0.04573,-0.00013
7.60000,-0.05387,-0.00009
7.65000,-0.06200,-0.00010
7.70000,-0.07053,-0.00012
7.75000,-0.07893,-0.00010
7.80000,-0.08707,-0.00010
7.85000,-0.09547,-0.00009
7.90000,-0.10373,-0.00008
7.95000,-0.11200,-0.00011
8.00000,-0.12027,-0.00010
8.05000,-0.12867,-0.00012
8.10000,-0.13720,-0.00010
8.15000,-0.14560,-0.00008
8.20000,-0.15387,-0.00008
8.25000,-0.16240,-0.00008
8.30000,-0.17067,-0.00010
8.35000,-0.17893,-0.00010
8.40000,-0.18720,-0.00008
8.45000,-0.19573,-0.00010
8.50000,-0.20387,-0.00009
8.55000,-0.21213,-0.00013
8.60000,-0.22067,-0.00008
8.65000,-0.22893,-0.00011
8.70000,-0.23707,-0.00009
8.75000,-0.24533,-0.00010
8.80000,-0.25387,-0.00008
8.85000,-0.26213,-0.00008
8.90000,-0.27040,-0.00010
8.95000,-0.27907,-0.00008
9.00000,-0.28733,-0.00008
9.05000,-0.29573,-0.00014
9.10000,-0.30400,-0.00007
9.15000,-0.31240,-0.00011
9.20000,-0.32067,-0.00010
9.25000,-0.32907,-0.00006
9.30000,-0.33720,-0.00005
9.35000,-0.34573,-0.00008
9.40000,-0.35387,-0.00010
9.45000,-0.36213,-0.00009
9.50000,-0.37067,-0.00007
9.55000,-0.37880,-0.00009
9.60000,-0.38707,-0.00005
9.65000,-0.39560,-0.00008
9.70000,-0.40400,-0.00007
9.75000,-0.41213,-0.00006
9.80000,-0.42067,-0.00005
9.85000,-0.42933,-0.00008
9.90000,-0.43733,-0.00008
9.95000,-0.44560,-0.00006
10.00000,-0.45400,-0.00006
10.05000,-0.46240,-0.00009
10.10000,-0.47067,-0.00006
10.15000,-0.47893,-0.00005
10.20000,-0.48733,-0.00005
10.25000,-0.49560,-0.00007
10.30000,-0.50387,-0.00005
10.35000,-0.51200,-0.00005
10.40000,-0.52053,-0.00006
10.45000,-0.52880,-0.00005
10.50000,-0.53693,-0.00007
10.55000,-0.54547,-0.00007
10.60000,-0.55400,-0.00005
10.65000,-0.56227,-0.00005
10.70000,-0.57053,-0.00004
10.75000,-0.57920,-0.00006
10.80000,-0.58720,-0.00006
10.85000,-0.59547,-0.00003
10.90000,-0.60387,-0.00002
10.95000,-0.61213,-0.00004
11.00000,-0.62027,-0.00006
11.05000,-0.62867,-0.00009
11.10000,-0.63720,-0.00006
11.15000,-0.64533,0.00000
11.20000,-0.65373,-0.00003
11.25000,-0.66213,-0.00006
11.30000,-0.67053,-0.00004
11.35000,-0.67880,-0.00007
11.40000,-0.68707,-0.00003
11.45000,-0.69546,-0.00001
11.50000,-0.70386,-0.00002
11.55000,-0.71213,-0.00003
11.60000,-0.72040,-0.00005
11.65000,-0.72906,-0.00001
11.70000,-0.73720,0.00000
11.75000,-0.74546,0.00002
11.80000,-0.75386,-0.00006
11.85000,-0.76213,0.00000
11.90000,-0.77040,-0.00004
11.95000,-0.77866,0.00000
12.00000,-0.78720,0.00002
12.05000,-0.79546,-0.00001
12.10000,-0.80386,-0.00003
12.15000,-0.81240,-0.00003
12.20000,-0.82066,0.00001
12.25000,-0.82893,0.00003
12.30000,-0.83720,0.00003
12.35000,-0.84573,0.00000
12.40000,-0.85400,-0.00003
12.45000,-0.86240,0.00000
12.50000,-0.87066,0.00003
12.55000,-0.87906,0.00003
12.60000,-0.88720,0.00002
12.65000,-0.89546,0.00000
12.70000,-0.90400,-0.00001
12.75000,-0.91213,0.00001
12.80000,-0.92040,0.00003
12.85000,-0.92893,0.00005
12.90000,-0.93733,0.00001
12.95000,-0.94546,0.00000
13.00000,-0.95386,0.00001
13.05000,-0.96253,0.00003
13.10000,-0.97053,0.00004
13.15000,-0.97893,0.00006
13.20000,-0.98746,0.00005
13.25000,-0.99573,0.00000
13.30000,-1.00386,0.00000
13.35000,-1.01226,0.00008
13.40000,-1.02053,0.00006
13.45000,-1.02893,0.00008
13.50000,-1.03720,0.00006
13.55000,-1.04533,0.00000
13.60000,-1.05386,0.00004
13.65000,-1.06213,0.00006
13.70000,-1.07040,0.00009
13.75000,-1.07893,0.00007
13.80000,-1.08733,0.00006
13.85000,-1.09546,0.00003
13.90000,-1.10386,0.00006
13.95000,-1.11253,0.00007
14.00000,-1.12053,0.00006
14.05000,-1.12880,0.00005
14.10000,-1.13720,0.00002
14.15000,-1.14546,0.00007
14.20000,-1.15373,0.00009
14.25000,-1.16200,0.00007
14.30000,-1.17053,0.00010
14.35000,-1.17866,0.00007
14.40000,-1.18693,0.00006
14.45000,-1.19533,0.00006
14.50000,-1.20386,0.00010
14.55000,-1.21213,0.00009
14.60000,-1.22040,0.00008
14.65000,-1.22893,0.00007
14.70000,-1.23733,0.00007
14.75000,-1.24560,0.00010
14.80000,-1.25386,0.00012
14.85000,-1.26253,0.00010
14.90000,-1.27066,0.00006
14.95000,-1.27880,0.00007
15.00000,-1.28720,0.00011
15.05000,-1.29546,0.00009
15.10000,-1.30360,0.00011
15.15000,-1.31200,0.00009
15.20000,-1.32066,0.00011
15.25000,-1.32893,0.00008
15.30000,-1.33720,0.00013
15.35000,-1.34573,0.00015
15.40000,-1.35400,0.00012
15.45000,-1.36226,0.00011
15.50000,-1.37066,0.00011
15.55000,-1.37906,0.00009
15.60000,-1.38746,0.00011
15.65000,-1.39573,0.00011
15.70000,-1.40386,0.00013
15.75000,-1.41240,0.00009
15.80000,-1.42053,0.00013
15.85000,-1.42880,0.00012
15.90000,-1.43733,0.00014
15.95000,-1.44560,0.00013
16.00000,-1.45360,0.00013
16.05000,-1.46226,0.00008
16.10000,-1.47080,0.00012
16.15000,-1.47880,0.00012
16.20000,-1.48706,0.00016
16.25000,-1.49573,0.00015
16.30000,-1.50386,0.00013
16.35000,-1.51226,0.00011
16.40000,-1.52066,0.00014
16.45000,-1.52893,0.00011
16.50000,-1.53720,0.00019
16.55000,-1.54560,0.00009
16.60000,-1.55386,0.00014
16.65000,-1.56226,0.00014
16.70000,-1.57053,0.00015
16.75000,-1.57866,0.00014
16.80000,-1.58733,0.00016
16.85000,-1.59560,0.00013
16.90000,-1.60373,0.00014
16.95000,-1.61213,0.00015
17.00000,-1.62080,0.00018
17.05000,-1.62880,0.00013
17.10000,-1.63720,0.00018
17.15000,-1.64586,0.00013
17.20000,-1.65386,0.00015
17.25000,-1.66213,0.00012
17.30000,-1.67053,0.00020
17.35000,-1.67880,0.00014
17.40000,-1.68706,0.00015
17.45000,-1.69533,0.00016
17.50000,-1.70373,0.00015
17.55000,-1.71200,0.00016
17.60000,-1.72026,0.00017
17.65000,-1.72866,0.00019
17.70000,-1.73733,0.00017
17.75000,-1.74573,0.00015
17.80000,-1.75386,0.00017
17.85000,-1.76240,0.00017
17.90000,-1.77066,0.00019
17.95000,-1.77893,0.00014
18.00000,-1.78720,0.00020
18.05000,-1.79573,0.00017
18.10000,-1.80386,0.00018
18.15000,-1.81200,0.00019
18.20000,-1.82053,0.00017
18.25000,-1.82880,0.00020
18.30000,-1.83693,0.00017
18.35000,-1.84533,0.00018
18.40000,-1.85400,0.00021
18.45000,-1.86213,0.00016
18.50000,-1.87040,0.00021
18.55000,-1.87906,0.00014
18.60000,-1.88746,0.00018
18.65000,-1.89573,0.00019
18.70000,-1.90413,0.00017
18.75000,-1.91253,0.00018
18.80000,-1.92066,0.00017
18.85000,-1.92906,0.00020
18.90000,-1.93720,0.00019
18.95000,-1.94560,0.00020
19.00000,-1.95386,0.00020
19.05000,-1.96200,0.00018
19.10000,-1.97053,0.00023
19.15000,-1.97880,0.00016
19.20000,-1.98693,0.00022
19.25000,-1.99546,0.00019
19.30000,-2.00400,0.00021
19.35000,-2.01213,0.00023
19.40000,-2.02053,0.00018
19.45000,-2.02920,0.00020
19.50000,-2.03733,0.00018
19.55000,-2.04560,0.00021
19.60000,-2.05413,0.00021
19.65000,-2.06239,0.00018
19.70000,-2.07053,0.00020
19.75000,-2.07893,0.00022
19.80000,-2.08719,0.00022
19.85000,-2.09560,0.00023
19.90000,-2.10386,0.00020
19.95000,-2.11199,0.00018
20.00000,-2.12053,0.00021
20.05000,-2.12893,0.00021
20.10000,-2.13706,0.00018
20.15000,-2.14573,0.00023
20.20000,-2.15413,0.00018
20.25000,-2.16213,0.00019
20.30000,-2.17053,0.00021
20.35000,-2.17906,0.00021
20.40000,-2.18733,0.00018
20.45000,-2.19559,0.00021
20.50000,-2.20399,0.00021
20.55000,-2.21213,0.00018
20.60000,-2.22026,0.00018
20.65000,-2.22879,0.00021
20.70000,-2.23719,0.00017
20.75000,-2.24533,0.00018
20.80000,-2.25373,0.00017
20.85000,-2.26213,0.00020
20.90000,-2.27066,0.00021
20.95000,-2.27893,0.00019
21.00000,-2.28719,0.00019
21.05000,-2.29559,0.00018
21.10000,-2.30413,0.00018
21.15000,-2.31213,0.00018
21.20000,-2.32039,0.00018
21.25000,-2.32893,0.00018
21.30000,-2.33719,0.00018
21.35000,-2.34546,0.00017
21.40000,-2.35386,0.00015
21.45000,-2.36226,0.00017
21.50000,-2.37039,0.00019
21.55000,-2.37866,0.00014
21.60000,-2.38733,0.00018
21.65000,-2.39546,0.00016
21.70000,-2.40399,0.00018
21.75000,-2.41239,0.00014
21.80000,-2.42066,0.00017
21.85000,-2.42893,0.00014
21.90000,-2.43733,0.00015
21.95000,-2.44573,0.00012
22.00000,-2.45399,0.00015
22.05000,-2.46226,0.00012
22.10000,-2.47053,0.00013
22.15000,-2.47906,0.00012
22.20000,-2.48719,0.00013
22.25000,-2.49533,0.00013
22.30000,-2.50386,0.00012
22.35000,-2.51213,0.00010
22.40000,-2.52026,0.00007
22.45000,-2.52879,0.00006
22.50000,-2.53746,0.00006
22.55000,-2.54559,0.00001
22.60000,-2.55386,0.00004
22.65000,-2.56253,0.00002
22.70000,-2.57079,0.00001
22.75000,-2.57906,-0.00002
22.80000,-2.58746,-0.00003
22.85000,-2.59573,-0.00005
22.90000,-2.60386,-0.00005
22.95000,-2.61226,-0.00007
23.00000,-2.62053,-0.00005
23.05000,-2.62893,-0.00010
23.10000,-2.63719,-0.00008
23.15000,-2.64533,-0.00012
23.20000,-2.65386,-0.00011
23.25000,-2.66226,-0.00011
23.30000,-2.67026,-0.00011
23.35000,-2.67893,-0.00012
23.40000,-2.68746,-0.00012
23.45000,-2.69546,-0.00014
23.50000,-2.70386,-0.00011
23.55000,-2.71253,-0.00015
23.60000,-2.72066,-0.00013
23.65000,-2.72879,-0.00012
23.70000,-2.73733,-0.00011
23.75000,-2.74559,-0.00013
23.80000,-2.75373,-0.00012
23.85000,-2.76213,-0.00013
23.90000,-2.77039,-0.00012
23.95000,-2.77866,-0.00013
24.00000,-2.78706,-0.00013
24.05000,-2.79533,-0.00014
24.10000,-2.80386,-0.00013
24.15000,-2.81239,-0.00011
24.20000,-2.82053,-0.00013
24.25000,-2.82893,-0.00012
24.30000,-2.83733,-0.00012
24.35000,-2.84546,-0.00013
24.40000,-2.85386,-0.00013
24.45000,-2.86239,-0.00013
24.50000,-2.87053,-0.00014
24.55000,-2.87879,-0.00014
24.60000,-2.88719,-0.00013
24.65000,-2.89559,-0.00012
24.70000,-2.90373,-0.00014
24.75000,-2.91199,-0.00015
24.80000,-2.92066,-0.00012
24.85000,-2.92879,-0.00013
24.90000,-2.93706,-0.00014
24.95000,-2.94559,-0.00013
25.00000,-2.95399,-0.00014
25.05000,-2.96226,-0.00016
25.10000,-2.97066,-0.00015
25.15000,-2.97906,-0.00013
25.20000,-2.98733,-0.00013
25.25000,-2.99573,-0.00013
25.30000,-3.00386,-0.00012
25.35000,-3.01239,-0.00013
25.40000,-3.02053,-0.00015
25.45000,-3.02866,-0.00014
25.50000,-3.03733,-0.00012
25.55000,-3.04559,-0.00016
25.60000,-3.05373,-0.00013
25.65000,-3.06226,-0.00015
25.70000,-3.07079,-0.00014
25.75000,-3.07879,-0.00016
25.80000,-3.08719,-0.00011
25.85000,-3.09586,-0.00014
25.90000,-3.10386,-0.00015
25.95000,-3.11213,-0.00012
26.00000,-3.12066,-0.00012
26.05000,-3.12893,-0.00017
26.10000,-3.13719,-0.00013
26.15000,-3.14546,-0.00013
26.20000,-3.15386,-0.00012
26.25000,-3.16213,-0.00013
26.30000,-3.17039,-0.00012
26.35000,-3.17853,-0.00013
26.40000,-3.18719,-0.00015
26.45000,-3.19559,-0.00014
26.50000,-3.20373,-0.00012
26.55000,-3.21226,-0.00015
26.60000,-3.22093,-0.00016
26.65000,-3.22893,-0.00013
26.70000,-3.23733,-0.00013
26.75000,-3.24586,-0.00012
26.80000,-3.25386,-0.00014
26.85000,-3.26213,-0.00012
26.90000,-3.27053,-0.00013
26.95000,-3.27879,-0.00013
27.00000,-3.28706,-0.00013
27.05000,-3.29546,-0.00016
27.10000,-3.30373,-0.00015
27.15000,-3.31213,-0.00015
27.20000,-3.32039,-0.00013
27.25000,-3.32879,-0.00013
27.30000,-3.33719,-0.00013
27.35000,-3.34546,-0.00013
27.40000,-3.35373,-0.00013
27.45000,-3.36213,-0.00014
27.50000,-3.37066,-0.00014
27.55000,-3.37879,-0.00015
27.60000,-3.38719,-0.00014
27.65000,-3.39573,-0.00015
27.70000,-3.40386,-0.00015
27.75000,-3.41212,-0.00013
27.80000,-3.42052,-0.00013
27.85000,-3.42893,-0.00012
27.90000,-3.43706,-0.00013
27.95000,-3.44532,-0.00015
28.00000,-3.45399,-0.00013
28.05000,-3.46212,-0.00016
28.10000,-3.47052,-0.00015
28.15000,-3.47906,-0.00012
28.20000,-3.48732,-0.00013
28.25000,-3.49572,-0.00015
28.30000,-3.50399,-0.00015
28.35000,-3.51226,-0.00013
28.40000,-3.52066,-0.00013
28.45000,-3.52892,-0.00013
28.50000,-3.53719,-0.00012
28.55000,-3.54586,-0.00017
28.60000,-3.55399,-0.00016
28.65000,-3.56212,-0.00013
28.70000,-3.57066,-0.00013
28.75000,-3.57892,-0.00014
28.80000,-3.58706,-0.00013
28.85000,-3.59559,-0.00013
28.90000,-3.60412,-0.00014
28.95000,-3.61212,-0.00015
29.00000,-3.62052,-0.00013
29.05000,-3.62906,-0.00016
29.10000,-3.63732,-0.00014
29.15000,-3.64559,-0.00013
29.20000,-3.65412,-0.00016
29.25000,-3.66239,-0.00015
29.30000,-3.67052,-0.00014
29.35000,-3.67892,-0.00012
29.40000,-3.68719,-0.00014
29.45000,-3.69559,-0.00014
29.50000,-3.70372,-0.00013
29.55000,-3.71186,-0.00015
29.60000,-3.72039,-0.00014
29.65000,-3.72879,-0.00013
29.70000,-3.73692,-0.00013
29.75000,-3.74546,-0.00014
29.80000,-3.75399,-0.00014
29.85000,-3.76212,-0.00013
29.90000,-3.77052,-0.00012
29.95000,-3.77906,-0.00013
30.00000,-3.78719,-0.00014
30.05000,-3.79546,-0.00013
30.10000,-3.80386,-0.00014
30.15000,-3.81226,-0.00014
30.20000,-3.82039,-0.00012
30.25000,-3.82866,-0.00015
30.30000,-3.83706,-0.00013
30.35000,-3.84532,-0.00014
30.40000,-3.85359,-0.00015
30.45000,-3.86199,-0.00016
30.50000,-3.87052,-0.00014
30.55000,-3.87892,-0.00014
30.60000,-3.88719,-0.00012
30.65000,-3.89572,-0.00014
30.70000,-3.90412,-0.00015
30.75000,-3.91226,-0.00015
30.80000,-3.92052,-0.00012
30.85000,-3.92906,-0.00012
30.90000,-3.93719,-0.00015
30.95000,-3.94546,-0.00014
31.00000,-3.95386,-0.00013
31.05000,-3.96226,-0.00016
31.10000,-3.97039,-0.00015
31.15000,-3.97879,-0.00016
31.20000,-3.98732,-0.00013
31.25000,-3.99546,-0.00014
31.30000,-4.00386,-0.00014
31.35000,-4.01239,-0.00016
31.40000,-4.02066,-0.00014
31.45000,-4.02892,-0.00017
31.50000,-4.03732,-0.00015
31.55000,-4.04572,-0.00016
31.60000,-4.05412,-0.00015
31.65000,-4.06239,-0.00014
31.70000,-4.07052,-0.00013
31.75000,-4.07906,-0.00014
31.80000,-4.08719,-0.00015
31.85000,-4.09532,-0.00015
31.90000,-4.10399,-0.00013
31.95000,-4.11212,-0.00013
32.00000,-4.12026,-0.00015
32.05000,-4.12879,-0.00017
32.10000,-4.13746,-0.00016
32.15000,-4.14559,-0.00017
32.20000,-4.15386,-0.00013
32.25000,-4.16252,-0.00015
32.30000,-4.17066,-0.00015
32.35000,-4.17892,-0.00014
32.40000,-4.18732,-0.00014
32.45000,-4.19572,-0.00015
32.50000,-4.20399,-0.00014
32.55000,-4.21226,-0.00016
32.60000,-4.22052,-0.00012
32.65000,-4.22892,-0.00014
32.70000,-4.23719,-0.00013
32.75000,-4.24532,-0.00013
32.80000,-4.25386,-0.00016
32.85000,-4.26226,-0.00013
32.90000,-4.27039,-0.00012
32.95000,-4.27892,-0.00013
33.00000,-4.28732,-0.00014
33.05000,-4.29546,-0.00017
33.10000,-4.30386,-0.00012
33.15000,-4.31239,-0.00013
33.20000,-4.32066,-0.00015
33.25000,-4.32879,-0.00013
33.30000,-4.33719,-0.00012
33.35000,-4.34559,-0.00013
33.40000,-4.35386,-0.00013
33.45000,-4.36212,-0.00014
33.50000,-4.37052,-0.00012
33.55000,-4.37879,-0.00014
33.60000,-4.38692,-0.00014
33.65000,-4.39532,-0.00015
33.70000,-4.40399,-0.00016
33.75000,-4.41239,-0.00013
33.80000,-4.42052,-0.00014
33.85000,-4.42906,-0.00013
33.90000,-4.43732,-0.00013
33.95000,-4.44546,-0.00012
34.00000,-4.45386,-0.00012
34.05000,-4.46239,-0.00016
34.10000,-4.47052,-0.00015
34.15000,-4.47866,-0.00014
34.20000,-4.48719,-0.00013
34.25000,-4.49559,-0.00013
34.30000,-4.50359,-0.00013
34.35000,-4.51199,-0.00015
34.40000,-4.52066,-0.00013
34.45000,-4.52879,-0.00015
34.50000,-4.53706,-0.00014
34.55000,-4.54572,-0.00015
34.60000,-4.55399,-0.00015
34.65000,-4.56226,-0.00013
34.70000,-4.57066,-0.00014
34.75000,-4.57906,-0.00013
34.80000,-4.58746,-0.00016
34.85000,-4.59572,-0.00015
34.90000,-4.60386,-0.00013
34.95000,-4.61239,-0.00013
35.00000,-4.62052,-0.00013
35.05000,-4.62866,-0.00015
35.10000,-4.63719,-0.00013
35.15000,-4.64559,-0.00013
35.20000,-4.65372,-0.00014
35.25000,-4.66226,-0.00014
35.30000,-4.67079,-0.00012
35.35000,-4.67892,-0.00012
35.40000,-4.68732,-0.00013
35.45000,-4.69586,-0.00016
35.50000,-4.70399,-0.00015
35.55000,-4.71226,-0.00015
35.60000,-4.72066,-0.00015
35.65000,-4.72892,-0.00013
35.70000,-4.73732,-0.00012
35.75000,-4.74559,-0.00013
35.80000,-4.75386,-0.00012
35.85000,-4.76212,-0.00013
35.90000,-4.77039,-0.00014
35.95000,-4.77852,-0.00016
36.00000,-4.78719,-0.00015
36.05000,-4.79559,-0.00015
36.10000,-4.80372,-0.00014
36.15000,-4.81226,-0.00014
36.20000,-4.82066,-0.00014
36.25000,-4.82879,-0.00014
36.30000,-4.83719,-0.00012
36.35000,-4.84572,-0.00014
36.40000,-4.85385,-0.00013
36.45000,-4.86212,-0.00012
36.50000,-4.87052,-0.00013
36.55000,-4.87879,-0.00013
36.60000,-4.88705,-0.00015
36.65000,-4.89545,-0.00014
36.70000,-4.90372,-0.00012
36.75000,-4.91199,-0.00013
36.80000,-4.92039,-0.00014
36.85000,-4.92879,-0.00014
36.90000,-4.93732,-0.00015
36.95000,-4.94559,-0.00010
37.00000,-4.95372,-0.00012
37.05000,-4.96225,-0.00015
37.10000,-4.97065,-0.00015
37.15000,-4.97892,-0.00016
37.20000,-4.98719,-0.00013
37.25000,-4.99572,-0.00014
37.30000,-5.00385,-0.00012
37.35000,-5.01199,-0.00014
37.40000,-5.02052,-0.00014
37.45000,-5.02892,-0.00014
37.50000,-5.03705,-0.00013
37.55000,-5.04545,-0.00016
37.60000,-5.05399,-0.00013
37.65000,-5.06212,-0.00013
37.70000,-5.07025,-0.00014
37.75000,-5.07892,-0.00014
37.80000,-5.08745,-0.00013
37.85000,-5.09572,-0.00015
37.90000,-5.10412,-0.00014
37.95000,-5.11239,-0.00012
38.00000,-5.12065,-0.00012
38.05000,-5.12892,-0.00015
38.10000,-5.13719,-0.00012
38.15000,-5.14572,-0.00015
38.20000,-5.15385,-0.00013
38.25000,-5.16199,-0.00014
38.30000,-5.17052,-0.00013
38.35000,-5.17879,-0.00013
38.38800,-5.18492,-0.00013