File: GFBaking/data/2_8PercentGluten/2_8gluten_4Point_1.is_flex_RawData/Specimen_RawData_2.csv
Time,Extension,Load
(sec),(mm),(N)
0.00000,0.00000,0.00009
0.05000,-0.00107,-0.00002
0.10000,-0.00547,0.00000
0.15000,-0.01480,0.00000
0.20000,-0.02547,0.00001
0.25000,-0.03587,0.00001
0.30000,-0.04547,-0.00001
0.35000,-0.05520,0.00001
0.40000,-0.06427,0.00001
0.45000,-0.07307,0.00000
0.50000,-0.08200,0.00000
0.55000,-0.09067,-0.00001
0.60000,-0.09893,0.00000
0.65000,-0.10773,0.00001
0.70000,-0.11627,0.00000
0.75000,-0.12440,0.00000
0.80000,-0.13267,0.00000
0.85000,-0.14147,0.00000
0.90000,-0.14960,-0.00001
0.95000,-0.15800,0.00001
1.00000,-0.16667,0.00001
1.05000,-0.17493,-0.00001
1.10000,-0.18333,0.00000
1.15000,-0.19173,0.00001
1.20000,-0.20000,0.00002
1.25000,-0.20840,0.00001
1.30000,-0.21667,0.00001
1.35000,-0.22480,0.00002
1.40000,-0.23333,0.00001
1.45000,-0.24173,0.00000
1.50000,-0.24973,0.00001
1.55000,-0.25827,0.00000
1.60000,-0.26653,0.00001
1.65000,-0.27467,0.00001
1.70000,-0.28320,0.00001
1.75000,-0.29173,0.00002
1.80000,-0.30000,0.00001
1.85000,-0.30827,0.00001
1.90000,-0.31693,0.00001
1.95000,-0.32507,-0.00001
2.00000,-0.33333,0.00000
2.05000,-0.34173,0.00000
2.10000,-0.35000,0.00000
2.15000,-0.35827,0.00003
2.20000,-0.36667,-0.00001
2.25000,-0.37493,0.00002
2.30000,-0.38320,0.00002
2.35000,-0.39147,0.00001
2.40000,-0.39960,0.00000
2.45000,-0.40813,0.00000
2.50000,-0.41653,0.00003
2.55000,-0.42467,0.00000
2.60000,-0.43320,0.00001
2.65000,-0.44173,0.00002
2.70000,-0.45000,0.00000
2.75000,-0.45827,0.00003
2.80000,-0.46680,0.00000
2.85000,-0.47507,0.00001
2.90000,-0.48320,0.00003
2.95000,-0.49160,0.00003
3.00000,-0.50000,0.00002
3.05000,-0.50800,-0.00001
3.10000,-0.51640,0.00001
3.15000,-0.52493,0.00002
3.20000,-0.53307,0.00000
3.25000,-0.54147,0.00000
3.30000,-0.54973,0.00000
3.35000,-0.55827,0.00000
3.40000,-0.56653,0.00002
3.45000,-0.57480,0.00002
3.50000,-0.58307,0.00000
3.55000,-0.59160,-0.00001
3.60000,-0.59987,0.00003
3.65000,-0.60813,0.00003
3.70000,-0.61667,0.00002
3.75000,-0.62493,0.00001
3.80000,-0.63307,0.00000
3.85000,-0.64147,0.00001
3.90000,-0.65000,0.00002
3.95000,-0.65800,0.00002
4.00000,-0.66640,0.00000
4.05000,-0.67493,0.00001
4.10000,-0.68320,0.00001
4.15000,-0.69146,0.00003
4.20000,-0.70000,0.00001
4.25000,-0.70826,0.00003
4.30000,-0.71653,0.00003
4.35000,-0.72506,0.00002
4.40000,-0.73333,0.00003
4.45000,-0.74173,0.00001
4.50000,-0.75013,0.00002
4.55000,-0.75826,0.00002
4.60000,-0.76666,-0.00001
4.65000,-0.77493,0.00003
4.70000,-0.78306,0.00001
4.75000,-0.79160,0.00002
4.80000,-0.79986,0.00003
4.85000,-0.80800,0.00001
4.90000,-0.81653,0.00002
4.95000,-0.82506,0.00001
5.00000,-0.83320,0.00001
5.05000,-0.84160,0.00002
5.10000,-0.85013,0.00001
5.15000,-0.85826,0.00001
5.20000,-0.86653,0.00001
5.25000,-0.87506,0.00003
5.30000,-0.88346,0.00000
5.35000,-0.89160,0.00003
5.40000,-0.89986,0.00001
5.45000,-0.90826,0.00004
5.50000,-0.91653,0.00003
5.55000,-0.92480,0.00001
5.60000,-0.93293,0.00001
5.65000,-0.94146,0.00002
5.70000,-0.94986,0.00003
5.75000,-0.95813,0.00003
5.80000,-0.96653,0.00002
5.85000,-0.97506,0.00002
5.90000,-0.98320,0.00002
5.95000,-0.99146,0.00003
6.00000,-1.00013,0.00002
6.05000,-1.00826,0.00000
6.10000,-1.01653,0.00003
6.15000,-1.02480,0.00002
6.20000,-1.03333,0.00002
6.25000,-1.04146,0.00002
6.30000,-1.04973,0.00000
6.35000,-1.05813,0.00001
6.40000,-1.06640,0.00001
6.45000,-1.07466,0.00001
6.50000,-1.08306,0.00001
6.55000,-1.09146,0.00000
6.60000,-1.09986,0.00000
6.65000,-1.10826,0.00003
6.70000,-1.11666,0.00001
6.75000,-1.12506,0.00001
6.80000,-1.13346,0.00001
6.85000,-1.14160,0.00002
6.90000,-1.15013,-0.00001
6.95000,-1.15840,0.00002
7.00000,-1.16653,0.00001
7.05000,-1.17480,0.00001
7.10000,-1.18320,0.00003
7.15000,-1.19133,0.00001
7.20000,-1.19973,0.00001
7.25000,-1.20826,0.00001
7.30000,-1.21653,0.00002
7.35000,-1.22480,0.00003
7.40000,-1.23333,0.00000
7.45000,-1.24160,0.00002
7.50000,-1.25000,0.00001
7.55000,-1.25840,0.00001
7.60000,-1.26666,0.00002
7.65000,-1.27506,0.00002
7.70000,-1.28346,0.00002
7.75000,-1.29146,0.00004
7.80000,-1.30000,0.00002
7.85000,-1.30826,0.00002
7.90000,-1.31640,0.00001
7.95000,-1.32493,0.00004
8.00000,-1.33333,0.00001
8.05000,-1.34133,0.00000
8.10000,-1.34986,0.00002
8.15000,-1.35840,0.00003
8.20000,-1.36640,0.00000
8.25000,-1.37480,0.00003
8.30000,-1.38333,0.00001
8.35000,-1.39160,0.00001
8.40000,-1.39986,0.00001
8.45000,-1.40840,0.00002
8.50000,-1.41666,0.00002
8.55000,-1.42480,0.00000
8.60000,-1.43320,0.00001
8.65000,-1.44146,0.00004
8.70000,-1.44986,0.00001
8.75000,-1.45813,0.00003
8.80000,-1.46626,0.00003
8.85000,-1.47493,0.00002
8.90000,-1.48333,0.00001
8.95000,-1.49146,0.00003
9.00000,-1.49986,0.00002
9.05000,-1.50840,-0.00001
9.10000,-1.51666,0.00000
9.15000,-1.52480,0.00001
9.20000,-1.53333,0.00002
9.25000,-1.54173,0.00001
9.30000,-1.54986,0.00003
9.35000,-1.55826,0.00003
9.40000,-1.56666,0.00001
9.45000,-1.57480,0.00004
9.50000,-1.58306,0.00001
9.55000,-1.59146,-0.00002
9.60000,-1.59973,0.00001
9.65000,-1.60800,0.00001
9.70000,-1.61640,0.00002
9.75000,-1.62493,0.00000
9.80000,-1.63333,0.00002
9.85000,-1.64160,0.00002
9.90000,-1.65000,0.00001
9.95000,-1.65840,0.00001
10.00000,-1.66666,0.00001
10.05000,-1.67493,0.00000
10.10000,-1.68346,0.00001
10.15000,-1.69173,0.00001
10.20000,-1.69973,0.00001
10.25000,-1.70813,0.00000
10.30000,-1.71653,0.00003
10.35000,-1.72466,0.00002
10.40000,-1.73293,0.00002
10.45000,-1.74160,0.00001
10.50000,-1.74973,0.00001
10.55000,-1.75800,-0.00001
10.60000,-1.76666,0.00001
10.65000,-1.77506,0.00001
10.70000,-1.78346,0.00002
10.75000,-1.79186,0.00001
10.80000,-1.80000,0.00001
10.85000,-1.80840,0.00001
10.90000,-1.81680,0.00001
10.95000,-1.82480,0.00003
11.00000,-1.83333,0.00002
11.05000,-1.84160,0.00001
11.10000,-1.84960,0.00001
11.15000,-1.85826,0.00003
11.20000,-1.86666,0.00002
11.25000,-1.87466,0.00004
11.30000,-1.88320,0.00001
11.35000,-1.89173,0.00002
11.40000,-1.89986,0.00001
11.45000,-1.90826,0.00003
11.50000,-1.91680,0.00002
11.55000,-1.92493,0.00001
11.60000,-1.93320,0.00003
11.65000,-1.94173,0.00003
11.70000,-1.95000,0.00000
11.75000,-1.95826,0.00002
11.80000,-1.96653,0.00000
11.85000,-1.97493,0.00004
11.90000,-1.98320,0.00003
11.95000,-1.99146,0.00004
12.00000,-1.99960,0.00000
12.05000,-2.00813,0.00001
12.10000,-2.01653,0.00002
12.15000,-2.02480,0.00002
12.20000,-2.03319,0.00001
12.25000,-2.04186,0.00001
12.30000,-2.04986,0.00001
12.35000,-2.05813,0.00003
12.40000,-2.06680,0.00003
12.45000,-2.07506,0.00001
12.50000,-2.08319,0.00003
12.55000,-2.09159,0.00002
12.60000,-2.09999,0.00002
12.65000,-2.10813,0.00003
12.70000,-2.11639,0.00002
12.75000,-2.12493,0.00003
12.80000,-2.13306,0.00003
12.85000,-2.14146,0.00002
12.90000,-2.14973,0.00002
12.95000,-2.15826,0.00001
13.00000,-2.16666,0.00004
13.05000,-2.17493,0.00002
13.10000,-2.18333,0.00003
13.15000,-2.19173,0.00002
13.20000,-2.19999,0.00002
13.25000,-2.20813,0.00003
13.30000,-2.21666,0.00003
13.35000,-2.22493,0.00004
13.40000,-2.23306,0.00002
13.45000,-2.24159,0.00001
13.50000,-2.24999,0.00002
13.55000,-2.25813,0.00000
13.60000,-2.26639,0.00000
13.65000,-2.27493,0.00001
13.70000,-2.28319,0.00003
13.75000,-2.29146,0.00003
13.80000,-2.30013,0.00002
13.85000,-2.30839,0.00002
13.90000,-2.31666,0.00002
13.95000,-2.32506,0.00004
14.00000,-2.33333,0.00002
14.05000,-2.34173,0.00000
14.10000,-2.34999,0.00002
14.15000,-2.35813,0.00002
14.20000,-2.36666,0.00002
14.25000,-2.37493,0.00002
14.30000,-2.38306,0.00003
14.35000,-2.39159,0.00003
14.40000,-2.39986,0.00002
14.45000,-2.40786,0.00001
14.50000,-2.41626,0.00001
14.55000,-2.42506,0.00000
14.60000,-2.43319,0.00000
14.65000,-2.44159,0.00005
14.70000,-2.45026,0.00002
14.75000,-2.45839,0.00000
14.80000,-2.46653,0.00001
14.85000,-2.47506,0.00002
14.90000,-2.48346,0.00002
14.95000,-2.49159,0.00002
15.00000,-2.49986,0.00002
15.05000,-2.50813,0.00001
15.10000,-2.51653,0.00002
15.15000,-2.52493,0.00003
15.20000,-2.53306,0.00003
15.25000,-2.54159,0.00001
15.30000,-2.54999,0.00004
15.35000,-2.55813,0.00004
15.40000,-2.56653,0.00003
15.45000,-2.57506,0.00003
15.50000,-2.58319,0.00001
15.55000,-2.59146,0.00001
15.60000,-2.60013,0.00002
15.65000,-2.60839,0.00001
15.70000,-2.61653,0.00001
15.75000,-2.62493,0.00003
15.80000,-2.63333,0.00002
15.85000,-2.64146,0.00003
15.90000,-2.64973,0.00000
15.95000,-2.65813,0.00002
16.00000,-2.66639,0.00001
16.05000,-2.67466,0.00004
16.10000,-2.68306,0.00002
16.15000,-2.69159,0.00002
16.20000,-2.69999,0.00003
16.25000,-2.70826,0.00000
16.30000,-2.71666,0.00003
16.35000,-2.72506,0.00002
16.40000,-2.73319,0.00003
16.45000,-2.74146,0.00002
16.50000,-2.75013,0.00004
16.55000,-2.75826,0.00001
16.60000,-2.76639,0.00000
16.65000,-2.77479,0.00001
16.70000,-2.78333,0.00003
16.75000,-2.79133,0.00002
16.80000,-2.79973,0.00001
16.85000,-2.80839,0.00002
16.90000,-2.81653,0.00001
16.95000,-2.82479,0.00004
17.00000,-2.83333,0.00004
17.05000,-2.84173,0.00002
17.10000,-2.84999,0.00004
17.15000,-2.85826,0.00004
17.20000,-2.86666,0.00003
17.25000,-2.87506,0.00002
17.30000,-2.88346,0.00001
17.35000,-2.89146,0.00003
17.40000,-2.89999,0.00004
17.45000,-2.90826,0.00003
17.50000,-2.91626,0.00003
17.55000,-2.92493,0.00000
17.60000,-2.93333,0.00001
17.65000,-2.94133,0.00004
17.70000,-2.94986,0.00001
17.75000,-2.95839,0.00002
17.80000,-2.96653,0.00001
17.85000,-2.97493,0.00003
17.90000,-2.98346,0.00001
17.95000,-2.99159,0.00002
18.00000,-2.99986,0.00003
18.05000,-3.00839,0.00002
18.10000,-3.01666,0.00002
18.15000,-3.02493,0.00001
18.20000,-3.03333,0.00003
18.25000,-3.04159,0.00001
18.30000,-3.05013,0.00001
18.35000,-3.05826,0.00002
18.40000,-3.06626,0.00002
18.45000,-3.07479,0.00001
18.50000,-3.08333,0.00004
18.55000,-3.09146,0.00001
18.60000,-3.09986,0.00001
18.65000,-3.10853,0.00002
18.70000,-3.11666,0.00001
18.75000,-3.12493,0.00004
18.80000,-3.13346,0.00003
18.85000,-3.14173,0.00001
18.90000,-3.14986,0.00001
18.95000,-3.15813,0.00003
19.00000,-3.16653,0.00003
19.05000,-3.17479,0.00001
19.10000,-3.18306,0.00001
19.15000,-3.19146,0.00005
19.20000,-3.19986,0.00002
19.25000,-3.20813,0.00003
19.30000,-3.21653,0.00004
19.35000,-3.22479,0.00001
19.40000,-3.23333,0.00002
19.45000,-3.24159,0.00003
19.50000,-3.24986,0.00001
19.55000,-3.25839,0.00001
19.60000,-3.26666,0.00002
19.65000,-3.27479,0.00004
19.70000,-3.28346,0.00003
19.75000,-3.29173,0.00001
19.80000,-3.29973,0.00001
19.85000,-3.30813,0.00002
19.90000,-3.31666,0.00003
19.95000,-3.32466,0.00002
20.00000,-3.33293,0.00000
20.05000,-3.34159,0.00002
20.10000,-3.34986,0.00002
20.15000,-3.35813,0.00003
20.20000,-3.36666,0.00001
20.25000,-3.37493,0.00002
20.30000,-3.38333,0.00001
20.35000,-3.39159,0.00003
20.40000,-3.39999,0.00003
20.45000,-3.40839,0.00001
20.50000,-3.41666,0.00002
20.55000,-3.42479,0.00000
20.60000,-3.43346,0.00001
20.65000,-3.44172,0.00001
20.70000,-3.44986,0.00001
20.75000,-3.45839,0.00002
20.80000,-3.46666,0.00002
20.85000,-3.47479,0.00004
20.90000,-3.48319,0.00000
20.95000,-3.49172,0.00002
21.00000,-3.49986,0.00001
21.05000,-3.50812,0.00000
21.10000,-3.51679,0.00001
21.15000,-3.52506,0.00000
21.20000,-3.53332,0.00001
21.25000,-3.54172,0.00002
21.30000,-3.55012,0.00000
21.35000,-3.55839,0.00000
21.40000,-3.56652,0.00002
21.45000,-3.57479,0.00004
21.50000,-3.58319,0.00002
21.55000,-3.59146,0.00001
21.60000,-3.59959,0.00000
21.65000,-3.60812,0.00000
21.70000,-3.61639,0.00002
21.75000,-3.62466,0.00001
21.80000,-3.63306,0.00000
21.85000,-3.64172,0.00002
21.90000,-3.64986,0.00001
21.95000,-3.65812,0.00001
22.00000,-3.66666,0.00001
22.05000,-3.67506,0.00000
22.10000,-3.68319,0.00002
22.15000,-3.69146,0.00001
22.20000,-3.69986,0.00001
22.25000,-3.70799,-0.00002
22.30000,-3.71626,0.00000
22.35000,-3.72479,0.00000
22.40000,-3.73306,0.00001
22.45000,-3.74132,0.00003
22.50000,-3.74972,0.00001
22.55000,-3.75812,0.00000
22.60000,-3.76666,-0.00001
22.65000,-3.77492,0.00003
22.70000,-3.78332,0.00001
22.75000,-3.79186,0.00001
22.80000,-3.79999,-0.00001
22.85000,-3.80826,0.00000
22.90000,-3.81679,0.00000
22.95000,-3.82506,-0.00001
23.00000,-3.83306,-0.00001
23.05000,-3.84146,-0.00002
23.10000,-3.84999,0.00002
23.15000,-3.85812,0.00002
23.20000,-3.86639,0.00000
23.25000,-3.87506,-0.00001
23.30000,-3.88319,0.00000
23.35000,-3.89146,0.00001
23.40000,-3.89999,0.00001
23.45000,-3.90826,0.00001
23.50000,-3.91666,0.00000
23.55000,-3.92506,-0.00001
23.60000,-3.93332,-0.00001
23.65000,-3.94186,0.00000
23.70000,-3.95012,-0.00001
23.75000,-3.95812,0.00000
23.80000,-3.96679,0.00000
23.85000,-3.97506,0.00000
23.90000,-3.98292,-0.00001
23.95000,-3.99159,0.00002
24.00000,-3.99986,0.00001
24.05000,-4.00799,-0.00001
24.10000,-4.01639,-0.00001
24.15000,-4.02519,0.00000
24.20000,-4.03332,0.00000
24.25000,-4.04159,0.00000
24.30000,-4.05012,0.00001
24.35000,-4.05839,-0.00001
24.40000,-4.06666,-0.00002
24.45000,-4.07506,0.00000
24.50000,-4.08332,0.00001
24.55000,-4.09159,-0.00001
24.60000,-4.09986,0.00002
24.65000,-4.10812,0.00001
24.70000,-4.11666,0.00001
24.75000,-4.12492,0.00001
24.80000,-4.13306,0.00000
24.85000,-4.14159,-0.00001
24.90000,-4.14999,-0.00001
24.95000,-4.15812,0.00001
25.00000,-4.16666,-0.00001
25.05000,-4.17506,-0.00001
25.10000,-4.18332,0.00000
25.15000,-4.19159,0.00001
25.20000,-4.20012,0.00000
25.25000,-4.20839,-0.00003
25.30000,-4.21652,0.00001
25.35000,-4.22479,0.00001
25.40000,-4.23319,0.00001
25.45000,-4.24146,0.00001
25.50000,-4.24972,0.00000
25.55000,-4.25826,-0.00002
25.60000,-4.26639,-0.00003
25.65000,-4.27466,-0.00002
25.70000,-4.28306,-0.00002
25.75000,-4.29146,0.00000
25.80000,-4.29999,0.00000
25.85000,-4.30839,0.00000
25.90000,-4.31652,0.00000
25.95000,-4.32506,0.00000
26.00000,-4.33332,0.00000
26.05000,-4.34146,-0.00001
26.10000,-4.35012,0.00001
26.15000,-4.35839,-0.00001
26.20000,-4.36639,-0.00001
26.25000,-4.37479,-0.00002
26.30000,-4.38332,-0.00001
26.35000,-4.39132,-0.00001
26.40000,-4.39959,-0.00002
26.45000,-4.40826,-0.00001
26.50000,-4.41652,0.00001
26.55000,-4.42466,-0.00002
26.60000,-4.43332,0.00000
26.65000,-4.44172,-0.00001
26.70000,-4.44999,-0.00001
26.75000,-4.45826,0.00001
26.80000,-4.46666,0.00000
26.85000,-4.47519,-0.00001
26.90000,-4.48346,-0.00001
26.95000,-4.49146,-0.00002
27.00000,-4.50012,0.00001
27.05000,-4.50839,-0.00003
27.10000,-4.51639,0.00000
27.15000,-4.52479,0.00000
27.20000,-4.53332,0.00001
27.25000,-4.54146,-0.00001
27.30000,-4.54986,0.00000
27.35000,-4.55839,0.00000
27.40000,-4.56652,-0.00001
27.45000,-4.57492,0.00000
27.50000,-4.58346,-0.00001
27.55000,-4.59159,-0.00002
27.60000,-4.59986,-0.00002
27.65000,-4.60826,0.00000
27.70000,-4.61666,-0.00001
27.75000,-4.62492,-0.00001
27.80000,-4.63319,0.00000
27.85000,-4.64146,0.00001
27.90000,-4.64999,0.00001
27.95000,-4.65812,-0.00001
28.00000,-4.66626,-0.00002
28.05000,-4.67479,-0.00003
28.10000,-4.68319,0.00000
28.15000,-4.69146,0.00001
28.20000,-4.69986,0.00000
28.25000,-4.70839,-0.00001
28.30000,-4.71652,-0.00001
28.35000,-4.72479,0.00000
28.40000,-4.73332,-0.00002
28.45000,-4.74172,-0.00002
28.50000,-4.74972,-0.00002
28.55000,-4.75812,-0.00003
28.60000,-4.76652,-0.00002
28.65000,-4.77479,0.00000
28.70000,-4.78292,-0.00001
28.75000,-4.79145,0.00000
28.80000,-4.79985,0.00000
28.85000,-4.80812,-0.00002
28.90000,-4.81652,-0.00001
28.95000,-4.82506,0.00000
29.00000,-4.83332,0.00000
29.05000,-4.84159,-0.00004
29.10000,-4.84985,-0.00002
29.15000,-4.85839,-0.00001
29.20000,-4.86665,-0.00002
29.25000,-4.87492,-0.00002
29.30000,-4.88345,-0.00002
29.35000,-4.89159,-0.00001
29.40000,-4.89972,-0.00004
29.45000,-4.90825,-0.00003
29.50000,-4.91665,0.00000
29.55000,-4.92465,-0.00002
29.60000,-4.93305,-0.00003
29.65000,-4.94159,-0.00002
29.70000,-4.94972,-0.00001
29.75000,-4.95799,-0.00003
29.80000,-4.96652,-0.00003
29.85000,-4.97505,-0.00001
29.90000,-4.98332,-0.00001
29.95000,-4.99172,-0.00002
30.00000,-4.99999,-0.00002
30.05000,-5.00825,-0.00004
30.10000,-5.01665,-0.00002
30.15000,-5.02479,0.00000
30.20000,-5.03332,-0.00002
30.25000,-5.04159,-0.00001
30.30000,-5.04959,-0.00004
30.35000,-5.05825,-0.00005
30.40000,-5.06652,-0.00001
30.45000,-5.07465,-0.00003
30.50000,-5.08319,-0.00003
30.55000,-5.09185,-0.00005
30.60000,-5.09999,-0.00003
30.65000,-5.10825,-0.00001
30.70000,-5.11692,-0.00001
30.75000,-5.12492,-0.00002
30.80000,-5.13319,-0.00002
30.85000,-5.14172,-0.00002
30.90000,-5.14999,-0.00003
30.95000,-5.15825,-0.00003
31.00000,-5.16665,-0.00003
31.05000,-5.17479,-0.00003
31.10000,-5.18332,-0.00003
31.15000,-5.19159,-0.00001
31.20000,-5.19972,-0.00001
31.25000,-5.20825,-0.00002
31.30000,-5.21652,-0.00002
31.35000,-5.22479,-0.00002
31.40000,-5.23332,-0.00003
31.45000,-5.24172,-0.00003
31.50000,-5.24999,-0.00004
31.55000,-5.25812,-0.00005
31.60000,-5.26679,-0.00003
31.65000,-5.27505,-0.00005
31.70000,-5.28319,-0.00003
31.75000,-5.29159,-0.00001
31.80000,-5.29999,-0.00004
31.85000,-5.30812,-0.00001
31.90000,-5.31639,-0.00004
31.95000,-5.32479,-0.00004
32.00000,-5.33319,-0.00003
32.05000,-5.34132,-0.00005
32.10000,-5.34972,-0.00003
32.15000,-5.35825,-0.00002
32.20000,-5.36665,-0.00003
32.25000,-5.37479,-0.00003
32.30000,-5.38319,-0.00003
32.35000,-5.39172,-0.00002
32.40000,-5.39999,-0.00003
32.45000,-5.40812,-0.00002
32.50000,-5.41679,-0.00001
32.55000,-5.42492,-0.00005
32.60000,-5.43305,-0.00005
32.65000,-5.44145,-0.00006
32.70000,-5.44985,-0.00003
32.75000,-5.45799,-0.00006
32.80000,-5.46625,-0.00007
32.85000,-5.47492,-0.00005
32.90000,-5.48319,-0.00003
32.95000,-5.49145,-0.00001
33.00000,-5.49999,-0.00002
33.05000,-5.50825,-0.00004
33.10000,-5.51652,-0.00001
33.15000,-5.52505,-0.00002
33.20000,-5.53332,-0.00004
33.25000,-5.54159,-0.00002
33.30000,-5.54999,-0.00004
33.35000,-5.55812,-0.00003
33.40000,-5.56665,-0.00005
33.45000,-5.57492,-0.00005
33.50000,-5.58292,-0.00004
33.55000,-5.59159,-0.00006
33.60000,-5.59999,-0.00004
33.65000,-5.60799,-0.00003
33.70000,-5.61652,-0.00004
33.75000,-5.62505,-0.00004
33.80000,-5.63319,-0.00007
33.85000,-5.64145,-0.00003
33.90000,-5.65012,-0.00004
33.95000,-5.65825,-0.00006
34.00000,-5.66652,-0.00003
34.05000,-5.67519,-0.00004
34.10000,-5.68332,-0.00004
34.15000,-5.69145,-0.00003
34.20000,-5.69985,-0.00002
34.25000,-5.70812,-0.00002
34.30000,-5.71639,-0.00004
34.35000,-5.72465,-0.00005
34.40000,-5.73292,-0.00006
34.45000,-5.74145,-0.00006
34.50000,-5.74999,-0.00004
34.55000,-5.75825,-0.00006
34.60000,-5.76665,-0.00004
34.65000,-5.77519,-0.00005
34.70000,-5.78319,-0.00004
34.75000,-5.79159,-0.00001
34.80000,-5.80012,-0.00004
34.85000,-5.80839,-0.00005
34.90000,-5.81652,-0.00004
34.95000,-5.82479,-0.00003
35.00000,-5.83332,-0.00004
35.05000,-5.84145,-0.00004
35.10000,-5.84972,-0.00004
35.15000,-5.85825,-0.00004
35.20000,-5.86639,-0.00003
35.25000,-5.87465,-0.00004
35.30000,-5.88319,-0.00005
35.35000,-5.89159,-0.00003
35.40000,-5.89999,-0.00004
35.45000,-5.90825,-0.00003
35.50000,-5.91665,-0.00004
35.55000,-5.92505,-0.00005
35.60000,-5.93332,-0.00006
35.65000,-5.94159,-0.00004
35.70000,-5.95012,-0.00002
35.75000,-5.95839,-0.00005
35.80000,-5.96652,-0.00005
35.85000,-5.97492,-0.00004
35.90000,-5.98319,-0.00003
35.95000,-5.99132,-0.00005
36.00000,-5.99959,-0.00005
36.05000,-6.00825,-0.00004
36.10000,-6.01652,-0.00001
36.15000,-6.02479,-0.00003
36.20000,-6.03332,-0.00002
36.25000,-6.04159,-0.00003
36.30000,-6.04985,-0.00003
36.35000,-6.05839,-0.00004
36.40000,-6.06665,-0.00004
36.45000,-6.07505,-0.00005
36.50000,-6.08345,-0.00004
36.55000,-6.09145,-0.00005
36.60000,-6.09998,-0.00004
36.65000,-6.10825,-0.00005
36.70000,-6.11639,-0.00002
36.75000,-6.12492,-0.00003
36.80000,-6.13319,-0.00003
36.85000,-6.14132,-0.00002
36.90000,-6.14985,-0.00004
36.95000,-6.15838,-0.00004
37.00000,-6.16652,-0.00005
37.05000,-6.17479,-0.00003
37.10000,-6.18345,-0.00004
37.15000,-6.19172,-0.00004
37.20000,-6.19998,-0.00003
37.25000,-6.20838,-0.00004
37.30000,-6.21665,-0.00005
37.35000,-6.22479,-0.00002
37.40000,-6.23318,-0.00003
37.45000,-6.24158,-0.00003
37.50000,-6.24985,-0.00003
37.55000,-6.25825,-0.00005
37.60000,-6.26638,-0.00005
37.65000,-6.27492,-0.00006
37.70000,-6.28332,-0.00004