File: GFBaking/data/3TspPectin/3TspPectin_1.is_comp_RawData/Specimen_RawData_4.csv
Time,Extension,Load
(sec),(mm),(N)
0.00000,-0.00027,-0.00260
0.10000,-0.00693,-0.00520
0.20000,-0.02640,-0.01289
0.30000,-0.04627,-0.01582
0.40000,-0.06480,-0.01462
0.50000,-0.08227,-0.01551
0.60000,-0.09960,-0.01879
0.70000,-0.11640,-0.02313
0.80000,-0.13347,-0.02867
0.90000,-0.15027,-0.03015
1.00000,-0.16693,-0.02834
1.10000,-0.18400,-0.02787
1.20000,-0.20027,-0.03103
1.30000,-0.21693,-0.03699
1.40000,-0.23360,-0.04013
1.50000,-0.25013,-0.03905
1.60000,-0.26680,-0.04032
1.70000,-0.28387,-0.04252
1.80000,-0.30053,-0.04497
1.90000,-0.31693,-0.05145
2.00000,-0.33387,-0.06164
2.10000,-0.35013,-0.06616
2.20000,-0.36693,-0.06683
2.30000,-0.38360,-0.07392
2.40000,-0.40027,-0.07966
2.50000,-0.41720,-0.08044
2.60000,-0.43373,-0.08516
2.70000,-0.45053,-0.08778
2.80000,-0.46707,-0.09204
2.90000,-0.48373,-0.09346
3.00000,-0.50027,-0.09653
3.10000,-0.51707,-0.10024
3.20000,-0.53373,-0.10636
3.30000,-0.55040,-0.10969
3.40000,-0.56733,-0.11229
3.50000,-0.58373,-0.11957
3.60000,-0.60040,-0.12672
3.70000,-0.61707,-0.12919
3.80000,-0.63373,-0.13672
3.90000,-0.65027,-0.14446
4.00000,-0.66707,-0.14983
4.10000,-0.68386,-0.15728
4.20000,-0.70026,-0.16563
4.30000,-0.71733,-0.17081
4.40000,-0.73360,-0.17293
4.50000,-0.75026,-0.18380
4.60000,-0.76680,-0.18954
4.70000,-0.78346,-0.18992
4.80000,-0.80013,-0.19540
4.90000,-0.81706,-0.20809
5.00000,-0.83373,-0.21398
5.10000,-0.85026,-0.21520
5.20000,-0.86720,-0.22890
5.30000,-0.88333,-0.23695
5.40000,-0.90026,-0.24093
5.50000,-0.91693,-0.25126
5.60000,-0.93360,-0.25950
5.70000,-0.95053,-0.26685
5.80000,-0.96720,-0.27418
5.90000,-0.98386,-0.28601
6.00000,-1.00053,-0.29725
6.10000,-1.01720,-0.30236
6.20000,-1.03360,-0.31189
6.30000,-1.05040,-0.32152
6.40000,-1.06720,-0.32955
6.50000,-1.08360,-0.33914
6.60000,-1.10053,-0.34702
6.70000,-1.11693,-0.35704
6.80000,-1.13373,-0.36363
6.90000,-1.15040,-0.37275
7.00000,-1.16693,-0.38269
7.10000,-1.18346,-0.38969
7.20000,-1.20026,-0.39944
7.30000,-1.21720,-0.40704
7.40000,-1.23360,-0.41735
7.50000,-1.25053,-0.42606
7.60000,-1.26693,-0.43393
7.70000,-1.28360,-0.44268
7.80000,-1.30026,-0.45126
7.90000,-1.31680,-0.45492
8.00000,-1.33360,-0.46810
8.10000,-1.35040,-0.47805
8.20000,-1.36720,-0.48636
8.30000,-1.38360,-0.49620
8.40000,-1.40066,-0.50232
8.50000,-1.41680,-0.51157
8.60000,-1.43360,-0.52223
8.70000,-1.45026,-0.53068
8.80000,-1.46693,-0.54122
8.90000,-1.48386,-0.55308
9.00000,-1.50040,-0.56166
9.10000,-1.51720,-0.57033
9.20000,-1.53373,-0.57911
9.30000,-1.55053,-0.59054
9.40000,-1.56693,-0.59781
9.50000,-1.58373,-0.60531
9.60000,-1.60053,-0.61748
9.70000,-1.61706,-0.62611
9.80000,-1.63400,-0.63667
9.90000,-1.65053,-0.64682
10.00000,-1.66706,-0.65613
10.10000,-1.68373,-0.66676
10.20000,-1.70026,-0.67989
10.30000,-1.71680,-0.69303
10.40000,-1.73373,-0.70478
10.50000,-1.75053,-0.71494
10.60000,-1.76693,-0.72729
10.70000,-1.78400,-0.73894
10.80000,-1.80026,-0.74997
10.90000,-1.81693,-0.76029
11.00000,-1.83360,-0.77404
11.10000,-1.85013,-0.78704
11.20000,-1.86693,-0.79736
11.30000,-1.88373,-0.81090
11.40000,-1.90053,-0.82415
11.50000,-1.91680,-0.84091
11.60000,-1.93386,-0.84523
11.70000,-1.95026,-0.85695
11.80000,-1.96693,-0.87145
11.90000,-1.98360,-0.87924
12.00000,-2.00026,-0.89480
12.10000,-2.01720,-0.90475
12.20000,-2.03373,-0.91698
12.30000,-2.05053,-0.92959
12.40000,-2.06706,-0.94153
12.50000,-2.08373,-0.95246
12.60000,-2.10013,-0.96569
12.70000,-2.11706,-0.97463
12.80000,-2.13373,-0.98771
12.90000,-2.15026,-1.00129
13.00000,-2.16733,-1.01175
13.10000,-2.18386,-1.02128
13.20000,-2.20039,-1.03166
13.30000,-2.21706,-1.03745
13.40000,-2.23373,-1.05585
13.50000,-2.25013,-1.06600
13.60000,-2.26706,-1.07861
13.70000,-2.28386,-1.08998
13.80000,-2.30013,-1.09932
13.90000,-2.31719,-1.11515
14.00000,-2.33359,-1.12430
14.10000,-2.35026,-1.13584
14.20000,-2.36693,-1.14898
14.30000,-2.38346,-1.15861
14.40000,-2.40026,-1.16990
14.50000,-2.41706,-1.18507
14.60000,-2.43373,-1.19379
14.70000,-2.45026,-1.20051
14.80000,-2.46733,-1.21214
14.90000,-2.48346,-1.22129
15.00000,-2.50013,-1.23190
15.10000,-2.51693,-1.24613
15.20000,-2.53359,-1.25724
15.30000,-2.55053,-1.26438
15.40000,-2.56706,-1.27664
15.50000,-2.58373,-1.28863
15.60000,-2.60039,-1.30267
15.70000,-2.61706,-1.31397
15.80000,-2.63359,-1.32802
15.90000,-2.65026,-1.33838
16.00000,-2.66719,-1.35110
16.10000,-2.68373,-1.36223
16.20000,-2.70066,-1.37303
16.30000,-2.71706,-1.38524
16.40000,-2.73386,-1.39637
16.50000,-2.75039,-1.40806
16.60000,-2.76706,-1.41964
16.70000,-2.78359,-1.43053
16.80000,-2.80039,-1.44294
16.90000,-2.81719,-1.45556
17.00000,-2.83373,-1.46613
17.10000,-2.85066,-1.47948
17.20000,-2.86693,-1.48896
17.30000,-2.88359,-1.50170
17.40000,-2.90026,-1.51230
17.50000,-2.91679,-1.52454
17.60000,-2.93346,-1.53585
17.70000,-2.95039,-1.54816
17.80000,-2.96706,-1.55883
17.90000,-2.98359,-1.57161
18.00000,-3.00053,-1.58288
18.10000,-3.01679,-1.59253
18.20000,-3.03359,-1.60542
18.30000,-3.05026,-1.61634
18.40000,-3.06706,-1.62855
18.50000,-3.08386,-1.63737
18.60000,-3.10053,-1.65153
18.70000,-3.11719,-1.66031
18.80000,-3.13373,-1.67341
18.90000,-3.15053,-1.68322
19.00000,-3.16679,-1.69388
19.10000,-3.18373,-1.70754
19.20000,-3.20053,-1.71761
19.30000,-3.21706,-1.73154
19.40000,-3.23399,-1.74082
19.50000,-3.25039,-1.75150
19.60000,-3.26706,-1.76235
19.70000,-3.28373,-1.77523
19.80000,-3.30039,-1.78587
19.90000,-3.31693,-1.79719
20.00000,-3.33373,-1.80945
20.10000,-3.35053,-1.81950
20.20000,-3.36693,-1.83060
20.30000,-3.38399,-1.84288
20.40000,-3.40039,-1.85242
20.50000,-3.41706,-1.86302
20.60000,-3.43359,-1.87334
20.70000,-3.45012,-1.88242
20.80000,-3.46692,-1.89426
20.90000,-3.48372,-1.90535
21.00000,-3.50039,-1.91604
21.10000,-3.51692,-1.92638
21.20000,-3.53386,-1.93677
21.30000,-3.55012,-1.94705
21.40000,-3.56692,-1.95895
21.50000,-3.58359,-1.96926
21.60000,-3.60026,-1.97965
21.70000,-3.61706,-1.99198
21.80000,-3.63372,-2.00037
21.90000,-3.65052,-2.01129
22.00000,-3.66692,-2.02244
22.10000,-3.68372,-2.03325
22.20000,-3.70026,-2.04386
22.30000,-3.71706,-2.05384
22.40000,-3.73386,-2.06329
22.50000,-3.75039,-2.07377
22.60000,-3.76732,-2.08429
22.70000,-3.78386,-2.09367
22.80000,-3.80052,-2.10289
22.90000,-3.81706,-2.11240
23.00000,-3.83372,-2.12145
23.10000,-3.85026,-2.13101
23.20000,-3.86719,-2.14128
23.30000,-3.88386,-2.14962
23.40000,-3.90026,-2.15592
23.50000,-3.91719,-2.16548
23.60000,-3.93359,-2.17503
23.70000,-3.95039,-2.18429
23.80000,-3.96692,-2.19685
23.90000,-3.98346,-2.20688
24.00000,-4.00012,-2.21657
24.10000,-4.01706,-2.22669
24.20000,-4.03372,-2.23721
24.30000,-4.05026,-2.24753
24.40000,-4.06719,-2.25637
24.50000,-4.08346,-2.26286
24.60000,-4.10026,-2.26435
24.70000,-4.11679,-2.24748
24.80000,-4.13359,-2.26284
24.90000,-4.15039,-2.27532
25.00000,-4.16706,-2.28758
25.10000,-4.18386,-2.29838
25.20000,-4.20039,-2.31016
25.30000,-4.21719,-2.32040
25.40000,-4.23346,-2.32915
25.50000,-4.25039,-2.33895
25.60000,-4.26719,-2.34712
25.70000,-4.28372,-2.33559
25.80000,-4.30066,-2.35120
25.90000,-4.31706,-2.36288
26.00000,-4.33386,-2.37443
26.10000,-4.35026,-2.38424
26.20000,-4.36706,-2.39366
26.30000,-4.38359,-2.40337
26.40000,-4.40026,-2.41235
26.50000,-4.41706,-2.38355
26.60000,-4.43359,-2.34794
26.70000,-4.45066,-2.37156
26.80000,-4.46706,-2.38998
26.90000,-4.48372,-2.40530
27.00000,-4.50026,-2.41983
27.10000,-4.51679,-2.43184
27.20000,-4.53346,-2.44464
27.30000,-4.55039,-2.45574
27.40000,-4.56706,-2.41633
27.50000,-4.58359,-2.42971
27.60000,-4.60052,-2.44682
27.70000,-4.61679,-2.45925
27.80000,-4.63359,-2.47245
27.90000,-4.65026,-2.48338
28.00000,-4.66692,-2.49536
28.10000,-4.68386,-2.50701
28.20000,-4.70052,-2.51775
28.30000,-4.71719,-2.52852
28.40000,-4.73372,-2.53743
28.50000,-4.75052,-2.54770
28.60000,-4.76692,-2.55611
28.70000,-4.78372,-2.56687
28.80000,-4.80039,-2.57529
28.90000,-4.81706,-2.58403
29.00000,-4.83399,-2.59251
29.10000,-4.85052,-2.60059
29.20000,-4.86719,-2.60993
29.30000,-4.88359,-2.61843
29.40000,-4.90025,-2.62711
29.50000,-4.91679,-2.63615
29.60000,-4.93372,-2.64467
29.70000,-4.95039,-2.65304
29.80000,-4.96679,-2.66043
29.90000,-4.98385,-2.66995
30.00000,-5.00025,-2.67760
30.10000,-5.01692,-2.68264
30.20000,-5.03359,-2.69177
30.30000,-5.05025,-2.69956
30.40000,-5.06679,-2.70875
30.50000,-5.08372,-2.71599
30.60000,-5.10039,-2.72216
30.70000,-5.11692,-2.73179
30.80000,-5.13399,-2.73901
30.90000,-5.15012,-2.74661
31.00000,-5.16692,-2.75514
31.10000,-5.18359,-2.76296
31.20000,-5.20025,-2.77083
31.30000,-5.21705,-2.77873
31.40000,-5.23372,-2.78587
31.50000,-5.25052,-2.79434
31.60000,-5.26719,-2.80071
31.70000,-5.28399,-2.80875
31.80000,-5.30025,-2.81418
31.90000,-5.31705,-2.82362
32.00000,-5.33385,-2.82944
32.10000,-5.35039,-2.83870
32.20000,-5.36732,-2.84144
32.30000,-5.38385,-2.84845
32.40000,-5.40039,-2.85750
32.50000,-5.41705,-2.87058
32.60000,-5.43372,-2.87454
32.70000,-5.45012,-2.87983
32.80000,-5.46705,-2.88740
32.90000,-5.48372,-2.89544
33.00000,-5.50025,-2.90432
33.10000,-5.51732,-2.91192
33.20000,-5.53372,-2.91994
33.30000,-5.55025,-2.92670
33.40000,-5.56692,-2.93490
33.50000,-5.58345,-2.94225
33.60000,-5.60025,-2.95034
33.70000,-5.61705,-2.95822
33.80000,-5.63385,-2.96458
33.90000,-5.65025,-2.97006
34.00000,-5.66719,-2.97777
34.10000,-5.68345,-2.98553
34.20000,-5.70025,-2.99371
34.30000,-5.71692,-3.00038
34.40000,-5.73345,-3.00686
34.50000,-5.75039,-3.01310
34.60000,-5.76719,-3.02030
34.70000,-5.78385,-3.02589
34.80000,-5.80039,-3.03362
34.90000,-5.81705,-3.04099
35.00000,-5.83345,-3.04636
35.10000,-5.85025,-3.05466
35.20000,-5.86719,-3.06134
35.30000,-5.88359,-3.06865
35.40000,-5.90065,-3.07603
35.50000,-5.91719,-3.08348
35.60000,-5.93385,-3.08956
35.70000,-5.95039,-3.09619
35.80000,-5.96705,-3.10123
35.90000,-5.98359,-3.10690
36.00000,-6.00039,-3.11380
36.10000,-6.01719,-3.11842
36.20000,-6.03359,-3.12508
36.30000,-6.05065,-3.13096
36.40000,-6.06692,-3.13667
36.50000,-6.08359,-3.14122
36.60000,-6.10025,-3.14727
36.70000,-6.11679,-3.15218
36.80000,-6.13345,-3.15823
36.90000,-6.15038,-3.16348
37.00000,-6.16705,-3.16805
37.10000,-6.18359,-3.17448
37.20000,-6.20065,-3.18026
37.30000,-6.21678,-3.18429
37.40000,-6.23358,-3.19102
37.50000,-6.25025,-3.19545
37.60000,-6.26692,-3.20100
37.70000,-6.28385,-3.20692
37.80000,-6.30038,-3.21150
37.90000,-6.31718,-3.21741
38.00000,-6.33372,-3.22303
38.10000,-6.35052,-3.22894
38.20000,-6.36692,-3.23335
38.30000,-6.38372,-3.23878
38.40000,-6.40038,-3.24433
38.50000,-6.41692,-3.24869
38.60000,-6.43385,-3.25301
38.70000,-6.45052,-3.25775
38.80000,-6.46718,-3.26278
38.90000,-6.48372,-3.26782
39.00000,-6.50025,-3.27292
39.10000,-6.51678,-3.27797
39.20000,-6.53372,-3.28501
39.30000,-6.55038,-3.29026
39.40000,-6.56692,-3.29628
39.50000,-6.58398,-3.30333
39.60000,-6.60038,-3.30777
39.70000,-6.61705,-3.31404
39.80000,-6.63358,-3.32004
39.90000,-6.65025,-3.32598
40.00000,-6.66692,-3.33259
40.10000,-6.68372,-3.33899
40.20000,-6.70052,-3.34486
40.30000,-6.71692,-3.35080
40.40000,-6.73398,-3.35625
40.50000,-6.75012,-3.36082
40.60000,-6.76692,-3.36670
40.70000,-6.78372,-3.37195
40.80000,-6.80012,-3.37763
40.90000,-6.81705,-3.38369
41.00000,-6.83372,-3.38813
41.10000,-6.85052,-3.39319
41.20000,-6.86705,-3.39996
41.30000,-6.88372,-3.40416
41.40000,-6.90025,-3.40876
41.50000,-6.91705,-3.41525
41.60000,-6.93385,-3.42034
41.70000,-6.95025,-3.42444
41.80000,-6.96732,-3.43052
41.90000,-6.98385,-3.43519
42.00000,-7.00038,-3.44036
42.10000,-7.01705,-3.44597
42.20000,-7.03385,-3.45163
42.30000,-7.05025,-3.45544
42.40000,-7.06705,-3.46225
42.50000,-7.08372,-3.46636
42.60000,-7.10038,-3.47171
42.70000,-7.11732,-3.47785
42.80000,-7.13372,-3.48221
42.90000,-7.15012,-3.48801
43.00000,-7.16705,-3.49417
43.10000,-7.18345,-3.50005
43.20000,-7.20025,-3.50646
43.30000,-7.21705,-3.51315
43.40000,-7.23372,-3.51882
43.50000,-7.25025,-3.52552
43.60000,-7.26732,-3.53280
43.70000,-7.28345,-3.53890
43.80000,-7.30025,-3.54559
43.90000,-7.31692,-3.55141
44.00000,-7.33358,-3.55834
44.10000,-7.35052,-3.56477
44.20000,-7.36718,-3.57020
44.30000,-7.38372,-3.57454
44.40000,-7.40038,-3.58109
44.50000,-7.41718,-3.58548
44.60000,-7.43358,-3.58984
44.70000,-7.45038,-3.59636
44.80000,-7.46718,-3.59961
44.90000,-7.48358,-3.60481
45.00000,-7.50065,-3.61037
45.10000,-7.51718,-3.61457
45.20000,-7.53385,-3.61862
45.30000,-7.55038,-3.62404
45.40000,-7.56718,-3.62790
45.50000,-7.58358,-3.63105
45.60000,-7.60038,-3.63701
45.70000,-7.61718,-3.64066
45.80000,-7.63358,-3.64576
45.90000,-7.65065,-3.65022
46.00000,-7.66691,-3.65310
46.10000,-7.68358,-3.65751
46.20000,-7.70025,-3.66175
46.30000,-7.71678,-3.66640
46.40000,-7.73358,-3.67208
46.50000,-7.75038,-3.67838
46.60000,-7.76718,-3.68374
46.70000,-7.78371,-3.68992
46.80000,-7.80051,-3.69448
46.90000,-7.81678,-3.69873
47.00000,-7.83345,-3.70567
47.10000,-7.85025,-3.71018
47.20000,-7.86691,-3.71739
47.30000,-7.88385,-3.72116
47.40000,-7.90038,-3.72566
47.50000,-7.91718,-3.73123
47.60000,-7.93371,-3.73835
47.70000,-7.95051,-3.74402
47.80000,-7.96691,-3.74941
47.90000,-7.98358,-3.75636
48.00000,-8.00038,-3.76274
48.10000,-8.01691,-3.77039
48.20000,-8.03398,-3.77728
48.30000,-8.05051,-3.78366
48.40000,-8.06718,-3.79037
48.50000,-8.08371,-3.79723
48.60000,-8.10038,-3.80498
48.70000,-8.11691,-3.81134
48.80000,-8.13371,-3.81798
48.90000,-8.15038,-3.82515
49.00000,-8.16691,-3.83049
49.10000,-8.18398,-3.83824
49.20000,-8.20038,-3.84344
49.30000,-8.21691,-3.85110
49.40000,-8.23358,-3.85713
49.50000,-8.25011,-3.86247
49.60000,-8.26691,-3.87001
49.70000,-8.28371,-3.87578
49.80000,-8.30038,-3.88184
49.90000,-8.31691,-3.88878
50.00000,-8.33385,-3.89400
50.10000,-8.35011,-3.90043
50.20000,-8.36691,-3.90732
50.30000,-8.38358,-3.91395
50.40000,-8.40025,-3.92253
50.50000,-8.41705,-3.92924
50.60000,-8.43385,-3.93826
50.70000,-8.45051,-3.94489
50.80000,-8.46705,-3.95314
50.90000,-8.48371,-3.95934
51.00000,-8.50011,-3.96785
51.10000,-8.51705,-3.97625
51.20000,-8.53371,-3.98285
51.30000,-8.55025,-3.99010
51.40000,-8.56731,-3.99856
51.50000,-8.58385,-4.00621
51.60000,-8.60051,-4.01271
51.70000,-8.61691,-4.01924
51.80000,-8.63371,-4.02683
51.90000,-8.65011,-4.03177
52.00000,-8.66705,-4.03926
52.10000,-8.68385,-4.04627
52.20000,-8.70025,-4.05109
52.30000,-8.71731,-4.05592
52.40000,-8.73358,-4.06330
52.50000,-8.75038,-4.07048
52.60000,-8.76691,-4.07756
52.70000,-8.78345,-4.08380
52.80000,-8.80024,-4.09096
52.90000,-8.81691,-4.09891
53.00000,-8.83371,-4.10516
53.10000,-8.85024,-4.11508
53.20000,-8.86731,-4.12109
53.30000,-8.88358,-4.12546
53.40000,-8.90024,-4.13227
53.50000,-8.91691,-4.13887
53.60000,-8.93358,-4.14523
53.70000,-8.95038,-4.15383
53.80000,-8.96691,-4.16092
53.90000,-8.98371,-4.16958
54.00000,-9.00024,-4.17780
54.10000,-9.01704,-4.18609
54.20000,-9.03344,-4.19231
54.30000,-9.05038,-4.20100
54.40000,-9.06718,-4.20688
54.50000,-9.08371,-4.21449
54.60000,-9.10078,-4.22049
54.70000,-9.11704,-4.22655
54.80000,-9.13384,-4.23335
54.90000,-9.15038,-4.23980
55.00000,-9.16704,-4.24655
55.10000,-9.18344,-4.25160
55.20000,-9.20024,-4.25921
55.30000,-9.21704,-4.26371
55.40000,-9.23358,-4.27141
55.50000,-9.25064,-4.27831
55.60000,-9.26704,-4.28432
55.70000,-9.28371,-4.28984
55.80000,-9.30024,-4.29453
55.90000,-9.31678,-4.29980
56.00000,-9.33344,-4.30525
56.10000,-9.35051,-4.31238
56.20000,-9.36704,-4.31619
56.30000,-9.38358,-4.32386
56.40000,-9.40064,-4.32824
56.50000,-9.41678,-4.33308
56.60000,-9.43371,-4.33961
56.70000,-9.45024,-4.34463
56.80000,-9.46691,-4.35118
56.90000,-9.48384,-4.35715
57.00000,-9.50038,-4.36441
57.10000,-9.51718,-4.36861
57.20000,-9.53371,-4.37482
57.30000,-9.55051,-4.38026
57.40000,-9.56678,-4.38437
57.50000,-9.58371,-4.39081
57.60000,-9.60038,-4.39617
57.70000,-9.61704,-4.40226
57.80000,-9.63384,-4.40771
57.90000,-9.65051,-4.41414
58.00000,-9.66718,-4.41948
58.10000,-9.68371,-4.42513
58.20000,-9.70038,-4.42987
58.30000,-9.71678,-4.43485
58.40000,-9.73371,-4.44202
58.50000,-9.75038,-4.44644
58.60000,-9.76691,-4.45314
58.70000,-9.78398,-4.45770
58.80000,-9.80024,-4.46207
58.90000,-9.81691,-4.46746
59.00000,-9.83358,-4.47218
59.10000,-9.85011,-4.47625
59.20000,-9.86678,-4.48126
59.30000,-9.88371,-4.48747
59.40000,-9.90038,-4.49124
59.50000,-9.91691,-4.49759
59.60000,-9.93398,-4.50221
59.70000,-9.95011,-4.50426
59.80000,-9.96691,-4.50894
59.90000,-9.98358,-4.51170
60.00000,-10.00024,-4.51553
60.10000,-10.01704,-4.52072
60.20000,-10.03384,-4.52529
60.30000,-10.05051,-4.52895
60.40000,-10.06704,-4.53312
60.50000,-10.08384,-4.53659
60.60000,-10.10024,-4.53967
60.70000,-10.11704,-4.54499
60.80000,-10.13384,-4.54810
60.90000,-10.15038,-4.55184
61.00000,-10.16731,-4.55671
61.10000,-10.18371,-4.55979
61.20000,-10.20051,-4.56248
61.30000,-10.21704,-4.56587
61.40000,-10.23384,-4.56943
61.50000,-10.25011,-4.57083
61.60000,-10.26704,-4.57626
61.70000,-10.28371,-4.57814
61.80000,-10.30024,-4.58367
61.90000,-10.31731,-4.58684
62.00000,-10.33358,-4.58927
62.10000,-10.35024,-4.59351
62.20000,-10.36691,-4.59700
62.30000,-10.38344,-4.59995
62.40000,-10.40011,-4.60347
62.50000,-10.41704,-4.60820
62.60000,-10.43384,-4.61150
62.70000,-10.45024,-4.61657
62.80000,-10.46717,-4.62103
62.90000,-10.48344,-4.62409
63.00000,-10.50024,-4.62851
63.10000,-10.51691,-4.63242
63.20000,-10.53357,-4.63541
63.30000,-10.55037,-4.63983
63.40000,-10.56717,-4.64304
63.50000,-10.58384,-4.64561
63.60000,-10.60037,-4.65014
63.70000,-10.61717,-4.65450
63.80000,-10.63344,-4.65748
63.90000,-10.65037,-4.66335
64.00000,-10.66704,-4.66783
64.10001,-10.68371,-4.67356
64.20000,-10.70051,-4.67814
64.30000,-10.71704,-4.68402
64.40000,-10.73384,-4.68937
64.50000,-10.75024,-4.69246
64.60001,-10.76717,-4.69618
64.70000,-10.78357,-4.69933
64.80000,-10.80051,-4.70705
64.90000,-10.81717,-4.70986
65.00000,-10.83357,-4.71592
65.10001,-10.85064,-4.71985
65.20000,-10.86691,-4.72503
65.30000,-10.88357,-4.72903
65.40000,-10.90024,-4.73402
65.50000,-10.91691,-4.73899
65.60001,-10.93344,-4.74314
65.70001,-10.95037,-4.74720
65.80000,-10.96717,-4.75116
65.90000,-10.98371,-4.75689
66.00000,-11.00064,-4.76181
66.10001,-11.01691,-4.76549
66.20001,-11.03357,-4.77148
66.30000,-11.05024,-4.77687
66.40000,-11.06691,-4.78219
66.50000,-11.08384,-4.78928
66.60001,-11.10051,-4.79378
66.70001,-11.11717,-4.79925
66.80000,-11.13357,-4.80523
66.90000,-11.15051,-4.81102
67.00000,-11.16691,-4.81470
67.10001,-11.18357,-4.82183
67.20001,-11.20024,-4.82401
67.30000,-11.21691,-4.82953
67.40000,-11.23397,-4.83612
67.50000,-11.25051,-4.83914
67.60001,-11.26717,-4.84358
67.70001,-11.28371,-4.84734
67.80000,-11.30037,-4.85015
67.90000,-11.31691,-4.85319
68.00000,-11.33371,-4.86250
68.10001,-11.35037,-4.86449
68.20001,-11.36691,-4.87220
68.30000,-11.38397,-4.87818
68.40000,-11.40024,-4.88364
68.50000,-11.41691,-4.89100
68.60001,-11.43357,-4.89910
68.70001,-11.45024,-4.90286
68.80000,-11.46691,-4.90791
68.90000,-11.48371,-4.91654
69.00000,-11.50051,-4.92132
69.10001,-11.51691,-4.92751
69.20001,-11.53397,-4.93496
69.30000,-11.55024,-4.94088
69.40000,-11.56691,-4.94825
69.50000,-11.58357,-4.95309
69.60001,-11.60024,-4.96339
69.70001,-11.61717,-4.97076
69.80000,-11.63371,-4.97779
69.90000,-11.65050,-4.98518
70.00000,-11.66704,-4.99450
70.10001,-11.68384,-4.99965
70.20001,-11.70010,-5.00443
70.30000,-11.71704,-5.01398
70.40000,-11.73384,-5.01899
70.50000,-11.75037,-5.02463
70.60001,-11.76744,-5.03137
70.70001,-11.78384,-5.03593
70.80000,-11.80037,-5.04148
70.90000,-11.81704,-5.04720
71.00000,-11.83384,-5.05294
71.10001,-11.85010,-5.05843
71.20001,-11.86690,-5.06531
71.30000,-11.88370,-5.07057
71.40000,-11.90024,-5.07606
71.50000,-11.91730,-5.08065
71.60001,-11.93357,-5.08538
71.70001,-11.95037,-5.08941
71.80000,-11.96690,-5.09454
71.90000,-11.98357,-5.10038
72.00000,-12.00010,-5.10704
72.10001,-12.01704,-5.11419
72.20001,-12.03370,-5.11916
72.30000,-12.05024,-5.12860
72.40000,-12.06717,-5.13889
72.50000,-12.08357,-5.14218
72.60001,-12.10024,-5.14556
72.70001,-12.11690,-5.15317
72.80000,-12.13357,-5.16122
72.90000,-12.15050,-5.16983
73.00000,-12.16717,-5.17866
73.10001,-12.18370,-5.18204
73.20001,-12.20037,-5.19065
73.30000,-12.21717,-5.19968
73.40000,-12.23357,-5.20552
73.50000,-12.25024,-5.21492
73.60001,-12.26704,-5.22768
73.70001,-12.28370,-5.23611
73.80000,-12.30064,-5.23992
73.90000,-12.31717,-5.24737
74.00000,-12.33384,-5.25657
74.10001,-12.35037,-5.26459
74.20001,-12.36704,-5.27157
74.30000,-12.38344,-5.27533
74.40000,-12.40037,-5.28384
74.50000,-12.41717,-5.29081
74.60001,-12.43370,-5.29879
74.70001,-12.45064,-5.30699
74.80000,-12.46690,-5.31233
74.90000,-12.48344,-5.31688
75.00000,-12.50024,-5.32423
75.10001,-12.51677,-5.32906
75.20001,-12.53344,-5.33800
75.30000,-12.55037,-5.34576
75.40000,-12.56717,-5.35154
75.50000,-12.58357,-5.35798
75.60001,-12.60050,-5.36359
75.70001,-12.61677,-5.36738
75.80000,-12.63357,-5.37511
75.90000,-12.65024,-5.37976
76.00000,-12.66690,-5.38593
76.10001,-12.68370,-5.39022
76.20001,-12.70050,-5.39564
76.30000,-12.71717,-5.40029
76.40000,-12.73370,-5.40503
76.50000,-12.75037,-5.41089
76.60001,-12.76690,-5.41907
76.70001,-12.78370,-5.42962
76.80000,-12.80050,-5.43250
76.90000,-12.81704,-5.43777
77.00000,-12.83397,-5.44615
77.10001,-12.85050,-5.45114
77.20001,-12.86717,-5.45521
77.30000,-12.88370,-5.45939
77.40000,-12.90050,-5.46388
77.50000,-12.91690,-5.46720
77.60001,-12.93370,-5.47501
77.70001,-12.95050,-5.47972
77.80000,-12.96690,-5.48591
77.90000,-12.98397,-5.49167
78.00000,-13.00023,-5.49822
78.10001,-13.01690,-5.50677
78.20001,-13.03357,-5.51160
78.30000,-13.05010,-5.51799
78.40000,-13.06690,-5.52518
78.50000,-13.08370,-5.53239
78.60001,-13.10050,-5.53548
78.70001,-13.11690,-5.54316
78.80000,-13.13384,-5.54773
78.90000,-13.15023,-5.55009
79.00000,-13.16703,-5.55556
79.10001,-13.18343,-5.55854
79.20001,-13.20010,-5.56471
79.30000,-13.21717,-5.57467
79.40000,-13.23383,-5.58152
79.50000,-13.25063,-5.58644
79.60001,-13.26717,-5.59107
79.70001,-13.28383,-5.59588
79.80000,-13.30023,-5.59981
79.90000,-13.31703,-5.60423
80.00000,-13.33383,-5.60821
80.10001,-13.35037,-5.61226
80.20001,-13.36730,-5.61960
80.30000,-13.38383,-5.62419
80.40000,-13.40050,-5.62815
80.50001,-13.41703,-5.63232
80.60001,-13.43383,-5.63745
80.70001,-13.45023,-5.64212
80.80000,-13.46703,-5.65181
80.90000,-13.48397,-5.65876
81.00001,-13.50023,-5.66813
81.10001,-13.51717,-5.67738
81.20001,-13.53370,-5.68624
81.30000,-13.55023,-5.69625
81.40000,-13.56690,-5.70494
81.50001,-13.58343,-5.71520
81.60001,-13.60010,-5.72740
81.70001,-13.61703,-5.73953
81.80000,-13.63383,-5.74736
81.90000,-13.65037,-5.75712
82.00001,-13.66730,-5.76690
82.10001,-13.68357,-5.77430
82.20001,-13.70023,-5.78621
82.30000,-13.71690,-5.79374
82.40000,-13.73370,-5.80345
82.50001,-13.75050,-5.81325
82.60001,-13.76717,-5.82174
82.70001,-13.78383,-5.82996
82.80000,-13.80050,-5.84019
82.90000,-13.81717,-5.84802
83.00001,-13.83357,-5.85392
83.10001,-13.85023,-5.86242
83.20001,-13.86703,-5.86953
83.30000,-13.88383,-5.87935
83.40000,-13.90077,-5.88957
83.50001,-13.91717,-5.89513
83.60001,-13.93383,-5.90243
83.70001,-13.95037,-5.90861
83.80000,-13.96703,-5.91576
83.90000,-13.98357,-5.92092
84.00001,-14.00037,-5.92943
84.10001,-14.01717,-5.93673
84.20001,-14.03370,-5.94456
84.30000,-14.05063,-5.95215
84.40000,-14.06703,-5.95888
84.50001,-14.08357,-5.96621
84.60001,-14.10023,-5.97456
84.70001,-14.11690,-5.98312
84.80000,-14.13357,-5.99057
84.90000,-14.15050,-5.99888
85.00001,-14.16717,-6.00395
85.10001,-14.18357,-6.01297
85.20001,-14.20063,-6.02241
85.30000,-14.21690,-6.02997
85.40000,-14.23356,-6.03944
85.50001,-14.25023,-6.04616
85.60001,-14.26703,-6.05096
85.70001,-14.28383,-6.05887
85.80000,-14.30037,-6.06393
85.90000,-14.31717,-6.06622
86.00001,-14.33383,-6.07528
86.10001,-14.35050,-6.08123
86.20001,-14.36690,-6.08680
86.30000,-14.38370,-6.09509
86.40000,-14.40050,-6.10384
86.50001,-14.41703,-6.11245
86.60001,-14.43397,-6.12203
86.70001,-14.45050,-6.13016
86.80000,-14.46716,-6.13957
86.90000,-14.48383,-6.14736
87.00001,-14.50050,-6.15510
87.10001,-14.51663,-6.15997
87.20001,-14.53370,-6.17296
87.30000,-14.55050,-6.18294
87.40000,-14.56690,-6.19532
87.50001,-14.58410,-6.20468
87.60001,-14.60036,-6.21339
87.70001,-14.61703,-6.22052
87.80000,-14.63356,-6.22914
87.90000,-14.65010,-6.23844
88.00001,-14.66690,-6.24833
88.10001,-14.68370,-6.26214
88.20001,-14.70036,-6.27160
88.30000,-14.71690,-6.28485
88.40000,-14.73396,-6.29613
88.50001,-14.75010,-6.30598
88.60001,-14.76690,-6.31835
88.70001,-14.78356,-6.32717
88.80000,-14.80023,-6.33773
88.90000,-14.81716,-6.34950
89.00001,-14.83383,-6.35951
89.10001,-14.85063,-6.36892
89.20001,-14.86703,-6.38031
89.30000,-14.88383,-6.39069
89.40000,-14.90023,-6.39844
89.50001,-14.91703,-6.41330
89.60001,-14.93383,-6.42527
89.70001,-14.95036,-6.43830
89.80000,-14.96730,-6.45066
89.90000,-14.98383,-6.46141
90.00001,-15.00050,-6.47499
90.06800,-15.01170,-6.48364