File: GFBaking/data/3TspPectin/3TspPectin_1.is_comp_RawData/Specimen_RawData_2.csv
Time,Extension,Load
(sec),(mm),(N)
0.00000,-1.33506,-0.00687
0.10000,-1.34040,-0.00825
0.20000,-1.35986,-0.01517
0.30000,-1.38026,-0.02311
0.40000,-1.39933,-0.02968
0.50000,-1.41680,-0.03339
0.60000,-1.43400,-0.03657
0.70000,-1.45120,-0.04179
0.80000,-1.46786,-0.04724
0.90000,-1.48493,-0.05205
1.00000,-1.50160,-0.05865
1.10000,-1.51840,-0.05982
1.20000,-1.53480,-0.06732
1.30000,-1.55173,-0.07230
1.40000,-1.56826,-0.07990
1.50000,-1.58493,-0.08698
1.60000,-1.60186,-0.09645
1.70000,-1.61813,-0.10462
1.80000,-1.63493,-0.11471
1.90000,-1.65160,-0.12346
2.00000,-1.66826,-0.13284
2.10000,-1.68493,-0.14144
2.20000,-1.70146,-0.15054
2.30000,-1.71826,-0.16008
2.40000,-1.73493,-0.16990
2.50000,-1.75186,-0.17891
2.60000,-1.76826,-0.18945
2.70000,-1.78506,-0.19919
2.80000,-1.80146,-0.20922
2.90000,-1.81826,-0.21945
3.00000,-1.83493,-0.23002
3.10000,-1.85146,-0.24053
3.20000,-1.86826,-0.25096
3.30000,-1.88506,-0.26075
3.40000,-1.90173,-0.27194
3.50000,-1.91813,-0.28125
3.60000,-1.93506,-0.29353
3.70000,-1.95160,-0.30287
3.80000,-1.96800,-0.31453
3.90000,-1.98506,-0.32543
4.00000,-2.00160,-0.33562
4.10000,-2.01840,-0.34658
4.20000,-2.03506,-0.35868
4.30000,-2.05186,-0.36735
4.40000,-2.06826,-0.37978
4.50000,-2.08519,-0.39080
4.60000,-2.10159,-0.40089
4.70000,-2.11799,-0.41197
4.80000,-2.13519,-0.42428
4.90000,-2.15159,-0.43549
5.00000,-2.16839,-0.44633
5.10000,-2.18519,-0.45686
5.20000,-2.20159,-0.46853
5.30000,-2.21826,-0.48073
5.40000,-2.23493,-0.49265
5.50000,-2.25159,-0.50314
5.60000,-2.26826,-0.51618
5.70000,-2.28506,-0.52603
5.80000,-2.30159,-0.53794
5.90000,-2.31839,-0.54984
6.00000,-2.33493,-0.55948
6.10000,-2.35159,-0.57023
6.20000,-2.36826,-0.58010
6.30000,-2.38466,-0.59158
6.40000,-2.40159,-0.60246
6.50000,-2.41839,-0.61531
6.60000,-2.43519,-0.62605
6.70000,-2.45133,-0.63839
6.80000,-2.46839,-0.64949
6.90000,-2.48493,-0.66113
7.00000,-2.50146,-0.67181
7.10000,-2.51839,-0.68415
7.20000,-2.53493,-0.69627
7.30000,-2.55173,-0.70901
7.40000,-2.56826,-0.71936
7.50000,-2.58506,-0.73043
7.60000,-2.60146,-0.74230
7.70000,-2.61826,-0.75324
7.80000,-2.63479,-0.76308
7.90000,-2.65133,-0.77308
8.00000,-2.66853,-0.78427
8.10000,-2.68506,-0.79273
8.20000,-2.70186,-0.80597
8.30000,-2.71839,-0.81727
8.40000,-2.73493,-0.82871
8.50000,-2.75159,-0.83834
8.60000,-2.76839,-0.85136
8.70000,-2.78479,-0.86335
8.80000,-2.80159,-0.87493
8.90000,-2.81853,-0.88740
9.00000,-2.83479,-0.89449
9.10000,-2.85173,-0.90913
9.20000,-2.86826,-0.92028
9.30000,-2.88479,-0.93248
9.40000,-2.90159,-0.94492
9.50000,-2.91813,-0.95172
9.60000,-2.93493,-0.96191
9.70000,-2.95173,-0.97655
9.80000,-2.96853,-0.98347
9.90000,-2.98493,-0.99492
10.00000,-3.00186,-1.00421
10.10000,-3.01826,-1.01251
10.20000,-3.03466,-1.02340
10.30000,-3.05173,-1.03750
10.40000,-3.06813,-1.04869
10.50000,-3.08506,-1.05981
10.60000,-3.10173,-1.06704
10.70000,-3.11839,-1.07818
10.80000,-3.13479,-1.09022
10.90000,-3.15173,-1.10152
11.00000,-3.16826,-1.11072
11.10000,-3.18479,-1.12079
11.20000,-3.20186,-1.13273
11.30000,-3.21826,-1.14484
11.40000,-3.23506,-1.15681
11.50000,-3.25173,-1.16933
11.60000,-3.26839,-1.18070
11.70000,-3.28506,-1.19345
11.80000,-3.30159,-1.20558
11.90000,-3.31826,-1.21682
12.00000,-3.33493,-1.22845
12.10000,-3.35186,-1.23897
12.20000,-3.36826,-1.25066
12.30000,-3.38519,-1.26363
12.40000,-3.40159,-1.27546
12.50000,-3.41812,-1.28693
12.60000,-3.43492,-1.29932
12.70000,-3.45146,-1.31021
12.80000,-3.46826,-1.32197
12.90000,-3.48492,-1.33462
13.00000,-3.50172,-1.34480
13.10000,-3.51812,-1.35697
13.20000,-3.53506,-1.36716
13.30000,-3.55159,-1.37955
13.40000,-3.56812,-1.39217
13.50000,-3.58506,-1.40367
13.60000,-3.60159,-1.41417
13.70000,-3.61839,-1.42375
13.80000,-3.63506,-1.43560
13.90000,-3.65172,-1.44584
14.00000,-3.66812,-1.45556
14.10000,-3.68506,-1.46724
14.20000,-3.70159,-1.47957
14.30000,-3.71812,-1.48819
14.40000,-3.73519,-1.50077
14.50000,-3.75159,-1.51003
14.60000,-3.76839,-1.52275
14.70000,-3.78492,-1.52952
14.80000,-3.80146,-1.53788
14.90000,-3.81812,-1.54907
15.00000,-3.83492,-1.56039
15.10000,-3.85146,-1.56603
15.20000,-3.86812,-1.57630
15.30000,-3.88506,-1.58620
15.40000,-3.90159,-1.59394
15.50000,-3.91839,-1.60279
15.60000,-3.93492,-1.61169
15.70000,-3.95159,-1.62367
15.80000,-3.96826,-1.63414
15.90000,-3.98466,-1.64485
16.00000,-4.00159,-1.65640
16.10000,-4.01839,-1.66845
16.20000,-4.03519,-1.67969
16.30000,-4.05159,-1.68989
16.40000,-4.06839,-1.70166
16.50000,-4.08492,-1.71303
16.60000,-4.10146,-1.72343
16.70000,-4.11826,-1.73396
16.80000,-4.13492,-1.74482
16.90000,-4.15172,-1.75483
17.00000,-4.16839,-1.76500
17.10000,-4.18506,-1.77162
17.20000,-4.20146,-1.73219
17.30000,-4.21839,-1.75583
17.40000,-4.23492,-1.77036
17.50000,-4.25146,-1.78337
17.60000,-4.26852,-1.79507
17.70000,-4.28479,-1.80333
17.80000,-4.30172,-1.81255
17.90000,-4.31839,-1.82199
18.00000,-4.33492,-1.83131
18.10000,-4.35172,-1.84148
18.20000,-4.36839,-1.85125
18.30000,-4.38492,-1.86137
18.40000,-4.40159,-1.87244
18.50000,-4.41852,-1.88192
18.60000,-4.43479,-1.89202
18.70000,-4.45172,-1.90259
18.80000,-4.46826,-1.91095
18.90000,-4.48492,-1.91953
19.00000,-4.50146,-1.92749
19.10000,-4.51812,-1.93432
19.20000,-4.53492,-1.94271
19.30000,-4.55172,-1.95336
19.40000,-4.56852,-1.96149
19.50000,-4.58479,-1.97029
19.60000,-4.60172,-1.97947
19.70000,-4.61812,-1.98805
19.80000,-4.63466,-1.99674
19.90000,-4.65159,-2.00590
20.00000,-4.66826,-2.01486
20.10000,-4.68506,-2.02189
20.20000,-4.70172,-2.02872
20.30000,-4.71852,-2.03605
20.40000,-4.73492,-2.04391
20.50000,-4.75172,-2.04750
20.60000,-4.76826,-2.05396
20.70000,-4.78479,-2.06001
20.80000,-4.80185,-2.06692
20.90000,-4.81826,-2.07372
21.00000,-4.83505,-2.07779
21.10000,-4.85172,-2.08431
21.20000,-4.86839,-2.09103
21.30000,-4.88492,-2.09598
21.40000,-4.90159,-2.10326
21.50000,-4.91825,-2.10722
21.60000,-4.93492,-2.11377
21.70000,-4.95172,-2.11810
21.80000,-4.96812,-2.12109
21.90000,-4.98519,-2.12677
22.00000,-5.00159,-2.13159
22.10000,-5.01825,-2.13504
22.20000,-5.03479,-2.13887
22.30000,-5.05145,-2.14104
22.40000,-5.06825,-2.14545
22.50000,-5.08505,-2.14979
22.60000,-5.10172,-2.15669
22.70000,-5.11812,-2.15972
22.80000,-5.13505,-2.16705
22.90000,-5.15159,-2.17246
23.00000,-5.16812,-2.17832
23.10000,-5.18505,-2.18617
23.20000,-5.20145,-2.19078
23.30000,-5.21839,-2.19650
23.40000,-5.23505,-2.20216
23.50000,-5.25172,-2.21013
23.60000,-5.26812,-2.21809
23.70000,-5.28505,-2.22699
23.80000,-5.30159,-2.23197
23.90000,-5.31812,-2.23898
24.00000,-5.33519,-2.24624
24.10000,-5.35159,-2.25399
24.20000,-5.36839,-2.26155
24.30000,-5.38505,-2.26964
24.40000,-5.40172,-2.27804
24.50000,-5.41825,-2.28622
24.60000,-5.43505,-2.29246
24.70000,-5.45159,-2.29970
24.80000,-5.46825,-2.31117
24.90000,-5.48505,-2.32016
25.00000,-5.50159,-2.33028
25.10000,-5.51852,-2.34070
25.20000,-5.53492,-2.34760
25.30000,-5.55159,-2.35454
25.40000,-5.56825,-2.36397
25.50000,-5.58479,-2.37026
25.60000,-5.60159,-2.37376
25.70000,-5.61839,-2.38501
25.80000,-5.63505,-2.39389
25.90000,-5.65159,-2.40268
26.00000,-5.66839,-2.41317
26.10000,-5.68492,-2.41925
26.20000,-5.70132,-2.42683
26.30000,-5.71825,-2.43530
26.40000,-5.73479,-2.44470
26.50000,-5.75172,-2.45289
26.60000,-5.76825,-2.46289
26.70000,-5.78519,-2.47219
26.80000,-5.80159,-2.48164
26.90000,-5.81852,-2.49204
27.00000,-5.83492,-2.50133
27.10000,-5.85145,-2.50922
27.20000,-5.86852,-2.51698
27.30000,-5.88505,-2.52383
27.40000,-5.90172,-2.53209
27.50000,-5.91839,-2.54149
27.60000,-5.93505,-2.55128
27.70000,-5.95159,-2.55864
27.80000,-5.96825,-2.56562
27.90000,-5.98479,-2.57087
28.00000,-6.00159,-2.57847
28.10000,-6.01852,-2.58667
28.20000,-6.03492,-2.59405
28.30000,-6.05172,-2.60428
28.40000,-6.06812,-2.61190
28.50000,-6.08479,-2.62135
28.60000,-6.10158,-2.62927
28.70000,-6.11812,-2.63872
28.80000,-6.13505,-2.64707
28.90000,-6.15158,-2.65707
29.00000,-6.16839,-2.66568
29.10000,-6.18478,-2.67361
29.20000,-6.20172,-2.68099
29.30000,-6.21812,-2.68816
29.40000,-6.23478,-2.69766
29.50000,-6.25172,-2.70526
29.60000,-6.26812,-2.71413
29.70000,-6.28505,-2.72194
29.80000,-6.30185,-2.73094
29.90000,-6.31838,-2.73829
30.00000,-6.33478,-2.74689
30.10000,-6.35172,-2.75414
30.20000,-6.36812,-2.76145
30.30000,-6.38478,-2.77045
30.40000,-6.40185,-2.77718
30.50000,-6.41812,-2.78396
30.60000,-6.43505,-2.79264
30.70000,-6.45185,-2.80072
30.80000,-6.46838,-2.80724
30.90000,-6.48492,-2.81377
31.00000,-6.50172,-2.82160
31.10000,-6.51825,-2.82842
31.20000,-6.53478,-2.83608
31.30000,-6.55185,-2.84448
31.40000,-6.56825,-2.85199
31.50000,-6.58505,-2.85988
31.60000,-6.60158,-2.86614
31.70000,-6.61812,-2.87397
31.80000,-6.63492,-2.88062
31.90000,-6.65132,-2.88702
32.00000,-6.66825,-2.89486
32.10000,-6.68492,-2.90405
32.20000,-6.70185,-2.91146
32.30000,-6.71812,-2.91986
32.40000,-6.73505,-2.92853
32.50000,-6.75145,-2.93530
32.60000,-6.76812,-2.94471
32.70000,-6.78505,-2.95329
32.80000,-6.80158,-2.96244
32.90000,-6.81838,-2.97184
33.00000,-6.83492,-2.97970
33.10000,-6.85172,-2.98835
33.20000,-6.86812,-2.99553
33.30000,-6.88505,-2.98658
33.40000,-6.90158,-2.99188
33.50000,-6.91812,-3.00492
33.60000,-6.93518,-3.01618
33.70000,-6.95158,-3.02716
33.80000,-6.96838,-3.03787
33.90000,-6.98505,-3.04642
34.00000,-7.00172,-3.05664
34.10000,-7.01812,-3.06463
34.20000,-7.03492,-3.07482
34.30000,-7.05158,-3.08415
34.40000,-7.06825,-3.09489
34.50000,-7.08505,-3.10399
34.60000,-7.10158,-3.11164
34.70000,-7.11852,-3.11986
34.80000,-7.13492,-3.12999
34.90000,-7.15158,-3.13840
35.00000,-7.16825,-3.14657
35.10000,-7.18478,-3.15342
35.20000,-7.20158,-3.16140
35.30000,-7.21825,-3.16785
35.40000,-7.23518,-3.17645
35.50000,-7.25158,-3.18467
35.60000,-7.26838,-3.19238
35.70000,-7.28492,-3.19871
35.80000,-7.30145,-3.20745
35.90000,-7.31838,-3.21580
36.00000,-7.33465,-3.22197
36.10000,-7.35158,-3.23046
36.20000,-7.36825,-3.23719
36.30000,-7.38505,-3.24394
36.40000,-7.40158,-3.25121
36.50000,-7.41838,-3.26218
36.60000,-7.43492,-3.26549
36.70000,-7.45145,-3.27219
36.80000,-7.46852,-3.27872
36.90000,-7.48492,-3.28318
37.00000,-7.50171,-3.29164
37.10000,-7.51838,-3.30017
37.20000,-7.53492,-3.30360
37.30000,-7.55158,-3.31049
37.40000,-7.56838,-3.31571
37.50000,-7.58491,-3.32128
37.60000,-7.60158,-3.32728
37.70000,-7.61851,-3.33218
37.80000,-7.63491,-3.33736
37.90000,-7.65185,-3.34279
38.00000,-7.66811,-3.34645
38.10000,-7.68478,-3.35210
38.20000,-7.70145,-3.35852
38.30000,-7.71798,-3.36310
38.40000,-7.73491,-3.36934
38.50000,-7.75158,-3.37646
38.60000,-7.76838,-3.38175
38.70000,-7.78491,-3.38609
38.80000,-7.80171,-3.39475
38.90000,-7.81811,-3.39795
39.00000,-7.83465,-3.40139
39.10000,-7.85171,-3.40680
39.20000,-7.86825,-3.41240
39.30000,-7.88505,-3.41992
39.40000,-7.90185,-3.42604
39.50000,-7.91838,-3.43271
39.60000,-7.93478,-3.44036
39.70000,-7.95171,-3.44528
39.80000,-7.96825,-3.44740
39.90000,-7.98478,-3.45555
40.00000,-8.00185,-3.46205
40.10000,-8.01825,-3.46639
40.20000,-8.03505,-3.47253
40.30000,-8.05185,-3.47588
40.40000,-8.06838,-3.47963
40.50000,-8.08491,-3.48847
40.60000,-8.10171,-3.49362
40.70000,-8.11838,-3.49658
40.80000,-8.13491,-3.50200
40.90000,-8.15171,-3.50646
41.00000,-8.16825,-3.51239
41.10000,-8.18518,-3.51706
41.20000,-8.20158,-3.52221
41.30000,-8.21825,-3.52458
41.40000,-8.23491,-3.52321
41.50000,-8.25145,-3.53463
41.60000,-8.26825,-3.54230
41.70000,-8.28505,-3.54885
41.80000,-8.30185,-3.55523
41.90000,-8.31825,-3.55916
42.00000,-8.33505,-3.56437
42.10000,-8.35145,-3.57165
42.20000,-8.36798,-3.57860
42.30000,-8.38505,-3.58734
42.40000,-8.40145,-3.58117
42.50000,-8.41838,-3.60173
42.60000,-8.43491,-3.61210
42.70000,-8.45171,-3.60961
42.80000,-8.46825,-3.61648
42.90000,-8.48505,-3.61667
43.00000,-8.50158,-3.62127
43.10000,-8.51798,-3.63114
43.20000,-8.53518,-3.64041
43.30000,-8.55158,-3.64571
43.40000,-8.56838,-3.64931
43.50000,-8.58518,-3.65517
43.60000,-8.60158,-3.66189
43.70000,-8.61825,-3.66632
43.80000,-8.63505,-3.67362
43.90000,-8.65171,-3.67983
44.00000,-8.66825,-3.69017
44.10000,-8.68518,-3.69286
44.20000,-8.70158,-3.69918
44.30000,-8.71851,-3.70640
44.40000,-8.73491,-3.70907
44.50000,-8.75158,-3.71435
44.60000,-8.76825,-3.71907
44.70000,-8.78478,-3.72441
44.80000,-8.80158,-3.73008
44.90000,-8.81825,-3.73583
45.00000,-8.83505,-3.74169
45.10000,-8.85145,-3.74667
45.20000,-8.86838,-3.75217
45.30000,-8.88478,-3.75660
45.40000,-8.90145,-3.76048
45.50000,-8.91825,-3.76444
45.60000,-8.93478,-3.76841
45.70000,-8.95171,-3.77467
45.80000,-8.96838,-3.77938
45.90000,-8.98518,-3.78668
46.00000,-9.00145,-3.78932
46.10000,-9.01838,-3.79294
46.20000,-9.03478,-3.79490
46.30000,-9.05144,-3.80075
46.40000,-9.06851,-3.80472
46.50000,-9.08478,-3.80736
46.60000,-9.10171,-3.81107
46.70000,-9.11851,-3.81580
46.80000,-9.13491,-3.81785
46.90000,-9.15144,-3.82039
47.00000,-9.16824,-3.82350
47.10000,-9.18491,-3.82512
47.20000,-9.20158,-3.82951
47.30000,-9.21838,-3.82947
47.40000,-9.23478,-3.83428
47.50000,-9.25184,-3.83812
47.60000,-9.26824,-3.83882
47.70000,-9.28491,-3.84087
47.80000,-9.30158,-3.84418
47.90000,-9.31824,-3.84641
48.00000,-9.33491,-3.84842
48.10000,-9.35158,-3.85294
48.20000,-9.36838,-3.85570
48.30000,-9.38478,-3.85783
48.40000,-9.40171,-3.86105
48.50000,-9.41824,-3.86242
48.60000,-9.43478,-3.86590
48.70000,-9.45171,-3.86942
48.80000,-9.46811,-3.87343
48.90000,-9.48504,-3.87700
49.00000,-9.50171,-3.87900
49.10000,-9.51838,-3.88068
49.20000,-9.53478,-3.88214
49.30000,-9.55171,-3.88614
49.40000,-9.56824,-3.88771
49.50000,-9.58478,-3.89149
49.60000,-9.60198,-3.89491
49.70000,-9.61824,-3.89590
49.80000,-9.63518,-3.89988
49.90000,-9.65171,-3.90255
50.00000,-9.66824,-3.90431
50.10000,-9.68491,-3.90826
50.20000,-9.70171,-3.91388
50.30000,-9.71824,-3.92043
50.40000,-9.73491,-3.92425
50.50000,-9.75171,-3.92865
50.60000,-9.76824,-3.93210
50.70000,-9.78531,-3.93792
50.80000,-9.80158,-3.94119
50.90000,-9.81811,-3.94526
51.00000,-9.83491,-3.94882
51.10000,-9.85144,-3.95320
51.20000,-9.86824,-3.95711
51.30000,-9.88491,-3.96200
51.40000,-9.90171,-3.96522
51.50000,-9.91824,-3.96893
51.60000,-9.93504,-3.97356
51.70000,-9.95144,-3.97372
51.80000,-9.96811,-3.97446
51.90000,-9.98504,-3.97638
52.00000,-10.00158,-3.97950
52.10000,-10.01838,-3.98317
52.20000,-10.03504,-3.98744
52.30000,-10.05184,-3.99133
52.40000,-10.06824,-3.99373
52.50000,-10.08504,-3.99719
52.60000,-10.10158,-4.00004
52.70000,-10.11811,-4.00545
52.80000,-10.13504,-4.00911
52.90000,-10.15158,-4.01311
53.00000,-10.16838,-4.01930
53.10000,-10.18504,-4.02281
53.20000,-10.20171,-4.02689
53.30000,-10.21838,-4.03203
53.40000,-10.23491,-4.03712
53.50000,-10.25144,-4.04123
53.60000,-10.26824,-4.04562
53.70000,-10.28531,-4.04993
53.80000,-10.30158,-4.05561
53.90000,-10.31851,-4.06160
54.00000,-10.33491,-4.06610
54.10000,-10.35144,-4.07156
54.20000,-10.36811,-4.07541
54.30000,-10.38464,-4.08083
54.40000,-10.40157,-4.08642
54.50000,-10.41824,-4.09154
54.60000,-10.43517,-4.09389
54.70000,-10.45157,-4.09647
54.80000,-10.46851,-4.09998
54.90000,-10.48491,-4.10267
55.00000,-10.50144,-4.10639
55.10000,-10.51824,-4.10911
55.20000,-10.53477,-4.11272
55.30000,-10.55171,-4.11620
55.40000,-10.56824,-4.12169
55.50000,-10.58504,-4.12535
55.60000,-10.60131,-4.12953
55.70000,-10.61837,-4.13378
55.80000,-10.63491,-4.13642
55.90000,-10.65144,-4.14070
56.00000,-10.66851,-4.14616
56.10000,-10.68491,-4.14992
56.20000,-10.70184,-4.15523
56.30000,-10.71837,-4.15965
56.40000,-10.73504,-4.16380
56.50000,-10.75157,-4.16732
56.60000,-10.76824,-4.16881
56.70000,-10.78491,-4.17248
56.80000,-10.80157,-4.18097
56.90000,-10.81851,-4.18785
57.00000,-10.83491,-4.19539
57.10000,-10.85184,-4.20487
57.20000,-10.86811,-4.21626
57.30000,-10.88477,-4.22187
57.40000,-10.90157,-4.23039
57.50000,-10.91811,-4.23632
57.60000,-10.93491,-4.24386
57.70000,-10.95171,-4.25180
57.80000,-10.96837,-4.25644
57.90000,-10.98477,-4.26167
58.00000,-11.00157,-4.26831
58.10000,-11.01824,-4.27300
58.20000,-11.03477,-4.27879
58.30000,-11.05171,-4.28358
58.40000,-11.06811,-4.29007
58.50000,-11.08504,-4.29573
58.60000,-11.10171,-4.30280
58.70000,-11.11851,-4.30707
58.80000,-11.13477,-4.31165
58.90000,-11.15171,-4.31645
59.00000,-11.16811,-4.31932
59.10000,-11.18464,-4.32534
59.20000,-11.20171,-4.33151
59.30000,-11.21811,-4.33607
59.40000,-11.23504,-4.34141
59.50000,-11.25171,-4.34605
59.60000,-11.26837,-4.35007
59.70000,-11.28491,-4.35554
59.80000,-11.30171,-4.36100
59.90000,-11.31837,-4.36456
60.00000,-11.33504,-4.37102
60.10000,-11.35184,-4.37672
60.20000,-11.36837,-4.38237
60.30000,-11.38531,-4.38833
60.40000,-11.40157,-4.39095
60.50000,-11.41824,-4.39530
60.60000,-11.43491,-4.40075
60.70000,-11.45144,-4.40585
60.80000,-11.46824,-4.41225
60.90000,-11.48504,-4.42011
61.00000,-11.50184,-4.42271
61.10000,-11.51824,-4.42803
61.20000,-11.53504,-4.43505
61.30000,-11.55157,-4.43955
61.40000,-11.56810,-4.44703
61.50000,-11.58504,-4.45126
61.60000,-11.60157,-4.45704
61.70000,-11.61837,-4.46431
61.80000,-11.63504,-4.46996
61.90000,-11.65184,-4.47533
62.00000,-11.66810,-4.48115
62.10000,-11.68504,-4.48540
62.20000,-11.70157,-4.49079
62.30000,-11.71810,-4.49778
62.40000,-11.73504,-4.50282
62.50000,-11.75144,-4.50903
62.60000,-11.76850,-4.51762
62.70000,-11.78517,-4.52137
62.80000,-11.80170,-4.52528
62.90000,-11.81837,-4.53112
63.00000,-11.83504,-4.53577
63.10000,-11.85157,-4.54164
63.20000,-11.86824,-4.54681
63.30000,-11.88504,-4.55076
63.40000,-11.90144,-4.55636
63.50000,-11.91850,-4.56354
63.60000,-11.93490,-4.56769
63.70000,-11.95130,-4.57452
63.80000,-11.96797,-4.57795
63.90000,-11.98477,-4.58215
64.00000,-12.00157,-4.58608
64.10001,-12.01837,-4.59231
64.20000,-12.03517,-4.59604
64.30000,-12.05157,-4.60075
64.40000,-12.06850,-4.60734
64.50000,-12.08490,-4.60658
64.60001,-12.10144,-4.61222
64.70000,-12.11837,-4.61652
64.80000,-12.13477,-4.62320
64.90000,-12.15170,-4.62908
65.00000,-12.16837,-4.63442
65.10001,-12.18504,-4.63607
65.20000,-12.20157,-4.64075
65.30000,-12.21837,-4.64729
65.40000,-12.23490,-4.65219
65.50000,-12.25144,-4.65346
65.60001,-12.26864,-4.65840
65.70001,-12.28504,-4.66094
65.80000,-12.30184,-4.66778
65.90000,-12.31850,-4.66926
66.00000,-12.33490,-4.66941
66.10001,-12.35157,-4.67359
66.20001,-12.36824,-4.67957
66.30000,-12.38490,-4.68445
66.40000,-12.40144,-4.69177
66.50000,-12.41837,-4.69338
66.60001,-12.43477,-4.69652
66.70001,-12.45184,-4.70674
66.80000,-12.46824,-4.71716
66.90000,-12.48504,-4.72298
67.00000,-12.50157,-4.71961
67.10001,-12.51810,-4.72194
67.20001,-12.53490,-4.72699
67.30000,-12.55144,-4.73547
67.40000,-12.56837,-4.73559
67.50000,-12.58477,-4.73562
67.60001,-12.60184,-4.74271
67.70001,-12.61824,-4.74689
67.80000,-12.63477,-4.75393
67.90000,-12.65170,-4.75791
68.00000,-12.66824,-4.75810
68.10001,-12.68504,-4.76168
68.20001,-12.70170,-4.76882
68.30000,-12.71837,-4.78004
68.40000,-12.73477,-4.78293
68.50000,-12.75184,-4.78197
68.60001,-12.76824,-4.78362
68.70001,-12.78464,-4.79040
68.80000,-12.80184,-4.79375
68.90000,-12.81823,-4.79335
69.00000,-12.83504,-4.79625
69.10001,-12.85170,-4.79777
69.20001,-12.86837,-4.79532
69.30000,-12.88490,-4.79879
69.40000,-12.90157,-4.80476
69.50000,-12.91823,-4.80549
69.60001,-12.93490,-4.81016
69.70001,-12.95184,-4.80943
69.80000,-12.96823,-4.81360
69.90000,-12.98503,-4.81975
70.00000,-13.00157,-4.82336
70.10001,-13.01810,-4.82766
70.20001,-13.03490,-4.83171
70.30000,-13.05130,-4.83537
70.40000,-13.06810,-4.83721
70.50000,-13.08490,-4.84378
70.60001,-13.10183,-4.84758
70.70001,-13.11810,-4.85135
70.80000,-13.13503,-4.85752
70.90000,-13.15157,-4.86211
71.00000,-13.16797,-4.86871
71.10001,-13.18503,-4.87451
71.20001,-13.20157,-4.88099
71.30000,-13.21837,-4.88843
71.40000,-13.23517,-4.89597
71.50000,-13.25183,-4.90289
71.60001,-13.26823,-4.90955
71.70001,-13.28503,-4.91787
71.80000,-13.30143,-4.92431
71.90000,-13.31810,-4.93398
72.00000,-13.33517,-4.94325
72.10001,-13.35157,-4.95106
72.20001,-13.36837,-4.96089
72.30000,-13.38503,-4.96917
72.40000,-13.40157,-4.97832
72.50000,-13.41823,-4.98734
72.60001,-13.43503,-4.99588
72.70001,-13.45170,-5.00204
72.80000,-13.46823,-5.01182
72.90000,-13.48517,-5.01882
73.00000,-13.50157,-5.02498
73.10001,-13.51837,-5.03270
73.20001,-13.53490,-5.03923
73.30000,-13.55143,-5.04429
73.40000,-13.56823,-5.05199
73.50000,-13.58477,-5.05942
73.60001,-13.60157,-5.06652
73.70001,-13.61823,-5.07679
73.80000,-13.63517,-5.08471
73.90000,-13.65157,-5.09076
74.00000,-13.66823,-5.09893
74.10001,-13.68477,-5.10283
74.20001,-13.70143,-5.10958
74.30000,-13.71810,-5.11683
74.40000,-13.73477,-5.12408
74.50000,-13.75183,-5.13292
74.60001,-13.76850,-5.13946
74.70001,-13.78517,-5.14479
74.80000,-13.80157,-5.15035
74.90000,-13.81837,-5.15741
75.00000,-13.83490,-5.16273
75.10001,-13.85143,-5.16994
75.20001,-13.86850,-5.17657
75.30000,-13.88490,-5.18128
75.40000,-13.90183,-5.18865
75.50000,-13.91850,-5.19371
75.60001,-13.93503,-5.19913
75.70001,-13.95157,-5.20502
75.80000,-13.96823,-5.20950
75.90000,-13.98490,-5.21349
76.00000,-14.00157,-5.22012
76.10001,-14.01837,-5.22366
76.20001,-14.03477,-5.22779
76.30000,-14.05170,-5.23327
76.40000,-14.06823,-5.23701
76.50000,-14.08490,-5.24122
76.60001,-14.10157,-5.24580
76.70001,-14.11810,-5.24975
76.80000,-14.13490,-5.25571
76.90000,-14.15157,-5.26201
77.00000,-14.16837,-5.26630
77.10001,-14.18477,-5.27005
77.20001,-14.20170,-5.27615
77.30000,-14.21823,-5.27813
77.40000,-14.23477,-5.28383
77.50000,-14.25170,-5.28934
77.60001,-14.26823,-5.29963
77.70001,-14.28503,-5.30513
77.80000,-14.30170,-5.30768
77.90000,-14.31836,-5.31272
78.00000,-14.33477,-5.31674
78.10001,-14.35170,-5.31968
78.20001,-14.36823,-5.32367
78.30000,-14.38463,-5.32981
78.40000,-14.40170,-5.33291
78.50000,-14.41823,-5.33952
78.60001,-14.43516,-5.34595
78.70001,-14.45183,-5.34834
78.80000,-14.46836,-5.35221
78.90000,-14.48490,-5.35727
79.00000,-14.50156,-5.36269
79.10001,-14.51836,-5.37131
79.20001,-14.53476,-5.37872
79.30000,-14.55183,-5.38009
79.40000,-14.56823,-5.38622
79.50000,-14.58516,-5.39296
79.60001,-14.60156,-5.39472
79.70001,-14.61810,-5.40137
79.80000,-14.63490,-5.40759
79.90000,-14.65143,-5.41159
80.00000,-14.66823,-5.41748
80.10001,-14.68503,-5.42415
80.20001,-14.70183,-5.42943
80.30000,-14.71810,-5.43645
80.40000,-14.73516,-5.44697
80.50001,-14.75156,-5.45182
80.60001,-14.76810,-5.45781
80.70001,-14.78503,-5.46205
80.80000,-14.80143,-5.46917
80.90000,-14.81823,-5.47557
81.00001,-14.83490,-5.48379
81.10001,-14.85170,-5.48908
81.20001,-14.86810,-5.49801
81.30000,-14.88503,-5.50470
81.40000,-14.90156,-5.51073
81.50001,-14.91796,-5.52048
81.60001,-14.93516,-5.52771
81.70001,-14.95170,-5.53450
81.80000,-14.96850,-5.54288
81.90000,-14.98516,-5.54847
82.00001,-15.00170,-5.55451
82.10001,-15.01823,-5.56283
82.20001,-15.03490,-5.57047
82.30000,-15.05143,-5.57394
82.40000,-15.06823,-5.58729
82.50001,-15.08516,-5.59675
82.60001,-15.10156,-5.60539
82.70001,-15.11850,-5.61343
82.80000,-15.13490,-5.61671
82.90000,-15.15143,-5.62266
83.00001,-15.16810,-5.63087
83.10001,-15.18476,-5.63727
83.20001,-15.20156,-5.64734
83.30000,-15.21823,-5.65835
83.40000,-15.23516,-5.66785
83.50001,-15.25156,-5.67722
83.60001,-15.26850,-5.68994
83.70001,-15.28490,-5.69390
83.80000,-15.30143,-5.70383
83.90000,-15.31836,-5.71356
84.00001,-15.33476,-5.72293
84.10001,-15.35170,-5.73470
84.20001,-15.36836,-5.74369
84.30000,-15.38503,-5.75274
84.40000,-15.40156,-5.76214
84.50001,-15.41836,-5.77122
84.60001,-15.43476,-5.77748
84.70001,-15.45143,-5.78939
84.80000,-15.46850,-5.80186
84.90000,-15.48490,-5.81258
85.00001,-15.50170,-5.82482
85.10001,-15.51836,-5.83559
85.20001,-15.53516,-5.84561
85.30000,-15.55143,-5.85776
85.40000,-15.56823,-5.87181
85.50001,-15.58490,-5.87978
85.60001,-15.60156,-5.89375
85.70001,-15.61849,-5.90702
85.80000,-15.63490,-5.91968
85.90000,-15.65183,-5.93242
86.00001,-15.66823,-5.94342
86.10001,-15.68490,-5.95888
86.20001,-15.70156,-5.96860
86.30000,-15.71796,-5.97879
86.40000,-15.73490,-5.99179
86.50001,-15.75170,-6.00779
86.60001,-15.76849,-6.01710
86.70001,-15.78476,-6.02983
86.80000,-15.80169,-6.04085
86.90000,-15.81823,-6.05114
87.00001,-15.83476,-6.06469
87.10001,-15.85156,-6.08006
87.20001,-15.86823,-6.09297
87.30000,-15.88503,-6.10688
87.40000,-15.90183,-6.12195
87.50001,-15.91850,-6.13312
87.60001,-15.93490,-6.14585
87.70001,-15.95183,-6.15627
87.80000,-15.96810,-6.16593
87.90000,-15.98463,-6.18183
88.00001,-16.00183,-6.19393
88.10001,-16.01823,-6.20770
88.20001,-16.03503,-6.22018
88.30000,-16.05169,-6.23234
88.40000,-16.06836,-6.25072
88.50001,-16.08489,-6.26459
88.60001,-16.10169,-6.28034
88.70001,-16.11823,-6.28943
88.80000,-16.13489,-6.30640
88.90000,-16.15183,-6.32201
89.00001,-16.16823,-6.33499
89.10001,-16.18516,-6.35139
89.20001,-16.20156,-6.36219
89.30000,-16.21809,-6.37586
89.40000,-16.23489,-6.39247
89.50001,-16.25143,-6.40641
89.60001,-16.26823,-6.42049
89.70001,-16.28503,-6.43797
89.80000,-16.30183,-6.45410
89.90000,-16.31823,-6.47285
90.00001,-16.33503,-6.48880
90.10001,-16.35143,-6.49915
90.20001,-16.36809,-6.51336
90.29201,-16.38356,-6.52052