File: GFBaking/data/3TspPectin/3TspPectin_1.is_comp_RawData/Specimen_RawData_3.csv
Time,Extension,Load
(sec),(mm),(N)
0.00000,-0.00027,-0.00674
0.10000,-0.00573,-0.00618
0.20000,-0.02507,-0.01730
0.30000,-0.04560,-0.03601
0.40000,-0.06413,-0.04674
0.50000,-0.08200,-0.05139
0.60000,-0.09960,-0.05820
0.70000,-0.11653,-0.06667
0.80000,-0.13347,-0.07240
0.90000,-0.15000,-0.07796
1.00000,-0.16693,-0.09194
1.10000,-0.18333,-0.10348
1.20000,-0.20013,-0.10341
1.30000,-0.21707,-0.10756
1.40000,-0.23347,-0.11652
1.50000,-0.25053,-0.12174
1.60000,-0.26693,-0.12738
1.70000,-0.28360,-0.13811
1.80000,-0.30027,-0.14451
1.90000,-0.31693,-0.14731
2.00000,-0.33347,-0.15249
2.10000,-0.35027,-0.16424
2.20000,-0.36707,-0.17392
2.30000,-0.38360,-0.17963
2.40000,-0.40040,-0.18764
2.50000,-0.41693,-0.19320
2.60000,-0.43347,-0.20342
2.70000,-0.45027,-0.21197
2.80000,-0.46680,-0.22077
2.90000,-0.48333,-0.23385
3.00000,-0.50013,-0.24963
3.10000,-0.51693,-0.25897
3.20000,-0.53347,-0.26390
3.30000,-0.55040,-0.27309
3.40000,-0.56667,-0.27903
3.50000,-0.58333,-0.28112
3.60000,-0.60013,-0.28235
3.70000,-0.61680,-0.29440
3.80000,-0.63373,-0.30057
3.90000,-0.65040,-0.30771
4.00000,-0.66707,-0.31487
4.10000,-0.68346,-0.31935
4.20000,-0.70040,-0.32469
4.30000,-0.71680,-0.34004
4.40000,-0.73346,-0.35351
4.50000,-0.75040,-0.36291
4.60000,-0.76680,-0.37430
4.70000,-0.78373,-0.38606
4.80000,-0.80026,-0.39963
4.90000,-0.81706,-0.40946
5.00000,-0.83360,-0.42232
5.10000,-0.85026,-0.43160
5.20000,-0.86680,-0.43880
5.30000,-0.88360,-0.44603
5.40000,-0.90040,-0.46044
5.50000,-0.91680,-0.46826
5.60000,-0.93386,-0.47467
5.70000,-0.95013,-0.48260
5.80000,-0.96680,-0.49133
5.90000,-0.98346,-0.49921
6.00000,-1.00000,-0.51195
6.10000,-1.01680,-0.52360
6.20000,-1.03360,-0.53326
6.30000,-1.05026,-0.54162
6.40000,-1.06680,-0.55217
6.50000,-1.08373,-0.56258
6.60000,-1.10000,-0.57377
6.70000,-1.11666,-0.58603
6.80000,-1.13360,-0.59275
6.90000,-1.15013,-0.60299
7.00000,-1.16706,-0.61453
7.10000,-1.18360,-0.62100
7.20000,-1.20040,-0.63295
7.30000,-1.21680,-0.64311
7.40000,-1.23360,-0.64920
7.50000,-1.25013,-0.65986
7.60000,-1.26666,-0.67070
7.70000,-1.28373,-0.68136
7.80000,-1.30013,-0.69195
7.90000,-1.31720,-0.70206
8.00000,-1.33360,-0.71131
8.10000,-1.35026,-0.72129
8.20000,-1.36693,-0.73305
8.30000,-1.38360,-0.74356
8.40000,-1.40013,-0.75439
8.50000,-1.41693,-0.76466
8.60000,-1.43373,-0.77174
8.70000,-1.45013,-0.78117
8.80000,-1.46706,-0.79559
8.90000,-1.48333,-0.80693
9.00000,-1.50000,-0.81735
9.10000,-1.51680,-0.82695
9.20000,-1.53333,-0.83821
9.30000,-1.55013,-0.85042
9.40000,-1.56693,-0.86305
9.50000,-1.58373,-0.87399
9.60000,-1.60013,-0.88435
9.70000,-1.61706,-0.89565
9.80000,-1.63346,-0.90561
9.90000,-1.65013,-0.91769
10.00000,-1.66680,-0.92865
10.10000,-1.68346,-0.93955
10.20000,-1.70040,-0.94998
10.30000,-1.71693,-0.96069
10.40000,-1.73360,-0.97103
10.50000,-1.75013,-0.98199
10.60000,-1.76693,-0.99235
10.70000,-1.78346,-1.00219
10.80000,-1.80013,-1.01231
10.90000,-1.81706,-1.02236
11.00000,-1.83346,-1.03101
11.10000,-1.85026,-1.04215
11.20000,-1.86693,-1.05319
11.30000,-1.88360,-1.06256
11.40000,-1.90026,-1.07271
11.50000,-1.91680,-1.08287
11.60000,-1.93346,-1.09347
11.70000,-1.95026,-1.10658
11.80000,-1.96706,-1.11601
11.90000,-1.98346,-1.12559
12.00000,-2.00040,-1.13651
12.10000,-2.01680,-1.14665
12.20000,-2.03346,-1.15503
12.30000,-2.05013,-1.16653
12.40000,-2.06666,-1.17767
12.50000,-2.08359,-1.18826
12.60000,-2.10026,-1.19993
12.70000,-2.11706,-1.20844
12.80000,-2.13346,-1.22186
12.90000,-2.15039,-1.23267
13.00000,-2.16666,-1.24192
13.10000,-2.18333,-1.25328
13.20000,-2.20026,-1.26236
13.30000,-2.21679,-1.27394
13.40000,-2.23373,-1.28415
13.50000,-2.25039,-1.29261
13.60000,-2.26706,-1.30302
13.70000,-2.28359,-1.31231
13.80000,-2.30039,-1.32281
13.90000,-2.31693,-1.32961
14.00000,-2.33346,-1.34212
14.10000,-2.35039,-1.35188
14.20000,-2.36693,-1.36303
14.30000,-2.38373,-1.37050
14.40000,-2.40039,-1.37934
14.50000,-2.41693,-1.39053
14.60000,-2.43346,-1.40033
14.70000,-2.45013,-1.41131
14.80000,-2.46679,-1.42022
14.90000,-2.48359,-1.42945
15.00000,-2.50039,-1.43935
15.10000,-2.51679,-1.45011
15.20000,-2.53386,-1.46133
15.30000,-2.55026,-1.47093
15.40000,-2.56679,-1.48127
15.50000,-2.58346,-1.49111
15.60000,-2.59999,-1.50201
15.70000,-2.61679,-1.51161
15.80000,-2.63359,-1.52238
15.90000,-2.65039,-1.53103
16.00000,-2.66666,-1.54032
16.10000,-2.68373,-1.54807
16.20000,-2.70013,-1.55698
16.30000,-2.71666,-1.56613
16.40000,-2.73359,-1.57676
16.50000,-2.75013,-1.58703
16.60000,-2.76706,-1.59734
16.70000,-2.78373,-1.60694
16.80000,-2.80039,-1.61575
16.90000,-2.81679,-1.62520
17.00000,-2.83359,-1.63495
17.10000,-2.85013,-1.64446
17.20000,-2.86679,-1.65361
17.30000,-2.88373,-1.66281
17.40000,-2.90013,-1.67163
17.50000,-2.91706,-1.68072
17.60000,-2.93359,-1.68826
17.70000,-2.95013,-1.69752
17.80000,-2.96679,-1.70640
17.90000,-2.98359,-1.71597
18.00000,-3.00013,-1.72448
18.10000,-3.01693,-1.73404
18.20000,-3.03386,-1.74204
18.30000,-3.05013,-1.74982
18.40000,-3.06719,-1.75755
18.50000,-3.08346,-1.76608
18.60000,-3.10013,-1.77346
18.70000,-3.11679,-1.78123
18.80000,-3.13333,-1.78955
18.90000,-3.15013,-1.79680
19.00000,-3.16693,-1.80532
19.10000,-3.18359,-1.81103
19.20000,-3.20013,-1.81851
19.30000,-3.21706,-1.82672
19.40000,-3.23346,-1.83273
19.50000,-3.24999,-1.84122
19.60000,-3.26679,-1.84768
19.70000,-3.28346,-1.85590
19.80000,-3.30039,-1.86283
19.90000,-3.31706,-1.87023
20.00000,-3.33359,-1.87795
20.10000,-3.35013,-1.88527
20.20000,-3.36706,-1.89329
20.30000,-3.38346,-1.89916
20.40000,-3.39999,-1.90687
20.50000,-3.41706,-1.91291
20.60000,-3.43346,-1.91015
20.70000,-3.45039,-1.91361
20.80000,-3.46692,-1.92108
20.90000,-3.48359,-1.92910
21.00000,-3.50026,-1.93674
21.10000,-3.51692,-1.94501
21.20000,-3.53359,-1.95164
21.30000,-3.55026,-1.96005
21.40000,-3.56706,-1.96690
21.50000,-3.58346,-1.97450
21.60000,-3.60052,-1.98223
21.70000,-3.61692,-1.98894
21.80000,-3.63346,-1.99580
21.90000,-3.65026,-2.00276
22.00000,-3.66666,-2.00888
22.10000,-3.68346,-2.01551
22.20000,-3.70012,-2.02278
22.30000,-3.71692,-2.02914
22.40000,-3.73346,-2.03635
22.50000,-3.75039,-2.04419
22.60000,-3.76666,-2.05092
22.70000,-3.78346,-2.05828
22.80000,-3.80026,-2.06540
22.90000,-3.81679,-2.07166
23.00000,-3.83359,-2.07799
23.10000,-3.85026,-2.08545
23.20000,-3.86706,-2.09198
23.30000,-3.88346,-2.09821
23.40000,-3.90039,-2.10502
23.50000,-3.91679,-2.11118
23.60000,-3.93346,-2.11797
23.70000,-3.95039,-2.12495
23.80000,-3.96679,-2.13140
23.90000,-3.98372,-2.13951
24.00000,-4.00012,-2.14502
24.10000,-4.01692,-2.15092
24.20000,-4.03359,-2.15763
24.30000,-4.05026,-2.16275
24.40000,-4.06679,-2.16658
24.50000,-4.08359,-2.17301
24.60000,-4.10039,-2.17865
24.70000,-4.11679,-2.18448
24.80000,-4.13386,-2.19107
24.90000,-4.15012,-2.19474
25.00000,-4.16679,-2.20095
25.10000,-4.18359,-2.20450
25.20000,-4.19999,-2.21037
25.30000,-4.21679,-2.21620
25.40000,-4.23359,-2.22284
25.50000,-4.25026,-2.22847
25.60000,-4.26666,-2.23212
25.70000,-4.28372,-2.23883
25.80000,-4.29999,-2.23948
25.90000,-4.31666,-2.24659
26.00000,-4.33359,-2.24971
26.10000,-4.35012,-2.25795
26.20000,-4.36706,-2.26247
26.30000,-4.38372,-2.26835
26.40000,-4.40039,-2.27242
26.50000,-4.41679,-2.27846
26.60000,-4.43359,-2.27977
26.70000,-4.45012,-2.28547
26.80000,-4.46679,-2.28668
26.90000,-4.48372,-2.29114
27.00000,-4.50026,-2.29561
27.10000,-4.51719,-2.29985
27.20000,-4.53372,-2.30146
27.30000,-4.55026,-2.30591
27.40000,-4.56692,-2.30755
27.50000,-4.58346,-2.31131
27.60000,-4.60012,-2.31305
27.70000,-4.61692,-2.31726
27.80000,-4.63372,-2.31907
27.90000,-4.64999,-2.32060
28.00000,-4.66706,-2.32199
28.10000,-4.68346,-2.32463
28.20000,-4.70012,-2.32741
28.30000,-4.71679,-2.32836
28.40000,-4.73346,-2.32834
28.50000,-4.74999,-2.33004
28.60000,-4.76692,-2.33299
28.70000,-4.78359,-2.33421
28.80000,-4.80012,-2.33729
28.90000,-4.81706,-2.33699
29.00000,-4.83345,-2.33713
29.10000,-4.84999,-2.34046
29.20000,-4.86679,-2.34348
29.30000,-4.88345,-2.34539
29.40000,-4.90025,-2.34675
29.50000,-4.91679,-2.34856
29.60000,-4.93372,-2.34888
29.70000,-4.95012,-2.35175
29.80000,-4.96705,-2.35176
29.90000,-4.98332,-2.35302
30.00000,-5.00012,-2.35471
30.10000,-5.01705,-2.35481
30.20000,-5.03345,-2.35495
30.30000,-5.05039,-2.35564
30.40000,-5.06692,-2.35733
30.50000,-5.08372,-2.35782
30.60000,-5.10025,-2.35941
30.70000,-5.11692,-2.36074
30.80000,-5.13345,-2.36105
30.90000,-5.15025,-2.36283
31.00000,-5.16692,-2.36309
31.10000,-5.18345,-2.36496
31.20000,-5.20052,-2.36754
31.30000,-5.21692,-2.36726
31.40000,-5.23345,-2.36852
31.50000,-5.24999,-2.36839
31.60000,-5.26679,-2.37066
31.70000,-5.28332,-2.37217
31.80000,-5.30025,-2.37423
31.90000,-5.31692,-2.37545
32.00000,-5.33332,-2.37596
32.10000,-5.35039,-2.37580
32.20000,-5.36679,-2.37432
32.30000,-5.38332,-2.37579
32.40000,-5.40025,-2.37280
32.50000,-5.41679,-2.37452
32.60000,-5.43359,-2.37522
32.70000,-5.45039,-2.37654
32.80000,-5.46705,-2.37781
32.90000,-5.48345,-2.37912
33.00000,-5.50039,-2.37887
33.10000,-5.51679,-2.37900
33.20000,-5.53345,-2.38120
33.30000,-5.55039,-2.38333
33.40000,-5.56679,-2.38237
33.50000,-5.58385,-2.38199
33.60000,-5.60025,-2.37896
33.70000,-5.61705,-2.38026
33.80000,-5.63345,-2.37895
33.90000,-5.65012,-2.38096
34.00000,-5.66679,-2.37701
34.10000,-5.68345,-2.37923
34.20000,-5.70025,-2.37758
34.30000,-5.71679,-2.37963
34.40000,-5.73385,-2.37916
34.50000,-5.75025,-2.38014
34.60000,-5.76679,-2.38002
34.70000,-5.78359,-2.37945
34.80000,-5.80012,-2.38130
34.90000,-5.81665,-2.38142
35.00000,-5.83359,-2.38181
35.10000,-5.85025,-2.38275
35.20000,-5.86679,-2.38109
35.30000,-5.88385,-2.38027
35.40000,-5.90012,-2.37962
35.50000,-5.91665,-2.38031
35.60000,-5.93359,-2.38066
35.70000,-5.95012,-2.37983
35.80000,-5.96692,-2.37949
35.90000,-5.98359,-2.37782
36.00000,-6.00039,-2.37704
36.10000,-6.01692,-2.37567
36.20000,-6.03372,-2.37329
36.30000,-6.05012,-2.36931
36.40000,-6.06679,-2.36867
36.50000,-6.08372,-2.36766
36.60000,-6.10025,-2.36683
36.70000,-6.11719,-2.36561
36.80000,-6.13359,-2.36414
36.90000,-6.15025,-2.36343
37.00000,-6.16692,-2.36357
37.10000,-6.18345,-2.36419
37.20000,-6.19998,-2.36399
37.30000,-6.21692,-2.36553
37.40000,-6.23372,-2.36676
37.50000,-6.25012,-2.36760
37.60000,-6.26718,-2.36982
37.70000,-6.28345,-2.36919
37.80000,-6.30012,-2.37003
37.90000,-6.31678,-2.36955
38.00000,-6.33345,-2.37262
38.10000,-6.35025,-2.37423
38.20000,-6.36692,-2.37663
38.30000,-6.38372,-2.37770
38.40000,-6.40012,-2.37830
38.50000,-6.41692,-2.37963
38.60000,-6.43332,-2.38049
38.70000,-6.44998,-2.38263
38.80000,-6.46692,-2.38473
38.90000,-6.48332,-2.38644
39.00000,-6.50025,-2.39004
39.10000,-6.51705,-2.39270
39.20000,-6.53372,-2.39444
39.30000,-6.55012,-2.39723
39.40000,-6.56692,-2.39999
39.50000,-6.58332,-2.40262
39.60000,-6.60012,-2.40706
39.70000,-6.61705,-2.41235
39.80000,-6.63345,-2.41115
39.90000,-6.65038,-2.41372
40.00000,-6.66705,-2.41541
40.10000,-6.68358,-2.41960
40.20000,-6.70025,-2.42139
40.30000,-6.71692,-2.42301
40.40000,-6.73345,-2.42075
40.50000,-6.75025,-2.42395
40.60000,-6.76705,-2.42635
40.70000,-6.78345,-2.42940
40.80000,-6.80038,-2.43052
40.90000,-6.81678,-2.43182
41.00000,-6.83345,-2.43428
41.10000,-6.85012,-2.43673
41.20000,-6.86665,-2.44010
41.30000,-6.88345,-2.44252
41.40000,-6.90025,-2.44433
41.50000,-6.91705,-2.44643
41.60000,-6.93345,-2.44881
41.70000,-6.95052,-2.45013
41.80000,-6.96665,-2.45214
41.90000,-6.98332,-2.45355
42.00000,-7.00025,-2.45411
42.10000,-7.01665,-2.45655
42.20000,-7.03358,-2.45810
42.30000,-7.05025,-2.45829
42.40000,-7.06705,-2.46261
42.50000,-7.08345,-2.46632
42.60000,-7.10038,-2.46955
42.70000,-7.11678,-2.47038
42.80000,-7.13345,-2.47240
42.90000,-7.15038,-2.47484
43.00000,-7.16678,-2.47816
43.10000,-7.18372,-2.48306
43.20000,-7.20025,-2.48527
43.30000,-7.21692,-2.48547
43.40000,-7.23358,-2.48660
43.50000,-7.25025,-2.48909
43.60000,-7.26678,-2.49060
43.70000,-7.28358,-2.49457
43.80000,-7.30038,-2.49670
43.90000,-7.31678,-2.49955
44.00000,-7.33385,-2.50232
44.10000,-7.35025,-2.50358
44.20000,-7.36678,-2.50480
44.30000,-7.38345,-2.50601
44.40000,-7.40012,-2.50604
44.50000,-7.41678,-2.50664
44.60000,-7.43358,-2.50864
44.70000,-7.45025,-2.50815
44.80000,-7.46678,-2.50982
44.90000,-7.48372,-2.51181
45.00000,-7.49998,-2.51163
45.10000,-7.51678,-2.51388
45.20000,-7.53358,-2.51604
45.30000,-7.54998,-2.51678
45.40000,-7.56691,-2.51845
45.50000,-7.58358,-2.51875
45.60000,-7.60038,-2.51521
45.70000,-7.61691,-2.51512
45.80000,-7.63371,-2.51437
45.90000,-7.65011,-2.50904
46.00000,-7.66678,-2.50939
46.10000,-7.68371,-2.50727
46.20000,-7.70011,-2.50850
46.30000,-7.71705,-2.51100
46.40000,-7.73358,-2.51191
46.50000,-7.75025,-2.51277
46.60000,-7.76691,-2.51350
46.70000,-7.78358,-2.51433
46.80000,-7.80011,-2.51374
46.90000,-7.81691,-2.51710
47.00000,-7.83371,-2.52003
47.10000,-7.85025,-2.52211
47.20000,-7.86718,-2.52459
47.30000,-7.88358,-2.52505
47.40000,-7.90011,-2.52582
47.50000,-7.91691,-2.52755
47.60000,-7.93331,-2.52827
47.70000,-7.95011,-2.52941
47.80000,-7.96678,-2.52871
47.90000,-7.98358,-2.52721
48.00000,-8.00011,-2.52733
48.10000,-8.01705,-2.52761
48.20000,-8.03331,-2.52570
48.30000,-8.04998,-2.52513
48.40000,-8.06678,-2.52344
48.50000,-8.08345,-2.52336
48.60000,-8.10038,-2.52396
48.70000,-8.11691,-2.52227
48.80000,-8.13358,-2.52102
48.90000,-8.15011,-2.52168
49.00000,-8.16691,-2.51978
49.10000,-8.18345,-2.52006
49.20000,-8.20011,-2.52029
49.30000,-8.21705,-2.52263
49.40000,-8.23345,-2.52343
49.50000,-8.25038,-2.52402
49.60000,-8.26705,-2.52456
49.70000,-8.28358,-2.52290
49.80000,-8.30025,-2.52297
49.90000,-8.31691,-2.52486
50.00000,-8.33358,-2.52602
50.10000,-8.35025,-2.52680
50.20000,-8.36705,-2.52636
50.30000,-8.38345,-2.52953
50.40000,-8.40038,-2.53216
50.50000,-8.41678,-2.53404
50.60000,-8.43345,-2.53484
50.70000,-8.45025,-2.53570
50.80000,-8.46665,-2.53881
50.90000,-8.48345,-2.54122
51.00000,-8.50025,-2.54304
51.10000,-8.51705,-2.54287
51.20000,-8.53345,-2.54505
51.30000,-8.55038,-2.54664
51.40000,-8.56665,-2.54466
51.50000,-8.58331,-2.54531
51.60000,-8.60025,-2.54454
51.70000,-8.61678,-2.54482
51.80000,-8.63358,-2.54646
51.90000,-8.65025,-2.54866
52.00000,-8.66705,-2.54893
52.10000,-8.68358,-2.54908
52.20000,-8.70038,-2.54456
52.30000,-8.71678,-2.54597
52.40000,-8.73331,-2.54522
52.50000,-8.75038,-2.54483
52.60000,-8.76678,-2.54539
52.70000,-8.78371,-2.54767
52.80000,-8.80038,-2.54694
52.90000,-8.81691,-2.54574
53.00000,-8.83358,-2.54944
53.10000,-8.85024,-2.54652
53.20000,-8.86678,-2.54538
53.30000,-8.88358,-2.54577
53.40000,-8.90038,-2.54328
53.50000,-8.91678,-2.54358
53.60000,-8.93384,-2.54405
53.70000,-8.95011,-2.54239
53.80000,-8.96678,-2.54680
53.90000,-8.98345,-2.54642
54.00000,-9.00011,-2.55083
54.10000,-9.01678,-2.55345
54.20000,-9.03358,-2.55661
54.30000,-9.05024,-2.55786
54.40000,-9.06665,-2.55946
54.50000,-9.08371,-2.56493
54.60000,-9.09998,-2.56607
54.70000,-9.11678,-2.56911
54.80000,-9.13344,-2.56974
54.90000,-9.14998,-2.57081
55.00000,-9.16691,-2.57148
55.10000,-9.18371,-2.57519
55.20000,-9.20038,-2.57719
55.30000,-9.21678,-2.57726
55.40000,-9.23358,-2.57956
55.50000,-9.25011,-2.58187
55.60000,-9.26678,-2.58323
55.70000,-9.28371,-2.58916
55.80000,-9.30011,-2.59194
55.90000,-9.31704,-2.59359
56.00000,-9.33371,-2.59765
56.10000,-9.35024,-2.59896
56.20000,-9.36678,-2.60290
56.30000,-9.38358,-2.60806
56.40000,-9.40011,-2.61022
56.50000,-9.41691,-2.61082
56.60000,-9.43371,-2.61531
56.70000,-9.45011,-2.61731
56.80000,-9.46718,-2.62356
56.90000,-9.48344,-2.62648
57.00000,-9.50011,-2.62661
57.10000,-9.51691,-2.63366
57.20000,-9.53344,-2.63796
57.30000,-9.55011,-2.64260
57.40000,-9.56691,-2.64699
57.50000,-9.58358,-2.64996
57.60000,-9.60011,-2.65704
57.70000,-9.61704,-2.66214
57.80000,-9.63344,-2.66488
57.90000,-9.64998,-2.67098
58.00000,-9.66678,-2.67302
58.10000,-9.68344,-2.67896
58.20000,-9.70024,-2.67897
58.30000,-9.71691,-2.68163
58.40000,-9.73371,-2.68461
58.50000,-9.75011,-2.69090
58.60000,-9.76704,-2.69422
58.70000,-9.78331,-2.69732
58.80000,-9.80011,-2.70418
58.90000,-9.81718,-2.71070
59.00000,-9.83358,-2.71652
59.10000,-9.85051,-2.72296
59.20000,-9.86691,-2.72719
59.30000,-9.88358,-2.73129
59.40000,-9.90011,-2.73480
59.50000,-9.91691,-2.73760
59.60000,-9.93344,-2.74054
59.70000,-9.95024,-2.74604
59.80000,-9.96691,-2.74970
59.90000,-9.98344,-2.75415
60.00000,-10.00064,-2.75881
60.10000,-10.01691,-2.76012
60.20000,-10.03344,-2.76301
60.30000,-10.05011,-2.76560
60.40000,-10.06664,-2.76978
60.50000,-10.08344,-2.77337
60.60000,-10.10011,-2.77793
60.70000,-10.11691,-2.78062
60.80000,-10.13344,-2.78374
60.90000,-10.15038,-2.78783
61.00000,-10.16664,-2.78914
61.10000,-10.18344,-2.79393
61.20000,-10.20024,-2.79484
61.30000,-10.21678,-2.74279
61.40000,-10.23358,-2.75827
61.50000,-10.25024,-2.76679
61.60000,-10.26717,-2.77311
61.70000,-10.28344,-2.77732
61.80000,-10.30037,-2.78099
61.90000,-10.31678,-2.78268
62.00000,-10.33344,-2.78588
62.10000,-10.35024,-2.78858
62.20000,-10.36691,-2.79149
62.30000,-10.38371,-2.79496
62.40000,-10.40037,-2.79787
62.50000,-10.41704,-2.79940
62.60000,-10.43357,-2.80202
62.70000,-10.45024,-2.80429
62.80000,-10.46677,-2.80555
62.90000,-10.48344,-2.80950
63.00000,-10.50037,-2.81166
63.10000,-10.51691,-2.81331
63.20000,-10.53384,-2.81534
63.30000,-10.55011,-2.81577
63.40000,-10.56677,-2.81806
63.50000,-10.58344,-2.81992
63.60000,-10.59997,-2.82188
63.70000,-10.61664,-2.82432
63.80000,-10.63344,-2.82812
63.90000,-10.65037,-2.83150
64.00000,-10.66677,-2.83455
64.10001,-10.68384,-2.83664
64.20000,-10.70011,-2.83696
64.30000,-10.71677,-2.84008
64.40000,-10.73344,-2.84370
64.50000,-10.74997,-2.84735
64.60001,-10.76691,-2.85175
64.70000,-10.78357,-2.85421
64.80000,-10.80037,-2.85842
64.90000,-10.81664,-2.86269
65.00000,-10.83371,-2.86800
65.10001,-10.85011,-2.86997
65.20000,-10.86677,-2.87319
65.30000,-10.88371,-2.87602
65.40000,-10.90011,-2.87875
65.50000,-10.91704,-2.88277
65.60001,-10.93371,-2.88458
65.70001,-10.95037,-2.88717
65.80000,-10.96691,-2.88847
65.90000,-10.98357,-2.89153
66.00000,-10.99997,-2.89398
66.10001,-11.01677,-2.89754
66.20001,-11.03371,-2.90096
66.30000,-11.05011,-2.90412
66.40000,-11.06717,-2.90682
66.50000,-11.08357,-2.90960
66.60001,-11.10011,-2.91239
66.70001,-11.11664,-2.91164
66.80000,-11.13331,-2.91225
66.90000,-11.14997,-2.91941
67.00000,-11.16691,-2.92374
67.10001,-11.18371,-2.92817
67.20001,-11.20011,-2.93071
67.30000,-11.21704,-2.93358
67.40000,-11.23331,-2.93523
67.50000,-11.25011,-2.94507
67.60001,-11.26677,-2.94756
67.70001,-11.28331,-2.95182
67.80000,-11.30024,-2.95653
67.90000,-11.31704,-2.96117
68.00000,-11.33371,-2.96688
68.10001,-11.35011,-2.97328
68.20001,-11.36691,-2.97302
68.30000,-11.38331,-2.97493
68.40000,-11.40011,-2.98101
68.50000,-11.41691,-2.98329
68.60001,-11.43344,-2.98747
68.70001,-11.45037,-2.98832
68.80000,-11.46704,-2.98986
68.90000,-11.48371,-2.99379
69.00000,-11.50011,-2.99582
69.10001,-11.51691,-2.99778
69.20001,-11.53344,-2.99808
69.30000,-11.55037,-3.00197
69.40000,-11.56704,-3.00204
69.50000,-11.58357,-3.00183
69.60001,-11.60050,-2.98086
69.70001,-11.61677,-2.98673
69.80000,-11.63357,-2.99371
69.90000,-11.65011,-2.99991
70.00000,-11.66664,-3.00664
70.10001,-11.68344,-3.01045
70.20001,-11.70037,-3.01679
70.30000,-11.71704,-3.01952
70.40000,-11.73357,-3.02388
70.50000,-11.75037,-3.02834
70.60001,-11.76677,-3.03041
70.70001,-11.78330,-3.03376
70.80000,-11.80010,-3.03670
70.90000,-11.81690,-3.03942
71.00000,-11.83370,-3.04503
71.10001,-11.85037,-3.04641
71.20001,-11.86690,-3.05024
71.30000,-11.88330,-3.05460
71.40000,-11.90024,-3.06006
71.50000,-11.91677,-3.06215
71.60001,-11.93344,-3.06691
71.70001,-11.95024,-3.06957
71.80000,-11.96677,-3.07260
71.90000,-11.98384,-3.07818
72.00000,-12.00050,-3.08122
72.10001,-12.01704,-3.08365
72.20001,-12.03370,-3.08747
72.30000,-12.05024,-3.09350
72.40000,-12.06690,-3.09653
72.50000,-12.08357,-3.10274
72.60001,-12.10037,-3.10656
72.70001,-12.11677,-3.11371
72.80000,-12.13384,-3.12000
72.90000,-12.15024,-3.12218
73.00000,-12.16677,-3.12766
73.10001,-12.18330,-3.13015
73.20001,-12.20010,-3.13477
73.30000,-12.21677,-3.13885
73.40000,-12.23357,-3.14480
73.50000,-12.25037,-3.14723
73.60001,-12.26677,-3.15094
73.70001,-12.28370,-3.15434
73.80000,-12.30010,-3.15652
73.90000,-12.31664,-3.16120
74.00000,-12.33357,-3.16349
74.10001,-12.35010,-3.16794
74.20001,-12.36704,-3.17123
74.30000,-12.38357,-3.17260
74.40000,-12.40037,-3.17541
74.50000,-12.41677,-3.17883
74.60001,-12.43370,-3.18211
74.70001,-12.44997,-3.18318
74.80000,-12.46677,-3.18559
74.90000,-12.48370,-3.18658
75.00000,-12.50024,-3.18907
75.10001,-12.51717,-3.19301
75.20001,-12.53357,-3.19443
75.30000,-12.55024,-3.19615
75.40000,-12.56677,-3.19818
75.50000,-12.58357,-3.20199
75.60001,-12.59997,-3.20369
75.70001,-12.61664,-3.20706
75.80000,-12.63357,-3.20990
75.90000,-12.65010,-3.21314
76.00000,-12.66717,-3.21616
76.10001,-12.68344,-3.21699
76.20001,-12.70010,-3.21975
76.30000,-12.71677,-3.22161
76.40000,-12.73344,-3.22259
76.50000,-12.75010,-3.22314
76.60001,-12.76677,-3.22561
76.70001,-12.78357,-3.22701
76.80000,-12.80010,-3.23092
76.90000,-12.81704,-3.23328
77.00000,-12.83344,-3.23431
77.10001,-12.84997,-3.23611
77.20001,-12.86690,-3.23672
77.30000,-12.88344,-3.23931
77.40000,-12.90024,-3.24116
77.50000,-12.91704,-3.24259
77.60001,-12.93357,-3.24213
77.70001,-12.95010,-3.24336
77.80000,-12.96704,-3.24322
77.90000,-12.98343,-3.23919
78.00000,-12.99997,-3.23567
78.10001,-13.01704,-3.23418
78.20001,-13.03357,-3.23345
78.30000,-13.05050,-3.23317
78.40000,-13.06704,-3.23022
78.50000,-13.08370,-3.22675
78.60001,-13.10023,-3.22424
78.70001,-13.11690,-3.22014
78.80000,-13.13343,-3.21668
78.90000,-13.15023,-3.21684
79.00000,-13.16703,-3.21408
79.10001,-13.18357,-3.20923
79.20001,-13.20037,-3.20532
79.30000,-13.21677,-3.20248
79.40000,-13.23330,-3.19994
79.50000,-13.25010,-3.19791
79.60001,-13.26663,-3.19724
79.70001,-13.28330,-3.19638
79.80000,-13.30010,-3.19822
79.90000,-13.31703,-3.19867
80.00000,-13.33343,-3.20082
80.10001,-13.35037,-3.20309
80.20001,-13.36677,-3.20531
80.30000,-13.38330,-3.20706
80.40000,-13.40023,-3.21169
80.50001,-13.41677,-3.21489
80.60001,-13.43357,-3.21928
80.70001,-13.45037,-3.22272
80.80000,-13.46703,-3.22565
80.90000,-13.48343,-3.22644
81.00001,-13.50023,-3.22612
81.10001,-13.51677,-3.22590
81.20001,-13.53343,-3.22801
81.30000,-13.55037,-3.22898
81.40000,-13.56690,-3.22957
81.50001,-13.58370,-3.23208
81.60001,-13.60023,-3.23242
81.70001,-13.61690,-3.23238
81.80000,-13.63357,-3.23303
81.90000,-13.65023,-3.23402
82.00001,-13.66690,-3.23474
82.10001,-13.68357,-3.23902
82.20001,-13.70037,-3.24166
82.30000,-13.71677,-3.24511
82.40000,-13.73370,-3.24794
82.50001,-13.75010,-3.24941
82.60001,-13.76677,-3.24977
82.70001,-13.78343,-3.25132
82.80000,-13.79997,-3.25249
82.90000,-13.81677,-3.25532
83.00001,-13.83357,-3.25827
83.10001,-13.85037,-3.25942
83.20001,-13.86677,-3.26208
83.30000,-13.88370,-3.26362
83.40000,-13.90010,-3.26435
83.50001,-13.91663,-3.26558
83.60001,-13.93343,-3.26447
83.70001,-13.94997,-3.26359
83.80000,-13.96703,-3.26269
83.90000,-13.98383,-3.26369
84.00001,-14.00037,-3.26292
84.10001,-14.01677,-3.26351
84.20001,-14.03370,-3.26473
84.30000,-14.05010,-3.26429
84.40000,-14.06677,-3.26782
84.50001,-14.08383,-3.26926
84.60001,-14.10010,-3.26985
84.70001,-14.11717,-3.27325
84.80000,-14.13370,-3.27308
84.90000,-14.15023,-3.27618
85.00001,-14.16677,-3.27885
85.10001,-14.18357,-3.28127
85.20001,-14.20010,-3.28218
85.30000,-14.21690,-3.28737
85.40000,-14.23383,-3.28978
85.50001,-14.25023,-3.29281
85.60001,-14.26703,-3.29547
85.70001,-14.28343,-3.29870
85.80000,-14.30010,-3.30246
85.90000,-14.31676,-3.30695
86.00001,-14.33343,-3.31203
86.10001,-14.34997,-3.31589
86.20001,-14.36676,-3.32172
86.30000,-14.38356,-3.32586
86.40000,-14.40010,-3.33190
86.50001,-14.41703,-3.33644
86.60001,-14.43330,-3.33958
86.70001,-14.44996,-3.34394
86.80000,-14.46676,-3.34792
86.90000,-14.48343,-3.35543
87.00001,-14.50023,-3.36321
87.10001,-14.51703,-3.36947
87.20001,-14.53370,-3.37525
87.30000,-14.55010,-3.38286
87.40000,-14.56703,-3.39040
87.50001,-14.58343,-3.39727
87.60001,-14.59996,-3.40462
87.70001,-14.61690,-3.41338
87.80000,-14.63356,-3.42307
87.90000,-14.65050,-3.43315
88.00001,-14.66703,-3.43875
88.10001,-14.68370,-3.44813
88.20001,-14.70023,-3.45680
88.30000,-14.71690,-3.46504
88.40000,-14.73343,-3.47215
88.50001,-14.75010,-3.48258
88.60001,-14.76703,-3.49000
88.70001,-14.78343,-3.49645
88.80000,-14.80050,-3.50437
88.90000,-14.81676,-3.51025
89.00001,-14.83343,-3.51803
89.10001,-14.85010,-3.52439
89.20001,-14.86676,-3.53239
89.30000,-14.88343,-3.54033
89.40000,-14.90023,-3.54988
89.50001,-14.91703,-3.55518
89.60001,-14.93330,-3.56258
89.70001,-14.95036,-3.56970
89.80000,-14.96676,-3.57404
89.90000,-14.98343,-3.58294
90.00001,-15.00023,-3.58925
90.10001,-15.01676,-3.59727
90.20001,-15.03370,-3.60593
90.30000,-15.05023,-3.61024
90.34200,-15.05716,-3.61214