File: GFBaking/data/3TspPectin/3TspPectin_1.is_comp_RawData/Specimen_RawData_1.csv
Time,Extension,Load
(sec),(mm),(N)
0.00000,0.00000,0.00070
0.10000,-0.00853,-0.00270
0.20000,-0.02907,-0.00667
0.30000,-0.04773,-0.00733
0.40000,-0.06547,-0.01309
0.50000,-0.08267,-0.01302
0.60000,-0.09960,-0.01534
0.70000,-0.11627,-0.01801
0.80000,-0.13333,-0.02612
0.90000,-0.15013,-0.02458
1.00000,-0.16667,-0.02074
1.10000,-0.18347,-0.02750
1.20000,-0.20000,-0.02806
1.30000,-0.21653,-0.02909
1.40000,-0.23333,-0.03191
1.50000,-0.24987,-0.03278
1.60000,-0.26653,-0.03668
1.70000,-0.28333,-0.04150
1.80000,-0.30000,-0.04187
1.90000,-0.31667,-0.05222
2.00000,-0.33360,-0.05478
2.10000,-0.34987,-0.05825
2.20000,-0.36640,-0.05930
2.30000,-0.38320,-0.06543
2.40000,-0.39973,-0.07278
2.50000,-0.41667,-0.07420
2.60000,-0.43347,-0.07944
2.70000,-0.45013,-0.08841
2.80000,-0.46653,-0.08757
2.90000,-0.48347,-0.09387
3.00000,-0.50000,-0.10212
3.10000,-0.51653,-0.11086
3.20000,-0.53360,-0.11301
3.30000,-0.55000,-0.11862
3.40000,-0.56693,-0.12569
3.50000,-0.58333,-0.13214
3.60000,-0.60013,-0.13715
3.70000,-0.61680,-0.14328
3.80000,-0.63333,-0.15017
3.90000,-0.65000,-0.14667
4.00000,-0.66667,-0.16331
4.10000,-0.68346,-0.17693
4.20000,-0.70000,-0.17415
4.30000,-0.71693,-0.18939
4.40000,-0.73333,-0.19188
4.50000,-0.74986,-0.19741
4.60000,-0.76666,-0.20569
4.70000,-0.78320,-0.21731
4.80000,-0.79986,-0.22159
4.90000,-0.81680,-0.23071
5.00000,-0.83360,-0.23755
5.10000,-0.84986,-0.24923
5.20000,-0.86680,-0.25588
5.30000,-0.88320,-0.26666
5.40000,-0.89986,-0.27929
5.50000,-0.91666,-0.29124
5.60000,-0.93320,-0.30203
5.70000,-0.95013,-0.31377
5.80000,-0.96666,-0.32898
5.90000,-0.98360,-0.33960
6.00000,-0.99986,-0.35230
6.10000,-1.01680,-0.35934
6.20000,-1.03320,-0.36957
6.30000,-1.04986,-0.37848
6.40000,-1.06680,-0.38857
6.50000,-1.08333,-0.39615
6.60000,-1.10026,-0.41004
6.70000,-1.11666,-0.41969
6.80000,-1.13333,-0.43051
6.90000,-1.15000,-0.44092
7.00000,-1.16666,-0.45142
7.10000,-1.18333,-0.45949
7.20000,-1.20000,-0.47052
7.30000,-1.21693,-0.48516
7.40000,-1.23333,-0.49585
7.50000,-1.25026,-0.50737
7.60000,-1.26666,-0.51903
7.70000,-1.28320,-0.53299
7.80000,-1.30000,-0.54363
7.90000,-1.31653,-0.55733
8.00000,-1.33320,-0.56825
8.10000,-1.35000,-0.58144
8.20000,-1.36666,-0.59089
8.30000,-1.38320,-0.60377
8.40000,-1.40013,-0.61426
8.50000,-1.41653,-0.62650
8.60000,-1.43320,-0.63742
8.70000,-1.45000,-0.65112
8.80000,-1.46666,-0.66562
8.90000,-1.48360,-0.67892
9.00000,-1.50026,-0.69326
9.10000,-1.51680,-0.70686
9.20000,-1.53320,-0.72161
9.30000,-1.55026,-0.73615
9.40000,-1.56666,-0.75066
9.50000,-1.58333,-0.76488
9.60000,-1.60026,-0.77923
9.70000,-1.61653,-0.79292
9.80000,-1.63333,-0.80751
9.90000,-1.65000,-0.82528
10.00000,-1.66680,-0.84068
10.10000,-1.68333,-0.86051
10.20000,-1.70000,-0.87685
10.30000,-1.71653,-0.89336
10.40000,-1.73333,-0.91123
10.50000,-1.75026,-0.93102
10.60000,-1.76666,-0.94737
10.70000,-1.78346,-0.96437
10.80000,-1.79986,-0.98191
10.90000,-1.81666,-1.00124
11.00000,-1.83333,-1.01515
11.10000,-1.84986,-1.03267
11.20000,-1.86666,-1.04971
11.30000,-1.88346,-1.06818
11.40000,-1.90026,-1.08461
11.50000,-1.91653,-1.10264
11.60000,-1.93360,-1.11894
11.70000,-1.94986,-1.13507
11.80000,-1.96640,-1.15063
11.90000,-1.98333,-1.16873
12.00000,-2.00000,-1.18174
12.10000,-2.01680,-1.20167
12.20000,-2.03346,-1.21699
12.30000,-2.05013,-1.23649
12.40000,-2.06666,-1.25634
12.50000,-2.08346,-1.27384
12.60000,-2.09999,-1.29359
12.70000,-2.11653,-1.31092
12.80000,-2.13346,-1.33613
12.90000,-2.14999,-1.34969
13.00000,-2.16693,-1.36981
13.10000,-2.18346,-1.38585
13.20000,-2.20013,-1.40121
13.30000,-2.21666,-1.41938
13.40000,-2.23333,-1.43382
13.50000,-2.24999,-1.44984
13.60000,-2.26666,-1.46870
13.70000,-2.28359,-1.48741
13.80000,-2.29999,-1.50720
13.90000,-2.31693,-1.52879
14.00000,-2.33333,-1.51534
14.10000,-2.34999,-1.54485
14.20000,-2.36666,-1.56035
14.30000,-2.38319,-1.57961
14.40000,-2.39999,-1.59205
14.50000,-2.41679,-1.60882
14.60000,-2.43359,-1.62270
14.70000,-2.44986,-1.63087
14.80000,-2.46666,-1.64129
14.90000,-2.48319,-1.65388
15.00000,-2.49986,-1.67529
15.10000,-2.51679,-1.69455
15.20000,-2.53333,-1.71630
15.30000,-2.55013,-1.73964
15.40000,-2.56679,-1.75841
15.50000,-2.58359,-1.77880
15.60000,-2.59999,-1.80369
15.70000,-2.61679,-1.82622
15.80000,-2.63319,-1.84680
15.90000,-2.64986,-1.86183
16.00000,-2.66693,-1.88103
16.10000,-2.68333,-1.89802
16.20000,-2.70013,-1.91663
16.30000,-2.71679,-1.93297
16.40000,-2.73333,-1.95037
16.50000,-2.74999,-1.96782
16.60000,-2.76666,-1.98419
16.70000,-2.78319,-1.99959
16.80000,-2.80013,-2.01799
16.90000,-2.81679,-2.02661
17.00000,-2.83333,-2.04077
17.10000,-2.85026,-2.04939
17.20000,-2.86666,-2.05870
17.30000,-2.88319,-2.05647
17.40000,-2.89999,-2.07121
17.50000,-2.91653,-2.09080
17.60000,-2.93319,-2.11154
17.70000,-2.94999,-2.12245
17.80000,-2.96679,-2.13401
17.90000,-2.98333,-2.14543
18.00000,-3.00026,-2.14697
18.10000,-3.01653,-2.14968
18.20000,-3.03306,-2.16826
18.30000,-3.04999,-2.18318
18.40000,-3.06653,-2.18645
18.50000,-3.08346,-2.19188
18.60000,-3.10013,-2.21938
18.70000,-3.11679,-2.24388
18.80000,-3.13319,-2.26391
18.90000,-3.15013,-2.28541
19.00000,-3.16666,-2.30569
19.10000,-3.18319,-2.31896
19.20000,-3.20026,-2.34194
19.30000,-3.21666,-2.36331
19.40000,-3.23359,-2.37859
19.50000,-3.25013,-2.39937
19.60000,-3.26679,-2.41120
19.70000,-3.28333,-2.42443
19.80000,-3.30013,-2.44420
19.90000,-3.31666,-2.46253
20.00000,-3.33333,-2.48013
20.10000,-3.35026,-2.49709
20.20000,-3.36666,-2.51178
20.30000,-3.38359,-2.53510
20.40000,-3.39999,-2.55293
20.50000,-3.41666,-2.56918
20.60000,-3.43332,-2.58652
20.70000,-3.44986,-2.60029
20.80000,-3.46652,-2.62114
20.90000,-3.48332,-2.63919
21.00000,-3.50012,-2.65763
21.10000,-3.51652,-2.67438
21.20000,-3.53359,-2.68865
21.30000,-3.54986,-2.70304
21.40000,-3.56652,-2.71879
21.50000,-3.58332,-2.73672
21.60000,-3.59999,-2.75407
21.70000,-3.61679,-2.77276
21.80000,-3.63346,-2.78586
21.90000,-3.65012,-2.79985
22.00000,-3.66666,-2.80971
22.10000,-3.68359,-2.83208
22.20000,-3.69986,-2.84516
22.30000,-3.71652,-2.86125
22.40000,-3.73359,-2.87601
22.50000,-3.74999,-2.89270
22.60000,-3.76692,-2.91089
22.70000,-3.78332,-2.92649
22.80000,-3.79999,-2.94269
22.90000,-3.81666,-2.96412
23.00000,-3.83332,-2.97563
23.10000,-3.84986,-2.99647
23.20000,-3.86666,-3.01042
23.30000,-3.88359,-3.01943
23.40000,-3.89999,-3.04319
23.50000,-3.91692,-3.06144
23.60000,-3.93332,-3.07139
23.70000,-3.94986,-3.08865
23.80000,-3.96666,-3.10178
23.90000,-3.98319,-3.12146
24.00000,-3.99999,-3.13220
24.10000,-4.01679,-3.13883
24.20000,-4.03346,-3.15901
24.30000,-4.04986,-3.17519
24.40000,-4.06679,-3.17776
24.50000,-4.08319,-3.19289
24.60000,-4.09986,-3.20092
24.70000,-4.11666,-3.22209
24.80000,-4.13332,-3.23485
24.90000,-4.15012,-3.25298
25.00000,-4.16679,-3.26475
25.10000,-4.18346,-3.27955
25.20000,-4.19999,-3.29081
25.30000,-4.21679,-3.30394
25.40000,-4.23332,-3.31279
25.50000,-4.24986,-3.32931
25.60000,-4.26692,-3.34011
25.70000,-4.28332,-3.35085
25.80000,-4.30026,-3.36399
25.90000,-4.31679,-3.37176
26.00000,-4.33346,-3.38216
26.10000,-4.34999,-3.40040
26.20000,-4.36666,-3.40376
26.30000,-4.38319,-3.41523
26.40000,-4.39999,-3.43121
26.50000,-4.41692,-3.44884
26.60000,-4.43319,-3.46320
26.70000,-4.45012,-3.47015
26.80000,-4.46652,-3.47839
26.90000,-4.48332,-3.49050
27.00000,-4.49999,-3.50049
27.10000,-4.51652,-3.50282
27.20000,-4.53319,-3.52186
27.30000,-4.55012,-3.53276
27.40000,-4.56679,-3.54152
27.50000,-4.58319,-3.55387
27.60000,-4.60026,-3.57150
27.70000,-4.61652,-3.57836
27.80000,-4.63306,-3.59205
27.90000,-4.64999,-3.60594
28.00000,-4.66666,-3.61687
28.10000,-4.68332,-3.62198
28.20000,-4.70012,-3.63229
28.30000,-4.71692,-3.64119
28.40000,-4.73332,-3.64665
28.50000,-4.75012,-3.65280
28.60000,-4.76666,-3.66381
28.70000,-4.78332,-3.67436
28.80000,-4.80025,-3.68026
28.90000,-4.81666,-3.68944
29.00000,-4.83359,-3.69956
29.10000,-4.84999,-3.70850
29.20000,-4.86679,-3.71312
29.30000,-4.88332,-3.72427
29.40000,-4.89999,-3.73148
29.50000,-4.91652,-3.73805
29.60000,-4.93332,-3.74298
29.70000,-4.95012,-3.75445
29.80000,-4.96665,-3.76374
29.90000,-4.98359,-3.77381
30.00000,-4.99999,-3.77878
30.10000,-5.01652,-3.78969
30.20000,-5.03332,-3.79514
30.30000,-5.04985,-3.80676
30.40000,-5.06652,-3.81504
30.50000,-5.08345,-3.82541
30.60000,-5.10012,-3.82958
30.70000,-5.11652,-3.83627
30.80000,-5.13359,-3.84111
30.90000,-5.14985,-3.84688
31.00000,-5.16652,-3.85161
31.10000,-5.18332,-3.85821
31.20000,-5.19985,-3.86623
31.30000,-5.21679,-3.87889
31.40000,-5.23345,-3.88209
31.50000,-5.25025,-3.88573
31.60000,-5.26652,-3.89314
31.70000,-5.28345,-3.90163
31.80000,-5.29999,-3.90514
31.90000,-5.31652,-3.91087
32.00000,-5.33345,-3.91510
32.10000,-5.34999,-3.92598
32.20000,-5.36692,-3.92762
32.30000,-5.38345,-3.93327
32.40000,-5.40012,-3.93842
32.50000,-5.41665,-3.94284
32.60000,-5.43332,-3.94807
32.70000,-5.44999,-3.95033
32.80000,-5.46665,-3.95633
32.90000,-5.48345,-3.96177
33.00000,-5.49985,-3.96421
33.10000,-5.51692,-3.96985
33.20000,-5.53319,-3.97162
33.30000,-5.54999,-3.97498
33.40000,-5.56665,-3.97788
33.50000,-5.58319,-3.98821
33.60000,-5.59985,-3.99139
33.70000,-5.61679,-3.99368
33.80000,-5.63345,-3.99885
33.90000,-5.64999,-4.00256
34.00000,-5.66692,-4.00505
34.10000,-5.68319,-4.00910
34.20000,-5.69985,-4.01032
34.30000,-5.71665,-4.01491
34.40000,-5.73332,-4.02191
34.50000,-5.75012,-4.02321
34.60000,-5.76665,-4.02282
34.70000,-5.78345,-4.02536
34.80000,-5.79999,-4.02884
34.90000,-5.81692,-4.03027
35.00000,-5.83332,-4.02947
35.10000,-5.84999,-4.03404
35.20000,-5.86679,-4.03732
35.30000,-5.88345,-4.03693
35.40000,-5.90025,-4.04177
35.50000,-5.91679,-4.04307
35.60000,-5.93345,-4.04453
35.70000,-5.95012,-4.04471
35.80000,-5.96665,-4.04991
35.90000,-5.98319,-4.04953
36.00000,-5.99999,-4.05574
36.10000,-6.01692,-4.05910
36.20000,-6.03332,-4.06196
36.30000,-6.05025,-4.06488
36.40000,-6.06665,-4.06661
36.50000,-6.08332,-4.07196
36.60000,-6.09998,-4.07304
36.70000,-6.11652,-4.07210
36.80000,-6.13332,-4.07401
36.90000,-6.15012,-4.07783
37.00000,-6.16679,-4.07625
37.10000,-6.18319,-4.07836
37.20000,-6.20025,-4.07790
37.30000,-6.21652,-4.06911
37.40000,-6.23318,-4.07180
37.50000,-6.24998,-4.08046
37.60000,-6.26652,-4.08278
37.70000,-6.28345,-4.08335
37.80000,-6.30025,-4.08186
37.90000,-6.31678,-4.08486
38.00000,-6.33318,-4.09456
38.10000,-6.35012,-4.09898
38.20000,-6.36652,-4.09769
38.30000,-6.38318,-4.10377
38.40000,-6.40025,-4.10284
38.50000,-6.41665,-4.10606
38.60000,-6.43358,-4.11507
38.70000,-6.45012,-4.12469
38.80000,-6.46678,-4.12090
38.90000,-6.48332,-4.12539
39.00000,-6.50012,-4.12926
39.10000,-6.51665,-4.12714
39.20000,-6.53332,-4.12962
39.30000,-6.55025,-4.12994
39.40000,-6.56665,-4.12408
39.50000,-6.58358,-4.11157
39.60000,-6.59985,-4.11920
39.70000,-6.61652,-4.12245
39.80000,-6.63332,-4.12341
39.90000,-6.64985,-4.12167
40.00000,-6.66652,-4.12260
40.10000,-6.68332,-4.12435
40.20000,-6.70012,-4.12996
40.30000,-6.71652,-4.13133
40.40000,-6.73358,-4.13728
40.50000,-6.74985,-4.13403
40.60000,-6.76638,-4.13590
40.70000,-6.78332,-4.14029
40.80000,-6.79998,-4.14476
40.90000,-6.81678,-4.14602
41.00000,-6.83345,-4.14777
41.10000,-6.85012,-4.15081
41.20000,-6.86652,-4.15323
41.30000,-6.88345,-4.15593
41.40000,-6.89998,-4.15764
41.50000,-6.91652,-4.16228
41.60000,-6.93358,-4.16329
41.70000,-6.94998,-4.16422
41.80000,-6.96692,-4.16859
41.90000,-6.98332,-4.17057
42.00000,-7.00012,-4.17240
42.10000,-7.01665,-4.17478
42.20000,-7.03332,-4.17898
42.30000,-7.04998,-4.17925
42.40000,-7.06678,-4.18317
42.50000,-7.08358,-4.18344
42.60000,-7.09985,-4.18701
42.70000,-7.11692,-4.19051
42.80000,-7.13345,-4.19306
42.90000,-7.14998,-4.19408
43.00000,-7.16665,-4.19675
43.10000,-7.18318,-4.19687
43.20000,-7.19998,-4.20070
43.30000,-7.21678,-4.20422
43.40000,-7.23345,-4.20625
43.50000,-7.24998,-4.20781
43.60000,-7.26692,-4.20870
43.70000,-7.28332,-4.21313
43.80000,-7.29985,-4.21416
43.90000,-7.31665,-4.21698
44.00000,-7.33305,-4.21753
44.10000,-7.34998,-4.22239
44.20000,-7.36665,-4.22370
44.30000,-7.38345,-4.22610
44.40000,-7.39998,-4.22918
44.50000,-7.41678,-4.23179
44.60000,-7.43318,-4.23123
44.70000,-7.44985,-4.23363
44.80000,-7.46692,-4.23436
44.90000,-7.48332,-4.23469
45.00000,-7.50025,-4.23530
45.10000,-7.51678,-4.23772
45.20000,-7.53332,-4.23909
45.30000,-7.54998,-4.24046
45.40000,-7.56665,-4.24243
45.50000,-7.58332,-4.24374
45.60000,-7.60011,-4.24717
45.70000,-7.61691,-4.24705
45.80000,-7.63331,-4.24860
45.90000,-7.65025,-4.25020
46.00000,-7.66665,-4.24904
46.10000,-7.68318,-4.24798
46.20000,-7.69998,-4.24963
46.30000,-7.71651,-4.24896
46.40000,-7.73331,-4.25086
46.50000,-7.74998,-4.25201
46.60000,-7.76678,-4.25120
46.70000,-7.78331,-4.25080
46.80000,-7.80025,-4.24907
46.90000,-7.81651,-4.24329
47.00000,-7.83318,-4.23980
47.10000,-7.85011,-4.23766
47.20000,-7.86651,-4.23425
47.30000,-7.88345,-4.23524
47.40000,-7.90011,-4.23255
47.50000,-7.91678,-4.22594
47.60000,-7.93331,-4.22489
47.70000,-7.95011,-4.22167
47.80000,-7.96665,-4.21590
47.90000,-7.98331,-4.21541
48.00000,-8.00025,-4.20841
48.10000,-8.01665,-4.20570
48.20000,-8.03358,-4.19975
48.30000,-8.05011,-4.19753
48.40000,-8.06678,-4.19224
48.50000,-8.08345,-4.19245
48.60000,-8.09998,-4.19009
48.70000,-8.11665,-4.19265
48.80000,-8.13331,-4.19010
48.90000,-8.15025,-4.19051
49.00000,-8.16665,-4.18846
49.10000,-8.18371,-4.18933
49.20000,-8.19998,-4.18663
49.30000,-8.21651,-4.19098
49.40000,-8.23331,-4.18600
49.50000,-8.24985,-4.18973
49.60000,-8.26665,-4.18980
49.70000,-8.28331,-4.19069
49.80000,-8.30025,-4.18911
49.90000,-8.31665,-4.19297
50.00000,-8.33358,-4.19481
50.10000,-8.34985,-4.19281
50.20000,-8.36638,-4.19359
50.30000,-8.38345,-4.19810
50.40000,-8.39998,-4.19902
50.50000,-8.41678,-4.19787
50.60000,-8.43331,-4.20167
50.70000,-8.45011,-4.20123
50.80000,-8.46665,-4.20450
50.90000,-8.48345,-4.20453
51.00000,-8.49985,-4.20729
51.10000,-8.51651,-4.21008
51.20000,-8.53345,-4.21039
51.30000,-8.54998,-4.21368
51.40000,-8.56691,-4.21596
51.50000,-8.58345,-4.21802
51.60000,-8.60011,-4.22299
51.70000,-8.61665,-4.22705
51.80000,-8.63345,-4.23038
51.90000,-8.64998,-4.22872
52.00000,-8.66665,-4.23180
52.10000,-8.68345,-4.23251
52.20000,-8.69998,-4.23588
52.30000,-8.71691,-4.23477
52.40000,-8.73331,-4.23679
52.50000,-8.74985,-4.23812
52.60000,-8.76665,-4.23908
52.70000,-8.78318,-4.24193
52.80000,-8.79998,-4.24732
52.90000,-8.81678,-4.24774
53.00000,-8.83345,-4.25301
53.10000,-8.84985,-4.25092
53.20000,-8.86691,-4.25170
53.30000,-8.88318,-4.25388
53.40000,-8.89985,-4.25880
53.50000,-8.91665,-4.25927
53.60000,-8.93318,-4.26005
53.70000,-8.95011,-4.26423
53.80000,-8.96678,-4.27440
53.90000,-8.98358,-4.27613
54.00000,-8.99998,-4.28317
54.10000,-9.01678,-4.27941
54.20000,-9.03318,-4.27958
54.30000,-9.04984,-4.28232
54.40000,-9.06691,-4.28744
54.50000,-9.08331,-4.28687
54.60000,-9.10024,-4.29297
54.70000,-9.11691,-4.29112
54.80000,-9.13344,-4.29779
54.90000,-9.14998,-4.30311
55.00000,-9.16664,-4.30891
55.10000,-9.18331,-4.30388
55.20000,-9.19998,-4.30626
55.30000,-9.21678,-4.30676
55.40000,-9.23331,-4.30821
55.50000,-9.25038,-4.30803
55.60000,-9.26664,-4.31104
55.70000,-9.28331,-4.30631
55.80000,-9.30011,-4.30798
55.90000,-9.31651,-4.31166
56.00000,-9.33331,-4.31555
56.10000,-9.34998,-4.31243
56.20000,-9.36678,-4.31629
56.30000,-9.38318,-4.31810
56.40000,-9.40024,-4.31985
56.50000,-9.41651,-4.31982
56.60000,-9.43318,-4.32700
56.70000,-9.44998,-4.32560
56.80000,-9.46651,-4.32877
56.90000,-9.48344,-4.32850
57.00000,-9.49998,-4.33235
57.10000,-9.51678,-4.33422
57.20000,-9.53318,-4.33755
57.30000,-9.55011,-4.34234
57.40000,-9.56651,-4.34245
57.50000,-9.58318,-4.34703
57.60000,-9.60024,-4.35162
57.70000,-9.61678,-4.35766
57.80000,-9.63358,-4.35740
57.90000,-9.65011,-4.36352
58.00000,-9.66664,-4.36408
58.10000,-9.68318,-4.36909
58.20000,-9.69998,-4.37168
58.30000,-9.71664,-4.37512
58.40000,-9.73331,-4.37755
58.50000,-9.75011,-4.38136
58.60000,-9.76651,-4.38215
58.70000,-9.78371,-4.38701
58.80000,-9.79998,-4.38828
58.90000,-9.81664,-4.39142
59.00000,-9.83331,-4.39030
59.10000,-9.84984,-4.39503
59.20000,-9.86651,-4.39454
59.30000,-9.88331,-4.39851
59.40000,-9.90011,-4.39875
59.50000,-9.91664,-4.40189
59.60000,-9.93358,-4.40522
59.70000,-9.94984,-4.40665
59.80000,-9.96664,-4.41228
59.90000,-9.98331,-4.41490
60.00000,-9.99998,-4.42033
60.10000,-10.01678,-4.42769
60.20000,-10.03331,-4.43315
60.30000,-10.05024,-4.43855
60.40000,-10.06664,-4.44722
60.50000,-10.08358,-4.45188
60.60000,-10.09984,-4.45876
60.70000,-10.11651,-4.46618
60.80000,-10.13344,-4.47315
60.90000,-10.14998,-4.47966
61.00000,-10.16691,-4.48803
61.10000,-10.18344,-4.49312
61.20000,-10.20024,-4.50167
61.30000,-10.21678,-4.50776
61.40000,-10.23344,-4.51862
61.50000,-10.24998,-4.51845
61.60000,-10.26664,-4.53072
61.70000,-10.28344,-4.53793
61.80000,-10.29998,-4.54267
61.90000,-10.31691,-4.55017
62.00000,-10.33331,-4.55805
62.10000,-10.34984,-4.56914
62.20000,-10.36664,-4.57752
62.30000,-10.38304,-4.58067
62.40000,-10.39984,-4.58933
62.50000,-10.41664,-4.59648
62.60000,-10.43344,-4.60451
62.70000,-10.44997,-4.62314
62.80000,-10.46691,-4.63448
62.90000,-10.48331,-4.63034
63.00000,-10.49984,-4.63943
63.10000,-10.51664,-4.64353
63.20000,-10.53331,-4.65724
63.30000,-10.55011,-4.66780
63.40000,-10.56677,-4.67021
63.50000,-10.58344,-4.67537
63.60000,-10.59997,-4.68560
63.70000,-10.61677,-4.69252
63.80000,-10.63317,-4.70277
63.90000,-10.64997,-4.71368
64.00000,-10.66677,-4.72185
64.10001,-10.68331,-4.73486
64.20000,-10.70024,-4.74396
64.30000,-10.71677,-4.74793
64.40000,-10.73344,-4.75420
64.50000,-10.74997,-4.76260
64.60001,-10.76677,-4.77203
64.70000,-10.78331,-4.77921
64.80000,-10.79997,-4.78680
64.90000,-10.81691,-4.79390
65.00000,-10.83331,-4.79931
65.10001,-10.85024,-4.80501
65.20000,-10.86664,-4.80759
65.30000,-10.88331,-4.81693
65.40000,-10.89997,-4.82501
65.50000,-10.91651,-4.83024
65.60001,-10.93331,-4.83824
65.70001,-10.94997,-4.84433
65.80000,-10.96691,-4.85085
65.90000,-10.98317,-4.85847
66.00000,-11.00011,-4.86495
66.10001,-11.01651,-4.87330
66.20001,-11.03317,-4.87931
66.30000,-11.04997,-4.88252
66.40000,-11.06651,-4.89335
66.50000,-11.08344,-4.89774
66.60001,-11.09997,-4.90749
66.70001,-11.11691,-4.91544
66.80000,-11.13317,-4.91869
66.90000,-11.15011,-4.92830
67.00000,-11.16651,-4.93321
67.10001,-11.18317,-4.94022
67.20001,-11.19997,-4.94946
67.30000,-11.21664,-4.95387
67.40000,-11.23357,-4.95826
67.50000,-11.25011,-4.96321
67.60001,-11.26677,-4.96835
67.70001,-11.28331,-4.97275
67.80000,-11.29997,-4.97859
67.90000,-11.31664,-4.98358
68.00000,-11.33331,-4.99013
68.10001,-11.35011,-4.99493
68.20001,-11.36677,-4.99928
68.30000,-11.38371,-5.00668
68.40000,-11.39997,-5.01199
68.50000,-11.41664,-5.01502
68.60001,-11.43331,-5.02113
68.70001,-11.44984,-5.02607
68.80000,-11.46664,-5.03163
68.90000,-11.48344,-5.03599
69.00000,-11.50011,-5.04063
69.10001,-11.51664,-5.04420
69.20001,-11.53357,-5.04924
69.30000,-11.54997,-5.05316
69.40000,-11.56650,-5.05983
69.50000,-11.58330,-5.06457
69.60001,-11.59997,-5.07085
69.70001,-11.61677,-5.07721
69.80000,-11.63344,-5.08185
69.90000,-11.65011,-5.08791
70.00000,-11.66664,-5.09450
70.10001,-11.68344,-5.09766
70.20001,-11.69984,-5.10136
70.30000,-11.71650,-5.10984
70.40000,-11.73344,-5.11570
70.50000,-11.74984,-5.12183
70.60001,-11.76690,-5.13111
70.70001,-11.78357,-5.13644
70.80000,-11.80024,-5.14194
70.90000,-11.81677,-5.14820
71.00000,-11.83344,-5.15245
71.10001,-11.84997,-5.15738
71.20001,-11.86677,-5.16612
71.30000,-11.88344,-5.17027
71.40000,-11.89997,-5.17851
71.50000,-11.91690,-5.18546
71.60001,-11.93317,-5.18981
71.70001,-11.94970,-5.19555
71.80000,-11.96650,-5.20260
71.90000,-11.98330,-5.20853
72.00000,-11.99997,-5.21569
72.10001,-12.01677,-5.21954
72.20001,-12.03357,-5.22519
72.30000,-12.04984,-5.23028
72.40000,-12.06677,-5.23490
72.50000,-12.08317,-5.23757
72.60001,-12.09984,-5.24219
72.70001,-12.11664,-5.24247
72.80000,-12.13317,-5.25003
72.90000,-12.15010,-5.25497
73.00000,-12.16677,-5.26093
73.10001,-12.18357,-5.26348
73.20001,-12.19997,-5.26647
73.30000,-12.21677,-5.27157
73.40000,-12.23317,-5.27195
73.50000,-12.24984,-5.27942
73.60001,-12.26677,-5.28309
73.70001,-12.28344,-5.28520
73.80000,-12.30024,-5.28947
73.90000,-12.31677,-5.29903
74.00000,-12.33344,-5.29957
74.10001,-12.34997,-5.30387
74.20001,-12.36664,-5.31052
74.30000,-12.38317,-5.31523
74.40000,-12.39984,-5.31981
74.50000,-12.41677,-5.32686
74.60001,-12.43330,-5.33007
74.70001,-12.45037,-5.33792
74.80000,-12.46677,-5.34304
74.90000,-12.48330,-5.35006
75.00000,-12.49997,-5.35271
75.10001,-12.51650,-5.35577
75.20001,-12.53317,-5.35748
75.30000,-12.54997,-5.36626
75.40000,-12.56677,-5.37423
75.50000,-12.58317,-5.37782
75.60001,-12.60024,-5.38542
75.70001,-12.61650,-5.38951
75.80000,-12.63317,-5.39892
75.90000,-12.64997,-5.40330
76.00000,-12.66664,-5.40760
76.10001,-12.68344,-5.41327
76.20001,-12.70010,-5.41845
76.30000,-12.71677,-5.42534
76.40000,-12.73330,-5.43142
76.50000,-12.75024,-5.43832
76.60001,-12.76664,-5.44134
76.70001,-12.78317,-5.44701
76.80000,-12.80010,-5.45302
76.90000,-12.81663,-5.46112
77.00000,-12.83357,-5.46937
77.10001,-12.85010,-5.47440
77.20001,-12.86677,-5.47943
77.30000,-12.88344,-5.48361
77.40000,-12.89997,-5.48766
77.50000,-12.91650,-5.49175
77.60001,-12.93330,-5.49869
77.70001,-12.95010,-5.50343
77.80000,-12.96663,-5.51063
77.90000,-12.98370,-5.51777
78.00000,-12.99997,-5.52014
78.10001,-13.01637,-5.52456
78.20001,-13.03330,-5.53014
78.30000,-13.04970,-5.53525
78.40000,-13.06637,-5.54264
78.50000,-13.08343,-5.54938
78.60001,-13.10023,-5.55344
78.70001,-13.11650,-5.55783
78.80000,-13.13343,-5.56324
78.90000,-13.14983,-5.56828
79.00000,-13.16637,-5.57569
79.10001,-13.18330,-5.57843
79.20001,-13.19983,-5.58487
79.30000,-13.21677,-5.58983
79.40000,-13.23343,-5.59530
79.50000,-13.25023,-5.59861
79.60001,-13.26663,-5.60393
79.70001,-13.28343,-5.60894
79.80000,-13.29997,-5.61176
79.90000,-13.31663,-5.61993
80.00000,-13.33343,-5.62358
80.10001,-13.34997,-5.62742
80.20001,-13.36690,-5.63140
80.30000,-13.38343,-5.63468
80.40000,-13.40010,-5.63884
80.50001,-13.41663,-5.64184
80.60001,-13.43330,-5.64621
80.70001,-13.44997,-5.64849
80.80000,-13.46677,-5.65435
80.90000,-13.48343,-5.65947
81.00001,-13.49997,-5.66221
81.10001,-13.51690,-5.66597
81.20001,-13.53330,-5.66834
81.30000,-13.54983,-5.67128
81.40000,-13.56650,-5.67273
81.50001,-13.58317,-5.67462
81.60001,-13.59983,-5.68094
81.70001,-13.61677,-5.68748
81.80000,-13.63357,-5.68939
81.90000,-13.64983,-5.69350
82.00001,-13.66690,-5.70129
82.10001,-13.68317,-5.71121
82.20001,-13.69970,-5.71454
82.30000,-13.71650,-5.71575
82.40000,-13.73317,-5.72010
82.50001,-13.75010,-5.72730
82.60001,-13.76690,-5.73240
82.70001,-13.78357,-5.73662
82.80000,-13.79997,-5.73601
82.90000,-13.81677,-5.73819
83.00001,-13.83330,-5.74317
83.10001,-13.84983,-5.74818
83.20001,-13.86690,-5.75165
83.30000,-13.88330,-5.75479
83.40000,-13.90023,-5.76070
83.50001,-13.91677,-5.76171
83.60001,-13.93343,-5.76716
83.70001,-13.94997,-5.77388
83.80000,-13.96663,-5.77952
83.90000,-13.98330,-5.78338
84.00001,-13.99997,-5.78670
84.10001,-14.01690,-5.79208
84.20001,-14.03330,-5.80002
84.30000,-14.05023,-5.80632
84.40000,-14.06663,-5.80904
84.50001,-14.08330,-5.81330
84.60001,-14.09997,-5.82034
84.70001,-14.11650,-5.82179
84.80000,-14.13317,-5.82603
84.90000,-14.14997,-5.83291
85.00001,-14.16677,-5.83539
85.10001,-14.18317,-5.83902
85.20001,-14.20023,-5.84216
85.30000,-14.21650,-5.84584
85.40000,-14.23317,-5.85462
85.50001,-14.24997,-5.86339
85.60001,-14.26663,-5.87061
85.70001,-14.28343,-5.87234
85.80000,-14.30023,-5.87516
85.90000,-14.31690,-5.88180
86.00001,-14.33330,-5.88755
86.10001,-14.35010,-5.88835
86.20001,-14.36663,-5.89278
86.30000,-14.38317,-5.90222
86.40000,-14.40010,-5.90687
86.50001,-14.41650,-5.90958
86.60001,-14.43356,-5.91715
86.70001,-14.45010,-5.92376
86.80000,-14.46676,-5.93265
86.90000,-14.48330,-5.93552
87.00001,-14.49996,-5.93684
87.10001,-14.51663,-5.94084
87.20001,-14.53330,-5.95183
87.30000,-14.55010,-5.95820
87.40000,-14.56663,-5.96298
87.50001,-14.58356,-5.96678
87.60001,-14.59996,-5.97007
87.70001,-14.61650,-5.98092
87.80000,-14.63330,-5.98568
87.90000,-14.64983,-5.99022
88.00001,-14.66663,-5.99453
88.10001,-14.68343,-5.99880
88.20001,-14.70010,-6.00370
88.30000,-14.71650,-6.01343
88.40000,-14.73356,-6.01849
88.50001,-14.74983,-6.02091
88.60001,-14.76650,-6.02579
88.70001,-14.78330,-6.02825
88.80000,-14.79983,-6.03088
88.90000,-14.81676,-6.04151
89.00001,-14.83343,-6.04581
89.10001,-14.85010,-6.05109
89.20001,-14.86663,-6.05862
89.30000,-14.88343,-6.06452
89.40000,-14.89983,-6.06923
89.50001,-14.91650,-6.07921
89.60001,-14.93356,-6.08510
89.70001,-14.95010,-6.09238
89.80000,-14.96690,-6.10618
89.90000,-14.98343,-6.11563
90.00001,-15.00010,-6.12616
90.10001,-15.01676,-6.13322
90.20001,-15.03330,-6.14335
90.30000,-15.04983,-6.15379
90.34600,-15.05770,-6.15587