File: GFBaking/data/3TspPectin/3TspPectin_4PointBend.is_flex_RawData/Specimen_RawData_3.csv
Time,Extension,Load
(sec),(mm),(N)
0.00000,0.00000,0.00006
0.05000,-0.00107,-0.00002
0.10000,-0.00560,-0.00005
0.15000,-0.01453,0.00000
0.20000,-0.02533,-0.00002
0.25000,-0.03560,-0.00003
0.30000,-0.04533,-0.00001
0.35000,-0.05507,-0.00002
0.40000,-0.06413,-0.00001
0.45000,-0.07307,-0.00001
0.50000,-0.08213,-0.00001
0.55000,-0.09053,-0.00001
0.60000,-0.09907,-0.00002
0.65000,-0.10773,-0.00002
0.70000,-0.11600,0.00000
0.75000,-0.12440,0.00000
0.80000,-0.13293,-0.00001
0.85000,-0.14133,-0.00002
0.90000,-0.15000,0.00001
0.95000,-0.15827,0.00000
1.00000,-0.16653,0.00001
1.05000,-0.17493,0.00001
1.10000,-0.18347,-0.00002
1.15000,-0.19160,0.00003
1.20000,-0.20000,0.00002
1.25000,-0.20853,0.00000
1.30000,-0.21640,0.00000
1.35000,-0.22480,0.00000
1.40000,-0.23347,0.00002
1.45000,-0.24147,0.00001
1.50000,-0.24960,0.00001
1.55000,-0.25827,-0.00001
1.60000,-0.26667,0.00000
1.65000,-0.27493,0.00003
1.70000,-0.28333,0.00001
1.75000,-0.29173,0.00001
1.80000,-0.30000,0.00000
1.85000,-0.30840,0.00003
1.90000,-0.31680,-0.00001
1.95000,-0.32520,0.00000
2.00000,-0.33360,0.00000
2.05000,-0.34160,-0.00001
2.10000,-0.35013,0.00002
2.15000,-0.35840,0.00000
2.20000,-0.36640,0.00002
2.25000,-0.37480,0.00000
2.30000,-0.38347,0.00003
2.35000,-0.39160,0.00000
2.40000,-0.39987,0.00002
2.45000,-0.40840,0.00002
2.50000,-0.41680,0.00002
2.55000,-0.42493,0.00000
2.60000,-0.43333,0.00002
2.65000,-0.44187,0.00001
2.70000,-0.44987,0.00002
2.75000,-0.45840,0.00003
2.80000,-0.46680,0.00001
2.85000,-0.47507,0.00002
2.90000,-0.48320,0.00002
2.95000,-0.49160,0.00003
3.00000,-0.50000,0.00002
3.05000,-0.50840,0.00000
3.10000,-0.51653,0.00002
3.15000,-0.52493,0.00003
3.20000,-0.53333,0.00003
3.25000,-0.54173,0.00001
3.30000,-0.55000,0.00002
3.35000,-0.55840,0.00003
3.40000,-0.56693,0.00003
3.45000,-0.57507,0.00004
3.50000,-0.58347,0.00002
3.55000,-0.59187,-0.00001
3.60000,-0.60000,0.00002
3.65000,-0.60827,0.00003
3.70000,-0.61680,0.00003
3.75000,-0.62480,0.00003
3.80000,-0.63307,0.00003
3.85000,-0.64160,0.00002
3.90000,-0.64973,0.00003
3.95000,-0.65800,0.00002
4.00000,-0.66653,0.00003
4.05000,-0.67480,0.00002
4.10000,-0.68320,0.00003
4.15000,-0.69146,0.00004
4.20000,-0.69973,0.00003
4.25000,-0.70826,0.00002
4.30000,-0.71666,0.00002
4.35000,-0.72493,0.00003
4.40000,-0.73346,0.00004
4.45000,-0.74186,0.00002
4.50000,-0.74986,0.00003
4.55000,-0.75813,0.00001
4.60000,-0.76680,0.00005
4.65000,-0.77480,0.00004
4.70000,-0.78293,0.00001
4.75000,-0.79160,0.00002
4.80000,-0.80000,0.00002
4.85000,-0.80826,0.00004
4.90000,-0.81666,0.00005
4.95000,-0.82506,0.00002
5.00000,-0.83346,0.00002
5.05000,-0.84173,0.00002
5.10000,-0.85013,0.00004
5.15000,-0.85853,0.00003
5.20000,-0.86680,0.00002
5.25000,-0.87493,0.00002
5.30000,-0.88333,0.00002
5.35000,-0.89173,0.00003
5.40000,-0.89986,0.00003
5.45000,-0.90826,0.00006
5.50000,-0.91680,0.00004
5.55000,-0.92480,0.00002
5.60000,-0.93320,0.00003
5.65000,-0.94186,0.00003
5.70000,-0.95013,0.00002
5.75000,-0.95826,0.00005
5.80000,-0.96680,0.00003
5.85000,-0.97520,0.00004
5.90000,-0.98333,0.00004
5.95000,-0.99173,0.00004
6.00000,-1.00013,0.00003
6.05000,-1.00840,0.00002
6.10000,-1.01666,0.00004
6.15000,-1.02493,0.00005
6.20000,-1.03333,0.00007
6.25000,-1.04146,0.00005
6.30000,-1.04973,0.00004
6.35000,-1.05813,0.00000
6.40000,-1.06666,0.00006
6.45000,-1.07480,0.00005
6.50000,-1.08306,0.00003
6.55000,-1.09186,0.00004
6.60000,-1.10013,0.00004
6.65000,-1.10813,0.00005
6.70000,-1.11653,0.00004
6.75000,-1.12520,0.00006
6.80000,-1.13320,0.00003
6.85000,-1.14160,0.00006
6.90000,-1.15026,0.00006
6.95000,-1.15826,0.00005
7.00000,-1.16653,0.00006
7.05000,-1.17493,0.00002
7.10000,-1.18306,0.00007
7.15000,-1.19146,0.00004
7.20000,-1.19986,0.00004
7.25000,-1.20826,0.00007
7.30000,-1.21666,0.00007
7.35000,-1.22506,0.00006
7.40000,-1.23333,0.00004
7.45000,-1.24186,0.00006
7.50000,-1.25013,0.00005
7.55000,-1.25826,0.00003
7.60000,-1.26680,0.00007
7.65000,-1.27520,0.00005
7.70000,-1.28306,0.00006
7.75000,-1.29146,0.00004
7.80000,-1.30013,0.00006
7.85000,-1.30813,0.00007
7.90000,-1.31640,0.00005
7.95000,-1.32493,0.00005
8.00000,-1.33333,0.00007
8.05000,-1.34146,0.00005
8.10000,-1.35000,0.00007
8.15000,-1.35840,0.00006
8.20000,-1.36666,0.00007
8.25000,-1.37506,0.00008
8.30000,-1.38333,0.00006
8.35000,-1.39186,0.00006
8.40000,-1.40026,0.00005
8.45000,-1.40840,0.00007
8.50000,-1.41680,0.00007
8.55000,-1.42506,0.00005
8.60000,-1.43320,0.00007
8.65000,-1.44160,0.00006
8.70000,-1.45013,0.00007
8.75000,-1.45813,0.00008
8.80000,-1.46640,0.00005
8.85000,-1.47520,0.00008
8.90000,-1.48346,0.00006
8.95000,-1.49160,0.00009
9.00000,-1.50000,0.00007
9.05000,-1.50853,0.00007
9.10000,-1.51666,0.00009
9.15000,-1.52506,0.00009
9.20000,-1.53346,0.00008
9.25000,-1.54160,0.00009
9.30000,-1.54986,0.00009
9.35000,-1.55813,0.00009
9.40000,-1.56653,0.00008
9.45000,-1.57480,0.00012
9.50000,-1.58306,0.00009
9.55000,-1.59133,0.00009
9.60000,-1.60000,0.00010
9.65000,-1.60826,0.00012
9.70000,-1.61653,0.00009
9.75000,-1.62506,0.00011
9.80000,-1.63360,0.00010
9.85000,-1.64160,0.00012
9.90000,-1.65013,0.00012
9.95000,-1.65866,0.00011
10.00000,-1.66653,0.00012
10.05000,-1.67493,0.00011
10.10000,-1.68346,0.00013
10.15000,-1.69146,0.00014
10.20000,-1.69986,0.00013
10.25000,-1.70826,0.00013
10.30000,-1.71653,0.00011
10.35000,-1.72480,0.00013
10.40000,-1.73320,0.00013
10.45000,-1.74160,0.00017
10.50000,-1.75000,0.00013
10.55000,-1.75840,0.00012
10.60000,-1.76653,0.00015
10.65000,-1.77520,0.00017
10.70000,-1.78346,0.00012
10.75000,-1.79160,0.00014
10.80000,-1.80013,0.00015
10.85000,-1.80853,0.00016
10.90000,-1.81653,0.00013
10.95000,-1.82480,0.00015
11.00000,-1.83346,0.00016
11.05000,-1.84146,0.00017
11.10000,-1.84973,0.00018
11.15000,-1.85826,0.00016
11.20000,-1.86653,0.00018
11.25000,-1.87480,0.00018
11.30000,-1.88333,0.00020
11.35000,-1.89173,0.00016
11.40000,-1.90013,0.00016
11.45000,-1.90853,0.00014
11.50000,-1.91680,0.00017
11.55000,-1.92520,0.00018
11.60000,-1.93346,0.00017
11.65000,-1.94160,0.00018
11.70000,-1.95013,0.00014
11.75000,-1.95840,0.00023
11.80000,-1.96653,0.00020
11.85000,-1.97493,0.00020
11.90000,-1.98346,0.00019
11.95000,-1.99160,0.00018
12.00000,-1.99986,0.00023
12.05000,-2.00840,0.00017
12.10000,-2.01666,0.00024
12.15000,-2.02493,0.00018
12.20000,-2.03333,0.00026
12.25000,-2.04186,0.00019
12.30000,-2.05000,0.00021
12.35000,-2.05853,0.00020
12.40000,-2.06693,0.00020
12.45000,-2.07506,0.00025
12.50000,-2.08333,0.00021
12.55000,-2.09173,0.00023
12.60000,-2.09999,0.00021
12.65000,-2.10826,0.00025
12.70000,-2.11653,0.00023
12.75000,-2.12479,0.00024
12.80000,-2.13333,0.00024
12.85000,-2.14159,0.00024
12.90000,-2.14986,0.00027
12.95000,-2.15839,0.00024
13.00000,-2.16679,0.00026
13.05000,-2.17479,0.00022
13.10000,-2.18333,0.00027
13.15000,-2.19186,0.00023
13.20000,-2.19986,0.00025
13.25000,-2.20826,0.00028
13.30000,-2.21679,0.00024
13.35000,-2.22479,0.00028
13.40000,-2.23306,0.00023
13.45000,-2.24146,0.00025
13.50000,-2.24973,0.00026
13.55000,-2.25799,0.00025
13.60000,-2.26653,0.00027
13.65000,-2.27493,0.00025
13.70000,-2.28333,0.00028
13.75000,-2.29173,0.00028
13.80000,-2.29986,0.00030
13.85000,-2.30853,0.00026
13.90000,-2.31693,0.00026
13.95000,-2.32493,0.00029
14.00000,-2.33333,0.00030
14.05000,-2.34186,0.00027
14.10000,-2.34986,0.00027
14.15000,-2.35826,0.00028
14.20000,-2.36679,0.00029
14.25000,-2.37479,0.00030
14.30000,-2.38293,0.00028
14.35000,-2.39159,0.00027
14.40000,-2.39986,0.00029
14.45000,-2.40813,0.00030
14.50000,-2.41666,0.00033
14.55000,-2.42506,0.00026
14.60000,-2.43333,0.00031
14.65000,-2.44159,0.00034
14.70000,-2.44999,0.00028
14.75000,-2.45839,0.00031
14.80000,-2.46679,0.00030
14.85000,-2.47493,0.00029
14.90000,-2.48333,0.00033
14.95000,-2.49173,0.00032
15.00000,-2.49986,0.00031
15.05000,-2.50826,0.00030
15.10000,-2.51666,0.00033
15.15000,-2.52479,0.00030
15.20000,-2.53319,0.00030
15.25000,-2.54186,0.00034
15.30000,-2.54999,0.00030
15.35000,-2.55826,0.00030
15.40000,-2.56679,0.00032
15.45000,-2.57519,0.00032
15.50000,-2.58333,0.00031
15.55000,-2.59173,0.00031
15.60000,-2.60013,0.00034
15.65000,-2.60839,0.00031
15.70000,-2.61666,0.00033
15.75000,-2.62506,0.00034
15.80000,-2.63333,0.00031
15.85000,-2.64159,0.00031
15.90000,-2.64986,0.00033
15.95000,-2.65813,0.00031
16.00000,-2.66666,0.00033
16.05000,-2.67493,0.00032
16.10000,-2.68319,0.00032
16.15000,-2.69173,0.00035
16.20000,-2.70013,0.00034
16.25000,-2.70813,0.00033
16.30000,-2.71679,0.00033
16.35000,-2.72533,0.00034
16.40000,-2.73319,0.00035
16.45000,-2.74159,0.00035
16.50000,-2.75026,0.00036
16.55000,-2.75813,0.00033
16.60000,-2.76653,0.00034
16.65000,-2.77493,0.00035
16.70000,-2.78306,0.00035
16.75000,-2.79146,0.00033
16.80000,-2.79999,0.00034
16.85000,-2.80826,0.00034
16.90000,-2.81679,0.00036
16.95000,-2.82506,0.00037
17.00000,-2.83319,0.00037
17.05000,-2.84173,0.00033
17.10000,-2.85013,0.00037
17.15000,-2.85826,0.00036
17.20000,-2.86679,0.00037
17.25000,-2.87519,0.00034
17.30000,-2.88319,0.00034
17.35000,-2.89146,0.00035
17.40000,-2.90013,0.00038
17.45000,-2.90813,0.00037
17.50000,-2.91639,0.00036
17.55000,-2.92506,0.00036
17.60000,-2.93333,0.00038
17.65000,-2.94159,0.00038
17.70000,-2.94999,0.00035
17.75000,-2.95839,0.00038
17.80000,-2.96679,0.00035
17.85000,-2.97519,0.00038
17.90000,-2.98346,0.00037
17.95000,-2.99186,0.00036
18.00000,-3.00026,0.00036
18.05000,-3.00826,0.00036
18.10000,-3.01679,0.00039
18.15000,-3.02506,0.00036
18.20000,-3.03319,0.00039
18.25000,-3.04159,0.00037
18.30000,-3.05013,0.00036
18.35000,-3.05826,0.00037
18.40000,-3.06653,0.00038
18.45000,-3.07519,0.00038
18.50000,-3.08346,0.00036
18.55000,-3.09159,0.00034
18.60000,-3.09999,0.00037
18.65000,-3.10853,0.00039
18.70000,-3.11679,0.00038
18.75000,-3.12506,0.00038
18.80000,-3.13359,0.00037
18.85000,-3.14173,0.00039
18.90000,-3.14999,0.00039
18.95000,-3.15839,0.00040
19.00000,-3.16679,0.00039
19.05000,-3.17506,0.00036
19.10000,-3.18319,0.00039
19.15000,-3.19146,0.00035
19.20000,-3.19999,0.00039
19.25000,-3.20826,0.00038
19.30000,-3.21653,0.00036
19.35000,-3.22519,0.00037
19.40000,-3.23359,0.00036
19.45000,-3.24159,0.00038
19.50000,-3.25013,0.00039
19.55000,-3.25866,0.00036
19.60000,-3.26666,0.00038
19.65000,-3.27493,0.00039
19.70000,-3.28346,0.00038
19.75000,-3.29159,0.00039
19.80000,-3.29986,0.00036
19.85000,-3.30826,0.00038
19.90000,-3.31653,0.00038
19.95000,-3.32479,0.00035
20.00000,-3.33333,0.00034
20.05000,-3.34159,0.00036
20.10000,-3.34999,0.00038
20.15000,-3.35839,0.00037
20.20000,-3.36653,0.00040
20.25000,-3.37519,0.00035
20.30000,-3.38359,0.00038
20.35000,-3.39159,0.00035
20.40000,-3.40013,0.00036
20.45000,-3.40866,0.00036
20.50000,-3.41652,0.00036
20.55000,-3.42479,0.00035
20.60000,-3.43346,0.00034
20.65000,-3.44159,0.00037
20.70000,-3.44972,0.00034
20.75000,-3.45826,0.00035
20.80000,-3.46666,0.00034
20.85000,-3.47492,0.00035
20.90000,-3.48332,0.00033
20.95000,-3.49186,0.00034
21.00000,-3.50012,0.00037
21.05000,-3.50852,0.00031
21.10000,-3.51679,0.00034
21.15000,-3.52519,0.00029
21.20000,-3.53359,0.00033
21.25000,-3.54159,0.00031
21.30000,-3.55012,0.00032
21.35000,-3.55839,0.00032
21.40000,-3.56652,0.00032
21.45000,-3.57479,0.00029
21.50000,-3.58332,0.00030
21.55000,-3.59146,0.00026
21.60000,-3.59972,0.00027
21.65000,-3.60852,0.00029
21.70000,-3.61679,0.00030
21.75000,-3.62492,0.00029
21.80000,-3.63346,0.00026
21.85000,-3.64186,0.00026
21.90000,-3.65012,0.00029
21.95000,-3.65852,0.00027
22.00000,-3.66692,0.00026
22.05000,-3.67519,0.00022
22.10000,-3.68332,0.00024
22.15000,-3.69172,0.00024
22.20000,-3.70012,0.00024
22.25000,-3.70826,0.00024
22.30000,-3.71652,0.00019
22.35000,-3.72492,0.00017
22.40000,-3.73346,0.00018
22.45000,-3.74159,0.00021
22.50000,-3.74986,0.00018
22.55000,-3.75852,0.00016
22.60000,-3.76692,0.00015
22.65000,-3.77492,0.00018
22.70000,-3.78332,0.00017
22.75000,-3.79199,0.00016
22.80000,-3.79999,0.00014
22.85000,-3.80826,0.00013
22.90000,-3.81679,0.00014
22.95000,-3.82492,0.00015
23.00000,-3.83319,0.00013
23.05000,-3.84159,0.00011
23.10000,-3.84986,0.00011
23.15000,-3.85812,0.00010
23.20000,-3.86652,0.00009
23.25000,-3.87492,0.00008
23.30000,-3.88346,0.00009
23.35000,-3.89172,0.00008
23.40000,-3.89986,0.00008
23.45000,-3.90852,0.00008
23.50000,-3.91679,0.00002
23.55000,-3.92492,0.00001
23.60000,-3.93346,0.00001
23.65000,-3.94186,0.00000
23.70000,-3.94986,-0.00001
23.75000,-3.95812,-0.00002
23.80000,-3.96679,-0.00001
23.85000,-3.97492,0.00001
23.90000,-3.98306,-0.00002
23.95000,-3.99159,-0.00002
24.00000,-3.99999,0.00000
24.05000,-4.00812,-0.00002
24.10000,-4.01652,-0.00003
24.15000,-4.02506,-0.00002
24.20000,-4.03346,0.00000
24.25000,-4.04186,-0.00001
24.30000,-4.05026,-0.00003
24.35000,-4.05852,-0.00004
24.40000,-4.06679,-0.00003
24.45000,-4.07492,-0.00002
24.50000,-4.08346,-0.00003
24.55000,-4.09172,-0.00005
24.60000,-4.09986,-0.00002
24.65000,-4.10826,-0.00005
24.70000,-4.11679,-0.00001
24.75000,-4.12492,-0.00002
24.80000,-4.13306,-0.00005
24.85000,-4.14186,-0.00004
24.90000,-4.15012,-0.00004
24.95000,-4.15826,-0.00003
25.00000,-4.16679,-0.00004
25.05000,-4.17532,-0.00005
25.10000,-4.18332,-0.00003
25.15000,-4.19172,-0.00005
25.20000,-4.20012,-0.00003
25.25000,-4.20839,-0.00002
25.30000,-4.21666,-0.00003
25.35000,-4.22492,-0.00004
25.40000,-4.23332,-0.00002
25.45000,-4.24159,-0.00002
25.50000,-4.24986,-0.00002
25.55000,-4.25826,-0.00006
25.60000,-4.26679,0.00000
25.65000,-4.27506,-0.00001
25.70000,-4.28332,-0.00005
25.75000,-4.29186,-0.00004
25.80000,-4.30012,-0.00004
25.85000,-4.30826,-0.00003
25.90000,-4.31679,-0.00003
25.95000,-4.32532,-0.00004
26.00000,-4.33319,-0.00004
26.05000,-4.34159,-0.00005
26.10000,-4.35012,-0.00002
26.15000,-4.35826,-0.00004
26.20000,-4.36652,-0.00004
26.25000,-4.37492,-0.00004
26.30000,-4.38319,-0.00004
26.35000,-4.39146,-0.00006
26.40000,-4.39986,-0.00006
26.45000,-4.40826,-0.00004
26.50000,-4.41679,-0.00001
26.55000,-4.42506,-0.00004
26.60000,-4.43332,-0.00003
26.65000,-4.44186,-0.00002
26.70000,-4.45012,-0.00002
26.75000,-4.45826,-0.00002
26.80000,-4.46666,-0.00004
26.85000,-4.47519,-0.00003
26.90000,-4.48319,-0.00002
26.95000,-4.49146,-0.00004
27.00000,-4.50012,-0.00003
27.05000,-4.50826,-0.00004
27.10000,-4.51639,-0.00005
27.15000,-4.52492,-0.00006
27.20000,-4.53319,-0.00003
27.25000,-4.54146,-0.00003
27.30000,-4.54999,-0.00003
27.35000,-4.55852,-0.00002
27.40000,-4.56679,-0.00003
27.45000,-4.57519,-0.00004
27.50000,-4.58332,-0.00002
27.55000,-4.59172,-0.00005
27.60000,-4.60012,-0.00003
27.65000,-4.60826,-0.00002
27.70000,-4.61666,-0.00004
27.75000,-4.62506,-0.00004
27.80000,-4.63319,-0.00003
27.85000,-4.64146,-0.00005
27.90000,-4.65012,-0.00002
27.95000,-4.65812,-0.00002
28.00000,-4.66639,-0.00002
28.05000,-4.67506,-0.00004
28.10000,-4.68346,-0.00003
28.15000,-4.69172,-0.00002
28.20000,-4.70012,-0.00003
28.25000,-4.70866,-0.00002
28.30000,-4.71679,-0.00003
28.35000,-4.72519,-0.00002
28.40000,-4.73372,-0.00004
28.45000,-4.74185,-0.00003
28.50000,-4.74999,0.00000
28.55000,-4.75839,-0.00003
28.60000,-4.76679,-0.00001
28.65000,-4.77506,-0.00002
28.70000,-4.78319,-0.00002
28.75000,-4.79159,-0.00004
28.80000,-4.80012,-0.00002
28.85000,-4.80839,-0.00001
28.90000,-4.81652,-0.00003
28.95000,-4.82506,-0.00002
29.00000,-4.83359,0.00000
29.05000,-4.84159,-0.00004
29.10000,-4.84999,0.00000
29.15000,-4.85865,-0.00003
29.20000,-4.86652,0.00001
29.25000,-4.87492,-0.00003
29.30000,-4.88345,0.00000
29.35000,-4.89159,-0.00001
29.40000,-4.89985,-0.00001
29.45000,-4.90825,-0.00001
29.50000,-4.91652,0.00000
29.55000,-4.92492,0.00001
29.60000,-4.93332,-0.00002
29.65000,-4.94159,0.00000
29.70000,-4.94999,-0.00001
29.75000,-4.95839,0.00000
29.80000,-4.96665,0.00002
29.85000,-4.97519,-0.00002
29.90000,-4.98359,0.00004
29.95000,-4.99159,-0.00001
30.00000,-4.99999,0.00001
30.05000,-5.00852,0.00000
30.10000,-5.01652,0.00000
30.15000,-5.02479,0.00000
30.20000,-5.03345,0.00002
30.25000,-5.04145,0.00002
30.30000,-5.04959,-0.00002
30.35000,-5.05825,0.00000
30.40000,-5.06665,0.00002
30.45000,-5.07479,0.00001
30.50000,-5.08332,0.00001
30.55000,-5.09172,0.00000
30.60000,-5.09999,0.00005
30.65000,-5.10839,0.00000
30.70000,-5.11665,0.00003
30.75000,-5.12519,0.00001
30.80000,-5.13345,0.00002
30.85000,-5.14159,0.00003
30.90000,-5.15012,0.00003
30.95000,-5.15852,0.00001
31.00000,-5.16652,0.00005
31.05000,-5.17479,0.00000
31.10000,-5.18345,0.00004
31.15000,-5.19159,0.00003
31.20000,-5.19999,0.00000
31.25000,-5.20852,0.00004
31.30000,-5.21679,0.00003
31.35000,-5.22492,0.00003
31.40000,-5.23359,0.00006
31.45000,-5.24199,-0.00002
31.50000,-5.25012,0.00004
31.55000,-5.25839,0.00003
31.60000,-5.26679,0.00002
31.65000,-5.27505,0.00006
31.70000,-5.28345,0.00000
31.75000,-5.29159,0.00005
31.80000,-5.30012,0.00004
31.85000,-5.30825,0.00004
31.90000,-5.31652,0.00007
31.95000,-5.32479,0.00000
32.00000,-5.33332,0.00004
32.05000,-5.34159,0.00003
32.10000,-5.34985,0.00003
32.15000,-5.35852,0.00004
32.20000,-5.36692,0.00000
32.25000,-5.37492,0.00006
32.30000,-5.38345,0.00005
32.35000,-5.39212,0.00001
32.40000,-5.39999,0.00004
32.45000,-5.40839,0.00004
32.50000,-5.41679,0.00007
32.55000,-5.42505,0.00003
32.60000,-5.43319,0.00007
32.65000,-5.44159,0.00004
32.70000,-5.44985,0.00004
32.75000,-5.45825,0.00006
32.80000,-5.46665,0.00004
32.85000,-5.47492,0.00007
32.90000,-5.48332,0.00007
32.95000,-5.49159,0.00008
33.00000,-5.49985,0.00008
33.05000,-5.50839,0.00007
33.10000,-5.51679,0.00010
33.15000,-5.52492,0.00009
33.20000,-5.53332,0.00009
33.25000,-5.54185,0.00006
33.30000,-5.54985,0.00006
33.35000,-5.55825,-0.00001
33.40000,-5.56679,0.00000
33.45000,-5.57492,-0.00001
33.50000,-5.58305,-0.00003
33.55000,-5.59159,-0.00005
33.60000,-5.59999,-0.00003
33.65000,-5.60812,-0.00005
33.70000,-5.61665,-0.00004
33.75000,-5.62505,-0.00005
33.80000,-5.63345,-0.00003
33.85000,-5.64185,-0.00002
33.90000,-5.64999,-0.00003
33.95000,-5.65852,-0.00002
34.00000,-5.66692,-0.00003
34.05000,-5.67492,-0.00005
34.10000,-5.68345,-0.00002
34.15000,-5.69185,-0.00004
34.20000,-5.69985,-0.00003
34.25000,-5.70812,-0.00005
34.30000,-5.71679,-0.00003
34.35000,-5.72479,-0.00003
34.40000,-5.73305,-0.00006
34.45000,-5.74185,-0.00004
34.50000,-5.75012,-0.00004
34.55000,-5.75839,-0.00005
34.60000,-5.76679,-0.00003
34.65000,-5.77532,-0.00004
34.70000,-5.78345,-0.00004
34.75000,-5.79185,-0.00002
34.80000,-5.80025,-0.00003
34.85000,-5.80852,-0.00002
34.90000,-5.81679,-0.00001
34.95000,-5.82505,-0.00002
35.00000,-5.83332,-0.00004
35.05000,-5.84172,-0.00004
35.10000,-5.84985,-0.00003
35.15000,-5.85812,-0.00006
35.20000,-5.86679,-0.00003
35.25000,-5.87505,-0.00003
35.30000,-5.88332,-0.00004
35.35000,-5.89172,-0.00003
35.40000,-5.90025,-0.00003
35.45000,-5.90825,-0.00002
35.50000,-5.91665,-0.00002
35.55000,-5.92519,-0.00004
35.60000,-5.93332,-0.00004
35.65000,-5.94159,-0.00002
35.70000,-5.94999,-0.00003
35.75000,-5.95839,-0.00001
35.80000,-5.96665,-0.00003
35.85000,-5.97505,-0.00001
35.90000,-5.98319,-0.00003
35.95000,-5.99145,-0.00004
36.00000,-5.99972,-0.00002
36.05000,-6.00812,-0.00004
36.10000,-6.01665,-0.00003
36.15000,-6.02505,-0.00002
36.20000,-6.03332,-0.00001
36.25000,-6.04185,-0.00001
36.30000,-6.05025,-0.00004
36.35000,-6.05825,-0.00002
36.40000,-6.06665,-0.00003
36.45000,-6.07532,-0.00001
36.50000,-6.08332,-0.00002
36.55000,-6.09159,-0.00003
36.60000,-6.10012,-0.00002
36.65000,-6.10812,-0.00002
36.70000,-6.11639,-0.00003
36.75000,-6.12492,-0.00002
36.80000,-6.13332,0.00000
36.85000,-6.14158,-0.00002
36.90000,-6.15012,-0.00003
36.95000,-6.15852,-0.00002
37.00000,-6.16679,-0.00003
37.05000,-6.17505,-0.00003
37.10000,-6.18332,-0.00003
37.15000,-6.19185,-0.00002
37.20000,-6.20012,-0.00002
37.25000,-6.20825,-0.00002
37.30000,-6.21678,0.00000
37.35000,-6.22519,-0.00002
37.40000,-6.23332,-0.00002
37.45000,-6.24158,-0.00001
37.50000,-6.25012,-0.00001
37.55000,-6.25825,-0.00002
37.60000,-6.26652,-0.00001
37.65000,-6.27505,0.00000
37.70000,-6.28345,-0.00001
37.75000,-6.29172,-0.00002
37.80000,-6.30012,-0.00002
37.85000,-6.30852,-0.00001
37.90000,-6.31678,-0.00001
37.95000,-6.32505,-0.00001
38.00000,-6.33345,0.00000
38.05000,-6.34172,-0.00002
38.10000,-6.35012,-0.00001
38.15000,-6.35838,0.00000
38.20000,-6.36665,-0.00001
38.25000,-6.37492,0.00000
38.30000,-6.38318,-0.00003
38.35000,-6.39145,-0.00002
38.40000,-6.40012,0.00000
38.45000,-6.40825,-0.00001
38.50000,-6.41652,-0.00001
38.55000,-6.42505,-0.00003
38.60000,-6.43345,0.00003
38.65000,-6.44158,-0.00001
38.70000,-6.45012,0.00001
38.75000,-6.45865,-0.00001
38.80000,-6.46665,-0.00001
38.85000,-6.47505,0.00002
38.90000,-6.48345,0.00000
38.95000,-6.49158,0.00001
39.00000,-6.49985,0.00000
39.05000,-6.50825,-0.00001
39.10000,-6.51652,-0.00001
39.15000,-6.52478,0.00001
39.20000,-6.53318,-0.00001
39.25000,-6.54158,-0.00001
39.30000,-6.55012,0.00003
39.35000,-6.55838,0.00001
39.40000,-6.56665,0.00003
39.45000,-6.57518,0.00001
39.50000,-6.58358,0.00002
39.55000,-6.59158,-0.00002
39.60000,-6.59998,0.00003
39.65000,-6.60852,0.00003
39.70000,-6.61652,0.00002
39.75000,-6.62492,0.00000
39.80000,-6.63345,0.00000
39.85000,-6.64145,0.00004
39.90000,-6.64958,-0.00001
39.95000,-6.65812,0.00001
40.00000,-6.66638,0.00001
40.05000,-6.67465,-0.00001
40.10000,-6.68318,0.00000
40.15000,-6.69172,0.00002
40.20000,-6.70012,0.00000
40.25000,-6.70865,0.00001
40.30000,-6.71678,0.00002
40.35000,-6.72518,0.00001
40.40000,-6.73345,0.00002
40.45000,-6.74158,-0.00002
40.50000,-6.74998,0.00005
40.55000,-6.75838,-0.00002
40.60000,-6.76638,0.00003
40.65000,-6.77478,-0.00002
40.70000,-6.78345,0.00000
40.75000,-6.79158,0.00001
40.80000,-6.79985,0.00000
40.85000,-6.80852,0.00001
40.90000,-6.81678,0.00001
40.95000,-6.82492,0.00001
41.00000,-6.83345,0.00003
41.05000,-6.84198,-0.00001
41.10000,-6.85012,0.00000
41.15000,-6.85852,0.00003
41.20000,-6.86692,0.00002
41.25000,-6.87505,0.00001
41.30000,-6.88332,0.00003
41.35000,-6.89172,-0.00001
41.40000,-6.90012,0.00004
41.45000,-6.90838,0.00000
41.50000,-6.91652,0.00003
41.55000,-6.92478,-0.00001
41.60000,-6.93345,0.00003
41.65000,-6.94172,0.00003
41.70000,-6.94998,0.00002
41.75000,-6.95852,0.00002
41.80000,-6.96692,-0.00001
41.85000,-6.97492,0.00004
41.90000,-6.98345,0.00004
41.95000,-6.99198,0.00002
42.00000,-6.99998,0.00003
42.05000,-7.00825,0.00000
42.10000,-7.01678,0.00003
42.15000,-7.02492,0.00004
42.20000,-7.03318,0.00002
42.25000,-7.04158,0.00003
42.30000,-7.04985,0.00002
42.35000,-7.05825,0.00002
42.40000,-7.06665,0.00005
42.45000,-7.07492,0.00001
42.50000,-7.08345,0.00005
42.55000,-7.09185,0.00001
42.60000,-7.09998,0.00004
42.65000,-7.10852,0.00005
42.70000,-7.11678,0.00002
42.75000,-7.12492,0.00003
42.80000,-7.13332,0.00002
42.85000,-7.14198,0.00004
42.90000,-7.14985,0.00002
42.95000,-7.15812,0.00003
43.00000,-7.16678,0.00005
43.05000,-7.17492,0.00002
43.10000,-7.18305,0.00002
43.15000,-7.19158,0.00004
43.20000,-7.19998,0.00003
43.25000,-7.20825,0.00005
43.30000,-7.21665,0.00003
43.35000,-7.22505,0.00003
43.40000,-7.23332,0.00006
43.45000,-7.24172,0.00004
43.50000,-7.24998,0.00004
43.55000,-7.25838,0.00001
43.60000,-7.26665,0.00005
43.65000,-7.27478,0.00005
43.70000,-7.28332,0.00002
43.75000,-7.29185,0.00004
43.80000,-7.29985,0.00002
43.85000,-7.30812,0.00002
43.90000,-7.31665,0.00003
43.95000,-7.32478,0.00005
44.00000,-7.33305,0.00002
44.05000,-7.34185,0.00003
44.10000,-7.35012,0.00003
44.15000,-7.35825,0.00006
44.20000,-7.36678,0.00002
44.25000,-7.37532,0.00002
44.30000,-7.38345,0.00004
44.35000,-7.39185,0.00005
44.40000,-7.40025,0.00003
44.45000,-7.40852,0.00005
44.50000,-7.41665,0.00006
44.55000,-7.42505,0.00003
44.60000,-7.43332,0.00006
44.65000,-7.44172,0.00006
44.70000,-7.44998,0.00005
44.75000,-7.45825,0.00002
44.80000,-7.46678,0.00006
44.85000,-7.47505,0.00005
44.90000,-7.48332,0.00005
44.95000,-7.49198,0.00004
45.00000,-7.50025,0.00003
45.05000,-7.50825,0.00003
45.10000,-7.51678,0.00005
45.15000,-7.52532,0.00004
45.20000,-7.53318,0.00002
45.25000,-7.54145,0.00002
45.30000,-7.55011,0.00003
45.35000,-7.55811,0.00003
45.40000,-7.56651,0.00002
45.45000,-7.57491,0.00002
45.50000,-7.58318,0.00004
45.55000,-7.59145,-0.00002
45.60000,-7.59998,0.00002
45.65000,-7.60825,0.00002
45.70000,-7.61678,0.00001
45.75000,-7.62518,0.00001
45.80000,-7.63331,0.00001
45.85000,-7.64185,0.00000
45.90000,-7.65025,-0.00001
45.95000,-7.65825,0.00000
46.00000,-7.66665,0.00002
46.05000,-7.67518,-0.00002
46.10000,-7.68318,-0.00001
46.15000,-7.69158,-0.00004
46.20000,-7.70011,-0.00001
46.25000,-7.70811,0.00000
46.30000,-7.71651,-0.00003
46.35000,-7.72505,-0.00001
46.40000,-7.73331,-0.00001
46.45000,-7.74145,-0.00002
46.50000,-7.74998,-0.00001
46.55000,-7.75838,-0.00002
46.60000,-7.76665,-0.00001
46.65000,-7.77505,-0.00001
46.70000,-7.78345,-0.00001
46.75000,-7.79185,-0.00002
46.80000,-7.80011,-0.00003
46.85000,-7.80825,-0.00002
46.90000,-7.81678,-0.00002
46.95000,-7.82505,-0.00002
47.00000,-7.83331,-0.00001
47.05000,-7.84145,-0.00005
47.10000,-7.84998,-0.00003
47.15000,-7.85811,-0.00003
47.20000,-7.86651,-0.00003
47.25000,-7.87518,-0.00002
47.30000,-7.88345,-0.00004
47.35000,-7.89158,-0.00002
47.40000,-7.89998,-0.00002
47.45000,-7.90865,-0.00004
47.50000,-7.91665,-0.00001
47.55000,-7.92505,-0.00004
47.60000,-7.93358,-0.00003
47.65000,-7.94171,-0.00002
47.70000,-7.94998,-0.00003
47.75000,-7.95838,-0.00002
47.80000,-7.96678,-0.00004
47.85000,-7.97505,-0.00001
47.90000,-7.98318,-0.00002
47.95000,-7.99145,-0.00006
48.00000,-7.99998,-0.00003
48.05000,-8.00825,-0.00003
48.09200,-8.01518,-0.00003