File: GFBaking/data/misc/7Gluten_Compression_Misc/7gluten1_1.is_comp.raw
"Test Type","Compression"
"Method Name","C:\Users\Public\Documents\Instron\Bluehill\Templates\Instron Examples\Bluehill\CompressionTest Bread.im_comp"
"Sample name","P:\+Courses\MatSci\Spring2016\GF Baking - Emily, Elizabeth, Frances\7gluten1.is_comp"
"User",""
"Sample note 1",""
"Sample note 2",""
"Sample note 3",""
"Geometry","Circular"
"Specimen",1
"Specimen label","7gluten1"
"Width",50.000000,"mm"
"Thickness",50.000000,"mm"
"Anvil height",25.480000,"mm"
"Diameter",21.870000,"mm"
"Inner diameter",8.000000,"mm"
"Outer diameter",10.000000,"mm"
"Wall thickness",1.000000,"mm"
"Area",3.756535,"cm^2"
"Linear density",100.000000,"tex"
"Sled weight",10.000000,"N"
"Loading span",10.000000,"mm"
"Support span",100.000000,"mm"
"Span ratio","2"
"Fixture type","4-point"
"Included"
"Final width",50.000000,"mm"
"Final thickness",50.000000,"mm"
"Final anvil height",50.000000,"mm"
"Final diameter",1.000000,"mm"
"Final Inner diameter",0.000000,"mm"
"Final outer diameter",1.000000,"mm"
"Final wall thickness",0.500000,"mm"
"Final area",0.007854,"cm^2"
"Final linear density",1.000000,"tex"
"Operator ID","George"
"Company","ABC"
"Laboratory Name","Zyx"
"Comment",""
"Custom text input  5",""
"Custom text input  6",""
"Custom text input  7",""
"Custom text input  8",""
"Custom text input  9",""
"Custom text input 10",""
"Custom text input 11",""
"Custom text input 12",""
"Custom text input 13",""
"Custom text input 14",""
"Custom text input 15",""
"Custom text input 16",""
"Custom text input 17",""
"Custom text input 18",""
"Custom text input 19",""
"Custom text input 20",""
"Custom text input 21",""
"Custom text input 22",""
"Custom text input 23",""
"Custom text input 24",""
"Custom text input 25",""
"Custom text input 26",""
"Custom text input 27",""
"Custom text input 28",""
"Custom text input 29",""
"Custom text input 30",""
"Custom text input 31",""
"Custom text input 32",""
"Custom text input 33",""
"Custom text input 34",""
"Custom text input 35",""
"Custom text input 36",""
"Custom text input 37",""
"Custom text input 38",""
"Custom text input 39",""
"Custom text input 40",""
"Custom text input 41",""
"Custom text input 42",""
"Custom text input 43",""
"Custom text input 44",""
"Custom text input 45",""
"Custom text input 46",""
"Custom text input 47",""
"Custom text input 48",""
"Custom text input 49",""
"Custom text input 50",""
"Temperature (deg C)",18.000000,""
"Humidity (%)",50.000000,""
"Custom number input  3",0.000000,""
"Custom number input  4",0.000000,""
"Custom number input  5",0.000000,""
"Custom number input  6",0.000000,""
"Custom number input  7",0.000000,""
"Custom number input  8",0.000000,""
"Custom number input  9",0.000000,""
"Custom number input 10",0.000000,""
"Time sec","Extension mm","Load kgf","Compressive stress MPa","Cycle Count ","Total Cycle Count ","Repetitions Count ","Marked Data ","PIP Count ","Compressive extension mm","Compressive strain %","Compressive load kgf","Displacement (Strain 1) mm","True strain %","Corrected Position mm","True stress Pa"
0,-0.000133333,-0.01092473,0.0002851963,0,0,0,0,0,-2.762533e-020,-1.084202e-019,0.01092473,0,0,-0.000133333,285.1963
0.2,-0.02386661,-0.01328349,0.0003467731,0,0,0,0,0,0.02373328,0.09314521,0.01328349,0,0.09318862,-0.02386661,346.4501
0.4,-0.06386652,-0.01735989,0.0004531898,0,0,0,0,0,0.06373318,0.2501315,0.01735989,0,0.2504449,-0.06386652,452.0562
0.6,-0.09919976,-0.02097953,0.0005476828,0,0,0,0,0,0.09906643,0.3888028,0.02097953,0,0.3895606,-0.09919976,545.5534
0.8,-0.1331997,-0.02427297,0.0006336599,0,0,0,0,0,0.1330663,0.5222411,0.02427297,0,0.5236095,-0.1331997,630.3506
1,-0.1665329,-0.02697379,0.0007041663,0,0,0,0,0,0.1663996,0.6530631,0.02697379,0,0.6552048,-0.1665329,699.5676
1.2,-0.1999995,-0.03024718,0.00078962,0,0,0,0,0,0.1998662,0.7844083,0.03024718,0,0.7875009,-0.1999995,783.4262
1.4,-0.2335994,-0.03268272,0.0008532013,0,0,0,0,0,0.2334661,0.9162768,0.03268272,0,0.9205005,-0.2335994,845.3836
1.6,-0.2667994,-0.03621255,0.0009453493,0,0,0,0,0,0.266666,1.046575,0.03621254,0,1.052091,-0.2667994,935.4555
1.8,-0.3001326,-0.03935037,0.001027264,0,0,0,0,0,0.2999993,1.177397,0.03935036,0,1.184384,-0.3001326,1015.169
2,-0.3335992,-0.04271814,0.001115181,0,0,0,0,0,0.3334658,1.308743,0.04271814,0,1.317382,-0.3335992,1100.587
2.2,-0.3670658,-0.04580877,0.001195864,0,0,0,0,0,0.3669325,1.440088,0.04580877,0,1.450558,-0.3670658,1178.643
2.4,-0.4001324,-0.04891616,0.001276984,0,0,0,0,0,0.399999,1.569863,0.04891616,0,1.582316,-0.4001324,1256.938
2.6,-0.4333323,-0.05237595,0.001367304,0,0,0,0,0,0.433199,1.700162,0.05237595,0,1.71478,-0.4333323,1344.058
2.8,-0.4667989,-0.05557059,0.001450702,0,0,0,0,0,0.4666655,1.831507,0.05557059,0,1.848487,-0.4667989,1424.132
3,-0.4999988,-0.05946733,0.001552429,0,0,0,0,0,0.4998655,1.961806,0.05946733,0,1.981305,-0.4999988,1521.973
3.2,-0.5333321,-0.06380839,0.001665755,0,0,0,0,0,0.5331987,2.092628,0.06380839,0,2.114833,-0.5333321,1630.897
3.4,-0.5667986,-0.06702278,0.001749668,0,0,0,0,0,0.5666653,2.223973,0.06702278,0,2.249076,-0.5667986,1710.756
3.6,-0.6001319,-0.07023834,0.001833612,0,0,0,0,0,0.5999986,2.354795,0.07023834,0,2.382963,-0.6001319,1790.434
3.8,-0.6335985,-0.07460776,0.001947679,0,0,0,0,0,0.6334652,2.48614,0.07460777,0,2.517567,-0.6335985,1899.256
4,-0.666665,-0.07822457,0.002042097,0,0,0,0,0,0.6665317,2.615915,0.07822457,0,2.650739,-0.666665,1988.678
4.2,-0.7001316,-0.08219266,0.002145686,0,0,0,0,0,0.6999983,2.747261,0.08219266,0,2.785704,-0.7001316,2086.739
4.4,-0.7334649,-0.08614885,0.002248965,0,0,0,0,0,0.7333316,2.878083,0.08614885,0,2.920312,-0.7334649,2184.238
4.6,-0.7670648,-0.09055059,0.002363875,0,0,0,0,0,0.7669315,3.009951,0.09055059,0,3.05618,-0.7670648,2292.723
4.8,-0.8002647,-0.0952235,0.002485864,0,0,0,0,0,0.8001314,3.140249,0.09522349,0,3.190612,-0.8002647,2407.802
5,-0.8334646,-0.0996908,0.002602485,0,0,0,0,0,0.8333313,3.270548,0.0996908,0,3.325226,-0.8334646,2517.37
5.2,-0.8669312,-0.1035309,0.002702732,0,0,0,0,0,0.8667979,3.401893,0.1035309,0,3.461104,-0.8669312,2610.788
5.4,-0.9003978,-0.1063171,0.002775469,0,0,0,0,0,0.9002644,3.533238,0.1063171,0,3.597168,-0.9003978,2677.405
5.6,-0.933331,-0.1108063,0.002892662,0,0,0,0,0,0.9331977,3.662491,0.1108063,0,3.731244,-0.933331,2786.719
5.8,-0.966531,-0.1148073,0.002997111,0,0,0,0,0,0.9663976,3.792789,0.1148073,0,3.866588,-0.966531,2883.437
6,-1.000131,-0.1186185,0.003096605,0,0,0,0,0,0.9999976,3.924658,0.1186185,0,4.003749,-1.000131,2975.074
6.2,-1.033464,-0.1223373,0.003193686,0,0,0,0,0,1.033331,4.05548,0.1223373,0,4.140008,-1.033464,3064.167
6.4,-1.066664,-0.1262488,0.003295797,0,0,0,0,0,1.066531,4.185779,0.1262488,0,4.275906,-1.066664,3157.842
6.6,-1.100131,-0.1303687,0.00340335,0,0,0,0,0,1.099997,4.317123,0.1303687,0,4.413083,-1.100131,3256.423
6.8,-1.133597,-0.1353447,0.00353325,0,0,0,0,0,1.133464,4.448469,0.1353447,0,4.550449,-1.133597,3376.074
7,-1.166931,-0.1389537,0.003627465,0,0,0,0,0,1.166797,4.579291,0.1389537,0,4.687456,-1.166931,3461.353
7.2,-1.200264,-0.14173,0.003699943,0,0,0,0,0,1.20013,4.710113,0.14173,0,4.82465,-1.200264,3525.672
7.4,-1.233464,-0.1463968,0.003821773,0,0,0,0,0,1.23333,4.840411,0.1463968,0,4.961482,-1.233464,3636.784
7.6,-1.266797,-0.1512711,0.003949018,0,0,0,0,0,1.266664,4.971233,0.1512711,0,5.099053,-1.266797,3752.703
7.8,-1.300263,-0.154732,0.004039366,0,0,0,0,0,1.30013,5.102578,0.1547319,0,5.237365,-1.300263,3833.254
8,-1.333463,-0.1606412,0.004193631,0,0,0,0,0,1.33333,5.232877,0.1606412,0,5.374764,-1.333463,3974.183
8.200001,-1.366797,-0.1652606,0.004314223,0,0,0,0,0,1.366663,5.363699,0.1652606,0,5.512905,-1.366797,4082.821
8.400001,-1.400263,-0.1699859,0.00443758,0,0,0,0,0,1.40013,5.495044,0.1699859,0,5.651791,-1.400263,4193.733
8.6,-1.43373,-0.1748873,0.004565532,0,0,0,0,0,1.433597,5.62639,0.1748873,0,5.79087,-1.43373,4308.657
8.8,-1.466796,-0.1792546,0.004679545,0,0,0,0,0,1.466663,5.756165,0.1792546,0,5.928477,-1.466796,4410.183
9,-1.499863,-0.1841859,0.004808277,0,0,0,0,0,1.49973,5.88594,0.1841858,0,6.066274,-1.499863,4525.265
9.200001,-1.533596,-0.1888799,0.004930818,0,0,0,0,0,1.533463,6.018332,0.1888799,0,6.207045,-1.533596,4634.065
9.400001,-1.566796,-0.1935681,0.005053206,0,0,0,0,0,1.566663,6.148631,0.1935681,0,6.345783,-1.566796,4742.503
9.6,-1.599996,-0.1975021,0.005155905,0,0,0,0,0,1.599863,6.278929,0.1975021,0,6.484715,-1.599996,4832.169
9.8,-1.633463,-0.2020602,0.005274897,0,0,0,0,0,1.633329,6.410275,0.2020602,0,6.624958,-1.633463,4936.762
10,-1.666929,-0.2070173,0.005404306,0,0,0,0,0,1.666796,6.541619,0.2070173,0,6.765398,-1.666929,5050.777
10.2,-1.700396,-0.2113398,0.005517146,0,0,0,0,0,1.700262,6.672965,0.2113398,0,6.906035,-1.700396,5148.989
10.4,-1.733596,-0.2158901,0.005635933,0,0,0,0,0,1.733462,6.803263,0.21589,0,7.045748,-1.733596,5252.506
10.6,-1.766662,-0.2204299,0.00575445,0,0,0,0,0,1.766529,6.933039,0.2204299,0,7.185094,-1.766662,5355.492
10.8,-1.800129,-0.2249702,0.005872975,0,0,0,0,0,1.799996,7.064384,0.2249702,0,7.326324,-1.800129,5458.086
11,-1.833596,-0.2291633,0.00598244,0,0,0,0,0,1.833462,7.195729,0.2291633,0,7.467753,-1.833596,5551.96
11.2,-1.866795,-0.2336718,0.006100135,0,0,0,0,0,1.866662,7.326028,0.2336718,0,7.608253,-1.866795,5653.238
11.4,-1.899995,-0.2379597,0.006212074,0,0,0,0,0,1.899862,7.456326,0.2379597,0,7.748951,-1.899995,5748.881
11.6,-1.933595,-0.2424337,0.006328871,0,0,0,0,0,1.933462,7.588195,0.2424337,0,7.891546,-1.933595,5848.624
11.8,-1.967062,-0.2468325,0.006443704,0,0,0,0,0,1.966929,7.719541,0.2468325,0,8.033777,-1.967062,5946.28
12,-1.999995,-0.2508874,0.00654956,0,0,0,0,0,1.999862,7.848793,0.2508874,0,8.17394,-1.999995,6035.499
12.2,-2.033328,-0.2550833,0.006659097,0,0,0,0,0,2.033195,7.979614,0.2550834,0,8.316005,-2.033328,6127.727
12.4,-2.066795,-0.2594689,0.006773583,0,0,0,0,0,2.066662,8.11096,0.2594689,0,8.458843,-2.066795,6224.18
12.6,-2.100128,-0.2636978,0.006883983,0,0,0,0,0,2.099995,8.241781,0.2636978,0,8.601312,-2.100128,6316.62
12.8,-2.133328,-0.2678956,0.006993569,0,0,0,0,0,2.133195,8.37208,0.2678956,0,8.743416,-2.133328,6408.062
13,-2.166795,-0.2719906,0.007100472,0,0,0,0,0,2.166662,8.503426,0.2719907,0,8.886865,-2.166795,6496.688
13.2,-2.200395,-0.2762912,0.00721274,0,0,0,0,0,2.200261,8.635294,0.2762912,0,9.031093,-2.200395,6589.899
13.4,-2.233728,-0.2803963,0.007319907,0,0,0,0,0,2.233594,8.766115,0.2803963,0,9.174381,-2.233728,6678.236
13.6,-2.266794,-0.284306,0.00742197,0,0,0,0,0,2.266661,8.895891,0.284306,0,9.316728,-2.266794,6761.72
13.8,-2.299994,-0.2883332,0.007527102,0,0,0,0,0,2.299861,9.02619,0.2883331,0,9.459852,-2.299994,6847.692
14,-2.333461,-0.2923715,0.007632526,0,0,0,0,0,2.333328,9.157536,0.2923715,0,9.604334,-2.333461,6933.575
14.2,-2.366928,-0.2961791,0.007731926,0,0,0,0,0,2.366794,9.28888,0.2961791,0,9.749024,-2.366928,7013.717
14.4,-2.400127,-0.3000318,0.007832503,0,0,0,0,0,2.399994,9.419179,0.3000318,0,9.892769,-2.400127,7094.746
14.6,-2.433461,-0.303847,0.0079321,0,0,0,0,0,2.433327,9.55,0.303847,0,10.0373,-2.433461,7174.584
14.8,-2.466927,-0.3076924,0.008032486,0,0,0,0,0,2.466794,9.681346,0.3076924,0,10.18262,-2.466927,7254.833
15,-2.500394,-0.31156,0.008133452,0,0,0,0,0,2.500261,9.812691,0.31156,0,10.32815,-2.500394,7335.342
15.2,-2.533461,-0.3152335,0.008229353,0,0,0,0,0,2.533327,9.942467,0.3152336,0,10.47215,-2.533461,7411.152
15.4,-2.566661,-0.3188829,0.00832462,0,0,0,0,0,2.566527,10.07277,0.3188829,0,10.61693,-2.566661,7486.1
15.6,-2.600127,-0.32259,0.008421398,0,0,0,0,0,2.599994,10.20411,0.32259,0,10.7631,-2.600127,7562.069
15.8,-2.63346,-0.3261357,0.00851396,0,0,0,0,0,2.633327,10.33493,0.3261357,0,10.90889,-2.63346,7634.048
16,-2.66666,-0.3296042,0.008604507,0,0,0,0,0,2.666527,10.46523,0.3296042,0,11.05432,-2.66666,7704.025
16.2,-2.700127,-0.3332481,0.008699633,0,0,0,0,0,2.699993,10.59658,0.3332481,0,11.20112,-2.700127,7777.77
16.4,-2.733593,-0.3368882,0.008794659,0,0,0,0,0,2.73346,10.72792,0.3368882,0,11.34814,-2.733593,7851.174
16.6,-2.76706,-0.3403367,0.008884684,0,0,0,0,0,2.766927,10.85927,0.3403367,0,11.49538,-2.76706,7919.873
16.8,-2.80026,-0.3436756,0.008971848,0,0,0,0,0,2.800127,10.98956,0.3436756,0,11.64166,-2.80026,7985.88
17,-2.833326,-0.3470606,0.009060217,0,0,0,0,0,2.833193,11.11934,0.3470606,0,11.78756,-2.833326,8052.78
17.2,-2.866793,-0.3504791,0.009149458,0,0,0,0,0,2.86666,11.25069,0.3504791,0,11.93545,-2.866793,8120.082
17.4,-2.90026,-0.3537639,0.00923521,0,0,0,0,0,2.900126,11.38203,0.3537639,0,12.08355,-2.90026,8184.055
17.6,-2.93346,-0.3570242,0.009320321,0,0,0,0,0,2.933326,11.51233,0.3570242,0,12.2307,-2.93346,8247.335
17.8,-2.966793,-0.3600296,0.00939878,0,0,0,0,0,2.966659,11.64315,0.3600296,0,12.37865,-2.966793,8304.466
18,-3.000393,-0.3632225,0.009482132,0,0,0,0,0,3.000259,11.77502,0.3632225,0,12.528,-3.000393,8365.609
18.2,-3.033859,-0.3664747,0.009567033,0,0,0,0,0,3.033726,11.90636,0.3664747,0,12.67699,-3.033859,8427.947
18.4,-3.066659,-0.3693195,0.009641298,0,0,0,0,0,3.066526,12.03509,0.3693195,0,12.82323,-3.066659,8480.959
18.6,-3.099992,-0.3723214,0.009719662,0,0,0,0,0,3.099859,12.16592,0.3723214,0,12.97206,-3.099992,8537.177
18.8,-3.133592,-0.3752818,0.009796947,0,0,0,0,0,3.133459,12.29778,0.3752818,0,13.1223,-3.133592,8592.14
19,-3.166659,-0.3780942,0.009870366,0,0,0,0,0,3.166526,12.42756,0.3780942,0,13.27038,-3.166659,8643.72
19.2,-3.199992,-0.380898,0.009943561,0,0,0,0,0,3.199859,12.55838,0.380898,0,13.41988,-3.199992,8694.81
19.4,-3.233325,-0.3834542,0.01001029,0,0,0,0,0,3.233192,12.6892,0.3834543,0,13.56961,-3.233325,8740.067
19.6,-3.266925,-0.3864115,0.01008749,0,0,0,0,0,3.266792,12.82107,0.3864115,0,13.72075,-3.266925,8794.169
19.8,-3.300392,-0.3892302,0.01016108,0,0,0,0,0,3.300258,12.95242,0.3892303,0,13.87153,-3.300392,8844.974
20,-3.333458,-0.3916214,0.0102235,0,0,0,0,0,3.333325,13.08219,0.3916214,0,14.02073,-3.333458,8886.044
20.2,-3.366658,-0.3941742,0.01029014,0,0,0,0,0,3.366525,13.21249,0.3941742,0,14.17075,-3.366658,8930.558
20.4,-3.400125,-0.396467,0.01035,0,0,0,0,0,3.399992,13.34384,0.396467,0,14.3222,-3.400125,8968.912
20.6,-3.433592,-0.3989667,0.01041526,0,0,0,0,0,3.433458,13.47518,0.3989668,0,14.47389,-3.433592,9011.781
20.8,-3.466791,-0.4012646,0.01047524,0,0,0,0,0,3.466658,13.60548,0.4012646,0,14.62459,-3.466791,9050.036
21,-3.499991,-0.4035148,0.01053399,0,0,0,0,0,3.499858,13.73578,0.4035148,0,14.77553,-3.499991,9087.061
21.2,-3.533591,-0.4061161,0.01060189,0,0,0,0,0,3.533458,13.86765,0.4061161,0,14.92851,-3.533591,9131.661
21.4,-3.567058,-0.4077566,0.01064472,0,0,0,0,0,3.566925,13.99899,0.4077566,0,15.08112,-3.567058,9154.566
21.6,-3.599991,-0.4096873,0.01069512,0,0,0,0,0,3.599858,14.12824,0.4096873,0,15.23152,-3.599991,9184.09
21.8,-3.633325,-0.4118069,0.01075045,0,0,0,0,0,3.633191,14.25907,0.4118069,0,15.38398,-3.633325,9217.54
22,-3.666791,-0.4137633,0.01080153,0,0,0,0,0,3.666658,14.39041,0.4137633,0,15.53729,-3.666791,9247.144
22.2,-3.699991,-0.4150801,0.0108359,0,0,0,0,0,3.699857,14.52071,0.4150801,0,15.68961,-3.699991,9262.454
22.4,-3.733324,-0.4166467,0.0108768,0,0,0,0,0,3.733191,14.65153,0.4166467,0,15.84277,-3.733324,9283.183
22.6,-3.766658,-0.4186587,0.01092933,0,0,0,0,0,3.766524,14.78235,0.4186587,0,15.99617,-3.766658,9313.715
22.8,-3.800257,-0.420713,0.01098295,0,0,0,0,0,3.800124,14.91422,0.420713,0,16.15103,-3.800257,9344.932
23,-3.833724,-0.4221633,0.01102082,0,0,0,0,0,3.833591,15.04557,0.4221633,0,16.30552,-3.833724,9362.672
23.2,-3.866924,-0.4241428,0.01107249,0,0,0,0,0,3.866791,15.17587,0.4241428,0,16.45901,-3.866924,9392.144
23.4,-3.89999,-0.4256597,0.01111209,0,0,0,0,0,3.899857,15.30564,0.4256597,0,16.61212,-3.89999,9411.314
23.6,-3.93359,-0.4271973,0.01115223,0,0,0,0,0,3.933457,15.43751,0.4271973,0,16.76794,-3.93359,9430.603
23.8,-3.966924,-0.4291216,0.01120247,0,0,0,0,0,3.966791,15.56833,0.4291216,0,16.92277,-3.966924,9458.429
24,-3.99999,-0.4305205,0.01123898,0,0,0,0,0,3.999857,15.69811,0.4305205,0,17.07659,-3.99999,9474.676
24.2,-4.033323,-0.4315242,0.01126519,0,0,0,0,0,4.03319,15.82893,0.4315242,0,17.23189,-4.033323,9482.029
24.4,-4.06679,-0.432803,0.01129857,0,0,0,0,0,4.066657,15.96027,0.432803,0,17.38806,-4.06679,9495.288
24.6,-4.100523,-0.4340391,0.01133084,0,0,0,0,0,4.10039,16.09267,0.4340391,0,17.54572,-4.100523,9507.405
24.8,-4.133457,-0.4347002,0.0113481,0,0,0,0,0,4.133324,16.22192,0.4347002,0,17.69988,-4.133457,9507.218
25,-4.166657,-0.4355606,0.01137056,0,0,0,0,0,4.166523,16.35222,0.4355606,0,17.85553,-4.166657,9511.22
25.2,-4.200123,-0.4371099,0.011411,0,0,0,0,0,4.19999,16.48356,0.4371099,0,18.01267,-4.200123,9530.064
25.4,-4.233323,-0.4378562,0.01143049,0,0,0,0,0,4.23319,16.61386,0.4378562,0,18.16881,-4.233323,9531.442
25.6,-4.266656,-0.4385271,0.011448,0,0,0,0,0,4.266523,16.74468,0.4385271,0,18.32582,-4.266656,9531.071
25.8,-4.300123,-0.4394467,0.01147201,0,0,0,0,0,4.29999,16.87603,0.4394467,0,18.48371,-4.300123,9535.988
26,-4.33359,-0.4398894,0.01148356,0,0,0,0,0,4.333456,17.00737,0.4398894,0,18.64184,-4.33359,9530.512
26.2,-4.367056,-0.4405321,0.01150034,0,0,0,0,0,4.366923,17.13872,0.4405321,0,18.80023,-4.367056,9529.332
26.4,-4.400256,-0.4409581,0.01151146,0,0,0,0,0,4.400123,17.26902,0.4409581,0,18.9576,-4.400256,9523.547
26.6,-4.433323,-0.4410501,0.01151387,0,0,0,0,0,4.433189,17.39879,0.4410501,0,19.11459,-4.433323,9510.592
26.8,-4.466789,-0.4414173,0.01152345,0,0,0,0,0,4.466656,17.53014,0.4414173,0,19.27373,-4.466789,9503.375
27,-4.500256,-0.4415192,0.01152611,0,0,0,0,0,4.500123,17.66148,0.4415193,0,19.43312,-4.500256,9490.43
27.2,-4.533456,-0.4415221,0.01152619,0,0,0,0,0,4.533322,17.79178,0.4415221,0,19.59149,-4.533456,9475.474
27.4,-4.566655,-0.441703,0.01153091,0,0,0,0,0,4.566522,17.92208,0.441703,0,19.75012,-4.566655,9464.331
27.6,-4.600389,-0.4420805,0.01154076,0,0,0,0,0,4.600255,18.05447,0.4420805,0,19.91154,-4.600389,9457.14
27.8,-4.633722,-0.4422087,0.01154411,0,0,0,0,0,4.633588,18.18529,0.4422087,0,20.07132,-4.633722,9444.781
28,-4.666655,-0.4423736,0.01154842,0,0,0,0,0,4.666522,18.31455,0.4423736,0,20.22943,-4.666655,9433.376
28.2,-4.699989,-0.4425197,0.01155223,0,0,0,0,0,4.699856,18.44537,0.4425197,0,20.38971,-4.699989,9421.378
28.4,-4.733589,-0.4427925,0.01155935,0,0,0,0,0,4.733455,18.57724,0.4427925,0,20.55153,-4.733589,9411.945
28.6,-4.766788,-0.4427502,0.01155825,0,0,0,0,0,4.766654,18.70753,0.4427502,0,20.71168,-4.766788,9395.984
28.8,-4.800122,-0.4426117,0.01155463,0,0,0,0,0,4.799989,18.83836,0.4426117,0,20.87274,-4.800122,9377.929
29,-4.833455,-0.4424612,0.0115507,0,0,0,0,0,4.833322,18.96918,0.4424612,0,21.03406,-4.833455,9359.629
29.2,-4.866921,-0.4423755,0.01154847,0,0,0,0,0,4.866788,19.10052,0.4423755,0,21.19628,-4.866921,9342.648
29.4,-4.900388,-0.4422588,0.01154542,0,0,0,0,0,4.900254,19.23187,0.4422587,0,21.35877,-4.900388,9325.019
29.6,-4.933721,-0.4419388,0.01153706,0,0,0,0,0,4.933588,19.36269,0.4419388,0,21.52088,-4.933721,9303.178
29.8,-4.966788,-0.4415906,0.01152798,0,0,0,0,0,4.966655,19.49247,0.4415906,0,21.68194,-4.966788,9280.889
30,-4.999988,-0.441086,0.0115148,0,0,0,0,0,4.999854,19.62276,0.441086,0,21.84392,-4.999988,9255.281
30.2,-5.033721,-0.4404808,0.011499,0,0,0,0,0,5.033587,19.75516,0.4404808,0,22.00877,-5.033721,9227.358
30.4,-5.066788,-0.4402325,0.01149252,0,0,0,0,0,5.066655,19.88493,0.4402325,0,22.17063,-5.066788,9207.242
30.6,-5.099988,-0.4399159,0.01148426,0,0,0,0,0,5.099854,20.01523,0.4399159,0,22.3334,-5.099988,9185.656
30.8,-5.133587,-0.4400264,0.01148714,0,0,0,0,0,5.133454,20.1471,0.4400264,0,22.4984,-5.133587,9172.815
31,-5.167188,-0.4399426,0.01148495,0,0,0,0,0,5.167054,20.27897,0.4399426,0,22.66367,-5.167188,9155.923
31.2,-5.200121,-0.4399082,0.01148406,0,0,0,0,0,5.199987,20.40822,0.4399082,0,22.82594,-5.200121,9140.364
31.4,-5.23332,-0.4398638,0.0114829,0,0,0,0,0,5.233187,20.53852,0.4398638,0,22.98978,-5.23332,9124.479
31.6,-5.266921,-0.4399816,0.01148597,0,0,0,0,0,5.266787,20.67039,0.4399816,0,23.15587,-5.266921,9111.777
31.8,-5.30012,-0.4398704,0.01148307,0,0,0,0,0,5.299987,20.80069,0.4398704,0,23.32025,-5.30012,9094.513
32,-5.33332,-0.4398016,0.01148127,0,0,0,0,0,5.333187,20.93098,0.4398015,0,23.48491,-5.33332,9078.128
32.2,-5.366654,-0.4398233,0.01148184,0,0,0,0,0,5.36652,21.06181,0.4398233,0,23.6505,-5.366654,9063.556
32.4,-5.400253,-0.4400406,0.01148751,0,0,0,0,0,5.40012,21.19367,0.4400406,0,23.81769,-5.400253,9052.887
32.6,-5.433587,-0.4398871,0.01148351,0,0,0,0,0,5.433453,21.3245,0.4398871,0,23.98383,-5.433587,9034.706
32.8,-5.46692,-0.4397615,0.01148023,0,0,0,0,0,5.466787,21.45532,0.4397615,0,24.15025,-5.46692,9017.107
33,-5.499986,-0.4400928,0.01148888,0,0,0,0,0,5.499853,21.58509,0.4400928,0,24.31562,-5.499986,9008.991
33.2,-5.533453,-0.4393347,0.01146908,0,0,0,0,0,5.533319,21.71644,0.4393347,0,24.48325,-5.533453,8978.407
33.4,-5.56692,-0.4399696,0.01148566,0,0,0,0,0,5.566786,21.84778,0.4399696,0,24.65118,-5.56692,8976.297
33.6,-5.600119,-0.439964,0.01148551,0,0,0,0,0,5.599986,21.97808,0.439964,0,24.81804,-5.600119,8961.216
33.8,-5.633453,-0.4400271,0.01148716,0,0,0,0,0,5.63332,22.10891,0.4400271,0,24.98586,-5.633453,8947.474
34,-5.667053,-0.44055,0.01150081,0,0,0,0,0,5.66692,22.24077,0.44055,0,25.1553,-5.667053,8942.942
34.2,-5.700386,-0.4404331,0.01149776,0,0,0,0,0,5.700253,22.3716,0.4404331,0,25.32368,-5.700386,8925.526
34.4,-5.733453,-0.4405568,0.01150099,0,0,0,0,0,5.73332,22.50137,0.4405568,0,25.491,-5.733453,8913.108
34.6,-5.766653,-0.4409726,0.01151184,0,0,0,0,0,5.76652,22.63167,0.4409726,0,25.65927,-5.766653,8906.52
34.8,-5.800119,-0.4413673,0.01152215,0,0,0,0,0,5.799985,22.76301,0.4413673,0,25.82917,-5.800119,8899.359
35,-5.833319,-0.4416247,0.01152887,0,0,0,0,0,5.833185,22.89331,0.4416247,0,25.99802,-5.833319,8889.526
35.2,-5.866652,-0.4420145,0.01153904,0,0,0,0,0,5.866519,23.02414,0.4420145,0,26.16783,-5.866652,8882.277
35.4,-5.900119,-0.442289,0.01154621,0,0,0,0,0,5.899986,23.15548,0.442289,0,26.3386,-5.900119,8872.628
35.6,-5.933586,-0.4428578,0.01156106,0,0,0,0,0,5.933452,23.28683,0.4428578,0,26.50967,-5.933586,8868.854
35.8,-5.966919,-0.4432543,0.01157141,0,0,0,0,0,5.966785,23.41765,0.4432543,0,26.68035,-5.966919,8861.657
36,-6.000252,-0.4435703,0.01157966,0,0,0,0,0,6.000119,23.54847,0.4435703,0,26.85132,-6.000252,8852.824
36.2,-6.033319,-0.4439007,0.01158828,0,0,0,0,0,6.033185,23.67825,0.4439007,0,27.02122,-6.033319,8844.38
36.4,-6.066785,-0.4442765,0.01159809,0,0,0,0,0,6.066651,23.80959,0.4442765,0,27.19346,-6.066785,8836.634
36.6,-6.100385,-0.4445678,0.0116057,0,0,0,0,0,6.100251,23.94146,0.4445678,0,27.36668,-6.100385,8827.124
36.8,-6.133452,-0.4446901,0.01160889,0,0,0,0,0,6.133318,24.07123,0.4446901,0,27.53746,-6.133452,8814.486
37,-6.166785,-0.4448909,0.01161413,0,0,0,0,0,6.166652,24.20206,0.4448909,0,27.7099,-6.166785,8803.273
37.2,-6.200385,-0.4452921,0.01162461,0,0,0,0,0,6.200252,24.33393,0.4452921,0,27.88403,-6.200385,8795.883
37.4,-6.233718,-0.445646,0.01163384,0,0,0,0,0,6.233584,24.46475,0.445646,0,28.05707,-6.233718,8787.654
37.6,-6.266651,-0.4456446,0.01163381,0,0,0,0,0,6.266518,24.594,0.4456446,0,28.22833,-6.266651,8772.588
37.8,-6.299985,-0.4456405,0.0116337,0,0,0,0,0,6.299851,24.72482,0.4456404,0,28.40197,-6.299985,8757.288
38,-6.333318,-0.4455851,0.01163226,0,0,0,0,0,6.333184,24.85564,0.4455851,0,28.57591,-6.333318,8740.983
38.2,-6.366651,-0.4456793,0.01163471,0,0,0,0,0,6.366518,24.98646,0.4456793,0,28.75016,-6.366651,8727.61
38.4,-6.399984,-0.4457909,0.01163763,0,0,0,0,0,6.399851,25.11729,0.4457909,0,28.92471,-6.399984,8714.571
38.6,-6.433451,-0.4459362,0.01164142,0,0,0,0,0,6.433318,25.24863,0.4459362,0,29.10027,-6.433451,8702.121
38.8,-6.466918,-0.4462196,0.01164882,0,0,0,0,0,6.466784,25.37998,0.4462196,0,29.27613,-6.466918,8692.35
39,-6.500251,-0.4464462,0.01165473,0,0,0,0,0,6.500117,25.5108,0.4464462,0,29.4516,-6.500251,8681.518
39.2,-6.533584,-0.4467216,0.01166192,0,0,0,0,0,6.533451,25.64162,0.4467216,0,29.62738,-6.533584,8671.617
39.4,-6.566651,-0.4469265,0.01166727,0,0,0,0,0,6.566517,25.7714,0.4469265,0,29.80206,-6.566651,8660.453
39.6,-6.600117,-0.447265,0.01167611,0,0,0,0,0,6.599984,25.90274,0.447265,0,29.97916,-6.600117,8651.678
39.8,-6.633584,-0.4474724,0.01168152,0,0,0,0,0,6.633451,26.03409,0.4474724,0,30.15658,-6.633584,8640.346
40,-6.666784,-0.4477622,0.01168909,0,0,0,0,0,6.66665,26.16438,0.4477622,0,30.3329,-6.666784,8630.71
40.2,-6.699983,-0.4477264,0.01168815,0,0,0,0,0,6.69985,26.29468,0.4477264,0,30.50953,-6.699983,8614.791
40.4,-6.733584,-0.4477843,0.01168967,0,0,0,0,0,6.73345,26.42655,0.4477843,0,30.6886,-6.733584,8600.49
40.6,-6.767184,-0.4480861,0.01169754,0,0,0,0,0,6.76705,26.55842,0.4480861,0,30.86799,-6.767184,8590.861
40.8,-6.800117,-0.4479837,0.01169487,0,0,0,0,0,6.799984,26.68767,0.4479837,0,31.04414,-6.800117,8573.783
41,-6.833317,-0.4480231,0.0116959,0,0,0,0,0,6.833184,26.81797,0.4480231,0,31.22203,-6.833317,8559.296
41.2,-6.866783,-0.4482693,0.01170233,0,0,0,0,0,6.86665,26.94932,0.4482693,0,31.40167,-6.866783,8548.63
41.4,-6.899983,-0.448389,0.01170545,0,0,0,0,0,6.899849,27.07961,0.4483891,0,31.58019,-6.899983,8535.662
41.6,-6.933317,-0.4482526,0.01170189,0,0,0,0,0,6.933183,27.21044,0.4482526,0,31.75976,-6.933317,8517.755
41.8,-6.96665,-0.4486242,0.01171159,0,0,0,0,0,6.966516,27.34126,0.4486242,0,31.93965,-6.96665,8509.495
42,-7.000249,-0.4490283,0.01172214,0,0,0,0,0,7.000116,27.47313,0.4490283,0,32.1213,-7.000249,8501.702
42.2,-7.033716,-0.4493167,0.01172967,0,0,0,0,0,7.033582,27.60447,0.4493167,0,32.30256,-7.033716,8491.757
42.4,-7.066916,-0.4496009,0.01173709,0,0,0,0,0,7.066783,27.73477,0.4496009,0,32.48271,-7.066916,8481.834
42.6,-7.100116,-0.4499397,0.01174593,0,0,0,0,0,7.099983,27.86507,0.4499397,0,32.66318,-7.100116,8472.92
42.8,-7.133449,-0.4503163,0.01175577,0,0,0,0,0,7.133316,27.99589,0.4503163,0,32.8447,-7.133449,8464.634
43,-7.166916,-0.4506962,0.01176568,0,0,0,0,0,7.166782,28.12724,0.4506962,0,33.02728,-7.166916,8456.322
43.2,-7.200249,-0.4512402,0.01177988,0,0,0,0,0,7.200116,28.25806,0.4512402,0,33.20947,-7.200249,8451.117
43.4,-7.233449,-0.4512507,0.01178016,0,0,0,0,0,7.233315,28.38836,0.4512507,0,33.39125,-7.233449,8435.966
43.6,-7.267049,-0.451666,0.011791,0,0,0,0,0,7.266916,28.52023,0.451666,0,33.57557,-7.267049,8428.179
43.8,-7.300382,-0.4519488,0.01179838,0,0,0,0,0,7.300248,28.65105,0.4519488,0,33.75875,-7.300382,8418.022
44,-7.333449,-0.4521786,0.01180438,0,0,0,0,0,7.333315,28.78082,0.4521786,0,33.94081,-7.333449,8406.984
44.2,-7.366515,-0.4525802,0.01181487,0,0,0,0,0,7.366382,28.9106,0.4525802,0,34.12319,-7.366515,8399.118
44.4,-7.400249,-0.4529286,0.01182396,0,0,0,0,0,7.400115,29.04299,0.4529286,0,34.3096,-7.400249,8389.929
44.6,-7.433448,-0.4533079,0.01183386,0,0,0,0,0,7.433315,29.17329,0.4533079,0,34.4934,-7.433448,8381.535
44.8,-7.466648,-0.4536256,0.01184216,0,0,0,0,0,7.466515,29.30359,0.4536256,0,34.67754,-7.466648,8371.979
45,-7.500115,-0.4539171,0.01184976,0,0,0,0,0,7.499982,29.43493,0.4539171,0,34.8635,-7.500115,8361.795
45.2,-7.533448,-0.4542034,0.01185724,0,0,0,0,0,7.533315,29.56576,0.4542034,0,35.04906,-7.533448,8351.557
45.4,-7.566915,-0.4544216,0.01186294,0,0,0,0,0,7.566781,29.6971,0.4544216,0,35.23571,-7.566915,8339.989
45.6,-7.600248,-0.4547596,0.01187176,0,0,0,0,0,7.600115,29.82792,0.4547596,0,35.42197,-7.600248,8330.661
45.8,-7.633314,-0.4549793,0.0118775,0,0,0,0,0,7.633181,29.9577,0.4549793,0,35.60708,-7.633314,8319.271
46,-7.666781,-0.455531,0.0118919,0,0,0,0,0,7.666648,30.08904,0.455531,0,35.79478,-7.666781,8313.74
46.2,-7.700248,-0.4559646,0.01190322,0,0,0,0,0,7.700114,30.22039,0.4559646,0,35.98283,-7.700248,8306.019
46.4,-7.733448,-0.4563998,0.01191458,0,0,0,0,0,7.733315,30.35069,0.4563998,0,36.16974,-7.733448,8298.421
46.6,-7.766781,-0.4568465,0.01192624,0,0,0,0,0,7.766648,30.48151,0.4568465,0,36.35774,-7.766781,8290.942
46.8,-7.800248,-0.4572024,0.01193553,0,0,0,0,0,7.800114,30.61285,0.4572024,0,36.54685,-7.800248,8281.725
47,-7.833715,-0.4576644,0.01194759,0,0,0,0,0,7.833581,30.7442,0.4576644,0,36.73633,-7.833715,8274.4
47.2,-7.866648,-0.4578456,0.01195232,0,0,0,0,0,7.866515,30.87345,0.4578456,0,36.92314,-7.866648,8262.227
47.4,-7.899981,-0.4579748,0.0119557,0,0,0,0,0,7.899848,31.00427,0.4579749,0,37.11256,-7.899981,8248.919
47.6,-7.933581,-0.458413,0.01196713,0,0,0,0,0,7.933448,31.13614,0.458413,0,37.30387,-7.933581,8241.03
47.8,-7.966648,-0.4584646,0.01196848,0,0,0,0,0,7.966515,31.26592,0.4584646,0,37.4925,-7.966648,8226.426
48,-7.999981,-0.4583317,0.01196501,0,0,0,0,0,7.999847,31.39674,0.4583317,0,37.68301,-7.999981,8208.389
48.2,-8.033314,-0.458398,0.01196674,0,0,0,0,0,8.03318,31.52756,0.458398,0,37.87389,-8.033314,8193.92
48.4,-8.067047,-0.4586005,0.01197203,0,0,0,0,0,8.066914,31.65995,0.4586005,0,38.06743,-8.067047,8181.69
48.6,-8.10038,-0.4584623,0.01196842,0,0,0,0,0,8.100247,31.79077,0.4584623,0,38.25904,-8.10038,8163.567
48.8,-8.13358,-0.4583655,0.0119659,0,0,0,0,0,8.133447,31.92107,0.4583655,0,38.45025,-8.13358,8146.253
49,-8.166647,-0.4582772,0.01196359,0,0,0,0,0,8.166512,32.05085,0.4582772,0,38.64105,-8.166647,8129.158
49.2,-8.200114,-0.4579956,0.01195624,0,0,0,0,0,8.199981,32.18219,0.4579956,0,38.83454,-8.200114,8108.458
49.4,-8.23358,-0.4580253,0.01195701,0,0,0,0,0,8.233447,32.31354,0.4580252,0,39.0284,-8.23358,8093.278
49.6,-8.26678,-0.4578316,0.01195196,0,0,0,0,0,8.266646,32.44384,0.4578316,0,39.22109,-8.26678,8074.282
49.8,-8.29998,-0.4578337,0.01195201,0,0,0,0,0,8.299848,32.57414,0.4578337,0,39.41415,-8.29998,8058.747
50,-8.333713,-0.4581367,0.01195992,0,0,0,0,0,8.33358,32.70653,0.4581367,0,39.61069,-8.333713,8048.247
50.2,-8.36718,-0.458428,0.01196752,0,0,0,0,0,8.367046,32.83788,0.458428,0,39.80607,-8.36718,8037.644
50.4,-8.400113,-0.4584777,0.01196882,0,0,0,0,0,8.399981,32.96713,0.4584777,0,39.99871,-8.400113,8023.047
50.6,-8.433313,-0.4587499,0.01197593,0,0,0,0,0,8.433179,33.09742,0.4587499,0,40.19327,-8.433313,8012.205
50.8,-8.466779,-0.4594751,0.01199486,0,0,0,0,0,8.466646,33.22877,0.4594751,0,40.38979,-8.466779,8009.116
51,-8.499979,-0.4599881,0.01200825,0,0,0,0,0,8.499846,33.35907,0.4599881,0,40.58512,-8.499979,8002.412
51.2,-8.533313,-0.4606287,0.01202498,0,0,0,0,0,8.53318,33.48989,0.4606287,0,40.78162,-8.533313,7997.824
51.4,-8.566779,-0.4611447,0.01203845,0,0,0,0,0,8.566646,33.62123,0.4611447,0,40.9793,-8.566779,7990.972
51.6,-8.600246,-0.4620041,0.01206088,0,0,0,0,0,8.600113,33.75258,0.4620041,0,41.17737,-8.600246,7990.023
51.8,-8.633712,-0.4625393,0.01207485,0,0,0,0,0,8.633579,33.88393,0.4625393,0,41.37583,-8.633712,7983.418
52,-8.666912,-0.4627205,0.01207958,0,0,0,0,0,8.666779,34.01423,0.4627205,0,41.5731,-8.666912,7970.807
52.2,-8.699846,-0.4632925,0.01209452,0,0,0,0,0,8.699712,34.14347,0.4632925,0,41.76916,-8.699846,7965.028
52.4,-8.733446,-0.4640226,0.01211358,0,0,0,0,0,8.733313,34.27534,0.4640226,0,41.96961,-8.733446,7961.606
52.6,-8.767045,-0.463838,0.01210876,0,0,0,0,0,8.766912,34.40721,0.463838,0,42.17044,-8.767045,7942.471
52.8,-8.799979,-0.4639706,0.01211222,0,0,0,0,0,8.799846,34.53646,0.4639706,0,42.36769,-8.799979,7929.087
53,-8.833446,-0.4647881,0.01213356,0,0,0,0,0,8.833312,34.66781,0.4647881,0,42.56854,-8.833446,7927.12
53.2,-8.867045,-0.4645456,0.01212723,0,0,0,0,0,8.866912,34.79968,0.4645456,0,42.77058,-8.867045,7906.993
53.4,-8.900379,-0.4653356,0.01214785,0,0,0,0,0,8.900246,34.9305,0.4653356,0,42.97143,-8.900379,7904.547
53.6,-8.933445,-0.4656932,0.01215719,0,0,0,0,0,8.933312,35.06028,0.4656932,0,43.17107,-8.933445,7894.844
53.8,-8.966645,-0.4662004,0.01217043,0,0,0,0,0,8.966511,35.19057,0.4662004,0,43.37191,-8.966645,7887.585
54,-9.000111,-0.4672119,0.01219684,0,0,0,0,0,8.999978,35.32192,0.4672119,0,43.57478,-9.000111,7888.679
54.2,-9.033178,-0.4673632,0.01220078,0,0,0,0,0,9.033045,35.45169,0.4673632,0,43.77563,-9.033178,7875.399
54.4,-9.066778,-0.4678995,0.01221479,0,0,0,0,0,9.066645,35.58356,0.4678995,0,43.98014,-9.066778,7868.329
54.6,-9.100111,-0.4684482,0.01222911,0,0,0,0,0,9.099978,35.71439,0.4684482,0,44.18343,-9.100111,7861.558
54.8,-9.133711,-0.4688896,0.01224063,0,0,0,0,0,9.133578,35.84626,0.4688896,0,44.38877,-9.133711,7852.823
55,-9.167044,-0.4693873,0.01225362,0,0,0,0,0,9.166911,35.97708,0.4693873,0,44.5929,-9.167044,7845.128
55.2,-9.200377,-0.4695232,0.01225717,0,0,0,0,0,9.200244,36.1079,0.4695233,0,44.79744,-9.200377,7831.366
55.4,-9.233444,-0.4696056,0.01225932,0,0,0,0,0,9.23331,36.23767,0.4696056,0,45.00076,-9.233444,7816.83
55.6,-9.266778,-0.4695636,0.01225823,0,0,0,0,0,9.266644,36.3685,0.4695636,0,45.20615,-9.266778,7800.095
55.8,-9.300244,-0.4697118,0.0122621,0,0,0,0,0,9.300111,36.49984,0.4697118,0,45.41278,-9.300244,7786.45
56,-9.333444,-0.4697857,0.01226402,0,0,0,0,0,9.333311,36.63014,0.4697857,0,45.61818,-9.333444,7771.695
56.2,-9.36651,-0.4694856,0.01225619,0,0,0,0,0,9.366377,36.75991,0.4694856,0,45.82318,-9.36651,7750.825
56.4,-9.400377,-0.4695623,0.01225819,0,0,0,0,0,9.400244,36.89283,0.4695623,0,46.03358,-9.400377,7735.798
56.6,-9.433844,-0.4695167,0.012257,0,0,0,0,0,9.433711,37.02418,0.4695167,0,46.24193,-9.433844,7718.948
56.8,-9.466777,-0.4690463,0.01224472,0,0,0,0,0,9.466643,37.15343,0.4690463,0,46.44738,-9.466777,7695.388
57,-9.500111,-0.4691005,0.01224614,0,0,0,0,0,9.499976,37.28425,0.4691005,0,46.65575,-9.500111,7680.257
57.2,-9.533577,-0.4689528,0.01224228,0,0,0,0,0,9.533442,37.41559,0.4689528,0,46.8654,-9.533577,7661.759
57.4,-9.566776,-0.4687813,0.0122378,0,0,0,0,0,9.566644,37.54589,0.4687813,0,47.07382,-9.566776,7643.012
57.6,-9.599976,-0.468582,0.0122326,0,0,0,0,0,9.599843,37.67619,0.468582,0,47.28267,-9.599976,7623.824
57.8,-9.63331,-0.4684637,0.01222951,0,0,0,0,0,9.633177,37.80701,0.4684637,0,47.4928,-9.63331,7605.899
58,-9.666909,-0.4686922,0.01223548,0,0,0,0,0,9.666777,37.93888,0.4686922,0,47.70505,-9.666909,7593.476
58.2,-9.700377,-0.4685979,0.01223302,0,0,0,0,0,9.700243,38.07023,0.4685979,0,47.91692,-9.700377,7575.879
58.4,-9.733576,-0.4685339,0.01223135,0,0,0,0,0,9.733443,38.20053,0.4685339,0,48.12753,-9.733576,7558.908
58.6,-9.766643,-0.4683969,0.01222777,0,0,0,0,0,9.766509,38.3303,0.4683969,0,48.33774,-9.766643,7540.829
58.8,-9.800109,-0.468095,0.01221989,0,0,0,0,0,9.799975,38.46164,0.468095,0,48.55095,-9.800109,7519.919
59,-9.833576,-0.4677195,0.01221008,0,0,0,0,0,9.833443,38.59299,0.4677195,0,48.76462,-9.833576,7497.848
59.2,-9.866776,-0.4675058,0.01220451,0,0,0,0,0,9.866643,38.72329,0.4675058,0,48.97704,-9.866776,7478.52
59.4,-9.900109,-0.4669416,0.01218978,0,0,0,0,0,9.899976,38.85411,0.4669416,0,49.19076,-9.900109,7453.549
59.6,-9.933576,-0.4666264,0.01218155,0,0,0,0,0,9.933443,38.98546,0.4666263,0,49.4058,-9.933576,7432.516
59.8,-9.967042,-0.4664266,0.01217633,0,0,0,0,0,9.966909,39.1168,0.4664266,0,49.62129,-9.967042,7413.342
60,-9.999976,-0.4660827,0.01216736,0,0,0,0,0,9.999843,39.24606,0.4660827,0,49.83382,-9.999976,7392.149
60.2,-10.03318,-0.4657284,0.01215811,0,0,0,0,0,10.03304,39.37635,0.4657284,0,50.04851,-10.03318,7370.689
60.4,-10.06691,-0.4658555,0.01216143,0,0,0,0,0,10.06677,39.50874,0.4658555,0,50.26713,-10.06691,7356.599
60.6,-10.10024,-0.465506,0.0121523,0,0,0,0,0,10.10011,39.63956,0.465506,0,50.48364,-10.10024,7335.182
60.8,-10.13331,-0.4649007,0.0121365,0,0,0,0,0,10.13317,39.76934,0.4649007,0,50.69887,-10.13331,7309.893
61,-10.16678,-0.4644786,0.01212548,0,0,0,0,0,10.16664,39.90069,0.4644786,0,50.91718,-10.16678,7287.33
61.2,-10.20024,-0.4644311,0.01212424,0,0,0,0,0,10.20011,40.03203,0.464431,0,51.13596,-10.20024,7270.66
61.4,-10.23358,-0.4641637,0.01211726,0,0,0,0,0,10.23344,40.16286,0.4641637,0,51.35436,-10.23358,7250.622
61.6,-10.26691,-0.4637651,0.01210685,0,0,0,0,0,10.26678,40.29368,0.4637651,0,51.57323,-10.26691,7228.557
61.8,-10.30011,-0.4633706,0.01209656,0,0,0,0,0,10.29997,40.42397,0.4633706,0,51.79169,-10.30011,7206.648
62,-10.33331,-0.4628019,0.01208171,0,0,0,0,0,10.33317,40.55427,0.4628018,0,52.01064,-10.33331,7182.059
62.2,-10.36678,-0.4620367,0.01206173,0,0,0,0,0,10.36664,40.68562,0.4620367,0,52.23184,-10.36678,7154.341
62.4,-10.40024,-0.4614505,0.01204643,0,0,0,0,0,10.40011,40.81696,0.4614505,0,52.45352,-10.40024,7129.442
62.6,-10.43331,-0.4606534,0.01202562,0,0,0,0,0,10.43318,40.94674,0.4606534,0,52.67304,-10.43331,7101.522
62.8,-10.46704,-0.4605274,0.01202233,0,0,0,0,0,10.46691,41.07913,0.4605274,0,52.89749,-10.46704,7083.662
63,-10.50037,-0.4603512,0.01201773,0,0,0,0,0,10.50024,41.20995,0.4603512,0,53.11976,-10.50037,7065.231
63.2,-10.53331,-0.4599257,0.01200662,0,0,0,0,0,10.53317,41.33921,0.4599257,0,53.33986,-10.53331,7043.181
63.4,-10.56677,-0.4597769,0.01200274,0,0,0,0,0,10.56664,41.47055,0.4597769,0,53.56401,-10.56677,7025.138
63.6,-10.60011,-0.4598886,0.01200566,0,0,0,0,0,10.59997,41.60137,0.4598886,0,53.78778,-10.60011,7011.139
63.8,-10.63344,-0.4598674,0.0120051,0,0,0,0,0,10.63331,41.73219,0.4598674,0,54.01205,-10.63344,6995.11
64,-10.66677,-0.4598722,0.01200523,0,0,0,0,0,10.66664,41.86301,0.4598722,0,54.23682,-10.66677,6979.477
64.2,-10.69997,-0.4599326,0.0120068,0,0,0,0,0,10.69984,41.99332,0.4599326,0,54.4612,-10.69997,6964.748
64.4,-10.73357,-0.4601513,0.01201251,0,0,0,0,0,10.73344,42.12518,0.4601513,0,54.68878,-10.73357,6952.22
64.60001,-10.76704,-0.4601283,0.01201191,0,0,0,0,0,10.76691,42.25653,0.4601283,0,54.91599,-10.76704,6936.095
64.8,-10.80024,-0.4598892,0.01200567,0,0,0,0,0,10.80011,42.38683,0.4598892,0,55.1419,-10.80024,6916.848
65,-10.83317,-0.4599304,0.01200675,0,0,0,0,0,10.83304,42.51608,0.4599304,0,55.36649,-10.83317,6901.949
65.2,-10.86677,-0.4601119,0.01201148,0,0,0,0,0,10.86664,42.64795,0.4601119,0,55.59615,-10.86677,6888.833
65.4,-10.90024,-0.4602498,0.01201509,0,0,0,0,0,10.90011,42.77929,0.4602498,0,55.82544,-10.90024,6875.117
65.60001,-10.93344,-0.4602652,0.01201549,0,0,0,0,0,10.93331,42.90959,0.4602652,0,56.05341,-10.93344,6859.691
65.8,-10.96677,-0.4604133,0.01201935,0,0,0,0,0,10.96664,43.04041,0.4604133,0,56.28282,-10.96677,6846.173
66,-11.00024,-0.4602245,0.01201442,0,0,0,0,0,11.00011,43.17176,0.4602245,0,56.51368,-11.00024,6827.586
66.20001,-11.03371,-0.4604279,0.01201973,0,0,0,0,0,11.03357,43.3031,0.4604279,0,56.74507,-11.03371,6814.816
66.4,-11.06677,-0.4606871,0.0120265,0,0,0,0,0,11.06664,43.43288,0.4606871,0,56.97423,-11.06677,6803.046
66.60001,-11.10011,-0.4605428,0.01202273,0,0,0,0,0,11.09997,43.5637,0.4605428,0,57.20576,-11.10011,6785.185
66.8,-11.13344,-0.4605096,0.01202187,0,0,0,0,0,11.13331,43.69452,0.4605096,0,57.43783,-11.13344,6768.97
67,-11.16651,-0.4605537,0.01202302,0,0,0,0,0,11.16637,43.8243,0.4605537,0,57.66859,-11.16651,6754.014
67.20001,-11.19997,-0.4604488,0.01202028,0,0,0,0,0,11.19984,43.95564,0.4604488,0,57.90267,-11.19997,6736.688
67.4,-11.23344,-0.4603012,0.01201643,0,0,0,0,0,11.23331,44.08699,0.4603012,0,58.13731,-11.23344,6718.746
67.60001,-11.26704,-0.460541,0.01202269,0,0,0,0,0,11.26691,44.21886,0.460541,0,58.37343,-11.26704,6706.392
67.8,-11.30037,-0.4601902,0.01201353,0,0,0,0,0,11.30024,44.34968,0.4601902,0,58.60824,-11.30037,6685.568
68,-11.33357,-0.4601347,0.01201208,0,0,0,0,0,11.33344,44.47998,0.4601347,0,58.84265,-11.33357,6669.109
68.20001,-11.36664,-0.4597412,0.01200181,0,0,0,0,0,11.36651,44.60975,0.4597412,0,59.07666,-11.36664,6647.831
68.4,-11.40024,-0.4592895,0.01199002,0,0,0,0,0,11.4001,44.74162,0.4592896,0,59.31501,-11.40024,6625.489
68.60001,-11.43357,-0.4590156,0.01198286,0,0,0,0,0,11.43344,44.87244,0.4590156,0,59.55205,-11.43357,6605.86
68.8,-11.46677,-0.4587715,0.01197649,0,0,0,0,0,11.46664,45.00274,0.4587715,0,59.78869,-11.46677,6586.742
69,-11.49997,-0.4585932,0.01197184,0,0,0,0,0,11.49984,45.13304,0.4585932,0,60.02589,-11.49997,6568.583
69.20001,-11.53357,-0.4586678,0.01197379,0,0,0,0,0,11.53344,45.26491,0.4586678,0,60.26652,-11.53357,6553.863
69.4,-11.56704,-0.458648,0.01197327,0,0,0,0,0,11.56691,45.39626,0.458648,0,60.50677,-11.56704,6537.853
69.60001,-11.59997,-0.4586582,0.01197353,0,0,0,0,0,11.59984,45.52551,0.4586582,0,60.74376,-11.59997,6522.522
69.8,-11.63317,-0.458605,0.01197215,0,0,0,0,0,11.63304,45.6558,0.458605,0,60.98323,-11.63317,6506.167
70,-11.66677,-0.4588791,0.0119793,0,0,0,0,0,11.66664,45.78767,0.4588791,0,61.22619,-11.66677,6494.259
70.20001,-11.69997,-0.459087,0.01198473,0,0,0,0,0,11.69984,45.91797,0.459087,0,61.46683,-11.69997,6481.585
70.4,-11.73344,-0.4592363,0.01198863,0,0,0,0,0,11.7333,46.04932,0.4592363,0,61.70998,-11.73344,6467.946
[...]
52.2,-8.700112,-0.4668401,0.01209846,0,0,0,0,0,8.699978,33.95776,0.4668401,0,41.48756,-8.700112,7990.091
52.4,-8.733446,-0.4680177,0.01212897,0,0,0,0,0,8.733313,34.08787,0.4680177,0,41.68477,-8.733446,7994.464
52.6,-8.767045,-0.468931,0.01215264,0,0,0,0,0,8.766912,34.21902,0.468931,0,41.88394,-8.767045,7994.128
52.8,-8.800379,-0.4697188,0.01217306,0,0,0,0,0,8.800246,34.34912,0.4697188,0,42.08193,-8.800379,7991.72
53,-8.833311,-0.4696991,0.01217255,0,0,0,0,0,8.833178,34.47766,0.4696991,0,42.27791,-8.833311,7975.737
53.2,-8.866645,-0.4710208,0.0122068,0,0,0,0,0,8.866512,34.60778,0.4710208,0,42.47668,-8.866645,7982.299
53.4,-8.900379,-0.4720363,0.01223312,0,0,0,0,0,8.900246,34.73944,0.4720363,0,42.67824,-8.900379,7983.401
53.6,-8.933579,-0.4723122,0.01224027,0,0,0,0,0,8.933445,34.86903,0.4723122,0,42.877,-8.933579,7972.204
53.8,-8.966645,-0.4744229,0.01229497,0,0,0,0,0,8.966512,34.9981,0.4744229,0,43.07536,-8.966645,7991.963
54,-9.000378,-0.4751927,0.01231492,0,0,0,0,0,9.000244,35.12976,0.4751927,0,43.27812,-9.000378,7988.717
54.2,-9.033845,-0.4772457,0.01236812,0,0,0,0,0,9.033711,35.26039,0.4772457,0,43.47969,-9.033845,8007.074
54.4,-9.066911,-0.4796054,0.01242927,0,0,0,0,0,9.066778,35.38945,0.4796054,0,43.67925,-9.066911,8030.622
54.6,-9.100378,-0.4812783,0.01247263,0,0,0,0,0,9.100245,35.52008,0.4812783,0,43.88163,-9.100378,8042.342
54.8,-9.133578,-0.4833621,0.01252663,0,0,0,0,0,9.133445,35.64967,0.4833621,0,44.08281,-9.133578,8060.93
55,-9.166645,-0.485355,0.01257828,0,0,0,0,0,9.166511,35.77873,0.485355,0,44.28357,-9.166645,8077.931
55.2,-9.200244,-0.486931,0.01261912,0,0,0,0,0,9.200111,35.90988,0.486931,0,44.488,-9.200244,8087.61
55.4,-9.233444,-0.4888182,0.01266803,0,0,0,0,0,9.233311,36.03946,0.4888182,0,44.69039,-9.233444,8102.54
55.6,-9.266778,-0.4894048,0.01268323,0,0,0,0,0,9.266644,36.16957,0.4894048,0,44.89402,-9.266778,8095.762
55.8,-9.300377,-0.4919522,0.01274925,0,0,0,0,0,9.300243,36.30072,0.4919522,0,45.09968,-9.300377,8121.181
56,-9.333711,-0.4943728,0.01281198,0,0,0,0,0,9.333578,36.43083,0.4943728,0,45.30415,-9.333711,8144.472
56.2,-9.366778,-0.4963928,0.01286433,0,0,0,0,0,9.366644,36.55989,0.4963928,0,45.50739,-9.366778,8161.147
56.4,-9.400244,-0.498342,0.01291485,0,0,0,0,0,9.40011,36.69052,0.498342,0,45.71351,-9.400244,8176.322
56.6,-9.433444,-0.5000795,0.01295987,0,0,0,0,0,9.433311,36.8201,0.5000795,0,45.9184,-9.433444,8188.035
56.8,-9.466777,-0.5020909,0.013012,0,0,0,0,0,9.466642,36.95021,0.5020909,0,46.12454,-9.466777,8204.04
57,-9.499977,-0.5039926,0.01306129,0,0,0,0,0,9.499844,37.0798,0.5039926,0,46.33028,-9.499977,8218.188
57.2,-9.53371,-0.5062079,0.0131187,0,0,0,0,0,9.533576,37.21146,0.5062079,0,46.53976,-9.53371,8237.038
57.4,-9.567177,-0.5079041,0.01316265,0,0,0,0,0,9.567043,37.34209,0.5079041,0,46.74803,-9.567177,8247.443
57.6,-9.600377,-0.5095036,0.01320411,0,0,0,0,0,9.600244,37.47168,0.5095036,0,46.95506,-9.600377,8256.306
57.8,-9.633576,-0.5112796,0.01325013,0,0,0,0,0,9.633443,37.60126,0.5112796,0,47.16251,-9.633576,8267.915
58,-9.666909,-0.5125743,0.01328368,0,0,0,0,0,9.666776,37.73137,0.5125743,0,47.37123,-9.666909,8271.57
58.2,-9.70011,-0.5141971,0.01332574,0,0,0,0,0,9.699976,37.86095,0.5141971,0,47.57956,-9.70011,8280.489
58.4,-9.733443,-0.515976,0.01337184,0,0,0,0,0,9.73331,37.99106,0.515976,0,47.78916,-9.733443,8291.737
58.6,-9.766776,-0.5174615,0.01341034,0,0,0,0,0,9.766643,38.12117,0.5174615,0,47.9992,-9.766776,8298.162
58.8,-9.799976,-0.5189024,0.01344768,0,0,0,0,0,9.799843,38.25075,0.5189024,0,48.20884,-9.799976,8303.843
59,-9.833709,-0.5205239,0.0134897,0,0,0,0,0,9.833576,38.38242,0.5205238,0,48.4223,-9.833709,8312.029
59.2,-9.867042,-0.5220708,0.01352979,0,0,0,0,0,9.866908,38.51252,0.5220708,0,48.63366,-9.867042,8319.128
59.4,-9.900109,-0.5237958,0.0135745,0,0,0,0,0,9.899976,38.64159,0.5237958,0,48.8438,-9.900109,8329.096
59.6,-9.933576,-0.525279,0.01361294,0,0,0,0,0,9.933443,38.77222,0.525279,0,49.05692,-9.933576,8334.899
59.8,-9.966909,-0.5270084,0.01365775,0,0,0,0,0,9.966776,38.90232,0.5270084,0,49.26964,-9.966909,8344.57
60,-10.00011,-0.5285827,0.01369855,0,0,0,0,0,9.999975,39.03191,0.5285828,0,49.48196,-10.00011,8351.747
60.2,-10.03331,-0.5299727,0.01373458,0,0,0,0,0,10.03318,39.1615,0.5299727,0,49.69473,-10.03331,8355.91
60.4,-10.06691,-0.5318212,0.01378248,0,0,0,0,0,10.06678,39.29264,0.5318212,0,49.91053,-10.06691,8366.98
60.6,-10.10051,-0.5335697,0.01382779,0,0,0,0,0,10.10038,39.42379,0.5335696,0,50.1268,-10.10051,8376.353
60.8,-10.13371,-0.5352948,0.0138725,0,0,0,0,0,10.13358,39.55338,0.5352948,0,50.34095,-10.13371,8385.459
61,-10.16704,-0.5368641,0.01391317,0,0,0,0,0,10.16691,39.68348,0.5368641,0,50.55642,-10.16704,8391.94
61.2,-10.20024,-0.5384458,0.01395416,0,0,0,0,0,10.20011,39.81307,0.5384458,0,50.7715,-10.20024,8398.581
61.4,-10.23344,-0.5398548,0.01399068,0,0,0,0,0,10.23331,39.94265,0.5398548,0,50.98703,-10.23344,8402.429
61.6,-10.26678,-0.5410036,0.01402045,0,0,0,0,0,10.26664,40.07276,0.5410036,0,51.2039,-10.26678,8402.068
61.8,-10.29998,-0.5421262,0.01404954,0,0,0,0,0,10.29984,40.20235,0.5421262,0,51.42037,-10.29998,8401.297
62,-10.33331,-0.5434528,0.01408392,0,0,0,0,0,10.33317,40.33245,0.5434527,0,51.63819,-10.33331,8403.529
62.2,-10.36704,-0.5446579,0.01411515,0,0,0,0,0,10.36691,40.46412,0.5446579,0,51.85911,-10.36704,8403.58
62.4,-10.40037,-0.5454898,0.01413671,0,0,0,0,0,10.40024,40.59423,0.5454898,0,52.07788,-10.40037,8398.022
62.6,-10.43344,-0.546424,0.01416092,0,0,0,0,0,10.43331,40.72329,0.546424,0,52.29538,-10.43344,8394.128
62.8,-10.46691,-0.5476413,0.01419247,0,0,0,0,0,10.46677,40.85392,0.5476413,0,52.51598,-10.46691,8394.289
63,-10.50037,-0.5486469,0.01421853,0,0,0,0,0,10.50024,40.98455,0.5486469,0,52.73709,-10.50037,8391.129
63.2,-10.53357,-0.5493144,0.01423583,0,0,0,0,0,10.53344,41.11413,0.5493144,0,52.95691,-10.53357,8382.89
63.4,-10.56664,-0.5505432,0.01426767,0,0,0,0,0,10.56651,41.2432,0.5505432,0,53.17633,-10.56664,8383.229
63.6,-10.60024,-0.5511382,0.01428309,0,0,0,0,0,10.60011,41.37435,0.5511382,0,53.39978,-10.60024,8373.556
63.8,-10.63371,-0.5523583,0.01431471,0,0,0,0,0,10.63357,41.50497,0.5523583,0,53.62284,-10.63371,8373.396
64,-10.66704,-0.5532514,0.01433786,0,0,0,0,0,10.66691,41.63508,0.5532514,0,53.84552,-10.66704,8368.279
64.2,-10.70024,-0.5540168,0.01435769,0,0,0,0,0,10.70011,41.76467,0.5540168,0,54.06779,-10.70024,8361.25
64.4,-10.73357,-0.5558679,0.01440567,0,0,0,0,0,10.73344,41.89477,0.5558679,0,54.29145,-10.73357,8370.445
64.60001,-10.76677,-0.556795,0.01442969,0,0,0,0,0,10.76664,42.02436,0.5567949,0,54.51472,-10.76677,8365.706
64.8,-10.80011,-0.5584959,0.01447377,0,0,0,0,0,10.79997,42.15446,0.5584959,0,54.73939,-10.80011,8372.431
65,-10.83357,-0.5594313,0.01449801,0,0,0,0,0,10.83344,42.28509,0.5594313,0,54.96547,-10.83357,8367.515
65.2,-10.86677,-0.5600477,0.01451399,0,0,0,0,0,10.86664,42.41468,0.5600477,0,55.19025,-10.86677,8357.927
65.4,-10.90037,-0.5618711,0.01456124,0,0,0,0,0,10.90024,42.54583,0.5618711,0,55.41825,-10.90037,8366.042
65.60001,-10.93384,-0.5625219,0.01457811,0,0,0,0,0,10.93371,42.67645,0.5625219,0,55.64587,-10.93384,8356.69
65.8,-10.96664,-0.5631953,0.01459556,0,0,0,0,0,10.96651,42.80447,0.5631953,0,55.86945,-10.96664,8348.008
66,-11.00024,-0.5645832,0.01463153,0,0,0,0,0,11.00011,42.93562,0.5645832,0,56.09902,-11.00024,8349.39
66.20001,-11.03371,-0.565511,0.01465557,0,0,0,0,0,11.03357,43.06625,0.565511,0,56.32819,-11.03371,8343.968
66.4,-11.06677,-0.5665884,0.01468349,0,0,0,0,0,11.06664,43.19532,0.5665883,0,56.55514,-11.06677,8340.912
66.60001,-11.10011,-0.5675015,0.01470716,0,0,0,0,0,11.09997,43.32542,0.5675015,0,56.78444,-11.10011,8335.22
66.8,-11.13371,-0.5687206,0.01473875,0,0,0,0,0,11.13357,43.45657,0.5687206,0,57.01612,-11.13371,8333.796
67,-11.16717,-0.569979,0.01477136,0,0,0,0,0,11.16704,43.5872,0.569979,0,57.24741,-11.16717,8332.94
67.20001,-11.20037,-0.5715502,0.01481208,0,0,0,0,0,11.20024,43.71678,0.5715503,0,57.47738,-11.20037,8336.717
67.4,-11.23357,-0.5724591,0.01483564,0,0,0,0,0,11.23344,43.84637,0.5724592,0,57.70788,-11.23357,8330.75
67.60001,-11.26691,-0.5736174,0.01486565,0,0,0,0,0,11.26677,43.97647,0.5736173,0,57.93985,-11.26691,8328.264
67.8,-11.30024,-0.5753272,0.01490997,0,0,0,0,0,11.30011,44.10658,0.5753272,0,58.17235,-11.30024,8333.69
68,-11.33344,-0.5762808,0.01493468,0,0,0,0,0,11.33331,44.23617,0.5762808,0,58.40447,-11.33344,8328.149
68.20001,-11.36664,-0.5769708,0.01495256,0,0,0,0,0,11.36651,44.36575,0.5769708,0,58.63712,-11.36664,8318.744
68.4,-11.39997,-0.5785008,0.01499221,0,0,0,0,0,11.39984,44.49586,0.5785007,0,58.87126,-11.39997,8321.298
68.60001,-11.43357,-0.5795173,0.01501856,0,0,0,0,0,11.43344,44.62701,0.5795173,0,59.10782,-11.43357,8316.224
68.8,-11.46704,-0.5818657,0.01507941,0,0,0,0,0,11.46691,44.75763,0.5818657,0,59.344,-11.46704,8330.226
69,-11.50011,-0.5826166,0.01509888,0,0,0,0,0,11.49997,44.8867,0.5826166,0,59.5779,-11.50011,8321.489
69.20001,-11.53357,-0.5836147,0.01512474,0,0,0,0,0,11.53344,45.01733,0.5836147,0,59.81521,-11.53357,8315.988
69.4,-11.56691,-0.5842742,0.01514183,0,0,0,0,0,11.56677,45.14743,0.5842742,0,60.05212,-11.56691,8305.685
69.60001,-11.60024,-0.5857423,0.01517988,0,0,0,0,0,11.60011,45.27754,0.5857422,0,60.28959,-11.60024,8306.804
69.8,-11.6333,-0.5868754,0.01520924,0,0,0,0,0,11.63317,45.4066,0.5868754,0,60.52572,-11.6333,8303.244
70,-11.66704,-0.5884375,0.01524973,0,0,0,0,0,11.6669,45.53827,0.5884375,0,60.76719,-11.66704,8305.266
70.20001,-11.7005,-0.5900816,0.01529234,0,0,0,0,0,11.70037,45.6689,0.5900816,0,61.00733,-11.7005,8308.494
70.4,-11.73371,-0.591124,0.01531935,0,0,0,0,0,11.73357,45.79848,0.591124,0,61.24613,-11.73371,8303.32
70.60001,-11.7669,-0.5919865,0.0153417,0,0,0,0,0,11.76677,45.92807,0.5919865,0,61.4855,-11.7669,8295.555
70.8,-11.80024,-0.5935742,0.01538285,0,0,0,0,0,11.8001,46.05817,0.5935742,0,61.7264,-11.80024,8297.789
71,-11.83344,-0.5950915,0.01542217,0,0,0,0,0,11.8333,46.18776,0.5950915,0,61.96692,-11.83344,8299.015
71.20001,-11.86677,-0.5960356,0.01544664,0,0,0,0,0,11.86664,46.31787,0.5960356,0,62.209,-11.86677,8292.085
71.4,-11.9001,-0.5974911,0.01548436,0,0,0,0,0,11.89997,46.44798,0.5974911,0,62.45166,-11.9001,8292.187
71.60001,-11.9333,-0.5990715,0.01552531,0,0,0,0,0,11.93317,46.57756,0.5990714,0,62.69393,-11.9333,8294.001
71.8,-11.9669,-0.6000709,0.01555122,0,0,0,0,0,11.96677,46.70871,0.6000709,0,62.93973,-11.9669,8287.443
72,-12.00037,-0.6016268,0.01559154,0,0,0,0,0,12.00024,46.83933,0.6016268,0,63.18514,-12.00037,8288.566
72.20001,-12.0333,-0.6028288,0.01562269,0,0,0,0,0,12.03317,46.96788,0.6028288,0,63.42724,-12.0333,8285.042
72.4,-12.06677,-0.6042079,0.01565843,0,0,0,0,0,12.06664,47.09851,0.6042079,0,63.67386,-12.06677,8283.542
72.60001,-12.10037,-0.6056551,0.01569593,0,0,0,0,0,12.10024,47.22965,0.6056551,0,63.92207,-12.10037,8282.798
72.8,-12.13357,-0.6072311,0.01573678,0,0,0,0,0,12.13344,47.35924,0.6072311,0,64.16794,-12.13357,8283.959
73,-12.16677,-0.6084748,0.01576901,0,0,0,0,0,12.16664,47.48882,0.6084748,0,64.41441,-12.16677,8280.491
73.20001,-12.20024,-0.6099594,0.01580748,0,0,0,0,0,12.2001,47.61945,0.6099594,0,64.66349,-12.20024,8280.046
73.4,-12.2337,-0.6112644,0.0158413,0,0,0,0,0,12.23357,47.75008,0.6112644,0,64.91318,-12.2337,8277.067
73.60001,-12.26704,-0.6126306,0.01587671,0,0,0,0,0,12.2669,47.88018,0.6126307,0,65.1625,-12.26704,8274.911
73.8,-12.3001,-0.6137354,0.01590534,0,0,0,0,0,12.29997,48.00925,0.6137354,0,65.41044,-12.3001,8269.305
74,-12.33344,-0.6149458,0.01593671,0,0,0,0,0,12.3333,48.13936,0.6149458,0,65.661,-12.33344,8264.878
74.20001,-12.3669,-0.6162145,0.01596959,0,0,0,0,0,12.36677,48.26998,0.6162145,0,65.91319,-12.3669,8261.071
74.4,-12.4001,-0.6170377,0.01599092,0,0,0,0,0,12.39997,48.39957,0.6170377,0,66.16402,-12.4001,8251.384
74.60001,-12.43344,-0.6179643,0.01601493,0,0,0,0,0,12.4333,48.52968,0.6179643,0,66.41648,-12.43344,8242.937
74.8,-12.46664,-0.6189305,0.01603997,0,0,0,0,0,12.4665,48.65926,0.6189305,0,66.66857,-12.46664,8235.041
75,-12.50024,-0.6197143,0.01606029,0,0,0,0,0,12.5001,48.79041,0.6197143,0,66.92433,-12.50024,8224.407
75.20001,-12.5337,-0.6207105,0.0160861,0,0,0,0,0,12.53357,48.92104,0.6207106,0,67.17975,-12.5337,8216.615
75.4,-12.56677,-0.6214055,0.01610411,0,0,0,0,0,12.56664,49.0501,0.6214055,0,67.43274,-12.56677,8205.03
75.60001,-12.6001,-0.6222701,0.01612652,0,0,0,0,0,12.59997,49.18021,0.6222702,0,67.68843,-12.6001,8195.465
75.8,-12.63357,-0.6233334,0.01615408,0,0,0,0,0,12.63344,49.31084,0.6233334,0,67.9458,-12.63357,8188.366
76,-12.6669,-0.6245652,0.016186,0,0,0,0,0,12.66677,49.44094,0.6245652,0,68.20281,-12.6669,8183.489
76.20001,-12.69997,-0.6253784,0.01620707,0,0,0,0,0,12.69984,49.57001,0.6253784,0,68.45841,-12.69997,8173.226
76.4,-12.7337,-0.6267207,0.01624186,0,0,0,0,0,12.73357,49.70168,0.6267207,0,68.71984,-12.7337,8169.385
76.60001,-12.76717,-0.6280729,0.01627691,0,0,0,0,0,12.76704,49.8323,0.6280729,0,68.97988,-12.76717,8165.749
76.8,-12.80024,-0.6291437,0.01630465,0,0,0,0,0,12.8001,49.96136,0.6291437,0,69.23747,-12.80024,8158.627
77,-12.8337,-0.6303572,0.0163361,0,0,0,0,0,12.83357,50.092,0.6303572,0,69.49888,-12.8337,8153.023
77.20001,-12.8669,-0.6315107,0.016366,0,0,0,0,0,12.86677,50.22158,0.6315107,0,69.75886,-12.8669,8146.735
77.4,-12.90024,-0.6327511,0.01639814,0,0,0,0,0,12.9001,50.35168,0.6327512,0,70.02058,-12.90024,8141.402
77.60001,-12.93343,-0.6340397,0.01643154,0,0,0,0,0,12.9333,50.48127,0.6340397,0,70.28192,-12.93343,8136.688
77.8,-12.96663,-0.6351918,0.01646139,0,0,0,0,0,12.9665,50.61086,0.6351917,0,70.54396,-12.96663,8130.141
78,-13.0001,-0.6367088,0.01650071,0,0,0,0,0,12.99997,50.74149,0.6367087,0,70.8088,-13.0001,8128.004
78.20001,-13.03357,-0.6380441,0.01653531,0,0,0,0,0,13.03343,50.87211,0.6380441,0,71.07432,-13.03357,8123.451
78.4,-13.0669,-0.6396123,0.01657596,0,0,0,0,0,13.06677,51.00222,0.6396123,0,71.33952,-13.0669,8121.85
78.60001,-13.1001,-0.6409801,0.0166114,0,0,0,0,0,13.09997,51.13181,0.6409801,0,71.60434,-13.1001,8117.693
78.8,-13.13343,-0.6423933,0.01664802,0,0,0,0,0,13.1333,51.26191,0.6423932,0,71.87093,-13.13343,8113.929
79,-13.16703,-0.6438655,0.01668618,0,0,0,0,0,13.1669,51.39306,0.6438655,0,72.14038,-13.16703,8110.642
79.20001,-13.20023,-0.6454881,0.01672823,0,0,0,0,0,13.2001,51.52264,0.6454881,0,72.40734,-13.20023,8109.404
79.4,-13.23343,-0.646803,0.01676231,0,0,0,0,0,13.2333,51.65223,0.646803,0,72.67501,-13.23343,8104.202
79.60001,-13.26703,-0.6482487,0.01679977,0,0,0,0,0,13.2669,51.78338,0.6482487,0,72.94664,-13.26703,8100.283
79.8,-13.3005,-0.6500051,0.01684529,0,0,0,0,0,13.30037,51.914,0.6500051,0,73.21792,-13.3005,8100.226
80,-13.3337,-0.6512245,0.01687689,0,0,0,0,0,13.33357,52.04359,0.6512245,0,73.48776,-13.3337,8093.553
80.20001,-13.3669,-0.6525205,0.01691048,0,0,0,0,0,13.36677,52.17317,0.6525205,0,73.75834,-13.3669,8087.746
80.4,-13.4001,-0.6539088,0.01694646,0,0,0,0,0,13.39997,52.30276,0.6539088,0,74.02966,-13.4001,8082.994
80.60001,-13.43343,-0.6553496,0.0169838,0,0,0,0,0,13.4333,52.43287,0.6553496,0,74.30282,-13.43343,8078.705
80.8,-13.46677,-0.6566266,0.01701689,0,0,0,0,0,13.46663,52.56297,0.6566266,0,74.57671,-13.46677,8072.307
81.00001,-13.5001,-0.6582548,0.01705909,0,0,0,0,0,13.49997,52.69308,0.6582549,0,74.85135,-13.5001,8070.13
81.20001,-13.53343,-0.6598725,0.01710101,0,0,0,0,0,13.5333,52.82319,0.6598725,0,75.12677,-13.53343,8067.712
81.4,-13.5669,-0.6615707,0.01714502,0,0,0,0,0,13.56677,52.95381,0.6615707,0,75.40404,-13.5669,8066.078
81.60001,-13.60037,-0.6634812,0.01719453,0,0,0,0,0,13.60023,53.08444,0.6634812,0,75.68208,-13.60037,8066.911
81.8,-13.6333,-0.6652155,0.01723948,0,0,0,0,0,13.63317,53.21298,0.6652156,0,75.95645,-13.6333,8065.838
82.00001,-13.66677,-0.6671574,0.0172898,0,0,0,0,0,13.66663,53.34361,0.6671575,0,76.23603,-13.66677,8066.798
82.20001,-13.70037,-0.6692531,0.01734411,0,0,0,0,0,13.70023,53.47476,0.6692531,0,76.51752,-13.70037,8069.391
82.4,-13.73357,-0.6712381,0.01739556,0,0,0,0,0,13.73343,53.60435,0.6712381,0,76.79644,-13.73357,8070.782
82.60001,-13.76677,-0.673071,0.01744306,0,0,0,0,0,13.76663,53.73393,0.673071,0,77.07614,-13.76677,8070.217
82.8,-13.80037,-0.6748702,0.01748969,0,0,0,0,0,13.80023,53.86508,0.6748702,0,77.36,-13.80037,8068.853
83.00001,-13.83383,-0.676858,0.0175412,0,0,0,0,0,13.8337,53.9957,0.6768579,0,77.64354,-13.83383,8069.705
83.20001,-13.86703,-0.6785092,0.01758399,0,0,0,0,0,13.8669,54.12529,0.6785092,0,77.92562,-13.86703,8066.606
83.4,-13.90023,-0.6802207,0.01762835,0,0,0,0,0,13.9001,54.25488,0.6802207,0,78.2085,-13.90023,8064.11
83.60001,-13.93357,-0.6818654,0.01767097,0,0,0,0,0,13.93343,54.38498,0.6818654,0,78.49332,-13.93357,8060.616
83.8,-13.96677,-0.6835523,0.01771469,0,0,0,0,0,13.96663,54.51457,0.6835523,0,78.77781,-13.96677,8057.602
84.00001,-14.0001,-0.6851131,0.01775514,0,0,0,0,0,13.99997,54.64468,0.6851131,0,79.06426,-14.0001,8052.9
84.20001,-14.03343,-0.6869185,0.01780192,0,0,0,0,0,14.0333,54.77478,0.6869185,0,79.35153,-14.03343,8050.959
84.4,-14.06677,-0.6887994,0.01785067,0,0,0,0,0,14.06663,54.90489,0.6887994,0,79.63963,-14.06677,8049.78
84.60001,-14.10037,-0.6906922,0.01789972,0,0,0,0,0,14.10023,55.03603,0.6906922,0,79.93088,-14.10037,8048.425
84.8,-14.1337,-0.6927546,0.01795317,0,0,0,0,0,14.13356,55.16614,0.6927546,0,80.22065,-14.1337,8049.1
85.00001,-14.16677,-0.6943926,0.01799562,0,0,0,0,0,14.16663,55.29521,0.6943926,0,80.50895,-14.16677,8044.904
85.20001,-14.2001,-0.6960337,0.01803815,0,0,0,0,0,14.19997,55.42532,0.6960337,0,80.80041,-14.2001,8040.449
85.4,-14.23343,-0.6977844,0.01808352,0,0,0,0,0,14.2333,55.55542,0.6977844,0,81.09272,-14.23343,8037.145
85.60001,-14.26676,-0.699484,0.01812757,0,0,0,0,0,14.26663,55.68552,0.6994841,0,81.38588,-14.26676,8033.137
85.8,-14.3001,-0.7009842,0.01816645,0,0,0,0,0,14.29996,55.81563,0.7009842,0,81.67991,-14.3001,8026.73
86.00001,-14.3337,-0.7028899,0.01821583,0,0,0,0,0,14.33356,55.94678,0.7028899,0,81.97717,-14.3337,8024.662
86.20001,-14.3673,-0.7047643,0.01826441,0,0,0,0,0,14.36716,56.07793,0.7047644,0,82.27532,-14.3673,8022.108
86.4,-14.40023,-0.7060196,0.01829694,0,0,0,0,0,14.4001,56.20647,0.7060196,0,82.56842,-14.40023,8012.877
86.60001,-14.43356,-0.7075806,0.0183374,0,0,0,0,0,14.43343,56.33658,0.7075806,0,82.86595,-14.43356,8006.734
86.8,-14.4669,-0.7091324,0.01837761,0,0,0,0,0,14.46676,56.46668,0.7091324,0,83.16437,-14.4669,8000.384
87.00001,-14.49996,-0.7102583,0.01840679,0,0,0,0,0,14.49983,56.59575,0.7102583,0,83.46128,-14.49996,7989.329
87.20001,-14.53343,-0.7115744,0.0184409,0,0,0,0,0,14.5333,56.72638,0.7115744,0,83.76269,-14.53343,7980.045
87.4,-14.56676,-0.7125975,0.01846741,0,0,0,0,0,14.56663,56.85648,0.7125975,0,84.0638,-14.56676,7967.491
87.60001,-14.6001,-0.7138495,0.01849986,0,0,0,0,0,14.59996,56.98659,0.7138495,0,84.36582,-14.6001,7957.42
87.8,-14.6337,-0.7152719,0.01853672,0,0,0,0,0,14.63356,57.11774,0.7152719,0,84.67119,-14.6337,7948.966
88.00001,-14.66703,-0.7168823,0.01857845,0,0,0,0,0,14.6669,57.24784,0.7168823,0,84.97505,-14.66703,7942.69
88.20001,-14.70023,-0.7180068,0.0186076,0,0,0,0,0,14.7001,57.37743,0.7180068,0,85.27863,-14.70023,7931.036
88.4,-14.73343,-0.7192655,0.01864022,0,0,0,0,0,14.7333,57.50702,0.7192655,0,85.58312,-14.73343,7920.785
88.60001,-14.76703,-0.7203668,0.01866876,0,0,0,0,0,14.7669,57.63816,0.7203668,0,85.89223,-14.76703,7908.43
88.8,-14.8001,-0.7216678,0.01870247,0,0,0,0,0,14.79996,57.76723,0.7216678,0,86.19737,-14.8001,7898.573
89.00001,-14.83343,-0.7227393,0.01873024,0,0,0,0,0,14.8333,57.89734,0.7227393,0,86.50592,-14.83343,7885.931
89.20001,-14.8669,-0.7240403,0.01876396,0,0,0,0,0,14.86676,58.02796,0.7240403,0,86.81665,-14.8669,7875.616
89.4,-14.9005,-0.7254204,0.01879973,0,0,0,0,0,14.90036,58.15911,0.7254204,0,87.12961,-14.9005,7865.972
89.60001,-14.93356,-0.7261892,0.01881965,0,0,0,0,0,14.93343,58.28817,0.7261893,0,87.43855,-14.93356,7850.02
89.8,-14.9669,-0.7274598,0.01885258,0,0,0,0,0,14.96676,58.41828,0.7274598,0,87.75096,-14.9669,7839.227
90.00001,-15.00023,-0.728599,0.0188821,0,0,0,0,0,15.0001,58.54839,0.728599,0,88.06434,-15.00023,7826.935
90.12,-15.0205,-0.7293216,0.01890083,0,0,0,0,0,15.02036,58.62749,0.7293216,0,88.25535,-15.0205,7819.747