File: GFBaking/data/misc/XG_Compression_Misc/original stuff from the instron/CompresiveTestXgumWeek1.is_comp.raw
"Test Type","Compression"
"Method Name","C:\Users\Public\Documents\Instron\Bluehill\Templates\Instron Examples\Bluehill\CompressionTest Bread.im_comp"
"Sample name","P:\+Courses\MatSci\Spring2016\GF Baking - Emily, Elizabeth, Frances\CompresiveTestXgumWeek1.is_comp"
"User",""
"Sample note 1",""
"Sample note 2",""
"Sample note 3",""
"Geometry","Circular"
"Specimen",1
"Specimen label","Sample1"
"Width",50.000000,"mm"
"Thickness",50.000000,"mm"
"Anvil height",20.800000,"mm"
"Diameter",24.320000,"mm"
"Inner diameter",8.000000,"mm"
"Outer diameter",10.000000,"mm"
"Wall thickness",1.000000,"mm"
"Area",4.645335,"cm^2"
"Linear density",100.000000,"tex"
"Sled weight",10.000000,"N"
"Loading span",10.000000,"mm"
"Support span",100.000000,"mm"
"Span ratio","2"
"Fixture type","4-point"
"Included"
"Final width",50.000000,"mm"
"Final thickness",50.000000,"mm"
"Final anvil height",50.000000,"mm"
"Final diameter",1.000000,"mm"
"Final Inner diameter",0.000000,"mm"
"Final outer diameter",1.000000,"mm"
"Final wall thickness",0.500000,"mm"
"Final area",0.007854,"cm^2"
"Final linear density",1.000000,"tex"
"Operator ID","George"
"Company","ABC"
"Laboratory Name","Zyx"
"Comment",""
"Custom text input  5",""
"Custom text input  6",""
"Custom text input  7",""
"Custom text input  8",""
"Custom text input  9",""
"Custom text input 10",""
"Custom text input 11",""
"Custom text input 12",""
"Custom text input 13",""
"Custom text input 14",""
"Custom text input 15",""
"Custom text input 16",""
"Custom text input 17",""
"Custom text input 18",""
"Custom text input 19",""
"Custom text input 20",""
"Custom text input 21",""
"Custom text input 22",""
"Custom text input 23",""
"Custom text input 24",""
"Custom text input 25",""
"Custom text input 26",""
"Custom text input 27",""
"Custom text input 28",""
"Custom text input 29",""
"Custom text input 30",""
"Custom text input 31",""
"Custom text input 32",""
"Custom text input 33",""
"Custom text input 34",""
"Custom text input 35",""
"Custom text input 36",""
"Custom text input 37",""
"Custom text input 38",""
"Custom text input 39",""
"Custom text input 40",""
"Custom text input 41",""
"Custom text input 42",""
"Custom text input 43",""
"Custom text input 44",""
"Custom text input 45",""
"Custom text input 46",""
"Custom text input 47",""
"Custom text input 48",""
"Custom text input 49",""
"Custom text input 50",""
"Temperature (deg C)",18.000000,""
"Humidity (%)",50.000000,""
"Custom number input  3",0.000000,""
"Custom number input  4",0.000000,""
"Custom number input  5",0.000000,""
"Custom number input  6",0.000000,""
"Custom number input  7",0.000000,""
"Custom number input  8",0.000000,""
"Custom number input  9",0.000000,""
"Custom number input 10",0.000000,""
"Time sec","Extension mm","Load kgf","Compressive stress MPa","Cycle Count ","Total Cycle Count ","Repetitions Count ","Marked Data ","PIP Count ","Compressive extension mm","Compressive strain %","Compressive load kgf","Displacement (Strain 1) mm","True strain %","Corrected Position mm","True stress Pa"
0,0,-0.003084175,6.510926e-005,0,0,0,0,0,0,0,0.003084176,0,0,0,65.10926
0.2,-0.0286666,-0.004623235,9.759995e-005,0,0,0,0,0,0.02866659,0.1378202,0.004623235,0,0.1379152,-0.0286666,97.46544
0.4,-0.06519984,-0.006259099,0.0001321343,0,0,0,0,0,0.06519984,0.3134608,0.0062591,0,0.3139531,-0.06519984,131.7201
0.6,-0.09946642,-0.008132701,0.0001716874,0,0,0,0,0,0.09946642,0.478204,0.008132701,0,0.479351,-0.09946642,170.8664
0.8,-0.133333,-0.009785675,0.0002065829,0,0,0,0,0,0.133333,0.6410241,0.009785675,0,0.6430875,-0.133333,205.2587
1,-0.1669329,-0.01123919,0.0002372676,0,0,0,0,0,0.1669329,0.8025621,0.01123918,0,0.8058,-0.1669329,235.3634
1.2,-0.2001328,-0.0126623,0.0002673107,0,0,0,0,0,0.2001328,0.9621771,0.0126623,0,0.9668359,-0.2001328,264.7387
1.4,-0.2334661,-0.01404707,0.0002965442,0,0,0,0,0,0.2334661,1.122433,0.01404707,0,1.12878,-0.2334661,293.2157
1.6,-0.2669327,-0.01611871,0.0003402781,0,0,0,0,0,0.2669327,1.28333,0.01611871,0,1.291636,-0.2669327,335.9112
1.8,-0.3001326,-0.01816716,0.0003835225,0,0,0,0,0,0.3001326,1.442945,0.01816716,0,1.453457,-0.3001326,377.9885
2,-0.3330659,-0.02010388,0.0004244079,0,0,0,0,0,0.3330659,1.601278,0.02010388,0,1.614237,-0.3330659,417.612
2.2,-0.3666658,-0.02223127,0.0004693189,0,0,0,0,0,0.3666658,1.762816,0.02223127,0,1.778539,-0.3666658,461.0456
2.4,-0.4001324,-0.02412071,0.0005092063,0,0,0,0,0,0.4001324,1.923713,0.02412071,0,1.942457,-0.4001324,499.4106
2.6,-0.4335989,-0.02609532,0.0005508917,0,0,0,0,0,0.4335989,2.08461,0.02609532,0,2.106645,-0.4335989,539.4078
2.8,-0.4669322,-0.02806437,0.00059246,0,0,0,0,0,0.4669322,2.244866,0.02806437,0,2.270447,-0.4669322,579.1601
3,-0.4999988,-0.03032865,0.0006402606,0,0,0,0,0,0.4999988,2.40384,0.03032865,0,2.433204,-0.4999988,624.8697
3.2,-0.5334654,-0.03222161,0.0006802224,0,0,0,0,0,0.5334653,2.564737,0.03222162,0,2.5982,-0.5334654,662.7765
3.4,-0.5670653,-0.03474201,0.0007334299,0,0,0,0,0,0.5670653,2.726276,0.03474201,0,2.764128,-0.5670653,713.4346
3.6,-0.5998652,-0.0371948,0.0007852101,0,0,0,0,0,0.5998652,2.883967,0.0371948,0,2.926371,-0.5998652,762.5649
3.8,-0.6333318,-0.03956121,0.0008351667,0,0,0,0,0,0.6333318,3.044864,0.03956121,0,3.092183,-0.6333318,809.737
4,-0.6667984,-0.04200994,0.0008868613,0,0,0,0,0,0.6667984,3.205761,0.04200994,0,3.258271,-0.6667984,858.4306
4.2,-0.7002649,-0.04452538,0.0009399643,0,0,0,0,0,0.7002649,3.366658,0.04452538,0,3.424635,-0.7002649,908.3189
4.4,-0.7334649,-0.04730986,0.0009987465,0,0,0,0,0,0.7334649,3.526273,0.04730986,0,3.589948,-0.7334649,963.528
4.6,-0.7666648,-0.0503082,0.001062044,0,0,0,0,0,0.7666648,3.685889,0.05030821,0,3.755534,-0.7666648,1022.898
4.8,-0.8003981,-0.0534297,0.001127941,0,0,0,0,0,0.8003981,3.848068,0.0534297,0,3.924062,-0.8003981,1084.537
5,-0.8334646,-0.05649026,0.001192552,0,0,0,0,0,0.8334646,4.007041,0.05649026,0,4.089535,-0.8334646,1144.766
5.2,-0.8665312,-0.0595367,0.001256865,0,0,0,0,0,0.8665313,4.166016,0.0595367,0,4.255282,-0.8665312,1204.503
5.4,-0.8999978,-0.06271583,0.001323978,0,0,0,0,0,0.8999978,4.326912,0.06271583,0,4.423314,-0.8999978,1266.691
5.6,-0.9334644,-0.06594509,0.00139215,0,0,0,0,0,0.9334644,4.48781,0.06594509,0,4.59163,-0.9334644,1329.673
5.8,-0.966931,-0.06916879,0.001460205,0,0,0,0,0,0.966931,4.648707,0.06916879,0,4.760229,-0.966931,1392.324
6,-1.000264,-0.07255638,0.00153172,0,0,0,0,0,1.000264,4.808962,0.07255638,0,4.928439,-1.000264,1458.06
6.2,-1.033464,-0.0759409,0.001603169,0,0,0,0,0,1.033464,4.968578,0.0759409,0,5.096259,-1.033464,1523.515
6.4,-1.066797,-0.07909842,0.001669827,0,0,0,0,0,1.066797,5.128834,0.07909842,0,5.265036,-1.066797,1584.184
6.6,-1.100397,-0.08226089,0.001736589,0,0,0,0,0,1.100397,5.290372,0.08226088,0,5.435452,-1.100397,1644.717
6.8,-1.133331,-0.08539498,0.001802752,0,0,0,0,0,1.133331,5.448705,0.08539498,0,5.602769,-1.133331,1704.525
7,-1.166531,-0.08837135,0.001865585,0,0,0,0,0,1.16653,5.60832,0.08837134,0,5.771725,-1.166531,1760.957
7.2,-1.200264,-0.09145554,0.001930695,0,0,0,0,0,1.200264,5.770499,0.09145554,0,5.943688,-1.200264,1819.284
7.4,-1.23373,-0.09440128,0.001992882,0,0,0,0,0,1.23373,5.931396,0.09440129,0,6.114584,-1.23373,1874.676
7.6,-1.266797,-0.09762837,0.002061008,0,0,0,0,0,1.266797,6.09037,0.09762836,0,6.283725,-1.266797,1935.485
7.8,-1.30013,-0.1007558,0.00212703,0,0,0,0,0,1.30013,6.250626,0.1007558,0,6.45452,-1.30013,1994.077
8,-1.333597,-0.1040336,0.002196228,0,0,0,0,0,1.333597,6.411523,0.1040336,0,6.626292,-1.333597,2055.416
8.200001,-1.366797,-0.1071519,0.002262056,0,0,0,0,0,1.366797,6.571138,0.1071519,0,6.796987,-1.366797,2113.413
8.400001,-1.399863,-0.110126,0.002324843,0,0,0,0,0,1.399863,6.730112,0.110126,0,6.967287,-1.399863,2168.378
8.6,-1.433196,-0.1132302,0.002390375,0,0,0,0,0,1.433196,6.890368,0.1132302,0,7.139254,-1.433196,2225.67
8.8,-1.466796,-0.1164846,0.002459078,0,0,0,0,0,1.466796,7.051906,0.1164846,0,7.312897,-1.466796,2285.666
9,-1.50013,-0.1194831,0.002522378,0,0,0,0,0,1.50013,7.212162,0.1194831,0,7.485461,-1.50013,2340.46
9.200001,-1.533596,-0.1226292,0.002588795,0,0,0,0,0,1.533596,7.373059,0.1226292,0,7.659015,-1.533596,2397.922
9.400001,-1.566796,-0.125726,0.002654171,0,0,0,0,0,1.566796,7.532674,0.125726,0,7.831484,-1.566796,2454.241
9.6,-1.600129,-0.1287017,0.002716988,0,0,0,0,0,1.600129,7.69293,0.1287017,0,8.004945,-1.600129,2507.972
9.8,-1.633596,-0.1317307,0.002780934,0,0,0,0,0,1.633596,7.853827,0.1317307,0,8.179403,-1.633596,2562.524
10,-1.666529,-0.1346925,0.002843459,0,0,0,0,0,1.666529,8.012159,0.1346925,0,8.351378,-1.666529,2615.636
10.2,-1.699863,-0.1378493,0.002910103,0,0,0,0,0,1.699862,8.172416,0.1378493,0,8.525745,-1.699863,2672.277
10.4,-1.733462,-0.1405967,0.002968101,0,0,0,0,0,1.733462,8.333954,0.1405967,0,8.701815,-1.733462,2720.741
10.6,-1.767062,-0.1433524,0.003026277,0,0,0,0,0,1.767062,8.495492,0.1433524,0,8.878195,-1.767062,2769.18
10.8,-1.800262,-0.1464054,0.003090729,0,0,0,0,0,1.800262,8.655107,0.1464054,0,9.05278,-1.800262,2823.223
11,-1.833462,-0.1493281,0.003152428,0,0,0,0,0,1.833462,8.814722,0.1493281,0,9.227673,-1.833462,2874.551
11.2,-1.866929,-0.1520507,0.003209904,0,0,0,0,0,1.866929,8.975619,0.1520507,0,9.404279,-1.866929,2921.795
11.4,-1.900129,-0.1544654,0.00326088,0,0,0,0,0,1.900129,9.135234,0.1544654,0,9.579787,-1.900129,2962.991
11.6,-1.933195,-0.1572763,0.003320221,0,0,0,0,0,1.933195,9.294209,0.1572763,0,9.754898,-1.933195,3011.632
11.8,-1.966795,-0.1602673,0.003383363,0,0,0,0,0,1.966795,9.455746,0.1602673,0,9.933146,-1.966795,3063.441
12,-2.000128,-0.1630483,0.003442072,0,0,0,0,0,2.000128,9.616002,0.1630483,0,10.11029,-2.000128,3111.082
12.2,-2.033462,-0.1665534,0.003516067,0,0,0,0,0,2.033462,9.776258,0.1665534,0,10.28776,-2.033462,3172.327
12.4,-2.066795,-0.1690193,0.003568125,0,0,0,0,0,2.066795,9.936515,0.1690193,0,10.46554,-2.066795,3213.578
12.6,-2.100128,-0.1715821,0.003622228,0,0,0,0,0,2.100128,10.09677,0.1715821,0,10.64363,-2.100128,3256.5
12.8,-2.133461,-0.174531,0.00368448,0,0,0,0,0,2.133461,10.25703,0.174531,0,10.82204,-2.133461,3306.561
13,-2.166928,-0.1769389,0.003735312,0,0,0,0,0,2.166928,10.41792,0.1769389,0,11.00149,-2.166928,3346.17
13.2,-2.199995,-0.1797118,0.00379385,0,0,0,0,0,2.199995,10.5769,0.1797118,0,11.17911,-2.199995,3392.578
13.4,-2.233195,-0.1832489,0.003868523,0,0,0,0,0,2.233195,10.73651,0.183249,0,11.35777,-2.233195,3453.178
13.6,-2.266928,-0.1857194,0.003920677,0,0,0,0,0,2.266928,10.89869,0.1857194,0,11.53962,-2.266928,3493.374
13.8,-2.300394,-0.1887894,0.003985486,0,0,0,0,0,2.300395,11.05959,0.1887894,0,11.72036,-2.300394,3544.708
14,-2.333328,-0.1916184,0.004045208,0,0,0,0,0,2.333328,11.21792,0.1916184,0,11.89854,-2.333328,3591.42
14.2,-2.366661,-0.1939572,0.004094581,0,0,0,0,0,2.366661,11.37818,0.1939571,0,12.07921,-2.366661,3628.692
14.4,-2.400261,-0.1967363,0.004153252,0,0,0,0,0,2.400261,11.53972,0.1967363,0,12.26165,-2.400261,3673.978
14.6,-2.433461,-0.1992706,0.004206753,0,0,0,0,0,2.433461,11.69933,0.1992707,0,12.44225,-2.433461,3714.591
14.8,-2.466527,-0.2011909,0.004247291,0,0,0,0,0,2.466527,11.8583,0.2011909,0,12.62245,-2.466527,3743.635
15,-2.499994,-0.203869,0.004303828,0,0,0,0,0,2.499994,12.0192,0.203869,0,12.80516,-2.499994,3786.542
15.2,-2.533327,-0.2066215,0.004361934,0,0,0,0,0,2.533327,12.17946,0.2066215,0,12.98747,-2.533327,3830.674
15.4,-2.566794,-0.2093759,0.004420082,0,0,0,0,0,2.566794,12.34035,0.2093759,0,13.17085,-2.566794,3874.628
15.6,-2.60026,-0.2117601,0.004470414,0,0,0,0,0,2.60026,12.50125,0.2117601,0,13.35457,-2.60026,3911.557
15.8,-2.63346,-0.2146439,0.004531294,0,0,0,0,0,2.63346,12.66087,0.2146439,0,13.53716,-2.63346,3957.593
16,-2.66666,-0.2170137,0.004581321,0,0,0,0,0,2.66666,12.82048,0.2170137,0,13.72008,-2.66666,3993.974
16.2,-2.70026,-0.2195042,0.004633899,0,0,0,0,0,2.70026,12.98202,0.2195042,0,13.90554,-2.70026,4032.325
16.4,-2.733193,-0.2220526,0.004687696,0,0,0,0,0,2.733193,13.14035,0.2220526,0,14.08766,-2.733193,4071.717
16.6,-2.766527,-0.2243047,0.004735239,0,0,0,0,0,2.766526,13.30061,0.2243046,0,14.27233,-2.766527,4105.424
16.8,-2.800127,-0.2267671,0.004787223,0,0,0,0,0,2.800127,13.46215,0.2267671,0,14.45883,-2.800127,4142.76
17,-2.833593,-0.2293427,0.004841596,0,0,0,0,0,2.833593,13.62304,0.2293427,0,14.64493,-2.833593,4182.023
17.2,-2.86666,-0.2314427,0.004885929,0,0,0,0,0,2.86666,13.78202,0.2314427,0,14.82914,-2.86666,4212.55
17.4,-2.900126,-0.2336461,0.004932444,0,0,0,0,0,2.900126,13.94291,0.2336461,0,15.01593,-2.900126,4244.717
17.6,-2.933593,-0.2360725,0.004983667,0,0,0,0,0,2.933593,14.10381,0.2360725,0,15.20307,-2.933593,4280.78
17.8,-2.966793,-0.2383145,0.005030998,0,0,0,0,0,2.966793,14.26343,0.2383145,0,15.38907,-2.966793,4313.406
18,-2.999859,-0.2405209,0.005077577,0,0,0,0,0,2.999859,14.4224,0.2405209,0,15.57466,-2.999859,4345.268
18.2,-3.033326,-0.2425791,0.005121027,0,0,0,0,0,3.033326,14.5833,0.2425791,0,15.76285,-3.033326,4374.212
18.4,-3.066659,-0.2448228,0.005168392,0,0,0,0,0,3.066659,14.74355,0.2448228,0,15.95065,-3.066659,4406.387
18.6,-3.100126,-0.2468675,0.005211559,0,0,0,0,0,3.100126,14.90445,0.2468675,0,16.13955,-3.100126,4434.804
18.8,-3.133459,-0.2488254,0.00525289,0,0,0,0,0,3.133459,15.06471,0.2488254,0,16.32805,-3.133459,4461.557
19,-3.166659,-0.2512361,0.005303783,0,0,0,0,0,3.166659,15.22432,0.2512361,0,16.51615,-3.166659,4496.318
19.2,-3.200125,-0.2535295,0.005352198,0,0,0,0,0,3.200125,15.38522,0.2535295,0,16.70612,-3.200125,4528.75
19.4,-3.233592,-0.2555345,0.005394526,0,0,0,0,0,3.233592,15.54612,0.2555345,0,16.89645,-3.233592,4555.887
19.6,-3.266659,-0.2578407,0.005443211,0,0,0,0,0,3.266659,15.70509,0.2578407,0,17.08487,-3.266659,4588.35
19.8,-3.300125,-0.2600399,0.005489638,0,0,0,0,0,3.300125,15.86599,0.2600399,0,17.27593,-3.300125,4618.653
20,-3.333458,-0.2620165,0.005531366,0,0,0,0,0,3.333459,16.02624,0.2620165,0,17.46659,-3.333458,4644.895
20.2,-3.366925,-0.2640314,0.005573902,0,0,0,0,0,3.366925,16.18714,0.2640314,0,17.65837,-3.366925,4671.646
20.4,-3.399992,-0.266181,0.005619281,0,0,0,0,0,3.399992,16.34611,0.2661811,0,17.84823,-3.399992,4700.747
20.6,-3.433458,-0.2683608,0.005665297,0,0,0,0,0,3.433458,16.50701,0.2683608,0,18.04075,-3.433458,4730.126
20.8,-3.467058,-0.2705573,0.005711668,0,0,0,0,0,3.467058,16.66855,0.2705573,0,18.23441,-3.467058,4759.616
21,-3.499991,-0.2725312,0.005753338,0,0,0,0,0,3.499991,16.82688,0.2725312,0,18.4246,-3.499991,4785.231
21.2,-3.533191,-0.2742806,0.005790269,0,0,0,0,0,3.533191,16.9865,0.2742806,0,18.61669,-3.533191,4806.706
21.4,-3.566791,-0.276445,0.005835962,0,0,0,0,0,3.566791,17.14804,0.276445,0,18.81147,-3.566791,4835.209
21.6,-3.600125,-0.2784026,0.005877289,0,0,0,0,0,3.600125,17.30829,0.2784027,0,19.00508,-3.600125,4860.03
21.8,-3.633458,-0.2801665,0.005914524,0,0,0,0,0,3.633457,17.46855,0.2801665,0,19.19907,-3.633458,4881.343
22,-3.666791,-0.2822469,0.005958444,0,0,0,0,0,3.666791,17.6288,0.2822469,0,19.39344,-3.666791,4908.042
22.2,-3.699991,-0.2840068,0.005995598,0,0,0,0,0,3.699991,17.78842,0.2840069,0,19.5874,-3.699991,4929.076
22.4,-3.733591,-0.2861391,0.006040611,0,0,0,0,0,3.733591,17.94996,0.2861391,0,19.78408,-3.733591,4956.324
22.6,-3.766924,-0.2880019,0.006079937,0,0,0,0,0,3.766924,18.11021,0.2880019,0,19.97959,-3.766924,4978.847
22.8,-3.799857,-0.2899194,0.006120415,0,0,0,0,0,3.799857,18.26855,0.2899193,0,20.17313,-3.799857,5002.304
23,-3.833191,-0.2920651,0.006165714,0,0,0,0,0,3.83319,18.4288,0.2920651,0,20.36939,-3.833191,5029.447
23.2,-3.866791,-0.2939903,0.006206356,0,0,0,0,0,3.866791,18.59034,0.2939903,0,20.56762,-3.866791,5052.574
23.4,-3.900257,-0.296158,0.006252117,0,0,0,0,0,3.900257,18.75124,0.296158,0,20.76546,-3.900257,5079.767
23.6,-3.933457,-0.2981154,0.006293439,0,0,0,0,0,3.933457,18.91085,0.2981154,0,20.9621,-3.933457,5103.296
23.8,-3.966791,-0.3000335,0.006333932,0,0,0,0,0,3.966791,19.07111,0.3000335,0,21.15993,-3.966791,5125.981
24,-4.000257,-0.3019514,0.00637442,0,0,0,0,0,4.000257,19.232,0.3019513,0,21.35894,-4.000257,5148.491
24.2,-4.033323,-0.3037985,0.006413414,0,0,0,0,0,4.033323,19.39098,0.3037985,0,21.55596,-4.033323,5169.79
24.4,-4.06639,-0.3055445,0.006450274,0,0,0,0,0,4.06639,19.54995,0.3055445,0,21.75337,-4.06639,5189.248
24.6,-4.100123,-0.3074194,0.006489853,0,0,0,0,0,4.100123,19.71213,0.3074194,0,21.95517,-4.100123,5210.565
24.8,-4.133457,-0.3092597,0.006528704,0,0,0,0,0,4.133457,19.87239,0.3092597,0,22.15497,-4.133457,5231.294
25,-4.16679,-0.3109066,0.006563472,0,0,0,0,0,4.16679,20.03264,0.3109066,0,22.35517,-4.16679,5248.635
25.2,-4.200256,-0.312805,0.006603549,0,0,0,0,0,4.200256,20.19354,0.312805,0,22.55657,-4.200256,5270.058
25.4,-4.233456,-0.3145225,0.006639806,0,0,0,0,0,4.233456,20.35316,0.3145225,0,22.75678,-4.233456,5288.396
25.6,-4.26679,-0.3158509,0.00666785,0,0,0,0,0,4.266789,20.51341,0.3158509,0,22.95819,-4.26679,5300.046
25.8,-4.300123,-0.3175618,0.006703967,0,0,0,0,0,4.300123,20.67367,0.3175618,0,23.16001,-4.300123,5318.011
26,-4.33319,-0.3192932,0.00674052,0,0,0,0,0,4.333189,20.83264,0.3192932,0,23.36061,-4.33319,5336.291
26.2,-4.366523,-0.3208169,0.006772685,0,0,0,0,0,4.366523,20.9929,0.3208169,0,23.56324,-4.366523,5350.903
26.4,-4.400122,-0.3224128,0.006806376,0,0,0,0,0,4.400123,21.15443,0.3224128,0,23.76791,-4.400122,5366.526
26.6,-4.433723,-0.324426,0.006848876,0,0,0,0,0,4.433722,21.31598,0.324426,0,23.973,-4.433723,5388.972
26.8,-4.466789,-0.3258679,0.006879316,0,0,0,0,0,4.466789,21.47495,0.3258679,0,24.17525,-4.466789,5401.987
27,-4.500122,-0.3273559,0.006910729,0,0,0,0,0,4.500122,21.6352,0.3273559,0,24.37954,-4.500122,5415.579
27.2,-4.533456,-0.3290983,0.006947511,0,0,0,0,0,4.533456,21.79546,0.3290983,0,24.58425,-4.533456,5433.269
27.4,-4.566655,-0.3304106,0.006975215,0,0,0,0,0,4.566656,21.95507,0.3304106,0,24.78856,-4.566655,5443.801
27.6,-4.599855,-0.3317818,0.007004162,0,0,0,0,0,4.599855,22.11469,0.3317818,0,24.99328,-4.599855,5455.213
27.8,-4.633322,-0.3332576,0.007035318,0,0,0,0,0,4.633322,22.27559,0.3332576,0,25.20008,-4.633322,5468.16
28,-4.666655,-0.3348665,0.007069284,0,0,0,0,0,4.666656,22.43584,0.3348665,0,25.40648,-4.666655,5483.23
28.2,-4.700122,-0.3363096,0.007099748,0,0,0,0,0,4.700122,22.59674,0.3363096,0,25.61413,-4.700122,5495.437
28.4,-4.733455,-0.3377612,0.007130393,0,0,0,0,0,4.733455,22.757,0.3377612,0,25.82138,-4.733455,5507.729
28.6,-4.766788,-0.3392318,0.007161438,0,0,0,0,0,4.766788,22.91725,0.3392318,0,26.02907,-4.766788,5520.233
28.8,-4.800122,-0.3405563,0.007189399,0,0,0,0,0,4.800122,23.07751,0.3405563,0,26.23719,-4.800122,5530.265
29,-4.833588,-0.3418742,0.00721722,0,0,0,0,0,4.833589,23.23841,0.3418742,0,26.44657,-4.833588,5540.054
29.2,-4.866655,-0.3434262,0.007249984,0,0,0,0,0,4.866655,23.39738,0.3434262,0,26.65389,-4.866655,5553.678
29.4,-4.899855,-0.3447,0.007276876,0,0,0,0,0,4.899855,23.55699,0.3447,0,26.86247,-4.899855,5562.663
29.6,-4.933455,-0.3458935,0.007302071,0,0,0,0,0,4.933455,23.71853,0.3458935,0,27.07402,-4.933455,5570.127
29.8,-4.966921,-0.3469494,0.007324361,0,0,0,0,0,4.966921,23.87943,0.3469494,0,27.28516,-4.966921,5575.346
30,-5.000121,-0.3481898,0.007350548,0,0,0,0,0,5.000121,24.03904,0.3481898,0,27.49507,-5.000121,5583.547
30.2,-5.033454,-0.3494166,0.007376446,0,0,0,0,0,5.033454,24.1993,0.3494166,0,27.70627,-5.033454,5591.398
30.4,-5.066921,-0.3508286,0.007406256,0,0,0,0,0,5.066921,24.3602,0.3508286,0,27.91875,-5.066921,5602.077
30.6,-5.100121,-0.3522049,0.00743531,0,0,0,0,0,5.100121,24.51981,0.3522049,0,28.13,-5.100121,5612.186
30.8,-5.133187,-0.3534247,0.00746106,0,0,0,0,0,5.133187,24.67879,0.3534247,0,28.34084,-5.133187,5619.761
31,-5.166654,-0.3547533,0.007489108,0,0,0,0,0,5.166654,24.83968,0.3547533,0,28.55468,-5.166654,5628.837
31.2,-5.200121,-0.356128,0.007518128,0,0,0,0,0,5.20012,25.00058,0.356128,0,28.76898,-5.200121,5638.553
31.4,-5.233454,-0.3573366,0.007543643,0,0,0,0,0,5.233454,25.16084,0.3573366,0,28.98289,-5.233454,5645.599
31.6,-5.266787,-0.3584009,0.007566111,0,0,0,0,0,5.266787,25.32109,0.3584009,0,29.19725,-5.266787,5650.289
31.8,-5.30012,-0.3591261,0.007581422,0,0,0,0,0,5.30012,25.48135,0.3591261,0,29.41207,-5.30012,5649.573
32,-5.333454,-0.360573,0.007611965,0,0,0,0,0,5.333454,25.64161,0.360573,0,29.62736,-5.333454,5660.135
32.2,-5.36692,-0.3618849,0.00763966,0,0,0,0,0,5.36692,25.8025,0.3618849,0,29.84398,-5.36692,5668.437
32.4,-5.39972,-0.3632288,0.007668033,0,0,0,0,0,5.39972,25.96019,0.3632288,0,30.05673,-5.39972,5677.397
32.6,-5.433187,-0.3644642,0.007694113,0,0,0,0,0,5.433187,26.12109,0.3644642,0,30.27428,-5.433187,5684.326
32.8,-5.466787,-0.3656705,0.007719578,0,0,0,0,0,5.466787,26.28263,0.3656705,0,30.49317,-5.466787,5690.67
33,-5.500386,-0.3668232,0.007743913,0,0,0,0,0,5.500386,26.44417,0.3668232,0,30.71254,-5.500386,5696.099
33.2,-5.533453,-0.3679558,0.007767823,0,0,0,0,0,5.533453,26.60314,0.3679558,0,30.9289,-5.533453,5701.338
33.4,-5.566787,-0.3680403,0.007769606,0,0,0,0,0,5.566786,26.7634,0.3680403,0,31.14748,-5.566787,5690.196
33.6,-5.600253,-0.3696991,0.007804625,0,0,0,0,0,5.600253,26.92429,0.3696991,0,31.36742,-5.600253,5703.285
33.8,-5.63332,-0.3702477,0.007816208,0,0,0,0,0,5.63332,27.08327,0.3702477,0,31.58521,-5.63332,5699.323
34,-5.66652,-0.370901,0.007829998,0,0,0,0,0,5.66652,27.24288,0.370901,0,31.80434,-5.66652,5696.881
34.2,-5.699986,-0.3722852,0.00785922,0,0,0,0,0,5.699986,27.40378,0.3722852,0,32.02573,-5.699986,5705.496
34.4,-5.733453,-0.3732134,0.007878814,0,0,0,0,0,5.733453,27.56468,0.3732134,0,32.24761,-5.733453,5707.044
34.6,-5.766919,-0.3735746,0.00788644,0,0,0,0,0,5.766919,27.72557,0.3735746,0,32.46998,-5.766919,5699.88
34.8,-5.800119,-0.3738788,0.007892861,0,0,0,0,0,5.800119,27.88519,0.3738787,0,32.69107,-5.800119,5691.922
35,-5.833319,-0.3762607,0.007943146,0,0,0,0,0,5.833319,28.0448,0.3762607,0,32.91265,-5.833319,5715.506
35.2,-5.866786,-0.3768361,0.007955292,0,0,0,0,0,5.866786,28.2057,0.3768361,0,33.13651,-5.866786,5711.446
35.4,-5.900119,-0.3780893,0.007981749,0,0,0,0,0,5.900119,28.36596,0.3780893,0,33.35998,-5.900119,5717.65
35.6,-5.933186,-0.3802344,0.008027033,0,0,0,0,0,5.933186,28.52493,0.3802344,0,33.58215,-5.933186,5737.327
35.8,-5.966652,-0.38029,0.008028207,0,0,0,0,0,5.966652,28.68583,0.38029,0,33.80751,-5.966652,5725.25
36,-6.000119,-0.3814766,0.008053257,0,0,0,0,0,6.000119,28.84673,0.3814766,0,34.03338,-6.000119,5730.156
36.2,-6.033719,-0.3832055,0.008089756,0,0,0,0,0,6.033719,29.00826,0.3832055,0,34.26067,-6.033719,5743.058
36.4,-6.066652,-0.3838387,0.008103122,0,0,0,0,0,6.066652,29.1666,0.3838387,0,34.48395,-6.066652,5739.717
36.6,-6.100119,-0.3845176,0.008117455,0,0,0,0,0,6.100119,29.32749,0.3845176,0,34.71136,-6.100119,5736.809
36.8,-6.133585,-0.3857699,0.008143893,0,0,0,0,0,6.133585,29.48839,0.3857699,0,34.93928,-6.133585,5742.39
37,-6.166652,-0.3861212,0.008151309,0,0,0,0,0,6.166652,29.64737,0.3861212,0,35.16499,-6.166652,5734.661
37.2,-6.199852,-0.3868792,0.008167311,0,0,0,0,0,6.199852,29.80698,0.3868792,0,35.39213,-6.199852,5732.882
37.4,-6.233318,-0.3874643,0.008179662,0,0,0,0,0,6.233318,29.96788,0.3874643,0,35.62161,-6.233318,5728.391
37.6,-6.266651,-0.3885015,0.008201558,0,0,0,0,0,6.266651,30.12813,0.3885015,0,35.85071,-6.266651,5730.582
37.8,-6.300118,-0.3900328,0.008233885,0,0,0,0,0,6.300118,30.28903,0.3900328,0,36.08125,-6.300118,5739.921
38,-6.333451,-0.3906761,0.008247466,0,0,0,0,0,6.333451,30.44929,0.3906761,0,36.3114,-6.333451,5736.172
38.2,-6.366785,-0.3918825,0.008272934,0,0,0,0,0,6.366785,30.60954,0.3918825,0,36.54208,-6.366785,5740.626
38.4,-6.400251,-0.3933483,0.008303877,0,0,0,0,0,6.400251,30.77044,0.3933483,0,36.77422,-6.400251,5748.738
38.6,-6.433451,-0.3941221,0.008320212,0,0,0,0,0,6.433451,30.93005,0.3941221,0,37.00505,-6.433451,5746.766
38.8,-6.466651,-0.3949502,0.008337696,0,0,0,0,0,6.466651,31.08967,0.3949502,0,37.23641,-6.466651,5745.534
39,-6.499851,-0.3961997,0.008364073,0,0,0,0,0,6.499851,31.24928,0.3961997,0,37.4683,-6.499851,5750.36
39.2,-6.533584,-0.3965923,0.008372361,0,0,0,0,0,6.533584,31.41146,0.3965923,0,37.70447,-6.533584,5742.48
39.4,-6.566784,-0.3978978,0.00839992,0,0,0,0,0,6.566784,31.57108,0.3978978,0,37.93746,-6.566784,5747.975
39.6,-6.600117,-0.3990515,0.008424276,0,0,0,0,0,6.600117,31.73133,0.3990515,0,38.17193,-6.600117,5751.141
39.8,-6.63345,-0.3999205,0.008442621,0,0,0,0,0,6.633451,31.89159,0.3999205,0,38.40695,-6.63345,5750.135
40,-6.666917,-0.4013448,0.00847269,0,0,0,0,0,6.666917,32.05249,0.4013448,0,38.64347,-6.666917,5756.982
40.2,-6.699983,-0.4021814,0.008490351,0,0,0,0,0,6.699984,32.21146,0.4021814,0,38.8777,-6.699983,5755.485
40.4,-6.733184,-0.4031092,0.008509938,0,0,0,0,0,6.733184,32.37107,0.4031092,0,39.11344,-6.733184,5755.18
40.6,-6.766784,-0.4041856,0.008532662,0,0,0,0,0,6.766783,32.53261,0.4041857,0,39.35258,-6.766784,5756.764
40.8,-6.799983,-0.4051515,0.008553051,0,0,0,0,0,6.799983,32.69223,0.4051515,0,39.58944,-6.799983,5756.868
41,-6.83345,-0.4057687,0.008566082,0,0,0,0,0,6.83345,32.85313,0.4057687,0,39.82878,-6.83345,5751.856
41.2,-6.866917,-0.4068226,0.00858833,0,0,0,0,0,6.866917,33.01402,0.4068226,0,40.06869,-6.866917,5752.977
41.4,-6.900116,-0.4079745,0.008612647,0,0,0,0,0,6.900117,33.17364,0.4079745,0,40.30725,-6.900116,5755.519
41.6,-6.93345,-0.4087578,0.008629184,0,0,0,0,0,6.93345,33.33389,0.4087578,0,40.54735,-6.93345,5752.741
41.8,-6.966916,-0.4097676,0.008650502,0,0,0,0,0,6.966916,33.49479,0.4097676,0,40.78899,-6.966916,5753.035
42,-6.999849,-0.4106065,0.008668212,0,0,0,0,0,6.999849,33.65312,0.4106065,0,41.02735,-6.999849,5751.088
42.2,-7.033183,-0.4114792,0.008686635,0,0,0,0,0,7.033182,33.81338,0.4114792,0,41.26918,-7.033183,5749.39
42.4,-7.066916,-0.4126403,0.008711146,0,0,0,0,0,7.066916,33.97556,0.4126403,0,41.51452,-7.066916,5751.486
42.6,-7.100249,-0.4134983,0.008729259,0,0,0,0,0,7.10025,34.13581,0.4134983,0,41.75754,-7.100249,5749.455
42.8,-7.133449,-0.4143801,0.008747875,0,0,0,0,0,7.13345,34.29543,0.4143801,0,42.00017,-7.133449,5747.754
43,-7.166649,-0.415281,0.008766892,0,0,0,0,0,7.166649,34.45504,0.415281,0,42.24339,-7.166649,5746.256
43.2,-7.200249,-0.4165358,0.008793383,0,0,0,0,0,7.200249,34.61658,0.4165358,0,42.49015,-7.200249,5749.414
43.4,-7.233449,-0.417505,0.008813843,0,0,0,0,0,7.233449,34.7762,0.417505,0,42.73457,-7.233449,5748.724
43.6,-7.266515,-0.4181973,0.008828458,0,0,0,0,0,7.266515,34.93517,0.4181973,0,42.9786,-7.266515,5744.222
43.8,-7.299982,-0.4194821,0.008855581,0,0,0,0,0,7.299982,35.09607,0.4194821,0,43.22619,-7.299982,5747.621
44,-7.333315,-0.4203854,0.008874652,0,0,0,0,0,7.333315,35.25632,0.4203855,0,43.47342,-7.333315,5745.776
44.2,-7.366782,-0.4214211,0.008896516,0,0,0,0,0,7.366782,35.41722,0.4214211,0,43.72224,-7.366782,5745.617
44.4,-7.400115,-0.4222277,0.008913543,0,0,0,0,0,7.400115,35.57748,0.4222277,0,43.97069,-7.400115,5742.329
44.6,-7.433582,-0.423189,0.008933837,0,0,0,0,0,7.433582,35.73837,0.423189,0,44.22075,-7.433582,5741.029
44.8,-7.466915,-0.4242078,0.008955344,0,0,0,0,0,7.466915,35.89863,0.4242077,0,44.47044,-7.466915,5740.498
45,-7.500248,-0.4252885,0.00897816,0,0,0,0,0,7.500248,36.05889,0.4252886,0,44.72076,-7.500248,5740.735
45.2,-7.533181,-0.4261611,0.008996581,0,0,0,0,0,7.533182,36.21722,0.4261611,0,44.9687,-7.533181,5738.269
45.4,-7.566648,-0.4272853,0.009020313,0,0,0,0,0,7.566648,36.37812,0.4272853,0,45.22127,-7.566648,5738.893
45.6,-7.600115,-0.4282694,0.009041088,0,0,0,0,0,7.600115,36.53901,0.4282694,0,45.47448,-7.600115,5737.563
45.8,-7.633581,-0.4291612,0.009059914,0,0,0,0,0,7.633581,36.69991,0.4291612,0,45.72834,-7.633581,5734.934
46,-7.666781,-0.430011,0.009077854,0,0,0,0,0,7.666781,36.85952,0.4300109,0,45.98082,-7.666781,5731.8
46.2,-7.700115,-0.4306802,0.009091982,0,0,0,0,0,7.700115,37.01978,0.4306802,0,46.23495,-7.700115,5726.15
46.4,-7.733581,-0.431198,0.009102913,0,0,0,0,0,7.733581,37.18068,0.431198,0,46.49075,-7.733581,5718.388
46.6,-7.766781,-0.4319072,0.009117885,0,0,0,0,0,7.766781,37.34029,0.4319072,0,46.74516,-7.766781,5713.239
46.8,-7.799848,-0.4328227,0.009137211,0,0,0,0,0,7.799848,37.49927,0.4328226,0,46.99919,-7.799848,5710.824
47,-7.833181,-0.4336792,0.009155292,0,0,0,0,0,7.833181,37.65952,0.4336792,0,47.25593,-7.833181,5707.453
47.2,-7.866648,-0.4343626,0.009169721,0,0,0,0,0,7.866648,37.82042,0.4343626,0,47.51436,-7.866648,5701.694
47.4,-7.900114,-0.4356873,0.009197685,0,0,0,0,0,7.900114,37.98132,0.4356873,0,47.77345,-7.900114,5704.283
47.6,-7.933447,-0.4363314,0.009211283,0,0,0,0,0,7.933447,38.14157,0.4363314,0,48.03218,-7.933447,5697.955
47.8,-7.966781,-0.4378572,0.009243494,0,0,0,0,0,7.966781,38.30183,0.4378572,0,48.29159,-7.966781,5703.066
48,-8.000114,-0.4387224,0.009261758,0,0,0,0,0,8.000114,38.46209,0.4387224,0,48.55167,-8.000114,5699.493
48.2,-8.033447,-0.4395851,0.009279971,0,0,0,0,0,8.033447,38.62234,0.4395851,0,48.81243,-8.033447,5695.829
48.4,-8.066514,-0.440773,0.009305048,0,0,0,0,0,8.066514,38.78131,0.440773,0,49.07177,-8.066514,5696.428
48.6,-8.099981,-0.441354,0.009317313,0,0,0,0,0,8.09998,38.94221,0.441354,0,49.33495,-8.099981,5688.945
48.8,-8.13358,-0.4423545,0.009338435,0,0,0,0,0,8.13358,39.10375,0.4423545,0,49.59986,-8.13358,5686.757
49,-8.166914,-0.4434654,0.009361886,0,0,0,0,0,8.166914,39.26401,0.4434654,0,49.86337,-8.166914,5686.034
49.2,-8.200114,-0.443964,0.009372413,0,0,0,0,0,8.200113,39.42362,0.443964,0,50.12652,-8.200114,5677.468
49.4,-8.233447,-0.4449553,0.009393341,0,0,0,0,0,8.233447,39.58388,0.4449553,0,50.39142,-8.233447,5675.092
49.6,-8.266914,-0.4460511,0.009416474,0,0,0,0,0,8.266913,39.74478,0.4460512,0,50.65809,-8.266914,5673.917
49.8,-8.300113,-0.4463982,0.009423801,0,0,0,0,0,8.300114,39.90439,0.4463982,0,50.92334,-8.300113,5663.29
50,-8.33318,-0.4475231,0.009447549,0,0,0,0,0,8.33318,40.06337,0.4475231,0,51.18823,-8.33318,5662.543
50.2,-8.366646,-0.4481545,0.009460878,0,0,0,0,0,8.366646,40.22426,0.4481545,0,51.45703,-8.366646,5655.309
50.4,-8.400113,-0.4489578,0.009477835,0,0,0,0,0,8.400113,40.38516,0.4489578,0,51.72657,-8.400113,5650.196
50.6,-8.433446,-0.4501555,0.00950312,0,0,0,0,0,8.433446,40.54541,0.4501555,0,51.99574,-8.433446,5650.04
50.8,-8.466779,-0.4508845,0.00951851,0,0,0,0,0,8.46678,40.70567,0.4508845,0,52.26565,-8.466779,5643.936
51,-8.499979,-0.4518856,0.009539643,0,0,0,0,0,8.499979,40.86528,0.4518856,0,52.5352,-8.499979,5641.241
51.2,-8.533313,-0.453274,0.009568954,0,0,0,0,0,8.533313,41.02554,0.453274,0,52.80658,-8.533313,5643.239
51.4,-8.566779,-0.4540445,0.00958522,0,0,0,0,0,8.566779,41.18644,0.4540445,0,53.07977,-8.566779,5637.409
51.6,-8.599979,-0.4557217,0.009620626,0,0,0,0,0,8.599978,41.34605,0.4557217,0,53.35153,-8.599979,5642.877
51.8,-8.633179,-0.4565048,0.009637157,0,0,0,0,0,8.633179,41.50566,0.4565048,0,53.62403,-8.633179,5637.191
52,-8.666779,-0.4574745,0.00965763,0,0,0,0,0,8.666779,41.66721,0.4574745,0,53.90058,-8.666779,5633.565
52.2,-8.700112,-0.4588226,0.00968609,0,0,0,0,0,8.700112,41.82746,0.4588226,0,54.17568,-8.700112,5634.644
52.4,-8.733313,-0.4598009,0.009706741,0,0,0,0,0,8.733313,41.98708,0.4598009,0,54.45044,-8.733313,5631.164
52.6,-8.766912,-0.4609807,0.009731649,0,0,0,0,0,8.766912,42.14862,0.4609807,0,54.72928,-8.766912,5629.894
52.8,-8.800245,-0.4623114,0.009759742,0,0,0,0,0,8.800245,42.30887,0.4623114,0,55.00667,-8.800245,5630.505
53,-8.833446,-0.4633118,0.009780859,0,0,0,0,0,8.833446,42.46849,0.4633118,0,55.28374,-8.833446,5627.076
53.2,-8.866512,-0.4642186,0.009800003,0,0,0,0,0,8.866512,42.62746,0.4642186,0,55.56044,-8.866512,5622.511
53.4,-8.899978,-0.4655844,0.009828835,0,0,0,0,0,8.899979,42.78836,0.4655843,0,55.84128,-8.899978,5623.238
53.6,-8.933445,-0.466772,0.009853906,0,0,0,0,0,8.933445,42.94926,0.466772,0,56.12291,-8.933445,5621.727
53.8,-8.966912,-0.4679894,0.009879608,0,0,0,0,0,8.966911,43.11015,0.4679894,0,56.40533,-8.966912,5620.494
54,-9.000111,-0.4693373,0.009908061,0,0,0,0,0,9.000112,43.26977,0.4693373,0,56.68629,-9.000111,5620.866
54.2,-9.033444,-0.4705923,0.009934557,0,0,0,0,0,9.033444,43.43002,0.4705923,0,56.96917,-9.033444,5619.977
54.4,-9.066778,-0.472008,0.009964444,0,0,0,0,0,9.066778,43.59028,0.472008,0,57.25287,-9.066778,5620.915
54.6,-9.100111,-0.4732892,0.00999149,0,0,0,0,0,9.100111,43.75053,0.4732892,0,57.53736,-9.100111,5620.16
54.8,-9.133311,-0.4745984,0.01001913,0,0,0,0,0,9.133311,43.91015,0.4745984,0,57.82153,-9.133311,5619.714
55,-9.166645,-0.4758552,0.01004566,0,0,0,0,0,9.166645,44.07041,0.4758552,0,58.10766,-9.166645,5618.497
55.2,-9.200244,-0.4773422,0.01007705,0,0,0,0,0,9.200244,44.23195,0.4773422,0,58.39689,-9.200244,5619.776
55.4,-9.233711,-0.47894,0.01011078,0,0,0,0,0,9.233711,44.39284,0.47894,0,58.68583,-9.233711,5622.319
55.6,-9.266911,-0.4802393,0.01013821,0,0,0,0,0,9.266912,44.55246,0.4802393,0,58.97328,-9.266911,5621.389
55.8,-9.300111,-0.4817502,0.01017011,0,0,0,0,0,9.300111,44.71207,0.4817502,0,59.26156,-9.300111,5622.842
56,-9.333577,-0.4832031,0.01020078,0,0,0,0,0,9.333577,44.87297,0.4832031,0,59.553,-9.333577,5623.387
56.2,-9.366644,-0.4846406,0.01023113,0,0,0,0,0,9.366644,45.03194,0.4846406,0,59.84179,-9.366644,5623.852
56.4,-9.399843,-0.4860196,0.01026024,0,0,0,0,0,9.399843,45.19156,0.4860196,0,60.13259,-9.399843,5623.477
56.6,-9.433444,-0.4874235,0.01028988,0,0,0,0,0,9.433444,45.3531,0.4874235,0,60.42776,-9.433444,5623.099
56.8,-9.466643,-0.4889039,0.01032113,0,0,0,0,0,9.466643,45.51271,0.4889039,0,60.72027,-9.466643,5623.703
57,-9.500244,-0.4904294,0.01035333,0,0,0,0,0,9.500244,45.67425,0.4904294,0,61.01718,-9.500244,5624.525
57.2,-9.533443,-0.4916793,0.01037972,0,0,0,0,0,9.533443,45.83386,0.4916793,0,61.31142,-9.533443,5622.293
57.4,-9.566776,-0.4933995,0.01041603,0,0,0,0,0,9.566776,45.99412,0.4933995,0,61.60772,-9.566776,5625.271
57.6,-9.60011,-0.4947203,0.01044392,0,0,0,0,0,9.60011,46.15438,0.4947203,0,61.90491,-9.60011,5623.592
57.8,-9.633576,-0.4961855,0.01047485,0,0,0,0,0,9.633576,46.31527,0.4961855,0,62.20416,-9.633576,5623.394
58,-9.66651,-0.4977253,0.01050735,0,0,0,0,0,9.66651,46.47361,0.4977253,0,62.49953,-9.66651,5624.208
58.2,-9.699843,-0.4992017,0.01053852,0,0,0,0,0,9.699842,46.63386,0.4992017,0,62.79937,-9.699843,5624.003
58.4,-9.733576,-0.5009425,0.01057527,0,0,0,0,0,9.733577,46.79604,0.5009425,0,63.10374,-9.733576,5626.463
58.6,-9.766909,-0.5024353,0.01060679,0,0,0,0,0,9.76691,46.9563,0.5024353,0,63.4054,-9.766909,5626.232
58.8,-9.800109,-0.5038654,0.01063698,0,0,0,0,0,9.800109,47.11591,0.5038654,0,63.70676,-9.800109,5625.268
59,-9.833443,-0.5055156,0.01067181,0,0,0,0,0,9.833443,47.27617,0.5055156,0,64.01026,-9.833443,5626.589
59.2,-9.866909,-0.5073614,0.01071078,0,0,0,0,0,9.866909,47.43706,0.5073614,0,64.31589,-9.866909,5629.9
59.4,-9.900109,-0.5087455,0.01074,0,0,0,0,0,9.900109,47.59668,0.5087455,0,64.62002,-9.900109,5628.116
59.6,-9.93331,-0.5100621,0.01076779,0,0,0,0,0,9.93331,47.7563,0.5100621,0,64.92508,-9.93331,5625.494
59.8,-9.966509,-0.5114329,0.01079673,0,0,0,0,0,9.96651,47.91591,0.5114328,0,65.23107,-9.966509,5623.379
60,-10.00011,-0.5131622,0.01083324,0,0,0,0,0,10.00011,48.07745,0.5131621,0,65.54169,-10.00011,5624.894
60.2,-10.03344,-0.5145792,0.01086315,0,0,0,0,0,10.03344,48.23771,0.5145792,0,65.85082,-10.03344,5623.017
60.4,-10.06691,-0.5164135,0.01090188,0,0,0,0,0,10.06691,48.3986,0.5164135,0,66.16214,-10.06691,5625.521
60.6,-10.10011,-0.5169759,0.01091375,0,0,0,0,0,10.10011,48.55822,0.5169759,0,66.47194,-10.10011,5614.227
60.8,-10.13344,-0.5187194,0.01095056,0,0,0,0,0,10.13344,48.71847,0.5187194,0,66.78396,-10.13344,5615.612
61,-10.16691,-0.5203708,0.01098542,0,0,0,0,0,10.16691,48.87937,0.5203708,0,67.0982,-10.16691,5615.815
61.2,-10.19998,-0.5221618,0.01102323,0,0,0,0,0,10.19998,49.03834,0.5221618,0,67.40966,-10.19998,5617.62
61.4,-10.23318,-0.523914,0.01106022,0,0,0,0,0,10.23318,49.19796,0.523914,0,67.72336,-10.23318,5618.816
61.6,-10.26678,-0.5257733,0.01109947,0,0,0,0,0,10.26678,49.3595,0.5257733,0,68.04185,-10.26678,5620.827
61.8,-10.30024,-0.5274325,0.0111345,0,0,0,0,0,10.30024,49.52039,0.5274324,0,68.36007,-10.30024,5620.649
62,-10.33344,-0.5292228,0.01117229,0,0,0,0,0,10.33344,49.68,0.5292228,0,68.67677,-10.33344,5621.896
62.2,-10.36678,-0.5310102,0.01121002,0,0,0,0,0,10.36678,49.84026,0.5310102,0,68.99576,-10.36678,5622.918
62.4,-10.40024,-0.5336475,0.0112657,0,0,0,0,0,10.40024,50.00116,0.5336475,0,69.31704,-10.40024,5632.719
62.6,-10.43344,-0.5349648,0.01129351,0,0,0,0,0,10.43344,50.16077,0.5349648,0,69.63678,-10.43344,5628.597
62.8,-10.46651,-0.5366156,0.01132836,0,0,0,0,0,10.46651,50.31975,0.5366156,0,69.95627,-10.46651,5627.956
63,-10.49997,-0.538728,0.01137295,0,0,0,0,0,10.49997,50.48065,0.538728,0,70.28066,-10.49997,5631.812
63.2,-10.53344,-0.5401964,0.01140395,0,0,0,0,0,10.53344,50.64154,0.5401964,0,70.60611,-10.53344,5628.814
63.4,-10.56677,-0.5421098,0.01144435,0,0,0,0,0,10.56677,50.8018,0.5421098,0,70.93132,-10.56677,5630.412
63.6,-10.60011,-0.5440067,0.01148439,0,0,0,0,0,10.60011,50.96206,0.5440067,0,71.25758,-10.60011,5631.708
63.8,-10.63331,-0.546173,0.01153012,0,0,0,0,0,10.63331,51.12167,0.546173,0,71.58361,-10.63331,5635.73
64,-10.66691,-0.5481137,0.01157109,0,0,0,0,0,10.66691,51.28321,0.5481137,0,71.91465,-10.66691,5637.064
64.2,-10.70011,-0.5500068,0.01161106,0,0,0,0,0,10.70011,51.44283,0.5500068,0,72.24282,-10.70011,5638.001
64.4,-10.73317,-0.551927,0.01165159,0,0,0,0,0,10.73317,51.6018,0.551927,0,72.57075,-10.73317,5639.162
64.60001,-10.76664,-0.5540248,0.01169588,0,0,0,0,0,10.76664,51.7627,0.5540248,0,72.90375,-10.76664,5641.777
64.8,-10.80011,-0.556018,0.01173796,0,0,0,0,0,10.80011,51.92359,0.556018,0,73.23786,-10.80011,5643.188
65,-10.83371,-0.5578908,0.01177749,0,0,0,0,0,10.83371,52.08513,0.5578908,0,73.57443,-10.83371,5643.17
65.2,-10.86677,-0.5597377,0.01181648,0,0,0,0,0,10.86677,52.2441,0.5597377,0,73.90676,-10.86677,5643.068
65.4,-10.90037,-0.5618299,0.01186065,0,0,0,0,0,10.90037,52.40564,0.5618299,0,74.2456,-10.90037,5645
65.60001,-10.93357,-0.5637958,0.01190215,0,0,0,0,0,10.93357,52.56526,0.5637957,0,74.58152,-10.93357,5645.755
65.8,-10.96664,-0.5656089,0.01194043,0,0,0,0,0,10.96664,52.72423,0.5656089,0,74.91723,-10.96664,5644.93
66,-10.99984,-0.5676786,0.01198412,0,0,0,0,0,10.99984,52.88385,0.5676786,0,75.25542,-10.99984,5646.457
66.20001,-11.03331,-0.5696866,0.01202651,0,0,0,0,0,11.03331,53.04474,0.5696866,0,75.5975,-11.03331,5647.079
66.4,-11.06651,-0.5716031,0.01206697,0,0,0,0,0,11.06651,53.20436,0.5716031,0,75.93801,-11.06651,5646.816
66.60001,-11.10011,-0.5736671,0.01211054,0,0,0,0,0,11.10011,53.36589,0.5736671,0,76.2838,-11.10011,5647.644
66.8,-11.13331,-0.575629,0.01215196,0,0,0,0,0,11.13331,53.52551,0.5756291,0,76.62667,-11.13331,5647.561
67,-11.16677,-0.5779261,0.01220045,0,0,0,0,0,11.16677,53.68641,0.5779261,0,76.97347,-11.16677,5650.468
67.20001,-11.20011,-0.5796701,0.01223727,0,0,0,0,0,11.20011,53.84666,0.5796701,0,77.32009,-11.20011,5647.909
67.4,-11.23344,-0.5812977,0.01227163,0,0,0,0,0,11.23344,54.00692,0.5812978,0,77.66793,-11.23344,5644.101
67.60001,-11.26664,-0.5833482,0.01231492,0,0,0,0,0,11.26664,54.16653,0.5833482,0,78.01557,-11.26664,5644.354
67.8,-11.29997,-0.5853727,0.01235766,0,0,0,0,0,11.29997,54.32679,0.5853727,0,78.36583,-11.29997,5644.138
68,-11.33371,-0.5875468,0.01240355,0,0,0,0,0,11.33371,54.48897,0.5875468,0,78.72155,-11.33371,5644.985
68.20001,-11.36691,-0.5896342,0.01244762,0,0,0,0,0,11.36691,54.64859,0.5896342,0,79.07288,-11.36691,5645.172
68.4,-11.40011,-0.5914776,0.01248654,0,0,0,0,0,11.40011,54.8082,0.5914776,0,79.42545,-11.40011,5642.89
68.60001,-11.43344,-0.5933513,0.01252609,0,0,0,0,0,11.43344,54.96845,0.5933513,0,79.78069,-11.43344,5640.692
68.8,-11.46691,-0.595642,0.01257445,0,0,0,0,0,11.46691,55.12935,0.595642,0,80.13864,-11.46691,5642.237
69,-11.50011,-0.5979034,0.01262219,0,0,0,0,0,11.5001,55.28897,0.5979034,0,80.49499,-11.50011,5643.511
69.20001,-11.53317,-0.5996896,0.0126599,0,0,0,0,0,11.53317,55.44794,0.5996896,0,80.85118,-11.53317,5640.245
69.4,-11.56664,-0.6019076,0.01270672,0,0,0,0,0,11.56664,55.60884,0.6019076,0,81.21299,-11.56664,5640.66
69.60001,-11.59997,-0.6041429,0.01275391,0,0,0,0,0,11.59997,55.7691,0.6041428,0,81.57464,-11.59997,5641.169
69.8,-11.63357,-0.6064083,0.01280173,0,0,0,0,0,11.63357,55.93063,0.6064083,0,81.94052,-11.63357,5641.644
70,-11.66677,-0.6076911,0.01282881,0,0,0,0,0,11.66677,56.09025,0.607691,0,82.30338,-11.66677,5633.1
70.20001,-11.69997,-0.6100572,0.01287877,0,0,0,0,0,11.69997,56.24986,0.6100572,0,82.66755,-11.69997,5634.477
[...]
52.6,-8.766379,-0.245186,0.006543549,0,0,0,0,0,8.766379,33.88628,0.245186,0,41.37938,-8.766379,4326.184
52.8,-8.799845,-0.2457597,0.00655886,0,0,0,0,0,8.799846,34.01564,0.2457597,0,41.57524,-8.799845,4327.822
53,-8.833311,-0.2465423,0.006579748,0,0,0,0,0,8.833311,34.145,0.2465423,0,41.77148,-8.833311,4333.093
53.2,-8.866378,-0.2473554,0.006601448,0,0,0,0,0,8.866378,34.27282,0.2473554,0,41.96576,-8.866378,4338.946
53.4,-8.899978,-0.2480993,0.006621301,0,0,0,0,0,8.899979,34.4027,0.2480993,0,42.16356,-8.899978,4343.395
53.6,-8.933311,-0.2489826,0.006644873,0,0,0,0,0,8.933311,34.53155,0.2489826,0,42.36018,-8.933311,4350.296
53.8,-8.966645,-0.2499983,0.006671982,0,0,0,0,0,8.966645,34.6604,0.2499983,0,42.55719,-8.966645,4359.446
54,-8.999712,-0.2507212,0.006691274,0,0,0,0,0,8.999712,34.78822,0.2507212,0,42.753,-8.999712,4363.499
54.2,-9.033045,-0.2514699,0.006711256,0,0,0,0,0,9.033045,34.91706,0.2514699,0,42.95078,-9.033045,4367.882
54.4,-9.066511,-0.252178,0.006730154,0,0,0,0,0,9.066511,35.04643,0.252178,0,43.14974,-9.066511,4371.475
54.6,-9.099845,-0.2528636,0.006748452,0,0,0,0,0,9.099846,35.17528,0.2528636,0,43.34832,-9.099845,4374.665
54.8,-9.133311,-0.253736,0.006771733,0,0,0,0,0,9.133311,35.30464,0.253736,0,43.54807,-9.133311,4380.997
55,-9.166511,-0.2544651,0.006791192,0,0,0,0,0,9.166511,35.43298,0.2544651,0,43.74664,-9.166511,4384.871
55.2,-9.199978,-0.2554015,0.006816183,0,0,0,0,0,9.199978,35.56234,0.2554015,0,43.9472,-9.199978,4392.189
55.4,-9.233311,-0.2561041,0.006834933,0,0,0,0,0,9.233311,35.69119,0.2561041,0,44.14735,-9.233311,4395.464
55.6,-9.266644,-0.257044,0.006860018,0,0,0,0,0,9.266644,35.82004,0.257044,0,44.34791,-9.266644,4402.757
55.8,-9.29971,-0.2576768,0.006876906,0,0,0,0,0,9.29971,35.94786,0.2576768,0,44.54727,-9.29971,4404.806
56,-9.333311,-0.2584126,0.006896544,0,0,0,0,0,9.333311,36.07774,0.2584127,0,44.75025,-9.333311,4408.427
56.2,-9.366778,-0.2590366,0.006913195,0,0,0,0,0,9.366777,36.2071,0.2590365,0,44.95283,-9.366778,4410.127
56.4,-9.399843,-0.2598694,0.006935424,0,0,0,0,0,9.399843,36.33492,0.2598695,0,45.15339,-9.399843,4415.443
56.6,-9.43331,-0.2604693,0.006951432,0,0,0,0,0,9.43331,36.46428,0.2604693,0,45.35679,-9.43331,4416.642
56.8,-9.466777,-0.2611778,0.006970341,0,0,0,0,0,9.466777,36.59365,0.2611778,0,45.56061,-9.466777,4419.639
57,-9.49971,-0.2622179,0.006998099,0,0,0,0,0,9.49971,36.72095,0.2622179,0,45.76159,-9.49971,4428.33
57.2,-9.533044,-0.2628224,0.007014233,0,0,0,0,0,9.533044,36.8498,0.2628224,0,45.96542,-9.533044,4429.502
57.4,-9.566244,-0.263643,0.007036133,0,0,0,0,0,9.566244,36.97813,0.263643,0,46.16885,-9.566244,4434.302
57.6,-9.599843,-0.2641706,0.007050212,0,0,0,0,0,9.599843,37.10801,0.2641706,0,46.37514,-9.599843,4434.018
57.8,-9.63331,-0.2648541,0.007068454,0,0,0,0,0,9.63331,37.23738,0.2648541,0,46.58105,-9.63331,4436.347
58,-9.66651,-0.2653892,0.007082734,0,0,0,0,0,9.66651,37.36571,0.2653892,0,46.78573,-9.66651,4436.22
58.2,-9.699976,-0.2661073,0.0071019,0,0,0,0,0,9.699976,37.49508,0.2661073,0,46.99248,-9.699976,4439.037
58.4,-9.733177,-0.2668753,0.007122397,0,0,0,0,0,9.733177,37.62341,0.2668753,0,47.19802,-9.733177,4442.708
58.6,-9.766643,-0.2675128,0.00713941,0,0,0,0,0,9.766642,37.75277,0.2675128,0,47.40562,-9.766643,4444.085
58.8,-9.799976,-0.2681704,0.007156961,0,0,0,0,0,9.799976,37.88162,0.2681704,0,47.61283,-9.799976,4445.788
59,-9.832909,-0.2687389,0.007172131,0,0,0,0,0,9.83291,38.00893,0.2687389,0,47.81798,-9.832909,4446.081
59.2,-9.866376,-0.2694967,0.007192357,0,0,0,0,0,9.866377,38.13829,0.2694967,0,48.02688,-9.866376,4449.315
59.4,-9.899976,-0.2700955,0.007208338,0,0,0,0,0,9.899976,38.26817,0.2700955,0,48.23705,-9.899976,4449.839
59.6,-9.93331,-0.2709258,0.007230496,0,0,0,0,0,9.93331,38.39702,0.2709258,0,48.446,-9.93331,4454.201
59.8,-9.966643,-0.2714452,0.007244358,0,0,0,0,0,9.966642,38.52587,0.2714452,0,48.65538,-9.966643,4453.406
60,-10.00011,-0.2722537,0.007265936,0,0,0,0,0,10.00011,38.65523,0.2722537,0,48.86603,-10.00011,4457.271
60.2,-10.03331,-0.2730892,0.007288232,0,0,0,0,0,10.03331,38.78357,0.2730891,0,49.07545,-10.03331,4461.596
60.4,-10.06624,-0.2737024,0.0073046,0,0,0,0,0,10.06624,38.91087,0.2737024,0,49.28362,-10.06624,4462.316
60.6,-10.09971,-0.2745582,0.007327438,0,0,0,0,0,10.09971,39.04024,0.2745582,0,49.49561,-10.09971,4466.789
60.8,-10.13318,-0.2752828,0.007346778,0,0,0,0,0,10.13317,39.1696,0.2752829,0,49.70805,-10.13318,4469.075
61,-10.16651,-0.2760764,0.007367956,0,0,0,0,0,10.16651,39.29845,0.2760763,0,49.9201,-10.16651,4472.463
61.2,-10.19984,-0.2769105,0.007390216,0,0,0,0,0,10.19984,39.4273,0.2769105,0,50.13259,-10.19984,4476.454
61.4,-10.23331,-0.2776132,0.00740897,0,0,0,0,0,10.23331,39.55666,0.2776132,0,50.34638,-10.23331,4478.229
61.6,-10.26664,-0.2784726,0.007431906,0,0,0,0,0,10.26664,39.68551,0.2784726,0,50.55979,-10.26664,4482.516
61.8,-10.29998,-0.2792638,0.007453022,0,0,0,0,0,10.29998,39.81436,0.2792638,0,50.77364,-10.29998,4485.649
62,-10.33317,-0.2800871,0.007474993,0,0,0,0,0,10.33317,39.94269,0.2800871,0,50.98709,-10.33317,4489.28
62.2,-10.36637,-0.2809795,0.00749881,0,0,0,0,0,10.36637,40.07103,0.2809795,0,51.20101,-10.36637,4493.96
62.4,-10.39984,-0.2817673,0.007519836,0,0,0,0,0,10.39984,40.20039,0.2817673,0,51.41711,-10.39984,4496.832
62.6,-10.43357,-0.282662,0.007543714,0,0,0,0,0,10.43357,40.33078,0.282662,0,51.6354,-10.43357,4501.275
62.8,-10.46664,-0.283433,0.007564289,0,0,0,0,0,10.46664,40.4586,0.283433,0,51.84984,-10.46664,4503.883
63,-10.49997,-0.2842436,0.007585922,0,0,0,0,0,10.49997,40.58746,0.2842436,0,52.06648,-10.49997,4506.989
63.2,-10.53331,-0.2852065,0.00761162,0,0,0,0,0,10.53331,40.7163,0.2852065,0,52.28358,-10.53331,4512.45
63.4,-10.56651,-0.2859577,0.00763167,0,0,0,0,0,10.56651,40.84464,0.2859577,0,52.50029,-10.56651,4514.542
63.6,-10.59957,-0.286634,0.007649719,0,0,0,0,0,10.59957,40.97245,0.286634,0,52.7166,-10.59957,4515.441
63.8,-10.63317,-0.2875081,0.007673047,0,0,0,0,0,10.63317,41.10234,0.2875081,0,52.93688,-10.63317,4519.246
64,-10.66637,-0.2884368,0.007697832,0,0,0,0,0,10.66637,41.23067,0.2884368,0,53.15501,-10.66637,4523.964
64.2,-10.69984,-0.2892404,0.007719277,0,0,0,0,0,10.69984,41.36003,0.2892404,0,53.37537,-10.69984,4526.582
64.4,-10.73304,-0.2899266,0.007737591,0,0,0,0,0,10.73304,41.48837,0.2899266,0,53.59446,-10.73304,4527.391
64.60001,-10.76664,-0.2908546,0.007762359,0,0,0,0,0,10.76664,41.61825,0.2908546,0,53.81668,-10.76664,4531.802
64.8,-10.80011,-0.2918986,0.007790221,0,0,0,0,0,10.80011,41.74761,0.2918986,0,54.03851,-10.80011,4537.99
65,-10.83344,-0.2927468,0.007812858,0,0,0,0,0,10.83344,41.87646,0.2927468,0,54.25995,-10.83344,4541.11
65.2,-10.86664,-0.2932276,0.007825688,0,0,0,0,0,10.86664,42.0048,0.2932276,0,54.48098,-10.86664,4538.524
65.4,-10.89971,-0.2942521,0.007853032,0,0,0,0,0,10.89971,42.13261,0.2942521,0,54.70162,-10.89971,4544.344
65.60001,-10.93317,-0.295215,0.007878728,0,0,0,0,0,10.93317,42.26198,0.295215,0,54.92543,-10.93317,4549.022
65.8,-10.96677,-0.2959862,0.007899312,0,0,0,0,0,10.96677,42.39186,0.2959862,0,55.15062,-10.96677,4550.647
66,-10.99984,-0.2969289,0.007924469,0,0,0,0,0,10.99984,42.51968,0.2969289,0,55.37275,-10.99984,4555.01
66.20001,-11.03331,-0.2979001,0.00795039,0,0,0,0,0,11.03331,42.64904,0.2979001,0,55.59806,-11.03331,4559.625
66.4,-11.06664,-0.2987953,0.007974282,0,0,0,0,0,11.06664,42.77789,0.2987953,0,55.82298,-11.06664,4563.052
66.60001,-11.09997,-0.2999581,0.008005314,0,0,0,0,0,11.09997,42.90674,0.2999581,0,56.04841,-11.09997,4570.495
66.8,-11.13304,-0.3008303,0.008028591,0,0,0,0,0,11.13304,43.03455,0.3008303,0,56.27253,-11.13304,4573.523
67,-11.16624,-0.3016878,0.008051476,0,0,0,0,0,11.16624,43.16289,0.3016877,0,56.49807,-11.16624,4576.226
67.20001,-11.19997,-0.3028192,0.008081671,0,0,0,0,0,11.19997,43.29329,0.3028192,0,56.72775,-11.19997,4582.85
67.4,-11.23304,-0.3035779,0.008101919,0,0,0,0,0,11.23304,43.4211,0.3035779,0,56.9534,-11.23304,4583.977
67.60001,-11.26664,-0.3047441,0.008133043,0,0,0,0,0,11.26664,43.55098,0.3047441,0,57.18323,-11.26664,4591.022
67.8,-11.29997,-0.3056618,0.008157536,0,0,0,0,0,11.29997,43.67983,0.3056619,0,57.41175,-11.29997,4594.338
68,-11.33331,-0.3066355,0.008183519,0,0,0,0,0,11.3333,43.80868,0.3066354,0,57.64078,-11.33331,4598.428
68.20001,-11.36664,-0.3077107,0.008212216,0,0,0,0,0,11.36664,43.93753,0.3077107,0,57.87036,-11.36664,4603.971
68.4,-11.39984,-0.308572,0.008235201,0,0,0,0,0,11.39984,44.06586,0.308572,0,58.09953,-11.39984,4606.289
68.60001,-11.43304,-0.3095412,0.008261067,0,0,0,0,0,11.43304,44.1942,0.3095412,0,58.32923,-11.43304,4610.155
68.8,-11.46651,-0.3105575,0.008288192,0,0,0,0,0,11.46651,44.32356,0.3105575,0,58.56131,-11.46651,4614.57
69,-11.49997,-0.3115118,0.00831366,0,0,0,0,0,11.49997,44.45293,0.3115118,0,58.79394,-11.49997,4617.995
69.20001,-11.53331,-0.3121821,0.008331548,0,0,0,0,0,11.53331,44.58178,0.3121821,0,59.02617,-11.53331,4617.196
69.4,-11.56664,-0.3130591,0.008354956,0,0,0,0,0,11.56664,44.71062,0.3130592,0,59.25894,-11.56664,4619.403
69.60001,-11.60024,-0.3142512,0.008386768,0,0,0,0,0,11.60024,44.8405,0.3142512,0,59.49413,-11.60024,4626.099
69.8,-11.6333,-0.315032,0.008407608,0,0,0,0,0,11.6333,44.96832,0.315032,0,59.72612,-11.6333,4626.848
70,-11.66624,-0.3159118,0.008431086,0,0,0,0,0,11.66624,45.09563,0.3159118,0,59.95772,-11.66624,4629.035
70.20001,-11.6997,-0.3170998,0.008462792,0,0,0,0,0,11.6997,45.22499,0.3170998,0,60.19361,-11.6997,4635.495
70.4,-11.73304,-0.3181357,0.008490439,0,0,0,0,0,11.73304,45.35384,0.3181356,0,60.42912,-11.73304,4639.699
70.60001,-11.76637,-0.3191973,0.008518771,0,0,0,0,0,11.76637,45.48269,0.3191973,0,60.66519,-11.76637,4644.205
70.8,-11.79984,-0.3202849,0.008547799,0,0,0,0,0,11.79984,45.61205,0.3202849,0,60.90276,-11.79984,4648.972
71,-11.83317,-0.3214494,0.008578877,0,0,0,0,0,11.83317,45.7409,0.3214494,0,61.13995,-11.83317,4654.821
71.20001,-11.86664,-0.3225349,0.008607845,0,0,0,0,0,11.86664,45.87027,0.3225349,0,61.37865,-11.86664,4659.404
71.4,-11.89997,-0.3234784,0.008633026,0,0,0,0,0,11.89997,45.99911,0.3234784,0,61.61698,-11.89997,4661.91
71.60001,-11.93317,-0.324514,0.008660663,0,0,0,0,0,11.93317,46.12745,0.324514,0,61.85491,-11.93317,4665.72
71.8,-11.96637,-0.325398,0.008684256,0,0,0,0,0,11.96637,46.25578,0.325398,0,62.09341,-11.96637,4667.286
72,-11.99984,-0.3266886,0.0087187,0,0,0,0,0,11.99984,46.38515,0.3266886,0,62.3344,-11.99984,4674.518
72.20001,-12.03344,-0.3277616,0.008747336,0,0,0,0,0,12.03344,46.51503,0.3277616,0,62.57694,-12.03344,4678.511
72.4,-12.06664,-0.3279988,0.008753666,0,0,0,0,0,12.06664,46.64336,0.3279988,0,62.81718,-12.06664,4670.662
72.60001,-12.09997,-0.3294979,0.008793675,0,0,0,0,0,12.09997,46.77221,0.3294979,0,63.05895,-12.09997,4680.679
72.8,-12.1333,-0.3304688,0.008819586,0,0,0,0,0,12.1333,46.90106,0.3304688,0,63.30132,-12.1333,4683.107
73,-12.1665,-0.3314969,0.008847023,0,0,0,0,0,12.1665,47.02939,0.3314969,0,63.5433,-12.1665,4686.322
73.20001,-12.1997,-0.3324239,0.008871764,0,0,0,0,0,12.1997,47.15773,0.3324239,0,63.78587,-12.1997,4688.042
73.4,-12.23304,-0.3324968,0.00887371,0,0,0,0,0,12.23304,47.28658,0.3324968,0,64.03,-12.23304,4677.637
73.60001,-12.26637,-0.3340308,0.008914649,0,0,0,0,0,12.26637,47.41542,0.3340308,0,64.27474,-12.26637,4687.73
73.8,-12.29984,-0.3357567,0.00896071,0,0,0,0,0,12.29984,47.54479,0.3357567,0,64.52105,-12.29984,4700.359
74,-12.33317,-0.3370917,0.00899634,0,0,0,0,0,12.33317,47.67364,0.3370917,0,64.76698,-12.33317,4707.457
74.20001,-12.36664,-0.3390218,0.00904785,0,0,0,0,0,12.36664,47.803,0.3390218,0,65.01452,-12.36664,4722.706
74.4,-12.39997,-0.340353,0.009083376,0,0,0,0,0,12.39997,47.93185,0.340353,0,65.26168,-12.39997,4729.546
74.60001,-12.43344,-0.3415274,0.009114719,0,0,0,0,0,12.43344,48.06122,0.3415274,0,65.51044,-12.43344,4734.074
74.8,-12.4665,-0.3429307,0.009152171,0,0,0,0,0,12.4665,48.18903,0.3429307,0,65.75684,-12.4665,4741.828
75,-12.49984,-0.3446492,0.009198035,0,0,0,0,0,12.49984,48.31788,0.3446492,0,66.00584,-12.49984,4753.739
75.20001,-12.53344,-0.3458811,0.009230913,0,0,0,0,0,12.53344,48.44777,0.3458811,0,66.25746,-12.53344,4758.742
75.4,-12.56677,-0.3474839,0.009273686,0,0,0,0,0,12.56677,48.57661,0.3474839,0,66.50771,-12.56677,4768.844
75.60001,-12.6001,-0.3493042,0.009322268,0,0,0,0,0,12.6001,48.70546,0.3493042,0,66.75859,-12.6001,4781.815
75.8,-12.6333,-0.3502686,0.009348007,0,0,0,0,0,12.6333,48.83379,0.3502687,0,67.00909,-12.6333,4783.021
76,-12.66677,-0.3518901,0.009391282,0,0,0,0,0,12.66677,48.96316,0.3518901,0,67.26224,-12.66677,4793.013
76.20001,-12.69984,-0.3535678,0.009436054,0,0,0,0,0,12.69984,49.09098,0.3535678,0,67.513,-12.69984,4803.803
76.4,-12.73304,-0.3544209,0.009458823,0,0,0,0,0,12.73304,49.21931,0.3544209,0,67.7654,-12.73304,4803.256
76.60001,-12.76637,-0.3558084,0.009495853,0,0,0,0,0,12.76637,49.34816,0.3558084,0,68.01946,-12.76637,4809.824
76.8,-12.7997,-0.3574104,0.009538606,0,0,0,0,0,12.7997,49.47701,0.3574104,0,68.27416,-12.7997,4819.189
77,-12.83317,-0.3586463,0.00957159,0,0,0,0,0,12.83317,49.60637,0.3586463,0,68.53055,-12.83317,4823.471
77.20001,-12.8665,-0.3597571,0.009601235,0,0,0,0,0,12.8665,49.73522,0.3597571,0,68.78656,-12.8665,4826.04
77.4,-12.89997,-0.3608465,0.00963031,0,0,0,0,0,12.89997,49.86459,0.3608465,0,69.04426,-12.89997,4828.196
77.60001,-12.9333,-0.362679,0.009679216,0,0,0,0,0,12.9333,49.99343,0.362679,0,69.30159,-12.9333,4840.243
77.8,-12.96677,-0.3642387,0.009720842,0,0,0,0,0,12.96677,50.1228,0.3642387,0,69.56062,-12.96677,4848.484
78,-12.99983,-0.3656562,0.009758671,0,0,0,0,0,12.99983,50.25062,0.3656562,0,69.81721,-12.99983,4854.879
78.20001,-13.03304,-0.3667612,0.009788162,0,0,0,0,0,13.03304,50.37895,0.3667612,0,70.07551,-13.03304,4856.988
78.4,-13.0665,-0.3682315,0.009827402,0,0,0,0,0,13.0665,50.50832,0.3682315,0,70.33655,-13.0665,4863.747
78.60001,-13.1001,-0.3698052,0.009869399,0,0,0,0,0,13.1001,50.6382,0.3698052,0,70.59933,-13.1001,4871.714
78.8,-13.1333,-0.371804,0.009922744,0,0,0,0,0,13.1333,50.76653,0.371804,0,70.85965,-13.1333,4885.311
79,-13.1665,-0.3733039,0.009962773,0,0,0,0,0,13.1665,50.89486,0.3733039,0,71.12065,-13.1665,4892.233
79.20001,-13.19997,-0.3755391,0.01002243,0,0,0,0,0,13.19997,51.02423,0.3755391,0,71.38444,-13.19997,4908.561
79.4,-13.23303,-0.3769024,0.01005881,0,0,0,0,0,13.23303,51.15205,0.3769024,0,71.64577,-13.23303,4913.524
79.60001,-13.2665,-0.378463,0.01010046,0,0,0,0,0,13.2665,51.28141,0.378463,0,71.91095,-13.2665,4920.803
79.8,-13.2997,-0.3803114,0.01014979,0,0,0,0,0,13.2997,51.40974,0.3803114,0,72.17472,-13.2997,4931.81
80,-13.33303,-0.3822645,0.01020192,0,0,0,0,0,13.33303,51.53859,0.3822646,0,72.44024,-13.33303,4943.993
80.20001,-13.3665,-0.383904,0.01024567,0,0,0,0,0,13.3665,51.66796,0.383904,0,72.70755,-13.3665,4951.943
80.4,-13.39997,-0.3854443,0.01028678,0,0,0,0,0,13.39997,51.79732,0.3854443,0,72.97556,-13.39997,4958.503
80.60001,-13.4333,-0.3874898,0.01034137,0,0,0,0,0,13.4333,51.92617,0.3874898,0,73.24323,-13.4333,4971.492
80.8,-13.46663,-0.3889237,0.01037964,0,0,0,0,0,13.46663,52.05502,0.3889237,0,73.51161,-13.46663,4976.515
81.00001,-13.49997,-0.3905873,0.01042404,0,0,0,0,0,13.49997,52.18387,0.3905873,0,73.78071,-13.49997,4984.371
81.20001,-13.53317,-0.3925518,0.01047647,0,0,0,0,0,13.53317,52.3122,0.3925518,0,74.04946,-13.53317,4995.996
81.4,-13.56637,-0.3940851,0.01051738,0,0,0,0,0,13.56637,52.44054,0.3940851,0,74.31894,-13.56637,5002.011
81.60001,-13.59997,-0.3960023,0.01056855,0,0,0,0,0,13.59997,52.57042,0.3960023,0,74.5924,-13.59997,5012.62
81.8,-13.63343,-0.3982925,0.01062967,0,0,0,0,0,13.63343,52.69978,0.3982925,0,74.86553,-13.63343,5027.858
82.00001,-13.66637,-0.4004012,0.01068595,0,0,0,0,0,13.66637,52.82708,0.4004012,0,75.13502,-13.66637,5040.874
82.20001,-13.69997,-0.4022183,0.01073445,0,0,0,0,0,13.69997,52.95696,0.4022183,0,75.41073,-13.69997,5049.809
82.4,-13.73343,-0.4041463,0.0107859,0,0,0,0,0,13.73343,53.08633,0.4041463,0,75.68611,-13.73343,5060.061
82.60001,-13.7665,-0.4058891,0.01083241,0,0,0,0,0,13.7665,53.21415,0.4058891,0,75.95893,-13.7665,5068.036
82.8,-13.7997,-0.4073691,0.01087191,0,0,0,0,0,13.7997,53.34248,0.4073691,0,76.23361,-13.7997,5072.564
83.00001,-13.83303,-0.4091844,0.01092036,0,0,0,0,0,13.83303,53.47133,0.4091844,0,76.51015,-13.83303,5081.097
83.20001,-13.86637,-0.4112192,0.01097466,0,0,0,0,0,13.86637,53.60018,0.4112192,0,76.78745,-13.86637,5092.224
83.4,-13.89983,-0.4127285,0.01101494,0,0,0,0,0,13.89983,53.72955,0.4127285,0,77.06666,-13.89983,5096.663
83.60001,-13.9333,-0.4149156,0.01107331,0,0,0,0,0,13.9333,53.85891,0.4149156,0,77.34662,-13.9333,5109.347
83.8,-13.9665,-0.417048,0.01113022,0,0,0,0,0,13.9665,53.98724,0.417048,0,77.62514,-13.9665,5121.322
84.00001,-13.99997,-0.4189914,0.01118209,0,0,0,0,0,13.99997,54.11661,0.4189914,0,77.90669,-13.99997,5130.721
84.20001,-14.03343,-0.421205,0.01124116,0,0,0,0,0,14.03343,54.24597,0.421205,0,78.18903,-14.03343,5143.286
84.4,-14.0665,-0.4231726,0.01129368,0,0,0,0,0,14.0665,54.37379,0.4231727,0,78.46878,-14.0665,5152.877
84.60001,-14.0997,-0.4250591,0.01134402,0,0,0,0,0,14.0997,54.50212,0.4250591,0,78.75045,-14.0997,5161.29
84.8,-14.13317,-0.4271537,0.01139992,0,0,0,0,0,14.13317,54.63148,0.4271537,0,79.03519,-14.13317,5171.976
85.00001,-14.16677,-0.4293283,0.01145796,0,0,0,0,0,14.16677,54.76137,0.4293283,0,79.32188,-14.16677,5183.425
85.20001,-14.19983,-0.4309567,0.01150142,0,0,0,0,0,14.19983,54.88918,0.4309568,0,79.60481,-14.19983,5188.384
85.4,-14.2333,-0.4332925,0.01156376,0,0,0,0,0,14.2333,55.01855,0.4332925,0,79.89199,-14.2333,5201.546
85.60001,-14.26676,-0.4356251,0.01162601,0,0,0,0,0,14.26676,55.14791,0.4356251,0,80.18,-14.26676,5214.507
85.8,-14.29983,-0.4377333,0.01168227,0,0,0,0,0,14.29983,55.27573,0.4377333,0,80.46539,-14.29983,5224.811
86.00001,-14.33303,-0.4398921,0.01173989,0,0,0,0,0,14.33303,55.40407,0.4398921,0,80.75275,-14.33303,5235.512
86.20001,-14.36637,-0.4421887,0.01180118,0,0,0,0,0,14.36637,55.53291,0.4421887,0,81.04209,-14.36637,5247.64
86.4,-14.39983,-0.4444648,0.01186192,0,0,0,0,0,14.39983,55.66228,0.4444648,0,81.33343,-14.39983,5259.307
86.60001,-14.43317,-0.4465954,0.01191879,0,0,0,0,0,14.43317,55.79113,0.4465954,0,81.62447,-14.43317,5269.161
86.8,-14.4665,-0.4490019,0.01198301,0,0,0,0,0,14.4665,55.91998,0.4490019,0,81.91635,-14.4665,5282.114
87.00001,-14.49983,-0.4516671,0.01205414,0,0,0,0,0,14.49983,56.04882,0.4516671,0,82.20908,-14.49983,5297.936
87.20001,-14.5333,-0.4539077,0.01211394,0,0,0,0,0,14.5333,56.17819,0.4539077,0,82.50386,-14.5333,5308.547
87.4,-14.56663,-0.4561615,0.01217409,0,0,0,0,0,14.56663,56.30704,0.4561615,0,82.79831,-14.56663,5319.219
87.60001,-14.59996,-0.4585626,0.01223817,0,0,0,0,0,14.59996,56.43589,0.4585626,0,83.09365,-14.59996,5331.449
87.8,-14.63303,-0.4605996,0.01229253,0,0,0,0,0,14.63303,56.56371,0.4605996,0,83.38748,-14.63303,5339.42
88.00001,-14.66663,-0.4632578,0.01236347,0,0,0,0,0,14.66663,56.69359,0.4632578,0,83.68694,-14.66663,5354.176
88.20001,-14.69996,-0.4655304,0.01242412,0,0,0,0,0,14.69996,56.82243,0.4655304,0,83.98491,-14.69996,5364.434
88.4,-14.7333,-0.4678205,0.01248524,0,0,0,0,0,14.7333,56.95129,0.4678205,0,84.28378,-14.7333,5374.737
88.60001,-14.76676,-0.4700273,0.01254414,0,0,0,0,0,14.76676,57.08065,0.4700273,0,84.58474,-14.76676,5383.863
88.8,-14.8001,-0.4723296,0.01260558,0,0,0,0,0,14.8001,57.2095,0.4723296,0,84.8854,-14.8001,5393.992
89.00001,-14.8333,-0.4746643,0.01266789,0,0,0,0,0,14.8333,57.33783,0.4746643,0,85.18576,-14.8333,5404.398
89.20001,-14.86623,-0.4766434,0.01272071,0,0,0,0,0,14.86623,57.46513,0.4766434,0,85.48461,-14.86623,5410.737
89.4,-14.8997,-0.4790832,0.01278582,0,0,0,0,0,14.8997,57.5945,0.4790832,0,85.78921,-14.8997,5421.893
89.60001,-14.93303,-0.4815305,0.01285114,0,0,0,0,0,14.93303,57.72335,0.4815305,0,86.09352,-14.93303,5433.03
89.8,-14.9665,-0.4837767,0.01291108,0,0,0,0,0,14.9665,57.85271,0.4837767,0,86.39999,-14.9665,5441.671
90.00001,-14.99983,-0.4861134,0.01297345,0,0,0,0,0,14.99983,57.98156,0.4861134,0,86.70617,-14.99983,5451.24
90.03001,-15.0049,-0.4870673,0.0129989,0,0,0,0,0,15.0049,58.00115,0.4870673,0,86.75279,-15.0049,5459.39